Workbook

Sheet No.1
B1: =AB4 -> 0 | E1: 年産 組織法人経営体に関する経営分析調査（麦類・そば・なたね・畑作物生産費（組織法人経営）） 集計結果検討表 Ｎｏ．１
G3: 集計番号 | J3: 集計名称 | Q3: 集計経営体数 | V3: 集計倍率 | AB3: 調査年 | AG3: 都道府県等 | AL3: 経営種類 | AQ3: 生産費区分 | AV3: 規模階層 | BA3: 平均値種類 | BF3: 加重・総和の別 | BK3: 集計区分 | BP3: 田畑区分 | BU3: ビール麦販売区分 | BZ3: てんさい栽培区分
B4: 本年産 | AH4: =IF(AG4<>"",DGET(リスト!A2:B71,"都道府県番号",リスト!B73:B74),"") | AM4: =IF(AL4>0,DGET(リスト!AE2:AF4,"経営種類",リスト!AF6:AF7),"") | AR4: =IF(AQ4>0,DGET(リスト!D2:E13,"生産費区分",リスト!E15:E16),"") | AW4: =IF(AV4<>"",IF(OR(AQ4=77,AQ4=78,AQ4=79),DGET(リスト!J20:K24,"規模階層",リスト!K16:K17),IF(AQ4=76,DGET(リスト!J27:K35,"規模階層",リスト!K16:K17),IF(AQ4=84,DGET(リスト!J38:K42,"規模階層",リスト!K16:K17),IF(AQ4=75,DGET(リスト!M3:N7,"規模階層",リスト!K16:K17),IF(AQ4=86,DGET(リスト!M10:N15,"規模階層",リスト!K16:K17),IF(AQ4=85,DGET(リスト!M18:N22,"規模階層",リスト!K16:K17),"")))))),"") | BB4: =IF(BA4<>"",DGET(リスト!V2:W7,"平均値種類",リスト!W9:W10),"") | BG4: =IF(BF4>0,DGET(リスト!Y2:Z4,"加重・総和の別",リスト!Z6:Z7),"") | BL4: =IF(BK4>0,DGET(リスト!G2:H8,"集計区分",リスト!H10:H11),"") | BQ4: =IF(BP4<>"",DGET(リスト!S2:T6,"田畑区分",リスト!T8:T9),"") | BV4: =IF(BU4<>"",DGET(リスト!P2:Q7,"ビール麦販売区分",リスト!Q9:Q10),"") | CA4: =IF(BZ4<>"",DGET(リスト!AB2:AC6,"てんさい栽培区分",リスト!AC8:AC9),"")
B5: 前年産
B7: １ 生産費総括 | AZ7: 単位：円 | BD7: ４ 調査作物収入 | CG7: 単位：円、kg
I8: 購入 | T8: 自給 | AE8: 償却 | AP8: 計 | BL8: 数量 | BW8: 価額
I9: =IF($B$1<>"",$B$1,"") -> 0 | M9: =IF($B$1<>"",$B$1-1,"") -> -1 | Q9: 増減率 | T9: =IF($B$1<>"",$B$1,"") -> 0 | X9: =IF($B$1<>"",$B$1-1,"") -> -1 | AB9: 増減率 | AE9: =IF($B$1<>"",$B$1,"") -> 0 | AI9: =IF($B$1<>"",$B$1-1,"") -> -1 | AM9: 増減率 | AP9: =IF($B$1<>"",$B$1,"") -> 0 | AT9: =IF($B$1<>"",$B$1-1,"") -> -1 | AX9: 増減率 | BL9: =IF($B$1<>"",$B$1,"") -> 0 | BP9: =IF($B$1<>"",$B$1-1,"") -> -1 | BT9: 増減率 | BW9: =IF($B$1<>"",$B$1,"") -> 0 | CA9: =IF($B$1<>"",$B$1-1,"") -> -1 | CE9: 増減率
B10: 物財費 | Q10: =IF(I10="-", "-", IF(M10="-", "-", IF(ABS(M10)=0, "-", ROUND(100*(I10-M10)/ABS(M10), 1)))) -> - | R10: =IF(N10="-", "-", IF(P10="-", "-", IF(ABS(P10)=0, "-", ROUND(100*(N10-P10)/ABS(P10), 1)))) -> - | S10: =IF(O10="-", "-", IF(Q10="-", "-", IF(ABS(Q10)=0, "-", ROUND(100*(O10-Q10)/ABS(Q10), 1)))) -> - | AB10: =IF(T10="-", "-", IF(X10="-", "-", IF(ABS(X10)=0, "-", ROUND(100*(T10-X10)/ABS(X10), 1)))) -> - | AC10: =IF(Y10="-", "-", IF(AA10="-", "-", IF(ABS(AA10)=0, "-", ROUND(100*(Y10-AA10)/ABS(AA10), 1)))) -> - | AD10: =IF(Z10="-", "-", IF(AB10="-", "-", IF(ABS(AB10)=0, "-", ROUND(100*(Z10-AB10)/ABS(AB10), 1)))) -> - | AM10: =IF(AE10="-", "-", IF(AI10="-", "-", IF(ABS(AI10)=0, "-", ROUND(100*(AE10-AI10)/ABS(AI10), 1)))) -> - | AN10: =IF(AJ10="-", "-", IF(AL10="-", "-", IF(ABS(AL10)=0, "-", ROUND(100*(AJ10-AL10)/ABS(AL10), 1)))) -> - | AO10: =IF(AK10="-", "-", IF(AM10="-", "-", IF(ABS(AM10)=0, "-", ROUND(100*(AK10-AM10)/ABS(AM10), 1)))) -> - | AX10: =IF(AP10="-", "-", IF(AT10="-", "-", IF(ABS(AT10)=0, "-", ROUND(100*(AP10-AT10)/ABS(AT10), 1)))) -> - | AY10: =IF(AU10="-", "-", IF(AW10="-", "-", IF(ABS(AW10)=0, "-", ROUND(100*(AU10-AW10)/ABS(AW10), 1)))) -> - | AZ10: =IF(AV10="-", "-", IF(AX10="-", "-", IF(ABS(AX10)=0, "-", ROUND(100*(AV10-AX10)/ABS(AX10), 1)))) -> - | BD10: 主産物 | BE10: 販売用 | BT10: =IF(BL10="-", "-", IF(BP10="-", "-", IF(ABS(BP10)=0, "-", ROUND(100*(BL10-BP10)/ABS(BP10), 1)))) -> - | BU10: =IF(BQ10="-", "-", IF(BS10="-", "-", IF(ABS(BS10)=0, "-", ROUND(100*(BQ10-BS10)/ABS(BS10), 1)))) -> - | BV10: =IF(BR10="-", "-", IF(BT10="-", "-", IF(ABS(BT10)=0, "-", ROUND(100*(BR10-BT10)/ABS(BT10), 1)))) -> - | CE10: =IF(BW10="-", "-", IF(CA10="-", "-", IF(ABS(CA10)=0, "-", ROUND(100*(BW10-CA10)/ABS(CA10), 1)))) -> - | CF10: =IF(CB10="-", "-", IF(CD10="-", "-", IF(ABS(CD10)=0, "-", ROUND(100*(CB10-CD10)/ABS(CD10), 1)))) -> - | CG10: =IF(CC10="-", "-", IF(CE10="-", "-", IF(ABS(CE10)=0, "-", ROUND(100*(CC10-CE10)/ABS(CE10), 1)))) -> -
C11: 種苗費 | Q11: =IF(I11="-", "-", IF(M11="-", "-", IF(ABS(M11)=0, "-", ROUND(100*(I11-M11)/ABS(M11), 1)))) -> - | R11: =IF(N11="-", "-", IF(P11="-", "-", IF(ABS(P11)=0, "-", ROUND(100*(N11-P11)/ABS(P11), 1)))) -> - | S11: =IF(O11="-", "-", IF(Q11="-", "-", IF(ABS(Q11)=0, "-", ROUND(100*(O11-Q11)/ABS(Q11), 1)))) -> - | AB11: =IF(T11="-", "-", IF(X11="-", "-", IF(ABS(X11)=0, "-", ROUND(100*(T11-X11)/ABS(X11), 1)))) -> - | AC11: =IF(Y11="-", "-", IF(AA11="-", "-", IF(ABS(AA11)=0, "-", ROUND(100*(Y11-AA11)/ABS(AA11), 1)))) -> - | AD11: =IF(Z11="-", "-", IF(AB11="-", "-", IF(ABS(AB11)=0, "-", ROUND(100*(Z11-AB11)/ABS(AB11), 1)))) -> - | AX11: =IF(AP11="-", "-", IF(AT11="-", "-", IF(ABS(AT11)=0, "-", ROUND(100*(AP11-AT11)/ABS(AT11), 1)))) -> - | AY11: =IF(AU11="-", "-", IF(AW11="-", "-", IF(ABS(AW11)=0, "-", ROUND(100*(AU11-AW11)/ABS(AW11), 1)))) -> - | AZ11: =IF(AV11="-", "-", IF(AX11="-", "-", IF(ABS(AX11)=0, "-", ROUND(100*(AV11-AX11)/ABS(AX11), 1)))) -> - | BE11: 組織用 | BT11: =IF(BL11="-", "-", IF(BP11="-", "-", IF(ABS(BP11)=0, "-", ROUND(100*(BL11-BP11)/ABS(BP11), 1)))) -> - | BU11: =IF(BQ11="-", "-", IF(BS11="-", "-", IF(ABS(BS11)=0, "-", ROUND(100*(BQ11-BS11)/ABS(BS11), 1)))) -> - | BV11: =IF(BR11="-", "-", IF(BT11="-", "-", IF(ABS(BT11)=0, "-", ROUND(100*(BR11-BT11)/ABS(BT11), 1)))) -> - | CE11: =IF(BW11="-", "-", IF(CA11="-", "-", IF(ABS(CA11)=0, "-", ROUND(100*(BW11-CA11)/ABS(CA11), 1)))) -> - | CF11: =IF(CB11="-", "-", IF(CD11="-", "-", IF(ABS(CD11)=0, "-", ROUND(100*(CB11-CD11)/ABS(CD11), 1)))) -> - | CG11: =IF(CC11="-", "-", IF(CE11="-", "-", IF(ABS(CE11)=0, "-", ROUND(100*(CC11-CE11)/ABS(CE11), 1)))) -> -
C12: 肥料費 | Q12: =IF(I12="-", "-", IF(M12="-", "-", IF(ABS(M12)=0, "-", ROUND(100*(I12-M12)/ABS(M12), 1)))) -> - | R12: =IF(N12="-", "-", IF(P12="-", "-", IF(ABS(P12)=0, "-", ROUND(100*(N12-P12)/ABS(P12), 1)))) -> - | S12: =IF(O12="-", "-", IF(Q12="-", "-", IF(ABS(Q12)=0, "-", ROUND(100*(O12-Q12)/ABS(Q12), 1)))) -> - | AB12: =IF(T12="-", "-", IF(X12="-", "-", IF(ABS(X12)=0, "-", ROUND(100*(T12-X12)/ABS(X12), 1)))) -> - | AC12: =IF(Y12="-", "-", IF(AA12="-", "-", IF(ABS(AA12)=0, "-", ROUND(100*(Y12-AA12)/ABS(AA12), 1)))) -> - | AD12: =IF(Z12="-", "-", IF(AB12="-", "-", IF(ABS(AB12)=0, "-", ROUND(100*(Z12-AB12)/ABS(AB12), 1)))) -> - | AX12: =IF(AP12="-", "-", IF(AT12="-", "-", IF(ABS(AT12)=0, "-", ROUND(100*(AP12-AT12)/ABS(AT12), 1)))) -> - | AY12: =IF(AU12="-", "-", IF(AW12="-", "-", IF(ABS(AW12)=0, "-", ROUND(100*(AU12-AW12)/ABS(AW12), 1)))) -> - | AZ12: =IF(AV12="-", "-", IF(AX12="-", "-", IF(ABS(AX12)=0, "-", ROUND(100*(AV12-AX12)/ABS(AX12), 1)))) -> - | BE12: 計 | BT12: =IF(BL12="-", "-", IF(BP12="-", "-", IF(ABS(BP12)=0, "-", ROUND(100*(BL12-BP12)/ABS(BP12), 1)))) -> - | BU12: =IF(BQ12="-", "-", IF(BS12="-", "-", IF(ABS(BS12)=0, "-", ROUND(100*(BQ12-BS12)/ABS(BS12), 1)))) -> - | BV12: =IF(BR12="-", "-", IF(BT12="-", "-", IF(ABS(BT12)=0, "-", ROUND(100*(BR12-BT12)/ABS(BT12), 1)))) -> - | CE12: =IF(BW12="-", "-", IF(CA12="-", "-", IF(ABS(CA12)=0, "-", ROUND(100*(BW12-CA12)/ABS(CA12), 1)))) -> - | CF12: =IF(CB12="-", "-", IF(CD12="-", "-", IF(ABS(CD12)=0, "-", ROUND(100*(CB12-CD12)/ABS(CD12), 1)))) -> - | CG12: =IF(CC12="-", "-", IF(CE12="-", "-", IF(ABS(CE12)=0, "-", ROUND(100*(CC12-CE12)/ABS(CE12), 1)))) -> -
C13: 農業薬剤費 | Q13: =IF(I13="-", "-", IF(M13="-", "-", IF(ABS(M13)=0, "-", ROUND(100*(I13-M13)/ABS(M13), 1)))) -> - | R13: =IF(N13="-", "-", IF(P13="-", "-", IF(ABS(P13)=0, "-", ROUND(100*(N13-P13)/ABS(P13), 1)))) -> - | S13: =IF(O13="-", "-", IF(Q13="-", "-", IF(ABS(Q13)=0, "-", ROUND(100*(O13-Q13)/ABS(Q13), 1)))) -> - | AX13: =IF(AP13="-", "-", IF(AT13="-", "-", IF(ABS(AT13)=0, "-", ROUND(100*(AP13-AT13)/ABS(AT13), 1)))) -> - | AY13: =IF(AU13="-", "-", IF(AW13="-", "-", IF(ABS(AW13)=0, "-", ROUND(100*(AU13-AW13)/ABS(AW13), 1)))) -> - | AZ13: =IF(AV13="-", "-", IF(AX13="-", "-", IF(ABS(AX13)=0, "-", ROUND(100*(AV13-AX13)/ABS(AX13), 1)))) -> - | BD13: 副産物 | BT13: =IF(BL13="-", "-", IF(BP13="-", "-", IF(ABS(BP13)=0, "-", ROUND(100*(BL13-BP13)/ABS(BP13), 1)))) -> - | BU13: =IF(BQ13="-", "-", IF(BS13="-", "-", IF(ABS(BS13)=0, "-", ROUND(100*(BQ13-BS13)/ABS(BS13), 1)))) -> - | BV13: =IF(BR13="-", "-", IF(BT13="-", "-", IF(ABS(BT13)=0, "-", ROUND(100*(BR13-BT13)/ABS(BT13), 1)))) -> - | CE13: =IF(BW13="-", "-", IF(CA13="-", "-", IF(ABS(CA13)=0, "-", ROUND(100*(BW13-CA13)/ABS(CA13), 1)))) -> - | CF13: =IF(CB13="-", "-", IF(CD13="-", "-", IF(ABS(CD13)=0, "-", ROUND(100*(CB13-CD13)/ABS(CD13), 1)))) -> - | CG13: =IF(CC13="-", "-", IF(CE13="-", "-", IF(ABS(CE13)=0, "-", ROUND(100*(CC13-CE13)/ABS(CE13), 1)))) -> -
C14: 光熱動力費 | Q14: =IF(I14="-", "-", IF(M14="-", "-", IF(ABS(M14)=0, "-", ROUND(100*(I14-M14)/ABS(M14), 1)))) -> - | R14: =IF(N14="-", "-", IF(P14="-", "-", IF(ABS(P14)=0, "-", ROUND(100*(N14-P14)/ABS(P14), 1)))) -> - | S14: =IF(O14="-", "-", IF(Q14="-", "-", IF(ABS(Q14)=0, "-", ROUND(100*(O14-Q14)/ABS(Q14), 1)))) -> - | AB14: =IF(T14="-", "-", IF(X14="-", "-", IF(ABS(X14)=0, "-", ROUND(100*(T14-X14)/ABS(X14), 1)))) -> - | AC14: =IF(Y14="-", "-", IF(AA14="-", "-", IF(ABS(AA14)=0, "-", ROUND(100*(Y14-AA14)/ABS(AA14), 1)))) -> - | AD14: =IF(Z14="-", "-", IF(AB14="-", "-", IF(ABS(AB14)=0, "-", ROUND(100*(Z14-AB14)/ABS(AB14), 1)))) -> - | AX14: =IF(AP14="-", "-", IF(AT14="-", "-", IF(ABS(AT14)=0, "-", ROUND(100*(AP14-AT14)/ABS(AT14), 1)))) -> - | AY14: =IF(AU14="-", "-", IF(AW14="-", "-", IF(ABS(AW14)=0, "-", ROUND(100*(AU14-AW14)/ABS(AW14), 1)))) -> - | AZ14: =IF(AV14="-", "-", IF(AX14="-", "-", IF(ABS(AX14)=0, "-", ROUND(100*(AV14-AX14)/ABS(AX14), 1)))) -> - | BD14: 粗収益 | CE14: =IF(BW14="-", "-", IF(CA14="-", "-", IF(ABS(CA14)=0, "-", ROUND(100*(BW14-CA14)/ABS(CA14), 1)))) -> - | CF14: =IF(CB14="-", "-", IF(CD14="-", "-", IF(ABS(CD14)=0, "-", ROUND(100*(CB14-CD14)/ABS(CD14), 1)))) -> - | CG14: =IF(CC14="-", "-", IF(CE14="-", "-", IF(ABS(CE14)=0, "-", ROUND(100*(CC14-CE14)/ABS(CE14), 1)))) -> -
C15: その他の諸材料費 | Q15: =IF(I15="-", "-", IF(M15="-", "-", IF(ABS(M15)=0, "-", ROUND(100*(I15-M15)/ABS(M15), 1)))) -> - | R15: =IF(N15="-", "-", IF(P15="-", "-", IF(ABS(P15)=0, "-", ROUND(100*(N15-P15)/ABS(P15), 1)))) -> - | S15: =IF(O15="-", "-", IF(Q15="-", "-", IF(ABS(Q15)=0, "-", ROUND(100*(O15-Q15)/ABS(Q15), 1)))) -> - | AB15: =IF(T15="-", "-", IF(X15="-", "-", IF(ABS(X15)=0, "-", ROUND(100*(T15-X15)/ABS(X15), 1)))) -> - | AC15: =IF(Y15="-", "-", IF(AA15="-", "-", IF(ABS(AA15)=0, "-", ROUND(100*(Y15-AA15)/ABS(AA15), 1)))) -> - | AD15: =IF(Z15="-", "-", IF(AB15="-", "-", IF(ABS(AB15)=0, "-", ROUND(100*(Z15-AB15)/ABS(AB15), 1)))) -> - | AX15: =IF(AP15="-", "-", IF(AT15="-", "-", IF(ABS(AT15)=0, "-", ROUND(100*(AP15-AT15)/ABS(AT15), 1)))) -> - | AY15: =IF(AU15="-", "-", IF(AW15="-", "-", IF(ABS(AW15)=0, "-", ROUND(100*(AU15-AW15)/ABS(AW15), 1)))) -> - | AZ15: =IF(AV15="-", "-", IF(AX15="-", "-", IF(ABS(AX15)=0, "-", ROUND(100*(AV15-AX15)/ABS(AX15), 1)))) -> - | BD15: （参考）奨励金 | CE15: =IF(BW15="-", "-", IF(CA15="-", "-", IF(ABS(CA15)=0, "-", ROUND(100*(BW15-CA15)/ABS(CA15), 1)))) -> - | CF15: =IF(CB15="-", "-", IF(CD15="-", "-", IF(ABS(CD15)=0, "-", ROUND(100*(CB15-CD15)/ABS(CD15), 1)))) -> - | CG15: =IF(CC15="-", "-", IF(CE15="-", "-", IF(ABS(CE15)=0, "-", ROUND(100*(CC15-CE15)/ABS(CE15), 1)))) -> -
C16: 土地改良及び水利費 | Q16: =IF(I16="-", "-", IF(M16="-", "-", IF(ABS(M16)=0, "-", ROUND(100*(I16-M16)/ABS(M16), 1)))) -> - | R16: =IF(N16="-", "-", IF(P16="-", "-", IF(ABS(P16)=0, "-", ROUND(100*(N16-P16)/ABS(P16), 1)))) -> - | S16: =IF(O16="-", "-", IF(Q16="-", "-", IF(ABS(Q16)=0, "-", ROUND(100*(O16-Q16)/ABS(Q16), 1)))) -> - | AX16: =IF(AP16="-", "-", IF(AT16="-", "-", IF(ABS(AT16)=0, "-", ROUND(100*(AP16-AT16)/ABS(AT16), 1)))) -> - | AY16: =IF(AU16="-", "-", IF(AW16="-", "-", IF(ABS(AW16)=0, "-", ROUND(100*(AU16-AW16)/ABS(AW16), 1)))) -> - | AZ16: =IF(AV16="-", "-", IF(AX16="-", "-", IF(ABS(AX16)=0, "-", ROUND(100*(AV16-AX16)/ABS(AX16), 1)))) -> -
C17: 賃借料及び料金 | Q17: =IF(I17="-", "-", IF(M17="-", "-", IF(ABS(M17)=0, "-", ROUND(100*(I17-M17)/ABS(M17), 1)))) -> - | R17: =IF(N17="-", "-", IF(P17="-", "-", IF(ABS(P17)=0, "-", ROUND(100*(N17-P17)/ABS(P17), 1)))) -> - | S17: =IF(O17="-", "-", IF(Q17="-", "-", IF(ABS(Q17)=0, "-", ROUND(100*(O17-Q17)/ABS(Q17), 1)))) -> - | AX17: =IF(AP17="-", "-", IF(AT17="-", "-", IF(ABS(AT17)=0, "-", ROUND(100*(AP17-AT17)/ABS(AT17), 1)))) -> - | AY17: =IF(AU17="-", "-", IF(AW17="-", "-", IF(ABS(AW17)=0, "-", ROUND(100*(AU17-AW17)/ABS(AW17), 1)))) -> - | AZ17: =IF(AV17="-", "-", IF(AX17="-", "-", IF(ABS(AX17)=0, "-", ROUND(100*(AV17-AX17)/ABS(AX17), 1)))) -> -
C18: 物件税及び公課諸負担 | Q18: =IF(I18="-", "-", IF(M18="-", "-", IF(ABS(M18)=0, "-", ROUND(100*(I18-M18)/ABS(M18), 1)))) -> - | R18: =IF(N18="-", "-", IF(P18="-", "-", IF(ABS(P18)=0, "-", ROUND(100*(N18-P18)/ABS(P18), 1)))) -> - | S18: =IF(O18="-", "-", IF(Q18="-", "-", IF(ABS(Q18)=0, "-", ROUND(100*(O18-Q18)/ABS(Q18), 1)))) -> - | AX18: =IF(AP18="-", "-", IF(AT18="-", "-", IF(ABS(AT18)=0, "-", ROUND(100*(AP18-AT18)/ABS(AT18), 1)))) -> - | AY18: =IF(AU18="-", "-", IF(AW18="-", "-", IF(ABS(AW18)=0, "-", ROUND(100*(AU18-AW18)/ABS(AW18), 1)))) -> - | AZ18: =IF(AV18="-", "-", IF(AX18="-", "-", IF(ABS(AX18)=0, "-", ROUND(100*(AV18-AX18)/ABS(AX18), 1)))) -> - | BD18: ５ 農業共済金、各種助成措置の状況 | CG18: 単位：円
C19: 建物費 | Q19: =IF(I19="-", "-", IF(M19="-", "-", IF(ABS(M19)=0, "-", ROUND(100*(I19-M19)/ABS(M19), 1)))) -> - | R19: =IF(N19="-", "-", IF(P19="-", "-", IF(ABS(P19)=0, "-", ROUND(100*(N19-P19)/ABS(P19), 1)))) -> - | S19: =IF(O19="-", "-", IF(Q19="-", "-", IF(ABS(Q19)=0, "-", ROUND(100*(O19-Q19)/ABS(Q19), 1)))) -> - | AM19: =IF(AE19="-", "-", IF(AI19="-", "-", IF(ABS(AI19)=0, "-", ROUND(100*(AE19-AI19)/ABS(AI19), 1)))) -> - | AN19: =IF(AJ19="-", "-", IF(AL19="-", "-", IF(ABS(AL19)=0, "-", ROUND(100*(AJ19-AL19)/ABS(AL19), 1)))) -> - | AO19: =IF(AK19="-", "-", IF(AM19="-", "-", IF(ABS(AM19)=0, "-", ROUND(100*(AK19-AM19)/ABS(AM19), 1)))) -> - | AX19: =IF(AP19="-", "-", IF(AT19="-", "-", IF(ABS(AT19)=0, "-", ROUND(100*(AP19-AT19)/ABS(AT19), 1)))) -> - | AY19: =IF(AU19="-", "-", IF(AW19="-", "-", IF(ABS(AW19)=0, "-", ROUND(100*(AU19-AW19)/ABS(AW19), 1)))) -> - | AZ19: =IF(AV19="-", "-", IF(AX19="-", "-", IF(ABS(AX19)=0, "-", ROUND(100*(AV19-AX19)/ABS(AX19), 1)))) -> - | BL19: 拠出金 | BW19: 受取金
C20: 自動車費 | Q20: =IF(I20="-", "-", IF(M20="-", "-", IF(ABS(M20)=0, "-", ROUND(100*(I20-M20)/ABS(M20), 1)))) -> - | R20: =IF(N20="-", "-", IF(P20="-", "-", IF(ABS(P20)=0, "-", ROUND(100*(N20-P20)/ABS(P20), 1)))) -> - | S20: =IF(O20="-", "-", IF(Q20="-", "-", IF(ABS(Q20)=0, "-", ROUND(100*(O20-Q20)/ABS(Q20), 1)))) -> - | AM20: =IF(AE20="-", "-", IF(AI20="-", "-", IF(ABS(AI20)=0, "-", ROUND(100*(AE20-AI20)/ABS(AI20), 1)))) -> - | AN20: =IF(AJ20="-", "-", IF(AL20="-", "-", IF(ABS(AL20)=0, "-", ROUND(100*(AJ20-AL20)/ABS(AL20), 1)))) -> - | AO20: =IF(AK20="-", "-", IF(AM20="-", "-", IF(ABS(AM20)=0, "-", ROUND(100*(AK20-AM20)/ABS(AM20), 1)))) -> - | AX20: =IF(AP20="-", "-", IF(AT20="-", "-", IF(ABS(AT20)=0, "-", ROUND(100*(AP20-AT20)/ABS(AT20), 1)))) -> - | AY20: =IF(AU20="-", "-", IF(AW20="-", "-", IF(ABS(AW20)=0, "-", ROUND(100*(AU20-AW20)/ABS(AW20), 1)))) -> - | AZ20: =IF(AV20="-", "-", IF(AX20="-", "-", IF(ABS(AX20)=0, "-", ROUND(100*(AV20-AX20)/ABS(AX20), 1)))) -> - | BL20: =IF($B$1<>"",$B$1,"") -> 0 | BP20: =IF($B$1<>"",$B$1-1,"") -> -1 | BT20: 増減率 | BW20: =IF($B$1<>"",$B$1,"") -> 0 | CA20: =IF($B$1<>"",$B$1-1,"") -> -1 | CE20: 増減率
C21: 農機具費 | Q21: =IF(I21="-", "-", IF(M21="-", "-", IF(ABS(M21)=0, "-", ROUND(100*(I21-M21)/ABS(M21), 1)))) -> - | R21: =IF(N21="-", "-", IF(P21="-", "-", IF(ABS(P21)=0, "-", ROUND(100*(N21-P21)/ABS(P21), 1)))) -> - | S21: =IF(O21="-", "-", IF(Q21="-", "-", IF(ABS(Q21)=0, "-", ROUND(100*(O21-Q21)/ABS(Q21), 1)))) -> - | AM21: =IF(AE21="-", "-", IF(AI21="-", "-", IF(ABS(AI21)=0, "-", ROUND(100*(AE21-AI21)/ABS(AI21), 1)))) -> - | AN21: =IF(AJ21="-", "-", IF(AL21="-", "-", IF(ABS(AL21)=0, "-", ROUND(100*(AJ21-AL21)/ABS(AL21), 1)))) -> - | AO21: =IF(AK21="-", "-", IF(AM21="-", "-", IF(ABS(AM21)=0, "-", ROUND(100*(AK21-AM21)/ABS(AM21), 1)))) -> - | AX21: =IF(AP21="-", "-", IF(AT21="-", "-", IF(ABS(AT21)=0, "-", ROUND(100*(AP21-AT21)/ABS(AT21), 1)))) -> - | AY21: =IF(AU21="-", "-", IF(AW21="-", "-", IF(ABS(AW21)=0, "-", ROUND(100*(AU21-AW21)/ABS(AW21), 1)))) -> - | AZ21: =IF(AV21="-", "-", IF(AX21="-", "-", IF(ABS(AX21)=0, "-", ROUND(100*(AV21-AX21)/ABS(AX21), 1)))) -> - | BD21: 農業共済金 | BT21: =IF(BL21="-", "-", IF(BP21="-", "-", IF(ABS(BP21)=0, "-", ROUND(100*(BL21-BP21)/ABS(BP21), 1)))) -> - | BU21: =IF(BQ21="-", "-", IF(BS21="-", "-", IF(ABS(BS21)=0, "-", ROUND(100*(BQ21-BS21)/ABS(BS21), 1)))) -> - | BV21: =IF(BR21="-", "-", IF(BT21="-", "-", IF(ABS(BT21)=0, "-", ROUND(100*(BR21-BT21)/ABS(BT21), 1)))) -> - | CE21: =IF(BW21="-", "-", IF(CA21="-", "-", IF(ABS(CA21)=0, "-", ROUND(100*(BW21-CA21)/ABS(CA21), 1)))) -> - | CF21: =IF(CB21="-", "-", IF(CD21="-", "-", IF(ABS(CD21)=0, "-", ROUND(100*(CB21-CD21)/ABS(CD21), 1)))) -> - | CG21: =IF(CC21="-", "-", IF(CE21="-", "-", IF(ABS(CE21)=0, "-", ROUND(100*(CC21-CE21)/ABS(CE21), 1)))) -> -
C22: 生産管理費 | Q22: =IF(I22="-", "-", IF(M22="-", "-", IF(ABS(M22)=0, "-", ROUND(100*(I22-M22)/ABS(M22), 1)))) -> - | R22: =IF(N22="-", "-", IF(P22="-", "-", IF(ABS(P22)=0, "-", ROUND(100*(N22-P22)/ABS(P22), 1)))) -> - | S22: =IF(O22="-", "-", IF(Q22="-", "-", IF(ABS(Q22)=0, "-", ROUND(100*(O22-Q22)/ABS(Q22), 1)))) -> - | AM22: =IF(AE22="-", "-", IF(AI22="-", "-", IF(ABS(AI22)=0, "-", ROUND(100*(AE22-AI22)/ABS(AI22), 1)))) -> - | AN22: =IF(AJ22="-", "-", IF(AL22="-", "-", IF(ABS(AL22)=0, "-", ROUND(100*(AJ22-AL22)/ABS(AL22), 1)))) -> - | AO22: =IF(AK22="-", "-", IF(AM22="-", "-", IF(ABS(AM22)=0, "-", ROUND(100*(AK22-AM22)/ABS(AM22), 1)))) -> - | AX22: =IF(AP22="-", "-", IF(AT22="-", "-", IF(ABS(AT22)=0, "-", ROUND(100*(AP22-AT22)/ABS(AT22), 1)))) -> - | AY22: =IF(AU22="-", "-", IF(AW22="-", "-", IF(ABS(AW22)=0, "-", ROUND(100*(AU22-AW22)/ABS(AW22), 1)))) -> - | AZ22: =IF(AV22="-", "-", IF(AX22="-", "-", IF(ABS(AX22)=0, "-", ROUND(100*(AV22-AX22)/ABS(AX22), 1)))) -> - | BD22: 畑作物の直接 支払交付金 | BH22: 面積払 | CE22: =IF(BW22="-", "-", IF(CA22="-", "-", IF(ABS(CA22)=0, "-", ROUND(100*(BW22-CA22)/ABS(CA22), 1)))) -> - | CF22: =IF(CB22="-", "-", IF(CD22="-", "-", IF(ABS(CD22)=0, "-", ROUND(100*(CB22-CD22)/ABS(CD22), 1)))) -> - | CG22: =IF(CC22="-", "-", IF(CE22="-", "-", IF(ABS(CE22)=0, "-", ROUND(100*(CC22-CE22)/ABS(CE22), 1)))) -> -
B23: 労働費 | Q23: =IF(I23="-", "-", IF(M23="-", "-", IF(ABS(M23)=0, "-", ROUND(100*(I23-M23)/ABS(M23), 1)))) -> - | R23: =IF(N23="-", "-", IF(P23="-", "-", IF(ABS(P23)=0, "-", ROUND(100*(N23-P23)/ABS(P23), 1)))) -> - | S23: =IF(O23="-", "-", IF(Q23="-", "-", IF(ABS(Q23)=0, "-", ROUND(100*(O23-Q23)/ABS(Q23), 1)))) -> - | AB23: =IF(T23="-", "-", IF(X23="-", "-", IF(ABS(X23)=0, "-", ROUND(100*(T23-X23)/ABS(X23), 1)))) -> - | AC23: =IF(Y23="-", "-", IF(AA23="-", "-", IF(ABS(AA23)=0, "-", ROUND(100*(Y23-AA23)/ABS(AA23), 1)))) -> - | AD23: =IF(Z23="-", "-", IF(AB23="-", "-", IF(ABS(AB23)=0, "-", ROUND(100*(Z23-AB23)/ABS(AB23), 1)))) -> - | AX23: =IF(AP23="-", "-", IF(AT23="-", "-", IF(ABS(AT23)=0, "-", ROUND(100*(AP23-AT23)/ABS(AT23), 1)))) -> - | AY23: =IF(AU23="-", "-", IF(AW23="-", "-", IF(ABS(AW23)=0, "-", ROUND(100*(AU23-AW23)/ABS(AW23), 1)))) -> - | AZ23: =IF(AV23="-", "-", IF(AX23="-", "-", IF(ABS(AX23)=0, "-", ROUND(100*(AV23-AX23)/ABS(AX23), 1)))) -> - | BH23: 数量払 | CE23: =IF(BW23="-", "-", IF(CA23="-", "-", IF(ABS(CA23)=0, "-", ROUND(100*(BW23-CA23)/ABS(CA23), 1)))) -> - | CF23: =IF(CB23="-", "-", IF(CD23="-", "-", IF(ABS(CD23)=0, "-", ROUND(100*(CB23-CD23)/ABS(CD23), 1)))) -> - | CG23: =IF(CC23="-", "-", IF(CE23="-", "-", IF(ABS(CE23)=0, "-", ROUND(100*(CC23-CE23)/ABS(CE23), 1)))) -> -
C24: 直接労働費 | Q24: =IF(I24="-", "-", IF(M24="-", "-", IF(ABS(M24)=0, "-", ROUND(100*(I24-M24)/ABS(M24), 1)))) -> - | R24: =IF(N24="-", "-", IF(P24="-", "-", IF(ABS(P24)=0, "-", ROUND(100*(N24-P24)/ABS(P24), 1)))) -> - | S24: =IF(O24="-", "-", IF(Q24="-", "-", IF(ABS(Q24)=0, "-", ROUND(100*(O24-Q24)/ABS(Q24), 1)))) -> - | AB24: =IF(T24="-", "-", IF(X24="-", "-", IF(ABS(X24)=0, "-", ROUND(100*(T24-X24)/ABS(X24), 1)))) -> - | AC24: =IF(Y24="-", "-", IF(AA24="-", "-", IF(ABS(AA24)=0, "-", ROUND(100*(Y24-AA24)/ABS(AA24), 1)))) -> - | AD24: =IF(Z24="-", "-", IF(AB24="-", "-", IF(ABS(AB24)=0, "-", ROUND(100*(Z24-AB24)/ABS(AB24), 1)))) -> - | AX24: =IF(AP24="-", "-", IF(AT24="-", "-", IF(ABS(AT24)=0, "-", ROUND(100*(AP24-AT24)/ABS(AT24), 1)))) -> - | AY24: =IF(AU24="-", "-", IF(AW24="-", "-", IF(ABS(AW24)=0, "-", ROUND(100*(AU24-AW24)/ABS(AW24), 1)))) -> - | AZ24: =IF(AV24="-", "-", IF(AX24="-", "-", IF(ABS(AX24)=0, "-", ROUND(100*(AV24-AX24)/ABS(AX24), 1)))) -> - | BD24: 水田活用の直接支払交付金 | CE24: =IF(BW24="-", "-", IF(CA24="-", "-", IF(ABS(CA24)=0, "-", ROUND(100*(BW24-CA24)/ABS(CA24), 1)))) -> - | CF24: =IF(CB24="-", "-", IF(CD24="-", "-", IF(ABS(CD24)=0, "-", ROUND(100*(CB24-CD24)/ABS(CD24), 1)))) -> - | CG24: =IF(CC24="-", "-", IF(CE24="-", "-", IF(ABS(CE24)=0, "-", ROUND(100*(CC24-CE24)/ABS(CE24), 1)))) -> -
C25: 間接労働費 | Q25: =IF(I25="-", "-", IF(M25="-", "-", IF(ABS(M25)=0, "-", ROUND(100*(I25-M25)/ABS(M25), 1)))) -> - | R25: =IF(N25="-", "-", IF(P25="-", "-", IF(ABS(P25)=0, "-", ROUND(100*(N25-P25)/ABS(P25), 1)))) -> - | S25: =IF(O25="-", "-", IF(Q25="-", "-", IF(ABS(Q25)=0, "-", ROUND(100*(O25-Q25)/ABS(Q25), 1)))) -> - | AB25: =IF(T25="-", "-", IF(X25="-", "-", IF(ABS(X25)=0, "-", ROUND(100*(T25-X25)/ABS(X25), 1)))) -> - | AC25: =IF(Y25="-", "-", IF(AA25="-", "-", IF(ABS(AA25)=0, "-", ROUND(100*(Y25-AA25)/ABS(AA25), 1)))) -> - | AD25: =IF(Z25="-", "-", IF(AB25="-", "-", IF(ABS(AB25)=0, "-", ROUND(100*(Z25-AB25)/ABS(AB25), 1)))) -> - | AX25: =IF(AP25="-", "-", IF(AT25="-", "-", IF(ABS(AT25)=0, "-", ROUND(100*(AP25-AT25)/ABS(AT25), 1)))) -> - | AY25: =IF(AU25="-", "-", IF(AW25="-", "-", IF(ABS(AW25)=0, "-", ROUND(100*(AU25-AW25)/ABS(AW25), 1)))) -> - | AZ25: =IF(AV25="-", "-", IF(AX25="-", "-", IF(ABS(AX25)=0, "-", ROUND(100*(AV25-AX25)/ABS(AX25), 1)))) -> - | BE25: 戦略作物助成 | CE25: =IF(BW25="-", "-", IF(CA25="-", "-", IF(ABS(CA25)=0, "-", ROUND(100*(BW25-CA25)/ABS(CA25), 1)))) -> - | CF25: =IF(CB25="-", "-", IF(CD25="-", "-", IF(ABS(CD25)=0, "-", ROUND(100*(CB25-CD25)/ABS(CD25), 1)))) -> - | CG25: =IF(CC25="-", "-", IF(CE25="-", "-", IF(ABS(CE25)=0, "-", ROUND(100*(CC25-CE25)/ABS(CE25), 1)))) -> -
B26: 費用合計 | Q26: =IF(I26="-", "-", IF(M26="-", "-", IF(ABS(M26)=0, "-", ROUND(100*(I26-M26)/ABS(M26), 1)))) -> - | R26: =IF(N26="-", "-", IF(P26="-", "-", IF(ABS(P26)=0, "-", ROUND(100*(N26-P26)/ABS(P26), 1)))) -> - | S26: =IF(O26="-", "-", IF(Q26="-", "-", IF(ABS(Q26)=0, "-", ROUND(100*(O26-Q26)/ABS(Q26), 1)))) -> - | AB26: =IF(T26="-", "-", IF(X26="-", "-", IF(ABS(X26)=0, "-", ROUND(100*(T26-X26)/ABS(X26), 1)))) -> - | AC26: =IF(Y26="-", "-", IF(AA26="-", "-", IF(ABS(AA26)=0, "-", ROUND(100*(Y26-AA26)/ABS(AA26), 1)))) -> - | AD26: =IF(Z26="-", "-", IF(AB26="-", "-", IF(ABS(AB26)=0, "-", ROUND(100*(Z26-AB26)/ABS(AB26), 1)))) -> - | AM26: =IF(AE26="-", "-", IF(AI26="-", "-", IF(ABS(AI26)=0, "-", ROUND(100*(AE26-AI26)/ABS(AI26), 1)))) -> - | AN26: =IF(AJ26="-", "-", IF(AL26="-", "-", IF(ABS(AL26)=0, "-", ROUND(100*(AJ26-AL26)/ABS(AL26), 1)))) -> - | AO26: =IF(AK26="-", "-", IF(AM26="-", "-", IF(ABS(AM26)=0, "-", ROUND(100*(AK26-AM26)/ABS(AM26), 1)))) -> - | AX26: =IF(AP26="-", "-", IF(AT26="-", "-", IF(ABS(AT26)=0, "-", ROUND(100*(AP26-AT26)/ABS(AT26), 1)))) -> - | AY26: =IF(AU26="-", "-", IF(AW26="-", "-", IF(ABS(AW26)=0, "-", ROUND(100*(AU26-AW26)/ABS(AW26), 1)))) -> - | AZ26: =IF(AV26="-", "-", IF(AX26="-", "-", IF(ABS(AX26)=0, "-", ROUND(100*(AV26-AX26)/ABS(AX26), 1)))) -> - | BE26: 産地交付金 | CE26: =IF(BW26="-", "-", IF(CA26="-", "-", IF(ABS(CA26)=0, "-", ROUND(100*(BW26-CA26)/ABS(CA26), 1)))) -> - | CF26: =IF(CB26="-", "-", IF(CD26="-", "-", IF(ABS(CD26)=0, "-", ROUND(100*(CB26-CD26)/ABS(CD26), 1)))) -> - | CG26: =IF(CC26="-", "-", IF(CE26="-", "-", IF(ABS(CE26)=0, "-", ROUND(100*(CC26-CE26)/ABS(CE26), 1)))) -> -
B27: 副産物価額 | AX27: =IF(AP27="-", "-", IF(AT27="-", "-", IF(ABS(AT27)=0, "-", ROUND(100*(AP27-AT27)/ABS(AT27), 1)))) -> - | AY27: =IF(AU27="-", "-", IF(AW27="-", "-", IF(ABS(AW27)=0, "-", ROUND(100*(AU27-AW27)/ABS(AW27), 1)))) -> - | AZ27: =IF(AV27="-", "-", IF(AX27="-", "-", IF(ABS(AX27)=0, "-", ROUND(100*(AV27-AX27)/ABS(AX27), 1)))) -> - | BT27: =IF(BL27="-", "-", IF(BP27="-", "-", IF(ABS(BP27)=0, "-", ROUND(100*(BL27-BP27)/ABS(BP27), 1)))) -> - | BU27: =IF(BQ27="-", "-", IF(BS27="-", "-", IF(ABS(BS27)=0, "-", ROUND(100*(BQ27-BS27)/ABS(BS27), 1)))) -> - | BV27: =IF(BR27="-", "-", IF(BT27="-", "-", IF(ABS(BT27)=0, "-", ROUND(100*(BR27-BT27)/ABS(BT27), 1)))) -> - | CE27: =IF(BW27="-", "-", IF(CA27="-", "-", IF(ABS(CA27)=0, "-", ROUND(100*(BW27-CA27)/ABS(CA27), 1)))) -> - | CF27: =IF(CB27="-", "-", IF(CD27="-", "-", IF(ABS(CD27)=0, "-", ROUND(100*(CB27-CD27)/ABS(CD27), 1)))) -> - | CG27: =IF(CC27="-", "-", IF(CE27="-", "-", IF(ABS(CE27)=0, "-", ROUND(100*(CC27-CE27)/ABS(CE27), 1)))) -> -
B28: 生産費 | AX28: =IF(AP28="-", "-", IF(AT28="-", "-", IF(ABS(AT28)=0, "-", ROUND(100*(AP28-AT28)/ABS(AT28), 1)))) -> - | AY28: =IF(AU28="-", "-", IF(AW28="-", "-", IF(ABS(AW28)=0, "-", ROUND(100*(AU28-AW28)/ABS(AW28), 1)))) -> - | AZ28: =IF(AV28="-", "-", IF(AX28="-", "-", IF(ABS(AX28)=0, "-", ROUND(100*(AV28-AX28)/ABS(AX28), 1)))) -> - | BT28: =IF(BL28="-", "-", IF(BP28="-", "-", IF(ABS(BP28)=0, "-", ROUND(100*(BL28-BP28)/ABS(BP28), 1)))) -> - | BU28: =IF(BQ28="-", "-", IF(BS28="-", "-", IF(ABS(BS28)=0, "-", ROUND(100*(BQ28-BS28)/ABS(BS28), 1)))) -> - | BV28: =IF(BR28="-", "-", IF(BT28="-", "-", IF(ABS(BT28)=0, "-", ROUND(100*(BR28-BT28)/ABS(BT28), 1)))) -> - | CE28: =IF(BW28="-", "-", IF(CA28="-", "-", IF(ABS(CA28)=0, "-", ROUND(100*(BW28-CA28)/ABS(CA28), 1)))) -> - | CF28: =IF(CB28="-", "-", IF(CD28="-", "-", IF(ABS(CD28)=0, "-", ROUND(100*(CB28-CD28)/ABS(CD28), 1)))) -> - | CG28: =IF(CC28="-", "-", IF(CE28="-", "-", IF(ABS(CE28)=0, "-", ROUND(100*(CC28-CE28)/ABS(CE28), 1)))) -> -
B29: 支払利子 | AX29: =IF(AP29="-", "-", IF(AT29="-", "-", IF(ABS(AT29)=0, "-", ROUND(100*(AP29-AT29)/ABS(AT29), 1)))) -> - | AY29: =IF(AU29="-", "-", IF(AW29="-", "-", IF(ABS(AW29)=0, "-", ROUND(100*(AU29-AW29)/ABS(AW29), 1)))) -> - | AZ29: =IF(AV29="-", "-", IF(AX29="-", "-", IF(ABS(AX29)=0, "-", ROUND(100*(AV29-AX29)/ABS(AX29), 1)))) -> - | BT29: =IF(BL29="-", "-", IF(BP29="-", "-", IF(ABS(BP29)=0, "-", ROUND(100*(BL29-BP29)/ABS(BP29), 1)))) -> - | BU29: =IF(BQ29="-", "-", IF(BS29="-", "-", IF(ABS(BS29)=0, "-", ROUND(100*(BQ29-BS29)/ABS(BS29), 1)))) -> - | BV29: =IF(BR29="-", "-", IF(BT29="-", "-", IF(ABS(BT29)=0, "-", ROUND(100*(BR29-BT29)/ABS(BT29), 1)))) -> - | CE29: =IF(BW29="-", "-", IF(CA29="-", "-", IF(ABS(CA29)=0, "-", ROUND(100*(BW29-CA29)/ABS(CA29), 1)))) -> - | CF29: =IF(CB29="-", "-", IF(CD29="-", "-", IF(ABS(CD29)=0, "-", ROUND(100*(CB29-CD29)/ABS(CD29), 1)))) -> - | CG29: =IF(CC29="-", "-", IF(CE29="-", "-", IF(ABS(CE29)=0, "-", ROUND(100*(CC29-CE29)/ABS(CE29), 1)))) -> -
B30: 支払地代 | AX30: =IF(AP30="-", "-", IF(AT30="-", "-", IF(ABS(AT30)=0, "-", ROUND(100*(AP30-AT30)/ABS(AT30), 1)))) -> - | AY30: =IF(AU30="-", "-", IF(AW30="-", "-", IF(ABS(AW30)=0, "-", ROUND(100*(AU30-AW30)/ABS(AW30), 1)))) -> - | AZ30: =IF(AV30="-", "-", IF(AX30="-", "-", IF(ABS(AX30)=0, "-", ROUND(100*(AV30-AX30)/ABS(AX30), 1)))) -> -
B31: 利子・地代算入生産費 | AX31: =IF(AP31="-", "-", IF(AT31="-", "-", IF(ABS(AT31)=0, "-", ROUND(100*(AP31-AT31)/ABS(AT31), 1)))) -> - | AY31: =IF(AU31="-", "-", IF(AW31="-", "-", IF(ABS(AW31)=0, "-", ROUND(100*(AU31-AW31)/ABS(AW31), 1)))) -> - | AZ31: =IF(AV31="-", "-", IF(AX31="-", "-", IF(ABS(AX31)=0, "-", ROUND(100*(AV31-AX31)/ABS(AX31), 1)))) -> -
B32: 自己資本利子 | AX32: =IF(AP32="-", "-", IF(AT32="-", "-", IF(ABS(AT32)=0, "-", ROUND(100*(AP32-AT32)/ABS(AT32), 1)))) -> - | AY32: =IF(AU32="-", "-", IF(AW32="-", "-", IF(ABS(AW32)=0, "-", ROUND(100*(AU32-AW32)/ABS(AW32), 1)))) -> - | AZ32: =IF(AV32="-", "-", IF(AX32="-", "-", IF(ABS(AX32)=0, "-", ROUND(100*(AV32-AX32)/ABS(AX32), 1)))) -> -
B33: 自作地地代 | AX33: =IF(AP33="-", "-", IF(AT33="-", "-", IF(ABS(AT33)=0, "-", ROUND(100*(AP33-AT33)/ABS(AT33), 1)))) -> - | AY33: =IF(AU33="-", "-", IF(AW33="-", "-", IF(ABS(AW33)=0, "-", ROUND(100*(AU33-AW33)/ABS(AW33), 1)))) -> - | AZ33: =IF(AV33="-", "-", IF(AX33="-", "-", IF(ABS(AX33)=0, "-", ROUND(100*(AV33-AX33)/ABS(AX33), 1)))) -> -
B34: 全算入生産費 | AX34: =IF(AP34="-", "-", IF(AT34="-", "-", IF(ABS(AT34)=0, "-", ROUND(100*(AP34-AT34)/ABS(AT34), 1)))) -> - | AY34: =IF(AU34="-", "-", IF(AW34="-", "-", IF(ABS(AW34)=0, "-", ROUND(100*(AU34-AW34)/ABS(AW34), 1)))) -> - | AZ34: =IF(AV34="-", "-", IF(AX34="-", "-", IF(ABS(AX34)=0, "-", ROUND(100*(AV34-AX34)/ABS(AX34), 1)))) -> -
B37: ２ 資本額及び資本利子 | AD37: 単位：円 | BD37: ６ 収益性 | BV37: 単位：円
I38: 資本額 | T38: 利子額 | BL38: =IF($B$1<>"",$B$1,"") -> 0 | BP38: =IF($B$1<>"",$B$1-1,"") -> -1 | BT38: 増減率
I39: =IF($B$1<>"",$B$1,"") -> 0 | M39: =IF($B$1<>"",$B$1-1,"") -> -1 | Q39: 増減率 | T39: =IF($B$1<>"",$B$1,"") -> 0 | X39: =IF($B$1<>"",$B$1-1,"") -> -1 | AB39: 増減率 | BD39: 粗収益 | BT39: =IF(BL39="-", "-", IF(BP39="-", "-", IF(ABS(BP39)=0, "-", ROUND(100*(BL39-BP39)/ABS(BP39), 1)))) -> - | BU39: =IF(BQ39="-", "-", IF(BS39="-", "-", IF(ABS(BS39)=0, "-", ROUND(100*(BQ39-BS39)/ABS(BS39), 1)))) -> - | BV39: =IF(BR39="-", "-", IF(BT39="-", "-", IF(ABS(BT39)=0, "-", ROUND(100*(BR39-BT39)/ABS(BT39), 1)))) -> -
B40: 資本額 | Q40: =IF(I40="-", "-", IF(M40="-", "-", IF(ABS(M40)=0, "-", ROUND(100*(I40-M40)/ABS(M40), 1)))) -> - | R40: =IF(N40="-", "-", IF(P40="-", "-", IF(ABS(P40)=0, "-", ROUND(100*(N40-P40)/ABS(P40), 1)))) -> - | S40: =IF(O40="-", "-", IF(Q40="-", "-", IF(ABS(Q40)=0, "-", ROUND(100*(O40-Q40)/ABS(Q40), 1)))) -> - | AB40: =IF(T40="-", "-", IF(X40="-", "-", IF(ABS(X40)=0, "-", ROUND(100*(T40-X40)/ABS(X40), 1)))) -> - | AC40: =IF(Y40="-", "-", IF(AA40="-", "-", IF(ABS(AA40)=0, "-", ROUND(100*(Y40-AA40)/ABS(AA40), 1)))) -> - | AD40: =IF(Z40="-", "-", IF(AB40="-", "-", IF(ABS(AB40)=0, "-", ROUND(100*(Z40-AB40)/ABS(AB40), 1)))) -> - | BD40: 生産費総額 | BT40: =IF(BL40="-", "-", IF(BP40="-", "-", IF(ABS(BP40)=0, "-", ROUND(100*(BL40-BP40)/ABS(BP40), 1)))) -> - | BU40: =IF(BQ40="-", "-", IF(BS40="-", "-", IF(ABS(BS40)=0, "-", ROUND(100*(BQ40-BS40)/ABS(BS40), 1)))) -> - | BV40: =IF(BR40="-", "-", IF(BT40="-", "-", IF(ABS(BT40)=0, "-", ROUND(100*(BR40-BT40)/ABS(BT40), 1)))) -> -
C41: 借入資本 | Q41: =IF(I41="-", "-", IF(M41="-", "-", IF(ABS(M41)=0, "-", ROUND(100*(I41-M41)/ABS(M41), 1)))) -> - | R41: =IF(N41="-", "-", IF(P41="-", "-", IF(ABS(P41)=0, "-", ROUND(100*(N41-P41)/ABS(P41), 1)))) -> - | S41: =IF(O41="-", "-", IF(Q41="-", "-", IF(ABS(Q41)=0, "-", ROUND(100*(O41-Q41)/ABS(Q41), 1)))) -> - | AB41: =IF(T41="-", "-", IF(X41="-", "-", IF(ABS(X41)=0, "-", ROUND(100*(T41-X41)/ABS(X41), 1)))) -> - | AC41: =IF(Y41="-", "-", IF(AA41="-", "-", IF(ABS(AA41)=0, "-", ROUND(100*(Y41-AA41)/ABS(AA41), 1)))) -> - | AD41: =IF(Z41="-", "-", IF(AB41="-", "-", IF(ABS(AB41)=0, "-", ROUND(100*(Z41-AB41)/ABS(AB41), 1)))) -> - | BD41: 利潤 | BT41: =IF(BL41="-", "-", IF(BP41="-", "-", IF(ABS(BP41)=0, "-", ROUND(100*(BL41-BP41)/ABS(BP41), 1)))) -> - | BU41: =IF(BQ41="-", "-", IF(BS41="-", "-", IF(ABS(BS41)=0, "-", ROUND(100*(BQ41-BS41)/ABS(BS41), 1)))) -> - | BV41: =IF(BR41="-", "-", IF(BT41="-", "-", IF(ABS(BT41)=0, "-", ROUND(100*(BR41-BT41)/ABS(BT41), 1)))) -> -
C42: 自己資本 | Q42: =IF(I42="-", "-", IF(M42="-", "-", IF(ABS(M42)=0, "-", ROUND(100*(I42-M42)/ABS(M42), 1)))) -> - | R42: =IF(N42="-", "-", IF(P42="-", "-", IF(ABS(P42)=0, "-", ROUND(100*(N42-P42)/ABS(P42), 1)))) -> - | S42: =IF(O42="-", "-", IF(Q42="-", "-", IF(ABS(Q42)=0, "-", ROUND(100*(O42-Q42)/ABS(Q42), 1)))) -> - | AB42: =IF(T42="-", "-", IF(X42="-", "-", IF(ABS(X42)=0, "-", ROUND(100*(T42-X42)/ABS(X42), 1)))) -> - | AC42: =IF(Y42="-", "-", IF(AA42="-", "-", IF(ABS(AA42)=0, "-", ROUND(100*(Y42-AA42)/ABS(AA42), 1)))) -> - | AD42: =IF(Z42="-", "-", IF(AB42="-", "-", IF(ABS(AB42)=0, "-", ROUND(100*(Z42-AB42)/ABS(AB42), 1)))) -> - | BD42: 所得 | BT42: =IF(BL42="-", "-", IF(BP42="-", "-", IF(ABS(BP42)=0, "-", ROUND(100*(BL42-BP42)/ABS(BP42), 1)))) -> - | BU42: =IF(BQ42="-", "-", IF(BS42="-", "-", IF(ABS(BS42)=0, "-", ROUND(100*(BQ42-BS42)/ABS(BS42), 1)))) -> - | BV42: =IF(BR42="-", "-", IF(BT42="-", "-", IF(ABS(BT42)=0, "-", ROUND(100*(BR42-BT42)/ABS(BT42), 1)))) -> -
B43: 資産別内訳 | C43: 流動資本 | Q43: =IF(I43="-", "-", IF(M43="-", "-", IF(ABS(M43)=0, "-", ROUND(100*(I43-M43)/ABS(M43), 1)))) -> - | R43: =IF(N43="-", "-", IF(P43="-", "-", IF(ABS(P43)=0, "-", ROUND(100*(N43-P43)/ABS(P43), 1)))) -> - | S43: =IF(O43="-", "-", IF(Q43="-", "-", IF(ABS(Q43)=0, "-", ROUND(100*(O43-Q43)/ABS(Q43), 1)))) -> - | BE43: １日当たり | BT43: =IF(BL43="-", "-", IF(BP43="-", "-", IF(ABS(BP43)=0, "-", ROUND(100*(BL43-BP43)/ABS(BP43), 1)))) -> - | BU43: =IF(BQ43="-", "-", IF(BS43="-", "-", IF(ABS(BS43)=0, "-", ROUND(100*(BQ43-BS43)/ABS(BS43), 1)))) -> - | BV43: =IF(BR43="-", "-", IF(BT43="-", "-", IF(ABS(BT43)=0, "-", ROUND(100*(BR43-BT43)/ABS(BT43), 1)))) -> -
C44: 労賃資本 | Q44: =IF(I44="-", "-", IF(M44="-", "-", IF(ABS(M44)=0, "-", ROUND(100*(I44-M44)/ABS(M44), 1)))) -> - | R44: =IF(N44="-", "-", IF(P44="-", "-", IF(ABS(P44)=0, "-", ROUND(100*(N44-P44)/ABS(P44), 1)))) -> - | S44: =IF(O44="-", "-", IF(Q44="-", "-", IF(ABS(Q44)=0, "-", ROUND(100*(O44-Q44)/ABS(Q44), 1)))) -> - | BD44: 構成員労働報酬 | BT44: =IF(BL44="-", "-", IF(BP44="-", "-", IF(ABS(BP44)=0, "-", ROUND(100*(BL44-BP44)/ABS(BP44), 1)))) -> - | BU44: =IF(BQ44="-", "-", IF(BS44="-", "-", IF(ABS(BS44)=0, "-", ROUND(100*(BQ44-BS44)/ABS(BS44), 1)))) -> - | BV44: =IF(BR44="-", "-", IF(BT44="-", "-", IF(ABS(BT44)=0, "-", ROUND(100*(BR44-BT44)/ABS(BT44), 1)))) -> -
...

Sheet No.2
B1: =AB4 | E1: 年産 組織法人経営体に関する経営分析調査（麦類・そば・なたね・畑作物生産費（組織法人経営）） 集計結果検討表 Ｎｏ．２
G3: 集計番号 | J3: 集計名称 | Q3: 集計経営体数 | V3: 集計倍率 | AB3: 調査年 | AG3: 都道府県等 | AL3: 経営種類 | AQ3: 生産費区分 | AV3: 規模階層 | BA3: 平均値種類 | BF3: 加重・総和の別 | BK3: 集計区分 | BP3: 田畑区分 | BU3: ビール麦販売区分 | BZ3: てんさい栽培区分
B4: 本年産 | G4: =IF(No.1!G4="","",No.1!G4) | H4: =IF(No.1!H4="","",No.1!H4) | I4: =IF(No.1!I4="","",No.1!I4) | J4: =IF(No.1!J4="","",No.1!J4) | K4: =IF(No.1!K4="","",No.1!K4) | L4: =IF(No.1!L4="","",No.1!L4) | M4: =IF(No.1!M4="","",No.1!M4) | N4: =IF(No.1!N4="","",No.1!N4) | ... Z4: =IF(No.1!Z4="","",No.1!Z4) | AB4: =IF(No.1!AB4="","",No.1!AB4) | AC4: =IF(No.1!AC4="","",No.1!AC4) | AD4: =IF(No.1!AD4="","",No.1!AD4) | AE4: =IF(No.1!AE4="","",No.1!AE4) | AF4: =IF(No.1!AF4="","",No.1!AF4) | AG4: =IF(No.1!AG4="","",No.1!AG4) | AH4: =IF(No.1!AH4="","",No.1!AH4) | AI4: =IF(No.1!AI4="","",No.1!AI4) | ... CD4: =IF(No.1!CD4="","",No.1!CD4)
B5: 前年産 | G5: =IF(No.1!G5="","",No.1!G5) | H5: =IF(No.1!H5="","",No.1!H5) | I5: =IF(No.1!I5="","",No.1!I5) | J5: =IF(No.1!J5="","",No.1!J5) | K5: =IF(No.1!K5="","",No.1!K5) | L5: =IF(No.1!L5="","",No.1!L5) | M5: =IF(No.1!M5="","",No.1!M5) | N5: =IF(No.1!N5="","",No.1!N5) | ... Z5: =IF(No.1!Z5="","",No.1!Z5)
B7: ７ 経営耕地（１経営体当たり） | AO7: 単位：ａ | AT7: 14 地 代（面積は１経営体当たり） | CG7: 単位：円、ａ
I8: 所有地 | T8: 借入地 | AE8: 計 | BA8: 自作地 | BL8: 借入地 | BW8: 計
I9: =IF($B$1<>"",$B$1,"") | M9: =IF($B$1<>"",$B$1-1,"") | Q9: 増減率 | T9: =IF($B$1<>"",$B$1,"") | X9: =IF($B$1<>"",$B$1-1,"") | AB9: 増減率 | AE9: =IF($B$1<>"",$B$1,"") | AI9: =IF($B$1<>"",$B$1-1,"") | AM9: 増減率 | BA9: =IF($B$1<>"",$B$1,"") | BE9: =IF($B$1<>"",$B$1-1,"") | BI9: 増減率 | BL9: =IF($B$1<>"",$B$1,"") | BP9: =IF($B$1<>"",$B$1-1,"") | BT9: 増減率 | BW9: =IF($B$1<>"",$B$1,"") | CA9: =IF($B$1<>"",$B$1-1,"") | CE9: 増減率
B10: 田 | Q10: =IF(I10="-", "-", IF(M10="-", "-", IF(ABS(M10)=0, "-", ROUND(100*(I10-M10)/ABS(M10), 1)))) -> - | R10: =IF(N10="-", "-", IF(P10="-", "-", IF(ABS(P10)=0, "-", ROUND(100*(N10-P10)/ABS(P10), 1)))) -> - | S10: =IF(O10="-", "-", IF(Q10="-", "-", IF(ABS(Q10)=0, "-", ROUND(100*(O10-Q10)/ABS(Q10), 1)))) -> - | AB10: =IF(T10="-", "-", IF(X10="-", "-", IF(ABS(X10)=0, "-", ROUND(100*(T10-X10)/ABS(X10), 1)))) -> - | AC10: =IF(Y10="-", "-", IF(AA10="-", "-", IF(ABS(AA10)=0, "-", ROUND(100*(Y10-AA10)/ABS(AA10), 1)))) -> - | AD10: =IF(Z10="-", "-", IF(AB10="-", "-", IF(ABS(AB10)=0, "-", ROUND(100*(Z10-AB10)/ABS(AB10), 1)))) -> - | AM10: =IF(AE10="-", "-", IF(AI10="-", "-", IF(ABS(AI10)=0, "-", ROUND(100*(AE10-AI10)/ABS(AI10), 1)))) -> - | AN10: =IF(AJ10="-", "-", IF(AL10="-", "-", IF(ABS(AL10)=0, "-", ROUND(100*(AJ10-AL10)/ABS(AL10), 1)))) -> - | AO10: =IF(AK10="-", "-", IF(AM10="-", "-", IF(ABS(AM10)=0, "-", ROUND(100*(AK10-AM10)/ABS(AM10), 1)))) -> - | AT10: 作付地 | AV10: 作付実面積 | BI10: =IF(BA10="-", "-", IF(BE10="-", "-", IF(ABS(BE10)=0, "-", ROUND(100*(BA10-BE10)/ABS(BE10), 1)))) -> - | BJ10: =IF(BF10="-", "-", IF(BH10="-", "-", IF(ABS(BH10)=0, "-", ROUND(100*(BF10-BH10)/ABS(BH10), 1)))) -> - | BK10: =IF(BG10="-", "-", IF(BI10="-", "-", IF(ABS(BI10)=0, "-", ROUND(100*(BG10-BI10)/ABS(BI10), 1)))) -> - | BT10: =IF(BL10="-", "-", IF(BP10="-", "-", IF(ABS(BP10)=0, "-", ROUND(100*(BL10-BP10)/ABS(BP10), 1)))) -> - | BU10: =IF(BQ10="-", "-", IF(BS10="-", "-", IF(ABS(BS10)=0, "-", ROUND(100*(BQ10-BS10)/ABS(BS10), 1)))) -> - | BV10: =IF(BR10="-", "-", IF(BT10="-", "-", IF(ABS(BT10)=0, "-", ROUND(100*(BR10-BT10)/ABS(BT10), 1)))) -> - | CE10: =IF(BW10="-", "-", IF(CA10="-", "-", IF(ABS(CA10)=0, "-", ROUND(100*(BW10-CA10)/ABS(CA10), 1)))) -> - | CF10: =IF(CB10="-", "-", IF(CD10="-", "-", IF(ABS(CD10)=0, "-", ROUND(100*(CB10-CD10)/ABS(CD10), 1)))) -> - | CG10: =IF(CC10="-", "-", IF(CE10="-", "-", IF(ABS(CE10)=0, "-", ROUND(100*(CC10-CE10)/ABS(CE10), 1)))) -> -
B11: 普通畑 | Q11: =IF(I11="-", "-", IF(M11="-", "-", IF(ABS(M11)=0, "-", ROUND(100*(I11-M11)/ABS(M11), 1)))) -> - | R11: =IF(N11="-", "-", IF(P11="-", "-", IF(ABS(P11)=0, "-", ROUND(100*(N11-P11)/ABS(P11), 1)))) -> - | S11: =IF(O11="-", "-", IF(Q11="-", "-", IF(ABS(Q11)=0, "-", ROUND(100*(O11-Q11)/ABS(Q11), 1)))) -> - | AB11: =IF(T11="-", "-", IF(X11="-", "-", IF(ABS(X11)=0, "-", ROUND(100*(T11-X11)/ABS(X11), 1)))) -> - | AC11: =IF(Y11="-", "-", IF(AA11="-", "-", IF(ABS(AA11)=0, "-", ROUND(100*(Y11-AA11)/ABS(AA11), 1)))) -> - | AD11: =IF(Z11="-", "-", IF(AB11="-", "-", IF(ABS(AB11)=0, "-", ROUND(100*(Z11-AB11)/ABS(AB11), 1)))) -> - | AM11: =IF(AE11="-", "-", IF(AI11="-", "-", IF(ABS(AI11)=0, "-", ROUND(100*(AE11-AI11)/ABS(AI11), 1)))) -> - | AN11: =IF(AJ11="-", "-", IF(AL11="-", "-", IF(ABS(AL11)=0, "-", ROUND(100*(AJ11-AL11)/ABS(AL11), 1)))) -> - | AO11: =IF(AK11="-", "-", IF(AM11="-", "-", IF(ABS(AM11)=0, "-", ROUND(100*(AK11-AM11)/ABS(AM11), 1)))) -> - | AV11: 土地台帳面積 | BI11: =IF(BA11="-", "-", IF(BE11="-", "-", IF(ABS(BE11)=0, "-", ROUND(100*(BA11-BE11)/ABS(BE11), 1)))) -> - | BJ11: =IF(BF11="-", "-", IF(BH11="-", "-", IF(ABS(BH11)=0, "-", ROUND(100*(BF11-BH11)/ABS(BH11), 1)))) -> - | BK11: =IF(BG11="-", "-", IF(BI11="-", "-", IF(ABS(BI11)=0, "-", ROUND(100*(BG11-BI11)/ABS(BI11), 1)))) -> - | BT11: =IF(BL11="-", "-", IF(BP11="-", "-", IF(ABS(BP11)=0, "-", ROUND(100*(BL11-BP11)/ABS(BP11), 1)))) -> - | BU11: =IF(BQ11="-", "-", IF(BS11="-", "-", IF(ABS(BS11)=0, "-", ROUND(100*(BQ11-BS11)/ABS(BS11), 1)))) -> - | BV11: =IF(BR11="-", "-", IF(BT11="-", "-", IF(ABS(BT11)=0, "-", ROUND(100*(BR11-BT11)/ABS(BT11), 1)))) -> - | CE11: =IF(BW11="-", "-", IF(CA11="-", "-", IF(ABS(CA11)=0, "-", ROUND(100*(BW11-CA11)/ABS(CA11), 1)))) -> - | CF11: =IF(CB11="-", "-", IF(CD11="-", "-", IF(ABS(CD11)=0, "-", ROUND(100*(CB11-CD11)/ABS(CD11), 1)))) -> - | CG11: =IF(CC11="-", "-", IF(CE11="-", "-", IF(ABS(CE11)=0, "-", ROUND(100*(CC11-CE11)/ABS(CE11), 1)))) -> -
B12: 樹園地 | Q12: =IF(I12="-", "-", IF(M12="-", "-", IF(ABS(M12)=0, "-", ROUND(100*(I12-M12)/ABS(M12), 1)))) -> - | R12: =IF(N12="-", "-", IF(P12="-", "-", IF(ABS(P12)=0, "-", ROUND(100*(N12-P12)/ABS(P12), 1)))) -> - | S12: =IF(O12="-", "-", IF(Q12="-", "-", IF(ABS(Q12)=0, "-", ROUND(100*(O12-Q12)/ABS(Q12), 1)))) -> - | AB12: =IF(T12="-", "-", IF(X12="-", "-", IF(ABS(X12)=0, "-", ROUND(100*(T12-X12)/ABS(X12), 1)))) -> - | AC12: =IF(Y12="-", "-", IF(AA12="-", "-", IF(ABS(AA12)=0, "-", ROUND(100*(Y12-AA12)/ABS(AA12), 1)))) -> - | AD12: =IF(Z12="-", "-", IF(AB12="-", "-", IF(ABS(AB12)=0, "-", ROUND(100*(Z12-AB12)/ABS(AB12), 1)))) -> - | AM12: =IF(AE12="-", "-", IF(AI12="-", "-", IF(ABS(AI12)=0, "-", ROUND(100*(AE12-AI12)/ABS(AI12), 1)))) -> - | AN12: =IF(AJ12="-", "-", IF(AL12="-", "-", IF(ABS(AL12)=0, "-", ROUND(100*(AJ12-AL12)/ABS(AL12), 1)))) -> - | AO12: =IF(AK12="-", "-", IF(AM12="-", "-", IF(ABS(AM12)=0, "-", ROUND(100*(AK12-AM12)/ABS(AM12), 1)))) -> - | AV12: 地代総額 | BI12: =IF(BA12="-", "-", IF(BE12="-", "-", IF(ABS(BE12)=0, "-", ROUND(100*(BA12-BE12)/ABS(BE12), 1)))) -> - | BJ12: =IF(BF12="-", "-", IF(BH12="-", "-", IF(ABS(BH12)=0, "-", ROUND(100*(BF12-BH12)/ABS(BH12), 1)))) -> - | BK12: =IF(BG12="-", "-", IF(BI12="-", "-", IF(ABS(BI12)=0, "-", ROUND(100*(BG12-BI12)/ABS(BI12), 1)))) -> - | BT12: =IF(BL12="-", "-", IF(BP12="-", "-", IF(ABS(BP12)=0, "-", ROUND(100*(BL12-BP12)/ABS(BP12), 1)))) -> - | BU12: =IF(BQ12="-", "-", IF(BS12="-", "-", IF(ABS(BS12)=0, "-", ROUND(100*(BQ12-BS12)/ABS(BS12), 1)))) -> - | BV12: =IF(BR12="-", "-", IF(BT12="-", "-", IF(ABS(BT12)=0, "-", ROUND(100*(BR12-BT12)/ABS(BT12), 1)))) -> - | CE12: =IF(BW12="-", "-", IF(CA12="-", "-", IF(ABS(CA12)=0, "-", ROUND(100*(BW12-CA12)/ABS(CA12), 1)))) -> - | CF12: =IF(CB12="-", "-", IF(CD12="-", "-", IF(ABS(CD12)=0, "-", ROUND(100*(CB12-CD12)/ABS(CD12), 1)))) -> - | CG12: =IF(CC12="-", "-", IF(CE12="-", "-", IF(ABS(CE12)=0, "-", ROUND(100*(CC12-CE12)/ABS(CE12), 1)))) -> -
B13: 牧草地 | Q13: =IF(I13="-", "-", IF(M13="-", "-", IF(ABS(M13)=0, "-", ROUND(100*(I13-M13)/ABS(M13), 1)))) -> - | AB13: =IF(T13="-", "-", IF(X13="-", "-", IF(ABS(X13)=0, "-", ROUND(100*(T13-X13)/ABS(X13), 1)))) -> - | AM13: =IF(AE13="-", "-", IF(AI13="-", "-", IF(ABS(AI13)=0, "-", ROUND(100*(AE13-AI13)/ABS(AI13), 1)))) -> - | AV13: 負担地代 | BI13: =IF(BA13="-", "-", IF(BE13="-", "-", IF(ABS(BE13)=0, "-", ROUND(100*(BA13-BE13)/ABS(BE13), 1)))) -> - | BJ13: =IF(BF13="-", "-", IF(BH13="-", "-", IF(ABS(BH13)=0, "-", ROUND(100*(BF13-BH13)/ABS(BH13), 1)))) -> - | BK13: =IF(BG13="-", "-", IF(BI13="-", "-", IF(ABS(BI13)=0, "-", ROUND(100*(BG13-BI13)/ABS(BI13), 1)))) -> - | BT13: =IF(BL13="-", "-", IF(BP13="-", "-", IF(ABS(BP13)=0, "-", ROUND(100*(BL13-BP13)/ABS(BP13), 1)))) -> - | BU13: =IF(BQ13="-", "-", IF(BS13="-", "-", IF(ABS(BS13)=0, "-", ROUND(100*(BQ13-BS13)/ABS(BS13), 1)))) -> - | BV13: =IF(BR13="-", "-", IF(BT13="-", "-", IF(ABS(BT13)=0, "-", ROUND(100*(BR13-BT13)/ABS(BT13), 1)))) -> - | CE13: =IF(BW13="-", "-", IF(CA13="-", "-", IF(ABS(CA13)=0, "-", ROUND(100*(BW13-CA13)/ABS(CA13), 1)))) -> - | CF13: =IF(CB13="-", "-", IF(CD13="-", "-", IF(ABS(CD13)=0, "-", ROUND(100*(CB13-CD13)/ABS(CD13), 1)))) -> - | CG13: =IF(CC13="-", "-", IF(CE13="-", "-", IF(ABS(CE13)=0, "-", ROUND(100*(CC13-CE13)/ABS(CE13), 1)))) -> -
B14: 計 | Q14: =IF(I14="-", "-", IF(M14="-", "-", IF(ABS(M14)=0, "-", ROUND(100*(I14-M14)/ABS(M14), 1)))) -> - | R14: =IF(N14="-", "-", IF(P14="-", "-", IF(ABS(P14)=0, "-", ROUND(100*(N14-P14)/ABS(P14), 1)))) -> - | S14: =IF(O14="-", "-", IF(Q14="-", "-", IF(ABS(Q14)=0, "-", ROUND(100*(O14-Q14)/ABS(Q14), 1)))) -> - | AB14: =IF(T14="-", "-", IF(X14="-", "-", IF(ABS(X14)=0, "-", ROUND(100*(T14-X14)/ABS(X14), 1)))) -> - | AC14: =IF(Y14="-", "-", IF(AA14="-", "-", IF(ABS(AA14)=0, "-", ROUND(100*(Y14-AA14)/ABS(AA14), 1)))) -> - | AD14: =IF(Z14="-", "-", IF(AB14="-", "-", IF(ABS(AB14)=0, "-", ROUND(100*(Z14-AB14)/ABS(AB14), 1)))) -> - | AM14: =IF(AE14="-", "-", IF(AI14="-", "-", IF(ABS(AI14)=0, "-", ROUND(100*(AE14-AI14)/ABS(AI14), 1)))) -> - | AN14: =IF(AJ14="-", "-", IF(AL14="-", "-", IF(ABS(AL14)=0, "-", ROUND(100*(AJ14-AL14)/ABS(AL14), 1)))) -> - | AO14: =IF(AK14="-", "-", IF(AM14="-", "-", IF(ABS(AM14)=0, "-", ROUND(100*(AK14-AM14)/ABS(AM14), 1)))) -> - | AT14: 以 外作付地 | AV14: 使用面積 | BI14: =IF(BA14="-", "-", IF(BE14="-", "-", IF(ABS(BE14)=0, "-", ROUND(100*(BA14-BE14)/ABS(BE14), 1)))) -> - | BJ14: =IF(BF14="-", "-", IF(BH14="-", "-", IF(ABS(BH14)=0, "-", ROUND(100*(BF14-BH14)/ABS(BH14), 1)))) -> - | BK14: =IF(BG14="-", "-", IF(BI14="-", "-", IF(ABS(BI14)=0, "-", ROUND(100*(BG14-BI14)/ABS(BI14), 1)))) -> - | BT14: =IF(BL14="-", "-", IF(BP14="-", "-", IF(ABS(BP14)=0, "-", ROUND(100*(BL14-BP14)/ABS(BP14), 1)))) -> - | BU14: =IF(BQ14="-", "-", IF(BS14="-", "-", IF(ABS(BS14)=0, "-", ROUND(100*(BQ14-BS14)/ABS(BS14), 1)))) -> - | BV14: =IF(BR14="-", "-", IF(BT14="-", "-", IF(ABS(BT14)=0, "-", ROUND(100*(BR14-BT14)/ABS(BT14), 1)))) -> - | CE14: =IF(BW14="-", "-", IF(CA14="-", "-", IF(ABS(CA14)=0, "-", ROUND(100*(BW14-CA14)/ABS(CA14), 1)))) -> - | CF14: =IF(CB14="-", "-", IF(CD14="-", "-", IF(ABS(CD14)=0, "-", ROUND(100*(CB14-CD14)/ABS(CD14), 1)))) -> - | CG14: =IF(CC14="-", "-", IF(CE14="-", "-", IF(ABS(CE14)=0, "-", ROUND(100*(CC14-CE14)/ABS(CE14), 1)))) -> -
AV15: 賃借料総額 | BI15: =IF(BA15="-", "-", IF(BE15="-", "-", IF(ABS(BE15)=0, "-", ROUND(100*(BA15-BE15)/ABS(BE15), 1)))) -> - | BJ15: =IF(BF15="-", "-", IF(BH15="-", "-", IF(ABS(BH15)=0, "-", ROUND(100*(BF15-BH15)/ABS(BH15), 1)))) -> - | BK15: =IF(BG15="-", "-", IF(BI15="-", "-", IF(ABS(BI15)=0, "-", ROUND(100*(BG15-BI15)/ABS(BI15), 1)))) -> - | BT15: =IF(BL15="-", "-", IF(BP15="-", "-", IF(ABS(BP15)=0, "-", ROUND(100*(BL15-BP15)/ABS(BP15), 1)))) -> - | BU15: =IF(BQ15="-", "-", IF(BS15="-", "-", IF(ABS(BS15)=0, "-", ROUND(100*(BQ15-BS15)/ABS(BS15), 1)))) -> - | BV15: =IF(BR15="-", "-", IF(BT15="-", "-", IF(ABS(BT15)=0, "-", ROUND(100*(BR15-BT15)/ABS(BT15), 1)))) -> - | CE15: =IF(BW15="-", "-", IF(CA15="-", "-", IF(ABS(CA15)=0, "-", ROUND(100*(BW15-CA15)/ABS(CA15), 1)))) -> - | CF15: =IF(CB15="-", "-", IF(CD15="-", "-", IF(ABS(CD15)=0, "-", ROUND(100*(CB15-CD15)/ABS(CD15), 1)))) -> - | CG15: =IF(CC15="-", "-", IF(CE15="-", "-", IF(ABS(CE15)=0, "-", ROUND(100*(CC15-CE15)/ABS(CE15), 1)))) -> -
AV16: 負担地代 | BI16: =IF(BA16="-", "-", IF(BE16="-", "-", IF(ABS(BE16)=0, "-", ROUND(100*(BA16-BE16)/ABS(BE16), 1)))) -> - | BJ16: =IF(BF16="-", "-", IF(BH16="-", "-", IF(ABS(BH16)=0, "-", ROUND(100*(BF16-BH16)/ABS(BH16), 1)))) -> - | BK16: =IF(BG16="-", "-", IF(BI16="-", "-", IF(ABS(BI16)=0, "-", ROUND(100*(BG16-BI16)/ABS(BI16), 1)))) -> - | BT16: =IF(BL16="-", "-", IF(BP16="-", "-", IF(ABS(BP16)=0, "-", ROUND(100*(BL16-BP16)/ABS(BP16), 1)))) -> - | BU16: =IF(BQ16="-", "-", IF(BS16="-", "-", IF(ABS(BS16)=0, "-", ROUND(100*(BQ16-BS16)/ABS(BS16), 1)))) -> - | BV16: =IF(BR16="-", "-", IF(BT16="-", "-", IF(ABS(BT16)=0, "-", ROUND(100*(BR16-BT16)/ABS(BT16), 1)))) -> - | CE16: =IF(BW16="-", "-", IF(CA16="-", "-", IF(ABS(CA16)=0, "-", ROUND(100*(BW16-CA16)/ABS(CA16), 1)))) -> - | CF16: =IF(CB16="-", "-", IF(CD16="-", "-", IF(ABS(CD16)=0, "-", ROUND(100*(CB16-CD16)/ABS(CD16), 1)))) -> - | CG16: =IF(CC16="-", "-", IF(CE16="-", "-", IF(ABS(CE16)=0, "-", ROUND(100*(CC16-CE16)/ABS(CE16), 1)))) -> -
B17: ８ 調査作物の作付面積（１経営体当たり） | S17: 単位：ａ | AT17: 実勢地代 | BI17: =IF(BA17="-", "-", IF(BE17="-", "-", IF(ABS(BE17)=0, "-", ROUND(100*(BA17-BE17)/ABS(BE17), 1)))) -> - | BJ17: =IF(BF17="-", "-", IF(BH17="-", "-", IF(ABS(BH17)=0, "-", ROUND(100*(BF17-BH17)/ABS(BH17), 1)))) -> - | BK17: =IF(BG17="-", "-", IF(BI17="-", "-", IF(ABS(BI17)=0, "-", ROUND(100*(BG17-BI17)/ABS(BI17), 1)))) -> - | BT17: =IF(BL17="-", "-", IF(BP17="-", "-", IF(ABS(BP17)=0, "-", ROUND(100*(BL17-BP17)/ABS(BP17), 1)))) -> - | BU17: =IF(BQ17="-", "-", IF(BS17="-", "-", IF(ABS(BS17)=0, "-", ROUND(100*(BQ17-BS17)/ABS(BS17), 1)))) -> - | BV17: =IF(BR17="-", "-", IF(BT17="-", "-", IF(ABS(BT17)=0, "-", ROUND(100*(BR17-BT17)/ABS(BT17), 1)))) -> - | CE17: =IF(BW17="-", "-", IF(CA17="-", "-", IF(ABS(CA17)=0, "-", ROUND(100*(BW17-CA17)/ABS(CA17), 1)))) -> - | CF17: =IF(CB17="-", "-", IF(CD17="-", "-", IF(ABS(CD17)=0, "-", ROUND(100*(CB17-CD17)/ABS(CD17), 1)))) -> - | CG17: =IF(CC17="-", "-", IF(CE17="-", "-", IF(ABS(CE17)=0, "-", ROUND(100*(CC17-CE17)/ABS(CE17), 1)))) -> -
I18: =IF($B$1<>"",$B$1,"") | M18: =IF($B$1<>"",$B$1-1,"") | Q18: 増減率
B19: 田 | Q19: =IF(I19="-", "-", IF(M19="-", "-", IF(ABS(M19)=0, "-", ROUND(100*(I19-M19)/ABS(M19), 1)))) -> - | R19: =IF(N19="-", "-", IF(P19="-", "-", IF(ABS(P19)=0, "-", ROUND(100*(N19-P19)/ABS(P19), 1)))) -> - | S19: =IF(O19="-", "-", IF(Q19="-", "-", IF(ABS(Q19)=0, "-", ROUND(100*(O19-Q19)/ABS(Q19), 1)))) -> -
B20: 畑 | Q20: =IF(I20="-", "-", IF(M20="-", "-", IF(ABS(M20)=0, "-", ROUND(100*(I20-M20)/ABS(M20), 1)))) -> - | R20: =IF(N20="-", "-", IF(P20="-", "-", IF(ABS(P20)=0, "-", ROUND(100*(N20-P20)/ABS(P20), 1)))) -> - | S20: =IF(O20="-", "-", IF(Q20="-", "-", IF(ABS(Q20)=0, "-", ROUND(100*(O20-Q20)/ABS(Q20), 1)))) -> - | AT20: 15 調査作物の品種別作付面積（１経営体当たり） | CC20: 単位：ａ
B21: 計 | Q21: =IF(I21="-", "-", IF(M21="-", "-", IF(ABS(M21)=0, "-", ROUND(100*(I21-M21)/ABS(M21), 1)))) -> - | R21: =IF(N21="-", "-", IF(P21="-", "-", IF(ABS(P21)=0, "-", ROUND(100*(N21-P21)/ABS(P21), 1)))) -> - | S21: =IF(O21="-", "-", IF(Q21="-", "-", IF(ABS(Q21)=0, "-", ROUND(100*(O21-Q21)/ABS(Q21), 1)))) -> - | BA21: =IF($B$1<>"",$B$1,"") | BE21: =IF($B$1<>"",$B$1-1,"") | BI21: 増減率 | BS21: =IF($B$1<>"",$B$1,"") | BW21: =IF($B$1<>"",$B$1-1,"") | CA21: 増減率
AT22: 計 | BI22: =IF(BA22="-", "-", IF(BE22="-", "-", IF(ABS(BE22)=0, "-", ROUND(100*(BA22-BE22)/ABS(BE22), 1)))) -> - | BJ22: =IF(BF22="-", "-", IF(BH22="-", "-", IF(ABS(BH22)=0, "-", ROUND(100*(BF22-BH22)/ABS(BH22), 1)))) -> - | BK22: =IF(BG22="-", "-", IF(BI22="-", "-", IF(ABS(BI22)=0, "-", ROUND(100*(BG22-BI22)/ABS(BI22), 1)))) -> -
AT23: コード１ | BI23: =IF(BA23="-", "-", IF(BE23="-", "-", IF(ABS(BE23)=0, "-", ROUND(100*(BA23-BE23)/ABS(BE23), 1)))) -> - | BJ23: =IF(BF23="-", "-", IF(BH23="-", "-", IF(ABS(BH23)=0, "-", ROUND(100*(BF23-BH23)/ABS(BH23), 1)))) -> - | BK23: =IF(BG23="-", "-", IF(BI23="-", "-", IF(ABS(BI23)=0, "-", ROUND(100*(BG23-BI23)/ABS(BI23), 1)))) -> - | BL23: コード１１ | CA23: =IF(BS23="-", "-", IF(BW23="-", "-", IF(ABS(BW23)=0, "-", ROUND(100*(BS23-BW23)/ABS(BW23), 1)))) -> - | CB23: =IF(BX23="-", "-", IF(BZ23="-", "-", IF(ABS(BZ23)=0, "-", ROUND(100*(BX23-BZ23)/ABS(BZ23), 1)))) -> - | CC23: =IF(BY23="-", "-", IF(CA23="-", "-", IF(ABS(CA23)=0, "-", ROUND(100*(BY23-CA23)/ABS(CA23), 1)))) -> -
B24: ９ 調査作物作業の受託状況（１経営体当たり） | X24: 10 調査作物作業の委託状況（１経営体当たり） | AT24: コード２ | BI24: =IF(BA24="-", "-", IF(BE24="-", "-", IF(ABS(BE24)=0, "-", ROUND(100*(BA24-BE24)/ABS(BE24), 1)))) -> - | BJ24: =IF(BF24="-", "-", IF(BH24="-", "-", IF(ABS(BH24)=0, "-", ROUND(100*(BF24-BH24)/ABS(BH24), 1)))) -> - | BK24: =IF(BG24="-", "-", IF(BI24="-", "-", IF(ABS(BI24)=0, "-", ROUND(100*(BG24-BI24)/ABS(BI24), 1)))) -> - | BL24: コード１２ | CA24: =IF(BS24="-", "-", IF(BW24="-", "-", IF(ABS(BW24)=0, "-", ROUND(100*(BS24-BW24)/ABS(BW24), 1)))) -> - | CB24: =IF(BX24="-", "-", IF(BZ24="-", "-", IF(ABS(BZ24)=0, "-", ROUND(100*(BX24-BZ24)/ABS(BZ24), 1)))) -> - | CC24: =IF(BY24="-", "-", IF(CA24="-", "-", IF(ABS(CA24)=0, "-", ROUND(100*(BY24-CA24)/ABS(CA24), 1)))) -> -
J25: 数量 | AF25: 数量 | AT25: コード３ | BI25: =IF(BA25="-", "-", IF(BE25="-", "-", IF(ABS(BE25)=0, "-", ROUND(100*(BA25-BE25)/ABS(BE25), 1)))) -> - | BJ25: =IF(BF25="-", "-", IF(BH25="-", "-", IF(ABS(BH25)=0, "-", ROUND(100*(BF25-BH25)/ABS(BH25), 1)))) -> - | BK25: =IF(BG25="-", "-", IF(BI25="-", "-", IF(ABS(BI25)=0, "-", ROUND(100*(BG25-BI25)/ABS(BI25), 1)))) -> - | BL25: コード１３ | CA25: =IF(BS25="-", "-", IF(BW25="-", "-", IF(ABS(BW25)=0, "-", ROUND(100*(BS25-BW25)/ABS(BW25), 1)))) -> - | CB25: =IF(BX25="-", "-", IF(BZ25="-", "-", IF(ABS(BZ25)=0, "-", ROUND(100*(BX25-BZ25)/ABS(BZ25), 1)))) -> - | CC25: =IF(BY25="-", "-", IF(CA25="-", "-", IF(ABS(CA25)=0, "-", ROUND(100*(BY25-CA25)/ABS(CA25), 1)))) -> -
J26: =IF($B$1<>"",$B$1,"") | N26: =IF($B$1<>"",$B$1-1,"") | R26: 増減率 | AF26: =IF($B$1<>"",$B$1,"") | AJ26: =IF($B$1<>"",$B$1-1,"") | AN26: 増減率 | AT26: コード４ | BI26: =IF(BA26="-", "-", IF(BE26="-", "-", IF(ABS(BE26)=0, "-", ROUND(100*(BA26-BE26)/ABS(BE26), 1)))) -> - | BJ26: =IF(BF26="-", "-", IF(BH26="-", "-", IF(ABS(BH26)=0, "-", ROUND(100*(BF26-BH26)/ABS(BH26), 1)))) -> - | BK26: =IF(BG26="-", "-", IF(BI26="-", "-", IF(ABS(BI26)=0, "-", ROUND(100*(BG26-BI26)/ABS(BI26), 1)))) -> - | BL26: コード１４ | CA26: =IF(BS26="-", "-", IF(BW26="-", "-", IF(ABS(BW26)=0, "-", ROUND(100*(BS26-BW26)/ABS(BW26), 1)))) -> - | CB26: =IF(BX26="-", "-", IF(BZ26="-", "-", IF(ABS(BZ26)=0, "-", ROUND(100*(BX26-BZ26)/ABS(BZ26), 1)))) -> - | CC26: =IF(BY26="-", "-", IF(CA26="-", "-", IF(ABS(CA26)=0, "-", ROUND(100*(BY26-CA26)/ABS(CA26), 1)))) -> -
B27: 全作業 | I27: ａ | R27: =IF(J27="-", "-", IF(N27="-", "-", IF(ABS(N27)=0, "-", ROUND(100*(J27-N27)/ABS(N27), 1)))) -> - | S27: =IF(O27="-", "-", IF(Q27="-", "-", IF(ABS(Q27)=0, "-", ROUND(100*(O27-Q27)/ABS(Q27), 1)))) -> - | T27: =IF(P27="-", "-", IF(R27="-", "-", IF(ABS(R27)=0, "-", ROUND(100*(P27-R27)/ABS(R27), 1)))) -> - | X27: 耕うん・整地 | AE27: ａ | AN27: =IF(AF27="-", "-", IF(AJ27="-", "-", IF(ABS(AJ27)=0, "-", ROUND(100*(AF27-AJ27)/ABS(AJ27), 1)))) -> - | AO27: =IF(AK27="-", "-", IF(AM27="-", "-", IF(ABS(AM27)=0, "-", ROUND(100*(AK27-AM27)/ABS(AM27), 1)))) -> - | AP27: =IF(AL27="-", "-", IF(AN27="-", "-", IF(ABS(AN27)=0, "-", ROUND(100*(AL27-AN27)/ABS(AN27), 1)))) -> - | AT27: コード５ | BI27: =IF(BA27="-", "-", IF(BE27="-", "-", IF(ABS(BE27)=0, "-", ROUND(100*(BA27-BE27)/ABS(BE27), 1)))) -> - | BJ27: =IF(BF27="-", "-", IF(BH27="-", "-", IF(ABS(BH27)=0, "-", ROUND(100*(BF27-BH27)/ABS(BH27), 1)))) -> - | BK27: =IF(BG27="-", "-", IF(BI27="-", "-", IF(ABS(BI27)=0, "-", ROUND(100*(BG27-BI27)/ABS(BI27), 1)))) -> - | BL27: コード１５ | CA27: =IF(BS27="-", "-", IF(BW27="-", "-", IF(ABS(BW27)=0, "-", ROUND(100*(BS27-BW27)/ABS(BW27), 1)))) -> - | CB27: =IF(BX27="-", "-", IF(BZ27="-", "-", IF(ABS(BZ27)=0, "-", ROUND(100*(BX27-BZ27)/ABS(BZ27), 1)))) -> - | CC27: =IF(BY27="-", "-", IF(CA27="-", "-", IF(ABS(CA27)=0, "-", ROUND(100*(BY27-CA27)/ABS(CA27), 1)))) -> -
B28: 耕うん・整地 | I28: ａ | R28: =IF(J28="-", "-", IF(N28="-", "-", IF(ABS(N28)=0, "-", ROUND(100*(J28-N28)/ABS(N28), 1)))) -> - | S28: =IF(O28="-", "-", IF(Q28="-", "-", IF(ABS(Q28)=0, "-", ROUND(100*(O28-Q28)/ABS(Q28), 1)))) -> - | T28: =IF(P28="-", "-", IF(R28="-", "-", IF(ABS(R28)=0, "-", ROUND(100*(P28-R28)/ABS(R28), 1)))) -> - | X28: は種 | AE28: ａ | AN28: =IF(AF28="-", "-", IF(AJ28="-", "-", IF(ABS(AJ28)=0, "-", ROUND(100*(AF28-AJ28)/ABS(AJ28), 1)))) -> - | AO28: =IF(AK28="-", "-", IF(AM28="-", "-", IF(ABS(AM28)=0, "-", ROUND(100*(AK28-AM28)/ABS(AM28), 1)))) -> - | AP28: =IF(AL28="-", "-", IF(AN28="-", "-", IF(ABS(AN28)=0, "-", ROUND(100*(AL28-AN28)/ABS(AN28), 1)))) -> - | AT28: コード６ | BI28: =IF(BA28="-", "-", IF(BE28="-", "-", IF(ABS(BE28)=0, "-", ROUND(100*(BA28-BE28)/ABS(BE28), 1)))) -> - | BJ28: =IF(BF28="-", "-", IF(BH28="-", "-", IF(ABS(BH28)=0, "-", ROUND(100*(BF28-BH28)/ABS(BH28), 1)))) -> - | BK28: =IF(BG28="-", "-", IF(BI28="-", "-", IF(ABS(BI28)=0, "-", ROUND(100*(BG28-BI28)/ABS(BI28), 1)))) -> - | BL28: コード１６ | CA28: =IF(BS28="-", "-", IF(BW28="-", "-", IF(ABS(BW28)=0, "-", ROUND(100*(BS28-BW28)/ABS(BW28), 1)))) -> - | CB28: =IF(BX28="-", "-", IF(BZ28="-", "-", IF(ABS(BZ28)=0, "-", ROUND(100*(BX28-BZ28)/ABS(BZ28), 1)))) -> - | CC28: =IF(BY28="-", "-", IF(CA28="-", "-", IF(ABS(CA28)=0, "-", ROUND(100*(BY28-CA28)/ABS(CA28), 1)))) -> -
B29: は種 | I29: ａ | R29: =IF(J29="-", "-", IF(N29="-", "-", IF(ABS(N29)=0, "-", ROUND(100*(J29-N29)/ABS(N29), 1)))) -> - | S29: =IF(O29="-", "-", IF(Q29="-", "-", IF(ABS(Q29)=0, "-", ROUND(100*(O29-Q29)/ABS(Q29), 1)))) -> - | T29: =IF(P29="-", "-", IF(R29="-", "-", IF(ABS(R29)=0, "-", ROUND(100*(P29-R29)/ABS(R29), 1)))) -> - | X29: 防除 | AE29: ａ | AN29: =IF(AF29="-", "-", IF(AJ29="-", "-", IF(ABS(AJ29)=0, "-", ROUND(100*(AF29-AJ29)/ABS(AJ29), 1)))) -> - | AO29: =IF(AK29="-", "-", IF(AM29="-", "-", IF(ABS(AM29)=0, "-", ROUND(100*(AK29-AM29)/ABS(AM29), 1)))) -> - | AP29: =IF(AL29="-", "-", IF(AN29="-", "-", IF(ABS(AN29)=0, "-", ROUND(100*(AL29-AN29)/ABS(AN29), 1)))) -> - | AT29: コード７ | BI29: =IF(BA29="-", "-", IF(BE29="-", "-", IF(ABS(BE29)=0, "-", ROUND(100*(BA29-BE29)/ABS(BE29), 1)))) -> - | BJ29: =IF(BF29="-", "-", IF(BH29="-", "-", IF(ABS(BH29)=0, "-", ROUND(100*(BF29-BH29)/ABS(BH29), 1)))) -> - | BK29: =IF(BG29="-", "-", IF(BI29="-", "-", IF(ABS(BI29)=0, "-", ROUND(100*(BG29-BI29)/ABS(BI29), 1)))) -> - | BL29: コード１７ | CA29: =IF(BS29="-", "-", IF(BW29="-", "-", IF(ABS(BW29)=0, "-", ROUND(100*(BS29-BW29)/ABS(BW29), 1)))) -> - | CB29: =IF(BX29="-", "-", IF(BZ29="-", "-", IF(ABS(BZ29)=0, "-", ROUND(100*(BX29-BZ29)/ABS(BZ29), 1)))) -> - | CC29: =IF(BY29="-", "-", IF(CA29="-", "-", IF(ABS(CA29)=0, "-", ROUND(100*(BY29-CA29)/ABS(CA29), 1)))) -> -
B30: 防除 | I30: ａ | R30: =IF(J30="-", "-", IF(N30="-", "-", IF(ABS(N30)=0, "-", ROUND(100*(J30-N30)/ABS(N30), 1)))) -> - | S30: =IF(O30="-", "-", IF(Q30="-", "-", IF(ABS(Q30)=0, "-", ROUND(100*(O30-Q30)/ABS(Q30), 1)))) -> - | T30: =IF(P30="-", "-", IF(R30="-", "-", IF(ABS(R30)=0, "-", ROUND(100*(P30-R30)/ABS(R30), 1)))) -> - | X30: 刈取・脱穀 | AE30: ａ | AN30: =IF(AF30="-", "-", IF(AJ30="-", "-", IF(ABS(AJ30)=0, "-", ROUND(100*(AF30-AJ30)/ABS(AJ30), 1)))) -> - | AO30: =IF(AK30="-", "-", IF(AM30="-", "-", IF(ABS(AM30)=0, "-", ROUND(100*(AK30-AM30)/ABS(AM30), 1)))) -> - | AP30: =IF(AL30="-", "-", IF(AN30="-", "-", IF(ABS(AN30)=0, "-", ROUND(100*(AL30-AN30)/ABS(AN30), 1)))) -> - | AT30: コード８ | BI30: =IF(BA30="-", "-", IF(BE30="-", "-", IF(ABS(BE30)=0, "-", ROUND(100*(BA30-BE30)/ABS(BE30), 1)))) -> - | BJ30: =IF(BF30="-", "-", IF(BH30="-", "-", IF(ABS(BH30)=0, "-", ROUND(100*(BF30-BH30)/ABS(BH30), 1)))) -> - | BK30: =IF(BG30="-", "-", IF(BI30="-", "-", IF(ABS(BI30)=0, "-", ROUND(100*(BG30-BI30)/ABS(BI30), 1)))) -> - | BL30: コード１８ | CA30: =IF(BS30="-", "-", IF(BW30="-", "-", IF(ABS(BW30)=0, "-", ROUND(100*(BS30-BW30)/ABS(BW30), 1)))) -> - | CB30: =IF(BX30="-", "-", IF(BZ30="-", "-", IF(ABS(BZ30)=0, "-", ROUND(100*(BX30-BZ30)/ABS(BZ30), 1)))) -> - | CC30: =IF(BY30="-", "-", IF(CA30="-", "-", IF(ABS(CA30)=0, "-", ROUND(100*(BY30-CA30)/ABS(CA30), 1)))) -> -
B31: 刈取・脱穀 | I31: ａ | R31: =IF(J31="-", "-", IF(N31="-", "-", IF(ABS(N31)=0, "-", ROUND(100*(J31-N31)/ABS(N31), 1)))) -> - | S31: =IF(O31="-", "-", IF(Q31="-", "-", IF(ABS(Q31)=0, "-", ROUND(100*(O31-Q31)/ABS(Q31), 1)))) -> - | T31: =IF(P31="-", "-", IF(R31="-", "-", IF(ABS(R31)=0, "-", ROUND(100*(P31-R31)/ABS(R31), 1)))) -> - | X31: 乾燥・調製 | AE31: kg | AN31: =IF(AF31="-", "-", IF(AJ31="-", "-", IF(ABS(AJ31)=0, "-", ROUND(100*(AF31-AJ31)/ABS(AJ31), 1)))) -> - | AO31: =IF(AK31="-", "-", IF(AM31="-", "-", IF(ABS(AM31)=0, "-", ROUND(100*(AK31-AM31)/ABS(AM31), 1)))) -> - | AP31: =IF(AL31="-", "-", IF(AN31="-", "-", IF(ABS(AN31)=0, "-", ROUND(100*(AL31-AN31)/ABS(AN31), 1)))) -> - | AT31: コード９ | BI31: =IF(BA31="-", "-", IF(BE31="-", "-", IF(ABS(BE31)=0, "-", ROUND(100*(BA31-BE31)/ABS(BE31), 1)))) -> - | BJ31: =IF(BF31="-", "-", IF(BH31="-", "-", IF(ABS(BH31)=0, "-", ROUND(100*(BF31-BH31)/ABS(BH31), 1)))) -> - | BK31: =IF(BG31="-", "-", IF(BI31="-", "-", IF(ABS(BI31)=0, "-", ROUND(100*(BG31-BI31)/ABS(BI31), 1)))) -> - | BL31: コード１９ | CA31: =IF(BS31="-", "-", IF(BW31="-", "-", IF(ABS(BW31)=0, "-", ROUND(100*(BS31-BW31)/ABS(BW31), 1)))) -> - | CB31: =IF(BX31="-", "-", IF(BZ31="-", "-", IF(ABS(BZ31)=0, "-", ROUND(100*(BX31-BZ31)/ABS(BZ31), 1)))) -> - | CC31: =IF(BY31="-", "-", IF(CA31="-", "-", IF(ABS(CA31)=0, "-", ROUND(100*(BY31-CA31)/ABS(CA31), 1)))) -> -
B32: 乾燥・調製 | I32: kg | R32: =IF(J32="-", "-", IF(N32="-", "-", IF(ABS(N32)=0, "-", ROUND(100*(J32-N32)/ABS(N32), 1)))) -> - | S32: =IF(O32="-", "-", IF(Q32="-", "-", IF(ABS(Q32)=0, "-", ROUND(100*(O32-Q32)/ABS(Q32), 1)))) -> - | T32: =IF(P32="-", "-", IF(R32="-", "-", IF(ABS(R32)=0, "-", ROUND(100*(P32-R32)/ABS(R32), 1)))) -> - | AT32: コード１０ | BI32: =IF(BA32="-", "-", IF(BE32="-", "-", IF(ABS(BE32)=0, "-", ROUND(100*(BA32-BE32)/ABS(BE32), 1)))) -> - | BJ32: =IF(BF32="-", "-", IF(BH32="-", "-", IF(ABS(BH32)=0, "-", ROUND(100*(BF32-BH32)/ABS(BH32), 1)))) -> - | BK32: =IF(BG32="-", "-", IF(BI32="-", "-", IF(ABS(BI32)=0, "-", ROUND(100*(BG32-BI32)/ABS(BI32), 1)))) -> - | BL32: コード２０ | CA32: =IF(BS32="-", "-", IF(BW32="-", "-", IF(ABS(BW32)=0, "-", ROUND(100*(BS32-BW32)/ABS(BW32), 1)))) -> - | CB32: =IF(BX32="-", "-", IF(BZ32="-", "-", IF(ABS(BZ32)=0, "-", ROUND(100*(BX32-BZ32)/ABS(BZ32), 1)))) -> - | CC32: =IF(BY32="-", "-", IF(CA32="-", "-", IF(ABS(CA32)=0, "-", ROUND(100*(BY32-CA32)/ABS(CA32), 1)))) -> -
B35: 11 物件税及び公課諸負担 | S35: 単位：円
I36: =IF($B$1<>"",$B$1,"") | M36: =IF($B$1<>"",$B$1-1,"") | Q36: 増減率
