Workbook

Sheet No1
B1: =B5&"年産 農業経営統計調査（小麦・大豆生産費統計（組織法人経営体）） 集計結果表№１" -> 年産 農業経営統計調査（小麦・大豆生産費統計（組織法人経営体）） 集計結果表№１
B2: 集計名称：
B3: ○ 指標部
A4: 1 | B4: 調査年 | H4: 都道府県等 | N4: 経営種類 | T4: 生産費区分 | Z4: 規模階層 | AF4: 平均値種類 | AL4: 集計経営体数 | AR4: 集計倍率 | AX4: 加重・総和の別 | BD4: 集計区分 | BJ4: 田畑区分
A5: 2 | I5: =IF(H5<>"",DGET(リスト!A2:B71,"都道府県番号",リスト!B73:B74),"") | O5: =IF(N5>0,DGET(リスト!V2:W4,"経営種類",リスト!W6:W7),"") | U5: =IF(T5>0,DGET(リスト!D2:E13,"生産費区分",リスト!E15:E16),"") | AA5: =IF(T5=81,DGET(リスト!J3:K15,"規模階層",リスト!K17:K18),IF(T5=82,DGET(リスト!J21:K31,"規模階層",リスト!K17:K18),"")) | AG5: =IF(AF5<>"",DGET(リスト!P2:Q7,"平均値種類",リスト!Q9:Q10),"") | AY5: =IF(AX5>0,DGET(リスト!S2:T4,"加重・総和の別",リスト!T6:T7),"") | BE5: =IF(BD5>0,DGET(リスト!G2:H8,"集計区分",リスト!H10:H11),"") | BK5: =IF(BJ5<>"",DGET(リスト!M2:N5,"田畑区分",リスト!N7:N8),"")
A6: 3 | B6: １ 生産費総括（円）
A7: 4 | H7: １０ ａ 当 た り | AF7: ６０ ｋｇ 当 た り
A8: 5 | H8: 購入 | N8: 自給 | T8: 償却 | Z8: 計 | AF8: 購入 | AL8: 自給 | AR8: 償却 | AX8: 計
A9: 6 | B9: 物財費 | BJ9: ４ 経営耕地（ａ）
A10: 7 | C10: 種苗費 | BP10: 所有地 | BV10: 借入地 | CB10: 計
A11: 8 | C11: 肥料費 | BJ11: 田
A12: 9 | C12: 農業薬剤費 | BJ12: 普通畑
A13: 10 | C13: 光熱動力費 | BJ13: 樹園地
A14: 11 | C14: その他諸材料費 | BJ14: 牧草地
A15: 12 | C15: 土地改良及び水利費 | BJ15: 計
A16: 13 | C16: 賃借料及び料金 | BJ16: ５ 地 代（円、ａ）
A17: 14 | C17: 物件税及び公課諸負担 | BP17: １ 経 営 体 当 た り
A18: 15 | C18: 建物費 | BP18: 自作地 | BV18: 借入地 | CB18: 計
A19: 16 | C19: 自動車費 | BJ19: 作付地 | BL19: 作付実面積
A20: 17 | C20: 農機具費 | BL20: 土地台帳面積
A21: 18 | C21: 生産管理費 | BL21: 地代総額
A22: 19 | B22: 労働費 | BL22: 負担地代
A23: 20 | C23: 直接労働費 | BJ23: 以 外 作付地 | BL23: 使用面積
A24: 21 | C24: 間接労働費 | BL24: 賃借料総額
A25: 22 | B25: 費用合計 | BL25: 負担地代
A26: 23 | B26: 副産物価額 | BP26: １０ ａ 当 た り
A27: 24 | B27: 生産費 | BP27: 自作地 | BV27: 借入地 | CB27: 計
A28: 25 | B28: 支払利子 | BJ28: 実勢地代
A29: 26 | B29: 支払地代 | BJ29: 作付地負担地代
A30: 27 | B30: 利子・地代算入生産費 | BJ30: 作付地以外地代
A31: 28 | B31: 自己資本利子
A32: 29 | B32: 自作地地代
A33: 30 | B33: 全算入生産費
A34: 31 | B34: ２ 投下労働時間（時間）10ａ当たり | AF34: ６ 資本額及び資本利子（円） | BJ34: 14 調査作物の作付面積（ａ）
A35: 32 | H35: 構成員 | N35: 雇用 | T35: 計 | Z35: ６０ｋｇ当たり | AL35: 資本額 | AX35: 利子額 | BP35: 面積
A36: 33 | AL36: １０ａ当たり | AR36: ６０ｋｇ当たり | AX36: １０ａ当たり | BD36: ６０ｋｇ当たり | BJ36: 田
A37: 34 | B37: 直接労働時間 | C37: 種子予措 | AF37: 資本額計 | BJ37: 畑
A38: 35 | C38: 育苗 | AG38: 借入資本 | BJ38: 計
A39: 36 | C39: 耕起整地 | AG39: 自己資本 | BJ39: 15 調査作物の品種別作付面積（ａ）
A40: 37 | C40: 基肥 | AF40: 資産別内訳 | AG40: 流動資本 | BP40: 品種コード | BV40: 面積
...

Sheet No2
B1: =B5&"年産 農業経営統計調査（小麦・大豆生産費統計（組織法人経営体）） 集計結果表№２" -> 年産 農業経営統計調査（小麦・大豆生産費統計（組織法人経営体）） 集計結果表№２
B2: 集計名称： | F2: =IF('No1'!F2<>"",'No1'!F2,"")
B3: ○ 指標部
A4: 1 | B4: 調査年 | H4: 都道府県等 | N4: 経営種類 | T4: 生産費区分 | Z4: 規模階層 | AF4: 平均値種類 | AL4: 集計経営体数 | AR4: 集計倍率 | AX4: 加重・総和の別 | BD4: 集計区分 | BJ4: 田畑区分
A5: 2 | B5: =IF('No1'!B5<>"",'No1'!B5,"") | H5: =IF('No1'!H5<>"",'No1'!H5,"") | I5: ='No1'!I5 | N5: =IF('No1'!N5<>"",'No1'!N5,"") | O5: ='No1'!O5 | T5: =IF('No1'!T5<>"",'No1'!T5,"") | U5: ='No1'!U5 | Z5: =IF('No1'!Z5<>"",'No1'!Z5,"") | AA5: ='No1'!AA5 | AF5: =IF('No1'!AF5<>"",'No1'!AF5,"") | AG5: ='No1'!AG5 | AL5: =IF('No1'!AL5<>"",'No1'!AL5,"") | AR5: =IF('No1'!AR5<>"",'No1'!AR5,"") | AX5: =IF('No1'!AX5<>"",'No1'!AX5,"") | AY5: ='No1'!AY5 | BD5: =IF('No1'!BD5<>"",'No1'!BD5,"") | BE5: ='No1'!BE5 | BJ5: =IF('No1'!BJ5<>"",'No1'!BJ5,"") | BK5: ='No1'!BK5
A6: 3 | B6: ８ 収益性（円） | AF6: 12 減価償却費（円）（所有台数は10経営体当たり） | BJ6: 21 生産物の処分内訳（㎏、円）
A7: 4 | H7: １０ａ当たり | AX7: １経営体当たり | BD7: １０ａ当たり | BJ7: 小麦 | BP7: １０ ａ 当 た り
A8: 5 | B8: 粗収益 | AF8: 建物・構築物 | AH8: 住宅 | BP8: 数量 | BV8: 価額 | CB8: 単価
A9: 6 | B9: 生産費総額 | AH9: 納屋・倉庫 | BJ9: 主産物 | BK9: 販売用 | BL9: １等
A10: 7 | B10: 利潤 | AH10: 用水路 | BL10: ２等
A11: 8 | B11: 所得 | AH11: 暗きょ排水施設 | BL11: 規格外Ａ
A12: 9 | C12: １日当たり | AH12: コンクリートけい畔 | BL12: その他
A13: 10 | B13: 構成員労働報酬 | AH13: 客土 | BL13: 小計
A14: 11 | C14: １日当たり | AH14: たい肥盤 | BK14: 組織用 | BL14: 食用
A15: 12 | B15: 〔参考〕各種助成措置を加えた場合（円） | AH15: その他 | BL15: 種子用
A16: 13 | H16: １０ａ当たり | AH16: 計 | BL16: その他
A17: 14 | B17: 粗収益 | AK17: 処分差損失 | BL17: 小計
A18: 15 | B18: 生産費総額 | AR18: 所有台数（台） | AX18: １経営体当たり | BD18: １０ａ当たり | BK18: 合計
A19: 16 | B19: 利潤 | AF19: 自動車 | AH19: 貨物自動車 | BJ19: 副産物 | BK19: 販売用 | BL19: 規格外Ｂ
A20: 17 | B20: 所得 | AH20: その他 | BL20: 規格外Ｃ
A21: 18 | C21: １日当たり | AH21: 計 | BL21: くず麦
A22: 19 | B22: 構成員労働報酬 | AK22: 処分差損失 | BL22: 麦わら
A23: 20 | C23: １日当たり | AR23: 所有台数（台） | AX23: １経営体当たり | BD23: １０ａ当たり | BL23: 小計
A24: 21 | B24: ９ 農業共済金、各種助成措置の状況（円） | C24: ９ 農業共済金、各種助成措置の状況（円） | D24: ９ 農業共済金、各種助成措置の状況（円） | E24: ９ 農業共済金、各種助成措置の状況（円） | F24: ９ 農業共済金、各種助成措置の状況（円） | G24: ９ 農業共済金、各種助成措置の状況（円） | H24: ９ 農業共済金、各種助成措置の状況（円） | I24: ９ 農業共済金、各種助成措置の状況（円） | J24: ９ 農業共済金、各種助成措置の状況（円） | K24: ９ 農業共済金、各種助成措置の状況（円） | L24: ９ 農業共済金、各種助成措置の状況（円） | M24: ９ 農業共済金、各種助成措置の状況（円） | N24: ９ 農業共済金、各種助成措置の状況（円） | O24: ９ 農業共済金、各種助成措置の状況（円） | P24: ９ 農業共済金、各種助成措置の状況（円） | Q24: ９ 農業共済金、各種助成措置の状況（円） | R24: ９ 農業共済金、各種助成措置の状況（円） | S24: ９ 農業共済金、各種助成措置の状況（円） | AF24: 農機具 | AH24: 乗用トラクター | AK24: 20馬力未満 | BK24: 組織用 | BL24: 規格外Ｂ
A25: 22 | H25: １ 経 営 体 当 た り | AK25: 20～50馬力未満 | BL25: 規格外Ｃ
A26: 23 | H26: 拠出金 | N26: 受取金 | AK26: 50馬力以上 | BL26: くず麦
A27: 24 | B27: 農業共済金 | AH27: 歩行用トラクター | BL27: 麦わら
A28: 25 | B28: 畑作物の直接支払交付金 | E28: 面積払 | AH28: たい肥等散布機 | BM28: 無評価
A29: 26 | E29: 数量払 | AH29: 総合は種機 | BL29: 小計
A30: 27 | B30: 水田活用の直接支払交付金 | AH30: 中耕除草機 | BK30: 合計
A31: 28 | C31: 戦略作物助成 | AH31: 肥料散布機 | BJ31: 大豆
A32: 29 | C32: 産地交付金 | AH32: 動力噴霧機 | BJ32: 主産物 | BK32: 販売用 | BL32: １等
A33: 30 | AH33: 動力散粉機 | BL33: ２等
A34: 31 | AH34: 自脱型 コンバイン | AK34: ３条以下 | BL34: ３等・規格外
A35: 32 | AK35: ４条以上 | BL35: 特定加工用
A36: 33 | H36: １０ ａ 当 た り | AH36: 普通型コンバイン | BL36: その他
A37: 34 | H37: 拠出金 | N37: 受取金 | AH37: 調査作物収穫機 | BL37: 小計
A38: 35 | B38: 農業共済金 | AH38: 脱穀機 | BK38: 組織用 | BL38: 食用
A39: 36 | B39: 畑作物の直接支払交付金 | E39: 面積払 | AH39: 乾燥機 | BL39: 種子用
A40: 37 | E40: 数量払 | AH40: トレーラー | BL40: その他
...

Sheet リスト
A2: 都道府県番号 | B2: コード | D2: 生産費区分 | E2: コード | G2: 集計区分 | H2: コード | J2: 小麦 | M2: 田畑区分 | N2: コード | P2: 平均値種類 | Q2: コード | S2: 加重・総和の別 | T2: コード | V2: 経営種類 | W2: コード
A3: 全国 | B3: 0 | G3: 全調査対象 | H3: 1 | J3: 規模階層 | K3: コード | M3: 田畑計 | N3: 3 | P3: 通常 | Q3: 0 | S3: 加重平均 | T3: 1 | V3: 個別経営体 | W3: 1
A4: 都府県平均 | B4: 60 | J4: 平均 | K4: 0 | M4: 田 | N4: 1 | P4: 総数 | Q4: 1 | S4: 総和平均 | T4: 2 | V4: 組織法人経営体 | W4: 2
A5: 北海道 | B5: 1 | J5: 5.0ha未満 | K5: 1 | M5: 畑 | N5: 2 | P5: 10ａ当たり | Q5: 2
A6: 東北 | B6: 61 | J6: 5.0～10.0 | K6: 2 | P6: 単位数量当たり | Q6: 3 | T6: コード | W6: コード
A7: 北陸 | B7: 62 | J7: 10.0ha以上 | K7: 3 | N7: コード | P7: １経営体当たり | Q7: 4 | T7: ="="&'No1'!AX5 -> = | W7: ="="&'No1'!N5 -> =
A8: 関東・東山 | B8: 63 | D8: 小麦 | E8: 81 | G8: 集計対象 | H8: 2 | J8: 10.0～15.0 | K8: 4 | N8: ="="&'No1'!BJ5 -> =
A9: 東海 | B9: 67 | D9: 大豆 | E9: 82 | J9: 15.0ha以上 | K9: 5 | Q9: コード
A10: 近畿 | B10: 68 | H10: コード | J10: 15.0～20.0 | K10: 6 | Q10: ="="&'No1'!AF5 -> =
A11: 中国 | B11: 71 | H11: ="="&'No1'!BD5 -> = | J11: 20.0ha以上 | K11: 7
A12: 四国 | B12: 74 | J12: 20.0～30.0 | K12: 8
A13: 九州 | B13: 75 | J13: 30.0ha以上 | K13: 9
A14: 沖縄 | B14: 47 | J14: 30.0～50.0 | K14: 10
A15: 北関東 | B15: 64 | E15: コード | J15: 50.0ha以上 | K15: 11
A16: 南関東 | B16: 65 | E16: ="="&'No1'!T5 -> =
A17: 東山 | B17: 66 | K17: コード
A18: 北東北 | B18: 69 | K18: ="="&'No1'!Z5 -> =
A19: 南東北 | B19: 70
A20: 山陰 | B20: 72 | J20: 大豆
A21: 山陽 | B21: 73 | J21: 規模階層 | K21: コード
A22: 北九州 | B22: 76 | J22: 平均 | K22: 0
A23: 南九州 | B23: 77 | J23: 5.0ha未満 | K23: 1
A24: 関東農政局 | B24: 93 | J24: 5.0～10.0 | K24: 2
A25: 東海農政局 | B25: 94 | J25: 10.0ha以上 | K25: 3
A26: 中国四国局 | B26: 95 | J26: 10.0～15.0 | K26: 4
A27: 青森 | B27: 2 | J27: 15.0ha以上 | K27: 5
A28: 岩手 | B28: 3 | J28: 15.0～20.0 | K28: 6
A29: 宮城 | B29: 4 | J29: 20.0ha以上 | K29: 7
A30: 秋田 | B30: 5 | J30: 20.0～30.0 | K30: 8
A31: 山形 | B31: 6 | J31: 30.0ha以上 | K31: 9
A32: 福島 | B32: 7
A33: 茨城 | B33: 8
A34: 栃木 | B34: 9
A35: 群馬 | B35: 10
A36: 埼玉 | B36: 11
A37: 千葉 | B37: 12
A38: 東京 | B38: 13
A39: 神奈川 | B39: 14
A40: 新潟 | B40: 15
A41: 富山 | B41: 16
...
