Workbook

Sheet No.1
A1: 2019 | C1: 年産 米生産費統計（個別経営体） 個別結果検討表 №１ | O1: センサス番号
A4: 【生産費】
A5: 区 分 | G5: 単位 | H5: =A1-2000 -> 19 | I5: 構成割合 | J5: =H5-1 -> 18 | K5: 構成割合 | L5: 増減率 | M5: 増減差 | N5: 主 な 増 減 要 因
I6: （％） | K6: （％） | L6: （％）
A7: 10 ａ 当 た り 生 産 費 | B7: 物財費 | G7: 円 | I7: =IFERROR(H7/$H$29*100,"-") -> - | K7: =IFERROR(J7/$J$29*100,"-") -> - | L7: =IFERROR(100*(H7-J7)/J7,"-") -> - | M7: =H7-J7 -> 0
C8: 種苗費 | G8: 〃 | I8: =IFERROR(H8/$H$29*100,"-") -> - | K8: =IFERROR(J8/$J$29*100,"-") -> - | L8: =IFERROR(100*(H8-J8)/J8,"-") -> - | M8: =H8-J8 -> 0
C9: 肥料費 | G9: 〃 | I9: =IFERROR(H9/$H$29*100,"-") -> - | K9: =IFERROR(J9/$J$29*100,"-") -> - | L9: =IFERROR(100*(H9-J9)/J9,"-") -> - | M9: =H9-J9 -> 0
C10: 農業薬剤費 | G10: 〃 | I10: =IFERROR(H10/$H$29*100,"-") -> - | K10: =IFERROR(J10/$J$29*100,"-") -> - | L10: =IFERROR(100*(H10-J10)/J10,"-") -> - | M10: =H10-J10 -> 0
C11: 光熱動力費 | G11: 〃 | I11: =IFERROR(H11/$H$29*100,"-") -> - | K11: =IFERROR(J11/$J$29*100,"-") -> - | L11: =IFERROR(100*(H11-J11)/J11,"-") -> - | M11: =H11-J11 -> 0
C12: その他の諸材料費 | G12: 〃 | I12: =IFERROR(H12/$H$29*100,"-") -> - | K12: =IFERROR(J12/$J$29*100,"-") -> - | L12: =IFERROR(100*(H12-J12)/J12,"-") -> - | M12: =H12-J12 -> 0
C13: 土地改良及び水利費 | G13: 〃 | I13: =IFERROR(H13/$H$29*100,"-") -> - | K13: =IFERROR(J13/$J$29*100,"-") -> - | L13: =IFERROR(100*(H13-J13)/J13,"-") -> - | M13: =H13-J13 -> 0
C14: 賃借料及び料金 | G14: 〃 | I14: =IFERROR(H14/$H$29*100,"-") -> - | K14: =IFERROR(J14/$J$29*100,"-") -> - | L14: =IFERROR(100*(H14-J14)/J14,"-") -> - | M14: =H14-J14 -> 0
C15: 物件税及び公課諸負担 | G15: 〃 | I15: =IFERROR(H15/$H$29*100,"-") -> - | K15: =IFERROR(J15/$J$29*100,"-") -> - | L15: =IFERROR(100*(H15-J15)/J15,"-") -> - | M15: =H15-J15 -> 0
C16: 建物費 | G16: 〃 | I16: =IFERROR(H16/$H$29*100,"-") -> - | K16: =IFERROR(J16/$J$29*100,"-") -> - | L16: =IFERROR(100*(H16-J16)/J16,"-") -> - | M16: =H16-J16 -> 0
D17: 償却費 | G17: 〃 | I17: =IFERROR(H17/$H$29*100,"-") -> - | K17: =IFERROR(J17/$J$29*100,"-") -> - | L17: =IFERROR(100*(H17-J17)/J17,"-") -> - | M17: =H17-J17 -> 0
C18: 自動車費 | G18: 〃 | I18: =IFERROR(H18/$H$29*100,"-") -> - | K18: =IFERROR(J18/$J$29*100,"-") -> - | L18: =IFERROR(100*(H18-J18)/J18,"-") -> - | M18: =H18-J18 -> 0
D19: 償却費 | G19: 〃 | I19: =IFERROR(H19/$H$29*100,"-") -> - | K19: =IFERROR(J19/$J$29*100,"-") -> - | L19: =IFERROR(100*(H19-J19)/J19,"-") -> - | M19: =H19-J19 -> 0
C20: 農機具費 | G20: 〃 | I20: =IFERROR(H20/$H$29*100,"-") -> - | K20: =IFERROR(J20/$J$29*100,"-") -> - | L20: =IFERROR(100*(H20-J20)/J20,"-") -> - | M20: =H20-J20 -> 0
D21: 償却費 | G21: 〃 | I21: =IFERROR(H21/$H$29*100,"-") -> - | K21: =IFERROR(J21/$J$29*100,"-") -> - | L21: =IFERROR(100*(H21-J21)/J21,"-") -> - | M21: =H21-J21 -> 0
C22: 生産管理費 | G22: 〃 | I22: =IFERROR(H22/$H$29*100,"-") -> - | K22: =IFERROR(J22/$J$29*100,"-") -> - | L22: =IFERROR(100*(H22-J22)/J22,"-") -> - | M22: =H22-J22 -> 0
D23: 償却費 | G23: 〃 | I23: =IFERROR(H23/$H$29*100,"-") -> - | K23: =IFERROR(J23/$J$29*100,"-") -> - | L23: =IFERROR(100*(H23-J23)/J23,"-") -> - | M23: =H23-J23 -> 0
B24: 労働費 | G24: 〃 | I24: =IFERROR(H24/$H$29*100,"-") -> - | K24: =IFERROR(J24/$J$29*100,"-") -> - | L24: =IFERROR(100*(H24-J24)/J24,"-") -> - | M24: =H24-J24 -> 0
D25: 家族 | G25: 〃 | I25: =IFERROR(H25/$H$29*100,"-") -> - | K25: =IFERROR(J25/$J$29*100,"-") -> - | L25: =IFERROR(100*(H25-J25)/J25,"-") -> - | M25: =H25-J25 -> 0
C26: 直接労働費 | G26: 〃 | I26: =IFERROR(H26/$H$29*100,"-") -> - | K26: =IFERROR(J26/$J$29*100,"-") -> - | L26: =IFERROR(100*(H26-J26)/J26,"-") -> - | M26: =H26-J26 -> 0
D27: 家族 | G27: 〃 | I27: =IFERROR(H27/$H$29*100,"-") -> - | K27: =IFERROR(J27/$J$29*100,"-") -> - | L27: =IFERROR(100*(H27-J27)/J27,"-") -> - | M27: =H27-J27 -> 0
C28: 間接労働費 | G28: 〃 | I28: =IFERROR(H28/$H$29*100,"-") -> - | K28: =IFERROR(J28/$J$29*100,"-") -> - | L28: =IFERROR(100*(H28-J28)/J28,"-") -> - | M28: =H28-J28 -> 0
B29: 費用合計 | G29: 〃 | I29: =IFERROR(H29/$H$29*100,"-") -> - | K29: =IFERROR(J29/$J$29*100,"-") -> - | L29: =IFERROR(100*(H29-J29)/J29,"-") -> - | M29: =H29-J29 -> 0
B30: 副産物価額 | G30: 〃 | L30: =IFERROR(100*(H30-J30)/J30,"-") -> - | M30: =H30-J30 -> 0
B31: 生産費（副産物価額差引） | G31: 〃 | L31: =IFERROR(100*(H31-J31)/J31,"-") -> - | M31: =H31-J31 -> 0
B32: 支払利子 | G32: 〃 | L32: =IFERROR(100*(H32-J32)/J32,"-") -> - | M32: =H32-J32 -> 0
B33: 支払地代 | G33: 〃 | L33: =IFERROR(100*(H33-J33)/J33,"-") -> - | M33: =H33-J33 -> 0
B34: 支払利子・地代算入生産費 | G34: 〃 | L34: =IFERROR(100*(H34-J34)/J34,"-") -> - | M34: =H34-J34 -> 0
B35: 自己資本利子 | G35: 〃 | L35: =IFERROR(100*(H35-J35)/J35,"-") -> - | M35: =H35-J35 -> 0
B36: 自作地地代 | G36: 〃 | L36: =IFERROR(100*(H36-J36)/J36,"-") -> - | M36: =H36-J36 -> 0
B37: 資本利子・地代全算入生産費 | G37: 〃 | L37: =IFERROR(100*(H37-J37)/J37,"-") -> - | M37: =H37-J37 -> 0
A38: 60kg当たり生産費 | G38: 〃 | L38: =IFERROR(100*(H38-J38)/J38,"-") -> - | M38: =H38-J38 -> 0
A39: 60kg当たり支払利子・地代算入生産費 | G39: 〃 | L39: =IFERROR(100*(H39-J39)/J39,"-") -> - | M39: =H39-J39 -> 0
A40: 60kg当たり全算入生産費 | G40: 〃 | L40: =IFERROR(100*(H40-J40)/J40,"-") -> - | M40: =H40-J40 -> 0
A41: 経営概況 | B41: 10ａ当たり収量 | G41: kg | L41: =IFERROR(100*(H41-J41)/J41,"-") -> - | M41: =H41-J41 -> 0
B42: 10ａ当たり粗収益 | G42: 円 | L42: =IFERROR(100*(H42-J42)/J42,"-") -> - | M42: =H42-J42 -> 0
...

Sheet No.2
A1: =No.1!A1&"年産 米生産費統計（個別経営体） 個別結果検討表 №２" -> 2019年産 米生産費統計（個別経営体） 個別結果検討表 №２ | AJ1: センサス番号
AJ2: =IF(No.1!O2="","",No.1!O2)
A4: 【労働時間（10ａ当たり）】 | Q4: 【生産物の概要（10ａ当たり）】 | AG4: 【稲作作業の委託状況（１経営体当たり）】
G5: =No.1!H5 -> 19 | J5: =G5-1 -> 18 | M5: 増減率 | W5: =$G$5 -> 19 | Z5: =$J$5 -> 18 | AC5: 増減率 | AL5: =$G$5 -> 19 | AO5: =$J$5 -> 18 | AR5: 増減率
M6: （％） | AC6: （％） | AR6: （％）
A7: 労働時間計 | M7: =IFERROR(100*(G7-J7)/J7,"-") -> - | Q7: 主産物 | R7: 数量（kg） | AC7: =IFERROR(100*(W7-Z7)/Z7,"-") -> - | AG7: 育苗 | AK7: ａ | AR7: =IFERROR(100*(AL7-AO7)/AO7,"-") -> -
B8: 直接労働時間 | M8: =IFERROR(100*(G8-J8)/J8,"-") -> - | R8: 価額 | AC8: =IFERROR(100*(W8-Z8)/Z8,"-") -> - | AG8: 耕うん・整地 | AK8: ａ | AR8: =IFERROR(100*(AL8-AO8)/AO8,"-") -> -
C9: 種子予措 | M9: =IFERROR(100*(G9-J9)/J9,"-") -> - | Q9: 副産物 | R9: くず米 | T9: 数量（kg） | AC9: =IFERROR(100*(W9-Z9)/Z9,"-") -> - | AG9: 田植 | AK9: ａ | AR9: =IFERROR(100*(AL9-AO9)/AO9,"-") -> -
C10: 育苗 | M10: =IFERROR(100*(G10-J10)/J10,"-") -> - | T10: 価額 | AC10: =IFERROR(100*(W10-Z10)/Z10,"-") -> - | AG10: 防除 | AK10: ａ | AR10: =IFERROR(100*(AL10-AO10)/AO10,"-") -> -
C11: 耕起整地 | M11: =IFERROR(100*(G11-J11)/J11,"-") -> - | R11: 稲わら (もみがら含む) | T11: 数量（kg） | AC11: =IFERROR(100*(W11-Z11)/Z11,"-") -> - | AG11: 刈取・脱穀 | AK11: ａ | AR11: =IFERROR(100*(AL11-AO11)/AO11,"-") -> -
C12: 基肥 | M12: =IFERROR(100*(G12-J12)/J12,"-") -> - | T12: 価額 | AC12: =IFERROR(100*(W12-Z12)/Z12,"-") -> - | AG12: 乾燥・調製 | AK12: kg | AR12: =IFERROR(100*(AL12-AO12)/AO12,"-") -> -
C13: 直まき | M13: =IFERROR(100*(G13-J13)/J13,"-") -> - | Q13: 粗収益 | AC13: =IFERROR(100*(W13-Z13)/Z13,"-") -> - | AH13: ライスセンター | AK13: kg | AR13: =IFERROR(100*(AL13-AO13)/AO13,"-") -> -
C14: 田植 | M14: =IFERROR(100*(G14-J14)/J14,"-") -> - | Q14: 所得 | AC14: =IFERROR(100*(W14-Z14)/Z14,"-") -> - | AH14: カントリーエレベーター | AK14: kg | AR14: =IFERROR(100*(AL14-AO14)/AO14,"-") -> -
C15: 追肥 | M15: =IFERROR(100*(G15-J15)/J15,"-") -> - | R15: １日当たり | AC15: =IFERROR(100*(W15-Z15)/Z15,"-") -> -
C16: 除草 | M16: =IFERROR(100*(G16-J16)/J16,"-") -> - | Q16: 家族労働報酬 | AC16: =IFERROR(100*(W16-Z16)/Z16,"-") -> -
C17: 管理 | M17: =IFERROR(100*(G17-J17)/J17,"-") -> - | R17: １日当たり | AC17: =IFERROR(100*(W17-Z17)/Z17,"-") -> -
C18: 防除 | M18: =IFERROR(100*(G18-J18)/J18,"-") -> - | Q18: （参考）各種助成措置を加えた場合
C19: 刈取脱穀 | M19: =IFERROR(100*(G19-J19)/J19,"-") -> - | R19: 粗収益 | AC19: =IFERROR(100*(W19-Z19)/Z19,"-") -> -
C20: 乾燥 | M20: =IFERROR(100*(G20-J20)/J20,"-") -> - | R20: 所得 | AC20: =IFERROR(100*(W20-Z20)/Z20,"-") -> -
C21: 生産管理 | M21: =IFERROR(100*(G21-J21)/J21,"-") -> - | S21: １日当たり | AC21: =IFERROR(100*(W21-Z21)/Z21,"-") -> -
B22: 間接労働時間 | M22: =IFERROR(100*(G22-J22)/J22,"-") -> - | R22: 家族労働報酬 | AC22: =IFERROR(100*(W22-Z22)/Z22,"-") -> -
A23: 家族労働時間 | M23: =IFERROR(100*(G23-J23)/J23,"-") -> - | S23: １日当たり | AC23: =IFERROR(100*(W23-Z23)/Z23,"-") -> -
B24: 男 | M24: =IFERROR(100*(G24-J24)/J24,"-") -> -
B25: 女 | M25: =IFERROR(100*(G25-J25)/J25,"-") -> -
A26: 雇用労働時間 | M26: =IFERROR(100*(G26-J26)/J26,"-") -> -
B27: 男 | M27: =IFERROR(100*(G27-J27)/J27,"-") -> -
B28: 女 | M28: =IFERROR(100*(G28-J28)/J28,"-") -> -
A30: 【作付面積、地代】
G31: 自作地 | P31: 借入地 | Y31: 計
G32: =$G$5 -> 19 | J32: =$J$5 -> 18 | M32: 増減率 | P32: =$G$5 -> 19 | S32: =$J$5 -> 18 | V32: 増減率 | Y32: =$G$5 -> 19 | AB32: =$J$5 -> 18 | AE32: 増減率
M33: （％） | V33: （％） | AE33: （％）
A34: 作付地 | C34: 作付実面積 | F34: （ａ） | M34: =IFERROR(100*(G34-J34)/J34,"-") -> - | V34: =IFERROR(100*(P34-S34)/S34,"-") -> - | AE34: =IFERROR(100*(Y34-AB34)/AB34,"-") -> -
C35: 土地台帳面積 | F35: （ａ） | M35: =IFERROR(100*(G35-J35)/J35,"-") -> - | V35: =IFERROR(100*(P35-S35)/S35,"-") -> - | AE35: =IFERROR(100*(Y35-AB35)/AB35,"-") -> -
C36: 10ａ当たり地代総額 | F36: （円） | M36: =IFERROR(100*(G36-J36)/J36,"-") -> - | V36: =IFERROR(100*(P36-S36)/S36,"-") -> - | AE36: =IFERROR(100*(Y36-AB36)/AB36,"-") -> -
C37: 10ａ当たり負担地代 | F37: （円） | M37: =IFERROR(100*(G37-J37)/J37,"-") -> - | V37: =IFERROR(100*(P37-S37)/S37,"-") -> - | AE37: =IFERROR(100*(Y37-AB37)/AB37,"-") -> -
A38: 作付地 以外 | C38: 使用面積 | F38: （ａ） | M38: =IFERROR(100*(G38-J38)/J38,"-") -> - | V38: =IFERROR(100*(P38-S38)/S38,"-") -> - | AE38: =IFERROR(100*(Y38-AB38)/AB38,"-") -> -
C39: 10ａ当たり賃借料総額 | F39: （円） | M39: =IFERROR(100*(G39-J39)/J39,"-") -> - | V39: =IFERROR(100*(P39-S39)/S39,"-") -> - | AE39: =IFERROR(100*(Y39-AB39)/AB39,"-") -> -
C40: 10ａ当たり負担地代 | F40: （円） | M40: =IFERROR(100*(G40-J40)/J40,"-") -> - | V40: =IFERROR(100*(P40-S40)/S40,"-") -> - | AE40: =IFERROR(100*(Y40-AB40)/AB40,"-") -> -
A41: 10ａ当たり実勢地代 | F41: （円） | M41: =IFERROR(100*(G41-J41)/J41,"-") -> - | V41: =IFERROR(100*(P41-S41)/S41,"-") -> - | AE41: =IFERROR(100*(Y41-AB41)/AB41,"-") -> -

Sheet No.3
A1: =No.1!A1&"年産 米生産費統計（個別経営体） 個別結果検討表 №３" -> 2019年産 米生産費統計（個別経営体） 個別結果検討表 №３ | M1: センサス番号
M2: =IF(No.1!O2="","",No.1!O2)
A4: 【生産物の処分内訳（10ａ当たり）】
G5: =No.1!H5 -> 19 | J5: =G5-1 -> 18 | M5: 増 減 率
G6: 数量 | H6: 価額 | I6: 単価 | J6: 数量 | K6: 価額 | L6: 単価 | M6: 数量 | N6: 価額 | O6: 単価
G7: （kg） | H7: （円） | I7: （円） | J7: （kg） | K7: （円） | L7: （円） | M7: （％） | N7: （％） | O7: （％）
A8: 玄米（予定を含む） | B8: 販売用 | C8: 主食用 | M8: =IFERROR(100*(G8-J8)/J8,"-") -> - | N8: =IFERROR(100*(H8-K8)/K8,"-") -> - | O8: =IFERROR(100*(I8-L8)/L8,"-") -> -
C9: 加工用 | M9: =IFERROR(100*(G9-J9)/J9,"-") -> - | N9: =IFERROR(100*(H9-K9)/K9,"-") -> - | O9: =IFERROR(100*(I9-L9)/L9,"-") -> -
C10: 区分出荷 | M10: =IFERROR(100*(G10-J10)/J10,"-") -> - | N10: =IFERROR(100*(H10-K10)/K10,"-") -> - | O10: =IFERROR(100*(I10-L10)/L10,"-") -> -
C11: 小計 | M11: =IFERROR(100*(G11-J11)/J11,"-") -> - | N11: =IFERROR(100*(H11-K11)/K11,"-") -> - | O11: =IFERROR(100*(I11-L11)/L11,"-") -> -
B12: 自家用 | C12: 種子用 | M12: =IFERROR(100*(G12-J12)/J12,"-") -> - | N12: =IFERROR(100*(H12-K12)/K12,"-") -> - | O12: =IFERROR(100*(I12-L12)/L12,"-") -> -
C13: 飯米用 | M13: =IFERROR(100*(G13-J13)/J13,"-") -> - | N13: =IFERROR(100*(H13-K13)/K13,"-") -> - | O13: =IFERROR(100*(I13-L13)/L13,"-") -> -
C14: その他 | M14: =IFERROR(100*(G14-J14)/J14,"-") -> - | N14: =IFERROR(100*(H14-K14)/K14,"-") -> - | O14: =IFERROR(100*(I14-L14)/L14,"-") -> -
C15: 小計 | M15: =IFERROR(100*(G15-J15)/J15,"-") -> - | N15: =IFERROR(100*(H15-K15)/K15,"-") -> - | O15: =IFERROR(100*(I15-L15)/L15,"-") -> -
B16: 合計 | M16: =IFERROR(100*(G16-J16)/J16,"-") -> - | N16: =IFERROR(100*(H16-K16)/K16,"-") -> - | O16: =IFERROR(100*(I16-L16)/L16,"-") -> -
A17: いなわら等 | B17: 販売 | C17: 加工用 | M17: =IFERROR(100*(G17-J17)/J17,"-") -> - | N17: =IFERROR(100*(H17-K17)/K17,"-") -> - | O17: =IFERROR(100*(I17-L17)/L17,"-") -> -
C18: その他 | M18: =IFERROR(100*(G18-J18)/J18,"-") -> - | N18: =IFERROR(100*(H18-K18)/K18,"-") -> - | O18: =IFERROR(100*(I18-L18)/L18,"-") -> -
B19: 自家用 | C19: 生わら | M19: =IFERROR(100*(G19-J19)/J19,"-") -> -
C20: 乾燥わら | M20: =IFERROR(100*(G20-J20)/J20,"-") -> - | N20: =IFERROR(100*(H20-K20)/K20,"-") -> - | O20: =IFERROR(100*(I20-L20)/L20,"-") -> -
C21: その他 | M21: =IFERROR(100*(G21-J21)/J21,"-") -> -
B22: いなわら小計 | M22: =IFERROR(100*(G22-J22)/J22,"-") -> - | N22: =IFERROR(100*(H22-K22)/K22,"-") -> -
B23: くず米 | M23: =IFERROR(100*(G23-J23)/J23,"-") -> - | N23: =IFERROR(100*(H23-K23)/K23,"-") -> - | O23: =IFERROR(100*(I23-L23)/L23,"-") -> -
B24: もみがら | M24: =IFERROR(100*(G24-J24)/J24,"-") -> - | N24: =IFERROR(100*(H24-K24)/K24,"-") -> - | O24: =IFERROR(100*(I24-L24)/L24,"-") -> -
B25: 合計 | N25: =IFERROR(100*(H25-K25)/K25,"-") -> -
A27: 【費用の内訳（10ａ当たり）】
G28: =G5 -> 19 | J28: =J5 -> 18 | M28: 増 減 率
G29: 数量 | H29: 価額 | I29: 単価 | J29: 数量 | K29: 価額 | L29: 単価 | M29: 数量 | N29: 価額 | O29: 単価
H30: （円） | I30: （円） | K30: （円） | L30: （円） | M30: （％） | N30: （％） | O30: （％）
A31: 種苗費 | N31: =IFERROR(100*(H31-K31)/K31,"-") -> -
B32: 種子もみ | D32: 購入 | F32: （kg） | M32: =IFERROR(100*(G32-J32)/J32,"-") -> - | N32: =IFERROR(100*(H32-K32)/K32,"-") -> - | O32: =IFERROR(100*(I32-L32)/L32,"-") -> -
D33: 自給 | F33: （kg） | M33: =IFERROR(100*(G33-J33)/J33,"-") -> - | N33: =IFERROR(100*(H33-K33)/K33,"-") -> - | O33: =IFERROR(100*(I33-L33)/L33,"-") -> -
B34: 苗 | F34: （ａ） | M34: =IFERROR(100*(G34-J34)/J34,"-") -> - | N34: =IFERROR(100*(H34-K34)/K34,"-") -> - | O34: =IFERROR(100*(I34-L34)/L34,"-") -> -
A35: 肥料費 | N35: =IFERROR(100*(H35-K35)/K35,"-") -> -
B36: 窒素質肥料 | F36: （kg） | M36: =IFERROR(100*(G36-J36)/J36,"-") -> - | N36: =IFERROR(100*(H36-K36)/K36,"-") -> - | O36: =IFERROR(100*(I36-L36)/L36,"-") -> -
B37: りん酸質肥料 | F37: （kg） | M37: =IFERROR(100*(G37-J37)/J37,"-") -> - | N37: =IFERROR(100*(H37-K37)/K37,"-") -> - | O37: =IFERROR(100*(I37-L37)/L37,"-") -> -
B38: カリ質肥料 | F38: （kg） | M38: =IFERROR(100*(G38-J38)/J38,"-") -> - | N38: =IFERROR(100*(H38-K38)/K38,"-") -> - | O38: =IFERROR(100*(I38-L38)/L38,"-") -> -
B39: けい酸質肥料 | F39: （kg） | M39: =IFERROR(100*(G39-J39)/J39,"-") -> - | N39: =IFERROR(100*(H39-K39)/K39,"-") -> - | O39: =IFERROR(100*(I39-L39)/L39,"-") -> -
B40: 炭酸カルシウム（石灰含む） | F40: （kg） | M40: =IFERROR(100*(G40-J40)/J40,"-") -> - | N40: =IFERROR(100*(H40-K40)/K40,"-") -> - | O40: =IFERROR(100*(I40-L40)/L40,"-") -> -
B41: 複合肥料 | F41: （kg） | M41: =IFERROR(100*(G41-J41)/J41,"-") -> - | N41: =IFERROR(100*(H41-K41)/K41,"-") -> - | O41: =IFERROR(100*(I41-L41)/L41,"-") -> -
B42: 土壌改良資材 | N42: =IFERROR(100*(H42-K42)/K42,"-") -> -
...

Sheet No.4
A1: =No.1!A1&"年産 米生産費統計（個別経営体） 個別結果検討表 №４" -> 2019年産 米生産費統計（個別経営体） 個別結果検討表 №４ | L1: センサス番号
L2: =IF(No.1!O2="","",No.1!O2)
A4: 【費用の内訳（10ａ当たり）（続き）】
F5: =No.1!H5 -> 19 | I5: =F5-1 -> 18 | L5: 増 減 率
F6: 数量 | G6: 価額 | H6: 単価 | I6: 数量 | J6: 価額 | K6: 単価 | L6: 数量 | M6: 価額 | N6: 単価
G7: （円） | H7: （円） | J7: （円） | K7: （円） | L7: （％） | M7: （％） | N7: （％）
A8: 農業薬剤費 | M8: =IFERROR(100*(G8-J8)/J8,"-") -> -
B9: 殺虫剤 | M9: =IFERROR(100*(G9-J9)/J9,"-") -> -
B10: 殺菌剤 | M10: =IFERROR(100*(G10-J10)/J10,"-") -> -
B11: 殺虫殺菌剤 | M11: =IFERROR(100*(G11-J11)/J11,"-") -> -
B12: 除草剤 | M12: =IFERROR(100*(G12-J12)/J12,"-") -> -
B13: その他 | M13: =IFERROR(100*(G13-J13)/J13,"-") -> -
A14: 光熱動力費 | M14: =IFERROR(100*(G14-J14)/J14,"-") -> -
B15: 動力燃料 | C15: 重油 | E15: （L） | L15: =IFERROR(100*(F15-I15)/I15,"-") -> - | M15: =IFERROR(100*(G15-J15)/J15,"-") -> - | N15: =IFERROR(100*(H15-K15)/K15,"-") -> -
C16: 軽油 | E16: （L） | L16: =IFERROR(100*(F16-I16)/I16,"-") -> - | M16: =IFERROR(100*(G16-J16)/J16,"-") -> - | N16: =IFERROR(100*(H16-K16)/K16,"-") -> -
C17: 灯油 | E17: （L） | L17: =IFERROR(100*(F17-I17)/I17,"-") -> - | M17: =IFERROR(100*(G17-J17)/J17,"-") -> - | N17: =IFERROR(100*(H17-K17)/K17,"-") -> -
C18: ガソリン | E18: （L） | L18: =IFERROR(100*(F18-I18)/I18,"-") -> - | M18: =IFERROR(100*(G18-J18)/J18,"-") -> - | N18: =IFERROR(100*(H18-K18)/K18,"-") -> -
C19: 潤滑油 | E19: （L） | L19: =IFERROR(100*(F19-I19)/I19,"-") -> - | M19: =IFERROR(100*(G19-J19)/J19,"-") -> - | N19: =IFERROR(100*(H19-K19)/K19,"-") -> -
C20: 混合油 | E20: （L） | L20: =IFERROR(100*(F20-I20)/I20,"-") -> - | M20: =IFERROR(100*(G20-J20)/J20,"-") -> - | N20: =IFERROR(100*(H20-K20)/K20,"-") -> -
B21: 電力料 | M21: =IFERROR(100*(G21-J21)/J21,"-") -> -
B22: その他 | M22: =IFERROR(100*(G22-J22)/J22,"-") -> -
B23: 自給 | M23: =IFERROR(100*(G23-J23)/J23,"-") -> -
A24: その他の諸材料費 | M24: =IFERROR(100*(G24-J24)/J24,"-") -> -
B25: 育苗用土（購入）（素土を含む） | E25: （kg） | L25: =IFERROR(100*(F25-I25)/I25,"-") -> - | M25: =IFERROR(100*(G25-J25)/J25,"-") -> - | N25: =IFERROR(100*(H25-K25)/K25,"-") -> -
B26: その他 | M26: =IFERROR(100*(G26-J26)/J26,"-") -> -
B27: 自給 | M27: =IFERROR(100*(G27-J27)/J27,"-") -> -
A28: 土地改良及び水利費 | M28: =IFERROR(100*(G28-J28)/J28,"-") -> -
B29: 土地改 良区費 | D29: 維持負担金 | M29: =IFERROR(100*(G29-J29)/J29,"-") -> -
D30: 償還金 | M30: =IFERROR(100*(G30-J30)/J30,"-") -> -
B31: 水利組合費 | M31: =IFERROR(100*(G31-J31)/J31,"-") -> -
B32: 揚水ポンプ組合費 | M32: =IFERROR(100*(G32-J32)/J32,"-") -> -
B33: その他 | M33: =IFERROR(100*(G33-J33)/J33,"-") -> -
A34: 賃借料及び料金 | M34: =IFERROR(100*(G34-J34)/J34,"-") -> -
B35: 共 同 負担金 | D35: 薬剤散布 | M35: =IFERROR(100*(G35-J35)/J35,"-") -> -
D36: 共同施設 | M36: =IFERROR(100*(G36-J36)/J36,"-") -> -
D37: 共同苗代 | M37: =IFERROR(100*(G37-J37)/J37,"-") -> -
B38: 農機具借料 | M38: =IFERROR(100*(G38-J38)/J38,"-") -> -
B39: 航空防除賃 | E39: （ａ） | L39: =IFERROR(100*(F39-I39)/I39,"-") -> - | M39: =IFERROR(100*(G39-J39)/J39,"-") -> - | N39: =IFERROR(100*(H39-K39)/K39,"-") -> -
B40: 賃耕料 | E40: （ａ） | L40: =IFERROR(100*(F40-I40)/I40,"-") -> - | M40: =IFERROR(100*(G40-J40)/J40,"-") -> - | N40: =IFERROR(100*(H40-K40)/K40,"-") -> -
B41: は種・田植賃 | E41: （ａ） | L41: =IFERROR(100*(F41-I41)/I41,"-") -> - | M41: =IFERROR(100*(G41-J41)/J41,"-") -> - | N41: =IFERROR(100*(H41-K41)/K41,"-") -> -
...

Sheet No.5
A1: =No.1!A1&"年産 米生産費統計（個別経営体） 個別結果検討表 №５" -> 2019年産 米生産費統計（個別経営体） 個別結果検討表 №５ | AH1: センサス番号
AH2: =IF(No.1!O2="","",No.1!O2)
A4: 【費用の内訳（10ａ当たり）（続き）】
G5: =No.1!H5 -> 19 | J5: =G5-1 -> 18 | M5: 増減率 | X5: 所 有 台 数（ １ 経 営 体 当 た り ） | AG5: 調 査 作 物 負 担 分 （ 1 0 ａ 当 た り ）
G6: （円） | J6: （円） | M6: （％） | X6: =$G$5 -> 19 | AA6: =$J$5 -> 18 | AD6: 増減率 | AG6: =$G$5 -> 19 | AJ6: =$J$5 -> 18 | AM6: 増減率
A7: 物件税 | M7: =IFERROR(100*(G7-J7)/J7,"-") -> - | X7: （台） | AA7: （台） | AD7: （％） | AG7: （円） | AJ7: （円） | AM7: （％）
B8: 固定資産税 | M8: =IFERROR(100*(G8-J8)/J8,"-") -> - | Q8: 減価償却費 | AM8: =IFERROR(100*(AG8-AJ8)/AJ8,"-") -> -
C9: 建物 | M9: =IFERROR(100*(G9-J9)/J9,"-") -> - | R9: 建物・構築物 | AM9: =IFERROR(100*(AG9-AJ9)/AJ9,"-") -> -
C10: 農機具 | M10: =IFERROR(100*(G10-J10)/J10,"-") -> - | T10: 処分差損失 | AM10: =IFERROR(100*(AG10-AJ10)/AJ10,"-") -> -
B11: 自動車重量税 | M11: =IFERROR(100*(G11-J11)/J11,"-") -> - | S11: 住宅 | AM11: =IFERROR(100*(AG11-AJ11)/AJ11,"-") -> -
B12: 自動車税 | M12: =IFERROR(100*(G12-J12)/J12,"-") -> - | S12: 納屋・倉庫 | AM12: =IFERROR(100*(AG12-AJ12)/AJ12,"-") -> -
B13: 不動産取得税 | M13: =IFERROR(100*(G13-J13)/J13,"-") -> - | S13: 用水路 | AM13: =IFERROR(100*(AG13-AJ13)/AJ13,"-") -> -
B14: 自動車取得税 | M14: =IFERROR(100*(G14-J14)/J14,"-") -> - | S14: 暗きょ排水施設 | AM14: =IFERROR(100*(AG14-AJ14)/AJ14,"-") -> -
B15: 軽自動車税 | M15: =IFERROR(100*(G15-J15)/J15,"-") -> - | S15: コンクリートけい畔 | AM15: =IFERROR(100*(AG15-AJ15)/AJ15,"-") -> -
B16: 水利地益税 | M16: =IFERROR(100*(G16-J16)/J16,"-") -> - | S16: 客土 | AM16: =IFERROR(100*(AG16-AJ16)/AJ16,"-") -> -
B17: 都市計画税 | M17: =IFERROR(100*(G17-J17)/J17,"-") -> - | S17: たい肥盤 | AM17: =IFERROR(100*(AG17-AJ17)/AJ17,"-") -> -
B18: 共同施設税 | M18: =IFERROR(100*(G18-J18)/J18,"-") -> - | S18: その他 | AM18: =IFERROR(100*(AG18-AJ18)/AJ18,"-") -> -
A19: 公課諸負担 | M19: =IFERROR(100*(G19-J19)/J19,"-") -> - | R19: 自動車 | AM19: =IFERROR(100*(AG19-AJ19)/AJ19,"-") -> -
B20: 集落協議会費 | M20: =IFERROR(100*(G20-J20)/J20,"-") -> - | T20: 処分差損失 | AM20: =IFERROR(100*(AG20-AJ20)/AJ20,"-") -> -
B21: 農業協同組合費 | M21: =IFERROR(100*(G21-J21)/J21,"-") -> - | S21: 貨物自動車 | AD21: =IFERROR(100*(X21-AA21)/AA21,"-") -> - | AM21: =IFERROR(100*(AG21-AJ21)/AJ21,"-") -> -
B22: 農事実行組合費 | M22: =IFERROR(100*(G22-J22)/J22,"-") -> - | S22: その他 | AM22: =IFERROR(100*(AG22-AJ22)/AJ22,"-") -> -
B23: 農業共済組合賦課金 | M23: =IFERROR(100*(G23-J23)/J23,"-") -> - | R23: 農機具 | AM23: =IFERROR(100*(AG23-AJ23)/AJ23,"-") -> -
B24: 自賠責保険 | M24: =IFERROR(100*(G24-J24)/J24,"-") -> - | T24: 処分差損失 | AM24: =IFERROR(100*(AG24-AJ24)/AJ24,"-") -> -
A25: 借入金・調査開始時残高合計 | M25: =IFERROR(100*(G25-J25)/J25,"-") -> - | S25: 電動機 | AD25: =IFERROR(100*(X25-AA25)/AA25,"-") -> - | AM25: =IFERROR(100*(AG25-AJ25)/AJ25,"-") -> -
A26: 借入金 | C26: 短期 | M26: =IFERROR(100*(G26-J26)/J26,"-") -> - | S26: 発動機 | AD26: =IFERROR(100*(X26-AA26)/AA26,"-") -> - | AM26: =IFERROR(100*(AG26-AJ26)/AJ26,"-") -> -
C27: 長期 | M27: =IFERROR(100*(G27-J27)/J27,"-") -> - | S27: 揚水ポンプ | AD27: =IFERROR(100*(X27-AA27)/AA27,"-") -> - | AM27: =IFERROR(100*(AG27-AJ27)/AJ27,"-") -> -
A28: 買掛未払金 | M28: =IFERROR(100*(G28-J28)/J28,"-") -> - | S28: 乗 用 トラク タ ー | U28: 20馬力未満 | AD28: =IFERROR(100*(X28-AA28)/AA28,"-") -> - | AM28: =IFERROR(100*(AG28-AJ28)/AJ28,"-") -> -
U29: 20～50馬力未満 | AD29: =IFERROR(100*(X29-AA29)/AA29,"-") -> - | AM29: =IFERROR(100*(AG29-AJ29)/AJ29,"-") -> -
U30: 50馬力以上 | AD30: =IFERROR(100*(X30-AA30)/AA30,"-") -> - | AM30: =IFERROR(100*(AG30-AJ30)/AJ30,"-") -> -
S31: 歩行用トラクター | AD31: =IFERROR(100*(X31-AA31)/AA31,"-") -> - | AM31: =IFERROR(100*(AG31-AJ31)/AJ31,"-") -> -
S32: 電熱育苗機 | AD32: =IFERROR(100*(X32-AA32)/AA32,"-") -> - | AM32: =IFERROR(100*(AG32-AJ32)/AJ32,"-") -> -
S33: 田植機 | U33: ２条植 | AD33: =IFERROR(100*(X33-AA33)/AA33,"-") -> - | AM33: =IFERROR(100*(AG33-AJ33)/AJ33,"-") -> -
U34: ３～５条植 | AD34: =IFERROR(100*(X34-AA34)/AA34,"-") -> - | AM34: =IFERROR(100*(AG34-AJ34)/AJ34,"-") -> -
U35: ６条植以上 | AD35: =IFERROR(100*(X35-AA35)/AA35,"-") -> - | AM35: =IFERROR(100*(AG35-AJ35)/AJ35,"-") -> -
S36: 動力噴霧機 | AD36: =IFERROR(100*(X36-AA36)/AA36,"-") -> - | AM36: =IFERROR(100*(AG36-AJ36)/AJ36,"-") -> -
S37: 動力散粉機 | AD37: =IFERROR(100*(X37-AA37)/AA37,"-") -> - | AM37: =IFERROR(100*(AG37-AJ37)/AJ37,"-") -> -
S38: バインダー | AD38: =IFERROR(100*(X38-AA38)/AA38,"-") -> - | AM38: =IFERROR(100*(AG38-AJ38)/AJ38,"-") -> -
S39: 自脱型コ ンバイン | U39: ３条以下 | AD39: =IFERROR(100*(X39-AA39)/AA39,"-") -> - | AM39: =IFERROR(100*(AG39-AJ39)/AJ39,"-") -> -
U40: ４条以上 | AD40: =IFERROR(100*(X40-AA40)/AA40,"-") -> - | AM40: =IFERROR(100*(AG40-AJ40)/AJ40,"-") -> -
S41: 普通型コンバイン | AD41: =IFERROR(100*(X41-AA41)/AA41,"-") -> - | AM41: =IFERROR(100*(AG41-AJ41)/AJ41,"-") -> -
...

Sheet No.6
A1: =No.1!A1&"年産 米生産費統計（個別経営体） 個別結果検討表 №６" -> 2019年産 米生産費統計（個別経営体） 個別結果検討表 №６ | M1: センサス番号
M2: =IF(No.1!O2="","",No.1!O2)
A4: 【飼料用米の生産費】
A5: 区 分 | G5: 単位 | H5: =No.1!H5 -> 19 | I5: =H5-1 -> 18 | J5: 増減率 | K5: 増減差 | L5: 主 な 増 減 要 因
J6: （％）
A7: 10 ａ 当 た り 生 産 費 | B7: 物財費 | G7: 円 | J7: =IFERROR(100*(H7-I7)/I7,"-") -> - | K7: =H7-I7 -> 0
C8: 種苗費 | G8: 〃 | J8: =IFERROR(100*(H8-I8)/I8,"-") -> - | K8: =H8-I8 -> 0
C9: 肥料費 | G9: 〃 | J9: =IFERROR(100*(H9-I9)/I9,"-") -> - | K9: =H9-I9 -> 0
C10: 農業薬剤費 | G10: 〃 | J10: =IFERROR(100*(H10-I10)/I10,"-") -> - | K10: =H10-I10 -> 0
C11: 光熱動力費 | G11: 〃 | J11: =IFERROR(100*(H11-I11)/I11,"-") -> - | K11: =H11-I11 -> 0
C12: その他の諸材料費 | G12: 〃 | J12: =IFERROR(100*(H12-I12)/I12,"-") -> - | K12: =H12-I12 -> 0
C13: 賃借料及び料金 | G13: 〃 | J13: =IFERROR(100*(H13-I13)/I13,"-") -> - | K13: =H13-I13 -> 0
C14: 物件税及び公課諸負担 | G14: 〃 | J14: =IFERROR(100*(H14-I14)/I14,"-") -> - | K14: =H14-I14 -> 0
C15: 農機具費 | G15: 〃 | J15: =IFERROR(100*(H15-I15)/I15,"-") -> - | K15: =H15-I15 -> 0
A16: 10 ａ 当 た り 作 業 別 労 動 時 間 | B16: 種子予措 | G16: 時間 | J16: =IFERROR(100*(H16-I16)/I16,"-") -> - | K16: =H16-I16 -> 0
B17: 育苗 | G17: 〃 | J17: =IFERROR(100*(H17-I17)/I17,"-") -> - | K17: =H17-I17 -> 0
B18: 耕起整地 | G18: 〃 | J18: =IFERROR(100*(H18-I18)/I18,"-") -> - | K18: =H18-I18 -> 0
B19: 基肥 | G19: 〃 | J19: =IFERROR(100*(H19-I19)/I19,"-") -> - | K19: =H19-I19 -> 0
B20: 直まき | G20: 〃 | J20: =IFERROR(100*(H20-I20)/I20,"-") -> - | K20: =H20-I20 -> 0
B21: 田植 | G21: 〃 | J21: =IFERROR(100*(H21-I21)/I21,"-") -> - | K21: =H21-I21 -> 0
B22: 追肥 | G22: 〃 | J22: =IFERROR(100*(H22-I22)/I22,"-") -> - | K22: =H22-I22 -> 0
B23: 除草 | G23: 〃 | J23: =IFERROR(100*(H23-I23)/I23,"-") -> - | K23: =H23-I23 -> 0
B24: 管理 | G24: 〃 | J24: =IFERROR(100*(H24-I24)/I24,"-") -> - | K24: =H24-I24 -> 0
B25: 防除 | G25: 〃 | J25: =IFERROR(100*(H25-I25)/I25,"-") -> - | K25: =H25-I25 -> 0
B26: 刈取脱穀 | G26: 〃 | J26: =IFERROR(100*(H26-I26)/I26,"-") -> - | K26: =H26-I26 -> 0
B27: 乾燥 | G27: 〃 | J27: =IFERROR(100*(H27-I27)/I27,"-") -> - | K27: =H27-I27 -> 0
A28: １経営体当たり飼料用米作付面積 | G28: ａ | J28: =IFERROR(100*(H28-I28)/I28,"-") -> - | K28: =H28-I28 -> 0
