Workbook

Sheet No.1
A1: 2019 | C1: 年産 米生産費統計（組織法人経営体） 個別結果検討表 №１ | O1: センサス番号
A4: 【生産費】
A5: 区 分 | G5: 単位 | H5: =A1-2000 -> 19 | I5: 構成割合 | J5: =H5-1 -> 18 | K5: 構成割合 | L5: 増減率 | M5: 増減差 | N5: 主 な 増 減 要 因
I6: （％） | K6: （％） | L6: （％）
A7: 10 ａ 当 た り 生 産 費 | B7: 物財費 | G7: 円 | I7: =IFERROR(H7/$H$29*100,"-") -> - | K7: =IFERROR(J7/$J$29*100,"-") -> - | L7: =IF(H7="-", "-", IF(J7="-", "-", IF(ABS(J7)=0, "-", ROUND(100*(H7-J7)/ABS(J7),1)))) -> - | M7: =H7-J7 -> 0
C8: 種苗費 | G8: 〃 | I8: =IFERROR(H8/$H$29*100,"-") -> - | K8: =IFERROR(J8/$J$29*100,"-") -> - | L8: =IF(H8="-", "-", IF(J8="-", "-", IF(ABS(J8)=0, "-", ROUND(100*(H8-J8)/ABS(J8),1)))) -> - | M8: =H8-J8 -> 0
C9: 肥料費 | G9: 〃 | I9: =IFERROR(H9/$H$29*100,"-") -> - | K9: =IFERROR(J9/$J$29*100,"-") -> - | L9: =IF(H9="-", "-", IF(J9="-", "-", IF(ABS(J9)=0, "-", ROUND(100*(H9-J9)/ABS(J9),1)))) -> - | M9: =H9-J9 -> 0
C10: 農業薬剤費 | G10: 〃 | I10: =IFERROR(H10/$H$29*100,"-") -> - | K10: =IFERROR(J10/$J$29*100,"-") -> - | L10: =IF(H10="-", "-", IF(J10="-", "-", IF(ABS(J10)=0, "-", ROUND(100*(H10-J10)/ABS(J10),1)))) -> - | M10: =H10-J10 -> 0
C11: 光熱動力費 | G11: 〃 | I11: =IFERROR(H11/$H$29*100,"-") -> - | K11: =IFERROR(J11/$J$29*100,"-") -> - | L11: =IF(H11="-", "-", IF(J11="-", "-", IF(ABS(J11)=0, "-", ROUND(100*(H11-J11)/ABS(J11),1)))) -> - | M11: =H11-J11 -> 0
C12: その他の諸材料費 | G12: 〃 | I12: =IFERROR(H12/$H$29*100,"-") -> - | K12: =IFERROR(J12/$J$29*100,"-") -> - | L12: =IF(H12="-", "-", IF(J12="-", "-", IF(ABS(J12)=0, "-", ROUND(100*(H12-J12)/ABS(J12),1)))) -> - | M12: =H12-J12 -> 0
C13: 土地改良及び水利費 | G13: 〃 | I13: =IFERROR(H13/$H$29*100,"-") -> - | K13: =IFERROR(J13/$J$29*100,"-") -> - | L13: =IF(H13="-", "-", IF(J13="-", "-", IF(ABS(J13)=0, "-", ROUND(100*(H13-J13)/ABS(J13),1)))) -> - | M13: =H13-J13 -> 0
C14: 賃借料及び料金 | G14: 〃 | I14: =IFERROR(H14/$H$29*100,"-") -> - | K14: =IFERROR(J14/$J$29*100,"-") -> - | L14: =IF(H14="-", "-", IF(J14="-", "-", IF(ABS(J14)=0, "-", ROUND(100*(H14-J14)/ABS(J14),1)))) -> - | M14: =H14-J14 -> 0
C15: 物件税及び公課諸負担 | G15: 〃 | I15: =IFERROR(H15/$H$29*100,"-") -> - | K15: =IFERROR(J15/$J$29*100,"-") -> - | L15: =IF(H15="-", "-", IF(J15="-", "-", IF(ABS(J15)=0, "-", ROUND(100*(H15-J15)/ABS(J15),1)))) -> - | M15: =H15-J15 -> 0
C16: 建物費 | G16: 〃 | I16: =IFERROR(H16/$H$29*100,"-") -> - | K16: =IFERROR(J16/$J$29*100,"-") -> - | L16: =IF(H16="-", "-", IF(J16="-", "-", IF(ABS(J16)=0, "-", ROUND(100*(H16-J16)/ABS(J16),1)))) -> - | M16: =H16-J16 -> 0
D17: 償却費 | G17: 〃 | I17: =IFERROR(H17/$H$29*100,"-") -> - | K17: =IFERROR(J17/$J$29*100,"-") -> - | L17: =IF(H17="-", "-", IF(J17="-", "-", IF(ABS(J17)=0, "-", ROUND(100*(H17-J17)/ABS(J17),1)))) -> - | M17: =H17-J17 -> 0
C18: 自動車費 | G18: 〃 | I18: =IFERROR(H18/$H$29*100,"-") -> - | K18: =IFERROR(J18/$J$29*100,"-") -> - | L18: =IF(H18="-", "-", IF(J18="-", "-", IF(ABS(J18)=0, "-", ROUND(100*(H18-J18)/ABS(J18),1)))) -> - | M18: =H18-J18 -> 0
D19: 償却費 | G19: 〃 | I19: =IFERROR(H19/$H$29*100,"-") -> - | K19: =IFERROR(J19/$J$29*100,"-") -> - | L19: =IF(H19="-", "-", IF(J19="-", "-", IF(ABS(J19)=0, "-", ROUND(100*(H19-J19)/ABS(J19),1)))) -> - | M19: =H19-J19 -> 0
C20: 農機具費 | G20: 〃 | I20: =IFERROR(H20/$H$29*100,"-") -> - | K20: =IFERROR(J20/$J$29*100,"-") -> - | L20: =IF(H20="-", "-", IF(J20="-", "-", IF(ABS(J20)=0, "-", ROUND(100*(H20-J20)/ABS(J20),1)))) -> - | M20: =H20-J20 -> 0
D21: 償却費 | G21: 〃 | I21: =IFERROR(H21/$H$29*100,"-") -> - | K21: =IFERROR(J21/$J$29*100,"-") -> - | L21: =IF(H21="-", "-", IF(J21="-", "-", IF(ABS(J21)=0, "-", ROUND(100*(H21-J21)/ABS(J21),1)))) -> - | M21: =H21-J21 -> 0
C22: 生産管理費 | G22: 〃 | I22: =IFERROR(H22/$H$29*100,"-") -> - | K22: =IFERROR(J22/$J$29*100,"-") -> - | L22: =IF(H22="-", "-", IF(J22="-", "-", IF(ABS(J22)=0, "-", ROUND(100*(H22-J22)/ABS(J22),1)))) -> - | M22: =H22-J22 -> 0
D23: 償却費 | G23: 〃 | I23: =IFERROR(H23/$H$29*100,"-") -> - | K23: =IFERROR(J23/$J$29*100,"-") -> - | L23: =IF(H23="-", "-", IF(J23="-", "-", IF(ABS(J23)=0, "-", ROUND(100*(H23-J23)/ABS(J23),1)))) -> - | M23: =H23-J23 -> 0
B24: 労働費 | G24: 〃 | I24: =IFERROR(H24/$H$29*100,"-") -> - | K24: =IFERROR(J24/$J$29*100,"-") -> - | L24: =IF(H24="-", "-", IF(J24="-", "-", IF(ABS(J24)=0, "-", ROUND(100*(H24-J24)/ABS(J24),1)))) -> - | M24: =H24-J24 -> 0
D25: 構成員 | G25: 〃 | I25: =IFERROR(H25/$H$29*100,"-") -> - | K25: =IFERROR(J25/$J$29*100,"-") -> - | L25: =IF(H25="-", "-", IF(J25="-", "-", IF(ABS(J25)=0, "-", ROUND(100*(H25-J25)/ABS(J25),1)))) -> - | M25: =H25-J25 -> 0
C26: 直接労働費 | G26: 〃 | I26: =IFERROR(H26/$H$29*100,"-") -> - | K26: =IFERROR(J26/$J$29*100,"-") -> - | L26: =IF(H26="-", "-", IF(J26="-", "-", IF(ABS(J26)=0, "-", ROUND(100*(H26-J26)/ABS(J26),1)))) -> - | M26: =H26-J26 -> 0
D27: 構成員 | G27: 〃 | I27: =IFERROR(H27/$H$29*100,"-") -> - | K27: =IFERROR(J27/$J$29*100,"-") -> - | L27: =IF(H27="-", "-", IF(J27="-", "-", IF(ABS(J27)=0, "-", ROUND(100*(H27-J27)/ABS(J27),1)))) -> - | M27: =H27-J27 -> 0
C28: 間接労働費 | G28: 〃 | I28: =IFERROR(H28/$H$29*100,"-") -> - | K28: =IFERROR(J28/$J$29*100,"-") -> - | L28: =IF(H28="-", "-", IF(J28="-", "-", IF(ABS(J28)=0, "-", ROUND(100*(H28-J28)/ABS(J28),1)))) -> - | M28: =H28-J28 -> 0
B29: 費用合計 | G29: 〃 | I29: =IFERROR(H29/$H$29*100,"-") -> - | K29: =IFERROR(J29/$J$29*100,"-") -> - | L29: =IF(H29="-", "-", IF(J29="-", "-", IF(ABS(J29)=0, "-", ROUND(100*(H29-J29)/ABS(J29),1)))) -> - | M29: =H29-J29 -> 0
B30: 副産物価額 | G30: 〃 | L30: =IF(H30="-", "-", IF(J30="-", "-", IF(ABS(J30)=0, "-", ROUND(100*(H30-J30)/ABS(J30),1)))) -> - | M30: =H30-J30 -> 0
B31: 生産費（副産物価額差引） | G31: 〃 | L31: =IF(H31="-", "-", IF(J31="-", "-", IF(ABS(J31)=0, "-", ROUND(100*(H31-J31)/ABS(J31),1)))) -> - | M31: =H31-J31 -> 0
B32: 支払利子 | G32: 〃 | L32: =IF(H32="-", "-", IF(J32="-", "-", IF(ABS(J32)=0, "-", ROUND(100*(H32-J32)/ABS(J32),1)))) -> - | M32: =H32-J32 -> 0
B33: 支払地代 | G33: 〃 | L33: =IF(H33="-", "-", IF(J33="-", "-", IF(ABS(J33)=0, "-", ROUND(100*(H33-J33)/ABS(J33),1)))) -> - | M33: =H33-J33 -> 0
B34: 支払利子・地代算入生産費 | G34: 〃 | L34: =IF(H34="-", "-", IF(J34="-", "-", IF(ABS(J34)=0, "-", ROUND(100*(H34-J34)/ABS(J34),1)))) -> - | M34: =H34-J34 -> 0
B35: 自己資本利子 | G35: 〃 | L35: =IF(H35="-", "-", IF(J35="-", "-", IF(ABS(J35)=0, "-", ROUND(100*(H35-J35)/ABS(J35),1)))) -> - | M35: =H35-J35 -> 0
B36: 自作地地代 | G36: 〃 | L36: =IF(H36="-", "-", IF(J36="-", "-", IF(ABS(J36)=0, "-", ROUND(100*(H36-J36)/ABS(J36),1)))) -> - | M36: =H36-J36 -> 0
B37: 資本利子・地代全算入生産費 | G37: 〃 | L37: =IF(H37="-", "-", IF(J37="-", "-", IF(ABS(J37)=0, "-", ROUND(100*(H37-J37)/ABS(J37),1)))) -> - | M37: =H37-J37 -> 0
A38: 60kg当たり生産費 | G38: 〃 | L38: =IF(H38="-", "-", IF(J38="-", "-", IF(ABS(J38)=0, "-", ROUND(100*(H38-J38)/ABS(J38),1)))) -> - | M38: =H38-J38 -> 0
A39: 60kg当たり支払利子・地代算入生産費 | G39: 〃 | L39: =IF(H39="-", "-", IF(J39="-", "-", IF(ABS(J39)=0, "-", ROUND(100*(H39-J39)/ABS(J39),1)))) -> - | M39: =H39-J39 -> 0
A40: 60kg当たり全算入生産費 | G40: 〃 | L40: =IF(H40="-", "-", IF(J40="-", "-", IF(ABS(J40)=0, "-", ROUND(100*(H40-J40)/ABS(J40),1)))) -> - | M40: =H40-J40 -> 0
A41: 経営概況 | B41: 10ａ当たり収量 | G41: kg | L41: =IF(H41="-", "-", IF(J41="-", "-", IF(ABS(J41)=0, "-", ROUND(100*(H41-J41)/ABS(J41),1)))) -> - | M41: =H41-J41 -> 0
B42: 10ａ当たり粗収益 | G42: 円 | L42: =IF(H42="-", "-", IF(J42="-", "-", IF(ABS(J42)=0, "-", ROUND(100*(H42-J42)/ABS(J42),1)))) -> - | M42: =H42-J42 -> 0
...

Sheet No.2
A1: =No.1!A1&"年産 米生産費統計（組織法人経営体） 個別結果検討表 №２" -> 2019年産 米生産費統計（組織法人経営体） 個別結果検討表 №２ | AJ1: センサス番号
AJ2: =IF(No.1!O2="","",No.1!O2)
A4: 【労働時間（10ａ当たり）】 | AU4: 【生産物の概要（10ａ当たり）】 | BM4: 【稲作作業の受託状況（１経営体当たり）】
G5: =No.1!A1-2000 -> 19 | J5: =G5-1 -> 18 | M5: 増減率 | O5: 備考欄 | BA5: =$G$5 -> 19 | BD5: =$J$5 -> 18 | BG5: 増減率 | BI5: 備考欄 | BQ5: =$G$5 -> 19 | BS5: =$J$5 -> 18 | BT5: 増減率 | BU5: 備考欄
M6: （％） | BG6: （％） | BT6: （％）
A7: 労働時間計 | M7: =IF(G7="-", "-", IF(J7="-", "-", IF(ABS(J7)=0, "-", ROUND(100*(G7-J7)/ABS(J7),1)))) -> - | AU7: 主産物 | AV7: 数量（kg） | BG7: =IF(BA7="-", "-", IF(BD7="-", "-", IF(ABS(BD7)=0, "-", ROUND(100*(BA7-BD7)/ABS(BD7),1)))) -> - | BM7: 全作業 | BP7: ａ | BT7: =IF(BQ7="-", "-", IF(BS7="-", "-", IF(ABS(BS7)=0, "-", ROUND(100*(BQ7-BS7)/ABS(BS7),1)))) -> -
B8: 直接労働時間 | M8: =IF(G8="-", "-", IF(J8="-", "-", IF(ABS(J8)=0, "-", ROUND(100*(G8-J8)/ABS(J8),1)))) -> - | AV8: 価額 | BG8: =IF(BA8="-", "-", IF(BD8="-", "-", IF(ABS(BD8)=0, "-", ROUND(100*(BA8-BD8)/ABS(BD8),1)))) -> - | BM8: 耕うん・整地 | BP8: ａ | BT8: =IF(BQ8="-", "-", IF(BS8="-", "-", IF(ABS(BS8)=0, "-", ROUND(100*(BQ8-BS8)/ABS(BS8),1)))) -> -
C9: 種子予措 | M9: =IF(G9="-", "-", IF(J9="-", "-", IF(ABS(J9)=0, "-", ROUND(100*(G9-J9)/ABS(J9),1)))) -> - | AU9: 副産物 | AV9: くず米 | AX9: 数量（kg） | BG9: =IF(BA9="-", "-", IF(BD9="-", "-", IF(ABS(BD9)=0, "-", ROUND(100*(BA9-BD9)/ABS(BD9),1)))) -> - | BM9: 育苗 | BP9: ａ | BT9: =IF(BQ9="-", "-", IF(BS9="-", "-", IF(ABS(BS9)=0, "-", ROUND(100*(BQ9-BS9)/ABS(BS9),1)))) -> -
C10: 育苗 | M10: =IF(G10="-", "-", IF(J10="-", "-", IF(ABS(J10)=0, "-", ROUND(100*(G10-J10)/ABS(J10),1)))) -> - | AX10: 価額 | BG10: =IF(BA10="-", "-", IF(BD10="-", "-", IF(ABS(BD10)=0, "-", ROUND(100*(BA10-BD10)/ABS(BD10),1)))) -> - | BM10: 田植 | BP10: ａ | BT10: =IF(BQ10="-", "-", IF(BS10="-", "-", IF(ABS(BS10)=0, "-", ROUND(100*(BQ10-BS10)/ABS(BS10),1)))) -> -
C11: 耕起整地 | M11: =IF(G11="-", "-", IF(J11="-", "-", IF(ABS(J11)=0, "-", ROUND(100*(G11-J11)/ABS(J11),1)))) -> - | AV11: 稲わら (もみがら含む) | AX11: 数量（kg） | BG11: =IF(BA11="-", "-", IF(BD11="-", "-", IF(ABS(BD11)=0, "-", ROUND(100*(BA11-BD11)/ABS(BD11),1)))) -> - | BM11: 防除 | BP11: ａ | BT11: =IF(BQ11="-", "-", IF(BS11="-", "-", IF(ABS(BS11)=0, "-", ROUND(100*(BQ11-BS11)/ABS(BS11),1)))) -> -
C12: 基肥 | M12: =IF(G12="-", "-", IF(J12="-", "-", IF(ABS(J12)=0, "-", ROUND(100*(G12-J12)/ABS(J12),1)))) -> - | AX12: 価額 | BG12: =IF(BA12="-", "-", IF(BD12="-", "-", IF(ABS(BD12)=0, "-", ROUND(100*(BA12-BD12)/ABS(BD12),1)))) -> - | BM12: 刈取・脱穀 | BP12: ａ | BT12: =IF(BQ12="-", "-", IF(BS12="-", "-", IF(ABS(BS12)=0, "-", ROUND(100*(BQ12-BS12)/ABS(BS12),1)))) -> -
C13: 直まき | M13: =IF(G13="-", "-", IF(J13="-", "-", IF(ABS(J13)=0, "-", ROUND(100*(G13-J13)/ABS(J13),1)))) -> - | AU13: 粗収益 | BG13: =IF(BA13="-", "-", IF(BD13="-", "-", IF(ABS(BD13)=0, "-", ROUND(100*(BA13-BD13)/ABS(BD13),1)))) -> - | BM13: 乾燥・調製 | BP13: kg | BT13: =IF(BQ13="-", "-", IF(BS13="-", "-", IF(ABS(BS13)=0, "-", ROUND(100*(BQ13-BS13)/ABS(BS13),1)))) -> -
C14: 田植 | M14: =IF(G14="-", "-", IF(J14="-", "-", IF(ABS(J14)=0, "-", ROUND(100*(G14-J14)/ABS(J14),1)))) -> - | AU14: 所得 | BG14: =IF(BA14="-", "-", IF(BD14="-", "-", IF(ABS(BD14)=0, "-", ROUND(100*(BA14-BD14)/ABS(BD14),1)))) -> -
C15: 追肥 | M15: =IF(G15="-", "-", IF(J15="-", "-", IF(ABS(J15)=0, "-", ROUND(100*(G15-J15)/ABS(J15),1)))) -> - | AV15: １日当たり | BG15: =IF(BA15="-", "-", IF(BD15="-", "-", IF(ABS(BD15)=0, "-", ROUND(100*(BA15-BD15)/ABS(BD15),1)))) -> -
C16: 除草 | M16: =IF(G16="-", "-", IF(J16="-", "-", IF(ABS(J16)=0, "-", ROUND(100*(G16-J16)/ABS(J16),1)))) -> - | AU16: 構成員労働報酬 | BG16: =IF(BA16="-", "-", IF(BD16="-", "-", IF(ABS(BD16)=0, "-", ROUND(100*(BA16-BD16)/ABS(BD16),1)))) -> - | BM16: 【稲作作業の委託状況（１経営体当たり）】
C17: 管理 | M17: =IF(G17="-", "-", IF(J17="-", "-", IF(ABS(J17)=0, "-", ROUND(100*(G17-J17)/ABS(J17),1)))) -> - | AV17: １日当たり | BG17: =IF(BA17="-", "-", IF(BD17="-", "-", IF(ABS(BD17)=0, "-", ROUND(100*(BA17-BD17)/ABS(BD17),1)))) -> - | BQ17: =$G$5 -> 19 | BS17: =$J$5 -> 18 | BT17: 増減率 | BU17: 備考欄
C18: 防除 | M18: =IF(G18="-", "-", IF(J18="-", "-", IF(ABS(J18)=0, "-", ROUND(100*(G18-J18)/ABS(J18),1)))) -> - | AU18: （参考）各種助成措置を加えた場合 | BT18: （％）
C19: 刈取脱穀 | M19: =IF(G19="-", "-", IF(J19="-", "-", IF(ABS(J19)=0, "-", ROUND(100*(G19-J19)/ABS(J19),1)))) -> - | AV19: 粗収益 | BG19: =IF(BA19="-", "-", IF(BD19="-", "-", IF(ABS(BD19)=0, "-", ROUND(100*(BA19-BD19)/ABS(BD19),1)))) -> - | BM19: 育苗 | BP19: ａ | BT19: =IF(BQ19="-", "-", IF(BS19="-", "-", IF(ABS(BS19)=0, "-", ROUND(100*(BQ19-BS19)/ABS(BS19),1)))) -> -
C20: 乾燥 | M20: =IF(G20="-", "-", IF(J20="-", "-", IF(ABS(J20)=0, "-", ROUND(100*(G20-J20)/ABS(J20),1)))) -> - | AV20: 所得 | BG20: =IF(BA20="-", "-", IF(BD20="-", "-", IF(ABS(BD20)=0, "-", ROUND(100*(BA20-BD20)/ABS(BD20),1)))) -> - | BM20: 防除 | BP20: ａ | BT20: =IF(BQ20="-", "-", IF(BS20="-", "-", IF(ABS(BS20)=0, "-", ROUND(100*(BQ20-BS20)/ABS(BS20),1)))) -> -
C21: 生産管理 | M21: =IF(G21="-", "-", IF(J21="-", "-", IF(ABS(J21)=0, "-", ROUND(100*(G21-J21)/ABS(J21),1)))) -> - | AW21: １日当たり | BG21: =IF(BA21="-", "-", IF(BD21="-", "-", IF(ABS(BD21)=0, "-", ROUND(100*(BA21-BD21)/ABS(BD21),1)))) -> - | BT21: =IF(BQ21="-", "-", IF(BS21="-", "-", IF(ABS(BS21)=0, "-", ROUND(100*(BQ21-BS21)/ABS(BS21),1)))) -> -
B22: 間接労働時間 | M22: =IF(G22="-", "-", IF(J22="-", "-", IF(ABS(J22)=0, "-", ROUND(100*(G22-J22)/ABS(J22),1)))) -> - | AV22: 構成員労働報酬 | BG22: =IF(BA22="-", "-", IF(BD22="-", "-", IF(ABS(BD22)=0, "-", ROUND(100*(BA22-BD22)/ABS(BD22),1)))) -> - | BT22: =IF(BQ22="-", "-", IF(BS22="-", "-", IF(ABS(BS22)=0, "-", ROUND(100*(BQ22-BS22)/ABS(BS22),1)))) -> -
A23: 構成員労働時間 | M23: =IF(G23="-", "-", IF(J23="-", "-", IF(ABS(J23)=0, "-", ROUND(100*(G23-J23)/ABS(J23),1)))) -> - | AW23: １日当たり | BG23: =IF(BA23="-", "-", IF(BD23="-", "-", IF(ABS(BD23)=0, "-", ROUND(100*(BA23-BD23)/ABS(BD23),1)))) -> - | BT23: =IF(BQ23="-", "-", IF(BS23="-", "-", IF(ABS(BS23)=0, "-", ROUND(100*(BQ23-BS23)/ABS(BS23),1)))) -> -
A24: 雇用労働時間 | M24: =IF(G24="-", "-", IF(J24="-", "-", IF(ABS(J24)=0, "-", ROUND(100*(G24-J24)/ABS(J24),1)))) -> - | BT24: =IF(BQ24="-", "-", IF(BS24="-", "-", IF(ABS(BS24)=0, "-", ROUND(100*(BQ24-BS24)/ABS(BS24),1)))) -> -
BT25: =IF(BQ25="-", "-", IF(BS25="-", "-", IF(ABS(BS25)=0, "-", ROUND(100*(BQ25-BS25)/ABS(BS25),1)))) -> -
BT26: =IF(BQ26="-", "-", IF(BS26="-", "-", IF(ABS(BS26)=0, "-", ROUND(100*(BQ26-BS26)/ABS(BS26),1)))) -> -
A30: 【作付面積、地代】
G31: 自作地 | P31: 借入地 | Y31: 計 | AH31: 備考欄
G32: =$G$5 -> 19 | J32: =$J$5 -> 18 | M32: 増減率 | P32: =$G$5 -> 19 | S32: =$J$5 -> 18 | V32: 増減率 | Y32: =$G$5 -> 19 | AB32: =$J$5 -> 18 | AE32: 増減率
M33: （％） | V33: （％） | AE33: （％）
A34: 作付地 | C34: 作付実面積 | F34: （ａ） | M34: =IF(G34="-", "-", IF(J34="-", "-", IF(ABS(J34)=0, "-", ROUND(100*(G34-J34)/ABS(J34),1)))) -> - | V34: =IF(P34="-", "-", IF(S34="-", "-", IF(ABS(S34)=0, "-", ROUND(100*(P34-S34)/ABS(S34),1)))) -> - | AE34: =IF(Y34="-", "-", IF(AB34="-", "-", IF(ABS(AB34)=0, "-", ROUND(100*(Y34-AB34)/ABS(AB34),1)))) -> -
C35: 土地台帳面積 | F35: （ａ） | M35: =IF(G35="-", "-", IF(J35="-", "-", IF(ABS(J35)=0, "-", ROUND(100*(G35-J35)/ABS(J35),1)))) -> - | V35: =IF(P35="-", "-", IF(S35="-", "-", IF(ABS(S35)=0, "-", ROUND(100*(P35-S35)/ABS(S35),1)))) -> - | AE35: =IF(Y35="-", "-", IF(AB35="-", "-", IF(ABS(AB35)=0, "-", ROUND(100*(Y35-AB35)/ABS(AB35),1)))) -> -
C36: 10a当たり地代総額 | F36: （円） | M36: =IF(G36="-", "-", IF(J36="-", "-", IF(ABS(J36)=0, "-", ROUND(100*(G36-J36)/ABS(J36),1)))) -> - | V36: =IF(P36="-", "-", IF(S36="-", "-", IF(ABS(S36)=0, "-", ROUND(100*(P36-S36)/ABS(S36),1)))) -> - | AE36: =IF(Y36="-", "-", IF(AB36="-", "-", IF(ABS(AB36)=0, "-", ROUND(100*(Y36-AB36)/ABS(AB36),1)))) -> -
C37: 10a当たり負担地代 | F37: （円） | M37: =IF(G37="-", "-", IF(J37="-", "-", IF(ABS(J37)=0, "-", ROUND(100*(G37-J37)/ABS(J37),1)))) -> - | V37: =IF(P37="-", "-", IF(S37="-", "-", IF(ABS(S37)=0, "-", ROUND(100*(P37-S37)/ABS(S37),1)))) -> - | AE37: =IF(Y37="-", "-", IF(AB37="-", "-", IF(ABS(AB37)=0, "-", ROUND(100*(Y37-AB37)/ABS(AB37),1)))) -> -
A38: 作付地 以外 | C38: 使用面積 | F38: （ａ） | M38: =IF(G38="-", "-", IF(J38="-", "-", IF(ABS(J38)=0, "-", ROUND(100*(G38-J38)/ABS(J38),1)))) -> - | V38: =IF(P38="-", "-", IF(S38="-", "-", IF(ABS(S38)=0, "-", ROUND(100*(P38-S38)/ABS(S38),1)))) -> - | AE38: =IF(Y38="-", "-", IF(AB38="-", "-", IF(ABS(AB38)=0, "-", ROUND(100*(Y38-AB38)/ABS(AB38),1)))) -> -
C39: 10ａ当たり賃借料総額 | F39: （円） | M39: =IF(G39="-", "-", IF(J39="-", "-", IF(ABS(J39)=0, "-", ROUND(100*(G39-J39)/ABS(J39),1)))) -> - | V39: =IF(P39="-", "-", IF(S39="-", "-", IF(ABS(S39)=0, "-", ROUND(100*(P39-S39)/ABS(S39),1)))) -> - | AE39: =IF(Y39="-", "-", IF(AB39="-", "-", IF(ABS(AB39)=0, "-", ROUND(100*(Y39-AB39)/ABS(AB39),1)))) -> -
C40: 10ａ当たり負担地代 | F40: （円） | M40: =IF(G40="-", "-", IF(J40="-", "-", IF(ABS(J40)=0, "-", ROUND(100*(G40-J40)/ABS(J40),1)))) -> - | V40: =IF(P40="-", "-", IF(S40="-", "-", IF(ABS(S40)=0, "-", ROUND(100*(P40-S40)/ABS(S40),1)))) -> - | AE40: =IF(Y40="-", "-", IF(AB40="-", "-", IF(ABS(AB40)=0, "-", ROUND(100*(Y40-AB40)/ABS(AB40),1)))) -> -
A41: 10ａ当たり実勢地代 | F41: （円） | M41: =IF(G41="-", "-", IF(J41="-", "-", IF(ABS(J41)=0, "-", ROUND(100*(G41-J41)/ABS(J41),1)))) -> - | V41: =IF(P41="-", "-", IF(S41="-", "-", IF(ABS(S41)=0, "-", ROUND(100*(P41-S41)/ABS(S41),1)))) -> - | AE41: =IF(Y41="-", "-", IF(AB41="-", "-", IF(ABS(AB41)=0, "-", ROUND(100*(Y41-AB41)/ABS(AB41),1)))) -> -

Sheet No.3
A1: =No.1!A1&"年産 米生産費統計（組織法人経営体） 個別結果検討表 №３" -> 2019年産 米生産費統計（組織法人経営体） 個別結果検討表 №３ | P1: センサス番号
P2: =IF(No.1!O2="","",No.1!O2)
A4: 【生産物の処分内訳（10ａ当たり）】
G5: =No.1!H5 -> 19 | J5: =G5-1 -> 18 | M5: 増 減 率 | P5: 備考欄
G6: 数量 | H6: 価額 | I6: 単価 | J6: 数量 | K6: 価額 | L6: 単価 | M6: 数量 | N6: 価額 | O6: 単価
G7: （kg） | H7: （円） | I7: （円） | J7: （kg） | K7: （円） | L7: （円） | M7: （％） | N7: （％） | O7: （％）
A8: 玄米（予定を含む） | B8: 販売用 | C8: 主食用 | M8: =IF(G8="-", "-", IF(J8="-", "-", IF(ABS(J8)=0, "-", ROUND(100*(G8-J8)/ABS(J8),1)))) -> - | N8: =IF(H8="-", "-", IF(K8="-", "-", IF(ABS(K8)=0, "-", ROUND(100*(H8-K8)/ABS(K8),1)))) -> - | O8: =IF(I8="-", "-", IF(L8="-", "-", IF(ABS(L8)=0, "-", ROUND(100*(I8-L8)/ABS(L8),1)))) -> -
C9: 加工用 | M9: =IF(G9="-", "-", IF(J9="-", "-", IF(ABS(J9)=0, "-", ROUND(100*(G9-J9)/ABS(J9),1)))) -> - | N9: =IF(H9="-", "-", IF(K9="-", "-", IF(ABS(K9)=0, "-", ROUND(100*(H9-K9)/ABS(K9),1)))) -> - | O9: =IF(I9="-", "-", IF(L9="-", "-", IF(ABS(L9)=0, "-", ROUND(100*(I9-L9)/ABS(L9),1)))) -> -
C10: 区分出荷 | M10: =IF(G10="-", "-", IF(J10="-", "-", IF(ABS(J10)=0, "-", ROUND(100*(G10-J10)/ABS(J10),1)))) -> - | N10: =IF(H10="-", "-", IF(K10="-", "-", IF(ABS(K10)=0, "-", ROUND(100*(H10-K10)/ABS(K10),1)))) -> - | O10: =IF(I10="-", "-", IF(L10="-", "-", IF(ABS(L10)=0, "-", ROUND(100*(I10-L10)/ABS(L10),1)))) -> -
C11: 小計 | M11: =IF(G11="-", "-", IF(J11="-", "-", IF(ABS(J11)=0, "-", ROUND(100*(G11-J11)/ABS(J11),1)))) -> - | N11: =IF(H11="-", "-", IF(K11="-", "-", IF(ABS(K11)=0, "-", ROUND(100*(H11-K11)/ABS(K11),1)))) -> - | O11: =IF(I11="-", "-", IF(L11="-", "-", IF(ABS(L11)=0, "-", ROUND(100*(I11-L11)/ABS(L11),1)))) -> -
B12: 組織用 | C12: 種子用 | M12: =IF(G12="-", "-", IF(J12="-", "-", IF(ABS(J12)=0, "-", ROUND(100*(G12-J12)/ABS(J12),1)))) -> - | N12: =IF(H12="-", "-", IF(K12="-", "-", IF(ABS(K12)=0, "-", ROUND(100*(H12-K12)/ABS(K12),1)))) -> - | O12: =IF(I12="-", "-", IF(L12="-", "-", IF(ABS(L12)=0, "-", ROUND(100*(I12-L12)/ABS(L12),1)))) -> -
C13: 飯米用 | M13: =IF(G13="-", "-", IF(J13="-", "-", IF(ABS(J13)=0, "-", ROUND(100*(G13-J13)/ABS(J13),1)))) -> - | N13: =IF(H13="-", "-", IF(K13="-", "-", IF(ABS(K13)=0, "-", ROUND(100*(H13-K13)/ABS(K13),1)))) -> - | O13: =IF(I13="-", "-", IF(L13="-", "-", IF(ABS(L13)=0, "-", ROUND(100*(I13-L13)/ABS(L13),1)))) -> -
C14: その他 | M14: =IF(G14="-", "-", IF(J14="-", "-", IF(ABS(J14)=0, "-", ROUND(100*(G14-J14)/ABS(J14),1)))) -> - | N14: =IF(H14="-", "-", IF(K14="-", "-", IF(ABS(K14)=0, "-", ROUND(100*(H14-K14)/ABS(K14),1)))) -> - | O14: =IF(I14="-", "-", IF(L14="-", "-", IF(ABS(L14)=0, "-", ROUND(100*(I14-L14)/ABS(L14),1)))) -> -
C15: 小計 | M15: =IF(G15="-", "-", IF(J15="-", "-", IF(ABS(J15)=0, "-", ROUND(100*(G15-J15)/ABS(J15),1)))) -> - | N15: =IF(H15="-", "-", IF(K15="-", "-", IF(ABS(K15)=0, "-", ROUND(100*(H15-K15)/ABS(K15),1)))) -> - | O15: =IF(I15="-", "-", IF(L15="-", "-", IF(ABS(L15)=0, "-", ROUND(100*(I15-L15)/ABS(L15),1)))) -> -
B16: 合計 | M16: =IF(G16="-", "-", IF(J16="-", "-", IF(ABS(J16)=0, "-", ROUND(100*(G16-J16)/ABS(J16),1)))) -> - | N16: =IF(H16="-", "-", IF(K16="-", "-", IF(ABS(K16)=0, "-", ROUND(100*(H16-K16)/ABS(K16),1)))) -> - | O16: =IF(I16="-", "-", IF(L16="-", "-", IF(ABS(L16)=0, "-", ROUND(100*(I16-L16)/ABS(L16),1)))) -> -
A17: いなわら等 | B17: 販売 | C17: 加工用 | M17: =IF(G17="-", "-", IF(J17="-", "-", IF(ABS(J17)=0, "-", ROUND(100*(G17-J17)/ABS(J17),1)))) -> - | N17: =IF(H17="-", "-", IF(K17="-", "-", IF(ABS(K17)=0, "-", ROUND(100*(H17-K17)/ABS(K17),1)))) -> - | O17: =IF(I17="-", "-", IF(L17="-", "-", IF(ABS(L17)=0, "-", ROUND(100*(I17-L17)/ABS(L17),1)))) -> -
C18: その他 | M18: =IF(G18="-", "-", IF(J18="-", "-", IF(ABS(J18)=0, "-", ROUND(100*(G18-J18)/ABS(J18),1)))) -> - | N18: =IF(H18="-", "-", IF(K18="-", "-", IF(ABS(K18)=0, "-", ROUND(100*(H18-K18)/ABS(K18),1)))) -> - | O18: =IF(I18="-", "-", IF(L18="-", "-", IF(ABS(L18)=0, "-", ROUND(100*(I18-L18)/ABS(L18),1)))) -> -
B19: 組織用 | C19: 生わら | M19: =IF(G19="-", "-", IF(J19="-", "-", IF(ABS(J19)=0, "-", ROUND(100*(G19-J19)/ABS(J19),1)))) -> -
C20: 乾燥わら | M20: =IF(G20="-", "-", IF(J20="-", "-", IF(ABS(J20)=0, "-", ROUND(100*(G20-J20)/ABS(J20),1)))) -> - | N20: =IF(H20="-", "-", IF(K20="-", "-", IF(ABS(K20)=0, "-", ROUND(100*(H20-K20)/ABS(K20),1)))) -> - | O20: =IF(I20="-", "-", IF(L20="-", "-", IF(ABS(L20)=0, "-", ROUND(100*(I20-L20)/ABS(L20),1)))) -> -
C21: その他 | M21: =IF(G21="-", "-", IF(J21="-", "-", IF(ABS(J21)=0, "-", ROUND(100*(G21-J21)/ABS(J21),1)))) -> -
B22: いなわら小計 | M22: =IF(G22="-", "-", IF(J22="-", "-", IF(ABS(J22)=0, "-", ROUND(100*(G22-J22)/ABS(J22),1)))) -> - | N22: =IF(H22="-", "-", IF(K22="-", "-", IF(ABS(K22)=0, "-", ROUND(100*(H22-K22)/ABS(K22),1)))) -> -
B23: くず米 | M23: =IF(G23="-", "-", IF(J23="-", "-", IF(ABS(J23)=0, "-", ROUND(100*(G23-J23)/ABS(J23),1)))) -> - | N23: =IF(H23="-", "-", IF(K23="-", "-", IF(ABS(K23)=0, "-", ROUND(100*(H23-K23)/ABS(K23),1)))) -> - | O23: =IF(I23="-", "-", IF(L23="-", "-", IF(ABS(L23)=0, "-", ROUND(100*(I23-L23)/ABS(L23),1)))) -> -
B24: もみがら | M24: =IF(G24="-", "-", IF(J24="-", "-", IF(ABS(J24)=0, "-", ROUND(100*(G24-J24)/ABS(J24),1)))) -> - | N24: =IF(H24="-", "-", IF(K24="-", "-", IF(ABS(K24)=0, "-", ROUND(100*(H24-K24)/ABS(K24),1)))) -> - | O24: =IF(I24="-", "-", IF(L24="-", "-", IF(ABS(L24)=0, "-", ROUND(100*(I24-L24)/ABS(L24),1)))) -> -
B25: 合計 | N25: =IF(H25="-", "-", IF(K25="-", "-", IF(ABS(K25)=0, "-", ROUND(100*(H25-K25)/ABS(K25),1)))) -> -
A27: 【費用の内訳（10ａ当たり）】
G28: =G5 -> 19 | J28: =J5 -> 18 | M28: 増 減 率 | P28: 備考欄
G29: 数量 | H29: 価額 | I29: 単価 | J29: 数量 | K29: 価額 | L29: 単価 | M29: 数量 | N29: 価額 | O29: 単価
H30: （円） | I30: （円） | K30: （円） | L30: （円） | M30: （％） | N30: （％） | O30: （％）
A31: 種苗費 | N31: =IF(H31="-", "-", IF(K31="-", "-", IF(ABS(K31)=0, "-", ROUND(100*(H31-K31)/ABS(K31),1)))) -> -
B32: 種子もみ | D32: 購入 | F32: （kg） | M32: =IF(G32="-", "-", IF(J32="-", "-", IF(ABS(J32)=0, "-", ROUND(100*(G32-J32)/ABS(J32),1)))) -> - | N32: =IF(H32="-", "-", IF(K32="-", "-", IF(ABS(K32)=0, "-", ROUND(100*(H32-K32)/ABS(K32),1)))) -> - | O32: =IF(I32="-", "-", IF(L32="-", "-", IF(ABS(L32)=0, "-", ROUND(100*(I32-L32)/ABS(L32),1)))) -> -
D33: 自給 | F33: （kg） | M33: =IF(G33="-", "-", IF(J33="-", "-", IF(ABS(J33)=0, "-", ROUND(100*(G33-J33)/ABS(J33),1)))) -> - | N33: =IF(H33="-", "-", IF(K33="-", "-", IF(ABS(K33)=0, "-", ROUND(100*(H33-K33)/ABS(K33),1)))) -> - | O33: =IF(I33="-", "-", IF(L33="-", "-", IF(ABS(L33)=0, "-", ROUND(100*(I33-L33)/ABS(L33),1)))) -> -
B34: 苗 | F34: （ａ） | M34: =IF(G34="-", "-", IF(J34="-", "-", IF(ABS(J34)=0, "-", ROUND(100*(G34-J34)/ABS(J34),1)))) -> - | N34: =IF(H34="-", "-", IF(K34="-", "-", IF(ABS(K34)=0, "-", ROUND(100*(H34-K34)/ABS(K34),1)))) -> - | O34: =IF(I34="-", "-", IF(L34="-", "-", IF(ABS(L34)=0, "-", ROUND(100*(I34-L34)/ABS(L34),1)))) -> -
A35: 肥料費 | N35: =IF(H35="-", "-", IF(K35="-", "-", IF(ABS(K35)=0, "-", ROUND(100*(H35-K35)/ABS(K35),1)))) -> -
B36: 窒素質肥料 | F36: （kg） | M36: =IF(G36="-", "-", IF(J36="-", "-", IF(ABS(J36)=0, "-", ROUND(100*(G36-J36)/ABS(J36),1)))) -> - | N36: =IF(H36="-", "-", IF(K36="-", "-", IF(ABS(K36)=0, "-", ROUND(100*(H36-K36)/ABS(K36),1)))) -> - | O36: =IF(I36="-", "-", IF(L36="-", "-", IF(ABS(L36)=0, "-", ROUND(100*(I36-L36)/ABS(L36),1)))) -> -
B37: りん酸質肥料 | F37: （kg） | M37: =IF(G37="-", "-", IF(J37="-", "-", IF(ABS(J37)=0, "-", ROUND(100*(G37-J37)/ABS(J37),1)))) -> - | N37: =IF(H37="-", "-", IF(K37="-", "-", IF(ABS(K37)=0, "-", ROUND(100*(H37-K37)/ABS(K37),1)))) -> - | O37: =IF(I37="-", "-", IF(L37="-", "-", IF(ABS(L37)=0, "-", ROUND(100*(I37-L37)/ABS(L37),1)))) -> -
B38: カリ質肥料 | F38: （kg） | M38: =IF(G38="-", "-", IF(J38="-", "-", IF(ABS(J38)=0, "-", ROUND(100*(G38-J38)/ABS(J38),1)))) -> - | N38: =IF(H38="-", "-", IF(K38="-", "-", IF(ABS(K38)=0, "-", ROUND(100*(H38-K38)/ABS(K38),1)))) -> - | O38: =IF(I38="-", "-", IF(L38="-", "-", IF(ABS(L38)=0, "-", ROUND(100*(I38-L38)/ABS(L38),1)))) -> -
B39: けい酸質肥料 | F39: （kg） | M39: =IF(G39="-", "-", IF(J39="-", "-", IF(ABS(J39)=0, "-", ROUND(100*(G39-J39)/ABS(J39),1)))) -> - | N39: =IF(H39="-", "-", IF(K39="-", "-", IF(ABS(K39)=0, "-", ROUND(100*(H39-K39)/ABS(K39),1)))) -> - | O39: =IF(I39="-", "-", IF(L39="-", "-", IF(ABS(L39)=0, "-", ROUND(100*(I39-L39)/ABS(L39),1)))) -> -
B40: 炭酸カルシウム（石灰含む） | F40: （kg） | M40: =IF(G40="-", "-", IF(J40="-", "-", IF(ABS(J40)=0, "-", ROUND(100*(G40-J40)/ABS(J40),1)))) -> - | N40: =IF(H40="-", "-", IF(K40="-", "-", IF(ABS(K40)=0, "-", ROUND(100*(H40-K40)/ABS(K40),1)))) -> - | O40: =IF(I40="-", "-", IF(L40="-", "-", IF(ABS(L40)=0, "-", ROUND(100*(I40-L40)/ABS(L40),1)))) -> -
B41: 複合肥料 | F41: （kg） | M41: =IF(G41="-", "-", IF(J41="-", "-", IF(ABS(J41)=0, "-", ROUND(100*(G41-J41)/ABS(J41),1)))) -> - | N41: =IF(H41="-", "-", IF(K41="-", "-", IF(ABS(K41)=0, "-", ROUND(100*(H41-K41)/ABS(K41),1)))) -> - | O41: =IF(I41="-", "-", IF(L41="-", "-", IF(ABS(L41)=0, "-", ROUND(100*(I41-L41)/ABS(L41),1)))) -> -
B42: 土壌改良資材 | N42: =IF(H42="-", "-", IF(K42="-", "-", IF(ABS(K42)=0, "-", ROUND(100*(H42-K42)/ABS(K42),1)))) -> -
...

Sheet No.4
A1: =No.1!A1&"年産 米生産費統計（組織法人経営体） 個別結果検討表 №４" -> 2019年産 米生産費統計（組織法人経営体） 個別結果検討表 №４ | O1: センサス番号
O2: =IF(No.1!O2="","",No.1!O2)
A4: 【費用の内訳（10ａ当たり）（続き）】
F5: =No.1!H5 -> 19 | I5: =F5-1 -> 18 | L5: 増 減 率 | O5: 備考欄
F6: 数量 | G6: 価額 | H6: 単価 | I6: 数量 | J6: 価額 | K6: 単価 | L6: 数量 | M6: 価額 | N6: 単価
G7: （円） | H7: （円） | J7: （円） | K7: （円） | L7: （％） | M7: （％） | N7: （％）
A8: 農業薬剤費 | M8: =IF(G8="-", "-", IF(J8="-", "-", IF(ABS(J8)=0, "-", ROUND(100*(G8-J8)/ABS(J8),1)))) -> -
B9: 殺虫剤 | M9: =IF(G9="-", "-", IF(J9="-", "-", IF(ABS(J9)=0, "-", ROUND(100*(G9-J9)/ABS(J9),1)))) -> -
B10: 殺菌剤 | M10: =IF(G10="-", "-", IF(J10="-", "-", IF(ABS(J10)=0, "-", ROUND(100*(G10-J10)/ABS(J10),1)))) -> -
B11: 殺虫殺菌剤 | M11: =IF(G11="-", "-", IF(J11="-", "-", IF(ABS(J11)=0, "-", ROUND(100*(G11-J11)/ABS(J11),1)))) -> -
B12: 除草剤 | M12: =IF(G12="-", "-", IF(J12="-", "-", IF(ABS(J12)=0, "-", ROUND(100*(G12-J12)/ABS(J12),1)))) -> -
B13: その他 | M13: =IF(G13="-", "-", IF(J13="-", "-", IF(ABS(J13)=0, "-", ROUND(100*(G13-J13)/ABS(J13),1)))) -> -
A14: 光熱動力費 | M14: =IF(G14="-", "-", IF(J14="-", "-", IF(ABS(J14)=0, "-", ROUND(100*(G14-J14)/ABS(J14),1)))) -> -
B15: 動力燃料 | C15: 重油 | E15: （L） | L15: =IF(F15="-", "-", IF(I15="-", "-", IF(ABS(I15)=0, "-", ROUND(100*(F15-I15)/ABS(I15),1)))) -> - | M15: =IF(G15="-", "-", IF(J15="-", "-", IF(ABS(J15)=0, "-", ROUND(100*(G15-J15)/ABS(J15),1)))) -> - | N15: =IF(H15="-", "-", IF(K15="-", "-", IF(ABS(K15)=0, "-", ROUND(100*(H15-K15)/ABS(K15),1)))) -> -
C16: 軽油 | E16: （L） | L16: =IF(F16="-", "-", IF(I16="-", "-", IF(ABS(I16)=0, "-", ROUND(100*(F16-I16)/ABS(I16),1)))) -> - | M16: =IF(G16="-", "-", IF(J16="-", "-", IF(ABS(J16)=0, "-", ROUND(100*(G16-J16)/ABS(J16),1)))) -> - | N16: =IF(H16="-", "-", IF(K16="-", "-", IF(ABS(K16)=0, "-", ROUND(100*(H16-K16)/ABS(K16),1)))) -> -
C17: 灯油 | E17: （L） | L17: =IF(F17="-", "-", IF(I17="-", "-", IF(ABS(I17)=0, "-", ROUND(100*(F17-I17)/ABS(I17),1)))) -> - | M17: =IF(G17="-", "-", IF(J17="-", "-", IF(ABS(J17)=0, "-", ROUND(100*(G17-J17)/ABS(J17),1)))) -> - | N17: =IF(H17="-", "-", IF(K17="-", "-", IF(ABS(K17)=0, "-", ROUND(100*(H17-K17)/ABS(K17),1)))) -> -
C18: ガソリン | E18: （L） | L18: =IF(F18="-", "-", IF(I18="-", "-", IF(ABS(I18)=0, "-", ROUND(100*(F18-I18)/ABS(I18),1)))) -> - | M18: =IF(G18="-", "-", IF(J18="-", "-", IF(ABS(J18)=0, "-", ROUND(100*(G18-J18)/ABS(J18),1)))) -> - | N18: =IF(H18="-", "-", IF(K18="-", "-", IF(ABS(K18)=0, "-", ROUND(100*(H18-K18)/ABS(K18),1)))) -> -
C19: 潤滑油 | E19: （L） | L19: =IF(F19="-", "-", IF(I19="-", "-", IF(ABS(I19)=0, "-", ROUND(100*(F19-I19)/ABS(I19),1)))) -> - | M19: =IF(G19="-", "-", IF(J19="-", "-", IF(ABS(J19)=0, "-", ROUND(100*(G19-J19)/ABS(J19),1)))) -> - | N19: =IF(H19="-", "-", IF(K19="-", "-", IF(ABS(K19)=0, "-", ROUND(100*(H19-K19)/ABS(K19),1)))) -> -
C20: 混合油 | E20: （L） | L20: =IF(F20="-", "-", IF(I20="-", "-", IF(ABS(I20)=0, "-", ROUND(100*(F20-I20)/ABS(I20),1)))) -> - | M20: =IF(G20="-", "-", IF(J20="-", "-", IF(ABS(J20)=0, "-", ROUND(100*(G20-J20)/ABS(J20),1)))) -> - | N20: =IF(H20="-", "-", IF(K20="-", "-", IF(ABS(K20)=0, "-", ROUND(100*(H20-K20)/ABS(K20),1)))) -> -
B21: 電力料 | M21: =IF(G21="-", "-", IF(J21="-", "-", IF(ABS(J21)=0, "-", ROUND(100*(G21-J21)/ABS(J21),1)))) -> -
B22: その他 | M22: =IF(G22="-", "-", IF(J22="-", "-", IF(ABS(J22)=0, "-", ROUND(100*(G22-J22)/ABS(J22),1)))) -> -
B23: 自給 | M23: =IF(G23="-", "-", IF(J23="-", "-", IF(ABS(J23)=0, "-", ROUND(100*(G23-J23)/ABS(J23),1)))) -> -
A24: その他の諸材料費 | M24: =IF(G24="-", "-", IF(J24="-", "-", IF(ABS(J24)=0, "-", ROUND(100*(G24-J24)/ABS(J24),1)))) -> -
B25: 育苗用土（購入）（素土を含む） | E25: （kg） | L25: =IF(F25="-", "-", IF(I25="-", "-", IF(ABS(I25)=0, "-", ROUND(100*(F25-I25)/ABS(I25),1)))) -> - | M25: =IF(G25="-", "-", IF(J25="-", "-", IF(ABS(J25)=0, "-", ROUND(100*(G25-J25)/ABS(J25),1)))) -> - | N25: =IF(H25="-", "-", IF(K25="-", "-", IF(ABS(K25)=0, "-", ROUND(100*(H25-K25)/ABS(K25),1)))) -> -
B26: その他 | M26: =IF(G26="-", "-", IF(J26="-", "-", IF(ABS(J26)=0, "-", ROUND(100*(G26-J26)/ABS(J26),1)))) -> -
B27: 自給 | M27: =IF(G27="-", "-", IF(J27="-", "-", IF(ABS(J27)=0, "-", ROUND(100*(G27-J27)/ABS(J27),1)))) -> -
A28: 土地改良及び水利費 | M28: =IF(G28="-", "-", IF(J28="-", "-", IF(ABS(J28)=0, "-", ROUND(100*(G28-J28)/ABS(J28),1)))) -> -
B29: 土地改 良区費 | D29: 維持負担金 | M29: =IF(G29="-", "-", IF(J29="-", "-", IF(ABS(J29)=0, "-", ROUND(100*(G29-J29)/ABS(J29),1)))) -> -
D30: 償還金 | M30: =IF(G30="-", "-", IF(J30="-", "-", IF(ABS(J30)=0, "-", ROUND(100*(G30-J30)/ABS(J30),1)))) -> -
B31: 水利組合費 | M31: =IF(G31="-", "-", IF(J31="-", "-", IF(ABS(J31)=0, "-", ROUND(100*(G31-J31)/ABS(J31),1)))) -> -
B32: 揚水ポンプ組合費 | M32: =IF(G32="-", "-", IF(J32="-", "-", IF(ABS(J32)=0, "-", ROUND(100*(G32-J32)/ABS(J32),1)))) -> -
B33: その他 | M33: =IF(G33="-", "-", IF(J33="-", "-", IF(ABS(J33)=0, "-", ROUND(100*(G33-J33)/ABS(J33),1)))) -> -
A34: 賃借料及び料金 | M34: =IF(G34="-", "-", IF(J34="-", "-", IF(ABS(J34)=0, "-", ROUND(100*(G34-J34)/ABS(J34),1)))) -> -
B35: 共 同 負担金 | D35: 薬剤散布 | M35: =IF(G35="-", "-", IF(J35="-", "-", IF(ABS(J35)=0, "-", ROUND(100*(G35-J35)/ABS(J35),1)))) -> -
D36: 共同施設 | M36: =IF(G36="-", "-", IF(J36="-", "-", IF(ABS(J36)=0, "-", ROUND(100*(G36-J36)/ABS(J36),1)))) -> -
D37: 共同苗代 | M37: =IF(G37="-", "-", IF(J37="-", "-", IF(ABS(J37)=0, "-", ROUND(100*(G37-J37)/ABS(J37),1)))) -> -
B38: 農機具借料 | M38: =IF(G38="-", "-", IF(J38="-", "-", IF(ABS(J38)=0, "-", ROUND(100*(G38-J38)/ABS(J38),1)))) -> -
B39: 航空防除賃 | E39: （ａ） | L39: =IF(F39="-", "-", IF(I39="-", "-", IF(ABS(I39)=0, "-", ROUND(100*(F39-I39)/ABS(I39),1)))) -> - | M39: =IF(G39="-", "-", IF(J39="-", "-", IF(ABS(J39)=0, "-", ROUND(100*(G39-J39)/ABS(J39),1)))) -> - | N39: =IF(H39="-", "-", IF(K39="-", "-", IF(ABS(K39)=0, "-", ROUND(100*(H39-K39)/ABS(K39),1)))) -> -
B40: 賃耕料 | E40: （ａ） | L40: =IF(F40="-", "-", IF(I40="-", "-", IF(ABS(I40)=0, "-", ROUND(100*(F40-I40)/ABS(I40),1)))) -> - | M40: =IF(G40="-", "-", IF(J40="-", "-", IF(ABS(J40)=0, "-", ROUND(100*(G40-J40)/ABS(J40),1)))) -> - | N40: =IF(H40="-", "-", IF(K40="-", "-", IF(ABS(K40)=0, "-", ROUND(100*(H40-K40)/ABS(K40),1)))) -> -
B41: は種・田植賃 | E41: （ａ） | L41: =IF(F41="-", "-", IF(I41="-", "-", IF(ABS(I41)=0, "-", ROUND(100*(F41-I41)/ABS(I41),1)))) -> - | M41: =IF(G41="-", "-", IF(J41="-", "-", IF(ABS(J41)=0, "-", ROUND(100*(G41-J41)/ABS(J41),1)))) -> - | N41: =IF(H41="-", "-", IF(K41="-", "-", IF(ABS(K41)=0, "-", ROUND(100*(H41-K41)/ABS(K41),1)))) -> -
...

Sheet No.5
A1: =No.1!A1&"年産 米生産費統計（組織法人経営体） 個別結果検討表 №５" -> 2019年産 米生産費統計（組織法人経営体） 個別結果検討表 №５ | AL1: センサス番号
AL2: =IF(No.1!O2="","",No.1!O2)
A4: 【費用の内訳（10ａ当たり）（続き）】
G5: =No.1!H5 -> 19 | J5: =G5-1 -> 18 | M5: 増減率 | P5: 備考 | Y5: 使 用 台 数 （ １ 経 営 体 当 た り ） | AH5: 調 査 作 物 負 担 分 （ 1 0 ａ 当 た り ） | AQ5: 備考欄
G6: （円） | J6: （円） | M6: （％） | Y6: =$G$5 -> 19 | AB6: =$J$5 -> 18 | AE6: 増減率 | AH6: =$G$5 -> 19 | AK6: =$J$5 -> 18 | AN6: 増減率
A7: 物件税 | M7: =IF(G7="-", "-", IF(J7="-", "-", IF(ABS(J7)=0, "-", ROUND(100*(G7-J7)/ABS(J7),1)))) -> - | Y7: （台） | AB7: （台） | AE7: （％） | AH7: （円） | AK7: （円） | AN7: （％）
B8: 固定資産税 | M8: =IF(G8="-", "-", IF(J8="-", "-", IF(ABS(J8)=0, "-", ROUND(100*(G8-J8)/ABS(J8),1)))) -> - | R8: 減価償却費 | AN8: =IF(AH8="-", "-", IF(AK8="-", "-", IF(ABS(AK8)=0, "-", ROUND(100*(AH8-AK8)/ABS(AK8),1)))) -> -
C9: 建物 | M9: =IF(G9="-", "-", IF(J9="-", "-", IF(ABS(J9)=0, "-", ROUND(100*(G9-J9)/ABS(J9),1)))) -> - | S9: 建物・構築物 | AN9: =IF(AH9="-", "-", IF(AK9="-", "-", IF(ABS(AK9)=0, "-", ROUND(100*(AH9-AK9)/ABS(AK9),1)))) -> -
C10: 農機具 | M10: =IF(G10="-", "-", IF(J10="-", "-", IF(ABS(J10)=0, "-", ROUND(100*(G10-J10)/ABS(J10),1)))) -> - | U10: 処分差損失 | AN10: =IF(AH10="-", "-", IF(AK10="-", "-", IF(ABS(AK10)=0, "-", ROUND(100*(AH10-AK10)/ABS(AK10),1)))) -> -
B11: 自動車重量税 | M11: =IF(G11="-", "-", IF(J11="-", "-", IF(ABS(J11)=0, "-", ROUND(100*(G11-J11)/ABS(J11),1)))) -> - | T11: 住宅 | AN11: =IF(AH11="-", "-", IF(AK11="-", "-", IF(ABS(AK11)=0, "-", ROUND(100*(AH11-AK11)/ABS(AK11),1)))) -> -
B12: 自動車税 | M12: =IF(G12="-", "-", IF(J12="-", "-", IF(ABS(J12)=0, "-", ROUND(100*(G12-J12)/ABS(J12),1)))) -> - | T12: 事務所 | AN12: =IF(AH12="-", "-", IF(AK12="-", "-", IF(ABS(AK12)=0, "-", ROUND(100*(AH12-AK12)/ABS(AK12),1)))) -> -
B13: 不動産取得税 | M13: =IF(G13="-", "-", IF(J13="-", "-", IF(ABS(J13)=0, "-", ROUND(100*(G13-J13)/ABS(J13),1)))) -> - | T13: 納屋・倉庫 | AN13: =IF(AH13="-", "-", IF(AK13="-", "-", IF(ABS(AK13)=0, "-", ROUND(100*(AH13-AK13)/ABS(AK13),1)))) -> -
B14: 軽自動車税 | M14: =IF(G14="-", "-", IF(J14="-", "-", IF(ABS(J14)=0, "-", ROUND(100*(G14-J14)/ABS(J14),1)))) -> - | T14: 作業場 | AN14: =IF(AH14="-", "-", IF(AK14="-", "-", IF(ABS(AK14)=0, "-", ROUND(100*(AH14-AK14)/ABS(AK14),1)))) -> -
B15: 水利地益税 | M15: =IF(G15="-", "-", IF(J15="-", "-", IF(ABS(J15)=0, "-", ROUND(100*(G15-J15)/ABS(J15),1)))) -> - | T15: 車庫 | AN15: =IF(AH15="-", "-", IF(AK15="-", "-", IF(ABS(AK15)=0, "-", ROUND(100*(AH15-AK15)/ABS(AK15),1)))) -> -
B16: 都市計画税 | M16: =IF(G16="-", "-", IF(J16="-", "-", IF(ABS(J16)=0, "-", ROUND(100*(G16-J16)/ABS(J16),1)))) -> - | T16: ライスセンター | AN16: =IF(AH16="-", "-", IF(AK16="-", "-", IF(ABS(AK16)=0, "-", ROUND(100*(AH16-AK16)/ABS(AK16),1)))) -> -
B17: 共同施設税 | M17: =IF(G17="-", "-", IF(J17="-", "-", IF(ABS(J17)=0, "-", ROUND(100*(G17-J17)/ABS(J17),1)))) -> - | T17: 育苗ハウス | AN17: =IF(AH17="-", "-", IF(AK17="-", "-", IF(ABS(AK17)=0, "-", ROUND(100*(AH17-AK17)/ABS(AK17),1)))) -> -
A18: 公課諸負担 | M18: =IF(G18="-", "-", IF(J18="-", "-", IF(ABS(J18)=0, "-", ROUND(100*(G18-J18)/ABS(J18),1)))) -> - | T18: 稲架 | AN18: =IF(AH18="-", "-", IF(AK18="-", "-", IF(ABS(AK18)=0, "-", ROUND(100*(AH18-AK18)/ABS(AK18),1)))) -> -
B19: 集落協議会費 | M19: =IF(G19="-", "-", IF(J19="-", "-", IF(ABS(J19)=0, "-", ROUND(100*(G19-J19)/ABS(J19),1)))) -> - | T19: コンクリートけい畔 | AN19: =IF(AH19="-", "-", IF(AK19="-", "-", IF(ABS(AK19)=0, "-", ROUND(100*(AH19-AK19)/ABS(AK19),1)))) -> -
B20: 農業協同組合費 | M20: =IF(G20="-", "-", IF(J20="-", "-", IF(ABS(J20)=0, "-", ROUND(100*(G20-J20)/ABS(J20),1)))) -> - | T20: 暗きょ排水施設 | AN20: =IF(AH20="-", "-", IF(AK20="-", "-", IF(ABS(AK20)=0, "-", ROUND(100*(AH20-AK20)/ABS(AK20),1)))) -> -
B21: 農事実行組合費 | M21: =IF(G21="-", "-", IF(J21="-", "-", IF(ABS(J21)=0, "-", ROUND(100*(G21-J21)/ABS(J21),1)))) -> - | T21: 客土 | AN21: =IF(AH21="-", "-", IF(AK21="-", "-", IF(ABS(AK21)=0, "-", ROUND(100*(AH21-AK21)/ABS(AK21),1)))) -> -
B22: 農業共済組合賦課金 | M22: =IF(G22="-", "-", IF(J22="-", "-", IF(ABS(J22)=0, "-", ROUND(100*(G22-J22)/ABS(J22),1)))) -> - | T22: 作業道 | AN22: =IF(AH22="-", "-", IF(AK22="-", "-", IF(ABS(AK22)=0, "-", ROUND(100*(AH22-AK22)/ABS(AK22),1)))) -> -
B23: 自賠責保険 | M23: =IF(G23="-", "-", IF(J23="-", "-", IF(ABS(J23)=0, "-", ROUND(100*(G23-J23)/ABS(J23),1)))) -> - | T23: 用水路 | AN23: =IF(AH23="-", "-", IF(AK23="-", "-", IF(ABS(AK23)=0, "-", ROUND(100*(AH23-AK23)/ABS(AK23),1)))) -> -
A24: 借入金・調査開始時残高合計 | M24: =IF(G24="-", "-", IF(J24="-", "-", IF(ABS(J24)=0, "-", ROUND(100*(G24-J24)/ABS(J24),1)))) -> - | T24: たい肥盤 | AN24: =IF(AH24="-", "-", IF(AK24="-", "-", IF(ABS(AK24)=0, "-", ROUND(100*(AH24-AK24)/ABS(AK24),1)))) -> -
A25: 借入金 | C25: 短期 | M25: =IF(G25="-", "-", IF(J25="-", "-", IF(ABS(J25)=0, "-", ROUND(100*(G25-J25)/ABS(J25),1)))) -> - | T25: その他 | AN25: =IF(AH25="-", "-", IF(AK25="-", "-", IF(ABS(AK25)=0, "-", ROUND(100*(AH25-AK25)/ABS(AK25),1)))) -> -
C26: 長期 | M26: =IF(G26="-", "-", IF(J26="-", "-", IF(ABS(J26)=0, "-", ROUND(100*(G26-J26)/ABS(J26),1)))) -> - | S26: 自動車 | AN26: =IF(AH26="-", "-", IF(AK26="-", "-", IF(ABS(AK26)=0, "-", ROUND(100*(AH26-AK26)/ABS(AK26),1)))) -> -
A27: 買掛未払金 | M27: =IF(G27="-", "-", IF(J27="-", "-", IF(ABS(J27)=0, "-", ROUND(100*(G27-J27)/ABS(J27),1)))) -> - | U27: 処分差損失 | AN27: =IF(AH27="-", "-", IF(AK27="-", "-", IF(ABS(AK27)=0, "-", ROUND(100*(AH27-AK27)/ABS(AK27),1)))) -> -
T28: 貨物自動車 | AE28: =IF(Y28="-", "-", IF(AB28="-", "-", IF(ABS(AB28)=0, "-", ROUND(100*(Y28-AB28)/ABS(AB28),1)))) -> - | AN28: =IF(AH28="-", "-", IF(AK28="-", "-", IF(ABS(AK28)=0, "-", ROUND(100*(AH28-AK28)/ABS(AK28),1)))) -> -
T29: その他 | AN29: =IF(AH29="-", "-", IF(AK29="-", "-", IF(ABS(AK29)=0, "-", ROUND(100*(AH29-AK29)/ABS(AK29),1)))) -> -
S30: 農機具 | AN30: =IF(AH30="-", "-", IF(AK30="-", "-", IF(ABS(AK30)=0, "-", ROUND(100*(AH30-AK30)/ABS(AK30),1)))) -> -
U31: 処分差損失 | AN31: =IF(AH31="-", "-", IF(AK31="-", "-", IF(ABS(AK31)=0, "-", ROUND(100*(AH31-AK31)/ABS(AK31),1)))) -> -
T32: 電動機 | AE32: =IF(Y32="-", "-", IF(AB32="-", "-", IF(ABS(AB32)=0, "-", ROUND(100*(Y32-AB32)/ABS(AB32),1)))) -> - | AN32: =IF(AH32="-", "-", IF(AK32="-", "-", IF(ABS(AK32)=0, "-", ROUND(100*(AH32-AK32)/ABS(AK32),1)))) -> -
T33: 発動機 | AE33: =IF(Y33="-", "-", IF(AB33="-", "-", IF(ABS(AB33)=0, "-", ROUND(100*(Y33-AB33)/ABS(AB33),1)))) -> - | AN33: =IF(AH33="-", "-", IF(AK33="-", "-", IF(ABS(AK33)=0, "-", ROUND(100*(AH33-AK33)/ABS(AK33),1)))) -> -
T34: 揚水ポンプ | AE34: =IF(Y34="-", "-", IF(AB34="-", "-", IF(ABS(AB34)=0, "-", ROUND(100*(Y34-AB34)/ABS(AB34),1)))) -> - | AN34: =IF(AH34="-", "-", IF(AK34="-", "-", IF(ABS(AK34)=0, "-", ROUND(100*(AH34-AK34)/ABS(AK34),1)))) -> -
T35: 乗 用 トラク タ ー | V35: 20馬力未満 | AE35: =IF(Y35="-", "-", IF(AB35="-", "-", IF(ABS(AB35)=0, "-", ROUND(100*(Y35-AB35)/ABS(AB35),1)))) -> - | AN35: =IF(AH35="-", "-", IF(AK35="-", "-", IF(ABS(AK35)=0, "-", ROUND(100*(AH35-AK35)/ABS(AK35),1)))) -> -
V36: 20～50馬力未満 | AE36: =IF(Y36="-", "-", IF(AB36="-", "-", IF(ABS(AB36)=0, "-", ROUND(100*(Y36-AB36)/ABS(AB36),1)))) -> - | AN36: =IF(AH36="-", "-", IF(AK36="-", "-", IF(ABS(AK36)=0, "-", ROUND(100*(AH36-AK36)/ABS(AK36),1)))) -> -
V37: 50～80馬力未満 | AE37: =IF(Y37="-", "-", IF(AB37="-", "-", IF(ABS(AB37)=0, "-", ROUND(100*(Y37-AB37)/ABS(AB37),1)))) -> - | AN37: =IF(AH37="-", "-", IF(AK37="-", "-", IF(ABS(AK37)=0, "-", ROUND(100*(AH37-AK37)/ABS(AK37),1)))) -> -
V38: 80～100馬力未満 | AE38: =IF(Y38="-", "-", IF(AB38="-", "-", IF(ABS(AB38)=0, "-", ROUND(100*(Y38-AB38)/ABS(AB38),1)))) -> - | AN38: =IF(AH38="-", "-", IF(AK38="-", "-", IF(ABS(AK38)=0, "-", ROUND(100*(AH38-AK38)/ABS(AK38),1)))) -> -
V39: 100馬力以上 | AE39: =IF(Y39="-", "-", IF(AB39="-", "-", IF(ABS(AB39)=0, "-", ROUND(100*(Y39-AB39)/ABS(AB39),1)))) -> - | AN39: =IF(AH39="-", "-", IF(AK39="-", "-", IF(ABS(AK39)=0, "-", ROUND(100*(AH39-AK39)/ABS(AK39),1)))) -> -
T40: 歩行用トラクター | AE40: =IF(Y40="-", "-", IF(AB40="-", "-", IF(ABS(AB40)=0, "-", ROUND(100*(Y40-AB40)/ABS(AB40),1)))) -> - | AN40: =IF(AH40="-", "-", IF(AK40="-", "-", IF(ABS(AK40)=0, "-", ROUND(100*(AH40-AK40)/ABS(AK40),1)))) -> -
T41: 電熱育苗機 | AE41: =IF(Y41="-", "-", IF(AB41="-", "-", IF(ABS(AB41)=0, "-", ROUND(100*(Y41-AB41)/ABS(AB41),1)))) -> - | AN41: =IF(AH41="-", "-", IF(AK41="-", "-", IF(ABS(AK41)=0, "-", ROUND(100*(AH41-AK41)/ABS(AK41),1)))) -> -
...
