Workbook
Name さとうきび: リスト!$Q$2:$Q$18
Name そば: リスト!$K$2:$K$18
Name てんさい: リスト!$P$2:$P$18
Name なたね: リスト!$O$2:$O$18
Name はだか麦: リスト!$J$2:$J$18
Name 牛乳異動事由: [1]種類・構造・型式・牛馬コード!$R$33:$T$40
Name 牛馬種類コード: [1]種類・構造・型式・牛馬コード!$R$2:$S$6
Name 型式コード: #REF!
Name 型式コード: #REF!
Name 型式コード: #REF!
Name 型式コード: #REF!
Name 建築物コード: #REF!
Name 建築物コード: #REF!
Name 建築物コード: #REF!
Name 建築物種類コード: [1]リスト!$E$5:$E$15
Name 建物コード: #REF!
Name 建物コード: #REF!
Name 建物コード: #REF!
Name 建物コード: #REF!
Name 原料用かんしょ: リスト!$M$2:$M$18
Name 原料用ばれいしょ: リスト!$N$2:$N$18
Name 個別経営体: リスト!$D$2:$D$6
Name 構造コード: #REF!
Name 構造コード: #REF!
Name 構造コード: #REF!
Name 構築物コード: #REF!
Name 構築物コード: #REF!
Name 構築物コード: #REF!
Name 残存割合: #REF!
Name 残存割合: #REF!
Name 残存割合: #REF!
Name 自給牧草給与割合: [1]自給飼料!$BW$52
Name 自動車コード: #REF!
Name 自動車コード: #REF!
Name 自動車コード: #REF!
Name 自動車コード: #REF!
Name 祝祭日: [2]祝祭日!$D$5:$E$31
Name 償却率: #REF!
Name 償却率: #REF!
Name 償却率: [1]種類・構造・型式・牛馬コード!$AH$4:$AI$103
Name 償却率: #REF!
Name 小麦: リスト!$G$2:$G$18
Name 新古_修繕区分: #REF!
Name 新古_修繕区分: #REF!
Name 新古_修繕区分: #REF!
Name 新古_修繕区分: #REF!
Name 性別コード: [1]種類・構造・型式・牛馬コード!$R$8:$T$10
Name 生産費: #REF!
Name 生産費: #REF!
Name 生産費: #REF!
Name 生産費: #REF!
Name 生産費該当畜区分コード: [1]種類・構造・型式・牛馬コード!$R$21:$T$25
Name 生産費区分: #REF!
Name 生産費区分: #REF!
Name 生産費区分: #REF!
Name 生産費区分: #REF!
Name 税制19年: #REF!
Name 税制19年: #REF!
Name 税制19年: #REF!
Name 税制20年: #REF!

Sheet 設定
C1: 農産物生産費統計 設定シート
B2: 2020センサス番号 <入力> | D2: 経営種類 <選択> | F2: 生産費区分 <選択>
C5: 設定 | G5: 集計 <自動>
B6: 集計月 | C6: 作業者 | D6: 性別 | E6: 年齢 | F6: 雇用形態 | G6: 労働時間
B7: <選択> | C7: <入力> | D7: <選択> | E7: <入力> | F7: <選択>
H8: =IF(設定!F3="米",リスト!F2, IF(OR(設定!F3="小麦",設定!F3="二条大麦",設定!F3="六条大麦",設定!F3="はだか麦"),リスト!G2, IF(設定!F3="そば",リスト!K2, IF(設定!F3="大豆",リスト!L2, IF(設定!F3="原料用かんしょ",リスト!M2, IF(設定!F3="原料用ばれいしょ",リスト!N2, IF(設定!F3="なたね",リスト!O2, IF(設定!F3="てんさい",リスト!P2, IF(設定!F3="さとうきび",リスト!Q2,""))))))))) | I8: =IF(設定!F3="米",リスト!F3, IF(OR(設定!F3="小麦",設定!F3="二条大麦",設定!F3="六条大麦",設定!F3="はだか麦"),リスト!G3, IF(設定!F3="そば",リスト!K3, IF(設定!F3="大豆",リスト!L3, IF(設定!F3="原料用かんしょ",リスト!M3, IF(設定!F3="原料用ばれいしょ",リスト!N3, IF(設定!F3="なたね",リスト!O3, IF(設定!F3="てんさい",リスト!P3, IF(設定!F3="さとうきび",リスト!Q3,""))))))))) | J8: =IF(設定!F3="米",リスト!F4, IF(OR(設定!F3="小麦",設定!F3="二条大麦",設定!F3="六条大麦",設定!F3="はだか麦"),リスト!G4, IF(設定!F3="そば",リスト!K4, IF(設定!F3="大豆",リスト!L4, IF(設定!F3="原料用かんしょ",リスト!M4, IF(設定!F3="原料用ばれいしょ",リスト!N4, IF(設定!F3="なたね",リスト!O4, IF(設定!F3="てんさい",リスト!P4, IF(設定!F3="さとうきび",リスト!Q4,""))))))))) | K8: =IF(設定!F3="米",リスト!F5, IF(OR(設定!F3="小麦",設定!F3="二条大麦",設定!F3="六条大麦",設定!F3="はだか麦"),リスト!G5, IF(設定!F3="そば",リスト!K5, IF(設定!F3="大豆",リスト!L5, IF(設定!F3="原料用かんしょ",リスト!M5, IF(設定!F3="原料用ばれいしょ",リスト!N5, IF(設定!F3="なたね",リスト!O5, IF(設定!F3="てんさい",リスト!P5, IF(設定!F3="さとうきび",リスト!Q5,""))))))))) | L8: =IF(設定!F3="米",リスト!F6, IF(OR(設定!F3="小麦",設定!F3="二条大麦",設定!F3="六条大麦",設定!F3="はだか麦"),リスト!G6, IF(設定!F3="そば",リスト!K6, IF(設定!F3="大豆",リスト!L6, IF(設定!F3="原料用かんしょ",リスト!M6, IF(設定!F3="原料用ばれいしょ",リスト!N6, IF(設定!F3="なたね",リスト!O6, IF(設定!F3="てんさい",リスト!P6, IF(設定!F3="さとうきび",リスト!Q6,""))))))))) | M8: =IF(設定!F3="米",リスト!F7, IF(OR(設定!F3="小麦",設定!F3="二条大麦",設定!F3="六条大麦",設定!F3="はだか麦"),リスト!G7, IF(設定!F3="そば",リスト!K7, IF(設定!F3="大豆",リスト!L7, IF(設定!F3="原料用かんしょ",リスト!M7, IF(設定!F3="原料用ばれいしょ",リスト!N7, IF(設定!F3="なたね",リスト!O7, IF(設定!F3="てんさい",リスト!P7, IF(設定!F3="さとうきび",リスト!Q7,""))))))))) | N8: =IF(設定!F3="米",リスト!F8, IF(OR(設定!F3="小麦",設定!F3="二条大麦",設定!F3="六条大麦",設定!F3="はだか麦"),リスト!G8, IF(設定!F3="そば",リスト!K8, IF(設定!F3="大豆",リスト!L8, IF(設定!F3="原料用かんしょ",リスト!M8, IF(設定!F3="原料用ばれいしょ",リスト!N8, IF(設定!F3="なたね",リスト!O8, IF(設定!F3="てんさい",リスト!P8, IF(設定!F3="さとうきび",リスト!Q8,""))))))))) | O8: =IF(設定!F3="米",リスト!F9, IF(OR(設定!F3="小麦",設定!F3="二条大麦",設定!F3="六条大麦",設定!F3="はだか麦"),リスト!G9, IF(設定!F3="そば",リスト!K9, IF(設定!F3="大豆",リスト!L9, IF(設定!F3="原料用かんしょ",リスト!M9, IF(設定!F3="原料用ばれいしょ",リスト!N9, IF(設定!F3="なたね",リスト!O9, IF(設定!F3="てんさい",リスト!P9, IF(設定!F3="さとうきび",リスト!Q9,""))))))))) | P8: =IF(設定!F3="米",リスト!F10, IF(OR(設定!F3="小麦",設定!F3="二条大麦",設定!F3="六条大麦",設定!F3="はだか麦"),リスト!G10, IF(設定!F3="そば",リスト!K10, IF(設定!F3="大豆",リスト!L10, IF(設定!F3="原料用かんしょ",リスト!M10, IF(設定!F3="原料用ばれいしょ",リスト!N10, IF(設定!F3="なたね",リスト!O10, IF(設定!F3="てんさい",リスト!P10, IF(設定!F3="さとうきび",リスト!Q10,""))))))))) | Q8: =IF(設定!F3="米",リスト!F11, IF(OR(設定!F3="小麦",設定!F3="二条大麦",設定!F3="六条大麦",設定!F3="はだか麦"),リスト!G11, IF(設定!F3="そば",リスト!K11, IF(設定!F3="大豆",リスト!L11, IF(設定!F3="原料用かんしょ",リスト!M11, IF(設定!F3="原料用ばれいしょ",リスト!N11, IF(設定!F3="なたね",リスト!O11, IF(設定!F3="てんさい",リスト!P11, IF(設定!F3="さとうきび",リスト!Q11,""))))))))) | R8: =IF(設定!F3="米",リスト!F12, IF(OR(設定!F3="小麦",設定!F3="二条大麦",設定!F3="六条大麦",設定!F3="はだか麦"),リスト!G12, IF(設定!F3="そば",リスト!K12, IF(設定!F3="大豆",リスト!L12, IF(設定!F3="原料用かんしょ",リスト!M12, IF(設定!F3="原料用ばれいしょ",リスト!N12, IF(設定!F3="なたね",リスト!O12, IF(設定!F3="てんさい",リスト!P12, IF(設定!F3="さとうきび",リスト!Q12,""))))))))) | S8: =IF(設定!F3="米",リスト!F13, IF(OR(設定!F3="小麦",設定!F3="二条大麦",設定!F3="六条大麦",設定!F3="はだか麦"),リスト!G13, IF(設定!F3="そば",リスト!K13, IF(設定!F3="大豆",リスト!L13, IF(設定!F3="原料用かんしょ",リスト!M13, IF(設定!F3="原料用ばれいしょ",リスト!N13, IF(設定!F3="なたね",リスト!O13, IF(設定!F3="てんさい",リスト!P13, IF(設定!F3="さとうきび",リスト!Q13,""))))))))) | T8: =IF(設定!F3="米",リスト!F14, IF(OR(設定!F3="小麦",設定!F3="二条大麦",設定!F3="六条大麦",設定!F3="はだか麦"),リスト!G14, IF(設定!F3="そば",リスト!K14, IF(設定!F3="大豆",リスト!L14, IF(設定!F3="原料用かんしょ",リスト!M14, IF(設定!F3="原料用ばれいしょ",リスト!N14, IF(設定!F3="なたね",リスト!O14, IF(設定!F3="てんさい",リスト!P14, IF(設定!F3="さとうきび",リスト!Q14,""))))))))) | U8: =IF(設定!F3="米",リスト!F15, IF(OR(設定!F3="小麦",設定!F3="二条大麦",設定!F3="六条大麦",設定!F3="はだか麦"),リスト!G15, IF(設定!F3="そば",リスト!K15, IF(設定!F3="大豆",リスト!L15, IF(設定!F3="原料用かんしょ",リスト!M15, IF(設定!F3="原料用ばれいしょ",リスト!N15, IF(設定!F3="なたね",リスト!O15, IF(設定!F3="てんさい",リスト!P15, IF(設定!F3="さとうきび",リスト!Q15,""))))))))) | V8: =IF(設定!F3="米",リスト!F16, IF(OR(設定!F3="小麦",設定!F3="二条大麦",設定!F3="六条大麦",設定!F3="はだか麦"),リスト!G16, IF(設定!F3="そば",リスト!K16, IF(設定!F3="大豆",リスト!L16, IF(設定!F3="原料用かんしょ",リスト!M16, IF(設定!F3="原料用ばれいしょ",リスト!N16, IF(設定!F3="なたね",リスト!O16, IF(設定!F3="てんさい",リスト!P16, IF(設定!F3="さとうきび",リスト!Q16,""))))))))) | W8: =IF(設定!F3="米",リスト!F17, IF(OR(設定!F3="小麦",設定!F3="二条大麦",設定!F3="六条大麦",設定!F3="はだか麦"),リスト!G17, IF(設定!F3="そば",リスト!K17, IF(設定!F3="大豆",リスト!L17, IF(設定!F3="原料用かんしょ",リスト!M17, IF(設定!F3="原料用ばれいしょ",リスト!N17, IF(設定!F3="なたね",リスト!O17, IF(設定!F3="てんさい",リスト!P17, IF(設定!F3="さとうきび",リスト!Q17,""))))))))) | X8: =IF(設定!F3="米",リスト!F18, IF(OR(設定!F3="小麦",設定!F3="二条大麦",設定!F3="六条大麦",設定!F3="はだか麦"),リスト!G18, IF(設定!F3="そば",リスト!K18, IF(設定!F3="大豆",リスト!L18, IF(設定!F3="原料用かんしょ",リスト!M18, IF(設定!F3="原料用ばれいしょ",リスト!N18, IF(設定!F3="なたね",リスト!O18, IF(設定!F3="てんさい",リスト!P18, IF(設定!F3="さとうきび",リスト!Q18,"")))))))))
G9: 時間 | H9: 時間 | I9: 時間 | J9: 時間 | K9: 時間 | L9: 時間 | M9: 時間 | N9: 時間 | O9: 時間 | P9: 時間 | Q9: 時間 | R9: 時間 | S9: 時間 | T9: 時間 | U9: 時間 | V9: 時間 | W9: 時間 | X9: 時間
B10: <=12 | G10: =SUM(H10:X10) -> 0 | H10: =SUMIFS(月別入力!$I:$I,月別入力!$E:$E,設定!$C10,月別入力!$D:$D,設定!H$8,月別入力!$B:$B,設定!$B10) -> 0 | I10: =SUMIFS(月別入力!$I:$I,月別入力!$E:$E,設定!$C10,月別入力!$D:$D,設定!I$8,月別入力!$B:$B,設定!$B10) -> 0 | J10: =SUMIFS(月別入力!$I:$I,月別入力!$E:$E,設定!$C10,月別入力!$D:$D,設定!J$8,月別入力!$B:$B,設定!$B10) -> 0 | K10: =SUMIFS(月別入力!$I:$I,月別入力!$E:$E,設定!$C10,月別入力!$D:$D,設定!K$8,月別入力!$B:$B,設定!$B10) -> 0 | L10: =SUMIFS(月別入力!$I:$I,月別入力!$E:$E,設定!$C10,月別入力!$D:$D,設定!L$8,月別入力!$B:$B,設定!$B10) -> 0 | M10: =SUMIFS(月別入力!$I:$I,月別入力!$E:$E,設定!$C10,月別入力!$D:$D,設定!M$8,月別入力!$B:$B,設定!$B10) -> 0 | N10: =SUMIFS(月別入力!$I:$I,月別入力!$E:$E,設定!$C10,月別入力!$D:$D,設定!N$8,月別入力!$B:$B,設定!$B10) -> 0 | O10: =SUMIFS(月別入力!$I:$I,月別入力!$E:$E,設定!$C10,月別入力!$D:$D,設定!O$8,月別入力!$B:$B,設定!$B10) -> 0 | ... X10: =SUMIFS(月別入力!$I:$I,月別入力!$E:$E,設定!$C10,月別入力!$D:$D,設定!X$8,月別入力!$B:$B,設定!$B10) -> 0
B11: =B$10 -> <=12 | G11: =SUM(H11:X11) -> 0 | H11: =SUMIFS(月別入力!$I:$I,月別入力!$E:$E,設定!$C11,月別入力!$D:$D,設定!H$8,月別入力!$B:$B,設定!$B11) -> 0 | I11: =SUMIFS(月別入力!$I:$I,月別入力!$E:$E,設定!$C11,月別入力!$D:$D,設定!I$8,月別入力!$B:$B,設定!$B11) -> 0 | J11: =SUMIFS(月別入力!$I:$I,月別入力!$E:$E,設定!$C11,月別入力!$D:$D,設定!J$8,月別入力!$B:$B,設定!$B11) -> 0 | K11: =SUMIFS(月別入力!$I:$I,月別入力!$E:$E,設定!$C11,月別入力!$D:$D,設定!K$8,月別入力!$B:$B,設定!$B11) -> 0 | L11: =SUMIFS(月別入力!$I:$I,月別入力!$E:$E,設定!$C11,月別入力!$D:$D,設定!L$8,月別入力!$B:$B,設定!$B11) -> 0 | M11: =SUMIFS(月別入力!$I:$I,月別入力!$E:$E,設定!$C11,月別入力!$D:$D,設定!M$8,月別入力!$B:$B,設定!$B11) -> 0 | N11: =SUMIFS(月別入力!$I:$I,月別入力!$E:$E,設定!$C11,月別入力!$D:$D,設定!N$8,月別入力!$B:$B,設定!$B11) -> 0 | O11: =SUMIFS(月別入力!$I:$I,月別入力!$E:$E,設定!$C11,月別入力!$D:$D,設定!O$8,月別入力!$B:$B,設定!$B11) -> 0 | ... X11: =SUMIFS(月別入力!$I:$I,月別入力!$E:$E,設定!$C11,月別入力!$D:$D,設定!X$8,月別入力!$B:$B,設定!$B11) -> 0
B12: =B$10 -> <=12 | G12: =SUM(H12:X12) -> 0 | H12: =SUMIFS(月別入力!$I:$I,月別入力!$E:$E,設定!$C12,月別入力!$D:$D,設定!H$8,月別入力!$B:$B,設定!$B12) -> 0 | I12: =SUMIFS(月別入力!$I:$I,月別入力!$E:$E,設定!$C12,月別入力!$D:$D,設定!I$8,月別入力!$B:$B,設定!$B12) -> 0 | J12: =SUMIFS(月別入力!$I:$I,月別入力!$E:$E,設定!$C12,月別入力!$D:$D,設定!J$8,月別入力!$B:$B,設定!$B12) -> 0 | K12: =SUMIFS(月別入力!$I:$I,月別入力!$E:$E,設定!$C12,月別入力!$D:$D,設定!K$8,月別入力!$B:$B,設定!$B12) -> 0 | L12: =SUMIFS(月別入力!$I:$I,月別入力!$E:$E,設定!$C12,月別入力!$D:$D,設定!L$8,月別入力!$B:$B,設定!$B12) -> 0 | M12: =SUMIFS(月別入力!$I:$I,月別入力!$E:$E,設定!$C12,月別入力!$D:$D,設定!M$8,月別入力!$B:$B,設定!$B12) -> 0 | N12: =SUMIFS(月別入力!$I:$I,月別入力!$E:$E,設定!$C12,月別入力!$D:$D,設定!N$8,月別入力!$B:$B,設定!$B12) -> 0 | O12: =SUMIFS(月別入力!$I:$I,月別入力!$E:$E,設定!$C12,月別入力!$D:$D,設定!O$8,月別入力!$B:$B,設定!$B12) -> 0 | ... X12: =SUMIFS(月別入力!$I:$I,月別入力!$E:$E,設定!$C12,月別入力!$D:$D,設定!X$8,月別入力!$B:$B,設定!$B12) -> 0
B13: =B$10 -> <=12 | G13: =SUM(H13:X13) -> 0 | H13: =SUMIFS(月別入力!$I:$I,月別入力!$E:$E,設定!$C13,月別入力!$D:$D,設定!H$8,月別入力!$B:$B,設定!$B13) -> 0 | I13: =SUMIFS(月別入力!$I:$I,月別入力!$E:$E,設定!$C13,月別入力!$D:$D,設定!I$8,月別入力!$B:$B,設定!$B13) -> 0 | J13: =SUMIFS(月別入力!$I:$I,月別入力!$E:$E,設定!$C13,月別入力!$D:$D,設定!J$8,月別入力!$B:$B,設定!$B13) -> 0 | K13: =SUMIFS(月別入力!$I:$I,月別入力!$E:$E,設定!$C13,月別入力!$D:$D,設定!K$8,月別入力!$B:$B,設定!$B13) -> 0 | L13: =SUMIFS(月別入力!$I:$I,月別入力!$E:$E,設定!$C13,月別入力!$D:$D,設定!L$8,月別入力!$B:$B,設定!$B13) -> 0 | M13: =SUMIFS(月別入力!$I:$I,月別入力!$E:$E,設定!$C13,月別入力!$D:$D,設定!M$8,月別入力!$B:$B,設定!$B13) -> 0 | N13: =SUMIFS(月別入力!$I:$I,月別入力!$E:$E,設定!$C13,月別入力!$D:$D,設定!N$8,月別入力!$B:$B,設定!$B13) -> 0 | O13: =SUMIFS(月別入力!$I:$I,月別入力!$E:$E,設定!$C13,月別入力!$D:$D,設定!O$8,月別入力!$B:$B,設定!$B13) -> 0 | ... X13: =SUMIFS(月別入力!$I:$I,月別入力!$E:$E,設定!$C13,月別入力!$D:$D,設定!X$8,月別入力!$B:$B,設定!$B13) -> 0
B14: =B$10 -> <=12 | G14: =SUM(H14:X14) -> 0 | H14: =SUMIFS(月別入力!$I:$I,月別入力!$E:$E,設定!$C14,月別入力!$D:$D,設定!H$8,月別入力!$B:$B,設定!$B14) -> 0 | I14: =SUMIFS(月別入力!$I:$I,月別入力!$E:$E,設定!$C14,月別入力!$D:$D,設定!I$8,月別入力!$B:$B,設定!$B14) -> 0 | J14: =SUMIFS(月別入力!$I:$I,月別入力!$E:$E,設定!$C14,月別入力!$D:$D,設定!J$8,月別入力!$B:$B,設定!$B14) -> 0 | K14: =SUMIFS(月別入力!$I:$I,月別入力!$E:$E,設定!$C14,月別入力!$D:$D,設定!K$8,月別入力!$B:$B,設定!$B14) -> 0 | L14: =SUMIFS(月別入力!$I:$I,月別入力!$E:$E,設定!$C14,月別入力!$D:$D,設定!L$8,月別入力!$B:$B,設定!$B14) -> 0 | M14: =SUMIFS(月別入力!$I:$I,月別入力!$E:$E,設定!$C14,月別入力!$D:$D,設定!M$8,月別入力!$B:$B,設定!$B14) -> 0 | N14: =SUMIFS(月別入力!$I:$I,月別入力!$E:$E,設定!$C14,月別入力!$D:$D,設定!N$8,月別入力!$B:$B,設定!$B14) -> 0 | O14: =SUMIFS(月別入力!$I:$I,月別入力!$E:$E,設定!$C14,月別入力!$D:$D,設定!O$8,月別入力!$B:$B,設定!$B14) -> 0 | ... X14: =SUMIFS(月別入力!$I:$I,月別入力!$E:$E,設定!$C14,月別入力!$D:$D,設定!X$8,月別入力!$B:$B,設定!$B14) -> 0
B15: =B$10 -> <=12 | G15: =SUM(H15:X15) -> 0 | H15: =SUMIFS(月別入力!$I:$I,月別入力!$E:$E,設定!$C15,月別入力!$D:$D,設定!H$8,月別入力!$B:$B,設定!$B15) -> 0 | I15: =SUMIFS(月別入力!$I:$I,月別入力!$E:$E,設定!$C15,月別入力!$D:$D,設定!I$8,月別入力!$B:$B,設定!$B15) -> 0 | J15: =SUMIFS(月別入力!$I:$I,月別入力!$E:$E,設定!$C15,月別入力!$D:$D,設定!J$8,月別入力!$B:$B,設定!$B15) -> 0 | K15: =SUMIFS(月別入力!$I:$I,月別入力!$E:$E,設定!$C15,月別入力!$D:$D,設定!K$8,月別入力!$B:$B,設定!$B15) -> 0 | L15: =SUMIFS(月別入力!$I:$I,月別入力!$E:$E,設定!$C15,月別入力!$D:$D,設定!L$8,月別入力!$B:$B,設定!$B15) -> 0 | M15: =SUMIFS(月別入力!$I:$I,月別入力!$E:$E,設定!$C15,月別入力!$D:$D,設定!M$8,月別入力!$B:$B,設定!$B15) -> 0 | N15: =SUMIFS(月別入力!$I:$I,月別入力!$E:$E,設定!$C15,月別入力!$D:$D,設定!N$8,月別入力!$B:$B,設定!$B15) -> 0 | O15: =SUMIFS(月別入力!$I:$I,月別入力!$E:$E,設定!$C15,月別入力!$D:$D,設定!O$8,月別入力!$B:$B,設定!$B15) -> 0 | ... X15: =SUMIFS(月別入力!$I:$I,月別入力!$E:$E,設定!$C15,月別入力!$D:$D,設定!X$8,月別入力!$B:$B,設定!$B15) -> 0
B16: =B$10 -> <=12 | G16: =SUM(H16:X16) -> 0 | H16: =SUMIFS(月別入力!$I:$I,月別入力!$E:$E,設定!$C16,月別入力!$D:$D,設定!H$8,月別入力!$B:$B,設定!$B16) -> 0 | I16: =SUMIFS(月別入力!$I:$I,月別入力!$E:$E,設定!$C16,月別入力!$D:$D,設定!I$8,月別入力!$B:$B,設定!$B16) -> 0 | J16: =SUMIFS(月別入力!$I:$I,月別入力!$E:$E,設定!$C16,月別入力!$D:$D,設定!J$8,月別入力!$B:$B,設定!$B16) -> 0 | K16: =SUMIFS(月別入力!$I:$I,月別入力!$E:$E,設定!$C16,月別入力!$D:$D,設定!K$8,月別入力!$B:$B,設定!$B16) -> 0 | L16: =SUMIFS(月別入力!$I:$I,月別入力!$E:$E,設定!$C16,月別入力!$D:$D,設定!L$8,月別入力!$B:$B,設定!$B16) -> 0 | M16: =SUMIFS(月別入力!$I:$I,月別入力!$E:$E,設定!$C16,月別入力!$D:$D,設定!M$8,月別入力!$B:$B,設定!$B16) -> 0 | N16: =SUMIFS(月別入力!$I:$I,月別入力!$E:$E,設定!$C16,月別入力!$D:$D,設定!N$8,月別入力!$B:$B,設定!$B16) -> 0 | O16: =SUMIFS(月別入力!$I:$I,月別入力!$E:$E,設定!$C16,月別入力!$D:$D,設定!O$8,月別入力!$B:$B,設定!$B16) -> 0 | ... X16: =SUMIFS(月別入力!$I:$I,月別入力!$E:$E,設定!$C16,月別入力!$D:$D,設定!X$8,月別入力!$B:$B,設定!$B16) -> 0
B17: =B$10 -> <=12 | G17: =SUM(H17:X17) -> 0 | H17: =SUMIFS(月別入力!$I:$I,月別入力!$E:$E,設定!$C17,月別入力!$D:$D,設定!H$8,月別入力!$B:$B,設定!$B17) -> 0 | I17: =SUMIFS(月別入力!$I:$I,月別入力!$E:$E,設定!$C17,月別入力!$D:$D,設定!I$8,月別入力!$B:$B,設定!$B17) -> 0 | J17: =SUMIFS(月別入力!$I:$I,月別入力!$E:$E,設定!$C17,月別入力!$D:$D,設定!J$8,月別入力!$B:$B,設定!$B17) -> 0 | K17: =SUMIFS(月別入力!$I:$I,月別入力!$E:$E,設定!$C17,月別入力!$D:$D,設定!K$8,月別入力!$B:$B,設定!$B17) -> 0 | L17: =SUMIFS(月別入力!$I:$I,月別入力!$E:$E,設定!$C17,月別入力!$D:$D,設定!L$8,月別入力!$B:$B,設定!$B17) -> 0 | M17: =SUMIFS(月別入力!$I:$I,月別入力!$E:$E,設定!$C17,月別入力!$D:$D,設定!M$8,月別入力!$B:$B,設定!$B17) -> 0 | N17: =SUMIFS(月別入力!$I:$I,月別入力!$E:$E,設定!$C17,月別入力!$D:$D,設定!N$8,月別入力!$B:$B,設定!$B17) -> 0 | O17: =SUMIFS(月別入力!$I:$I,月別入力!$E:$E,設定!$C17,月別入力!$D:$D,設定!O$8,月別入力!$B:$B,設定!$B17) -> 0 | ... X17: =SUMIFS(月別入力!$I:$I,月別入力!$E:$E,設定!$C17,月別入力!$D:$D,設定!X$8,月別入力!$B:$B,設定!$B17) -> 0
B18: =B$10 -> <=12 | G18: =SUM(H18:X18) -> 0 | H18: =SUMIFS(月別入力!$I:$I,月別入力!$E:$E,設定!$C18,月別入力!$D:$D,設定!H$8,月別入力!$B:$B,設定!$B18) -> 0 | I18: =SUMIFS(月別入力!$I:$I,月別入力!$E:$E,設定!$C18,月別入力!$D:$D,設定!I$8,月別入力!$B:$B,設定!$B18) -> 0 | J18: =SUMIFS(月別入力!$I:$I,月別入力!$E:$E,設定!$C18,月別入力!$D:$D,設定!J$8,月別入力!$B:$B,設定!$B18) -> 0 | K18: =SUMIFS(月別入力!$I:$I,月別入力!$E:$E,設定!$C18,月別入力!$D:$D,設定!K$8,月別入力!$B:$B,設定!$B18) -> 0 | L18: =SUMIFS(月別入力!$I:$I,月別入力!$E:$E,設定!$C18,月別入力!$D:$D,設定!L$8,月別入力!$B:$B,設定!$B18) -> 0 | M18: =SUMIFS(月別入力!$I:$I,月別入力!$E:$E,設定!$C18,月別入力!$D:$D,設定!M$8,月別入力!$B:$B,設定!$B18) -> 0 | N18: =SUMIFS(月別入力!$I:$I,月別入力!$E:$E,設定!$C18,月別入力!$D:$D,設定!N$8,月別入力!$B:$B,設定!$B18) -> 0 | O18: =SUMIFS(月別入力!$I:$I,月別入力!$E:$E,設定!$C18,月別入力!$D:$D,設定!O$8,月別入力!$B:$B,設定!$B18) -> 0 | ... X18: =SUMIFS(月別入力!$I:$I,月別入力!$E:$E,設定!$C18,月別入力!$D:$D,設定!X$8,月別入力!$B:$B,設定!$B18) -> 0
B19: =B$10 -> <=12 | G19: =SUM(H19:X19) -> 0 | H19: =SUMIFS(月別入力!$I:$I,月別入力!$E:$E,設定!$C19,月別入力!$D:$D,設定!H$8,月別入力!$B:$B,設定!$B19) -> 0 | I19: =SUMIFS(月別入力!$I:$I,月別入力!$E:$E,設定!$C19,月別入力!$D:$D,設定!I$8,月別入力!$B:$B,設定!$B19) -> 0 | J19: =SUMIFS(月別入力!$I:$I,月別入力!$E:$E,設定!$C19,月別入力!$D:$D,設定!J$8,月別入力!$B:$B,設定!$B19) -> 0 | K19: =SUMIFS(月別入力!$I:$I,月別入力!$E:$E,設定!$C19,月別入力!$D:$D,設定!K$8,月別入力!$B:$B,設定!$B19) -> 0 | L19: =SUMIFS(月別入力!$I:$I,月別入力!$E:$E,設定!$C19,月別入力!$D:$D,設定!L$8,月別入力!$B:$B,設定!$B19) -> 0 | M19: =SUMIFS(月別入力!$I:$I,月別入力!$E:$E,設定!$C19,月別入力!$D:$D,設定!M$8,月別入力!$B:$B,設定!$B19) -> 0 | N19: =SUMIFS(月別入力!$I:$I,月別入力!$E:$E,設定!$C19,月別入力!$D:$D,設定!N$8,月別入力!$B:$B,設定!$B19) -> 0 | O19: =SUMIFS(月別入力!$I:$I,月別入力!$E:$E,設定!$C19,月別入力!$D:$D,設定!O$8,月別入力!$B:$B,設定!$B19) -> 0 | ... X19: =SUMIFS(月別入力!$I:$I,月別入力!$E:$E,設定!$C19,月別入力!$D:$D,設定!X$8,月別入力!$B:$B,設定!$B19) -> 0
B20: =B$10 -> <=12 | G20: =SUM(H20:X20) -> 0 | H20: =SUMIFS(月別入力!$I:$I,月別入力!$E:$E,設定!$C20,月別入力!$D:$D,設定!H$8,月別入力!$B:$B,設定!$B20) -> 0 | I20: =SUMIFS(月別入力!$I:$I,月別入力!$E:$E,設定!$C20,月別入力!$D:$D,設定!I$8,月別入力!$B:$B,設定!$B20) -> 0 | J20: =SUMIFS(月別入力!$I:$I,月別入力!$E:$E,設定!$C20,月別入力!$D:$D,設定!J$8,月別入力!$B:$B,設定!$B20) -> 0 | K20: =SUMIFS(月別入力!$I:$I,月別入力!$E:$E,設定!$C20,月別入力!$D:$D,設定!K$8,月別入力!$B:$B,設定!$B20) -> 0 | L20: =SUMIFS(月別入力!$I:$I,月別入力!$E:$E,設定!$C20,月別入力!$D:$D,設定!L$8,月別入力!$B:$B,設定!$B20) -> 0 | M20: =SUMIFS(月別入力!$I:$I,月別入力!$E:$E,設定!$C20,月別入力!$D:$D,設定!M$8,月別入力!$B:$B,設定!$B20) -> 0 | N20: =SUMIFS(月別入力!$I:$I,月別入力!$E:$E,設定!$C20,月別入力!$D:$D,設定!N$8,月別入力!$B:$B,設定!$B20) -> 0 | O20: =SUMIFS(月別入力!$I:$I,月別入力!$E:$E,設定!$C20,月別入力!$D:$D,設定!O$8,月別入力!$B:$B,設定!$B20) -> 0 | ... X20: =SUMIFS(月別入力!$I:$I,月別入力!$E:$E,設定!$C20,月別入力!$D:$D,設定!X$8,月別入力!$B:$B,設定!$B20) -> 0
B21: =B$10 -> <=12 | G21: =SUM(H21:X21) -> 0 | H21: =SUMIFS(月別入力!$I:$I,月別入力!$E:$E,設定!$C21,月別入力!$D:$D,設定!H$8,月別入力!$B:$B,設定!$B21) -> 0 | I21: =SUMIFS(月別入力!$I:$I,月別入力!$E:$E,設定!$C21,月別入力!$D:$D,設定!I$8,月別入力!$B:$B,設定!$B21) -> 0 | J21: =SUMIFS(月別入力!$I:$I,月別入力!$E:$E,設定!$C21,月別入力!$D:$D,設定!J$8,月別入力!$B:$B,設定!$B21) -> 0 | K21: =SUMIFS(月別入力!$I:$I,月別入力!$E:$E,設定!$C21,月別入力!$D:$D,設定!K$8,月別入力!$B:$B,設定!$B21) -> 0 | L21: =SUMIFS(月別入力!$I:$I,月別入力!$E:$E,設定!$C21,月別入力!$D:$D,設定!L$8,月別入力!$B:$B,設定!$B21) -> 0 | M21: =SUMIFS(月別入力!$I:$I,月別入力!$E:$E,設定!$C21,月別入力!$D:$D,設定!M$8,月別入力!$B:$B,設定!$B21) -> 0 | N21: =SUMIFS(月別入力!$I:$I,月別入力!$E:$E,設定!$C21,月別入力!$D:$D,設定!N$8,月別入力!$B:$B,設定!$B21) -> 0 | O21: =SUMIFS(月別入力!$I:$I,月別入力!$E:$E,設定!$C21,月別入力!$D:$D,設定!O$8,月別入力!$B:$B,設定!$B21) -> 0 | ... X21: =SUMIFS(月別入力!$I:$I,月別入力!$E:$E,設定!$C21,月別入力!$D:$D,設定!X$8,月別入力!$B:$B,設定!$B21) -> 0
B22: =B$10 -> <=12 | G22: =SUM(H22:X22) -> 0 | H22: =SUMIFS(月別入力!$I:$I,月別入力!$E:$E,設定!$C22,月別入力!$D:$D,設定!H$8,月別入力!$B:$B,設定!$B22) -> 0 | I22: =SUMIFS(月別入力!$I:$I,月別入力!$E:$E,設定!$C22,月別入力!$D:$D,設定!I$8,月別入力!$B:$B,設定!$B22) -> 0 | J22: =SUMIFS(月別入力!$I:$I,月別入力!$E:$E,設定!$C22,月別入力!$D:$D,設定!J$8,月別入力!$B:$B,設定!$B22) -> 0 | K22: =SUMIFS(月別入力!$I:$I,月別入力!$E:$E,設定!$C22,月別入力!$D:$D,設定!K$8,月別入力!$B:$B,設定!$B22) -> 0 | L22: =SUMIFS(月別入力!$I:$I,月別入力!$E:$E,設定!$C22,月別入力!$D:$D,設定!L$8,月別入力!$B:$B,設定!$B22) -> 0 | M22: =SUMIFS(月別入力!$I:$I,月別入力!$E:$E,設定!$C22,月別入力!$D:$D,設定!M$8,月別入力!$B:$B,設定!$B22) -> 0 | N22: =SUMIFS(月別入力!$I:$I,月別入力!$E:$E,設定!$C22,月別入力!$D:$D,設定!N$8,月別入力!$B:$B,設定!$B22) -> 0 | O22: =SUMIFS(月別入力!$I:$I,月別入力!$E:$E,設定!$C22,月別入力!$D:$D,設定!O$8,月別入力!$B:$B,設定!$B22) -> 0 | ... X22: =SUMIFS(月別入力!$I:$I,月別入力!$E:$E,設定!$C22,月別入力!$D:$D,設定!X$8,月別入力!$B:$B,設定!$B22) -> 0
... B109: =B$10 -> <=12 | G109: =SUM(H109:X109) -> 0 | H109: =SUMIFS(月別入力!$I:$I,月別入力!$E:$E,設定!$C109,月別入力!$D:$D,設定!H$8,月別入力!$B:$B,設定!$B109) -> 0 | I109: =SUMIFS(月別入力!$I:$I,月別入力!$E:$E,設定!$C109,月別入力!$D:$D,設定!I$8,月別入力!$B:$B,設定!$B109) -> 0 | J109: =SUMIFS(月別入力!$I:$I,月別入力!$E:$E,設定!$C109,月別入力!$D:$D,設定!J$8,月別入力!$B:$B,設定!$B109) -> 0 | K109: =SUMIFS(月別入力!$I:$I,月別入力!$E:$E,設定!$C109,月別入力!$D:$D,設定!K$8,月別入力!$B:$B,設定!$B109) -> 0 | L109: =SUMIFS(月別入力!$I:$I,月別入力!$E:$E,設定!$C109,月別入力!$D:$D,設定!L$8,月別入力!$B:$B,設定!$B109) -> 0 | M109: =SUMIFS(月別入力!$I:$I,月別入力!$E:$E,設定!$C109,月別入力!$D:$D,設定!M$8,月別入力!$B:$B,設定!$B109) -> 0 | N109: =SUMIFS(月別入力!$I:$I,月別入力!$E:$E,設定!$C109,月別入力!$D:$D,設定!N$8,月別入力!$B:$B,設定!$B109) -> 0 | O109: =SUMIFS(月別入力!$I:$I,月別入力!$E:$E,設定!$C109,月別入力!$D:$D,設定!O$8,月別入力!$B:$B,設定!$B109) -> 0 | ... X109: =SUMIFS(月別入力!$I:$I,月別入力!$E:$E,設定!$C109,月別入力!$D:$D,設定!X$8,月別入力!$B:$B,設定!$B109) -> 0

Sheet 月別入力
B1: 農産物生産費統計 入力シート（月別）
B2: 2020センサス番号 <自動>
B3: =設定!B3 -> 0
B5: 月 | C5: 作業 <入力> | D5: →集計分類 <選択> | E5: 作業者 <選択> | F5: 性別 <自動> | G5: 年齢 <自動> | H5: 雇用形態 <自動> | I5: 労働時間 <入力>
F7: =IFERROR(VLOOKUP($E7,設定!$C:$F,2,0),"") | G7: =IFERROR(VLOOKUP($E7,設定!$C:$F,3,0),"") | H7: =IFERROR(VLOOKUP($E7,設定!$C:$F,4,0),"")
F8: =IFERROR(VLOOKUP($E8,設定!$C:$F,2,0),"") | G8: =IFERROR(VLOOKUP($E8,設定!$C:$F,3,0),"") | H8: =IFERROR(VLOOKUP($E8,設定!$C:$F,4,0),"")
F9: =IFERROR(VLOOKUP($E9,設定!$C:$F,2,0),"") | G9: =IFERROR(VLOOKUP($E9,設定!$C:$F,3,0),"") | H9: =IFERROR(VLOOKUP($E9,設定!$C:$F,4,0),"")
F10: =IFERROR(VLOOKUP($E10,設定!$C:$F,2,0),"") | G10: =IFERROR(VLOOKUP($E10,設定!$C:$F,3,0),"") | H10: =IFERROR(VLOOKUP($E10,設定!$C:$F,4,0),"")
F11: =IFERROR(VLOOKUP($E11,設定!$C:$F,2,0),"") | G11: =IFERROR(VLOOKUP($E11,設定!$C:$F,3,0),"") | H11: =IFERROR(VLOOKUP($E11,設定!$C:$F,4,0),"")
F12: =IFERROR(VLOOKUP($E12,設定!$C:$F,2,0),"") | G12: =IFERROR(VLOOKUP($E12,設定!$C:$F,3,0),"") | H12: =IFERROR(VLOOKUP($E12,設定!$C:$F,4,0),"")
F13: =IFERROR(VLOOKUP($E13,設定!$C:$F,2,0),"") | G13: =IFERROR(VLOOKUP($E13,設定!$C:$F,3,0),"") | H13: =IFERROR(VLOOKUP($E13,設定!$C:$F,4,0),"")
F14: =IFERROR(VLOOKUP($E14,設定!$C:$F,2,0),"") | G14: =IFERROR(VLOOKUP($E14,設定!$C:$F,3,0),"") | H14: =IFERROR(VLOOKUP($E14,設定!$C:$F,4,0),"")
F15: =IFERROR(VLOOKUP($E15,設定!$C:$F,2,0),"") | G15: =IFERROR(VLOOKUP($E15,設定!$C:$F,3,0),"") | H15: =IFERROR(VLOOKUP($E15,設定!$C:$F,4,0),"")
F16: =IFERROR(VLOOKUP($E16,設定!$C:$F,2,0),"") | G16: =IFERROR(VLOOKUP($E16,設定!$C:$F,3,0),"") | H16: =IFERROR(VLOOKUP($E16,設定!$C:$F,4,0),"")
F17: =IFERROR(VLOOKUP($E17,設定!$C:$F,2,0),"") | G17: =IFERROR(VLOOKUP($E17,設定!$C:$F,3,0),"") | H17: =IFERROR(VLOOKUP($E17,設定!$C:$F,4,0),"")
F18: =IFERROR(VLOOKUP($E18,設定!$C:$F,2,0),"") | G18: =IFERROR(VLOOKUP($E18,設定!$C:$F,3,0),"") | H18: =IFERROR(VLOOKUP($E18,設定!$C:$F,4,0),"")
... F106: =IFERROR(VLOOKUP($E106,設定!$C:$F,2,0),"") | G106: =IFERROR(VLOOKUP($E106,設定!$C:$F,3,0),"") | H106: =IFERROR(VLOOKUP($E106,設定!$C:$F,4,0),"")

Sheet 【12】作業別労働時間①_個別
A1: 農産物生産費統計 調査票貼付シート | BB1: 【職員記入欄】
A2: 【12】作業別労働時間 | BB2: 【12】作業別労働時間
BB6: 作業別労働時間
A7: １ 家族労働時間 | AJ7: ２ 雇用労働時間
U9: 単位：時間 | AX9: 単位：時間 | BM9: 単位：時間
C10: 作業 種類 | F10: 内容例示 | P10: 1 | Q10: 2 | R10: 3 | S10: 4 | T10: 5 | U10: 6 | V10: 7 | W10: 8 | X10: 9 | Y10: 10 | Z10: 11 | AA10: 12 | AB10: 13 | AC10: 14 | AD10: 15 | AE10: 16 | AF10: 17 | AG10: 18 | AH10: 19 | AI10: 20 | AJ10: 雇用労働 時間 男 | AK10: 雇用労働 時間 女 | AL10: 作業 種類 | AO10: 内容例示 | BD10: 家族 | BG10: 雇用
M11: 氏名 | P11: =リスト!T2 | Q11: =リスト!T3 | R11: =リスト!T4 | S11: =リスト!T5 | T11: =リスト!T6 | U11: =リスト!T7 | V11: =リスト!T8 | W11: =リスト!T9 | X11: =リスト!T10 | Y11: =リスト!T11 | Z11: =リスト!T12 | AA11: =リスト!T13 | AB11: =リスト!T14 | AC11: =リスト!T15 | AD11: =リスト!T16 | AE11: =リスト!T17 | AF11: =リスト!T18 | AG11: =リスト!T19 | AH11: =リスト!T20 | AI11: =リスト!T21 | BD11: 男 | BE11: 女 | BF11: 小計 | BG11: 男 | BJ11: 女 | BM11: 小 計
M12: 性別 | P12: =IFERROR(VLOOKUP(P11,設定!$C:$E,2,0),"") | Q12: =IFERROR(VLOOKUP(Q11,設定!$C:$E,2,0),"") | R12: =IFERROR(VLOOKUP(R11,設定!$C:$E,2,0),"") | S12: =IFERROR(VLOOKUP(S11,設定!$C:$E,2,0),"") | T12: =IFERROR(VLOOKUP(T11,設定!$C:$E,2,0),"") | U12: =IFERROR(VLOOKUP(U11,設定!$C:$E,2,0),"") | V12: =IFERROR(VLOOKUP(V11,設定!$C:$E,2,0),"") | W12: =IFERROR(VLOOKUP(W11,設定!$C:$E,2,0),"") | ... AI12: =IFERROR(VLOOKUP(AI11,設定!$C:$E,2,0),"") | BG12: 雇用 | BH12: 同居人、手伝い・共同作業受け | BI12: 計 | BJ12: 雇用 | BK12: 同居人、手伝い・共同作業受け | BL12: 計
M13: 年齢 | P13: =IFERROR(VLOOKUP(P11,設定!$C:$E,3,0),"") | Q13: =IFERROR(VLOOKUP(Q11,設定!$C:$E,3,0),"") | R13: =IFERROR(VLOOKUP(R11,設定!$C:$E,3,0),"") | S13: =IFERROR(VLOOKUP(S11,設定!$C:$E,3,0),"") | T13: =IFERROR(VLOOKUP(T11,設定!$C:$E,3,0),"") | U13: =IFERROR(VLOOKUP(U11,設定!$C:$E,3,0),"") | V13: =IFERROR(VLOOKUP(V11,設定!$C:$E,3,0),"") | W13: =IFERROR(VLOOKUP(W11,設定!$C:$E,3,0),"") | ... AI13: =IFERROR(VLOOKUP(AI11,設定!$C:$E,3,0),"")
A14: 【職員記入欄】 | F14: 該当する人別区分を 選択してください。 | M14: 人別区分 | P14: =IFERROR(VLOOKUP(P11,設定!$C:$F,4,0),"") | Q14: =IFERROR(VLOOKUP(Q11,設定!$C:$F,4,0),"") | R14: =IFERROR(VLOOKUP(R11,設定!$C:$F,4,0),"") | S14: =IFERROR(VLOOKUP(S11,設定!$C:$F,4,0),"") | T14: =IFERROR(VLOOKUP(T11,設定!$C:$F,4,0),"") | U14: =IFERROR(VLOOKUP(U11,設定!$C:$F,4,0),"") | V14: =IFERROR(VLOOKUP(V11,設定!$C:$F,4,0),"") | W14: =IFERROR(VLOOKUP(W11,設定!$C:$F,4,0),"") | ... AI14: =IFERROR(VLOOKUP(AI11,設定!$C:$F,4,0),"") | BB14: 計 | BD14: =SUBTOTAL(109,BD15:BD30) -> 0 | BE14: =SUBTOTAL(109,BE15:BE30) -> 0 | BF14: =SUM(BD14:BE14) -> 0 | BG14: =SUBTOTAL(109,BG15:BG29) -> 0 | BH14: =SUBTOTAL(109,BH15:BH29) -> 0 | BI14: =SUM(BG14:BH14) -> 0 | BJ14: =SUBTOTAL(109,BJ15:BJ29) -> 0 | BK14: =SUBTOTAL(109,BK15:BK29) -> 0 | BL14: =SUM(BJ14:BK14) -> 0 | BM14: =SUM(BI14,BL14) -> 0
C15: =設定!H8 | P15: =ROUND(SUMIFS(月別入力!$I:$I,月別入力!$D:$D,$C15,月別入力!$E:$E,P$11),1) -> 0 | Q15: =ROUND(SUMIFS(月別入力!$I:$I,月別入力!$D:$D,$C15,月別入力!$E:$E,Q$11),1) -> 0 | R15: =ROUND(SUMIFS(月別入力!$I:$I,月別入力!$D:$D,$C15,月別入力!$E:$E,R$11),1) -> 0 | S15: =ROUND(SUMIFS(月別入力!$I:$I,月別入力!$D:$D,$C15,月別入力!$E:$E,S$11),1) -> 0 | T15: =ROUND(SUMIFS(月別入力!$I:$I,月別入力!$D:$D,$C15,月別入力!$E:$E,T$11),1) -> 0 | U15: =ROUND(SUMIFS(月別入力!$I:$I,月別入力!$D:$D,$C15,月別入力!$E:$E,U$11),1) -> 0 | V15: =ROUND(SUMIFS(月別入力!$I:$I,月別入力!$D:$D,$C15,月別入力!$E:$E,V$11),1) -> 0 | W15: =ROUND(SUMIFS(月別入力!$I:$I,月別入力!$D:$D,$C15,月別入力!$E:$E,W$11),1) -> 0 | ... AI15: =ROUND(SUMIFS(月別入力!$I:$I,月別入力!$D:$D,$C15,月別入力!$E:$E,AI$11),1) -> 0 | AJ15: =ROUND(SUMIFS(月別入力!$I:$I,月別入力!$D:$D,$C15,月別入力!$H:$H,"[5]雇用",月別入力!$F:$F,"[1]男"),1) -> 0 | AK15: =ROUND(SUMIFS(月別入力!$I:$I,月別入力!$D:$D,$C15,月別入力!$H:$H,"[5]雇用",月別入力!$F:$F,"[2]女"),1) -> 0 | AL15: =C15 | BB15: 直接労働時間 | BC15: 種子予措 | BD15: =SUM(SUMIFS(P15:AI15,P14:AI14,{"[1]家族","[3]ゆい・手間替え受け"},P12:AI12,"[1]男")) -> 0 | BE15: =SUM(SUMIFS(P15:AI15,P14:AI14,{"[1]家族","[3]ゆい・手間替え受け"},P12:AI12,"[2]女")) -> 0 | BF15: =SUM(BD15:BE15) -> 0 | BG15: =AJ15 -> 0 | BH15: =SUM(SUMIFS(P15:AI15,P14:AI14,{"[2]同居人","[4]手伝い・共同作業受け"},P12:AI12,"[1]男")) -> 0 | BI15: =SUM(BG15:BH15) -> 0 | BJ15: =AK15 -> 0 | BK15: =SUM(SUMIFS(P15:AI15,P14:AI14,{"[2]同居人","[4]手伝い・共同作業受け"},P12:AI12,"[2]女")) -> 0 | BL15: =SUM(BJ15:BK15) -> 0 | BM15: =SUM(BI15,BL15) -> 0
C16: =設定!I8 | P16: =ROUND(SUMIFS(月別入力!$I:$I,月別入力!$D:$D,$C16,月別入力!$E:$E,P$11),1) -> 0 | Q16: =ROUND(SUMIFS(月別入力!$I:$I,月別入力!$D:$D,$C16,月別入力!$E:$E,Q$11),1) -> 0 | R16: =ROUND(SUMIFS(月別入力!$I:$I,月別入力!$D:$D,$C16,月別入力!$E:$E,R$11),1) -> 0 | S16: =ROUND(SUMIFS(月別入力!$I:$I,月別入力!$D:$D,$C16,月別入力!$E:$E,S$11),1) -> 0 | T16: =ROUND(SUMIFS(月別入力!$I:$I,月別入力!$D:$D,$C16,月別入力!$E:$E,T$11),1) -> 0 | U16: =ROUND(SUMIFS(月別入力!$I:$I,月別入力!$D:$D,$C16,月別入力!$E:$E,U$11),1) -> 0 | V16: =ROUND(SUMIFS(月別入力!$I:$I,月別入力!$D:$D,$C16,月別入力!$E:$E,V$11),1) -> 0 | W16: =ROUND(SUMIFS(月別入力!$I:$I,月別入力!$D:$D,$C16,月別入力!$E:$E,W$11),1) -> 0 | ... AI16: =ROUND(SUMIFS(月別入力!$I:$I,月別入力!$D:$D,$C16,月別入力!$E:$E,AI$11),1) -> 0 | AJ16: =ROUND(SUMIFS(月別入力!$I:$I,月別入力!$D:$D,$C16,月別入力!$H:$H,"[5]雇用",月別入力!$F:$F,"[1]男"),1) -> 0 | AK16: =ROUND(SUMIFS(月別入力!$I:$I,月別入力!$D:$D,$C16,月別入力!$H:$H,"[5]雇用",月別入力!$F:$F,"[2]女"),1) -> 0 | AL16: =C16 | BC16: 育苗 | BD16: =SUM(SUMIFS(P16:AI16,P14:AI14,{"[1]家族","[3]ゆい・手間替え受け"},P12:AI12,"[1]男")) -> 0 | BE16: =SUM(SUMIFS(P16:AI16,P14:AI14,{"[1]家族","[3]ゆい・手間替え受け"},P12:AI12,"[2]女")) -> 0 | BF16: =SUM(BD16:BE16) -> 0 | BG16: =AJ16 -> 0 | BH16: =SUM(SUMIFS(P16:AI16,P14:AI14,{"[2]同居人","[4]手伝い・共同作業受け"},P12:AI12,"[1]男")) -> 0 | BI16: =SUM(BG16:BH16) -> 0 | BJ16: =AK16 -> 0 | BK16: =SUM(SUMIFS(P16:AI16,P14:AI14,{"[2]同居人","[4]手伝い・共同作業受け"},P12:AI12,"[2]女")) -> 0 | BL16: =SUM(BJ16:BK16) -> 0 | BM16: =SUM(BI16,BL16) -> 0
C17: =設定!J8 | P17: =ROUND(SUMIFS(月別入力!$I:$I,月別入力!$D:$D,$C17,月別入力!$E:$E,P$11),1) -> 0 | Q17: =ROUND(SUMIFS(月別入力!$I:$I,月別入力!$D:$D,$C17,月別入力!$E:$E,Q$11),1) -> 0 | R17: =ROUND(SUMIFS(月別入力!$I:$I,月別入力!$D:$D,$C17,月別入力!$E:$E,R$11),1) -> 0 | S17: =ROUND(SUMIFS(月別入力!$I:$I,月別入力!$D:$D,$C17,月別入力!$E:$E,S$11),1) -> 0 | T17: =ROUND(SUMIFS(月別入力!$I:$I,月別入力!$D:$D,$C17,月別入力!$E:$E,T$11),1) -> 0 | U17: =ROUND(SUMIFS(月別入力!$I:$I,月別入力!$D:$D,$C17,月別入力!$E:$E,U$11),1) -> 0 | V17: =ROUND(SUMIFS(月別入力!$I:$I,月別入力!$D:$D,$C17,月別入力!$E:$E,V$11),1) -> 0 | W17: =ROUND(SUMIFS(月別入力!$I:$I,月別入力!$D:$D,$C17,月別入力!$E:$E,W$11),1) -> 0 | ... AI17: =ROUND(SUMIFS(月別入力!$I:$I,月別入力!$D:$D,$C17,月別入力!$E:$E,AI$11),1) -> 0 | AJ17: =ROUND(SUMIFS(月別入力!$I:$I,月別入力!$D:$D,$C17,月別入力!$H:$H,"[5]雇用",月別入力!$F:$F,"[1]男"),1) -> 0 | AK17: =ROUND(SUMIFS(月別入力!$I:$I,月別入力!$D:$D,$C17,月別入力!$H:$H,"[5]雇用",月別入力!$F:$F,"[2]女"),1) -> 0 | AL17: =C17 | BC17: 耕起整地 | BD17: =SUM(SUMIFS(P17:AI17,P14:AI14,{"[1]家族","[3]ゆい・手間替え受け"},P12:AI12,"[1]男")) -> 0 | BE17: =SUM(SUMIFS(P17:AI17,P14:AI14,{"[1]家族","[3]ゆい・手間替え受け"},P12:AI12,"[2]女")) -> 0 | BF17: =SUM(BD17:BE17) -> 0 | BG17: =AJ17 -> 0 | BH17: =SUM(SUMIFS(P17:AI17,P14:AI14,{"[2]同居人","[4]手伝い・共同作業受け"},P12:AI12,"[1]男")) -> 0 | BI17: =SUM(BG17:BH17) -> 0 | BJ17: =AK17 -> 0 | BK17: =SUM(SUMIFS(P17:AI17,P14:AI14,{"[2]同居人","[4]手伝い・共同作業受け"},P12:AI12,"[2]女")) -> 0 | BL17: =SUM(BJ17:BK17) -> 0 | BM17: =SUM(BI17,BL17) -> 0
C18: =設定!K8 | P18: =ROUND(SUMIFS(月別入力!$I:$I,月別入力!$D:$D,$C18,月別入力!$E:$E,P$11),1) -> 0 | Q18: =ROUND(SUMIFS(月別入力!$I:$I,月別入力!$D:$D,$C18,月別入力!$E:$E,Q$11),1) -> 0 | R18: =ROUND(SUMIFS(月別入力!$I:$I,月別入力!$D:$D,$C18,月別入力!$E:$E,R$11),1) -> 0 | S18: =ROUND(SUMIFS(月別入力!$I:$I,月別入力!$D:$D,$C18,月別入力!$E:$E,S$11),1) -> 0 | T18: =ROUND(SUMIFS(月別入力!$I:$I,月別入力!$D:$D,$C18,月別入力!$E:$E,T$11),1) -> 0 | U18: =ROUND(SUMIFS(月別入力!$I:$I,月別入力!$D:$D,$C18,月別入力!$E:$E,U$11),1) -> 0 | V18: =ROUND(SUMIFS(月別入力!$I:$I,月別入力!$D:$D,$C18,月別入力!$E:$E,V$11),1) -> 0 | W18: =ROUND(SUMIFS(月別入力!$I:$I,月別入力!$D:$D,$C18,月別入力!$E:$E,W$11),1) -> 0 | ... AI18: =ROUND(SUMIFS(月別入力!$I:$I,月別入力!$D:$D,$C18,月別入力!$E:$E,AI$11),1) -> 0 | AJ18: =ROUND(SUMIFS(月別入力!$I:$I,月別入力!$D:$D,$C18,月別入力!$H:$H,"[5]雇用",月別入力!$F:$F,"[1]男"),1) -> 0 | AK18: =ROUND(SUMIFS(月別入力!$I:$I,月別入力!$D:$D,$C18,月別入力!$H:$H,"[5]雇用",月別入力!$F:$F,"[2]女"),1) -> 0 | AL18: =C18 | BC18: 基肥 | BD18: =SUM(SUMIFS(P18:AI18,P14:AI14,{"[1]家族","[3]ゆい・手間替え受け"},P12:AI12,"[1]男")) -> 0 | BE18: =SUM(SUMIFS(P18:AI18,P14:AI14,{"[1]家族","[3]ゆい・手間替え受け"},P12:AI12,"[2]女")) -> 0 | BF18: =SUM(BD18:BE18) -> 0 | BG18: =AJ18 -> 0 | BH18: =SUM(SUMIFS(P18:AI18,P14:AI14,{"[2]同居人","[4]手伝い・共同作業受け"},P12:AI12,"[1]男")) -> 0 | BI18: =SUM(BG18:BH18) -> 0 | BJ18: =AK18 -> 0 | BK18: =SUM(SUMIFS(P18:AI18,P14:AI14,{"[2]同居人","[4]手伝い・共同作業受け"},P12:AI12,"[2]女")) -> 0 | BL18: =SUM(BJ18:BK18) -> 0 | BM18: =SUM(BI18,BL18) -> 0
C19: =設定!L8 | P19: =ROUND(SUMIFS(月別入力!$I:$I,月別入力!$D:$D,$C19,月別入力!$E:$E,P$11),1) -> 0 | Q19: =ROUND(SUMIFS(月別入力!$I:$I,月別入力!$D:$D,$C19,月別入力!$E:$E,Q$11),1) -> 0 | R19: =ROUND(SUMIFS(月別入力!$I:$I,月別入力!$D:$D,$C19,月別入力!$E:$E,R$11),1) -> 0 | S19: =ROUND(SUMIFS(月別入力!$I:$I,月別入力!$D:$D,$C19,月別入力!$E:$E,S$11),1) -> 0 | T19: =ROUND(SUMIFS(月別入力!$I:$I,月別入力!$D:$D,$C19,月別入力!$E:$E,T$11),1) -> 0 | U19: =ROUND(SUMIFS(月別入力!$I:$I,月別入力!$D:$D,$C19,月別入力!$E:$E,U$11),1) -> 0 | V19: =ROUND(SUMIFS(月別入力!$I:$I,月別入力!$D:$D,$C19,月別入力!$E:$E,V$11),1) -> 0 | W19: =ROUND(SUMIFS(月別入力!$I:$I,月別入力!$D:$D,$C19,月別入力!$E:$E,W$11),1) -> 0 | ... AI19: =ROUND(SUMIFS(月別入力!$I:$I,月別入力!$D:$D,$C19,月別入力!$E:$E,AI$11),1) -> 0 | AJ19: =ROUND(SUMIFS(月別入力!$I:$I,月別入力!$D:$D,$C19,月別入力!$H:$H,"[5]雇用",月別入力!$F:$F,"[1]男"),1) -> 0 | AK19: =ROUND(SUMIFS(月別入力!$I:$I,月別入力!$D:$D,$C19,月別入力!$H:$H,"[5]雇用",月別入力!$F:$F,"[2]女"),1) -> 0 | AL19: =C19 | BC19: 直まき／は種 | BD19: =SUM(SUMIFS(P19:AI19,P14:AI14,{"[1]家族","[3]ゆい・手間替え受け"},P12:AI12,"[1]男")) -> 0 | BE19: =SUM(SUMIFS(P19:AI19,P14:AI14,{"[1]家族","[3]ゆい・手間替え受け"},P12:AI12,"[2]女")) -> 0 | BF19: =SUM(BD19:BE19) -> 0 | BG19: =AJ19 -> 0 | BH19: =SUM(SUMIFS(P19:AI19,P14:AI14,{"[2]同居人","[4]手伝い・共同作業受け"},P12:AI12,"[1]男")) -> 0 | BI19: =SUM(BG19:BH19) -> 0 | BJ19: =AK19 -> 0 | BK19: =SUM(SUMIFS(P19:AI19,P14:AI14,{"[2]同居人","[4]手伝い・共同作業受け"},P12:AI12,"[2]女")) -> 0 | BL19: =SUM(BJ19:BK19) -> 0 | BM19: =SUM(BI19,BL19) -> 0
C20: =設定!M8 | P20: =ROUND(SUMIFS(月別入力!$I:$I,月別入力!$D:$D,$C20,月別入力!$E:$E,P$11),1) -> 0 | Q20: =ROUND(SUMIFS(月別入力!$I:$I,月別入力!$D:$D,$C20,月別入力!$E:$E,Q$11),1) -> 0 | R20: =ROUND(SUMIFS(月別入力!$I:$I,月別入力!$D:$D,$C20,月別入力!$E:$E,R$11),1) -> 0 | S20: =ROUND(SUMIFS(月別入力!$I:$I,月別入力!$D:$D,$C20,月別入力!$E:$E,S$11),1) -> 0 | T20: =ROUND(SUMIFS(月別入力!$I:$I,月別入力!$D:$D,$C20,月別入力!$E:$E,T$11),1) -> 0 | U20: =ROUND(SUMIFS(月別入力!$I:$I,月別入力!$D:$D,$C20,月別入力!$E:$E,U$11),1) -> 0 | V20: =ROUND(SUMIFS(月別入力!$I:$I,月別入力!$D:$D,$C20,月別入力!$E:$E,V$11),1) -> 0 | W20: =ROUND(SUMIFS(月別入力!$I:$I,月別入力!$D:$D,$C20,月別入力!$E:$E,W$11),1) -> 0 | ... AI20: =ROUND(SUMIFS(月別入力!$I:$I,月別入力!$D:$D,$C20,月別入力!$E:$E,AI$11),1) -> 0 | AJ20: =ROUND(SUMIFS(月別入力!$I:$I,月別入力!$D:$D,$C20,月別入力!$H:$H,"[5]雇用",月別入力!$F:$F,"[1]男"),1) -> 0 | AK20: =ROUND(SUMIFS(月別入力!$I:$I,月別入力!$D:$D,$C20,月別入力!$H:$H,"[5]雇用",月別入力!$F:$F,"[2]女"),1) -> 0 | AL20: =C20 | BC20: 田植／定植 | BD20: =SUM(SUMIFS(P20:AI20,P14:AI14,{"[1]家族","[3]ゆい・手間替え受け"},P12:AI12,"[1]男")) -> 0 | BE20: =SUM(SUMIFS(P20:AI20,P14:AI14,{"[1]家族","[3]ゆい・手間替え受け"},P12:AI12,"[2]女")) -> 0 | BF20: =SUM(BD20:BE20) -> 0 | BG20: =AJ20 -> 0 | BH20: =SUM(SUMIFS(P20:AI20,P14:AI14,{"[2]同居人","[4]手伝い・共同作業受け"},P12:AI12,"[1]男")) -> 0 | BI20: =SUM(BG20:BH20) -> 0 | BJ20: =AK20 -> 0 | BK20: =SUM(SUMIFS(P20:AI20,P14:AI14,{"[2]同居人","[4]手伝い・共同作業受け"},P12:AI12,"[2]女")) -> 0 | BL20: =SUM(BJ20:BK20) -> 0 | BM20: =SUM(BI20,BL20) -> 0
C21: =設定!N8 | P21: =ROUND(SUMIFS(月別入力!$I:$I,月別入力!$D:$D,$C21,月別入力!$E:$E,P$11),1) -> 0 | Q21: =ROUND(SUMIFS(月別入力!$I:$I,月別入力!$D:$D,$C21,月別入力!$E:$E,Q$11),1) -> 0 | R21: =ROUND(SUMIFS(月別入力!$I:$I,月別入力!$D:$D,$C21,月別入力!$E:$E,R$11),1) -> 0 | S21: =ROUND(SUMIFS(月別入力!$I:$I,月別入力!$D:$D,$C21,月別入力!$E:$E,S$11),1) -> 0 | T21: =ROUND(SUMIFS(月別入力!$I:$I,月別入力!$D:$D,$C21,月別入力!$E:$E,T$11),1) -> 0 | U21: =ROUND(SUMIFS(月別入力!$I:$I,月別入力!$D:$D,$C21,月別入力!$E:$E,U$11),1) -> 0 | V21: =ROUND(SUMIFS(月別入力!$I:$I,月別入力!$D:$D,$C21,月別入力!$E:$E,V$11),1) -> 0 | W21: =ROUND(SUMIFS(月別入力!$I:$I,月別入力!$D:$D,$C21,月別入力!$E:$E,W$11),1) -> 0 | ... AI21: =ROUND(SUMIFS(月別入力!$I:$I,月別入力!$D:$D,$C21,月別入力!$E:$E,AI$11),1) -> 0 | AJ21: =ROUND(SUMIFS(月別入力!$I:$I,月別入力!$D:$D,$C21,月別入力!$H:$H,"[5]雇用",月別入力!$F:$F,"[1]男"),1) -> 0 | AK21: =ROUND(SUMIFS(月別入力!$I:$I,月別入力!$D:$D,$C21,月別入力!$H:$H,"[5]雇用",月別入力!$F:$F,"[2]女"),1) -> 0 | AL21: =C21 | BC21: 株分け | BD21: =SUM(SUMIFS(P21:AI21,P14:AI14,{"[1]家族","[3]ゆい・手間替え受け"},P12:AI12,"[1]男")) -> 0 | BE21: =SUM(SUMIFS(P21:AI21,P14:AI14,{"[1]家族","[3]ゆい・手間替え受け"},P12:AI12,"[2]女")) -> 0 | BF21: =SUM(BD21:BE21) -> 0 | BG21: =AJ21 -> 0 | BH21: =SUM(SUMIFS(P21:AI21,P14:AI14,{"[2]同居人","[4]手伝い・共同作業受け"},P12:AI12,"[1]男")) -> 0 | BI21: =SUM(BG21:BH21) -> 0 | BJ21: =AK21 -> 0 | BK21: =SUM(SUMIFS(P21:AI21,P14:AI14,{"[2]同居人","[4]手伝い・共同作業受け"},P12:AI12,"[2]女")) -> 0 | BL21: =SUM(BJ21:BK21) -> 0 | BM21: =SUM(BI21,BL21) -> 0
C22: =設定!O8 | P22: =ROUND(SUMIFS(月別入力!$I:$I,月別入力!$D:$D,$C22,月別入力!$E:$E,P$11),1) -> 0 | Q22: =ROUND(SUMIFS(月別入力!$I:$I,月別入力!$D:$D,$C22,月別入力!$E:$E,Q$11),1) -> 0 | R22: =ROUND(SUMIFS(月別入力!$I:$I,月別入力!$D:$D,$C22,月別入力!$E:$E,R$11),1) -> 0 | S22: =ROUND(SUMIFS(月別入力!$I:$I,月別入力!$D:$D,$C22,月別入力!$E:$E,S$11),1) -> 0 | T22: =ROUND(SUMIFS(月別入力!$I:$I,月別入力!$D:$D,$C22,月別入力!$E:$E,T$11),1) -> 0 | U22: =ROUND(SUMIFS(月別入力!$I:$I,月別入力!$D:$D,$C22,月別入力!$E:$E,U$11),1) -> 0 | V22: =ROUND(SUMIFS(月別入力!$I:$I,月別入力!$D:$D,$C22,月別入力!$E:$E,V$11),1) -> 0 | W22: =ROUND(SUMIFS(月別入力!$I:$I,月別入力!$D:$D,$C22,月別入力!$E:$E,W$11),1) -> 0 | ... AI22: =ROUND(SUMIFS(月別入力!$I:$I,月別入力!$D:$D,$C22,月別入力!$E:$E,AI$11),1) -> 0 | AJ22: =ROUND(SUMIFS(月別入力!$I:$I,月別入力!$D:$D,$C22,月別入力!$H:$H,"[5]雇用",月別入力!$F:$F,"[1]男"),1) -> 0 | AK22: =ROUND(SUMIFS(月別入力!$I:$I,月別入力!$D:$D,$C22,月別入力!$H:$H,"[5]雇用",月別入力!$F:$F,"[2]女"),1) -> 0 | AL22: =C22 | BC22: 追肥 | BD22: =SUM(SUMIFS(P22:AI22,P14:AI14,{"[1]家族","[3]ゆい・手間替え受け"},P12:AI12,"[1]男")) -> 0 | BE22: =SUM(SUMIFS(P22:AI22,P14:AI14,{"[1]家族","[3]ゆい・手間替え受け"},P12:AI12,"[2]女")) -> 0 | BF22: =SUM(BD22:BE22) -> 0 | BG22: =AJ22 -> 0 | BH22: =SUM(SUMIFS(P22:AI22,P14:AI14,{"[2]同居人","[4]手伝い・共同作業受け"},P12:AI12,"[1]男")) -> 0 | BI22: =SUM(BG22:BH22) -> 0 | BJ22: =AK22 -> 0 | BK22: =SUM(SUMIFS(P22:AI22,P14:AI14,{"[2]同居人","[4]手伝い・共同作業受け"},P12:AI12,"[2]女")) -> 0 | BL22: =SUM(BJ22:BK22) -> 0 | BM22: =SUM(BI22,BL22) -> 0
C23: =設定!P8 | P23: =ROUND(SUMIFS(月別入力!$I:$I,月別入力!$D:$D,$C23,月別入力!$E:$E,P$11),1) -> 0 | Q23: =ROUND(SUMIFS(月別入力!$I:$I,月別入力!$D:$D,$C23,月別入力!$E:$E,Q$11),1) -> 0 | R23: =ROUND(SUMIFS(月別入力!$I:$I,月別入力!$D:$D,$C23,月別入力!$E:$E,R$11),1) -> 0 | S23: =ROUND(SUMIFS(月別入力!$I:$I,月別入力!$D:$D,$C23,月別入力!$E:$E,S$11),1) -> 0 | T23: =ROUND(SUMIFS(月別入力!$I:$I,月別入力!$D:$D,$C23,月別入力!$E:$E,T$11),1) -> 0 | U23: =ROUND(SUMIFS(月別入力!$I:$I,月別入力!$D:$D,$C23,月別入力!$E:$E,U$11),1) -> 0 | V23: =ROUND(SUMIFS(月別入力!$I:$I,月別入力!$D:$D,$C23,月別入力!$E:$E,V$11),1) -> 0 | W23: =ROUND(SUMIFS(月別入力!$I:$I,月別入力!$D:$D,$C23,月別入力!$E:$E,W$11),1) -> 0 | ... AI23: =ROUND(SUMIFS(月別入力!$I:$I,月別入力!$D:$D,$C23,月別入力!$E:$E,AI$11),1) -> 0 | AJ23: =ROUND(SUMIFS(月別入力!$I:$I,月別入力!$D:$D,$C23,月別入力!$H:$H,"[5]雇用",月別入力!$F:$F,"[1]男"),1) -> 0 | AK23: =ROUND(SUMIFS(月別入力!$I:$I,月別入力!$D:$D,$C23,月別入力!$H:$H,"[5]雇用",月別入力!$F:$F,"[2]女"),1) -> 0 | AL23: =C23 | BC23: 除草／中耕除草 | BD23: =SUM(SUMIFS(P23:AI23,P14:AI14,{"[1]家族","[3]ゆい・手間替え受け"},P12:AI12,"[1]男")) -> 0 | BE23: =SUM(SUMIFS(P23:AI23,P14:AI14,{"[1]家族","[3]ゆい・手間替え受け"},P12:AI12,"[2]女")) -> 0 | BF23: =SUM(BD23:BE23) -> 0 | BG23: =AJ23 -> 0 | BH23: =SUM(SUMIFS(P23:AI23,P14:AI14,{"[2]同居人","[4]手伝い・共同作業受け"},P12:AI12,"[1]男")) -> 0 | BI23: =SUM(BG23:BH23) -> 0 | BJ23: =AK23 -> 0 | BK23: =SUM(SUMIFS(P23:AI23,P14:AI14,{"[2]同居人","[4]手伝い・共同作業受け"},P12:AI12,"[2]女")) -> 0 | BL23: =SUM(BJ23:BK23) -> 0 | BM23: =SUM(BI23,BL23) -> 0
C24: =設定!Q8 | P24: =ROUND(SUMIFS(月別入力!$I:$I,月別入力!$D:$D,$C24,月別入力!$E:$E,P$11),1) -> 0 | Q24: =ROUND(SUMIFS(月別入力!$I:$I,月別入力!$D:$D,$C24,月別入力!$E:$E,Q$11),1) -> 0 | R24: =ROUND(SUMIFS(月別入力!$I:$I,月別入力!$D:$D,$C24,月別入力!$E:$E,R$11),1) -> 0 | S24: =ROUND(SUMIFS(月別入力!$I:$I,月別入力!$D:$D,$C24,月別入力!$E:$E,S$11),1) -> 0 | T24: =ROUND(SUMIFS(月別入力!$I:$I,月別入力!$D:$D,$C24,月別入力!$E:$E,T$11),1) -> 0 | U24: =ROUND(SUMIFS(月別入力!$I:$I,月別入力!$D:$D,$C24,月別入力!$E:$E,U$11),1) -> 0 | V24: =ROUND(SUMIFS(月別入力!$I:$I,月別入力!$D:$D,$C24,月別入力!$E:$E,V$11),1) -> 0 | W24: =ROUND(SUMIFS(月別入力!$I:$I,月別入力!$D:$D,$C24,月別入力!$E:$E,W$11),1) -> 0 | ... AI24: =ROUND(SUMIFS(月別入力!$I:$I,月別入力!$D:$D,$C24,月別入力!$E:$E,AI$11),1) -> 0 | AJ24: =ROUND(SUMIFS(月別入力!$I:$I,月別入力!$D:$D,$C24,月別入力!$H:$H,"[5]雇用",月別入力!$F:$F,"[1]男"),1) -> 0 | AK24: =ROUND(SUMIFS(月別入力!$I:$I,月別入力!$D:$D,$C24,月別入力!$H:$H,"[5]雇用",月別入力!$F:$F,"[2]女"),1) -> 0 | AL24: =C24 | BC24: 麦踏み | BD24: =SUM(SUMIFS(P24:AI24,P14:AI14,{"[1]家族","[3]ゆい・手間替え受け"},P12:AI12,"[1]男")) -> 0 | BE24: =SUM(SUMIFS(P24:AI24,P14:AI14,{"[1]家族","[3]ゆい・手間替え受け"},P12:AI12,"[2]女")) -> 0 | BF24: =SUM(BD24:BE24) -> 0 | BG24: =AJ24 -> 0 | BH24: =SUM(SUMIFS(P24:AI24,P14:AI14,{"[2]同居人","[4]手伝い・共同作業受け"},P12:AI12,"[1]男")) -> 0 | BI24: =SUM(BG24:BH24) -> 0 | BJ24: =AK24 -> 0 | BK24: =SUM(SUMIFS(P24:AI24,P14:AI14,{"[2]同居人","[4]手伝い・共同作業受け"},P12:AI12,"[2]女")) -> 0 | BL24: =SUM(BJ24:BK24) -> 0 | BM24: =SUM(BI24,BL24) -> 0
C25: =設定!R8 | P25: =ROUND(SUMIFS(月別入力!$I:$I,月別入力!$D:$D,$C25,月別入力!$E:$E,P$11),1) -> 0 | Q25: =ROUND(SUMIFS(月別入力!$I:$I,月別入力!$D:$D,$C25,月別入力!$E:$E,Q$11),1) -> 0 | R25: =ROUND(SUMIFS(月別入力!$I:$I,月別入力!$D:$D,$C25,月別入力!$E:$E,R$11),1) -> 0 | S25: =ROUND(SUMIFS(月別入力!$I:$I,月別入力!$D:$D,$C25,月別入力!$E:$E,S$11),1) -> 0 | T25: =ROUND(SUMIFS(月別入力!$I:$I,月別入力!$D:$D,$C25,月別入力!$E:$E,T$11),1) -> 0 | U25: =ROUND(SUMIFS(月別入力!$I:$I,月別入力!$D:$D,$C25,月別入力!$E:$E,U$11),1) -> 0 | V25: =ROUND(SUMIFS(月別入力!$I:$I,月別入力!$D:$D,$C25,月別入力!$E:$E,V$11),1) -> 0 | W25: =ROUND(SUMIFS(月別入力!$I:$I,月別入力!$D:$D,$C25,月別入力!$E:$E,W$11),1) -> 0 | ... AI25: =ROUND(SUMIFS(月別入力!$I:$I,月別入力!$D:$D,$C25,月別入力!$E:$E,AI$11),1) -> 0 | AJ25: =ROUND(SUMIFS(月別入力!$I:$I,月別入力!$D:$D,$C25,月別入力!$H:$H,"[5]雇用",月別入力!$F:$F,"[1]男"),1) -> 0 | AK25: =ROUND(SUMIFS(月別入力!$I:$I,月別入力!$D:$D,$C25,月別入力!$H:$H,"[5]雇用",月別入力!$F:$F,"[2]女"),1) -> 0 | AL25: =C25 | BC25: 管理 | BD25: =SUM(SUMIFS(P25:AI25,P14:AI14,{"[1]家族","[3]ゆい・手間替え受け"},P12:AI12,"[1]男")) -> 0 | BE25: =SUM(SUMIFS(P25:AI25,P14:AI14,{"[1]家族","[3]ゆい・手間替え受け"},P12:AI12,"[2]女")) -> 0 | BF25: =SUM(BD25:BE25) -> 0 | BG25: =AJ25 -> 0 | BH25: =SUM(SUMIFS(P25:AI25,P14:AI14,{"[2]同居人","[4]手伝い・共同作業受け"},P12:AI12,"[1]男")) -> 0 | BI25: =SUM(BG25:BH25) -> 0 | BJ25: =AK25 -> 0 | BK25: =SUM(SUMIFS(P25:AI25,P14:AI14,{"[2]同居人","[4]手伝い・共同作業受け"},P12:AI12,"[2]女")) -> 0 | BL25: =SUM(BJ25:BK25) -> 0 | BM25: =SUM(BI25,BL25) -> 0
C26: =設定!S8 | P26: =ROUND(SUMIFS(月別入力!$I:$I,月別入力!$D:$D,$C26,月別入力!$E:$E,P$11),1) -> 0 | Q26: =ROUND(SUMIFS(月別入力!$I:$I,月別入力!$D:$D,$C26,月別入力!$E:$E,Q$11),1) -> 0 | R26: =ROUND(SUMIFS(月別入力!$I:$I,月別入力!$D:$D,$C26,月別入力!$E:$E,R$11),1) -> 0 | S26: =ROUND(SUMIFS(月別入力!$I:$I,月別入力!$D:$D,$C26,月別入力!$E:$E,S$11),1) -> 0 | T26: =ROUND(SUMIFS(月別入力!$I:$I,月別入力!$D:$D,$C26,月別入力!$E:$E,T$11),1) -> 0 | U26: =ROUND(SUMIFS(月別入力!$I:$I,月別入力!$D:$D,$C26,月別入力!$E:$E,U$11),1) -> 0 | V26: =ROUND(SUMIFS(月別入力!$I:$I,月別入力!$D:$D,$C26,月別入力!$E:$E,V$11),1) -> 0 | W26: =ROUND(SUMIFS(月別入力!$I:$I,月別入力!$D:$D,$C26,月別入力!$E:$E,W$11),1) -> 0 | ... AI26: =ROUND(SUMIFS(月別入力!$I:$I,月別入力!$D:$D,$C26,月別入力!$E:$E,AI$11),1) -> 0 | AJ26: =ROUND(SUMIFS(月別入力!$I:$I,月別入力!$D:$D,$C26,月別入力!$H:$H,"[5]雇用",月別入力!$F:$F,"[1]男"),1) -> 0 | AK26: =ROUND(SUMIFS(月別入力!$I:$I,月別入力!$D:$D,$C26,月別入力!$H:$H,"[5]雇用",月別入力!$F:$F,"[2]女"),1) -> 0 | AL26: =C26 | BC26: 防除 | BD26: =SUM(SUMIFS(P26:AI26,P14:AI14,{"[1]家族","[3]ゆい・手間替え受け"},P12:AI12,"[1]男")) -> 0 | BE26: =SUM(SUMIFS(P26:AI26,P14:AI14,{"[1]家族","[3]ゆい・手間替え受け"},P12:AI12,"[2]女")) -> 0 | BF26: =SUM(BD26:BE26) -> 0 | BG26: =AJ26 -> 0 | BH26: =SUM(SUMIFS(P26:AI26,P14:AI14,{"[2]同居人","[4]手伝い・共同作業受け"},P12:AI12,"[1]男")) -> 0 | BI26: =SUM(BG26:BH26) -> 0 | BJ26: =AK26 -> 0 | BK26: =SUM(SUMIFS(P26:AI26,P14:AI14,{"[2]同居人","[4]手伝い・共同作業受け"},P12:AI12,"[2]女")) -> 0 | BL26: =SUM(BJ26:BK26) -> 0 | BM26: =SUM(BI26,BL26) -> 0
C27: =設定!T8 | P27: =ROUND(SUMIFS(月別入力!$I:$I,月別入力!$D:$D,$C27,月別入力!$E:$E,P$11),1) -> 0 | Q27: =ROUND(SUMIFS(月別入力!$I:$I,月別入力!$D:$D,$C27,月別入力!$E:$E,Q$11),1) -> 0 | R27: =ROUND(SUMIFS(月別入力!$I:$I,月別入力!$D:$D,$C27,月別入力!$E:$E,R$11),1) -> 0 | S27: =ROUND(SUMIFS(月別入力!$I:$I,月別入力!$D:$D,$C27,月別入力!$E:$E,S$11),1) -> 0 | T27: =ROUND(SUMIFS(月別入力!$I:$I,月別入力!$D:$D,$C27,月別入力!$E:$E,T$11),1) -> 0 | U27: =ROUND(SUMIFS(月別入力!$I:$I,月別入力!$D:$D,$C27,月別入力!$E:$E,U$11),1) -> 0 | V27: =ROUND(SUMIFS(月別入力!$I:$I,月別入力!$D:$D,$C27,月別入力!$E:$E,V$11),1) -> 0 | W27: =ROUND(SUMIFS(月別入力!$I:$I,月別入力!$D:$D,$C27,月別入力!$E:$E,W$11),1) -> 0 | ... AI27: =ROUND(SUMIFS(月別入力!$I:$I,月別入力!$D:$D,$C27,月別入力!$E:$E,AI$11),1) -> 0 | AJ27: =ROUND(SUMIFS(月別入力!$I:$I,月別入力!$D:$D,$C27,月別入力!$H:$H,"[5]雇用",月別入力!$F:$F,"[1]男"),1) -> 0 | AK27: =ROUND(SUMIFS(月別入力!$I:$I,月別入力!$D:$D,$C27,月別入力!$H:$H,"[5]雇用",月別入力!$F:$F,"[2]女"),1) -> 0 | AL27: =C27 | BC27: はく葉 | BD27: =SUM(SUMIFS(P27:AI27,P14:AI14,{"[1]家族","[3]ゆい・手間替え受け"},P12:AI12,"[1]男")) -> 0 | BE27: =SUM(SUMIFS(P27:AI27,P14:AI14,{"[1]家族","[3]ゆい・手間替え受け"},P12:AI12,"[2]女")) -> 0 | BF27: =SUM(BD27:BE27) -> 0 | BG27: =AJ27 -> 0 | BH27: =SUM(SUMIFS(P27:AI27,P14:AI14,{"[2]同居人","[4]手伝い・共同作業受け"},P12:AI12,"[1]男")) -> 0 | BI27: =SUM(BG27:BH27) -> 0 | BJ27: =AK27 -> 0 | BK27: =SUM(SUMIFS(P27:AI27,P14:AI14,{"[2]同居人","[4]手伝い・共同作業受け"},P12:AI12,"[2]女")) -> 0 | BL27: =SUM(BJ27:BK27) -> 0 | BM27: =SUM(BI27,BL27) -> 0
C28: =設定!U8 | P28: =ROUND(SUMIFS(月別入力!$I:$I,月別入力!$D:$D,$C28,月別入力!$E:$E,P$11),1) -> 0 | Q28: =ROUND(SUMIFS(月別入力!$I:$I,月別入力!$D:$D,$C28,月別入力!$E:$E,Q$11),1) -> 0 | R28: =ROUND(SUMIFS(月別入力!$I:$I,月別入力!$D:$D,$C28,月別入力!$E:$E,R$11),1) -> 0 | S28: =ROUND(SUMIFS(月別入力!$I:$I,月別入力!$D:$D,$C28,月別入力!$E:$E,S$11),1) -> 0 | T28: =ROUND(SUMIFS(月別入力!$I:$I,月別入力!$D:$D,$C28,月別入力!$E:$E,T$11),1) -> 0 | U28: =ROUND(SUMIFS(月別入力!$I:$I,月別入力!$D:$D,$C28,月別入力!$E:$E,U$11),1) -> 0 | V28: =ROUND(SUMIFS(月別入力!$I:$I,月別入力!$D:$D,$C28,月別入力!$E:$E,V$11),1) -> 0 | W28: =ROUND(SUMIFS(月別入力!$I:$I,月別入力!$D:$D,$C28,月別入力!$E:$E,W$11),1) -> 0 | ... AI28: =ROUND(SUMIFS(月別入力!$I:$I,月別入力!$D:$D,$C28,月別入力!$E:$E,AI$11),1) -> 0 | AJ28: =ROUND(SUMIFS(月別入力!$I:$I,月別入力!$D:$D,$C28,月別入力!$H:$H,"[5]雇用",月別入力!$F:$F,"[1]男"),1) -> 0 | AK28: =ROUND(SUMIFS(月別入力!$I:$I,月別入力!$D:$D,$C28,月別入力!$H:$H,"[5]雇用",月別入力!$F:$F,"[2]女"),1) -> 0 | AL28: =C28 | BC28: 刈取脱穀 | BD28: =SUM(SUMIFS(P28:AI28,P14:AI14,{"[1]家族","[3]ゆい・手間替え受け"},P12:AI12,"[1]男")) -> 0 | BE28: =SUM(SUMIFS(P28:AI28,P14:AI14,{"[1]家族","[3]ゆい・手間替え受け"},P12:AI12,"[2]女")) -> 0 | BF28: =SUM(BD28:BE28) -> 0 | BG28: =AJ28 -> 0 | BH28: =SUM(SUMIFS(P28:AI28,P14:AI14,{"[2]同居人","[4]手伝い・共同作業受け"},P12:AI12,"[1]男")) -> 0 | BI28: =SUM(BG28:BH28) -> 0 | BJ28: =AK28 -> 0 | BK28: =SUM(SUMIFS(P28:AI28,P14:AI14,{"[2]同居人","[4]手伝い・共同作業受け"},P12:AI12,"[2]女")) -> 0 | BL28: =SUM(BJ28:BK28) -> 0 | BM28: =SUM(BI28,BL28) -> 0
C29: =設定!V8 | P29: =ROUND(SUMIFS(月別入力!$I:$I,月別入力!$D:$D,$C29,月別入力!$E:$E,P$11),1) -> 0 | Q29: =ROUND(SUMIFS(月別入力!$I:$I,月別入力!$D:$D,$C29,月別入力!$E:$E,Q$11),1) -> 0 | R29: =ROUND(SUMIFS(月別入力!$I:$I,月別入力!$D:$D,$C29,月別入力!$E:$E,R$11),1) -> 0 | S29: =ROUND(SUMIFS(月別入力!$I:$I,月別入力!$D:$D,$C29,月別入力!$E:$E,S$11),1) -> 0 | T29: =ROUND(SUMIFS(月別入力!$I:$I,月別入力!$D:$D,$C29,月別入力!$E:$E,T$11),1) -> 0 | U29: =ROUND(SUMIFS(月別入力!$I:$I,月別入力!$D:$D,$C29,月別入力!$E:$E,U$11),1) -> 0 | V29: =ROUND(SUMIFS(月別入力!$I:$I,月別入力!$D:$D,$C29,月別入力!$E:$E,V$11),1) -> 0 | W29: =ROUND(SUMIFS(月別入力!$I:$I,月別入力!$D:$D,$C29,月別入力!$E:$E,W$11),1) -> 0 | ... AI29: =ROUND(SUMIFS(月別入力!$I:$I,月別入力!$D:$D,$C29,月別入力!$E:$E,AI$11),1) -> 0 | AJ29: =ROUND(SUMIFS(月別入力!$I:$I,月別入力!$D:$D,$C29,月別入力!$H:$H,"[5]雇用",月別入力!$F:$F,"[1]男"),1) -> 0 | AK29: =ROUND(SUMIFS(月別入力!$I:$I,月別入力!$D:$D,$C29,月別入力!$H:$H,"[5]雇用",月別入力!$F:$F,"[2]女"),1) -> 0 | AL29: =C29 | BC29: 乾燥 | BD29: =SUM(SUMIFS(P29:AI29,P14:AI14,{"[1]家族","[3]ゆい・手間替え受け"},P12:AI12,"[1]男")) -> 0 | BE29: =SUM(SUMIFS(P29:AI29,P14:AI14,{"[1]家族","[3]ゆい・手間替え受け"},P12:AI12,"[2]女")) -> 0 | BF29: =SUM(BD29:BE29) -> 0 | BG29: =AJ29 -> 0 | BH29: =SUM(SUMIFS(P29:AI29,P14:AI14,{"[2]同居人","[4]手伝い・共同作業受け"},P12:AI12,"[1]男")) -> 0 | BI29: =SUM(BG29:BH29) -> 0 | BJ29: =AK29 -> 0 | BK29: =SUM(SUMIFS(P29:AI29,P14:AI14,{"[2]同居人","[4]手伝い・共同作業受け"},P12:AI12,"[2]女")) -> 0 | BL29: =SUM(BJ29:BK29) -> 0 | BM29: =SUM(BI29,BL29) -> 0
C30: =設定!W8 | P30: =ROUND(SUMIFS(月別入力!$I:$I,月別入力!$D:$D,$C30,月別入力!$E:$E,P$11),1) -> 0 | Q30: =ROUND(SUMIFS(月別入力!$I:$I,月別入力!$D:$D,$C30,月別入力!$E:$E,Q$11),1) -> 0 | R30: =ROUND(SUMIFS(月別入力!$I:$I,月別入力!$D:$D,$C30,月別入力!$E:$E,R$11),1) -> 0 | S30: =ROUND(SUMIFS(月別入力!$I:$I,月別入力!$D:$D,$C30,月別入力!$E:$E,S$11),1) -> 0 | T30: =ROUND(SUMIFS(月別入力!$I:$I,月別入力!$D:$D,$C30,月別入力!$E:$E,T$11),1) -> 0 | U30: =ROUND(SUMIFS(月別入力!$I:$I,月別入力!$D:$D,$C30,月別入力!$E:$E,U$11),1) -> 0 | V30: =ROUND(SUMIFS(月別入力!$I:$I,月別入力!$D:$D,$C30,月別入力!$E:$E,V$11),1) -> 0 | W30: =ROUND(SUMIFS(月別入力!$I:$I,月別入力!$D:$D,$C30,月別入力!$E:$E,W$11),1) -> 0 | ... AI30: =ROUND(SUMIFS(月別入力!$I:$I,月別入力!$D:$D,$C30,月別入力!$E:$E,AI$11),1) -> 0 | AL30: =C30 | BC30: 生産管理 | BD30: =SUM(SUMIFS(P30:AI30,P14:AI14,{"[1]家族"},P12:AI12,"[1]男")) -> 0 | BE30: =SUM(SUMIFS(P30:AI30,P14:AI14,{"[1]家族"},P12:AI12,"[2]女")) -> 0 | BF30: =SUM(BD30:BE30) -> 0 | BO30: 労賃単価を入力してください。
C31: =設定!X8 | P31: =ROUND(SUMIFS(月別入力!$I:$I,月別入力!$D:$D,$C31,月別入力!$E:$E,P$11),1) -> 0 | Q31: =ROUND(SUMIFS(月別入力!$I:$I,月別入力!$D:$D,$C31,月別入力!$E:$E,Q$11),1) -> 0 | R31: =ROUND(SUMIFS(月別入力!$I:$I,月別入力!$D:$D,$C31,月別入力!$E:$E,R$11),1) -> 0 | S31: =ROUND(SUMIFS(月別入力!$I:$I,月別入力!$D:$D,$C31,月別入力!$E:$E,S$11),1) -> 0 | T31: =ROUND(SUMIFS(月別入力!$I:$I,月別入力!$D:$D,$C31,月別入力!$E:$E,T$11),1) -> 0 | U31: =ROUND(SUMIFS(月別入力!$I:$I,月別入力!$D:$D,$C31,月別入力!$E:$E,U$11),1) -> 0 | V31: =ROUND(SUMIFS(月別入力!$I:$I,月別入力!$D:$D,$C31,月別入力!$E:$E,V$11),1) -> 0 | W31: =ROUND(SUMIFS(月別入力!$I:$I,月別入力!$D:$D,$C31,月別入力!$E:$E,W$11),1) -> 0 | ... AI31: =ROUND(SUMIFS(月別入力!$I:$I,月別入力!$D:$D,$C31,月別入力!$E:$E,AI$11),1) -> 0 | AJ31: =ROUND(SUMIFS(月別入力!$I:$I,月別入力!$D:$D,$C31,月別入力!$H:$H,"[5]雇用",月別入力!$F:$F,"[1]男"),1) -> 0 | AK31: =ROUND(SUMIFS(月別入力!$I:$I,月別入力!$D:$D,$C31,月別入力!$H:$H,"[5]雇用",月別入力!$F:$F,"[2]女"),1) -> 0 | AL31: =C31 | BB31: 間接労働時間 | BD31: =SUM(SUMIFS(P31:AI31,P14:AI14,{"[1]家族","[3]ゆい・手間替え受け"},P12:AI12,"[1]男")) -> 0 | BE31: =SUM(SUMIFS(P31:AI31,P14:AI14,{"[1]家族","[3]ゆい・手間替え受け"},P12:AI12,"[2]女")) -> 0 | BF31: =SUM(BD31:BE31) -> 0 | BG31: =AJ31 -> 0 | BH31: =SUM(SUMIFS(P31:AI31,P14:AI14,{"[2]同居人","[4]手伝い・共同作業受け"},P12:AI12,"[1]男")) -> 0 | BI31: =SUM(BG31:BH31) -> 0 | BJ31: =AK31 -> 0 | BK31: =SUM(SUMIFS(P31:AI31,P14:AI14,{"[2]同居人","[4]手伝い・共同作業受け"},P12:AI12,"[2]女")) -> 0 | BL31: =SUM(BJ31:BK31) -> 0 | BM31: =SUM(BI31,BL31) -> 0 | BO31: 労賃単価（円）
C32: 注：「もみすり・調製作業」と「包装荷造り作業」が機械化一貫作業の場合、包装荷造りに要した作業時間を除いて記入してください。 | BB32: 労働時間合計 | BD32: =SUM(BD14,BD31) -> 0 | BE32: =SUM(BE14,BE31) -> 0 | BF32: =SUM(BD32:BE32) -> 0 | BG32: =SUM(BG14,BG31) -> 0 | BH32: =SUM(BH14,BH31) -> 0 | BI32: =SUM(BG32:BH32) -> 0 | BJ32: =SUM(BJ14,BJ31) -> 0 | BK32: =SUM(BK14,BK31) -> 0 | BL32: =SUM(BJ32:BK32) -> 0 | BM32: =SUM(BI32,BL32) -> 0
A33: ３ 支払賃金
C34: 当年産の対象品目生産のために雇用者に支払った労賃（現物支給も含む。）を記入してください。 | BB34: 年齢階層別労働時間・労働評価額
C35: 区分 | P35: 支払賃金（円） | Q35: 対象品目 負担割合（％） | BR35: 単位：時間、円
BD36: 家族
C37: 男 | BD37: 男 | BI37: 女 | BN37: 小 計
C38: 女 | BD38: ６５歳未満 | BE38: ６５～７０ | BF38: ７０～７５ | BG38: ７５歳以上 | BH38: 計 | BI38: ６５歳未満 | BJ38: ６５～７０ | BK38: ７０～７５ | BL38: ７５歳以上 | BM38: 計 | BN38: ６５歳未満 | BO38: ６５～７０ | BP38: ７０～７５ | BQ38: ７５歳以上 | BR38: 計
BB39: 労働時間 | BC39: 直接労働 | BD39: =SUMIFS(P15:AI15,P14:AI14,"[1]家族",P12:AI12,"[1]男",P13:AI13,"<65") + SUMIFS(P16:AI16,P14:AI14,"[1]家族",P12:AI12,"[1]男",P13:AI13,"<65") + SUMIFS(P17:AI17,P14:AI14,"[1]家族",P12:AI12,"[1]男",P13:AI13,"<65") + SUMIFS(P18:AI18,P14:AI14,"[1]家族",P12:AI12,"[1]男",P13:AI13,"<65") + SUMIFS(P19:AI19,P14:AI14,"[1]家族",P12:AI12,"[1]男",P13:AI13,"<65") + SUMIFS(P20:AI20,P14:AI14,"[1]家族",P12:AI12,"[1]男",P13:AI13,"<65") + SUMIFS(P21:AI21,P14:AI14,"[1]家族",P12:AI12,"[1]男",P13:AI13,"<65") + SUMIFS(P22:AI22,P14:AI14,"[1]家族",P12:AI12,"[1]男",P13:AI13,"<65") + SUMIFS(P23:AI23,P14:AI14,"[1]家族",P12:AI12,"[1]男",P13:AI13,"<65") + SUMIFS(P24:AI24,P14:AI14,"[1]家族",P12:AI12,"[1]男",P13:AI13,"<65") + SUMIFS(P25:AI25,P14:AI14,"[1]家族",P12:AI12,"[1]男",P13:AI13,"<65") + SUMIFS(P26:AI26,P14:AI14,"[1]家族",P12:AI12,"[1]男",P13:AI13,"<65") + SUMIFS(P27:AI27,P14:AI14,"[1]家族",P12:AI12,"[1]男",P13:AI13,"<65") + SUMIFS(P28:AI28,P14:AI14,"[1]家族",P12:AI12,"[1]男",P13:AI13,"<65") + SUMIFS(P29:AI29,P14:AI14,"[1]家族",P12:AI12,"[1]男",P13:AI13,"<65") + SUMIFS(P30:AI30,P14:AI14,"[1]家族",P12:AI12,"[1]男",P13:AI13,"<65") + SUMIFS(P15:AI15,P14:AI14,"[3]ゆい・手間替え受け",P12:AI12,"[1]男") + SUMIFS(P16:AI16,P14:AI14,"[3]ゆい・手間替え受け",P12:AI12,"[1]男") + SUMIFS(P17:AI17,P14:AI14,"[3]ゆい・手間替え受け",P12:AI12,"[1]男") + SUMIFS(P18:AI18,P14:AI14,"[3]ゆい・手間替え受け",P12:AI12,"[1]男") + SUMIFS(P19:AI19,P14:AI14,"[3]ゆい・手間替え受け",P12:AI12,"[1]男") + SUMIFS(P20:AI20,P14:AI14,"[3]ゆい・手間替え受け",P12:AI12,"[1]男") + SUMIFS(P21:AI21,P14:AI14,"[3]ゆい・手間替え受け",P12:AI12,"[1]男") + SUMIFS(P22:AI22,P14:AI14,"[3]ゆい・手間替え受け",P12:AI12,"[1]男") + SUMIFS(P23:AI23,P14:AI14,"[3]ゆい・手間替え受け",P12:AI12,"[1]男") + SUMIFS(P24:AI24,P14:AI14,"[3]ゆい・手間替え受け",P12:AI12,"[1]男") + SUMIFS(P25:AI25,P14:AI14,"[3]ゆい・手間替え受け",P12:AI12,"[1]男") + SUMIFS(P26:AI26,P14:AI14,"[3]ゆい・手間替え受け",P12:AI12,"[1]男") + SUMIFS(P27:AI27,P14:AI14,"[3]ゆい・手間替え受け",P12:AI12,"[1]男") + SUMIFS(P28:AI28,P14:AI14,"[3]ゆい・手間替え受け",P12:AI12,"[1]男") + SUMIFS(P29:AI29,P14:AI14,"[3]ゆい・手間替え受け",P12:AI12,"[1]男") -> 0 | BE39: =SUMIFS(P15:AI15,P14:AI14,"[1]家族",P12:AI12,"[1]男",P13:AI13,">=65",P13:AI13,"<70") + SUMIFS(P16:AI16,P14:AI14,"[1]家族",P12:AI12,"[1]男",P13:AI13,">=65",P13:AI13,"<70") + SUMIFS(P17:AI17,P14:AI14,"[1]家族",P12:AI12,"[1]男",P13:AI13,">=65",P13:AI13,"<70") + SUMIFS(P18:AI18,P14:AI14,"[1]家族",P12:AI12,"[1]男",P13:AI13,">=65",P13:AI13,"<70") + SUMIFS(P19:AI19,P14:AI14,"[1]家族",P12:AI12,"[1]男",P13:AI13,">=65",P13:AI13,"<70") + SUMIFS(P20:AI20,P14:AI14,"[1]家族",P12:AI12,"[1]男",P13:AI13,">=65",P13:AI13,"<70") + SUMIFS(P21:AI21,P14:AI14,"[1]家族",P12:AI12,"[1]男",P13:AI13,">=65",P13:AI13,"<70") + SUMIFS(P22:AI22,P14:AI14,"[1]家族",P12:AI12,"[1]男",P13:AI13,">=65",P13:AI13,"<70") + SUMIFS(P23:AI23,P14:AI14,"[1]家族",P12:AI12,"[1]男",P13:AI13,">=65",P13:AI13,"<70") + SUMIFS(P24:AI24,P14:AI14,"[1]家族",P12:AI12,"[1]男",P13:AI13,">=65",P13:AI13,"<70") + SUMIFS(P25:AI25,P14:AI14,"[1]家族",P12:AI12,"[1]男",P13:AI13,">=65",P13:AI13,"<70") + SUMIFS(P26:AI26,P14:AI14,"[1]家族",P12:AI12,"[1]男",P13:AI13,">=65",P13:AI13,"<70") + SUMIFS(P27:AI27,P14:AI14,"[1]家族",P12:AI12,"[1]男",P13:AI13,">=65",P13:AI13,"<70") + SUMIFS(P28:AI28,P14:AI14,"[1]家族",P12:AI12,"[1]男",P13:AI13,">=65",P13:AI13,"<70") + SUMIFS(P29:AI29,P14:AI14,"[1]家族",P12:AI12,"[1]男",P13:AI13,">=65",P13:AI13,"<70") + SUMIFS(P30:AI30,P14:AI14,"[1]家族",P12:AI12,"[1]男",P13:AI13,">=65",P13:AI13,"<70") -> 0 | BF39: =SUMIFS(P15:AI15,P14:AI14,"[1]家族",P12:AI12,"[1]男",P13:AI13,">=70",P13:AI13,"<75") + SUMIFS(P16:AI16,P14:AI14,"[1]家族",P12:AI12,"[1]男",P13:AI13,">=70",P13:AI13,"<75") + SUMIFS(P17:AI17,P14:AI14,"[1]家族",P12:AI12,"[1]男",P13:AI13,">=70",P13:AI13,"<75") + SUMIFS(P18:AI18,P14:AI14,"[1]家族",P12:AI12,"[1]男",P13:AI13,">=70",P13:AI13,"<75") + SUMIFS(P19:AI19,P14:AI14,"[1]家族",P12:AI12,"[1]男",P13:AI13,">=70",P13:AI13,"<75") + SUMIFS(P20:AI20,P14:AI14,"[1]家族",P12:AI12,"[1]男",P13:AI13,">=70",P13:AI13,"<75") + SUMIFS(P21:AI21,P14:AI14,"[1]家族",P12:AI12,"[1]男",P13:AI13,">=70",P13:AI13,"<75") + SUMIFS(P22:AI22,P14:AI14,"[1]家族",P12:AI12,"[1]男",P13:AI13,">=70",P13:AI13,"<75") + SUMIFS(P23:AI23,P14:AI14,"[1]家族",P12:AI12,"[1]男",P13:AI13,">=70",P13:AI13,"<75") + SUMIFS(P24:AI24,P14:AI14,"[1]家族",P12:AI12,"[1]男",P13:AI13,">=70",P13:AI13,"<75") + SUMIFS(P25:AI25,P14:AI14,"[1]家族",P12:AI12,"[1]男",P13:AI13,">=70",P13:AI13,"<75") + SUMIFS(P26:AI26,P14:AI14,"[1]家族",P12:AI12,"[1]男",P13:AI13,">=70",P13:AI13,"<75") + SUMIFS(P27:AI27,P14:AI14,"[1]家族",P12:AI12,"[1]男",P13:AI13,">=70",P13:AI13,"<75") + SUMIFS(P28:AI28,P14:AI14,"[1]家族",P12:AI12,"[1]男",P13:AI13,">=70",P13:AI13,"<75") + SUMIFS(P29:AI29,P14:AI14,"[1]家族",P12:AI12,"[1]男",P13:AI13,">=70",P13:AI13,"<75") + SUMIFS(P30:AI30,P14:AI14,"[1]家族",P12:AI12,"[1]男",P13:AI13,">=70",P13:AI13,"<75") -> 0 | BG39: =SUMIFS(P15:AI15,P14:AI14,"[1]家族",P12:AI12,"[1]男",P13:AI13,">=75") + SUMIFS(P16:AI16,P14:AI14,"[1]家族",P12:AI12,"[1]男",P13:AI13,">=75") + SUMIFS(P17:AI17,P14:AI14,"[1]家族",P12:AI12,"[1]男",P13:AI13,">=75") + SUMIFS(P18:AI18,P14:AI14,"[1]家族",P12:AI12,"[1]男",P13:AI13,">=75") + SUMIFS(P19:AI19,P14:AI14,"[1]家族",P12:AI12,"[1]男",P13:AI13,">=75") + SUMIFS(P20:AI20,P14:AI14,"[1]家族",P12:AI12,"[1]男",P13:AI13,">=75") + SUMIFS(P21:AI21,P14:AI14,"[1]家族",P12:AI12,"[1]男",P13:AI13,">=75") + SUMIFS(P22:AI22,P14:AI14,"[1]家族",P12:AI12,"[1]男",P13:AI13,">=75") + SUMIFS(P23:AI23,P14:AI14,"[1]家族",P12:AI12,"[1]男",P13:AI13,">=75") + SUMIFS(P24:AI24,P14:AI14,"[1]家族",P12:AI12,"[1]男",P13:AI13,">=75") + SUMIFS(P25:AI25,P14:AI14,"[1]家族",P12:AI12,"[1]男",P13:AI13,">=75") + SUMIFS(P26:AI26,P14:AI14,"[1]家族",P12:AI12,"[1]男",P13:AI13,">=75") + SUMIFS(P27:AI27,P14:AI14,"[1]家族",P12:AI12,"[1]男",P13:AI13,">=75") + SUMIFS(P28:AI28,P14:AI14,"[1]家族",P12:AI12,"[1]男",P13:AI13,">=75") + SUMIFS(P29:AI29,P14:AI14,"[1]家族",P12:AI12,"[1]男",P13:AI13,">=75") + SUMIFS(P30:AI30,P14:AI14,"[1]家族",P12:AI12,"[1]男",P13:AI13,">=75") -> 0 | BH39: =SUM(BD39:BG39) -> 0 | BI39: =SUMIFS(P15:AI15,P14:AI14,"[1]家族",P12:AI12,"[2]女",P13:AI13,"<65") + SUMIFS(P16:AI16,P14:AI14,"[1]家族",P12:AI12,"[2]女",P13:AI13,"<65") + SUMIFS(P17:AI17,P14:AI14,"[1]家族",P12:AI12,"[2]女",P13:AI13,"<65") + SUMIFS(P18:AI18,P14:AI14,"[1]家族",P12:AI12,"[2]女",P13:AI13,"<65") + SUMIFS(P19:AI19,P14:AI14,"[1]家族",P12:AI12,"[2]女",P13:AI13,"<65") + SUMIFS(P20:AI20,P14:AI14,"[1]家族",P12:AI12,"[2]女",P13:AI13,"<65") + SUMIFS(P21:AI21,P14:AI14,"[1]家族",P12:AI12,"[2]女",P13:AI13,"<65") + SUMIFS(P22:AI22,P14:AI14,"[1]家族",P12:AI12,"[2]女",P13:AI13,"<65") + SUMIFS(P23:AI23,P14:AI14,"[1]家族",P12:AI12,"[2]女",P13:AI13,"<65") + SUMIFS(P24:AI24,P14:AI14,"[1]家族",P12:AI12,"[2]女",P13:AI13,"<65") + SUMIFS(P25:AI25,P14:AI14,"[1]家族",P12:AI12,"[2]女",P13:AI13,"<65") + SUMIFS(P26:AI26,P14:AI14,"[1]家族",P12:AI12,"[2]女",P13:AI13,"<65") + SUMIFS(P27:AI27,P14:AI14,"[1]家族",P12:AI12,"[2]女",P13:AI13,"<65") + SUMIFS(P28:AI28,P14:AI14,"[1]家族",P12:AI12,"[2]女",P13:AI13,"<65") + SUMIFS(P29:AI29,P14:AI14,"[1]家族",P12:AI12,"[2]女",P13:AI13,"<65") + SUMIFS(P30:AI30,P14:AI14,"[1]家族",P12:AI12,"[2]女",P13:AI13,"<65") + SUMIFS(P15:AI15,P14:AI14,"[3]ゆい・手間替え受け",P12:AI12,"[2]女") + SUMIFS(P16:AI16,P14:AI14,"[3]ゆい・手間替え受け",P12:AI12,"[2]女") + SUMIFS(P17:AI17,P14:AI14,"[3]ゆい・手間替え受け",P12:AI12,"[2]女") + SUMIFS(P18:AI18,P14:AI14,"[3]ゆい・手間替え受け",P12:AI12,"[2]女") + SUMIFS(P19:AI19,P14:AI14,"[3]ゆい・手間替え受け",P12:AI12,"[2]女") + SUMIFS(P20:AI20,P14:AI14,"[3]ゆい・手間替え受け",P12:AI12,"[2]女") + SUMIFS(P21:AI21,P14:AI14,"[3]ゆい・手間替え受け",P12:AI12,"[2]女") + SUMIFS(P22:AI22,P14:AI14,"[3]ゆい・手間替え受け",P12:AI12,"[2]女") + SUMIFS(P23:AI23,P14:AI14,"[3]ゆい・手間替え受け",P12:AI12,"[2]女") + SUMIFS(P24:AI24,P14:AI14,"[3]ゆい・手間替え受け",P12:AI12,"[2]女") + SUMIFS(P25:AI25,P14:AI14,"[3]ゆい・手間替え受け",P12:AI12,"[2]女") + SUMIFS(P26:AI26,P14:AI14,"[3]ゆい・手間替え受け",P12:AI12,"[2]女") + SUMIFS(P27:AI27,P14:AI14,"[3]ゆい・手間替え受け",P12:AI12,"[2]女") + SUMIFS(P28:AI28,P14:AI14,"[3]ゆい・手間替え受け",P12:AI12,"[2]女") + SUMIFS(P29:AI29,P14:AI14,"[3]ゆい・手間替え受け",P12:AI12,"[2]女") -> 0 | BJ39: =SUMIFS(P15:AI15,P14:AI14,"[1]家族",P12:AI12,"[2]女",P13:AI13,">=65",P13:AI13,"<70") + SUMIFS(P16:AI16,P14:AI14,"[1]家族",P12:AI12,"[2]女",P13:AI13,">=65",P13:AI13,"<70") + SUMIFS(P17:AI17,P14:AI14,"[1]家族",P12:AI12,"[2]女",P13:AI13,">=65",P13:AI13,"<70") + SUMIFS(P18:AI18,P14:AI14,"[1]家族",P12:AI12,"[2]女",P13:AI13,">=65",P13:AI13,"<70") + SUMIFS(P19:AI19,P14:AI14,"[1]家族",P12:AI12,"[2]女",P13:AI13,">=65",P13:AI13,"<70") + SUMIFS(P20:AI20,P14:AI14,"[1]家族",P12:AI12,"[2]女",P13:AI13,">=65",P13:AI13,"<70") + SUMIFS(P21:AI21,P14:AI14,"[1]家族",P12:AI12,"[2]女",P13:AI13,">=65",P13:AI13,"<70") + SUMIFS(P22:AI22,P14:AI14,"[1]家族",P12:AI12,"[2]女",P13:AI13,">=65",P13:AI13,"<70") + SUMIFS(P23:AI23,P14:AI14,"[1]家族",P12:AI12,"[2]女",P13:AI13,">=65",P13:AI13,"<70") + SUMIFS(P24:AI24,P14:AI14,"[1]家族",P12:AI12,"[2]女",P13:AI13,">=65",P13:AI13,"<70") + SUMIFS(P25:AI25,P14:AI14,"[1]家族",P12:AI12,"[2]女",P13:AI13,">=65",P13:AI13,"<70") + SUMIFS(P26:AI26,P14:AI14,"[1]家族",P12:AI12,"[2]女",P13:AI13,">=65",P13:AI13,"<70") + SUMIFS(P27:AI27,P14:AI14,"[1]家族",P12:AI12,"[2]女",P13:AI13,">=65",P13:AI13,"<70") + SUMIFS(P28:AI28,P14:AI14,"[1]家族",P12:AI12,"[2]女",P13:AI13,">=65",P13:AI13,"<70") + SUMIFS(P29:AI29,P14:AI14,"[1]家族",P12:AI12,"[2]女",P13:AI13,">=65",P13:AI13,"<70") + SUMIFS(P30:AI30,P14:AI14,"[1]家族",P12:AI12,"[2]女",P13:AI13,">=65",P13:AI13,"<70") -> 0 | BK39: =SUMIFS(P15:AI15,P14:AI14,"[1]家族",P12:AI12,"[2]女",P13:AI13,">=70",P13:AI13,"<75") + SUMIFS(P16:AI16,P14:AI14,"[1]家族",P12:AI12,"[2]女",P13:AI13,">=70",P13:AI13,"<75") + SUMIFS(P17:AI17,P14:AI14,"[1]家族",P12:AI12,"[2]女",P13:AI13,">=70",P13:AI13,"<75") + SUMIFS(P18:AI18,P14:AI14,"[1]家族",P12:AI12,"[2]女",P13:AI13,">=70",P13:AI13,"<75") + SUMIFS(P19:AI19,P14:AI14,"[1]家族",P12:AI12,"[2]女",P13:AI13,">=70",P13:AI13,"<75") + SUMIFS(P20:AI20,P14:AI14,"[1]家族",P12:AI12,"[2]女",P13:AI13,">=70",P13:AI13,"<75") + SUMIFS(P21:AI21,P14:AI14,"[1]家族",P12:AI12,"[2]女",P13:AI13,">=70",P13:AI13,"<75") + SUMIFS(P22:AI22,P14:AI14,"[1]家族",P12:AI12,"[2]女",P13:AI13,">=70",P13:AI13,"<75") + SUMIFS(P23:AI23,P14:AI14,"[1]家族",P12:AI12,"[2]女",P13:AI13,">=70",P13:AI13,"<75") + SUMIFS(P24:AI24,P14:AI14,"[1]家族",P12:AI12,"[2]女",P13:AI13,">=70",P13:AI13,"<75") + SUMIFS(P25:AI25,P14:AI14,"[1]家族",P12:AI12,"[2]女",P13:AI13,">=70",P13:AI13,"<75") + SUMIFS(P26:AI26,P14:AI14,"[1]家族",P12:AI12,"[2]女",P13:AI13,">=70",P13:AI13,"<75") + SUMIFS(P27:AI27,P14:AI14,"[1]家族",P12:AI12,"[2]女",P13:AI13,">=70",P13:AI13,"<75") + SUMIFS(P28:AI28,P14:AI14,"[1]家族",P12:AI12,"[2]女",P13:AI13,">=70",P13:AI13,"<75") + SUMIFS(P29:AI29,P14:AI14,"[1]家族",P12:AI12,"[2]女",P13:AI13,">=70",P13:AI13,"<75") + SUMIFS(P30:AI30,P14:AI14,"[1]家族",P12:AI12,"[2]女",P13:AI13,">=70",P13:AI13,"<75") -> 0 | BL39: =SUMIFS(P15:AI15,P14:AI14,"[1]家族",P12:AI12,"[2]女",P13:AI13,">=75") + SUMIFS(P16:AI16,P14:AI14,"[1]家族",P12:AI12,"[2]女",P13:AI13,">=75") + SUMIFS(P17:AI17,P14:AI14,"[1]家族",P12:AI12,"[2]女",P13:AI13,">=75") + SUMIFS(P18:AI18,P14:AI14,"[1]家族",P12:AI12,"[2]女",P13:AI13,">=75") + SUMIFS(P19:AI19,P14:AI14,"[1]家族",P12:AI12,"[2]女",P13:AI13,">=75") + SUMIFS(P20:AI20,P14:AI14,"[1]家族",P12:AI12,"[2]女",P13:AI13,">=75") + SUMIFS(P21:AI21,P14:AI14,"[1]家族",P12:AI12,"[2]女",P13:AI13,">=75") + SUMIFS(P22:AI22,P14:AI14,"[1]家族",P12:AI12,"[2]女",P13:AI13,">=75") + SUMIFS(P23:AI23,P14:AI14,"[1]家族",P12:AI12,"[2]女",P13:AI13,">=75") + SUMIFS(P24:AI24,P14:AI14,"[1]家族",P12:AI12,"[2]女",P13:AI13,">=75") + SUMIFS(P25:AI25,P14:AI14,"[1]家族",P12:AI12,"[2]女",P13:AI13,">=75") + SUMIFS(P26:AI26,P14:AI14,"[1]家族",P12:AI12,"[2]女",P13:AI13,">=75") + SUMIFS(P27:AI27,P14:AI14,"[1]家族",P12:AI12,"[2]女",P13:AI13,">=75") + SUMIFS(P28:AI28,P14:AI14,"[1]家族",P12:AI12,"[2]女",P13:AI13,">=75") + SUMIFS(P29:AI29,P14:AI14,"[1]家族",P12:AI12,"[2]女",P13:AI13,">=75") + SUMIFS(P30:AI30,P14:AI14,"[1]家族",P12:AI12,"[2]女",P13:AI13,">=75") -> 0 | BM39: =SUM(BI39:BL39) -> 0 | BN39: =SUM(BD39,BI39) -> 0 | BO39: =SUM(BE39,BJ39) -> 0 | BP39: =SUM(BF39,BK39) -> 0 | BQ39: =SUM(BG39,BL39) -> 0 | BR39: =SUM(BN39:BQ39) -> 0
BC40: 間接労働 | BD40: =SUMIFS(P31:AI31,P14:AI14,"[1]家族",P12:AI12,"[1]男",P13:AI13,"<65") + SUMIFS(P31:AI31,P14:AI14,"[3]ゆい・手間替え受け",P12:AI12,"[1]男") -> 0 | BE40: =SUMIFS(P31:AI31,P14:AI14,"[1]家族",P12:AI12,"[1]男",P13:AI13,">=65",P13:AI13,"<70") -> 0 | BF40: =SUMIFS(P31:AI31,P14:AI14,"[1]家族",P12:AI12,"[1]男",P13:AI13,">=70",P13:AI13,"<75") -> 0 | BG40: =SUMIFS(P31:AI31,P14:AI14,"[1]家族",P12:AI12,"[1]男",P13:AI13,">=75") -> 0 | BH40: =SUM(BD40:BG40) -> 0 | BI40: =SUMIFS(P31:AI31,P14:AI14,"[1]家族",P12:AI12,"[2]女",P13:AI13,"<65") + SUMIFS(P31:AI31,P14:AI14,"[3]ゆい・手間替え受け",P12:AI12,"[2]女") -> 0 | BJ40: =SUMIFS(P31:AI31,P14:AI14,"[1]家族",P12:AI12,"[2]女",P13:AI13,">=65",P13:AI13,"<70") -> 0 | BK40: =SUMIFS(P31:AI31,P14:AI14,"[1]家族",P12:AI12,"[2]女",P13:AI13,">=70",P13:AI13,"<75") -> 0 | BL40: =SUMIFS(P31:AI31,P14:AI14,"[1]家族",P12:AI12,"[2]女",P13:AI13,">=75") -> 0 | BM40: =SUM(BI40:BL40) -> 0 | BN40: =SUM(BD40,BI40) -> 0 | BO40: =SUM(BE40,BJ40) -> 0 | BP40: =SUM(BF40,BK40) -> 0 | BQ40: =SUM(BG40,BL40) -> 0 | BR40: =SUM(BN40:BQ40) -> 0
