Workbook

Sheet No.1
A1: 2019 | C1: 年産 麦類・大豆・そば・なたね・畑作物生産費統計（個別経営体） | O1: センサス番号
A2: 個別結果検討表 №１
A4: 【生産費】
A5: 区 分 | G5: 単位 | H5: =A1-2000 -> 19 | I5: 構成割合 | J5: =H5-1 -> 18 | K5: 構成割合 | L5: 増減率 | M5: 増減差 | N5: 主 な 増 減 要 因
I6: （％） | K6: （％） | L6: （％）
A7: 10 ａ 当 た り 生 産 費 | B7: 物財費 | G7: 円 | I7: =IFERROR(H7/$H$29*100,"-") -> - | K7: =IFERROR(J7/$J$29*100,"-") -> - | L7: =IF(H7="-", "-", IF(J7="-", "-", IF(ABS(J7)=0, "-", ROUND(100*(H7-J7)/ABS(J7),10)))) -> - | M7: =H7-J7 -> 0
C8: 種苗費 | G8: 〃 | I8: =IFERROR(H8/$H$29*100,"-") -> - | K8: =IFERROR(J8/$J$29*100,"-") -> - | L8: =IF(H8="-", "-", IF(J8="-", "-", IF(ABS(J8)=0, "-", ROUND(100*(H8-J8)/ABS(J8),10)))) -> - | M8: =H8-J8 -> 0
C9: 肥料費 | G9: 〃 | I9: =IFERROR(H9/$H$29*100,"-") -> - | K9: =IFERROR(J9/$J$29*100,"-") -> - | L9: =IF(H9="-", "-", IF(J9="-", "-", IF(ABS(J9)=0, "-", ROUND(100*(H9-J9)/ABS(J9),10)))) -> - | M9: =H9-J9 -> 0
C10: 農業薬剤費 | G10: 〃 | I10: =IFERROR(H10/$H$29*100,"-") -> - | K10: =IFERROR(J10/$J$29*100,"-") -> - | L10: =IF(H10="-", "-", IF(J10="-", "-", IF(ABS(J10)=0, "-", ROUND(100*(H10-J10)/ABS(J10),10)))) -> - | M10: =H10-J10 -> 0
C11: 光熱動力費 | G11: 〃 | I11: =IFERROR(H11/$H$29*100,"-") -> - | K11: =IFERROR(J11/$J$29*100,"-") -> - | L11: =IF(H11="-", "-", IF(J11="-", "-", IF(ABS(J11)=0, "-", ROUND(100*(H11-J11)/ABS(J11),10)))) -> - | M11: =H11-J11 -> 0
C12: その他の諸材料費 | G12: 〃 | I12: =IFERROR(H12/$H$29*100,"-") -> - | K12: =IFERROR(J12/$J$29*100,"-") -> - | L12: =IF(H12="-", "-", IF(J12="-", "-", IF(ABS(J12)=0, "-", ROUND(100*(H12-J12)/ABS(J12),10)))) -> - | M12: =H12-J12 -> 0
C13: 土地改良及び水利費 | G13: 〃 | I13: =IFERROR(H13/$H$29*100,"-") -> - | K13: =IFERROR(J13/$J$29*100,"-") -> - | L13: =IF(H13="-", "-", IF(J13="-", "-", IF(ABS(J13)=0, "-", ROUND(100*(H13-J13)/ABS(J13),10)))) -> - | M13: =H13-J13 -> 0
C14: 賃借料及び料金 | G14: 〃 | I14: =IFERROR(H14/$H$29*100,"-") -> - | K14: =IFERROR(J14/$J$29*100,"-") -> - | L14: =IF(H14="-", "-", IF(J14="-", "-", IF(ABS(J14)=0, "-", ROUND(100*(H14-J14)/ABS(J14),10)))) -> - | M14: =H14-J14 -> 0
C15: 物件税及び公課諸負担 | G15: 〃 | I15: =IFERROR(H15/$H$29*100,"-") -> - | K15: =IFERROR(J15/$J$29*100,"-") -> - | L15: =IF(H15="-", "-", IF(J15="-", "-", IF(ABS(J15)=0, "-", ROUND(100*(H15-J15)/ABS(J15),10)))) -> - | M15: =H15-J15 -> 0
C16: 建物費 | G16: 〃 | I16: =IFERROR(H16/$H$29*100,"-") -> - | K16: =IFERROR(J16/$J$29*100,"-") -> - | L16: =IF(H16="-", "-", IF(J16="-", "-", IF(ABS(J16)=0, "-", ROUND(100*(H16-J16)/ABS(J16),10)))) -> - | M16: =H16-J16 -> 0
D17: 償却費 | G17: 〃 | I17: =IFERROR(H17/$H$29*100,"-") -> - | K17: =IFERROR(J17/$J$29*100,"-") -> - | L17: =IF(H17="-", "-", IF(J17="-", "-", IF(ABS(J17)=0, "-", ROUND(100*(H17-J17)/ABS(J17),10)))) -> - | M17: =H17-J17 -> 0
C18: 自動車費 | G18: 〃 | I18: =IFERROR(H18/$H$29*100,"-") -> - | K18: =IFERROR(J18/$J$29*100,"-") -> - | L18: =IF(H18="-", "-", IF(J18="-", "-", IF(ABS(J18)=0, "-", ROUND(100*(H18-J18)/ABS(J18),10)))) -> - | M18: =H18-J18 -> 0
D19: 償却費 | G19: 〃 | I19: =IFERROR(H19/$H$29*100,"-") -> - | K19: =IFERROR(J19/$J$29*100,"-") -> - | L19: =IF(H19="-", "-", IF(J19="-", "-", IF(ABS(J19)=0, "-", ROUND(100*(H19-J19)/ABS(J19),10)))) -> - | M19: =H19-J19 -> 0
C20: 農機具費 | G20: 〃 | I20: =IFERROR(H20/$H$29*100,"-") -> - | K20: =IFERROR(J20/$J$29*100,"-") -> - | L20: =IF(H20="-", "-", IF(J20="-", "-", IF(ABS(J20)=0, "-", ROUND(100*(H20-J20)/ABS(J20),10)))) -> - | M20: =H20-J20 -> 0
D21: 償却費 | G21: 〃 | I21: =IFERROR(H21/$H$29*100,"-") -> - | K21: =IFERROR(J21/$J$29*100,"-") -> - | L21: =IF(H21="-", "-", IF(J21="-", "-", IF(ABS(J21)=0, "-", ROUND(100*(H21-J21)/ABS(J21),10)))) -> - | M21: =H21-J21 -> 0
C22: 生産管理費 | G22: 〃 | I22: =IFERROR(H22/$H$29*100,"-") -> - | K22: =IFERROR(J22/$J$29*100,"-") -> - | L22: =IF(H22="-", "-", IF(J22="-", "-", IF(ABS(J22)=0, "-", ROUND(100*(H22-J22)/ABS(J22),10)))) -> - | M22: =H22-J22 -> 0
D23: 償却費 | G23: 〃 | I23: =IFERROR(H23/$H$29*100,"-") -> - | K23: =IFERROR(J23/$J$29*100,"-") -> - | L23: =IF(H23="-", "-", IF(J23="-", "-", IF(ABS(J23)=0, "-", ROUND(100*(H23-J23)/ABS(J23),10)))) -> - | M23: =H23-J23 -> 0
B24: 労働費 | G24: 〃 | I24: =IFERROR(H24/$H$29*100,"-") -> - | K24: =IFERROR(J24/$J$29*100,"-") -> - | L24: =IF(H24="-", "-", IF(J24="-", "-", IF(ABS(J24)=0, "-", ROUND(100*(H24-J24)/ABS(J24),10)))) -> - | M24: =H24-J24 -> 0
D25: 家族 | G25: 〃 | I25: =IFERROR(H25/$H$29*100,"-") -> - | K25: =IFERROR(J25/$J$29*100,"-") -> - | L25: =IF(H25="-", "-", IF(J25="-", "-", IF(ABS(J25)=0, "-", ROUND(100*(H25-J25)/ABS(J25),10)))) -> - | M25: =H25-J25 -> 0
C26: 直接労働費 | G26: 〃 | I26: =IFERROR(H26/$H$29*100,"-") -> - | K26: =IFERROR(J26/$J$29*100,"-") -> - | L26: =IF(H26="-", "-", IF(J26="-", "-", IF(ABS(J26)=0, "-", ROUND(100*(H26-J26)/ABS(J26),10)))) -> - | M26: =H26-J26 -> 0
D27: 家族 | G27: 〃 | I27: =IFERROR(H27/$H$29*100,"-") -> - | K27: =IFERROR(J27/$J$29*100,"-") -> - | L27: =IF(H27="-", "-", IF(J27="-", "-", IF(ABS(J27)=0, "-", ROUND(100*(H27-J27)/ABS(J27),10)))) -> - | M27: =H27-J27 -> 0
C28: 間接労働費 | G28: 〃 | I28: =IFERROR(H28/$H$29*100,"-") -> - | K28: =IFERROR(J28/$J$29*100,"-") -> - | L28: =IF(H28="-", "-", IF(J28="-", "-", IF(ABS(J28)=0, "-", ROUND(100*(H28-J28)/ABS(J28),10)))) -> - | M28: =H28-J28 -> 0
B29: 費用合計 | G29: 〃 | I29: =IFERROR(H29/$H$29*100,"-") -> - | K29: =IFERROR(J29/$J$29*100,"-") -> - | L29: =IF(H29="-", "-", IF(J29="-", "-", IF(ABS(J29)=0, "-", ROUND(100*(H29-J29)/ABS(J29),10)))) -> - | M29: =H29-J29 -> 0
B30: 副産物価額 | G30: 〃 | L30: =IF(H30="-", "-", IF(J30="-", "-", IF(ABS(J30)=0, "-", ROUND(100*(H30-J30)/ABS(J30),10)))) -> - | M30: =H30-J30 -> 0
B31: 生産費（副産物価額差引） | G31: 〃 | L31: =IF(H31="-", "-", IF(J31="-", "-", IF(ABS(J31)=0, "-", ROUND(100*(H31-J31)/ABS(J31),10)))) -> - | M31: =H31-J31 -> 0
B32: 支払利子 | G32: 〃 | L32: =IF(H32="-", "-", IF(J32="-", "-", IF(ABS(J32)=0, "-", ROUND(100*(H32-J32)/ABS(J32),10)))) -> - | M32: =H32-J32 -> 0
B33: 支払地代 | G33: 〃 | L33: =IF(H33="-", "-", IF(J33="-", "-", IF(ABS(J33)=0, "-", ROUND(100*(H33-J33)/ABS(J33),10)))) -> - | M33: =H33-J33 -> 0
B34: 支払利子・地代算入生産費 | G34: 〃 | L34: =IF(H34="-", "-", IF(J34="-", "-", IF(ABS(J34)=0, "-", ROUND(100*(H34-J34)/ABS(J34),10)))) -> - | M34: =H34-J34 -> 0
B35: 自己資本利子 | G35: 〃 | L35: =IF(H35="-", "-", IF(J35="-", "-", IF(ABS(J35)=0, "-", ROUND(100*(H35-J35)/ABS(J35),10)))) -> - | M35: =H35-J35 -> 0
B36: 自作地地代 | G36: 〃 | L36: =IF(H36="-", "-", IF(J36="-", "-", IF(ABS(J36)=0, "-", ROUND(100*(H36-J36)/ABS(J36),10)))) -> - | M36: =H36-J36 -> 0
B37: 資本利子・地代全算入生産費 | G37: 〃 | L37: =IF(H37="-", "-", IF(J37="-", "-", IF(ABS(J37)=0, "-", ROUND(100*(H37-J37)/ABS(J37),10)))) -> - | M37: =H37-J37 -> 0
A38: 単位数量当たり生産費 | G38: 〃 | L38: =IF(H38="-", "-", IF(J38="-", "-", IF(ABS(J38)=0, "-", ROUND(100*(H38-J38)/ABS(J38),10)))) -> - | M38: =H38-J38 -> 0
A39: 単位数量当たり支払利子・地代算入生産費 | G39: 〃 | L39: =IF(H39="-", "-", IF(J39="-", "-", IF(ABS(J39)=0, "-", ROUND(100*(H39-J39)/ABS(J39),10)))) -> - | M39: =H39-J39 -> 0
A40: 単位数量当たり全算入生産費 | G40: 〃 | L40: =IF(H40="-", "-", IF(J40="-", "-", IF(ABS(J40)=0, "-", ROUND(100*(H40-J40)/ABS(J40),10)))) -> - | M40: =H40-J40 -> 0
A41: 経営概況 | B41: 10ａ当たり収量 | G41: kg | L41: =IF(H41="-", "-", IF(J41="-", "-", IF(ABS(J41)=0, "-", ROUND(100*(H41-J41)/ABS(J41),10)))) -> - | M41: =H41-J41 -> 0
...

Sheet No.2
A1: =No.1!A1&"年産 麦類・大豆・そば・なたね・畑作物生産費統計（個別経営体）" -> 2019年産 麦類・大豆・そば・なたね・畑作物生産費統計（個別経営体） | Q1: センサス番号
A2: 個別結果検討表 №２ | Q2: =IF(No.1!O2="","",No.1!O2)
A4: 【労働時間（10ａ当たり）】 | U4: 【生産物の概要（10ａ当たり）】
E5: =No.1!H5 -> 19 | F5: =E5-1 -> 18 | G5: 増減率 | H5: 備考欄 | Y5: =E5 -> 19 | Z5: =F5 -> 18 | AA5: 増減率 | AB5: 備考欄
G6: （％） | AA6: （％）
A7: 労働時間計 | G7: =IF(E7="-", "-", IF(F7="-", "-", IF(ABS(F7)=0, "-", ROUND(100*(E7-F7)/ABS(F7),10)))) -> - | U7: 主産物 | V7: 数量（kg） | AA7: =IF(Y7="-", "-", IF(Z7="-", "-", IF(ABS(Z7)=0, "-", ROUND(100*(Y7-Z7)/ABS(Z7),10)))) -> -
B8: 直接労働時間 | G8: =IF(E8="-", "-", IF(F8="-", "-", IF(ABS(F8)=0, "-", ROUND(100*(E8-F8)/ABS(F8),10)))) -> - | V8: 価額 | AA8: =IF(Y8="-", "-", IF(Z8="-", "-", IF(ABS(Z8)=0, "-", ROUND(100*(Y8-Z8)/ABS(Z8),10)))) -> -
C9: 種子予措 | G9: =IF(E9="-", "-", IF(F9="-", "-", IF(ABS(F9)=0, "-", ROUND(100*(E9-F9)/ABS(F9),10)))) -> - | U9: 副産物価額 | AA9: =IF(Y9="-", "-", IF(Z9="-", "-", IF(ABS(Z9)=0, "-", ROUND(100*(Y9-Z9)/ABS(Z9),10)))) -> -
C10: 育苗 | G10: =IF(E10="-", "-", IF(F10="-", "-", IF(ABS(F10)=0, "-", ROUND(100*(E10-F10)/ABS(F10),10)))) -> - | U10: 粗収益 | AA10: =IF(Y10="-", "-", IF(Z10="-", "-", IF(ABS(Z10)=0, "-", ROUND(100*(Y10-Z10)/ABS(Z10),10)))) -> -
C11: 耕起整地 | G11: =IF(E11="-", "-", IF(F11="-", "-", IF(ABS(F11)=0, "-", ROUND(100*(E11-F11)/ABS(F11),10)))) -> - | U11: （参考）奨励金 | AA11: =IF(Y11="-", "-", IF(Z11="-", "-", IF(ABS(Z11)=0, "-", ROUND(100*(Y11-Z11)/ABS(Z11),10)))) -> -
C12: 基肥 | G12: =IF(E12="-", "-", IF(F12="-", "-", IF(ABS(F12)=0, "-", ROUND(100*(E12-F12)/ABS(F12),10)))) -> - | U12: 所得 | AA12: =IF(Y12="-", "-", IF(Z12="-", "-", IF(ABS(Z12)=0, "-", ROUND(100*(Y12-Z12)/ABS(Z12),10)))) -> -
C13: は種 | G13: =IF(E13="-", "-", IF(F13="-", "-", IF(ABS(F13)=0, "-", ROUND(100*(E13-F13)/ABS(F13),10)))) -> - | V13: １日当たり | AA13: =IF(Y13="-", "-", IF(Z13="-", "-", IF(ABS(Z13)=0, "-", ROUND(100*(Y13-Z13)/ABS(Z13),10)))) -> -
C14: 定植 | G14: =IF(E14="-", "-", IF(F14="-", "-", IF(ABS(F14)=0, "-", ROUND(100*(E14-F14)/ABS(F14),10)))) -> - | U14: 家族労働報酬 | AA14: =IF(Y14="-", "-", IF(Z14="-", "-", IF(ABS(Z14)=0, "-", ROUND(100*(Y14-Z14)/ABS(Z14),10)))) -> -
C15: 株分け | G15: =IF(E15="-", "-", IF(F15="-", "-", IF(ABS(F15)=0, "-", ROUND(100*(E15-F15)/ABS(F15),10)))) -> - | V15: １日当たり | AA15: =IF(Y15="-", "-", IF(Z15="-", "-", IF(ABS(Z15)=0, "-", ROUND(100*(Y15-Z15)/ABS(Z15),10)))) -> -
C16: 追肥 | G16: =IF(E16="-", "-", IF(F16="-", "-", IF(ABS(F16)=0, "-", ROUND(100*(E16-F16)/ABS(F16),10)))) -> - | U16: （参考）各種助成措置を加えた場合
C17: 中耕除草 | G17: =IF(E17="-", "-", IF(F17="-", "-", IF(ABS(F17)=0, "-", ROUND(100*(E17-F17)/ABS(F17),10)))) -> - | V17: 粗収益 | AA17: =IF(Y17="-", "-", IF(Z17="-", "-", IF(ABS(Z17)=0, "-", ROUND(100*(Y17-Z17)/ABS(Z17),10)))) -> -
C18: 麦踏み | G18: =IF(E18="-", "-", IF(F18="-", "-", IF(ABS(F18)=0, "-", ROUND(100*(E18-F18)/ABS(F18),10)))) -> - | V18: 所得 | AA18: =IF(Y18="-", "-", IF(Z18="-", "-", IF(ABS(Z18)=0, "-", ROUND(100*(Y18-Z18)/ABS(Z18),10)))) -> -
C19: 管理 | G19: =IF(E19="-", "-", IF(F19="-", "-", IF(ABS(F19)=0, "-", ROUND(100*(E19-F19)/ABS(F19),10)))) -> - | W19: １日当たり | AA19: =IF(Y19="-", "-", IF(Z19="-", "-", IF(ABS(Z19)=0, "-", ROUND(100*(Y19-Z19)/ABS(Z19),10)))) -> -
C20: 防除 | G20: =IF(E20="-", "-", IF(F20="-", "-", IF(ABS(F20)=0, "-", ROUND(100*(E20-F20)/ABS(F20),10)))) -> - | V20: 家族労働報酬 | AA20: =IF(Y20="-", "-", IF(Z20="-", "-", IF(ABS(Z20)=0, "-", ROUND(100*(Y20-Z20)/ABS(Z20),10)))) -> -
C21: はく葉 | G21: =IF(E21="-", "-", IF(F21="-", "-", IF(ABS(F21)=0, "-", ROUND(100*(E21-F21)/ABS(F21),10)))) -> - | W21: １日当たり | AA21: =IF(Y21="-", "-", IF(Z21="-", "-", IF(ABS(Z21)=0, "-", ROUND(100*(Y21-Z21)/ABS(Z21),10)))) -> -
C22: 刈取脱穀 | G22: =IF(E22="-", "-", IF(F22="-", "-", IF(ABS(F22)=0, "-", ROUND(100*(E22-F22)/ABS(F22),10)))) -> -
C23: 乾燥 | G23: =IF(E23="-", "-", IF(F23="-", "-", IF(ABS(F23)=0, "-", ROUND(100*(E23-F23)/ABS(F23),10)))) -> -
C24: 生産管理 | G24: =IF(E24="-", "-", IF(F24="-", "-", IF(ABS(F24)=0, "-", ROUND(100*(E24-F24)/ABS(F24),10)))) -> -
B25: 間接労働時間 | G25: =IF(E25="-", "-", IF(F25="-", "-", IF(ABS(F25)=0, "-", ROUND(100*(E25-F25)/ABS(F25),10)))) -> -
A26: 家族労働時間 | G26: =IF(E26="-", "-", IF(F26="-", "-", IF(ABS(F26)=0, "-", ROUND(100*(E26-F26)/ABS(F26),10)))) -> -
B27: 男 | G27: =IF(E27="-", "-", IF(F27="-", "-", IF(ABS(F27)=0, "-", ROUND(100*(E27-F27)/ABS(F27),10)))) -> - | U27: 【物件税及び公課諸負担（10ａ当たり）】
B28: 女 | G28: =IF(E28="-", "-", IF(F28="-", "-", IF(ABS(F28)=0, "-", ROUND(100*(E28-F28)/ABS(F28),10)))) -> - | Y28: =E5 -> 19 | Z28: =F5 -> 18 | AA28: 増減率 | AB28: 備考欄
A29: 雇用労働時間 | G29: =IF(E29="-", "-", IF(F29="-", "-", IF(ABS(F29)=0, "-", ROUND(100*(E29-F29)/ABS(F29),10)))) -> - | Y29: （円） | Z29: （円） | AA29: （％）
B30: 男 | G30: =IF(E30="-", "-", IF(F30="-", "-", IF(ABS(F30)=0, "-", ROUND(100*(E30-F30)/ABS(F30),10)))) -> - | U30: 物件税 | AA30: =IF(Y30="-", "-", IF(Z30="-", "-", IF(ABS(Z30)=0, "-", ROUND(100*(Y30-Z30)/ABS(Z30),10)))) -> -
B31: 女 | G31: =IF(E31="-", "-", IF(F31="-", "-", IF(ABS(F31)=0, "-", ROUND(100*(E31-F31)/ABS(F31),10)))) -> - | U31: 公課諸負担 | AA31: =IF(Y31="-", "-", IF(Z31="-", "-", IF(ABS(Z31)=0, "-", ROUND(100*(Y31-Z31)/ABS(Z31),10)))) -> -

Sheet No.3
A1: =No.1!A1&"年産 麦類・大豆・そば・なたね・畑作物生産費統計（個別経営体）" -> 2019年産 麦類・大豆・そば・なたね・畑作物生産費統計（個別経営体） | O1: センサス番号
A2: 個別結果検討表 №３ | O2: =IF(No.1!O2="","",No.1!O2)
A4: 【作付面積、地代】
I5: 自作地 | L5: 借入地 | O5: 計 | R5: 備考欄
I6: =No.1!H5 -> 19 | J6: =I6-1 -> 18 | K6: 増減率 | L6: =$I$6 -> 19 | M6: =$J$6 -> 18 | N6: 増減率 | O6: =$I$6 -> 19 | P6: =$J$6 -> 18 | Q6: 増減率
K7: （％） | N7: （％） | Q7: （％）
A8: 作付地 | C8: 作付実面積 | H8: （ａ） | K8: =IF(I8="-", "-", IF(J8="-", "-", IF(ABS(J8)=0, "-", ROUND(100*(I8-J8)/ABS(J8),10)))) -> - | N8: =IF(L8="-", "-", IF(M8="-", "-", IF(ABS(M8)=0, "-", ROUND(100*(L8-M8)/ABS(M8),10)))) -> - | Q8: =IF(O8="-", "-", IF(P8="-", "-", IF(ABS(P8)=0, "-", ROUND(100*(O8-P8)/ABS(P8),10)))) -> -
C9: 土地台帳面積 | H9: （ａ） | K9: =IF(I9="-", "-", IF(J9="-", "-", IF(ABS(J9)=0, "-", ROUND(100*(I9-J9)/ABS(J9),10)))) -> - | N9: =IF(L9="-", "-", IF(M9="-", "-", IF(ABS(M9)=0, "-", ROUND(100*(L9-M9)/ABS(M9),10)))) -> - | Q9: =IF(O9="-", "-", IF(P9="-", "-", IF(ABS(P9)=0, "-", ROUND(100*(O9-P9)/ABS(P9),10)))) -> -
C10: 10ａ当たり地代総額 | H10: （円） | K10: =IF(I10="-", "-", IF(J10="-", "-", IF(ABS(J10)=0, "-", ROUND(100*(I10-J10)/ABS(J10),10)))) -> - | N10: =IF(L10="-", "-", IF(M10="-", "-", IF(ABS(M10)=0, "-", ROUND(100*(L10-M10)/ABS(M10),10)))) -> - | Q10: =IF(O10="-", "-", IF(P10="-", "-", IF(ABS(P10)=0, "-", ROUND(100*(O10-P10)/ABS(P10),10)))) -> -
C11: 10ａ当たり負担地代 | H11: （円） | K11: =IF(I11="-", "-", IF(J11="-", "-", IF(ABS(J11)=0, "-", ROUND(100*(I11-J11)/ABS(J11),10)))) -> - | N11: =IF(L11="-", "-", IF(M11="-", "-", IF(ABS(M11)=0, "-", ROUND(100*(L11-M11)/ABS(M11),10)))) -> - | Q11: =IF(O11="-", "-", IF(P11="-", "-", IF(ABS(P11)=0, "-", ROUND(100*(O11-P11)/ABS(P11),10)))) -> -
A12: 作付地以外 | C12: 使用面積 | H12: （ａ） | K12: =IF(I12="-", "-", IF(J12="-", "-", IF(ABS(J12)=0, "-", ROUND(100*(I12-J12)/ABS(J12),10)))) -> - | N12: =IF(L12="-", "-", IF(M12="-", "-", IF(ABS(M12)=0, "-", ROUND(100*(L12-M12)/ABS(M12),10)))) -> - | Q12: =IF(O12="-", "-", IF(P12="-", "-", IF(ABS(P12)=0, "-", ROUND(100*(O12-P12)/ABS(P12),10)))) -> -
C13: 10ａ当たり賃借料総額 | H13: （円） | K13: =IF(I13="-", "-", IF(J13="-", "-", IF(ABS(J13)=0, "-", ROUND(100*(I13-J13)/ABS(J13),10)))) -> - | N13: =IF(L13="-", "-", IF(M13="-", "-", IF(ABS(M13)=0, "-", ROUND(100*(L13-M13)/ABS(M13),10)))) -> - | Q13: =IF(O13="-", "-", IF(P13="-", "-", IF(ABS(P13)=0, "-", ROUND(100*(O13-P13)/ABS(P13),10)))) -> -
C14: 10ａ当たり負担地代 | H14: （円） | K14: =IF(I14="-", "-", IF(J14="-", "-", IF(ABS(J14)=0, "-", ROUND(100*(I14-J14)/ABS(J14),10)))) -> - | N14: =IF(L14="-", "-", IF(M14="-", "-", IF(ABS(M14)=0, "-", ROUND(100*(L14-M14)/ABS(M14),10)))) -> - | Q14: =IF(O14="-", "-", IF(P14="-", "-", IF(ABS(P14)=0, "-", ROUND(100*(O14-P14)/ABS(P14),10)))) -> -
A15: 10ａ当たり実勢地代 | H15: （円） | K15: =IF(I15="-", "-", IF(J15="-", "-", IF(ABS(J15)=0, "-", ROUND(100*(I15-J15)/ABS(J15),10)))) -> - | N15: =IF(L15="-", "-", IF(M15="-", "-", IF(ABS(M15)=0, "-", ROUND(100*(L15-M15)/ABS(M15),10)))) -> - | Q15: =IF(O15="-", "-", IF(P15="-", "-", IF(ABS(P15)=0, "-", ROUND(100*(O15-P15)/ABS(P15),10)))) -> -
A17: 【調査対象栽培型を含む調査作物の収穫面積等（１経営体当たり）】
A18: てんさい
I19: 直まき | L19: 移植 | O19: 計 | R19: 備考欄
I20: =$I$6 -> 19 | J20: =$J$6 -> 18 | K20: 増減率 | L20: =$I$6 -> 19 | M20: =$J$6 -> 18 | N20: 増減率 | O20: =$I$6 -> 19 | P20: =$J$6 -> 18 | Q20: 増減率
K21: （％） | N21: （％） | Q21: （％）
A22: 収穫面積 | H22: （ａ） | K22: =IF(I22="-", "-", IF(J22="-", "-", IF(ABS(J22)=0, "-", ROUND(100*(I22-J22)/ABS(J22),10)))) -> - | N22: =IF(L22="-", "-", IF(M22="-", "-", IF(ABS(M22)=0, "-", ROUND(100*(L22-M22)/ABS(M22),10)))) -> - | Q22: =IF(O22="-", "-", IF(P22="-", "-", IF(ABS(P22)=0, "-", ROUND(100*(O22-P22)/ABS(P22),10)))) -> -
A24: さとうきび
I25: 株出し | L25: 春植え | O25: 夏植え | R25: 計 | U25: 備考欄
I26: =$I$6 -> 19 | J26: =$J$6 -> 18 | K26: 増減率 | L26: =$I$6 -> 19 | M26: =$J$6 -> 18 | N26: 増減率 | O26: =$I$6 -> 19 | P26: =$J$6 -> 18 | Q26: 増減率 | R26: =$I$6 -> 19 | S26: =$J$6 -> 18 | T26: 増減率
K27: （％） | N27: （％） | Q27: （％） | T27: （％）
A28: 収穫面積 | H28: （ａ） | K28: =IF(I28="-", "-", IF(J28="-", "-", IF(ABS(J28)=0, "-", ROUND(100*(I28-J28)/ABS(J28),10)))) -> - | N28: =IF(L28="-", "-", IF(M28="-", "-", IF(ABS(M28)=0, "-", ROUND(100*(L28-M28)/ABS(M28),10)))) -> - | Q28: =IF(O28="-", "-", IF(P28="-", "-", IF(ABS(P28)=0, "-", ROUND(100*(O28-P28)/ABS(P28),10)))) -> - | T28: =IF(R28="-", "-", IF(S28="-", "-", IF(ABS(S28)=0, "-", ROUND(100*(R28-S28)/ABS(S28),10)))) -> -
A31: 【麦類・大豆・そば・なたねの委託状況（１経営体当たり）】
I32: =$I$6 -> 19 | J32: =$J$6 -> 18 | K32: 増減率 | L32: 備考欄
K33: （％）
A34: 耕うん・整地 | H34: ａ | K34: =IF(I34="-", "-", IF(J34="-", "-", IF(ABS(J34)=0, "-", ROUND(100*(I34-J34)/ABS(J34),10)))) -> -
A35: は種 | H35: ａ | K35: =IF(I35="-", "-", IF(J35="-", "-", IF(ABS(J35)=0, "-", ROUND(100*(I35-J35)/ABS(J35),10)))) -> -
A36: 防除 | H36: ａ | K36: =IF(I36="-", "-", IF(J36="-", "-", IF(ABS(J36)=0, "-", ROUND(100*(I36-J36)/ABS(J36),10)))) -> -
A37: 刈取・脱穀 | H37: ａ | K37: =IF(I37="-", "-", IF(J37="-", "-", IF(ABS(J37)=0, "-", ROUND(100*(I37-J37)/ABS(J37),10)))) -> -
A38: 乾燥・調製 | H38: kg | K38: =IF(I38="-", "-", IF(J38="-", "-", IF(ABS(J38)=0, "-", ROUND(100*(I38-J38)/ABS(J38),10)))) -> -

Sheet No.4
A1: =No.1!A1&"年産 麦類・大豆・そば・なたね・畑作物生産費統計（個別経営体）" -> 2019年産 麦類・大豆・そば・なたね・畑作物生産費統計（個別経営体） | K1: センサス番号
A2: 個別結果検討表 №４ | K2: =IF(No.1!O2="","",No.1!O2)
A4: 【費用の内訳（１経営体当たり・10ａ当たり）】
F5: 使 用 台 数 （ １ 経 営 体 当 た り ） | I5: 調 査 作 物 負 担 分 （ 1 0 ａ 当 た り ） | L5: 備考欄
F6: =No.1!H5 -> 19 | G6: =F6-1 -> 18 | H6: 増減率 | I6: =F6 -> 19 | J6: =G6 -> 18 | K6: 増減率
F7: （台） | G7: （台） | H7: （％） | I7: (円) | J7: （円） | K7: （％）
A8: 減価償却費 | K8: =IF(I8="-", "-", IF(J8="-", "-", IF(ABS(J8)=0, "-", ROUND(100*(I8-J8)/ABS(J8),10)))) -> -
B9: 建物・構築物 | K9: =IF(I9="-", "-", IF(J9="-", "-", IF(ABS(J9)=0, "-", ROUND(100*(I9-J9)/ABS(J9),10)))) -> -
D10: 処分差損失 | K10: =IF(I10="-", "-", IF(J10="-", "-", IF(ABS(J10)=0, "-", ROUND(100*(I10-J10)/ABS(J10),10)))) -> -
C11: 住宅 | K11: =IF(I11="-", "-", IF(J11="-", "-", IF(ABS(J11)=0, "-", ROUND(100*(I11-J11)/ABS(J11),10)))) -> -
C12: 事務所 | K12: =IF(I12="-", "-", IF(J12="-", "-", IF(ABS(J12)=0, "-", ROUND(100*(I12-J12)/ABS(J12),10)))) -> -
C13: 納屋・倉庫 | K13: =IF(I13="-", "-", IF(J13="-", "-", IF(ABS(J13)=0, "-", ROUND(100*(I13-J13)/ABS(J13),10)))) -> -
C14: 作業場 | K14: =IF(I14="-", "-", IF(J14="-", "-", IF(ABS(J14)=0, "-", ROUND(100*(I14-J14)/ABS(J14),10)))) -> -
C15: 車庫 | K15: =IF(I15="-", "-", IF(J15="-", "-", IF(ABS(J15)=0, "-", ROUND(100*(I15-J15)/ABS(J15),10)))) -> -
C16: ライスセンター | K16: =IF(I16="-", "-", IF(J16="-", "-", IF(ABS(J16)=0, "-", ROUND(100*(I16-J16)/ABS(J16),10)))) -> -
C17: 育苗ハウス | K17: =IF(I17="-", "-", IF(J17="-", "-", IF(ABS(J17)=0, "-", ROUND(100*(I17-J17)/ABS(J17),10)))) -> -
C18: 稲架 | K18: =IF(I18="-", "-", IF(J18="-", "-", IF(ABS(J18)=0, "-", ROUND(100*(I18-J18)/ABS(J18),10)))) -> -
C19: コンクリートけい畔 | K19: =IF(I19="-", "-", IF(J19="-", "-", IF(ABS(J19)=0, "-", ROUND(100*(I19-J19)/ABS(J19),10)))) -> -
C20: 暗きょ排水施設 | K20: =IF(I20="-", "-", IF(J20="-", "-", IF(ABS(J20)=0, "-", ROUND(100*(I20-J20)/ABS(J20),10)))) -> -
C21: 客土 | K21: =IF(I21="-", "-", IF(J21="-", "-", IF(ABS(J21)=0, "-", ROUND(100*(I21-J21)/ABS(J21),10)))) -> -
C22: 作業道 | K22: =IF(I22="-", "-", IF(J22="-", "-", IF(ABS(J22)=0, "-", ROUND(100*(I22-J22)/ABS(J22),10)))) -> -
... C25: その他 | K25: =IF(I25="-", "-", IF(J25="-", "-", IF(ABS(J25)=0, "-", ROUND(100*(I25-J25)/ABS(J25),10)))) -> -
B26: 自動車 | K26: =IF(I26="-", "-", IF(J26="-", "-", IF(ABS(J26)=0, "-", ROUND(100*(I26-J26)/ABS(J26),10)))) -> -
D27: 処分差損失 | K27: =IF(I27="-", "-", IF(J27="-", "-", IF(ABS(J27)=0, "-", ROUND(100*(I27-J27)/ABS(J27),10)))) -> -
C28: 貨物自動車 | H28: =IF(F28="-", "-", IF(G28="-", "-", IF(ABS(G28)=0, "-", ROUND(100*(F28-G28)/ABS(G28),10)))) -> - | K28: =IF(I28="-", "-", IF(J28="-", "-", IF(ABS(J28)=0, "-", ROUND(100*(I28-J28)/ABS(J28),10)))) -> -
C29: その他 | K29: =IF(I29="-", "-", IF(J29="-", "-", IF(ABS(J29)=0, "-", ROUND(100*(I29-J29)/ABS(J29),10)))) -> -
B30: 農機具 | K30: =IF(I30="-", "-", IF(J30="-", "-", IF(ABS(J30)=0, "-", ROUND(100*(I30-J30)/ABS(J30),10)))) -> -
D31: 処分差損失 | K31: =IF(I31="-", "-", IF(J31="-", "-", IF(ABS(J31)=0, "-", ROUND(100*(I31-J31)/ABS(J31),10)))) -> -
C32: 乗 用 トラク タ ー | E32: 20馬力未満 | H32: =IF(F32="-", "-", IF(G32="-", "-", IF(ABS(G32)=0, "-", ROUND(100*(F32-G32)/ABS(G32),10)))) -> - | K32: =IF(I32="-", "-", IF(J32="-", "-", IF(ABS(J32)=0, "-", ROUND(100*(I32-J32)/ABS(J32),10)))) -> -
E33: 20～50馬力未満 | H33: =IF(F33="-", "-", IF(G33="-", "-", IF(ABS(G33)=0, "-", ROUND(100*(F33-G33)/ABS(G33),10)))) -> - | K33: =IF(I33="-", "-", IF(J33="-", "-", IF(ABS(J33)=0, "-", ROUND(100*(I33-J33)/ABS(J33),10)))) -> -
E34: 50～80馬力未満 | H34: =IF(F34="-", "-", IF(G34="-", "-", IF(ABS(G34)=0, "-", ROUND(100*(F34-G34)/ABS(G34),10)))) -> - | K34: =IF(I34="-", "-", IF(J34="-", "-", IF(ABS(J34)=0, "-", ROUND(100*(I34-J34)/ABS(J34),10)))) -> -
E35: 80～100馬力未満 | H35: =IF(F35="-", "-", IF(G35="-", "-", IF(ABS(G35)=0, "-", ROUND(100*(F35-G35)/ABS(G35),10)))) -> - | K35: =IF(I35="-", "-", IF(J35="-", "-", IF(ABS(J35)=0, "-", ROUND(100*(I35-J35)/ABS(J35),10)))) -> -
E36: 100馬力以上 | H36: =IF(F36="-", "-", IF(G36="-", "-", IF(ABS(G36)=0, "-", ROUND(100*(F36-G36)/ABS(G36),10)))) -> - | K36: =IF(I36="-", "-", IF(J36="-", "-", IF(ABS(J36)=0, "-", ROUND(100*(I36-J36)/ABS(J36),10)))) -> -
C37: 歩行用トラクター | H37: =IF(F37="-", "-", IF(G37="-", "-", IF(ABS(G37)=0, "-", ROUND(100*(F37-G37)/ABS(G37),10)))) -> - | K37: =IF(I37="-", "-", IF(J37="-", "-", IF(ABS(J37)=0, "-", ROUND(100*(I37-J37)/ABS(J37),10)))) -> -
C38: たい肥等散布機 | H38: =IF(F38="-", "-", IF(G38="-", "-", IF(ABS(G38)=0, "-", ROUND(100*(F38-G38)/ABS(G38),10)))) -> - | K38: =IF(I38="-", "-", IF(J38="-", "-", IF(ABS(J38)=0, "-", ROUND(100*(I38-J38)/ABS(J38),10)))) -> -
C39: 総合は種機 | H39: =IF(F39="-", "-", IF(G39="-", "-", IF(ABS(G39)=0, "-", ROUND(100*(F39-G39)/ABS(G39),10)))) -> - | K39: =IF(I39="-", "-", IF(J39="-", "-", IF(ABS(J39)=0, "-", ROUND(100*(I39-J39)/ABS(J39),10)))) -> -
C40: 移植機 | H40: =IF(F40="-", "-", IF(G40="-", "-", IF(ABS(G40)=0, "-", ROUND(100*(F40-G40)/ABS(G40),10)))) -> - | K40: =IF(I40="-", "-", IF(J40="-", "-", IF(ABS(J40)=0, "-", ROUND(100*(I40-J40)/ABS(J40),10)))) -> -
C41: 中耕除草機 | H41: =IF(F41="-", "-", IF(G41="-", "-", IF(ABS(G41)=0, "-", ROUND(100*(F41-G41)/ABS(G41),10)))) -> - | K41: =IF(I41="-", "-", IF(J41="-", "-", IF(ABS(J41)=0, "-", ROUND(100*(I41-J41)/ABS(J41),10)))) -> -
C42: 肥料散布機 | H42: =IF(F42="-", "-", IF(G42="-", "-", IF(ABS(G42)=0, "-", ROUND(100*(F42-G42)/ABS(G42),10)))) -> - | K42: =IF(I42="-", "-", IF(J42="-", "-", IF(ABS(J42)=0, "-", ROUND(100*(I42-J42)/ABS(J42),10)))) -> -
C43: 動力噴霧機 | H43: =IF(F43="-", "-", IF(G43="-", "-", IF(ABS(G43)=0, "-", ROUND(100*(F43-G43)/ABS(G43),10)))) -> - | K43: =IF(I43="-", "-", IF(J43="-", "-", IF(ABS(J43)=0, "-", ROUND(100*(I43-J43)/ABS(J43),10)))) -> -
...

Sheet No.5
A1: =No.1!A1&"年産 麦類・大豆・そば・なたね・畑作物生産費統計（個別経営体）" -> 2019年産 麦類・大豆・そば・なたね・畑作物生産費統計（個別経営体） | M1: センサス番号
A2: 個別結果検討表 №５ | M2: =IF(No.1!O2="","",No.1!O2)
A4: 【生産物の処分内訳（10ａ当たり）】
G5: =No.1!H5 -> 19 | J5: =G5-1 -> 18 | M5: 増 減 率 | P5: 備考欄
G6: 数量 | H6: 価額 | I6: 単価 | J6: 数量 | K6: 価額 | L6: 単価 | M6: 数量 | N6: 価額 | O6: 単価
G7: （kg） | H7: （円） | I7: （円） | J7: （kg） | K7: （円） | L7: （円） | M7: （％） | N7: （％） | O7: （％）
A8: 麦類 | B8: 主産物 | C8: 販売用 | D8: １等 | M8: =IF(G8="-", "-", IF(J8="-", "-", IF(ABS(J8)=0, "-", ROUND(100*(G8-J8)/ABS(J8),10)))) -> - | N8: =IF(H8="-", "-", IF(K8="-", "-", IF(ABS(K8)=0, "-", ROUND(100*(H8-K8)/ABS(K8),10)))) -> - | O8: =IF(I8="-", "-", IF(L8="-", "-", IF(ABS(L8)=0, "-", ROUND(100*(I8-L8)/ABS(L8),10)))) -> -
D9: ２等 | M9: =IF(G9="-", "-", IF(J9="-", "-", IF(ABS(J9)=0, "-", ROUND(100*(G9-J9)/ABS(J9),10)))) -> - | N9: =IF(H9="-", "-", IF(K9="-", "-", IF(ABS(K9)=0, "-", ROUND(100*(H9-K9)/ABS(K9),10)))) -> - | O9: =IF(I9="-", "-", IF(L9="-", "-", IF(ABS(L9)=0, "-", ROUND(100*(I9-L9)/ABS(L9),10)))) -> -
D10: 規格外Ａ | M10: =IF(G10="-", "-", IF(J10="-", "-", IF(ABS(J10)=0, "-", ROUND(100*(G10-J10)/ABS(J10),10)))) -> - | N10: =IF(H10="-", "-", IF(K10="-", "-", IF(ABS(K10)=0, "-", ROUND(100*(H10-K10)/ABS(K10),10)))) -> - | O10: =IF(I10="-", "-", IF(L10="-", "-", IF(ABS(L10)=0, "-", ROUND(100*(I10-L10)/ABS(L10),10)))) -> -
D11: その他 | M11: =IF(G11="-", "-", IF(J11="-", "-", IF(ABS(J11)=0, "-", ROUND(100*(G11-J11)/ABS(J11),10)))) -> - | N11: =IF(H11="-", "-", IF(K11="-", "-", IF(ABS(K11)=0, "-", ROUND(100*(H11-K11)/ABS(K11),10)))) -> - | O11: =IF(I11="-", "-", IF(L11="-", "-", IF(ABS(L11)=0, "-", ROUND(100*(I11-L11)/ABS(L11),10)))) -> -
D12: 小計 | M12: =IF(G12="-", "-", IF(J12="-", "-", IF(ABS(J12)=0, "-", ROUND(100*(G12-J12)/ABS(J12),10)))) -> - | N12: =IF(H12="-", "-", IF(K12="-", "-", IF(ABS(K12)=0, "-", ROUND(100*(H12-K12)/ABS(K12),10)))) -> - | O12: =IF(I12="-", "-", IF(L12="-", "-", IF(ABS(L12)=0, "-", ROUND(100*(I12-L12)/ABS(L12),10)))) -> -
C13: 自家用 | D13: 食用 | M13: =IF(G13="-", "-", IF(J13="-", "-", IF(ABS(J13)=0, "-", ROUND(100*(G13-J13)/ABS(J13),10)))) -> - | N13: =IF(H13="-", "-", IF(K13="-", "-", IF(ABS(K13)=0, "-", ROUND(100*(H13-K13)/ABS(K13),10)))) -> - | O13: =IF(I13="-", "-", IF(L13="-", "-", IF(ABS(L13)=0, "-", ROUND(100*(I13-L13)/ABS(L13),10)))) -> -
D14: 種子用 | M14: =IF(G14="-", "-", IF(J14="-", "-", IF(ABS(J14)=0, "-", ROUND(100*(G14-J14)/ABS(J14),10)))) -> - | N14: =IF(H14="-", "-", IF(K14="-", "-", IF(ABS(K14)=0, "-", ROUND(100*(H14-K14)/ABS(K14),10)))) -> - | O14: =IF(I14="-", "-", IF(L14="-", "-", IF(ABS(L14)=0, "-", ROUND(100*(I14-L14)/ABS(L14),10)))) -> -
D15: その他 | M15: =IF(G15="-", "-", IF(J15="-", "-", IF(ABS(J15)=0, "-", ROUND(100*(G15-J15)/ABS(J15),10)))) -> - | N15: =IF(H15="-", "-", IF(K15="-", "-", IF(ABS(K15)=0, "-", ROUND(100*(H15-K15)/ABS(K15),10)))) -> - | O15: =IF(I15="-", "-", IF(L15="-", "-", IF(ABS(L15)=0, "-", ROUND(100*(I15-L15)/ABS(L15),10)))) -> -
D16: 小計 | M16: =IF(G16="-", "-", IF(J16="-", "-", IF(ABS(J16)=0, "-", ROUND(100*(G16-J16)/ABS(J16),10)))) -> - | N16: =IF(H16="-", "-", IF(K16="-", "-", IF(ABS(K16)=0, "-", ROUND(100*(H16-K16)/ABS(K16),10)))) -> - | O16: =IF(I16="-", "-", IF(L16="-", "-", IF(ABS(L16)=0, "-", ROUND(100*(I16-L16)/ABS(L16),10)))) -> -
C17: 合計 | M17: =IF(G17="-", "-", IF(J17="-", "-", IF(ABS(J17)=0, "-", ROUND(100*(G17-J17)/ABS(J17),10)))) -> - | N17: =IF(H17="-", "-", IF(K17="-", "-", IF(ABS(K17)=0, "-", ROUND(100*(H17-K17)/ABS(K17),10)))) -> - | O17: =IF(I17="-", "-", IF(L17="-", "-", IF(ABS(L17)=0, "-", ROUND(100*(I17-L17)/ABS(L17),10)))) -> -
B18: 副産物 | C18: 販売用 | D18: 規格外Ｂ | M18: =IF(G18="-", "-", IF(J18="-", "-", IF(ABS(J18)=0, "-", ROUND(100*(G18-J18)/ABS(J18),10)))) -> - | N18: =IF(H18="-", "-", IF(K18="-", "-", IF(ABS(K18)=0, "-", ROUND(100*(H18-K18)/ABS(K18),10)))) -> - | O18: =IF(I18="-", "-", IF(L18="-", "-", IF(ABS(L18)=0, "-", ROUND(100*(I18-L18)/ABS(L18),10)))) -> -
D19: 規格外Ｃ | M19: =IF(G19="-", "-", IF(J19="-", "-", IF(ABS(J19)=0, "-", ROUND(100*(G19-J19)/ABS(J19),10)))) -> - | N19: =IF(H19="-", "-", IF(K19="-", "-", IF(ABS(K19)=0, "-", ROUND(100*(H19-K19)/ABS(K19),10)))) -> - | O19: =IF(I19="-", "-", IF(L19="-", "-", IF(ABS(L19)=0, "-", ROUND(100*(I19-L19)/ABS(L19),10)))) -> -
D20: くず麦 | M20: =IF(G20="-", "-", IF(J20="-", "-", IF(ABS(J20)=0, "-", ROUND(100*(G20-J20)/ABS(J20),10)))) -> - | N20: =IF(H20="-", "-", IF(K20="-", "-", IF(ABS(K20)=0, "-", ROUND(100*(H20-K20)/ABS(K20),10)))) -> - | O20: =IF(I20="-", "-", IF(L20="-", "-", IF(ABS(L20)=0, "-", ROUND(100*(I20-L20)/ABS(L20),10)))) -> -
D21: 麦わら | M21: =IF(G21="-", "-", IF(J21="-", "-", IF(ABS(J21)=0, "-", ROUND(100*(G21-J21)/ABS(J21),10)))) -> - | N21: =IF(H21="-", "-", IF(K21="-", "-", IF(ABS(K21)=0, "-", ROUND(100*(H21-K21)/ABS(K21),10)))) -> - | O21: =IF(I21="-", "-", IF(L21="-", "-", IF(ABS(L21)=0, "-", ROUND(100*(I21-L21)/ABS(L21),10)))) -> -
D22: 小計 | N22: =IF(H22="-", "-", IF(K22="-", "-", IF(ABS(K22)=0, "-", ROUND(100*(H22-K22)/ABS(K22),10)))) -> -
C23: 自家用 | D23: 規格外Ｂ | M23: =IF(G23="-", "-", IF(J23="-", "-", IF(ABS(J23)=0, "-", ROUND(100*(G23-J23)/ABS(J23),10)))) -> - | N23: =IF(H23="-", "-", IF(K23="-", "-", IF(ABS(K23)=0, "-", ROUND(100*(H23-K23)/ABS(K23),10)))) -> - | O23: =IF(I23="-", "-", IF(L23="-", "-", IF(ABS(L23)=0, "-", ROUND(100*(I23-L23)/ABS(L23),10)))) -> -
D24: 規格外Ｃ | M24: =IF(G24="-", "-", IF(J24="-", "-", IF(ABS(J24)=0, "-", ROUND(100*(G24-J24)/ABS(J24),10)))) -> - | N24: =IF(H24="-", "-", IF(K24="-", "-", IF(ABS(K24)=0, "-", ROUND(100*(H24-K24)/ABS(K24),10)))) -> - | O24: =IF(I24="-", "-", IF(L24="-", "-", IF(ABS(L24)=0, "-", ROUND(100*(I24-L24)/ABS(L24),10)))) -> -
D25: くず麦 | M25: =IF(G25="-", "-", IF(J25="-", "-", IF(ABS(J25)=0, "-", ROUND(100*(G25-J25)/ABS(J25),10)))) -> - | N25: =IF(H25="-", "-", IF(K25="-", "-", IF(ABS(K25)=0, "-", ROUND(100*(H25-K25)/ABS(K25),10)))) -> - | O25: =IF(I25="-", "-", IF(L25="-", "-", IF(ABS(L25)=0, "-", ROUND(100*(I25-L25)/ABS(L25),10)))) -> -
D26: 麦わら | M26: =IF(G26="-", "-", IF(J26="-", "-", IF(ABS(J26)=0, "-", ROUND(100*(G26-J26)/ABS(J26),10)))) -> - | N26: =IF(H26="-", "-", IF(K26="-", "-", IF(ABS(K26)=0, "-", ROUND(100*(H26-K26)/ABS(K26),10)))) -> - | O26: =IF(I26="-", "-", IF(L26="-", "-", IF(ABS(L26)=0, "-", ROUND(100*(I26-L26)/ABS(L26),10)))) -> -
E27: 無評価 | M27: =IF(G27="-", "-", IF(J27="-", "-", IF(ABS(J27)=0, "-", ROUND(100*(G27-J27)/ABS(J27),10)))) -> -
D28: 小計 | N28: =IF(H28="-", "-", IF(K28="-", "-", IF(ABS(K28)=0, "-", ROUND(100*(H28-K28)/ABS(K28),10)))) -> -
C29: 合計 | N29: =IF(H29="-", "-", IF(K29="-", "-", IF(ABS(K29)=0, "-", ROUND(100*(H29-K29)/ABS(K29),10)))) -> -
A30: ビール麦の販売内訳 | B30: 主産物 | C30: 販売用 | D30: １ 等 | M30: =IF(G30="-", "-", IF(J30="-", "-", IF(ABS(J30)=0, "-", ROUND(100*(G30-J30)/ABS(J30),10)))) -> - | N30: =IF(H30="-", "-", IF(K30="-", "-", IF(ABS(K30)=0, "-", ROUND(100*(H30-K30)/ABS(K30),10)))) -> - | O30: =IF(I30="-", "-", IF(L30="-", "-", IF(ABS(L30)=0, "-", ROUND(100*(I30-L30)/ABS(L30),10)))) -> -
D31: ２ 等 | M31: =IF(G31="-", "-", IF(J31="-", "-", IF(ABS(J31)=0, "-", ROUND(100*(G31-J31)/ABS(J31),10)))) -> - | N31: =IF(H31="-", "-", IF(K31="-", "-", IF(ABS(K31)=0, "-", ROUND(100*(H31-K31)/ABS(K31),10)))) -> - | O31: =IF(I31="-", "-", IF(L31="-", "-", IF(ABS(L31)=0, "-", ROUND(100*(I31-L31)/ABS(L31),10)))) -> -
D32: 等外上 | M32: =IF(G32="-", "-", IF(J32="-", "-", IF(ABS(J32)=0, "-", ROUND(100*(G32-J32)/ABS(J32),10)))) -> - | N32: =IF(H32="-", "-", IF(K32="-", "-", IF(ABS(K32)=0, "-", ROUND(100*(H32-K32)/ABS(K32),10)))) -> - | O32: =IF(I32="-", "-", IF(L32="-", "-", IF(ABS(L32)=0, "-", ROUND(100*(I32-L32)/ABS(L32),10)))) -> -
D33: 小計 | M33: =IF(G33="-", "-", IF(J33="-", "-", IF(ABS(J33)=0, "-", ROUND(100*(G33-J33)/ABS(J33),10)))) -> - | N33: =IF(H33="-", "-", IF(K33="-", "-", IF(ABS(K33)=0, "-", ROUND(100*(H33-K33)/ABS(K33),10)))) -> - | O33: =IF(I33="-", "-", IF(L33="-", "-", IF(ABS(L33)=0, "-", ROUND(100*(I33-L33)/ABS(L33),10)))) -> -
C34: 自家用 | D34: 食用 | M34: =IF(G34="-", "-", IF(J34="-", "-", IF(ABS(J34)=0, "-", ROUND(100*(G34-J34)/ABS(J34),10)))) -> - | N34: =IF(H34="-", "-", IF(K34="-", "-", IF(ABS(K34)=0, "-", ROUND(100*(H34-K34)/ABS(K34),10)))) -> - | O34: =IF(I34="-", "-", IF(L34="-", "-", IF(ABS(L34)=0, "-", ROUND(100*(I34-L34)/ABS(L34),10)))) -> -
D35: 種子用 | M35: =IF(G35="-", "-", IF(J35="-", "-", IF(ABS(J35)=0, "-", ROUND(100*(G35-J35)/ABS(J35),10)))) -> - | N35: =IF(H35="-", "-", IF(K35="-", "-", IF(ABS(K35)=0, "-", ROUND(100*(H35-K35)/ABS(K35),10)))) -> - | O35: =IF(I35="-", "-", IF(L35="-", "-", IF(ABS(L35)=0, "-", ROUND(100*(I35-L35)/ABS(L35),10)))) -> -
D36: その他 | M36: =IF(G36="-", "-", IF(J36="-", "-", IF(ABS(J36)=0, "-", ROUND(100*(G36-J36)/ABS(J36),10)))) -> - | N36: =IF(H36="-", "-", IF(K36="-", "-", IF(ABS(K36)=0, "-", ROUND(100*(H36-K36)/ABS(K36),10)))) -> - | O36: =IF(I36="-", "-", IF(L36="-", "-", IF(ABS(L36)=0, "-", ROUND(100*(I36-L36)/ABS(L36),10)))) -> -
D37: 小計 | M37: =IF(G37="-", "-", IF(J37="-", "-", IF(ABS(J37)=0, "-", ROUND(100*(G37-J37)/ABS(J37),10)))) -> - | N37: =IF(H37="-", "-", IF(K37="-", "-", IF(ABS(K37)=0, "-", ROUND(100*(H37-K37)/ABS(K37),10)))) -> - | O37: =IF(I37="-", "-", IF(L37="-", "-", IF(ABS(L37)=0, "-", ROUND(100*(I37-L37)/ABS(L37),10)))) -> -
C38: 合計 | M38: =IF(G38="-", "-", IF(J38="-", "-", IF(ABS(J38)=0, "-", ROUND(100*(G38-J38)/ABS(J38),10)))) -> - | N38: =IF(H38="-", "-", IF(K38="-", "-", IF(ABS(K38)=0, "-", ROUND(100*(H38-K38)/ABS(K38),10)))) -> - | O38: =IF(I38="-", "-", IF(L38="-", "-", IF(ABS(L38)=0, "-", ROUND(100*(I38-L38)/ABS(L38),10)))) -> -

Sheet No.5 (2)
A1: =No.1!A1&"年産 麦類・大豆・そば・なたね・畑作物生産費統計（個別経営体）" -> 2019年産 麦類・大豆・そば・なたね・畑作物生産費統計（個別経営体） | M1: センサス番号
A2: 個別結果検討表 №５ | M2: =IF(No.1!O2="","",No.1!O2)
A4: 【生産物の処分内訳（10ａ当たり）】
G5: =No.1!H5 -> 19 | J5: =G5-1 -> 18 | M5: 増 減 率 | P5: 備考欄
G6: 数量 | H6: 価額 | I6: 単価 | J6: 数量 | K6: 価額 | L6: 単価 | M6: 数量 | N6: 価額 | O6: 単価
G7: （kg） | H7: （円） | I7: （円） | J7: （kg） | K7: （円） | L7: （円） | M7: （％） | N7: （％） | O7: （％）
A8: 大豆 | B8: 主産物 | C8: 販売用 | D8: １等 | M8: =IF(G8="-", "-", IF(J8="-", "-", IF(ABS(J8)=0, "-", ROUND(100*(G8-J8)/ABS(J8),10)))) -> - | N8: =IF(H8="-", "-", IF(K8="-", "-", IF(ABS(K8)=0, "-", ROUND(100*(H8-K8)/ABS(K8),10)))) -> - | O8: =IF(I8="-", "-", IF(L8="-", "-", IF(ABS(L8)=0, "-", ROUND(100*(I8-L8)/ABS(L8),10)))) -> -
D9: ２等 | M9: =IF(G9="-", "-", IF(J9="-", "-", IF(ABS(J9)=0, "-", ROUND(100*(G9-J9)/ABS(J9),10)))) -> - | N9: =IF(H9="-", "-", IF(K9="-", "-", IF(ABS(K9)=0, "-", ROUND(100*(H9-K9)/ABS(K9),10)))) -> - | O9: =IF(I9="-", "-", IF(L9="-", "-", IF(ABS(L9)=0, "-", ROUND(100*(I9-L9)/ABS(L9),10)))) -> -
D10: ３等・規格外 | M10: =IF(G10="-", "-", IF(J10="-", "-", IF(ABS(J10)=0, "-", ROUND(100*(G10-J10)/ABS(J10),10)))) -> - | N10: =IF(H10="-", "-", IF(K10="-", "-", IF(ABS(K10)=0, "-", ROUND(100*(H10-K10)/ABS(K10),10)))) -> - | O10: =IF(I10="-", "-", IF(L10="-", "-", IF(ABS(L10)=0, "-", ROUND(100*(I10-L10)/ABS(L10),10)))) -> -
D11: 特定加工用 | M11: =IF(G11="-", "-", IF(J11="-", "-", IF(ABS(J11)=0, "-", ROUND(100*(G11-J11)/ABS(J11),10)))) -> - | N11: =IF(H11="-", "-", IF(K11="-", "-", IF(ABS(K11)=0, "-", ROUND(100*(H11-K11)/ABS(K11),10)))) -> - | O11: =IF(I11="-", "-", IF(L11="-", "-", IF(ABS(L11)=0, "-", ROUND(100*(I11-L11)/ABS(L11),10)))) -> -
D12: その他 | M12: =IF(G12="-", "-", IF(J12="-", "-", IF(ABS(J12)=0, "-", ROUND(100*(G12-J12)/ABS(J12),10)))) -> - | N12: =IF(H12="-", "-", IF(K12="-", "-", IF(ABS(K12)=0, "-", ROUND(100*(H12-K12)/ABS(K12),10)))) -> - | O12: =IF(I12="-", "-", IF(L12="-", "-", IF(ABS(L12)=0, "-", ROUND(100*(I12-L12)/ABS(L12),10)))) -> -
D13: 小計 | M13: =IF(G13="-", "-", IF(J13="-", "-", IF(ABS(J13)=0, "-", ROUND(100*(G13-J13)/ABS(J13),10)))) -> - | N13: =IF(H13="-", "-", IF(K13="-", "-", IF(ABS(K13)=0, "-", ROUND(100*(H13-K13)/ABS(K13),10)))) -> - | O13: =IF(I13="-", "-", IF(L13="-", "-", IF(ABS(L13)=0, "-", ROUND(100*(I13-L13)/ABS(L13),10)))) -> -
C14: 自家用 | D14: 食用 | M14: =IF(G14="-", "-", IF(J14="-", "-", IF(ABS(J14)=0, "-", ROUND(100*(G14-J14)/ABS(J14),10)))) -> - | N14: =IF(H14="-", "-", IF(K14="-", "-", IF(ABS(K14)=0, "-", ROUND(100*(H14-K14)/ABS(K14),10)))) -> - | O14: =IF(I14="-", "-", IF(L14="-", "-", IF(ABS(L14)=0, "-", ROUND(100*(I14-L14)/ABS(L14),10)))) -> -
D15: 種子用 | M15: =IF(G15="-", "-", IF(J15="-", "-", IF(ABS(J15)=0, "-", ROUND(100*(G15-J15)/ABS(J15),10)))) -> - | N15: =IF(H15="-", "-", IF(K15="-", "-", IF(ABS(K15)=0, "-", ROUND(100*(H15-K15)/ABS(K15),10)))) -> - | O15: =IF(I15="-", "-", IF(L15="-", "-", IF(ABS(L15)=0, "-", ROUND(100*(I15-L15)/ABS(L15),10)))) -> -
D16: その他 | M16: =IF(G16="-", "-", IF(J16="-", "-", IF(ABS(J16)=0, "-", ROUND(100*(G16-J16)/ABS(J16),10)))) -> - | N16: =IF(H16="-", "-", IF(K16="-", "-", IF(ABS(K16)=0, "-", ROUND(100*(H16-K16)/ABS(K16),10)))) -> - | O16: =IF(I16="-", "-", IF(L16="-", "-", IF(ABS(L16)=0, "-", ROUND(100*(I16-L16)/ABS(L16),10)))) -> -
D17: 小計 | M17: =IF(G17="-", "-", IF(J17="-", "-", IF(ABS(J17)=0, "-", ROUND(100*(G17-J17)/ABS(J17),10)))) -> - | N17: =IF(H17="-", "-", IF(K17="-", "-", IF(ABS(K17)=0, "-", ROUND(100*(H17-K17)/ABS(K17),10)))) -> - | O17: =IF(I17="-", "-", IF(L17="-", "-", IF(ABS(L17)=0, "-", ROUND(100*(I17-L17)/ABS(L17),10)))) -> -
C18: 合計 | M18: =IF(G18="-", "-", IF(J18="-", "-", IF(ABS(J18)=0, "-", ROUND(100*(G18-J18)/ABS(J18),10)))) -> - | N18: =IF(H18="-", "-", IF(K18="-", "-", IF(ABS(K18)=0, "-", ROUND(100*(H18-K18)/ABS(K18),10)))) -> - | O18: =IF(I18="-", "-", IF(L18="-", "-", IF(ABS(L18)=0, "-", ROUND(100*(I18-L18)/ABS(L18),10)))) -> -
B19: 副産物 | C19: 販売用 | M19: =IF(G19="-", "-", IF(J19="-", "-", IF(ABS(J19)=0, "-", ROUND(100*(G19-J19)/ABS(J19),10)))) -> - | N19: =IF(H19="-", "-", IF(K19="-", "-", IF(ABS(K19)=0, "-", ROUND(100*(H19-K19)/ABS(K19),10)))) -> - | O19: =IF(I19="-", "-", IF(L19="-", "-", IF(ABS(L19)=0, "-", ROUND(100*(I19-L19)/ABS(L19),10)))) -> -
C20: 自家用 | M20: =IF(G20="-", "-", IF(J20="-", "-", IF(ABS(J20)=0, "-", ROUND(100*(G20-J20)/ABS(J20),10)))) -> - | N20: =IF(H20="-", "-", IF(K20="-", "-", IF(ABS(K20)=0, "-", ROUND(100*(H20-K20)/ABS(K20),10)))) -> - | O20: =IF(I20="-", "-", IF(L20="-", "-", IF(ABS(L20)=0, "-", ROUND(100*(I20-L20)/ABS(L20),10)))) -> -
C21: 計 | M21: =IF(G21="-", "-", IF(J21="-", "-", IF(ABS(J21)=0, "-", ROUND(100*(G21-J21)/ABS(J21),10)))) -> - | N21: =IF(H21="-", "-", IF(K21="-", "-", IF(ABS(K21)=0, "-", ROUND(100*(H21-K21)/ABS(K21),10)))) -> - | O21: =IF(I21="-", "-", IF(L21="-", "-", IF(ABS(L21)=0, "-", ROUND(100*(I21-L21)/ABS(L21),10)))) -> -
G23: =G5 -> 19 | J23: =J5 -> 18 | M23: 増 減 率 | P23: 備考欄
G24: 数量 | H24: 価額 | I24: 単価 | J24: 数量 | K24: 価額 | L24: 単価 | M24: 数量 | N24: 価額 | O24: 単価
G25: （kg） | H25: （円） | I25: （円） | J25: （kg） | K25: （円） | L25: （円） | M25: （％） | N25: （％） | O25: （％）
A26: そば | B26: 主産物 | C26: 販売用 | D26: １等 | M26: =IF(G26="-", "-", IF(J26="-", "-", IF(ABS(J26)=0, "-", ROUND(100*(G26-J26)/ABS(J26),10)))) -> - | N26: =IF(H26="-", "-", IF(K26="-", "-", IF(ABS(K26)=0, "-", ROUND(100*(H26-K26)/ABS(K26),10)))) -> - | O26: =IF(I26="-", "-", IF(L26="-", "-", IF(ABS(L26)=0, "-", ROUND(100*(I26-L26)/ABS(L26),10)))) -> -
D27: ２等 | M27: =IF(G27="-", "-", IF(J27="-", "-", IF(ABS(J27)=0, "-", ROUND(100*(G27-J27)/ABS(J27),10)))) -> - | N27: =IF(H27="-", "-", IF(K27="-", "-", IF(ABS(K27)=0, "-", ROUND(100*(H27-K27)/ABS(K27),10)))) -> - | O27: =IF(I27="-", "-", IF(L27="-", "-", IF(ABS(L27)=0, "-", ROUND(100*(I27-L27)/ABS(L27),10)))) -> -
D28: 規格外 | M28: =IF(G28="-", "-", IF(J28="-", "-", IF(ABS(J28)=0, "-", ROUND(100*(G28-J28)/ABS(J28),10)))) -> - | N28: =IF(H28="-", "-", IF(K28="-", "-", IF(ABS(K28)=0, "-", ROUND(100*(H28-K28)/ABS(K28),10)))) -> - | O28: =IF(I28="-", "-", IF(L28="-", "-", IF(ABS(L28)=0, "-", ROUND(100*(I28-L28)/ABS(L28),10)))) -> -
D29: その他 | M29: =IF(G29="-", "-", IF(J29="-", "-", IF(ABS(J29)=0, "-", ROUND(100*(G29-J29)/ABS(J29),10)))) -> - | N29: =IF(H29="-", "-", IF(K29="-", "-", IF(ABS(K29)=0, "-", ROUND(100*(H29-K29)/ABS(K29),10)))) -> - | O29: =IF(I29="-", "-", IF(L29="-", "-", IF(ABS(L29)=0, "-", ROUND(100*(I29-L29)/ABS(L29),10)))) -> -
D30: 小計 | M30: =IF(G30="-", "-", IF(J30="-", "-", IF(ABS(J30)=0, "-", ROUND(100*(G30-J30)/ABS(J30),10)))) -> - | N30: =IF(H30="-", "-", IF(K30="-", "-", IF(ABS(K30)=0, "-", ROUND(100*(H30-K30)/ABS(K30),10)))) -> - | O30: =IF(I30="-", "-", IF(L30="-", "-", IF(ABS(L30)=0, "-", ROUND(100*(I30-L30)/ABS(L30),10)))) -> -
C31: 自家用 | D31: 食用 | M31: =IF(G31="-", "-", IF(J31="-", "-", IF(ABS(J31)=0, "-", ROUND(100*(G31-J31)/ABS(J31),10)))) -> - | N31: =IF(H31="-", "-", IF(K31="-", "-", IF(ABS(K31)=0, "-", ROUND(100*(H31-K31)/ABS(K31),10)))) -> - | O31: =IF(I31="-", "-", IF(L31="-", "-", IF(ABS(L31)=0, "-", ROUND(100*(I31-L31)/ABS(L31),10)))) -> -
D32: 種子用 | M32: =IF(G32="-", "-", IF(J32="-", "-", IF(ABS(J32)=0, "-", ROUND(100*(G32-J32)/ABS(J32),10)))) -> - | N32: =IF(H32="-", "-", IF(K32="-", "-", IF(ABS(K32)=0, "-", ROUND(100*(H32-K32)/ABS(K32),10)))) -> - | O32: =IF(I32="-", "-", IF(L32="-", "-", IF(ABS(L32)=0, "-", ROUND(100*(I32-L32)/ABS(L32),10)))) -> -
D33: その他 | M33: =IF(G33="-", "-", IF(J33="-", "-", IF(ABS(J33)=0, "-", ROUND(100*(G33-J33)/ABS(J33),10)))) -> - | N33: =IF(H33="-", "-", IF(K33="-", "-", IF(ABS(K33)=0, "-", ROUND(100*(H33-K33)/ABS(K33),10)))) -> - | O33: =IF(I33="-", "-", IF(L33="-", "-", IF(ABS(L33)=0, "-", ROUND(100*(I33-L33)/ABS(L33),10)))) -> -
D34: 小計 | M34: =IF(G34="-", "-", IF(J34="-", "-", IF(ABS(J34)=0, "-", ROUND(100*(G34-J34)/ABS(J34),10)))) -> - | N34: =IF(H34="-", "-", IF(K34="-", "-", IF(ABS(K34)=0, "-", ROUND(100*(H34-K34)/ABS(K34),10)))) -> - | O34: =IF(I34="-", "-", IF(L34="-", "-", IF(ABS(L34)=0, "-", ROUND(100*(I34-L34)/ABS(L34),10)))) -> -
C35: 合計 | M35: =IF(G35="-", "-", IF(J35="-", "-", IF(ABS(J35)=0, "-", ROUND(100*(G35-J35)/ABS(J35),10)))) -> - | N35: =IF(H35="-", "-", IF(K35="-", "-", IF(ABS(K35)=0, "-", ROUND(100*(H35-K35)/ABS(K35),10)))) -> - | O35: =IF(I35="-", "-", IF(L35="-", "-", IF(ABS(L35)=0, "-", ROUND(100*(I35-L35)/ABS(L35),10)))) -> -
B36: 副産物 | C36: 販売用 | M36: =IF(G36="-", "-", IF(J36="-", "-", IF(ABS(J36)=0, "-", ROUND(100*(G36-J36)/ABS(J36),10)))) -> - | N36: =IF(H36="-", "-", IF(K36="-", "-", IF(ABS(K36)=0, "-", ROUND(100*(H36-K36)/ABS(K36),10)))) -> - | O36: =IF(I36="-", "-", IF(L36="-", "-", IF(ABS(L36)=0, "-", ROUND(100*(I36-L36)/ABS(L36),10)))) -> -
C37: 自家用 | M37: =IF(G37="-", "-", IF(J37="-", "-", IF(ABS(J37)=0, "-", ROUND(100*(G37-J37)/ABS(J37),10)))) -> - | N37: =IF(H37="-", "-", IF(K37="-", "-", IF(ABS(K37)=0, "-", ROUND(100*(H37-K37)/ABS(K37),10)))) -> - | O37: =IF(I37="-", "-", IF(L37="-", "-", IF(ABS(L37)=0, "-", ROUND(100*(I37-L37)/ABS(L37),10)))) -> -
C38: 計 | M38: =IF(G38="-", "-", IF(J38="-", "-", IF(ABS(J38)=0, "-", ROUND(100*(G38-J38)/ABS(J38),10)))) -> - | N38: =IF(H38="-", "-", IF(K38="-", "-", IF(ABS(K38)=0, "-", ROUND(100*(H38-K38)/ABS(K38),10)))) -> - | O38: =IF(I38="-", "-", IF(L38="-", "-", IF(ABS(L38)=0, "-", ROUND(100*(I38-L38)/ABS(L38),10)))) -> -

Sheet No.5 (3)
A1: =No.1!A1&"年産 麦類・大豆・そば・なたね・畑作物生産費統計（個別経営体）" -> 2019年産 麦類・大豆・そば・なたね・畑作物生産費統計（個別経営体） | M1: センサス番号
A2: 個別結果検討表 №５ | M2: =IF(No.1!O2="","",No.1!O2)
A4: 【生産物の処分内訳（10ａ当たり）】
G5: =No.1!H5 -> 19 | J5: =G5-1 -> 18 | M5: 増 減 率 | P5: 備考欄
G6: 数量 | H6: 価額 | I6: 単価 | J6: 数量 | K6: 価額 | L6: 単価 | M6: 数量 | N6: 価額 | O6: 単価
G7: （kg） | H7: （円） | I7: （円） | J7: （kg） | K7: （円） | L7: （円） | M7: （％） | N7: （％） | O7: （％）
A8: 畑作物・なたね | B8: 主産物 | C8: 販売用 | M8: =IF(G8="-", "-", IF(J8="-", "-", IF(ABS(J8)=0, "-", ROUND(100*(G8-J8)/ABS(J8),10)))) -> - | N8: =IF(H8="-", "-", IF(K8="-", "-", IF(ABS(K8)=0, "-", ROUND(100*(H8-K8)/ABS(K8),10)))) -> - | O8: =IF(I8="-", "-", IF(L8="-", "-", IF(ABS(L8)=0, "-", ROUND(100*(I8-L8)/ABS(L8),10)))) -> -
C9: 自家用 | D9: 食用 | M9: =IF(G9="-", "-", IF(J9="-", "-", IF(ABS(J9)=0, "-", ROUND(100*(G9-J9)/ABS(J9),10)))) -> - | N9: =IF(H9="-", "-", IF(K9="-", "-", IF(ABS(K9)=0, "-", ROUND(100*(H9-K9)/ABS(K9),10)))) -> - | O9: =IF(I9="-", "-", IF(L9="-", "-", IF(ABS(L9)=0, "-", ROUND(100*(I9-L9)/ABS(L9),10)))) -> -
D10: 種苗用 | M10: =IF(G10="-", "-", IF(J10="-", "-", IF(ABS(J10)=0, "-", ROUND(100*(G10-J10)/ABS(J10),10)))) -> - | N10: =IF(H10="-", "-", IF(K10="-", "-", IF(ABS(K10)=0, "-", ROUND(100*(H10-K10)/ABS(K10),10)))) -> - | O10: =IF(I10="-", "-", IF(L10="-", "-", IF(ABS(L10)=0, "-", ROUND(100*(I10-L10)/ABS(L10),10)))) -> -
D11: その他 | M11: =IF(G11="-", "-", IF(J11="-", "-", IF(ABS(J11)=0, "-", ROUND(100*(G11-J11)/ABS(J11),10)))) -> - | N11: =IF(H11="-", "-", IF(K11="-", "-", IF(ABS(K11)=0, "-", ROUND(100*(H11-K11)/ABS(K11),10)))) -> - | O11: =IF(I11="-", "-", IF(L11="-", "-", IF(ABS(L11)=0, "-", ROUND(100*(I11-L11)/ABS(L11),10)))) -> -
D12: 小計 | M12: =IF(G12="-", "-", IF(J12="-", "-", IF(ABS(J12)=0, "-", ROUND(100*(G12-J12)/ABS(J12),10)))) -> - | N12: =IF(H12="-", "-", IF(K12="-", "-", IF(ABS(K12)=0, "-", ROUND(100*(H12-K12)/ABS(K12),10)))) -> - | O12: =IF(I12="-", "-", IF(L12="-", "-", IF(ABS(L12)=0, "-", ROUND(100*(I12-L12)/ABS(L12),10)))) -> -
C13: 合計 | M13: =IF(G13="-", "-", IF(J13="-", "-", IF(ABS(J13)=0, "-", ROUND(100*(G13-J13)/ABS(J13),10)))) -> - | N13: =IF(H13="-", "-", IF(K13="-", "-", IF(ABS(K13)=0, "-", ROUND(100*(H13-K13)/ABS(K13),10)))) -> - | O13: =IF(I13="-", "-", IF(L13="-", "-", IF(ABS(L13)=0, "-", ROUND(100*(I13-L13)/ABS(L13),10)))) -> -
B14: 副産物 | C14: 販売用 | M14: =IF(G14="-", "-", IF(J14="-", "-", IF(ABS(J14)=0, "-", ROUND(100*(G14-J14)/ABS(J14),10)))) -> - | N14: =IF(H14="-", "-", IF(K14="-", "-", IF(ABS(K14)=0, "-", ROUND(100*(H14-K14)/ABS(K14),10)))) -> - | O14: =IF(I14="-", "-", IF(L14="-", "-", IF(ABS(L14)=0, "-", ROUND(100*(I14-L14)/ABS(L14),10)))) -> -
C15: 自家用 | M15: =IF(G15="-", "-", IF(J15="-", "-", IF(ABS(J15)=0, "-", ROUND(100*(G15-J15)/ABS(J15),10)))) -> - | N15: =IF(H15="-", "-", IF(K15="-", "-", IF(ABS(K15)=0, "-", ROUND(100*(H15-K15)/ABS(K15),10)))) -> - | O15: =IF(I15="-", "-", IF(L15="-", "-", IF(ABS(L15)=0, "-", ROUND(100*(I15-L15)/ABS(L15),10)))) -> -
C16: 計 | M16: =IF(G16="-", "-", IF(J16="-", "-", IF(ABS(J16)=0, "-", ROUND(100*(G16-J16)/ABS(J16),10)))) -> - | N16: =IF(H16="-", "-", IF(K16="-", "-", IF(ABS(K16)=0, "-", ROUND(100*(H16-K16)/ABS(K16),10)))) -> - | O16: =IF(I16="-", "-", IF(L16="-", "-", IF(ABS(L16)=0, "-", ROUND(100*(I16-L16)/ABS(L16),10)))) -> -
A18: 【取引糖度（てんさい、さとうきび）】
G19: =$G$5 -> 19 | H19: =$I$6 -> 単価 | I19: =$I$6 -> 単価 | J19: =$J$5 -> 18 | K19: =$I$6 -> 単価 | L19: =$I$6 -> 単価 | M19: 増減率（取引糖度は増減差） | P19: 備考欄
G20: 出荷量 | H20: 糖度換算出荷量 | I20: 取引糖度 | J20: 出荷量 | K20: 糖度換算出荷量 | L20: 取引糖度 | M20: 出荷量 | N20: 糖度換算出荷量 | O20: 取引糖度
G21: （kg） | H21: （kg） | I21: （％） | J21: （kg） | K21: （kg） | L21: （％） | M21: （％） | N21: （％） | O21: （％）
A22: てんさい・さとうきび | M22: =IF(G22="-", "-", IF(J22="-", "-", IF(ABS(J22)=0, "-", ROUND(100*(G22-J22)/ABS(J22),10)))) -> - | N22: =IF(H22="-", "-", IF(K22="-", "-", IF(ABS(K22)=0, "-", ROUND(100*(H22-K22)/ABS(K22),10)))) -> - | O22: =I22-L22 -> 0
