Workbook
Name 経費範囲: #REF!
Name 現場調査費: #REF!
Name 現調単価: #REF!
Name 合計: #REF!
Name 材料範囲: #REF!
Name 諸経費率: #REF!
Name 範囲: #REF!
Name 労務範囲: #REF!

Sheet No.1
C1: 年 農業経営統計調査 育成牛・肥育牛生産費統計 集計結果検討表 №１
F3: 集計番号 | I3: 集計名称 | S3: 集計経営体数 | W3: 集計倍率 | AB3: 都道府県等 | AG3: 規模階層 | AN3: 生産費区分
A4: 本年 | AC4: =IF(AB4<>"",DGET(リスト!A2:B71,"都道府県等",リスト!B73:B74),"") | AH4: =IF(OR(AN4=92,AN4=93),DGET(リスト!D2:E8,"規模階層",リスト!E22:E23),IF(OR(AN4=94,AN4=95,AN4=96),DGET(リスト!D11:E20,"規模階層",リスト!E22:E23),"")) | AO4: =IF(AN4<>"",DGET(リスト!D26:E31,"生産費区分",リスト!E33:E34),"")
A5: 前年
A7: 【生産費総括（調査対象畜１頭当たり）】 | AQ7: 単位：円、％
H8: 購 入 | Q8: 自 給 | Z8: 償 却 | AI8: 計
H9: 本年 | K9: 前年 | N9: 増減率 | Q9: 本年 | T9: 前年 | W9: 増減率 | Z9: 本年 | AC9: 前年 | AF9: 増減率 | AI9: 本年 | AL9: 前年 | AO9: 増減率
A10: 物財費 | N10: =IF(H10="-", "-", IF(K10="-", "-", IF(ABS(K10)=0, "-", ROUND(100*(H10-K10)/ABS(K10),10)))) -> - | W10: =IF(Q10="-", "-", IF(T10="-", "-", IF(ABS(T10)=0, "-", ROUND(100*(Q10-T10)/ABS(T10),10)))) -> - | AF10: =IF(Z10="-", "-", IF(AC10="-", "-", IF(ABS(AC10)=0, "-", ROUND(100*(Z10-AC10)/ABS(AC10),10)))) -> - | AO10: =IF(AI10="-", "-", IF(AL10="-", "-", IF(ABS(AL10)=0, "-", ROUND(100*(AI10-AL10)/ABS(AL10),10)))) -> -
B11: もと畜費 | N11: =IF(H11="-", "-", IF(K11="-", "-", IF(ABS(K11)=0, "-", ROUND(100*(H11-K11)/ABS(K11),10)))) -> - | W11: =IF(Q11="-", "-", IF(T11="-", "-", IF(ABS(T11)=0, "-", ROUND(100*(Q11-T11)/ABS(T11),10)))) -> - | AO11: =IF(AI11="-", "-", IF(AL11="-", "-", IF(ABS(AL11)=0, "-", ROUND(100*(AI11-AL11)/ABS(AL11),10)))) -> -
B12: 飼料費 | N12: =IF(H12="-", "-", IF(K12="-", "-", IF(ABS(K12)=0, "-", ROUND(100*(H12-K12)/ABS(K12),10)))) -> - | W12: =IF(Q12="-", "-", IF(T12="-", "-", IF(ABS(T12)=0, "-", ROUND(100*(Q12-T12)/ABS(T12),10)))) -> - | AO12: =IF(AI12="-", "-", IF(AL12="-", "-", IF(ABS(AL12)=0, "-", ROUND(100*(AI12-AL12)/ABS(AL12),10)))) -> -
C13: 流通飼料費 | N13: =IF(H13="-", "-", IF(K13="-", "-", IF(ABS(K13)=0, "-", ROUND(100*(H13-K13)/ABS(K13),10)))) -> - | W13: =IF(Q13="-", "-", IF(T13="-", "-", IF(ABS(T13)=0, "-", ROUND(100*(Q13-T13)/ABS(T13),10)))) -> - | AO13: =IF(AI13="-", "-", IF(AL13="-", "-", IF(ABS(AL13)=0, "-", ROUND(100*(AI13-AL13)/ABS(AL13),10)))) -> -
C14: 牧草・放牧・採草費 | W14: =IF(Q14="-", "-", IF(T14="-", "-", IF(ABS(T14)=0, "-", ROUND(100*(Q14-T14)/ABS(T14),10)))) -> - | AO14: =IF(AI14="-", "-", IF(AL14="-", "-", IF(ABS(AL14)=0, "-", ROUND(100*(AI14-AL14)/ABS(AL14),10)))) -> -
B15: 敷料費 | N15: =IF(H15="-", "-", IF(K15="-", "-", IF(ABS(K15)=0, "-", ROUND(100*(H15-K15)/ABS(K15),10)))) -> - | W15: =IF(Q15="-", "-", IF(T15="-", "-", IF(ABS(T15)=0, "-", ROUND(100*(Q15-T15)/ABS(T15),10)))) -> - | AO15: =IF(AI15="-", "-", IF(AL15="-", "-", IF(ABS(AL15)=0, "-", ROUND(100*(AI15-AL15)/ABS(AL15),10)))) -> -
B16: 光熱動力費 | N16: =IF(H16="-", "-", IF(K16="-", "-", IF(ABS(K16)=0, "-", ROUND(100*(H16-K16)/ABS(K16),10)))) -> - | W16: =IF(Q16="-", "-", IF(T16="-", "-", IF(ABS(T16)=0, "-", ROUND(100*(Q16-T16)/ABS(T16),10)))) -> - | AO16: =IF(AI16="-", "-", IF(AL16="-", "-", IF(ABS(AL16)=0, "-", ROUND(100*(AI16-AL16)/ABS(AL16),10)))) -> -
B17: その他の諸材料費 | N17: =IF(H17="-", "-", IF(K17="-", "-", IF(ABS(K17)=0, "-", ROUND(100*(H17-K17)/ABS(K17),10)))) -> - | W17: =IF(Q17="-", "-", IF(T17="-", "-", IF(ABS(T17)=0, "-", ROUND(100*(Q17-T17)/ABS(T17),10)))) -> - | AO17: =IF(AI17="-", "-", IF(AL17="-", "-", IF(ABS(AL17)=0, "-", ROUND(100*(AI17-AL17)/ABS(AL17),10)))) -> -
B18: 獣医師料及び医薬品費 | N18: =IF(H18="-", "-", IF(K18="-", "-", IF(ABS(K18)=0, "-", ROUND(100*(H18-K18)/ABS(K18),10)))) -> - | AO18: =IF(AI18="-", "-", IF(AL18="-", "-", IF(ABS(AL18)=0, "-", ROUND(100*(AI18-AL18)/ABS(AL18),10)))) -> -
B19: 賃借料及び料金 | N19: =IF(H19="-", "-", IF(K19="-", "-", IF(ABS(K19)=0, "-", ROUND(100*(H19-K19)/ABS(K19),10)))) -> - | AO19: =IF(AI19="-", "-", IF(AL19="-", "-", IF(ABS(AL19)=0, "-", ROUND(100*(AI19-AL19)/ABS(AL19),10)))) -> -
B20: 物件税･公課諸負担 | N20: =IF(H20="-", "-", IF(K20="-", "-", IF(ABS(K20)=0, "-", ROUND(100*(H20-K20)/ABS(K20),10)))) -> - | AO20: =IF(AI20="-", "-", IF(AL20="-", "-", IF(ABS(AL20)=0, "-", ROUND(100*(AI20-AL20)/ABS(AL20),10)))) -> -
B21: 建物費 | N21: =IF(H21="-", "-", IF(K21="-", "-", IF(ABS(K21)=0, "-", ROUND(100*(H21-K21)/ABS(K21),10)))) -> - | AF21: =IF(Z21="-", "-", IF(AC21="-", "-", IF(ABS(AC21)=0, "-", ROUND(100*(Z21-AC21)/ABS(AC21),10)))) -> - | AO21: =IF(AI21="-", "-", IF(AL21="-", "-", IF(ABS(AL21)=0, "-", ROUND(100*(AI21-AL21)/ABS(AL21),10)))) -> -
B22: 自動車費 | N22: =IF(H22="-", "-", IF(K22="-", "-", IF(ABS(K22)=0, "-", ROUND(100*(H22-K22)/ABS(K22),10)))) -> - | AF22: =IF(Z22="-", "-", IF(AC22="-", "-", IF(ABS(AC22)=0, "-", ROUND(100*(Z22-AC22)/ABS(AC22),10)))) -> - | AO22: =IF(AI22="-", "-", IF(AL22="-", "-", IF(ABS(AL22)=0, "-", ROUND(100*(AI22-AL22)/ABS(AL22),10)))) -> -
B23: 農機具費 | N23: =IF(H23="-", "-", IF(K23="-", "-", IF(ABS(K23)=0, "-", ROUND(100*(H23-K23)/ABS(K23),10)))) -> - | AF23: =IF(Z23="-", "-", IF(AC23="-", "-", IF(ABS(AC23)=0, "-", ROUND(100*(Z23-AC23)/ABS(AC23),10)))) -> - | AO23: =IF(AI23="-", "-", IF(AL23="-", "-", IF(ABS(AL23)=0, "-", ROUND(100*(AI23-AL23)/ABS(AL23),10)))) -> -
B24: 生産管理費 | N24: =IF(H24="-", "-", IF(K24="-", "-", IF(ABS(K24)=0, "-", ROUND(100*(H24-K24)/ABS(K24),10)))) -> - | AF24: =IF(Z24="-", "-", IF(AC24="-", "-", IF(ABS(AC24)=0, "-", ROUND(100*(Z24-AC24)/ABS(AC24),10)))) -> - | AO24: =IF(AI24="-", "-", IF(AL24="-", "-", IF(ABS(AL24)=0, "-", ROUND(100*(AI24-AL24)/ABS(AL24),10)))) -> -
A25: 労働費 | N25: =IF(H25="-", "-", IF(K25="-", "-", IF(ABS(K25)=0, "-", ROUND(100*(H25-K25)/ABS(K25),10)))) -> - | W25: =IF(Q25="-", "-", IF(T25="-", "-", IF(ABS(T25)=0, "-", ROUND(100*(Q25-T25)/ABS(T25),10)))) -> - | AO25: =IF(AI25="-", "-", IF(AL25="-", "-", IF(ABS(AL25)=0, "-", ROUND(100*(AI25-AL25)/ABS(AL25),10)))) -> -
B26: 直接労働費 | N26: =IF(H26="-", "-", IF(K26="-", "-", IF(ABS(K26)=0, "-", ROUND(100*(H26-K26)/ABS(K26),10)))) -> - | W26: =IF(Q26="-", "-", IF(T26="-", "-", IF(ABS(T26)=0, "-", ROUND(100*(Q26-T26)/ABS(T26),10)))) -> - | AO26: =IF(AI26="-", "-", IF(AL26="-", "-", IF(ABS(AL26)=0, "-", ROUND(100*(AI26-AL26)/ABS(AL26),10)))) -> -
B27: 間接労働費 | N27: =IF(H27="-", "-", IF(K27="-", "-", IF(ABS(K27)=0, "-", ROUND(100*(H27-K27)/ABS(K27),10)))) -> - | W27: =IF(Q27="-", "-", IF(T27="-", "-", IF(ABS(T27)=0, "-", ROUND(100*(Q27-T27)/ABS(T27),10)))) -> - | AO27: =IF(AI27="-", "-", IF(AL27="-", "-", IF(ABS(AL27)=0, "-", ROUND(100*(AI27-AL27)/ABS(AL27),10)))) -> -
C28: 自給牧草労働費 | N28: =IF(H28="-", "-", IF(K28="-", "-", IF(ABS(K28)=0, "-", ROUND(100*(H28-K28)/ABS(K28),10)))) -> - | W28: =IF(Q28="-", "-", IF(T28="-", "-", IF(ABS(T28)=0, "-", ROUND(100*(Q28-T28)/ABS(T28),10)))) -> - | AO28: =IF(AI28="-", "-", IF(AL28="-", "-", IF(ABS(AL28)=0, "-", ROUND(100*(AI28-AL28)/ABS(AL28),10)))) -> -
A29: 費用合計 | N29: =IF(H29="-", "-", IF(K29="-", "-", IF(ABS(K29)=0, "-", ROUND(100*(H29-K29)/ABS(K29),10)))) -> - | W29: =IF(Q29="-", "-", IF(T29="-", "-", IF(ABS(T29)=0, "-", ROUND(100*(Q29-T29)/ABS(T29),10)))) -> - | AF29: =IF(Z29="-", "-", IF(AC29="-", "-", IF(ABS(AC29)=0, "-", ROUND(100*(Z29-AC29)/ABS(AC29),10)))) -> - | AO29: =IF(AI29="-", "-", IF(AL29="-", "-", IF(ABS(AL29)=0, "-", ROUND(100*(AI29-AL29)/ABS(AL29),10)))) -> -
A30: 副産物価額 | AO30: =IF(AI30="-", "-", IF(AL30="-", "-", IF(ABS(AL30)=0, "-", ROUND(100*(AI30-AL30)/ABS(AL30),10)))) -> -
A31: 生産費 | AO31: =IF(AI31="-", "-", IF(AL31="-", "-", IF(ABS(AL31)=0, "-", ROUND(100*(AI31-AL31)/ABS(AL31),10)))) -> -
A32: 支払利子 | AO32: =IF(AI32="-", "-", IF(AL32="-", "-", IF(ABS(AL32)=0, "-", ROUND(100*(AI32-AL32)/ABS(AL32),10)))) -> -
A33: 支払地代 | AO33: =IF(AI33="-", "-", IF(AL33="-", "-", IF(ABS(AL33)=0, "-", ROUND(100*(AI33-AL33)/ABS(AL33),10)))) -> -
A34: 利子･地代算入生産費 | AO34: =IF(AI34="-", "-", IF(AL34="-", "-", IF(ABS(AL34)=0, "-", ROUND(100*(AI34-AL34)/ABS(AL34),10)))) -> -
A35: 自己資本利子 | AO35: =IF(AI35="-", "-", IF(AL35="-", "-", IF(ABS(AL35)=0, "-", ROUND(100*(AI35-AL35)/ABS(AL35),10)))) -> -
A36: 自作地地代 | AO36: =IF(AI36="-", "-", IF(AL36="-", "-", IF(ABS(AL36)=0, "-", ROUND(100*(AI36-AL36)/ABS(AL36),10)))) -> -
A37: 全算入生産費 | AO37: =IF(AI37="-", "-", IF(AL37="-", "-", IF(ABS(AL37)=0, "-", ROUND(100*(AI37-AL37)/ABS(AL37),10)))) -> -

Sheet No.2
A1: =IF(No.1!A1="","",No.1!A1) | C1: 年 農業経営統計調査 育成牛・肥育牛生産費統計 集計結果検討表 №２
F3: 集計番号 | I3: 集計名称 | T3: 都道府県等 | Y3: 規模階層 | AF3: 生産費区分
A4: 本年 | F4: =IF(No.1!F4="","",No.1!F4) | I4: =IF(No.1!I4="","",No.1!I4) | T4: =IF(No.1!AB4="","",No.1!AB4) | U4: =IF(No.1!AC4="","",No.1!AC4) | Y4: =IF(No.1!AG4="","",No.1!AG4) | Z4: =IF(No.1!AH4="","",No.1!AH4) | AF4: =IF(No.1!AN4="","",No.1!AN4) | AG4: =IF(No.1!AO4="","",No.1!AO4)
A5: 前年 | F5: =IF(No.1!F5="","",No.1!F5) | I5: =IF(No.1!I5="","",No.1!I5)
A7: 【生産費総括（肥育牛生体100kg当たり）】 | AQ7: 単位：円、％
H8: 購 入 | Q8: 自 給 | Z8: 償 却 | AI8: 計
H9: 本年 | K9: 前年 | N9: 増減率 | Q9: 本年 | T9: 前年 | W9: 増減率 | Z9: 本年 | AC9: 前年 | AF9: 増減率 | AI9: 本年 | AL9: 前年 | AO9: 増減率
A10: 物財費 | N10: =IF(H10="-", "-", IF(K10="-", "-", IF(ABS(K10)=0, "-", ROUND(100*(H10-K10)/ABS(K10),10)))) -> - | W10: =IF(Q10="-", "-", IF(T10="-", "-", IF(ABS(T10)=0, "-", ROUND(100*(Q10-T10)/ABS(T10),10)))) -> - | AF10: =IF(Z10="-", "-", IF(AC10="-", "-", IF(ABS(AC10)=0, "-", ROUND(100*(Z10-AC10)/ABS(AC10),10)))) -> - | AO10: =IF(AI10="-", "-", IF(AL10="-", "-", IF(ABS(AL10)=0, "-", ROUND(100*(AI10-AL10)/ABS(AL10),10)))) -> -
B11: もと畜費 | N11: =IF(H11="-", "-", IF(K11="-", "-", IF(ABS(K11)=0, "-", ROUND(100*(H11-K11)/ABS(K11),10)))) -> - | W11: =IF(Q11="-", "-", IF(T11="-", "-", IF(ABS(T11)=0, "-", ROUND(100*(Q11-T11)/ABS(T11),10)))) -> - | AO11: =IF(AI11="-", "-", IF(AL11="-", "-", IF(ABS(AL11)=0, "-", ROUND(100*(AI11-AL11)/ABS(AL11),10)))) -> -
B12: 飼料費 | N12: =IF(H12="-", "-", IF(K12="-", "-", IF(ABS(K12)=0, "-", ROUND(100*(H12-K12)/ABS(K12),10)))) -> - | W12: =IF(Q12="-", "-", IF(T12="-", "-", IF(ABS(T12)=0, "-", ROUND(100*(Q12-T12)/ABS(T12),10)))) -> - | AO12: =IF(AI12="-", "-", IF(AL12="-", "-", IF(ABS(AL12)=0, "-", ROUND(100*(AI12-AL12)/ABS(AL12),10)))) -> -
C13: 流通飼料費 | N13: =IF(H13="-", "-", IF(K13="-", "-", IF(ABS(K13)=0, "-", ROUND(100*(H13-K13)/ABS(K13),10)))) -> - | W13: =IF(Q13="-", "-", IF(T13="-", "-", IF(ABS(T13)=0, "-", ROUND(100*(Q13-T13)/ABS(T13),10)))) -> - | AO13: =IF(AI13="-", "-", IF(AL13="-", "-", IF(ABS(AL13)=0, "-", ROUND(100*(AI13-AL13)/ABS(AL13),10)))) -> -
C14: 牧草・放牧・採草費 | W14: =IF(Q14="-", "-", IF(T14="-", "-", IF(ABS(T14)=0, "-", ROUND(100*(Q14-T14)/ABS(T14),10)))) -> - | AO14: =IF(AI14="-", "-", IF(AL14="-", "-", IF(ABS(AL14)=0, "-", ROUND(100*(AI14-AL14)/ABS(AL14),10)))) -> -
B15: 敷料費 | N15: =IF(H15="-", "-", IF(K15="-", "-", IF(ABS(K15)=0, "-", ROUND(100*(H15-K15)/ABS(K15),10)))) -> - | W15: =IF(Q15="-", "-", IF(T15="-", "-", IF(ABS(T15)=0, "-", ROUND(100*(Q15-T15)/ABS(T15),10)))) -> - | AO15: =IF(AI15="-", "-", IF(AL15="-", "-", IF(ABS(AL15)=0, "-", ROUND(100*(AI15-AL15)/ABS(AL15),10)))) -> -
B16: 光熱動力費 | N16: =IF(H16="-", "-", IF(K16="-", "-", IF(ABS(K16)=0, "-", ROUND(100*(H16-K16)/ABS(K16),10)))) -> - | W16: =IF(Q16="-", "-", IF(T16="-", "-", IF(ABS(T16)=0, "-", ROUND(100*(Q16-T16)/ABS(T16),10)))) -> - | AO16: =IF(AI16="-", "-", IF(AL16="-", "-", IF(ABS(AL16)=0, "-", ROUND(100*(AI16-AL16)/ABS(AL16),10)))) -> -
B17: その他の諸材料費 | N17: =IF(H17="-", "-", IF(K17="-", "-", IF(ABS(K17)=0, "-", ROUND(100*(H17-K17)/ABS(K17),10)))) -> - | W17: =IF(Q17="-", "-", IF(T17="-", "-", IF(ABS(T17)=0, "-", ROUND(100*(Q17-T17)/ABS(T17),10)))) -> - | AO17: =IF(AI17="-", "-", IF(AL17="-", "-", IF(ABS(AL17)=0, "-", ROUND(100*(AI17-AL17)/ABS(AL17),10)))) -> -
B18: 獣医師料及び医薬品費 | N18: =IF(H18="-", "-", IF(K18="-", "-", IF(ABS(K18)=0, "-", ROUND(100*(H18-K18)/ABS(K18),10)))) -> - | AO18: =IF(AI18="-", "-", IF(AL18="-", "-", IF(ABS(AL18)=0, "-", ROUND(100*(AI18-AL18)/ABS(AL18),10)))) -> -
B19: 賃借料及び料金 | N19: =IF(H19="-", "-", IF(K19="-", "-", IF(ABS(K19)=0, "-", ROUND(100*(H19-K19)/ABS(K19),10)))) -> - | AO19: =IF(AI19="-", "-", IF(AL19="-", "-", IF(ABS(AL19)=0, "-", ROUND(100*(AI19-AL19)/ABS(AL19),10)))) -> -
B20: 物件税･公課諸負担 | N20: =IF(H20="-", "-", IF(K20="-", "-", IF(ABS(K20)=0, "-", ROUND(100*(H20-K20)/ABS(K20),10)))) -> - | AO20: =IF(AI20="-", "-", IF(AL20="-", "-", IF(ABS(AL20)=0, "-", ROUND(100*(AI20-AL20)/ABS(AL20),10)))) -> -
B21: 建物費 | N21: =IF(H21="-", "-", IF(K21="-", "-", IF(ABS(K21)=0, "-", ROUND(100*(H21-K21)/ABS(K21),10)))) -> - | AF21: =IF(Z21="-", "-", IF(AC21="-", "-", IF(ABS(AC21)=0, "-", ROUND(100*(Z21-AC21)/ABS(AC21),10)))) -> - | AO21: =IF(AI21="-", "-", IF(AL21="-", "-", IF(ABS(AL21)=0, "-", ROUND(100*(AI21-AL21)/ABS(AL21),10)))) -> -
B22: 自動車費 | N22: =IF(H22="-", "-", IF(K22="-", "-", IF(ABS(K22)=0, "-", ROUND(100*(H22-K22)/ABS(K22),10)))) -> - | AF22: =IF(Z22="-", "-", IF(AC22="-", "-", IF(ABS(AC22)=0, "-", ROUND(100*(Z22-AC22)/ABS(AC22),10)))) -> - | AO22: =IF(AI22="-", "-", IF(AL22="-", "-", IF(ABS(AL22)=0, "-", ROUND(100*(AI22-AL22)/ABS(AL22),10)))) -> -
B23: 農機具費 | N23: =IF(H23="-", "-", IF(K23="-", "-", IF(ABS(K23)=0, "-", ROUND(100*(H23-K23)/ABS(K23),10)))) -> - | AF23: =IF(Z23="-", "-", IF(AC23="-", "-", IF(ABS(AC23)=0, "-", ROUND(100*(Z23-AC23)/ABS(AC23),10)))) -> - | AO23: =IF(AI23="-", "-", IF(AL23="-", "-", IF(ABS(AL23)=0, "-", ROUND(100*(AI23-AL23)/ABS(AL23),10)))) -> -
B24: 生産管理費 | N24: =IF(H24="-", "-", IF(K24="-", "-", IF(ABS(K24)=0, "-", ROUND(100*(H24-K24)/ABS(K24),10)))) -> - | AF24: =IF(Z24="-", "-", IF(AC24="-", "-", IF(ABS(AC24)=0, "-", ROUND(100*(Z24-AC24)/ABS(AC24),10)))) -> - | AO24: =IF(AI24="-", "-", IF(AL24="-", "-", IF(ABS(AL24)=0, "-", ROUND(100*(AI24-AL24)/ABS(AL24),10)))) -> -
A25: 労働費 | N25: =IF(H25="-", "-", IF(K25="-", "-", IF(ABS(K25)=0, "-", ROUND(100*(H25-K25)/ABS(K25),10)))) -> - | W25: =IF(Q25="-", "-", IF(T25="-", "-", IF(ABS(T25)=0, "-", ROUND(100*(Q25-T25)/ABS(T25),10)))) -> - | AO25: =IF(AI25="-", "-", IF(AL25="-", "-", IF(ABS(AL25)=0, "-", ROUND(100*(AI25-AL25)/ABS(AL25),10)))) -> -
B26: 直接労働費 | N26: =IF(H26="-", "-", IF(K26="-", "-", IF(ABS(K26)=0, "-", ROUND(100*(H26-K26)/ABS(K26),10)))) -> - | W26: =IF(Q26="-", "-", IF(T26="-", "-", IF(ABS(T26)=0, "-", ROUND(100*(Q26-T26)/ABS(T26),10)))) -> - | AO26: =IF(AI26="-", "-", IF(AL26="-", "-", IF(ABS(AL26)=0, "-", ROUND(100*(AI26-AL26)/ABS(AL26),10)))) -> -
B27: 間接労働費 | N27: =IF(H27="-", "-", IF(K27="-", "-", IF(ABS(K27)=0, "-", ROUND(100*(H27-K27)/ABS(K27),10)))) -> - | W27: =IF(Q27="-", "-", IF(T27="-", "-", IF(ABS(T27)=0, "-", ROUND(100*(Q27-T27)/ABS(T27),10)))) -> - | AO27: =IF(AI27="-", "-", IF(AL27="-", "-", IF(ABS(AL27)=0, "-", ROUND(100*(AI27-AL27)/ABS(AL27),10)))) -> -
C28: 自給牧草労働費 | N28: =IF(H28="-", "-", IF(K28="-", "-", IF(ABS(K28)=0, "-", ROUND(100*(H28-K28)/ABS(K28),10)))) -> - | W28: =IF(Q28="-", "-", IF(T28="-", "-", IF(ABS(T28)=0, "-", ROUND(100*(Q28-T28)/ABS(T28),10)))) -> - | AO28: =IF(AI28="-", "-", IF(AL28="-", "-", IF(ABS(AL28)=0, "-", ROUND(100*(AI28-AL28)/ABS(AL28),10)))) -> -
A29: 費用合計 | N29: =IF(H29="-", "-", IF(K29="-", "-", IF(ABS(K29)=0, "-", ROUND(100*(H29-K29)/ABS(K29),10)))) -> - | W29: =IF(Q29="-", "-", IF(T29="-", "-", IF(ABS(T29)=0, "-", ROUND(100*(Q29-T29)/ABS(T29),10)))) -> - | AF29: =IF(Z29="-", "-", IF(AC29="-", "-", IF(ABS(AC29)=0, "-", ROUND(100*(Z29-AC29)/ABS(AC29),10)))) -> - | AO29: =IF(AI29="-", "-", IF(AL29="-", "-", IF(ABS(AL29)=0, "-", ROUND(100*(AI29-AL29)/ABS(AL29),10)))) -> -
A30: 副産物価額 | AO30: =IF(AI30="-", "-", IF(AL30="-", "-", IF(ABS(AL30)=0, "-", ROUND(100*(AI30-AL30)/ABS(AL30),10)))) -> -
A31: 生産費 | AO31: =IF(AI31="-", "-", IF(AL31="-", "-", IF(ABS(AL31)=0, "-", ROUND(100*(AI31-AL31)/ABS(AL31),10)))) -> -
A32: 支払利子 | AO32: =IF(AI32="-", "-", IF(AL32="-", "-", IF(ABS(AL32)=0, "-", ROUND(100*(AI32-AL32)/ABS(AL32),10)))) -> -
A33: 支払地代 | AO33: =IF(AI33="-", "-", IF(AL33="-", "-", IF(ABS(AL33)=0, "-", ROUND(100*(AI33-AL33)/ABS(AL33),10)))) -> -
A34: 利子･地代算入生産費 | AO34: =IF(AI34="-", "-", IF(AL34="-", "-", IF(ABS(AL34)=0, "-", ROUND(100*(AI34-AL34)/ABS(AL34),10)))) -> -
A35: 自己資本利子 | AO35: =IF(AI35="-", "-", IF(AL35="-", "-", IF(ABS(AL35)=0, "-", ROUND(100*(AI35-AL35)/ABS(AL35),10)))) -> -
A36: 自作地地代 | AO36: =IF(AI36="-", "-", IF(AL36="-", "-", IF(ABS(AL36)=0, "-", ROUND(100*(AI36-AL36)/ABS(AL36),10)))) -> -
A37: 全算入生産費 | AO37: =IF(AI37="-", "-", IF(AL37="-", "-", IF(ABS(AL37)=0, "-", ROUND(100*(AI37-AL37)/ABS(AL37),10)))) -> -

Sheet No.3
A1: =IF(No.1!A1="","",No.1!A1) | C1: 年 農業経営統計調査 育成牛・肥育牛生産費統計 集計結果検討表 №３
F3: 集計番号 | I3: 集計名称 | T3: 都道府県等 | Y3: 規模階層 | AF3: 生産費区分
A4: 本年 | F4: =IF(No.1!F4="","",No.1!F4) | I4: =IF(No.1!I4="","",No.1!I4) | T4: =IF(No.1!AB4="","",No.1!AB4) | U4: =IF(No.1!AC4="","",No.1!AC4) | Y4: =IF(No.1!AG4="","",No.1!AG4) | Z4: =IF(No.1!AH4="","",No.1!AH4) | AF4: =IF(No.1!AN4="","",No.1!AN4) | AG4: =IF(No.1!AO4="","",No.1!AO4)
A5: 前年 | F5: =IF(No.1!F5="","",No.1!F5) | I5: =IF(No.1!I5="","",No.1!I5)
A7: 調査対象畜１頭当たり
A8: 【家族員数及び農業就業者等】１経営体当たり | AH8: 単位：人、％ | AK8: 【資本額】 | AZ8: 単位：円、％
H9: 男 | Q9: 女 | Z9: 計 | AR9: 本年 | AU9: 前年 | AX9: 増減率
H10: 本年 | K10: 前年 | N10: 増減率 | Q10: 本年 | T10: 前年 | W10: 増減率 | Z10: 本年 | AC10: 前年 | AF10: 増減率 | AK10: 計 | AX10: =IF(AR10="-", "-", IF(AU10="-", "-", IF(ABS(AU10)=0, "-", ROUND(100*(AR10-AU10)/ABS(AU10),10)))) -> -
A11: 世帯員 | N11: =IF(H11="-", "-", IF(K11="-", "-", IF(ABS(K11)=0, "-", ROUND(100*(H11-K11)/ABS(K11),10)))) -> - | W11: =IF(Q11="-", "-", IF(T11="-", "-", IF(ABS(T11)=0, "-", ROUND(100*(Q11-T11)/ABS(T11),10)))) -> - | AF11: =IF(Z11="-", "-", IF(AC11="-", "-", IF(ABS(AC11)=0, "-", ROUND(100*(Z11-AC11)/ABS(AC11),10)))) -> - | AL11: 借入資本 | AX11: =IF(AR11="-", "-", IF(AU11="-", "-", IF(ABS(AU11)=0, "-", ROUND(100*(AR11-AU11)/ABS(AU11),10)))) -> -
B12: 家族 | N12: =IF(H12="-", "-", IF(K12="-", "-", IF(ABS(K12)=0, "-", ROUND(100*(H12-K12)/ABS(K12),10)))) -> - | W12: =IF(Q12="-", "-", IF(T12="-", "-", IF(ABS(T12)=0, "-", ROUND(100*(Q12-T12)/ABS(T12),10)))) -> - | AF12: =IF(Z12="-", "-", IF(AC12="-", "-", IF(ABS(AC12)=0, "-", ROUND(100*(Z12-AC12)/ABS(AC12),10)))) -> - | AL12: 自己資本 | AX12: =IF(AR12="-", "-", IF(AU12="-", "-", IF(ABS(AU12)=0, "-", ROUND(100*(AR12-AU12)/ABS(AU12),10)))) -> -
A13: 農業就業者 | N13: =IF(H13="-", "-", IF(K13="-", "-", IF(ABS(K13)=0, "-", ROUND(100*(H13-K13)/ABS(K13),10)))) -> - | W13: =IF(Q13="-", "-", IF(T13="-", "-", IF(ABS(T13)=0, "-", ROUND(100*(Q13-T13)/ABS(T13),10)))) -> - | AF13: =IF(Z13="-", "-", IF(AC13="-", "-", IF(ABS(AC13)=0, "-", ROUND(100*(Z13-AC13)/ABS(AC13),10)))) -> - | AK13: 資産別内訳 | AL13: 流動資本 | AX13: =IF(AR13="-", "-", IF(AU13="-", "-", IF(ABS(AU13)=0, "-", ROUND(100*(AR13-AU13)/ABS(AU13),10)))) -> -
B14: 農業専従者 | N14: =IF(H14="-", "-", IF(K14="-", "-", IF(ABS(K14)=0, "-", ROUND(100*(H14-K14)/ABS(K14),10)))) -> - | W14: =IF(Q14="-", "-", IF(T14="-", "-", IF(ABS(T14)=0, "-", ROUND(100*(Q14-T14)/ABS(T14),10)))) -> - | AF14: =IF(Z14="-", "-", IF(AC14="-", "-", IF(ABS(AC14)=0, "-", ROUND(100*(Z14-AC14)/ABS(AC14),10)))) -> - | AL14: 労賃資本 | AX14: =IF(AR14="-", "-", IF(AU14="-", "-", IF(ABS(AU14)=0, "-", ROUND(100*(AR14-AU14)/ABS(AU14),10)))) -> -
A15: 農業年雇 | N15: =IF(H15="-", "-", IF(K15="-", "-", IF(ABS(K15)=0, "-", ROUND(100*(H15-K15)/ABS(K15),10)))) -> - | W15: =IF(Q15="-", "-", IF(T15="-", "-", IF(ABS(T15)=0, "-", ROUND(100*(Q15-T15)/ABS(T15),10)))) -> - | AF15: =IF(Z15="-", "-", IF(AC15="-", "-", IF(ABS(AC15)=0, "-", ROUND(100*(Z15-AC15)/ABS(AC15),10)))) -> - | AL15: 固定資本 | AX15: =IF(AR15="-", "-", IF(AU15="-", "-", IF(ABS(AU15)=0, "-", ROUND(100*(AR15-AU15)/ABS(AU15),10)))) -> -
AM16: 建物 | AX16: =IF(AR16="-", "-", IF(AU16="-", "-", IF(ABS(AU16)=0, "-", ROUND(100*(AR16-AU16)/ABS(AU16),10)))) -> -
A17: 【経営耕地（調査開始時）】１経営体当たり | AH17: 単位：ａ、％ | AM17: 自動車 | AX17: =IF(AR17="-", "-", IF(AU17="-", "-", IF(ABS(AU17)=0, "-", ROUND(100*(AR17-AU17)/ABS(AU17),10)))) -> -
H18: 所 有 地 | Q18: 借 入 地 | Z18: 計 | AM18: 農機具 | AX18: =IF(AR18="-", "-", IF(AU18="-", "-", IF(ABS(AU18)=0, "-", ROUND(100*(AR18-AU18)/ABS(AU18),10)))) -> -
H19: 本年 | K19: 前年 | N19: 増減率 | Q19: 本年 | T19: 前年 | W19: 増減率 | Z19: 本年 | AC19: 前年 | AF19: 増減率 | AM19: 牧草関係 | AX19: =IF(AR19="-", "-", IF(AU19="-", "-", IF(ABS(AU19)=0, "-", ROUND(100*(AR19-AU19)/ABS(AU19),10)))) -> -
A20: 田 | N20: =IF(H20="-", "-", IF(K20="-", "-", IF(ABS(K20)=0, "-", ROUND(100*(H20-K20)/ABS(K20),10)))) -> - | W20: =IF(Q20="-", "-", IF(T20="-", "-", IF(ABS(T20)=0, "-", ROUND(100*(Q20-T20)/ABS(T20),10)))) -> - | AF20: =IF(Z20="-", "-", IF(AC20="-", "-", IF(ABS(AC20)=0, "-", ROUND(100*(Z20-AC20)/ABS(AC20),10)))) -> -
A21: 普通畑 | N21: =IF(H21="-", "-", IF(K21="-", "-", IF(ABS(K21)=0, "-", ROUND(100*(H21-K21)/ABS(K21),10)))) -> - | W21: =IF(Q21="-", "-", IF(T21="-", "-", IF(ABS(T21)=0, "-", ROUND(100*(Q21-T21)/ABS(T21),10)))) -> - | AF21: =IF(Z21="-", "-", IF(AC21="-", "-", IF(ABS(AC21)=0, "-", ROUND(100*(Z21-AC21)/ABS(AC21),10)))) -> - | AK21: 【資本利子】 | AZ21: 単位：円、％
A22: 樹園地 | N22: =IF(H22="-", "-", IF(K22="-", "-", IF(ABS(K22)=0, "-", ROUND(100*(H22-K22)/ABS(K22),10)))) -> - | W22: =IF(Q22="-", "-", IF(T22="-", "-", IF(ABS(T22)=0, "-", ROUND(100*(Q22-T22)/ABS(T22),10)))) -> - | AF22: =IF(Z22="-", "-", IF(AC22="-", "-", IF(ABS(AC22)=0, "-", ROUND(100*(Z22-AC22)/ABS(AC22),10)))) -> - | AR22: 本年 | AU22: 前年 | AX22: 増減率
A23: 牧草地 | N23: =IF(H23="-", "-", IF(K23="-", "-", IF(ABS(K23)=0, "-", ROUND(100*(H23-K23)/ABS(K23),10)))) -> - | W23: =IF(Q23="-", "-", IF(T23="-", "-", IF(ABS(T23)=0, "-", ROUND(100*(Q23-T23)/ABS(T23),10)))) -> - | AF23: =IF(Z23="-", "-", IF(AC23="-", "-", IF(ABS(AC23)=0, "-", ROUND(100*(Z23-AC23)/ABS(AC23),10)))) -> - | AK23: 計 | AX23: =IF(AR23="-", "-", IF(AU23="-", "-", IF(ABS(AU23)=0, "-", ROUND(100*(AR23-AU23)/ABS(AU23),10)))) -> -
A24: 計 | N24: =IF(H24="-", "-", IF(K24="-", "-", IF(ABS(K24)=0, "-", ROUND(100*(H24-K24)/ABS(K24),10)))) -> - | W24: =IF(Q24="-", "-", IF(T24="-", "-", IF(ABS(T24)=0, "-", ROUND(100*(Q24-T24)/ABS(T24),10)))) -> - | AF24: =IF(Z24="-", "-", IF(AC24="-", "-", IF(ABS(AC24)=0, "-", ROUND(100*(Z24-AC24)/ABS(AC24),10)))) -> - | AL24: 支払利子 | AX24: =IF(AR24="-", "-", IF(AU24="-", "-", IF(ABS(AU24)=0, "-", ROUND(100*(AR24-AU24)/ABS(AU24),10)))) -> -
AL25: 自己資本利子 | AX25: =IF(AR25="-", "-", IF(AU25="-", "-", IF(ABS(AU25)=0, "-", ROUND(100*(AR25-AU25)/ABS(AU25),10)))) -> -
A27: 【飼養頭数】１経営体当たり | P27: 単位：頭、％
H28: 本年 | K28: 前年 | N28: 増減率
A29: １ 月 | N29: =IF(H29="-", "-", IF(K29="-", "-", IF(ABS(K29)=0, "-", ROUND(100*(H29-K29)/ABS(K29),10)))) -> -
A30: ２ 月 | N30: =IF(H30="-", "-", IF(K30="-", "-", IF(ABS(K30)=0, "-", ROUND(100*(H30-K30)/ABS(K30),10)))) -> -
A31: ３ 月 | N31: =IF(H31="-", "-", IF(K31="-", "-", IF(ABS(K31)=0, "-", ROUND(100*(H31-K31)/ABS(K31),10)))) -> -
A32: ４ 月 | N32: =IF(H32="-", "-", IF(K32="-", "-", IF(ABS(K32)=0, "-", ROUND(100*(H32-K32)/ABS(K32),10)))) -> -
A33: ５ 月 | N33: =IF(H33="-", "-", IF(K33="-", "-", IF(ABS(K33)=0, "-", ROUND(100*(H33-K33)/ABS(K33),10)))) -> -
A34: ６ 月 | N34: =IF(H34="-", "-", IF(K34="-", "-", IF(ABS(K34)=0, "-", ROUND(100*(H34-K34)/ABS(K34),10)))) -> -
A35: ７ 月 | N35: =IF(H35="-", "-", IF(K35="-", "-", IF(ABS(K35)=0, "-", ROUND(100*(H35-K35)/ABS(K35),10)))) -> -
A36: ８ 月 | N36: =IF(H36="-", "-", IF(K36="-", "-", IF(ABS(K36)=0, "-", ROUND(100*(H36-K36)/ABS(K36),10)))) -> -
A37: ９ 月 | N37: =IF(H37="-", "-", IF(K37="-", "-", IF(ABS(K37)=0, "-", ROUND(100*(H37-K37)/ABS(K37),10)))) -> -
A38: 10 月 | N38: =IF(H38="-", "-", IF(K38="-", "-", IF(ABS(K38)=0, "-", ROUND(100*(H38-K38)/ABS(K38),10)))) -> -
A39: 11 月 | N39: =IF(H39="-", "-", IF(K39="-", "-", IF(ABS(K39)=0, "-", ROUND(100*(H39-K39)/ABS(K39),10)))) -> -
A40: 12 月 | N40: =IF(H40="-", "-", IF(K40="-", "-", IF(ABS(K40)=0, "-", ROUND(100*(H40-K40)/ABS(K40),10)))) -> -
... A42: 飼養月平均頭数 | N42: =IF(H42="-", "-", IF(K42="-", "-", IF(ABS(K42)=0, "-", ROUND(100*(H42-K42)/ABS(K42),10)))) -> -

Sheet No.4
A1: =IF(No.1!A1="","",No.1!A1) | C1: 年 農業経営統計調査 育成牛・肥育牛生産費統計 集計結果検討表 №４
F3: 集計番号 | I3: 集計名称 | T3: 都道府県等 | Y3: 規模階層 | AF3: 生産費区分
A4: 本年 | F4: =IF(No.1!F4="","",No.1!F4) | I4: =IF(No.1!I4="","",No.1!I4) | T4: =IF(No.1!AB4="","",No.1!AB4) | U4: =IF(No.1!AC4="","",No.1!AC4) | Y4: =IF(No.1!AG4="","",No.1!AG4) | Z4: =IF(No.1!AH4="","",No.1!AH4) | AF4: =IF(No.1!AN4="","",No.1!AN4) | AG4: =IF(No.1!AO4="","",No.1!AO4)
A5: 前年 | F5: =IF(No.1!F5="","",No.1!F5) | I5: =IF(No.1!I5="","",No.1!I5)
A7: 調査対象畜１頭当たり
A8: 【主産物の概要】 | AH8: 単位：頭、月、円、㎏、％ | AK8: 【〔参考１〕収益性等】 | AZ8: 単位：円、％
H9: 購 入 | Q9: 自 給 | Z9: 計 | AR9: 本年 | AU9: 前年 | AX9: 増減率
H10: 本年 | K10: 前年 | N10: 増減率 | Q10: 本年 | T10: 前年 | W10: 増減率 | Z10: 本年 | AC10: 前年 | AF10: 増減率 | AK10: 粗収益 | AX10: =IF(AR10="-", "-", IF(AU10="-", "-", IF(ABS(AU10)=0, "-", ROUND(100*(AR10-AU10)/ABS(AU10),10)))) -> -
A11: もと畜 | B11: 仕 入 | C11: 頭数 | N11: =IF(H11="-", "-", IF(K11="-", "-", IF(ABS(K11)=0, "-", ROUND(100*(H11-K11)/ABS(K11),10)))) -> - | W11: =IF(Q11="-", "-", IF(T11="-", "-", IF(ABS(T11)=0, "-", ROUND(100*(Q11-T11)/ABS(T11),10)))) -> - | AF11: =IF(Z11="-", "-", IF(AC11="-", "-", IF(ABS(AC11)=0, "-", ROUND(100*(Z11-AC11)/ABS(AC11),10)))) -> - | AK11: 生産費総額 | AX11: =IF(AR11="-", "-", IF(AU11="-", "-", IF(ABS(AU11)=0, "-", ROUND(100*(AR11-AU11)/ABS(AU11),10)))) -> -
C12: 月数 | N12: =IF(H12="-", "-", IF(K12="-", "-", IF(ABS(K12)=0, "-", ROUND(100*(H12-K12)/ABS(K12),10)))) -> - | W12: =IF(Q12="-", "-", IF(T12="-", "-", IF(ABS(T12)=0, "-", ROUND(100*(Q12-T12)/ABS(T12),10)))) -> - | AF12: =IF(Z12="-", "-", IF(AC12="-", "-", IF(ABS(AC12)=0, "-", ROUND(100*(Z12-AC12)/ABS(AC12),10)))) -> - | AK12: 利潤 | AX12: =IF(AR12="-", "-", IF(AU12="-", "-", IF(ABS(AU12)=0, "-", ROUND(100*(AR12-AU12)/ABS(AU12),10)))) -> -
C13: 評価額 | N13: =IF(H13="-", "-", IF(K13="-", "-", IF(ABS(K13)=0, "-", ROUND(100*(H13-K13)/ABS(K13),10)))) -> - | W13: =IF(Q13="-", "-", IF(T13="-", "-", IF(ABS(T13)=0, "-", ROUND(100*(Q13-T13)/ABS(T13),10)))) -> - | AF13: =IF(Z13="-", "-", IF(AC13="-", "-", IF(ABS(AC13)=0, "-", ROUND(100*(Z13-AC13)/ABS(AC13),10)))) -> - | AK13: 所得 | AX13: =IF(AR13="-", "-", IF(AU13="-", "-", IF(ABS(AU13)=0, "-", ROUND(100*(AR13-AU13)/ABS(AU13),10)))) -> -
A14: 販売 | C14: 頭数 | N14: =IF(H14="-", "-", IF(K14="-", "-", IF(ABS(K14)=0, "-", ROUND(100*(H14-K14)/ABS(K14),10)))) -> - | W14: =IF(Q14="-", "-", IF(T14="-", "-", IF(ABS(T14)=0, "-", ROUND(100*(Q14-T14)/ABS(T14),10)))) -> - | AF14: =IF(Z14="-", "-", IF(AC14="-", "-", IF(ABS(AC14)=0, "-", ROUND(100*(Z14-AC14)/ABS(AC14),10)))) -> - | AL14: １日当たり | AX14: =IF(AR14="-", "-", IF(AU14="-", "-", IF(ABS(AU14)=0, "-", ROUND(100*(AR14-AU14)/ABS(AU14),10)))) -> -
C15: 月齢 | N15: =IF(H15="-", "-", IF(K15="-", "-", IF(ABS(K15)=0, "-", ROUND(100*(H15-K15)/ABS(K15),10)))) -> - | W15: =IF(Q15="-", "-", IF(T15="-", "-", IF(ABS(T15)=0, "-", ROUND(100*(Q15-T15)/ABS(T15),10)))) -> - | AF15: =IF(Z15="-", "-", IF(AC15="-", "-", IF(ABS(AC15)=0, "-", ROUND(100*(Z15-AC15)/ABS(AC15),10)))) -> - | AK15: 家族労働報酬 | AX15: =IF(AR15="-", "-", IF(AU15="-", "-", IF(ABS(AU15)=0, "-", ROUND(100*(AR15-AU15)/ABS(AU15),10)))) -> -
C16: 生体重 | N16: =IF(H16="-", "-", IF(K16="-", "-", IF(ABS(K16)=0, "-", ROUND(100*(H16-K16)/ABS(K16),10)))) -> - | W16: =IF(Q16="-", "-", IF(T16="-", "-", IF(ABS(T16)=0, "-", ROUND(100*(Q16-T16)/ABS(T16),10)))) -> - | AF16: =IF(Z16="-", "-", IF(AC16="-", "-", IF(ABS(AC16)=0, "-", ROUND(100*(Z16-AC16)/ABS(AC16),10)))) -> - | AL16: １日当たり | AX16: =IF(AR16="-", "-", IF(AU16="-", "-", IF(ABS(AU16)=0, "-", ROUND(100*(AR16-AU16)/ABS(AU16),10)))) -> -
C17: 評価額 | N17: =IF(H17="-", "-", IF(K17="-", "-", IF(ABS(K17)=0, "-", ROUND(100*(H17-K17)/ABS(K17),10)))) -> - | W17: =IF(Q17="-", "-", IF(T17="-", "-", IF(ABS(T17)=0, "-", ROUND(100*(Q17-T17)/ABS(T17),10)))) -> - | AF17: =IF(Z17="-", "-", IF(AC17="-", "-", IF(ABS(AC17)=0, "-", ROUND(100*(Z17-AC17)/ABS(AC17),10)))) -> -
C18: 肥育・育成期間 | N18: =IF(H18="-", "-", IF(K18="-", "-", IF(ABS(K18)=0, "-", ROUND(100*(H18-K18)/ABS(K18),10)))) -> - | W18: =IF(Q18="-", "-", IF(T18="-", "-", IF(ABS(T18)=0, "-", ROUND(100*(Q18-T18)/ABS(T18),10)))) -> - | AF18: =IF(Z18="-", "-", IF(AC18="-", "-", IF(ABS(AC18)=0, "-", ROUND(100*(Z18-AC18)/ABS(AC18),10)))) -> - | AK18: 【〔参考２〕消費税】 | AZ18: 単位：円、％
A19: 死亡・とうた頭数 | N19: =IF(H19="-", "-", IF(K19="-", "-", IF(ABS(K19)=0, "-", ROUND(100*(H19-K19)/ABS(K19),10)))) -> - | W19: =IF(Q19="-", "-", IF(T19="-", "-", IF(ABS(T19)=0, "-", ROUND(100*(Q19-T19)/ABS(T19),10)))) -> - | AF19: =IF(Z19="-", "-", IF(AC19="-", "-", IF(ABS(AC19)=0, "-", ROUND(100*(Z19-AC19)/ABS(AC19),10)))) -> - | AR19: 本年 | AU19: 前年 | AX19: 増減率
A20: 注：もと畜仕入頭数、販売頭数、死亡・とうた頭数は１経営体当たり | AK20: 消費税 | AX20: =IF(AR20="-", "-", IF(AU20="-", "-", IF(ABS(AU20)=0, "-", ROUND(100*(AR20-AU20)/ABS(AU20),10)))) -> -
A22: 【販売肉用牛の品種別頭数】 | P22: 単位：頭、％ | S22: 【販売回数、延べ計算期間】
H23: 本年 | K23: 前年 | N23: 増減率 | S23: １経営体当たり | AH23: 単位：回、年、％
A24: 黒毛 | N24: =IF(H24="-", "-", IF(K24="-", "-", IF(ABS(K24)=0, "-", ROUND(100*(H24-K24)/ABS(K24),10)))) -> - | Z24: 本年 | AC24: 前年 | AF24: 増減率
A25: 褐毛 | N25: =IF(H25="-", "-", IF(K25="-", "-", IF(ABS(K25)=0, "-", ROUND(100*(H25-K25)/ABS(K25),10)))) -> - | S25: 販売回数 | AF25: =IF(Z25="-", "-", IF(AC25="-", "-", IF(ABS(AC25)=0, "-", ROUND(100*(Z25-AC25)/ABS(AC25),10)))) -> -
A26: 日本短角 | N26: =IF(H26="-", "-", IF(K26="-", "-", IF(ABS(K26)=0, "-", ROUND(100*(H26-K26)/ABS(K26),10)))) -> - | S26: 延べ計算期間 | AF26: =IF(Z26="-", "-", IF(AC26="-", "-", IF(ABS(AC26)=0, "-", ROUND(100*(Z26-AC26)/ABS(AC26),10)))) -> -
A27: 乳用種 | N27: =IF(H27="-", "-", IF(K27="-", "-", IF(ABS(K27)=0, "-", ROUND(100*(H27-K27)/ABS(K27),10)))) -> -
A28: その他 | N28: =IF(H28="-", "-", IF(K28="-", "-", IF(ABS(K28)=0, "-", ROUND(100*(H28-K28)/ABS(K28),10)))) -> -
A29: 計 | N29: =IF(H29="-", "-", IF(K29="-", "-", IF(ABS(K29)=0, "-", ROUND(100*(H29-K29)/ABS(K29),10)))) -> -
A31: 【副産物】 | AH31: 単位：㎏、頭、円、％
H32: 数 量 | Q32: 価 額 | Z32: 単 価
H33: 本年 | K33: 前年 | N33: 増減率 | Q33: 本年 | T33: 前年 | W33: 増減率 | Z33: 本年 | AC33: 前年 | AF33: 増減率
A34: きゅう肥 | B34: 利用計 | N34: =IF(H34="-", "-", IF(K34="-", "-", IF(ABS(K34)=0, "-", ROUND(100*(H34-K34)/ABS(K34),10)))) -> - | W34: =IF(Q34="-", "-", IF(T34="-", "-", IF(ABS(T34)=0, "-", ROUND(100*(Q34-T34)/ABS(T34),10)))) -> - | AF34: =IF(Z34="-", "-", IF(AC34="-", "-", IF(ABS(AC34)=0, "-", ROUND(100*(Z34-AC34)/ABS(AC34),10)))) -> -
C35: 販売 | N35: =IF(H35="-", "-", IF(K35="-", "-", IF(ABS(K35)=0, "-", ROUND(100*(H35-K35)/ABS(K35),10)))) -> - | W35: =IF(Q35="-", "-", IF(T35="-", "-", IF(ABS(T35)=0, "-", ROUND(100*(Q35-T35)/ABS(T35),10)))) -> - | AF35: =IF(Z35="-", "-", IF(AC35="-", "-", IF(ABS(AC35)=0, "-", ROUND(100*(Z35-AC35)/ABS(AC35),10)))) -> -
C36: 自家農業仕向 | N36: =IF(H36="-", "-", IF(K36="-", "-", IF(ABS(K36)=0, "-", ROUND(100*(H36-K36)/ABS(K36),10)))) -> - | W36: =IF(Q36="-", "-", IF(T36="-", "-", IF(ABS(T36)=0, "-", ROUND(100*(Q36-T36)/ABS(T36),10)))) -> - | AF36: =IF(Z36="-", "-", IF(AC36="-", "-", IF(ABS(AC36)=0, "-", ROUND(100*(Z36-AC36)/ABS(AC36),10)))) -> -
B37: その他数量 | N37: =IF(H37="-", "-", IF(K37="-", "-", IF(ABS(K37)=0, "-", ROUND(100*(H37-K37)/ABS(K37),10)))) -> -
B38: 搬出量 | N38: =IF(H38="-", "-", IF(K38="-", "-", IF(ABS(K38)=0, "-", ROUND(100*(H38-K38)/ABS(K38),10)))) -> -
A39: 事故牛・４ヶ月未満の子牛 | N39: =IF(H39="-", "-", IF(K39="-", "-", IF(ABS(K39)=0, "-", ROUND(100*(H39-K39)/ABS(K39),10)))) -> - | W39: =IF(Q39="-", "-", IF(T39="-", "-", IF(ABS(T39)=0, "-", ROUND(100*(Q39-T39)/ABS(T39),10)))) -> - | AF39: =IF(Z39="-", "-", IF(AC39="-", "-", IF(ABS(AC39)=0, "-", ROUND(100*(Z39-AC39)/ABS(AC39),10)))) -> -
A40: 計 | W40: =IF(Q40="-", "-", IF(T40="-", "-", IF(ABS(T40)=0, "-", ROUND(100*(Q40-T40)/ABS(T40),10)))) -> -
A41: 注：事故牛・４ヶ月未満の子牛は1経営体当たり

Sheet No.5
A1: =IF(No.1!A1="","",No.1!A1) | C1: 年 農業経営統計調査 育成牛・肥育牛生産費統計 集計結果検討表 №５
F3: 集計番号 | I3: 集計名称 | T3: 都道府県等 | Y3: 規模階層 | AF3: 生産費区分
A4: 本年 | F4: =IF(No.1!F4="","",No.1!F4) | I4: =IF(No.1!I4="","",No.1!I4) | T4: =IF(No.1!AB4="","",No.1!AB4) | U4: =IF(No.1!AC4="","",No.1!AC4) | Y4: =IF(No.1!AG4="","",No.1!AG4) | Z4: =IF(No.1!AH4="","",No.1!AH4) | AF4: =IF(No.1!AN4="","",No.1!AN4) | AG4: =IF(No.1!AO4="","",No.1!AO4)
A5: 前年 | F5: =IF(No.1!F5="","",No.1!F5) | I5: =IF(No.1!I5="","",No.1!I5)
A7: 調査対象畜１頭当たり
A8: 【流通飼料（購入飼料）の給与量と価額】 | AQ8: 単位：㎏、円、％
H9: 数 量 | Q9: 価 額 | Z9: 単 価 | AI9: TDN換算率 | AL9: TDN換算量
H10: 本年 | K10: 前年 | N10: 増減率 | Q10: 本年 | T10: 前年 | W10: 増減率 | Z10: 本年 | AC10: 前年 | AF10: 増減率 | AL10: 本年 | AO10: 前年
A11: 穀類計 | N11: =IF(H11="-", "-", IF(K11="-", "-", IF(ABS(K11)=0, "-", ROUND(100*(H11-K11)/ABS(K11),10)))) -> - | W11: =IF(Q11="-", "-", IF(T11="-", "-", IF(ABS(T11)=0, "-", ROUND(100*(Q11-T11)/ABS(T11),10)))) -> -
B12: 大麦 | N12: =IF(H12="-", "-", IF(K12="-", "-", IF(ABS(K12)=0, "-", ROUND(100*(H12-K12)/ABS(K12),10)))) -> - | W12: =IF(Q12="-", "-", IF(T12="-", "-", IF(ABS(T12)=0, "-", ROUND(100*(Q12-T12)/ABS(T12),10)))) -> - | AF12: =IF(Z12="-", "-", IF(AC12="-", "-", IF(ABS(AC12)=0, "-", ROUND(100*(Z12-AC12)/ABS(AC12),10)))) -> - | AI12: 74.4
B13: その他の麦 | N13: =IF(H13="-", "-", IF(K13="-", "-", IF(ABS(K13)=0, "-", ROUND(100*(H13-K13)/ABS(K13),10)))) -> - | W13: =IF(Q13="-", "-", IF(T13="-", "-", IF(ABS(T13)=0, "-", ROUND(100*(Q13-T13)/ABS(T13),10)))) -> - | AF13: =IF(Z13="-", "-", IF(AC13="-", "-", IF(ABS(AC13)=0, "-", ROUND(100*(Z13-AC13)/ABS(AC13),10)))) -> - | AI13: 78.7
B14: とうもろこし | N14: =IF(H14="-", "-", IF(K14="-", "-", IF(ABS(K14)=0, "-", ROUND(100*(H14-K14)/ABS(K14),10)))) -> - | W14: =IF(Q14="-", "-", IF(T14="-", "-", IF(ABS(T14)=0, "-", ROUND(100*(Q14-T14)/ABS(T14),10)))) -> - | AF14: =IF(Z14="-", "-", IF(AC14="-", "-", IF(ABS(AC14)=0, "-", ROUND(100*(Z14-AC14)/ABS(AC14),10)))) -> - | AI14: 80
B15: 大豆 | N15: =IF(H15="-", "-", IF(K15="-", "-", IF(ABS(K15)=0, "-", ROUND(100*(H15-K15)/ABS(K15),10)))) -> - | W15: =IF(Q15="-", "-", IF(T15="-", "-", IF(ABS(T15)=0, "-", ROUND(100*(Q15-T15)/ABS(T15),10)))) -> - | AF15: =IF(Z15="-", "-", IF(AC15="-", "-", IF(ABS(AC15)=0, "-", ROUND(100*(Z15-AC15)/ABS(AC15),10)))) -> - | AI15: 91
B16: 飼料用米 | N16: =IF(H16="-", "-", IF(K16="-", "-", IF(ABS(K16)=0, "-", ROUND(100*(H16-K16)/ABS(K16),10)))) -> - | W16: =IF(Q16="-", "-", IF(T16="-", "-", IF(ABS(T16)=0, "-", ROUND(100*(Q16-T16)/ABS(T16),10)))) -> - | AF16: =IF(Z16="-", "-", IF(AC16="-", "-", IF(ABS(AC16)=0, "-", ROUND(100*(Z16-AC16)/ABS(AC16),10)))) -> - | AI16: 80.9
B17: その他 | N17: =IF(H17="-", "-", IF(K17="-", "-", IF(ABS(K17)=0, "-", ROUND(100*(H17-K17)/ABS(K17),10)))) -> - | W17: =IF(Q17="-", "-", IF(T17="-", "-", IF(ABS(T17)=0, "-", ROUND(100*(Q17-T17)/ABS(T17),10)))) -> - | AF17: =IF(Z17="-", "-", IF(AC17="-", "-", IF(ABS(AC17)=0, "-", ROUND(100*(Z17-AC17)/ABS(AC17),10)))) -> - | AI17: 79.6
A18: ぬか・ふすま計 | N18: =IF(H18="-", "-", IF(K18="-", "-", IF(ABS(K18)=0, "-", ROUND(100*(H18-K18)/ABS(K18),10)))) -> - | W18: =IF(Q18="-", "-", IF(T18="-", "-", IF(ABS(T18)=0, "-", ROUND(100*(Q18-T18)/ABS(T18),10)))) -> -
B19: ふすま | N19: =IF(H19="-", "-", IF(K19="-", "-", IF(ABS(K19)=0, "-", ROUND(100*(H19-K19)/ABS(K19),10)))) -> - | W19: =IF(Q19="-", "-", IF(T19="-", "-", IF(ABS(T19)=0, "-", ROUND(100*(Q19-T19)/ABS(T19),10)))) -> - | AF19: =IF(Z19="-", "-", IF(AC19="-", "-", IF(ABS(AC19)=0, "-", ROUND(100*(Z19-AC19)/ABS(AC19),10)))) -> - | AI19: 62.7
B20: 米・麦ぬか | N20: =IF(H20="-", "-", IF(K20="-", "-", IF(ABS(K20)=0, "-", ROUND(100*(H20-K20)/ABS(K20),10)))) -> - | W20: =IF(Q20="-", "-", IF(T20="-", "-", IF(ABS(T20)=0, "-", ROUND(100*(Q20-T20)/ABS(T20),10)))) -> - | AF20: =IF(Z20="-", "-", IF(AC20="-", "-", IF(ABS(AC20)=0, "-", ROUND(100*(Z20-AC20)/ABS(AC20),10)))) -> - | AI20: 69.3
B21: その他 | N21: =IF(H21="-", "-", IF(K21="-", "-", IF(ABS(K21)=0, "-", ROUND(100*(H21-K21)/ABS(K21),10)))) -> - | W21: =IF(Q21="-", "-", IF(T21="-", "-", IF(ABS(T21)=0, "-", ROUND(100*(Q21-T21)/ABS(T21),10)))) -> - | AF21: =IF(Z21="-", "-", IF(AC21="-", "-", IF(ABS(AC21)=0, "-", ROUND(100*(Z21-AC21)/ABS(AC21),10)))) -> - | AI21: 63
A22: 植物性かす類計 | N22: =IF(H22="-", "-", IF(K22="-", "-", IF(ABS(K22)=0, "-", ROUND(100*(H22-K22)/ABS(K22),10)))) -> - | W22: =IF(Q22="-", "-", IF(T22="-", "-", IF(ABS(T22)=0, "-", ROUND(100*(Q22-T22)/ABS(T22),10)))) -> -
B23: 大豆油かす | N23: =IF(H23="-", "-", IF(K23="-", "-", IF(ABS(K23)=0, "-", ROUND(100*(H23-K23)/ABS(K23),10)))) -> - | W23: =IF(Q23="-", "-", IF(T23="-", "-", IF(ABS(T23)=0, "-", ROUND(100*(Q23-T23)/ABS(T23),10)))) -> - | AF23: =IF(Z23="-", "-", IF(AC23="-", "-", IF(ABS(AC23)=0, "-", ROUND(100*(Z23-AC23)/ABS(AC23),10)))) -> - | AI23: 76.8
B24: ビートパルプ | N24: =IF(H24="-", "-", IF(K24="-", "-", IF(ABS(K24)=0, "-", ROUND(100*(H24-K24)/ABS(K24),10)))) -> - | W24: =IF(Q24="-", "-", IF(T24="-", "-", IF(ABS(T24)=0, "-", ROUND(100*(Q24-T24)/ABS(T24),10)))) -> - | AF24: =IF(Z24="-", "-", IF(AC24="-", "-", IF(ABS(AC24)=0, "-", ROUND(100*(Z24-AC24)/ABS(AC24),10)))) -> - | AI24: 67.3
B25: その他 | N25: =IF(H25="-", "-", IF(K25="-", "-", IF(ABS(K25)=0, "-", ROUND(100*(H25-K25)/ABS(K25),10)))) -> - | W25: =IF(Q25="-", "-", IF(T25="-", "-", IF(ABS(T25)=0, "-", ROUND(100*(Q25-T25)/ABS(T25),10)))) -> - | AF25: =IF(Z25="-", "-", IF(AC25="-", "-", IF(ABS(AC25)=0, "-", ROUND(100*(Z25-AC25)/ABS(AC25),10)))) -> - | AI25: 34.1
A26: 配合飼料 | N26: =IF(H26="-", "-", IF(K26="-", "-", IF(ABS(K26)=0, "-", ROUND(100*(H26-K26)/ABS(K26),10)))) -> - | W26: =IF(Q26="-", "-", IF(T26="-", "-", IF(ABS(T26)=0, "-", ROUND(100*(Q26-T26)/ABS(T26),10)))) -> - | AF26: =IF(Z26="-", "-", IF(AC26="-", "-", IF(ABS(AC26)=0, "-", ROUND(100*(Z26-AC26)/ABS(AC26),10)))) -> - | AI26: 72
A27: ＴＭＲ | N27: =IF(H27="-", "-", IF(K27="-", "-", IF(ABS(K27)=0, "-", ROUND(100*(H27-K27)/ABS(K27),10)))) -> - | W27: =IF(Q27="-", "-", IF(T27="-", "-", IF(ABS(T27)=0, "-", ROUND(100*(Q27-T27)/ABS(T27),10)))) -> - | AF27: =IF(Z27="-", "-", IF(AC27="-", "-", IF(ABS(AC27)=0, "-", ROUND(100*(Z27-AC27)/ABS(AC27),10)))) -> - | AI27: 31.4
A28: 牛乳脱脂乳 | N28: =IF(H28="-", "-", IF(K28="-", "-", IF(ABS(K28)=0, "-", ROUND(100*(H28-K28)/ABS(K28),10)))) -> - | W28: =IF(Q28="-", "-", IF(T28="-", "-", IF(ABS(T28)=0, "-", ROUND(100*(Q28-T28)/ABS(T28),10)))) -> - | AF28: =IF(Z28="-", "-", IF(AC28="-", "-", IF(ABS(AC28)=0, "-", ROUND(100*(Z28-AC28)/ABS(AC28),10)))) -> - | AI28: 76
A29: いも類及び野菜類 | N29: =IF(H29="-", "-", IF(K29="-", "-", IF(ABS(K29)=0, "-", ROUND(100*(H29-K29)/ABS(K29),10)))) -> - | W29: =IF(Q29="-", "-", IF(T29="-", "-", IF(ABS(T29)=0, "-", ROUND(100*(Q29-T29)/ABS(T29),10)))) -> - | AF29: =IF(Z29="-", "-", IF(AC29="-", "-", IF(ABS(AC29)=0, "-", ROUND(100*(Z29-AC29)/ABS(AC29),10)))) -> - | AI29: 12.3
A30: その他わら類計 | N30: =IF(H30="-", "-", IF(K30="-", "-", IF(ABS(K30)=0, "-", ROUND(100*(H30-K30)/ABS(K30),10)))) -> - | W30: =IF(Q30="-", "-", IF(T30="-", "-", IF(ABS(T30)=0, "-", ROUND(100*(Q30-T30)/ABS(T30),10)))) -> -
B31: 稲わら | N31: =IF(H31="-", "-", IF(K31="-", "-", IF(ABS(K31)=0, "-", ROUND(100*(H31-K31)/ABS(K31),10)))) -> - | W31: =IF(Q31="-", "-", IF(T31="-", "-", IF(ABS(T31)=0, "-", ROUND(100*(Q31-T31)/ABS(T31),10)))) -> - | AF31: =IF(Z31="-", "-", IF(AC31="-", "-", IF(ABS(AC31)=0, "-", ROUND(100*(Z31-AC31)/ABS(AC31),10)))) -> - | AI31: 37.7
B32: その他 | N32: =IF(H32="-", "-", IF(K32="-", "-", IF(ABS(K32)=0, "-", ROUND(100*(H32-K32)/ABS(K32),10)))) -> - | W32: =IF(Q32="-", "-", IF(T32="-", "-", IF(ABS(T32)=0, "-", ROUND(100*(Q32-T32)/ABS(T32),10)))) -> - | AF32: =IF(Z32="-", "-", IF(AC32="-", "-", IF(ABS(AC32)=0, "-", ROUND(100*(Z32-AC32)/ABS(AC32),10)))) -> - | AI32: 39
A33: 生牧草 | N33: =IF(H33="-", "-", IF(K33="-", "-", IF(ABS(K33)=0, "-", ROUND(100*(H33-K33)/ABS(K33),10)))) -> - | W33: =IF(Q33="-", "-", IF(T33="-", "-", IF(ABS(T33)=0, "-", ROUND(100*(Q33-T33)/ABS(T33),10)))) -> - | AF33: =IF(Z33="-", "-", IF(AC33="-", "-", IF(ABS(AC33)=0, "-", ROUND(100*(Z33-AC33)/ABS(AC33),10)))) -> - | AI33: 11.4
A34: 乾牧草計 | N34: =IF(H34="-", "-", IF(K34="-", "-", IF(ABS(K34)=0, "-", ROUND(100*(H34-K34)/ABS(K34),10)))) -> - | W34: =IF(Q34="-", "-", IF(T34="-", "-", IF(ABS(T34)=0, "-", ROUND(100*(Q34-T34)/ABS(T34),10)))) -> -
B35: ヘイキューブ | N35: =IF(H35="-", "-", IF(K35="-", "-", IF(ABS(K35)=0, "-", ROUND(100*(H35-K35)/ABS(K35),10)))) -> - | W35: =IF(Q35="-", "-", IF(T35="-", "-", IF(ABS(T35)=0, "-", ROUND(100*(Q35-T35)/ABS(T35),10)))) -> - | AF35: =IF(Z35="-", "-", IF(AC35="-", "-", IF(ABS(AC35)=0, "-", ROUND(100*(Z35-AC35)/ABS(AC35),10)))) -> - | AI35: 52.6
B36: その他 | N36: =IF(H36="-", "-", IF(K36="-", "-", IF(ABS(K36)=0, "-", ROUND(100*(H36-K36)/ABS(K36),10)))) -> - | W36: =IF(Q36="-", "-", IF(T36="-", "-", IF(ABS(T36)=0, "-", ROUND(100*(Q36-T36)/ABS(T36),10)))) -> - | AF36: =IF(Z36="-", "-", IF(AC36="-", "-", IF(ABS(AC36)=0, "-", ROUND(100*(Z36-AC36)/ABS(AC36),10)))) -> - | AI36: 49.1
A37: サイレージ計 | N37: =IF(H37="-", "-", IF(K37="-", "-", IF(ABS(K37)=0, "-", ROUND(100*(H37-K37)/ABS(K37),10)))) -> - | W37: =IF(Q37="-", "-", IF(T37="-", "-", IF(ABS(T37)=0, "-", ROUND(100*(Q37-T37)/ABS(T37),10)))) -> -
B38: いね科 | D38: 稲発酵粗飼料 | N38: =IF(H38="-", "-", IF(K38="-", "-", IF(ABS(K38)=0, "-", ROUND(100*(H38-K38)/ABS(K38),10)))) -> - | W38: =IF(Q38="-", "-", IF(T38="-", "-", IF(ABS(T38)=0, "-", ROUND(100*(Q38-T38)/ABS(T38),10)))) -> - | AF38: =IF(Z38="-", "-", IF(AC38="-", "-", IF(ABS(AC38)=0, "-", ROUND(100*(Z38-AC38)/ABS(AC38),10)))) -> - | AI38: 21.1
D39: その他 | N39: =IF(H39="-", "-", IF(K39="-", "-", IF(ABS(K39)=0, "-", ROUND(100*(H39-K39)/ABS(K39),10)))) -> - | W39: =IF(Q39="-", "-", IF(T39="-", "-", IF(ABS(T39)=0, "-", ROUND(100*(Q39-T39)/ABS(T39),10)))) -> - | AF39: =IF(Z39="-", "-", IF(AC39="-", "-", IF(ABS(AC39)=0, "-", ROUND(100*(Z39-AC39)/ABS(AC39),10)))) -> - | AI39: 19
B40: その他 | N40: =IF(H40="-", "-", IF(K40="-", "-", IF(ABS(K40)=0, "-", ROUND(100*(H40-K40)/ABS(K40),10)))) -> - | W40: =IF(Q40="-", "-", IF(T40="-", "-", IF(ABS(T40)=0, "-", ROUND(100*(Q40-T40)/ABS(T40),10)))) -> - | AF40: =IF(Z40="-", "-", IF(AC40="-", "-", IF(ABS(AC40)=0, "-", ROUND(100*(Z40-AC40)/ABS(AC40),10)))) -> - | AI40: 15.9
A41: その他 | W41: =IF(Q41="-", "-", IF(T41="-", "-", IF(ABS(T41)=0, "-", ROUND(100*(Q41-T41)/ABS(T41),10)))) -> -
A42: 合計 | W42: =IF(Q42="-", "-", IF(T42="-", "-", IF(ABS(T42)=0, "-", ROUND(100*(Q42-T42)/ABS(T42),10)))) -> -
...

Sheet No.6
A1: =IF(No.1!A1="","",No.1!A1) | C1: 年 農業経営統計調査 育成牛・肥育牛生産費統計 集計結果検討表 №６
F3: 集計番号 | I3: 集計名称 | T3: 都道府県等 | Y3: 規模階層 | AF3: 生産費区分
A4: 本年 | F4: =IF(No.1!F4="","",No.1!F4) | I4: =IF(No.1!I4="","",No.1!I4) | T4: =IF(No.1!AB4="","",No.1!AB4) | U4: =IF(No.1!AC4="","",No.1!AC4) | Y4: =IF(No.1!AG4="","",No.1!AG4) | Z4: =IF(No.1!AH4="","",No.1!AH4) | AF4: =IF(No.1!AN4="","",No.1!AN4) | AG4: =IF(No.1!AO4="","",No.1!AO4)
A5: 前年 | F5: =IF(No.1!F5="","",No.1!F5) | I5: =IF(No.1!I5="","",No.1!I5)
A7: 調査対象畜１頭当たり
A8: 【流通飼料（自給飼料）の給与量と価額】 | AH8: 単位：㎏、円、％
H9: 数 量 | Q9: 価 額 | Z9: 単 価 | AI9: TDN 換算率 | AL9: TDN換算給与量
H10: 本年 | K10: 前年 | N10: 増減率 | Q10: 本年 | T10: 前年 | W10: 増減率 | Z10: 本年 | AC10: 前年 | AF10: 増減率 | AL10: 本年 | AO10: 前年
A11: 稲わら | N11: =IF(H11="-", "-", IF(K11="-", "-", IF(ABS(K11)=0, "-", ROUND(100*(H11-K11)/ABS(K11),10)))) -> - | W11: =IF(Q11="-", "-", IF(T11="-", "-", IF(ABS(T11)=0, "-", ROUND(100*(Q11-T11)/ABS(T11),10)))) -> - | AF11: =IF(Z11="-", "-", IF(AC11="-", "-", IF(ABS(AC11)=0, "-", ROUND(100*(Z11-AC11)/ABS(AC11),10)))) -> - | AI11: 37.7
A12: その他 | N12: =IF(H12="-", "-", IF(K12="-", "-", IF(ABS(K12)=0, "-", ROUND(100*(H12-K12)/ABS(K12),10)))) -> - | W12: =IF(Q12="-", "-", IF(T12="-", "-", IF(ABS(T12)=0, "-", ROUND(100*(Q12-T12)/ABS(T12),10)))) -> - | AF12: =IF(Z12="-", "-", IF(AC12="-", "-", IF(ABS(AC12)=0, "-", ROUND(100*(Z12-AC12)/ABS(AC12),10)))) -> - | AI12: 39
A13: 合計 | W13: =IF(Q13="-", "-", IF(T13="-", "-", IF(ABS(T13)=0, "-", ROUND(100*(Q13-T13)/ABS(T13),10)))) -> -
A15: 【自給牧草の給与量】 | AZ15: 単位：㎏、％
H16: 生 牧 草 | Q16: 乾 牧 草 | Z16: サイレージ | AI16: TDN換算給与量
AI17: 生 牧 草 | AO17: 乾 牧 草 | AU17: サイレージ
H18: 本年 | K18: 前年 | N18: 増減率 | Q18: 本年 | T18: 前年 | W18: 増減率 | Z18: 本年 | AC18: 前年 | AF18: 増減率 | AI18: 本年 | AL18: 前年 | AO18: 本年 | AR18: 前年 | AU18: 本年 | AX18: 前年
A19: いね科計 | N19: =IF(H19="-", "-", IF(K19="-", "-", IF(ABS(K19)=0, "-", ROUND(100*(H19-K19)/ABS(K19),10)))) -> - | W19: =IF(Q19="-", "-", IF(T19="-", "-", IF(ABS(T19)=0, "-", ROUND(100*(Q19-T19)/ABS(T19),10)))) -> - | AF19: =IF(Z19="-", "-", IF(AC19="-", "-", IF(ABS(AC19)=0, "-", ROUND(100*(Z19-AC19)/ABS(AC19),10)))) -> -
B20: デントコーン | N20: =IF(H20="-", "-", IF(K20="-", "-", IF(ABS(K20)=0, "-", ROUND(100*(H20-K20)/ABS(K20),10)))) -> - | W20: =IF(Q20="-", "-", IF(T20="-", "-", IF(ABS(T20)=0, "-", ROUND(100*(Q20-T20)/ABS(T20),10)))) -> - | AF20: =IF(Z20="-", "-", IF(AC20="-", "-", IF(ABS(AC20)=0, "-", ROUND(100*(Z20-AC20)/ABS(AC20),10)))) -> -
B21: イタリアンライグラス | N21: =IF(H21="-", "-", IF(K21="-", "-", IF(ABS(K21)=0, "-", ROUND(100*(H21-K21)/ABS(K21),10)))) -> - | W21: =IF(Q21="-", "-", IF(T21="-", "-", IF(ABS(T21)=0, "-", ROUND(100*(Q21-T21)/ABS(T21),10)))) -> - | AF21: =IF(Z21="-", "-", IF(AC21="-", "-", IF(ABS(AC21)=0, "-", ROUND(100*(Z21-AC21)/ABS(AC21),10)))) -> -
B22: ソルゴー | N22: =IF(H22="-", "-", IF(K22="-", "-", IF(ABS(K22)=0, "-", ROUND(100*(H22-K22)/ABS(K22),10)))) -> - | W22: =IF(Q22="-", "-", IF(T22="-", "-", IF(ABS(T22)=0, "-", ROUND(100*(Q22-T22)/ABS(T22),10)))) -> - | AF22: =IF(Z22="-", "-", IF(AC22="-", "-", IF(ABS(AC22)=0, "-", ROUND(100*(Z22-AC22)/ABS(AC22),10)))) -> -
B23: 稲発酵粗飼料 | AF23: =IF(Z23="-", "-", IF(AC23="-", "-", IF(ABS(AC23)=0, "-", ROUND(100*(Z23-AC23)/ABS(AC23),10)))) -> -
B24: その他 | N24: =IF(H24="-", "-", IF(K24="-", "-", IF(ABS(K24)=0, "-", ROUND(100*(H24-K24)/ABS(K24),10)))) -> - | W24: =IF(Q24="-", "-", IF(T24="-", "-", IF(ABS(T24)=0, "-", ROUND(100*(Q24-T24)/ABS(T24),10)))) -> - | AF24: =IF(Z24="-", "-", IF(AC24="-", "-", IF(ABS(AC24)=0, "-", ROUND(100*(Z24-AC24)/ABS(AC24),10)))) -> -
A25: まぜまき計 | N25: =IF(H25="-", "-", IF(K25="-", "-", IF(ABS(K25)=0, "-", ROUND(100*(H25-K25)/ABS(K25),10)))) -> - | W25: =IF(Q25="-", "-", IF(T25="-", "-", IF(ABS(T25)=0, "-", ROUND(100*(Q25-T25)/ABS(T25),10)))) -> - | AF25: =IF(Z25="-", "-", IF(AC25="-", "-", IF(ABS(AC25)=0, "-", ROUND(100*(Z25-AC25)/ABS(AC25),10)))) -> -
B26: いね科主 | N26: =IF(H26="-", "-", IF(K26="-", "-", IF(ABS(K26)=0, "-", ROUND(100*(H26-K26)/ABS(K26),10)))) -> - | W26: =IF(Q26="-", "-", IF(T26="-", "-", IF(ABS(T26)=0, "-", ROUND(100*(Q26-T26)/ABS(T26),10)))) -> - | AF26: =IF(Z26="-", "-", IF(AC26="-", "-", IF(ABS(AC26)=0, "-", ROUND(100*(Z26-AC26)/ABS(AC26),10)))) -> -
B27: その他 | N27: =IF(H27="-", "-", IF(K27="-", "-", IF(ABS(K27)=0, "-", ROUND(100*(H27-K27)/ABS(K27),10)))) -> - | W27: =IF(Q27="-", "-", IF(T27="-", "-", IF(ABS(T27)=0, "-", ROUND(100*(Q27-T27)/ABS(T27),10)))) -> - | AF27: =IF(Z27="-", "-", IF(AC27="-", "-", IF(ABS(AC27)=0, "-", ROUND(100*(Z27-AC27)/ABS(AC27),10)))) -> -
A28: その他 | N28: =IF(H28="-", "-", IF(K28="-", "-", IF(ABS(K28)=0, "-", ROUND(100*(H28-K28)/ABS(K28),10)))) -> - | W28: =IF(Q28="-", "-", IF(T28="-", "-", IF(ABS(T28)=0, "-", ROUND(100*(Q28-T28)/ABS(T28),10)))) -> - | AF28: =IF(Z28="-", "-", IF(AC28="-", "-", IF(ABS(AC28)=0, "-", ROUND(100*(Z28-AC28)/ABS(AC28),10)))) -> -
A29: 穀類 | N29: =IF(H29="-", "-", IF(K29="-", "-", IF(ABS(K29)=0, "-", ROUND(100*(H29-K29)/ABS(K29),10)))) -> -
A30: いも類及び野菜類 | N30: =IF(H30="-", "-", IF(K30="-", "-", IF(ABS(K30)=0, "-", ROUND(100*(H30-K30)/ABS(K30),10)))) -> -
A31: 野生草 | N31: =IF(H31="-", "-", IF(K31="-", "-", IF(ABS(K31)=0, "-", ROUND(100*(H31-K31)/ABS(K31),10)))) -> -
A32: 野乾草 | W32: =IF(Q32="-", "-", IF(T32="-", "-", IF(ABS(T32)=0, "-", ROUND(100*(Q32-T32)/ABS(T32),10)))) -> -
A33: 放牧場費（時間） | N33: =IF(H33="-", "-", IF(K33="-", "-", IF(ABS(K33)=0, "-", ROUND(100*(H33-K33)/ABS(K33),10)))) -> -
H36: TDN換算率 | Z36: TDN換算率 | AR36: TDN換算率
H37: 生 牧 草 | K37: 乾 牧 草 | N37: サイレージ | Z37: 生 牧 草 | AC37: 乾 牧 草 | AF37: サイレージ
A38: いね科計 | S38: まぜまき計 | AK38: 穀類 | AR38: 79.6
B39: デントコーン | H39: 15.5 | K39: 49 | N39: 17.5 | T39: いね科主 | Z39: 11.4 | AC39: 51.5 | AF39: 19 | AK39: いも類及び野菜類 | AR39: 11.2
B40: イタリアンライグラス | H40: 11.8 | K40: 53.4 | N40: 22 | T40: その他 | Z40: 11.5 | AC40: 49 | AF40: 15.9 | AK40: 野生草 | AR40: 18.7
B41: ソルゴー | H41: 12.8 | K41: 47.5 | N41: 17.7 | S41: その他 | Z41: 8.5 | AC41: 49.1 | AF41: 15.9 | AK41: 野乾草 | AR41: 40.6
B42: 稲発酵粗飼料 | N42: 21.1
B43: その他 | H43: 11.6 | K43: 49.1 | N43: 19

Sheet No.7
A1: =IF(No.1!A1="","",No.1!A1) | C1: 年 農業経営統計調査 育成牛・肥育牛生産費統計 集計結果検討表 №７
F3: 集計番号 | I3: 集計名称 | T3: 都道府県等 | Y3: 規模階層 | AF3: 生産費区分
A4: 本年 | F4: =IF(No.1!F4="","",No.1!F4) | I4: =IF(No.1!I4="","",No.1!I4) | T4: =IF(No.1!AB4="","",No.1!AB4) | U4: =IF(No.1!AC4="","",No.1!AC4) | Y4: =IF(No.1!AG4="","",No.1!AG4) | Z4: =IF(No.1!AH4="","",No.1!AH4) | AF4: =IF(No.1!AN4="","",No.1!AN4) | AG4: =IF(No.1!AO4="","",No.1!AO4)
A5: 前年 | F5: =IF(No.1!F5="","",No.1!F5) | I5: =IF(No.1!I5="","",No.1!I5)
A7: 調査対象畜１頭当たり
A8: 【固定資産の所有状況】
A9: （建物等） | Y9: 単位：円、％ | AB9: （農機具） | AZ9: 単位：台、円、％
G10: 所有状況 | Q10: 償 却 費 | AI10: 所有台数 | AR10: 償 却 費
G11: 単位 | H11: 本年 | K11: 前年 | N11: 増減率 | Q11: 本年 | T11: 前年 | W11: 増減率 | AI11: 本年 | AL11: 前年 | AO11: 増減率 | AR11: 本年 | AU11: 前年 | AX11: 増減率
AB12: バキュームカー | AO12: =IF(AI12="-", "-", IF(AL12="-", "-", IF(ABS(AL12)=0, "-", ROUND(100*(AI12-AL12)/ABS(AL12),10)))) -> - | AX12: =IF(AR12="-", "-", IF(AU12="-", "-", IF(ABS(AU12)=0, "-", ROUND(100*(AR12-AU12)/ABS(AU12),10)))) -> -
A13: 畜舎 | G13: ㎡ | N13: =IF(H13="-", "-", IF(K13="-", "-", IF(ABS(K13)=0, "-", ROUND(100*(H13-K13)/ABS(K13),10)))) -> - | W13: =IF(Q13="-", "-", IF(T13="-", "-", IF(ABS(T13)=0, "-", ROUND(100*(Q13-T13)/ABS(T13),10)))) -> - | AB13: マニュアスプレッダー | AO13: =IF(AI13="-", "-", IF(AL13="-", "-", IF(ABS(AL13)=0, "-", ROUND(100*(AI13-AL13)/ABS(AL13),10)))) -> - | AX13: =IF(AR13="-", "-", IF(AU13="-", "-", IF(ABS(AU13)=0, "-", ROUND(100*(AR13-AU13)/ABS(AU13),10)))) -> -
A14: 納屋・倉庫 | G14: ㎡ | N14: =IF(H14="-", "-", IF(K14="-", "-", IF(ABS(K14)=0, "-", ROUND(100*(H14-K14)/ABS(K14),10)))) -> - | W14: =IF(Q14="-", "-", IF(T14="-", "-", IF(ABS(T14)=0, "-", ROUND(100*(Q14-T14)/ABS(T14),10)))) -> - | AB14: ふん尿搬出機 | AO14: =IF(AI14="-", "-", IF(AL14="-", "-", IF(ABS(AL14)=0, "-", ROUND(100*(AI14-AL14)/ABS(AL14),10)))) -> - | AX14: =IF(AR14="-", "-", IF(AU14="-", "-", IF(ABS(AU14)=0, "-", ROUND(100*(AR14-AU14)/ABS(AU14),10)))) -> -
A15: たい肥舎 | G15: ㎡ | N15: =IF(H15="-", "-", IF(K15="-", "-", IF(ABS(K15)=0, "-", ROUND(100*(H15-K15)/ABS(K15),10)))) -> - | W15: =IF(Q15="-", "-", IF(T15="-", "-", IF(ABS(T15)=0, "-", ROUND(100*(Q15-T15)/ABS(T15),10)))) -> - | AB15: 切り返し機(ﾛｰﾀﾞｰ) | AO15: =IF(AI15="-", "-", IF(AL15="-", "-", IF(ABS(AL15)=0, "-", ROUND(100*(AI15-AL15)/ABS(AL15),10)))) -> - | AX15: =IF(AR15="-", "-", IF(AU15="-", "-", IF(ABS(AU15)=0, "-", ROUND(100*(AR15-AU15)/ABS(AU15),10)))) -> -
A16: ふん尿貯留槽 | G16: 基 | N16: =IF(H16="-", "-", IF(K16="-", "-", IF(ABS(K16)=0, "-", ROUND(100*(H16-K16)/ABS(K16),10)))) -> - | W16: =IF(Q16="-", "-", IF(T16="-", "-", IF(ABS(T16)=0, "-", ROUND(100*(Q16-T16)/ABS(T16),10)))) -> - | AB16: 動力噴霧機 | AO16: =IF(AI16="-", "-", IF(AL16="-", "-", IF(ABS(AL16)=0, "-", ROUND(100*(AI16-AL16)/ABS(AL16),10)))) -> - | AX16: =IF(AR16="-", "-", IF(AU16="-", "-", IF(ABS(AU16)=0, "-", ROUND(100*(AR16-AU16)/ABS(AU16),10)))) -> -
A17: ﾌﾟﾗｽﾁｯｸ利用乾燥施設 | G17: ㎡ | N17: =IF(H17="-", "-", IF(K17="-", "-", IF(ABS(K17)=0, "-", ROUND(100*(H17-K17)/ABS(K17),10)))) -> - | W17: =IF(Q17="-", "-", IF(T17="-", "-", IF(ABS(T17)=0, "-", ROUND(100*(Q17-T17)/ABS(T17),10)))) -> - | AB17: トラクター | AO17: =IF(AI17="-", "-", IF(AL17="-", "-", IF(ABS(AL17)=0, "-", ROUND(100*(AI17-AL17)/ABS(AL17),10)))) -> - | AX17: =IF(AR17="-", "-", IF(AU17="-", "-", IF(ABS(AU17)=0, "-", ROUND(100*(AR17-AU17)/ABS(AU17),10)))) -> -
A18: 飼料用タンク | G18: 基 | N18: =IF(H18="-", "-", IF(K18="-", "-", IF(ABS(K18)=0, "-", ROUND(100*(H18-K18)/ABS(K18),10)))) -> - | W18: =IF(Q18="-", "-", IF(T18="-", "-", IF(ABS(T18)=0, "-", ROUND(100*(Q18-T18)/ABS(T18),10)))) -> - | AB18: カッター | AO18: =IF(AI18="-", "-", IF(AL18="-", "-", IF(ABS(AL18)=0, "-", ROUND(100*(AI18-AL18)/ABS(AL18),10)))) -> - | AX18: =IF(AR18="-", "-", IF(AU18="-", "-", IF(ABS(AU18)=0, "-", ROUND(100*(AR18-AU18)/ABS(AU18),10)))) -> -
A19: その他 | G19: － | W19: =IF(Q19="-", "-", IF(T19="-", "-", IF(ABS(T19)=0, "-", ROUND(100*(Q19-T19)/ABS(T19),10)))) -> - | AB19: 飼料粉砕機 | AO19: =IF(AI19="-", "-", IF(AL19="-", "-", IF(ABS(AL19)=0, "-", ROUND(100*(AI19-AL19)/ABS(AL19),10)))) -> - | AX19: =IF(AR19="-", "-", IF(AU19="-", "-", IF(ABS(AU19)=0, "-", ROUND(100*(AR19-AU19)/ABS(AU19),10)))) -> -
A20: 計 | G20: － | W20: =IF(Q20="-", "-", IF(T20="-", "-", IF(ABS(T20)=0, "-", ROUND(100*(Q20-T20)/ABS(T20),10)))) -> - | AB20: 飼料配合機 | AO20: =IF(AI20="-", "-", IF(AL20="-", "-", IF(ABS(AL20)=0, "-", ROUND(100*(AI20-AL20)/ABS(AL20),10)))) -> - | AX20: =IF(AR20="-", "-", IF(AU20="-", "-", IF(ABS(AU20)=0, "-", ROUND(100*(AR20-AU20)/ABS(AU20),10)))) -> -
A21: 注：所有状況は１経営体当たり | AB21: 自動給餌機 | AO21: =IF(AI21="-", "-", IF(AL21="-", "-", IF(ABS(AL21)=0, "-", ROUND(100*(AI21-AL21)/ABS(AL21),10)))) -> - | AX21: =IF(AR21="-", "-", IF(AU21="-", "-", IF(ABS(AU21)=0, "-", ROUND(100*(AR21-AU21)/ABS(AU21),10)))) -> -
AB22: 自動給水機 | AO22: =IF(AI22="-", "-", IF(AL22="-", "-", IF(ABS(AL22)=0, "-", ROUND(100*(AI22-AL22)/ABS(AL22),10)))) -> - | AX22: =IF(AR22="-", "-", IF(AU22="-", "-", IF(ABS(AU22)=0, "-", ROUND(100*(AR22-AU22)/ABS(AU22),10)))) -> -
A23: （自動車） | Y23: 単位：台、円、％ | AB23: その他 | AX23: =IF(AR23="-", "-", IF(AU23="-", "-", IF(ABS(AU23)=0, "-", ROUND(100*(AR23-AU23)/ABS(AU23),10)))) -> -
H24: 所有台数 | Q24: 償 却 費 | AB24: 計 | AX24: =IF(AR24="-", "-", IF(AU24="-", "-", IF(ABS(AU24)=0, "-", ROUND(100*(AR24-AU24)/ABS(AU24),10)))) -> -
H25: 本年 | K25: 前年 | N25: 増減率 | Q25: 本年 | T25: 前年 | W25: 増減率 | AB25: 注：所有台数は10経営体当たり
A26: 貨物自動車 | N26: =IF(H26="-", "-", IF(K26="-", "-", IF(ABS(K26)=0, "-", ROUND(100*(H26-K26)/ABS(K26),10)))) -> - | W26: =IF(Q26="-", "-", IF(T26="-", "-", IF(ABS(T26)=0, "-", ROUND(100*(Q26-T26)/ABS(T26),10)))) -> -
A27: その他 | W27: =IF(Q27="-", "-", IF(T27="-", "-", IF(ABS(T27)=0, "-", ROUND(100*(Q27-T27)/ABS(T27),10)))) -> -
A28: 計 | W28: =IF(Q28="-", "-", IF(T28="-", "-", IF(ABS(T28)=0, "-", ROUND(100*(Q28-T28)/ABS(T28),10)))) -> -
A29: 注：所有台数は10経営体当たり
A31: 【処分差損失】
H32: 本年 | K32: 前年 | N32: 増減率
A33: 建物 | N33: =IF(H33="-", "-", IF(K33="-", "-", IF(ABS(K33)=0, "-", ROUND(100*(H33-K33)/ABS(K33),10)))) -> -
A34: 自動車 | N34: =IF(H34="-", "-", IF(K34="-", "-", IF(ABS(K34)=0, "-", ROUND(100*(H34-K34)/ABS(K34),10)))) -> -
A35: 農機具 | N35: =IF(H35="-", "-", IF(K35="-", "-", IF(ABS(K35)=0, "-", ROUND(100*(H35-K35)/ABS(K35),10)))) -> -
A36: 生産管理機器 | N36: =IF(H36="-", "-", IF(K36="-", "-", IF(ABS(K36)=0, "-", ROUND(100*(H36-K36)/ABS(K36),10)))) -> -

Sheet No.8
A1: =IF(No.1!A1="","",No.1!A1) | D1: 年 農業経営統計調査 育成牛・肥育牛生産費統計 集計結果検討表 №８
F3: 集計番号 | I3: 集計名称 | T3: 都道府県等 | Y3: 規模階層 | AF3: 生産費区分
A4: 本年 | F4: =IF(No.1!F4="","",No.1!F4) | I4: =IF(No.1!I4="","",No.1!I4) | T4: =IF(No.1!AB4="","",No.1!AB4) | U4: =IF(No.1!AC4="","",No.1!AC4) | Y4: =IF(No.1!AG4="","",No.1!AG4) | Z4: =IF(No.1!AH4="","",No.1!AH4) | AF4: =IF(No.1!AN4="","",No.1!AN4) | AG4: =IF(No.1!AO4="","",No.1!AO4)
A5: 前年 | F5: =IF(No.1!F5="","",No.1!F5) | I5: =IF(No.1!I5="","",No.1!I5)
A7: 調査対象畜１頭当たり
A8: 【作業別家族労働時間及び家族労働費】 | BC8: 単位：時間、円、％
H9: 家族（男） | P9: 家族（女） | X9: 家族（計） | AF9: 雇用（男） | AN9: 雇用（女） | AV9: 雇用（計）
H10: 本年 | K10: 前年 | N10: 増減率 | P10: 本年 | S10: 前年 | V10: 増減率 | X10: 本年 | AA10: 前年 | AD10: 増減率 | AF10: 本年 | AI10: 前年 | AL10: 増減率 | AN10: 本年 | AQ10: 前年 | AT10: 増減率 | AV10: 本年 | AY10: 前年 | BB10: 増減率
A11: 直接労働時間計 | N11: =IF(H11="-", "-", IF(K11="-", "-", IF(ABS(K11)=0, "-", ROUND(100*(H11-K11)/ABS(K11),10)))) -> - | V11: =IF(P11="-", "-", IF(S11="-", "-", IF(ABS(S11)=0, "-", ROUND(100*(P11-S11)/ABS(S11),10)))) -> - | AD11: =IF(X11="-", "-", IF(AA11="-", "-", IF(ABS(AA11)=0, "-", ROUND(100*(X11-AA11)/ABS(AA11),10)))) -> - | AL11: =IF(AF11="-", "-", IF(AI11="-", "-", IF(ABS(AI11)=0, "-", ROUND(100*(AF11-AI11)/ABS(AI11),10)))) -> - | AT11: =IF(AN11="-", "-", IF(AQ11="-", "-", IF(ABS(AQ11)=0, "-", ROUND(100*(AN11-AQ11)/ABS(AQ11),10)))) -> - | BB11: =IF(AV11="-", "-", IF(AY11="-", "-", IF(ABS(AY11)=0, "-", ROUND(100*(AV11-AY11)/ABS(AY11),10)))) -> -
B12: 飼料調理・給与・給水 | N12: =IF(H12="-", "-", IF(K12="-", "-", IF(ABS(K12)=0, "-", ROUND(100*(H12-K12)/ABS(K12),10)))) -> - | V12: =IF(P12="-", "-", IF(S12="-", "-", IF(ABS(S12)=0, "-", ROUND(100*(P12-S12)/ABS(S12),10)))) -> - | AD12: =IF(X12="-", "-", IF(AA12="-", "-", IF(ABS(AA12)=0, "-", ROUND(100*(X12-AA12)/ABS(AA12),10)))) -> - | AL12: =IF(AF12="-", "-", IF(AI12="-", "-", IF(ABS(AI12)=0, "-", ROUND(100*(AF12-AI12)/ABS(AI12),10)))) -> - | AT12: =IF(AN12="-", "-", IF(AQ12="-", "-", IF(ABS(AQ12)=0, "-", ROUND(100*(AN12-AQ12)/ABS(AQ12),10)))) -> - | BB12: =IF(AV12="-", "-", IF(AY12="-", "-", IF(ABS(AY12)=0, "-", ROUND(100*(AV12-AY12)/ABS(AY12),10)))) -> -
B13: 敷料搬入･きゅう肥搬出 | N13: =IF(H13="-", "-", IF(K13="-", "-", IF(ABS(K13)=0, "-", ROUND(100*(H13-K13)/ABS(K13),10)))) -> - | V13: =IF(P13="-", "-", IF(S13="-", "-", IF(ABS(S13)=0, "-", ROUND(100*(P13-S13)/ABS(S13),10)))) -> - | AD13: =IF(X13="-", "-", IF(AA13="-", "-", IF(ABS(AA13)=0, "-", ROUND(100*(X13-AA13)/ABS(AA13),10)))) -> - | AL13: =IF(AF13="-", "-", IF(AI13="-", "-", IF(ABS(AI13)=0, "-", ROUND(100*(AF13-AI13)/ABS(AI13),10)))) -> - | AT13: =IF(AN13="-", "-", IF(AQ13="-", "-", IF(ABS(AQ13)=0, "-", ROUND(100*(AN13-AQ13)/ABS(AQ13),10)))) -> - | BB13: =IF(AV13="-", "-", IF(AY13="-", "-", IF(ABS(AY13)=0, "-", ROUND(100*(AV13-AY13)/ABS(AY13),10)))) -> -
B14: その他 | N14: =IF(H14="-", "-", IF(K14="-", "-", IF(ABS(K14)=0, "-", ROUND(100*(H14-K14)/ABS(K14),10)))) -> - | V14: =IF(P14="-", "-", IF(S14="-", "-", IF(ABS(S14)=0, "-", ROUND(100*(P14-S14)/ABS(S14),10)))) -> - | AD14: =IF(X14="-", "-", IF(AA14="-", "-", IF(ABS(AA14)=0, "-", ROUND(100*(X14-AA14)/ABS(AA14),10)))) -> - | AL14: =IF(AF14="-", "-", IF(AI14="-", "-", IF(ABS(AI14)=0, "-", ROUND(100*(AF14-AI14)/ABS(AI14),10)))) -> - | AT14: =IF(AN14="-", "-", IF(AQ14="-", "-", IF(ABS(AQ14)=0, "-", ROUND(100*(AN14-AQ14)/ABS(AQ14),10)))) -> - | BB14: =IF(AV14="-", "-", IF(AY14="-", "-", IF(ABS(AY14)=0, "-", ROUND(100*(AV14-AY14)/ABS(AY14),10)))) -> -
A15: 間接労働時間 | N15: =IF(H15="-", "-", IF(K15="-", "-", IF(ABS(K15)=0, "-", ROUND(100*(H15-K15)/ABS(K15),10)))) -> - | V15: =IF(P15="-", "-", IF(S15="-", "-", IF(ABS(S15)=0, "-", ROUND(100*(P15-S15)/ABS(S15),10)))) -> - | AD15: =IF(X15="-", "-", IF(AA15="-", "-", IF(ABS(AA15)=0, "-", ROUND(100*(X15-AA15)/ABS(AA15),10)))) -> - | AL15: =IF(AF15="-", "-", IF(AI15="-", "-", IF(ABS(AI15)=0, "-", ROUND(100*(AF15-AI15)/ABS(AI15),10)))) -> - | AT15: =IF(AN15="-", "-", IF(AQ15="-", "-", IF(ABS(AQ15)=0, "-", ROUND(100*(AN15-AQ15)/ABS(AQ15),10)))) -> - | BB15: =IF(AV15="-", "-", IF(AY15="-", "-", IF(ABS(AY15)=0, "-", ROUND(100*(AV15-AY15)/ABS(AY15),10)))) -> -
B16: 自給牧草労働時間 | N16: =IF(H16="-", "-", IF(K16="-", "-", IF(ABS(K16)=0, "-", ROUND(100*(H16-K16)/ABS(K16),10)))) -> - | V16: =IF(P16="-", "-", IF(S16="-", "-", IF(ABS(S16)=0, "-", ROUND(100*(P16-S16)/ABS(S16),10)))) -> - | AD16: =IF(X16="-", "-", IF(AA16="-", "-", IF(ABS(AA16)=0, "-", ROUND(100*(X16-AA16)/ABS(AA16),10)))) -> - | AL16: =IF(AF16="-", "-", IF(AI16="-", "-", IF(ABS(AI16)=0, "-", ROUND(100*(AF16-AI16)/ABS(AI16),10)))) -> - | AT16: =IF(AN16="-", "-", IF(AQ16="-", "-", IF(ABS(AQ16)=0, "-", ROUND(100*(AN16-AQ16)/ABS(AQ16),10)))) -> - | BB16: =IF(AV16="-", "-", IF(AY16="-", "-", IF(ABS(AY16)=0, "-", ROUND(100*(AV16-AY16)/ABS(AY16),10)))) -> -
A17: 労働時間合計 | N17: =IF(H17="-", "-", IF(K17="-", "-", IF(ABS(K17)=0, "-", ROUND(100*(H17-K17)/ABS(K17),10)))) -> - | V17: =IF(P17="-", "-", IF(S17="-", "-", IF(ABS(S17)=0, "-", ROUND(100*(P17-S17)/ABS(S17),10)))) -> - | AD17: =IF(X17="-", "-", IF(AA17="-", "-", IF(ABS(AA17)=0, "-", ROUND(100*(X17-AA17)/ABS(AA17),10)))) -> - | AL17: =IF(AF17="-", "-", IF(AI17="-", "-", IF(ABS(AI17)=0, "-", ROUND(100*(AF17-AI17)/ABS(AI17),10)))) -> - | AT17: =IF(AN17="-", "-", IF(AQ17="-", "-", IF(ABS(AQ17)=0, "-", ROUND(100*(AN17-AQ17)/ABS(AQ17),10)))) -> - | BB17: =IF(AV17="-", "-", IF(AY17="-", "-", IF(ABS(AY17)=0, "-", ROUND(100*(AV17-AY17)/ABS(AY17),10)))) -> -
A18: 労働費 | N18: =IF(H18="-", "-", IF(K18="-", "-", IF(ABS(K18)=0, "-", ROUND(100*(H18-K18)/ABS(K18),10)))) -> - | V18: =IF(P18="-", "-", IF(S18="-", "-", IF(ABS(S18)=0, "-", ROUND(100*(P18-S18)/ABS(S18),10)))) -> - | AD18: =IF(X18="-", "-", IF(AA18="-", "-", IF(ABS(AA18)=0, "-", ROUND(100*(X18-AA18)/ABS(AA18),10)))) -> - | AL18: =IF(AF18="-", "-", IF(AI18="-", "-", IF(ABS(AI18)=0, "-", ROUND(100*(AF18-AI18)/ABS(AI18),10)))) -> - | AT18: =IF(AN18="-", "-", IF(AQ18="-", "-", IF(ABS(AQ18)=0, "-", ROUND(100*(AN18-AQ18)/ABS(AQ18),10)))) -> - | BB18: =IF(AV18="-", "-", IF(AY18="-", "-", IF(ABS(AY18)=0, "-", ROUND(100*(AV18-AY18)/ABS(AY18),10)))) -> -
