Workbook
Name 経費範囲: #REF!
Name 現場調査費: #REF!
Name 現調単価: #REF!
Name 合計: #REF!
Name 材料範囲: #REF!
Name 諸経費率: #REF!
Name 範囲: #REF!
Name 労務範囲: #REF!

Sheet No.1
B1: =AB4 -> 0 | E1: 年産 米生産費統計結果（組織法人経営体） 集計結果検討表 Ｎｏ．１
G3: 集計番号 | J3: 集計名称 | Q3: 集計経営体数 | V3: 集計倍率 | AB3: 調査年 | AG3: 都道府県等 | AL3: 経営種類 | AQ3: 生産費区分 | AV3: 規模階層 | BA3: 平均値種類 | BF3: 加重・総和の別 | BK3: 集計区分
B4: 本年産 | AH4: =IF(AG4<>"",DGET(リスト!A2:B71,"都道府県番号",リスト!B73:B74),"") | AM4: =IF(AL4>0,DGET(リスト!S2:T4,"経営種類",リスト!T6:T7),"") | AR4: =IF(AQ4>0,DGET(リスト!D2:E13,"生産費区分",リスト!E15:E16),"") | AW4: =IF(AV4<>"",DGET(リスト!J3:K17,"規模階層",リスト!K19:K20),"") | BB4: =IF(BA4<>"",DGET(リスト!M2:N7,"平均値種類",リスト!N9:N10),"") | BG4: =IF(BF4>0,DGET(リスト!P2:Q4,"加重・総和の別",リスト!Q6:Q7),"") | BL4: =IF(BK4>0,DGET(リスト!G2:H7,"集計区分",リスト!H9:H10),"")
B5: 前年産
B7: １ 生産費総括 | AZ7: 単位：円 | BE7: ４ 調査作物収入 | CG7: 単位：円、kg
I8: 購入 | T8: 自給 | AE8: 償却 | AP8: 計 | BL8: 数量 | BW8: 価額
I9: =IF($B$1<>"",$B$1,"") -> 0 | M9: =IF($B$1<>"",$B$1-1,"") -> -1 | Q9: 増減率 | T9: =IF($B$1<>"",$B$1,"") -> 0 | X9: =IF($B$1<>"",$B$1-1,"") -> -1 | AB9: 増減率 | AE9: =IF($B$1<>"",$B$1,"") -> 0 | AI9: =IF($B$1<>"",$B$1-1,"") -> -1 | AM9: 増減率 | AP9: =IF($B$1<>"",$B$1,"") -> 0 | AT9: =IF($B$1<>"",$B$1-1,"") -> -1 | AX9: 増減率 | BL9: =IF($B$1<>"",$B$1,"") -> 0 | BP9: =IF($B$1<>"",$B$1-1,"") -> -1 | BT9: 増減率 | BW9: =IF($B$1<>"",$B$1,"") -> 0 | CA9: =IF($B$1<>"",$B$1-1,"") -> -1 | CE9: 増減率
B10: 物財費 | Q10: =IF(I10="-", "-", IF(M10="-", "-", IF(ABS(M10)=0, "-", ROUND(100*(I10-M10)/ABS(M10), 10)))) -> - | R10: =IF(N10="-", "-", IF(P10="-", "-", IF(ABS(P10)=0, "-", ROUND(100*(N10-P10)/ABS(P10), 1)))) -> - | S10: =IF(O10="-", "-", IF(Q10="-", "-", IF(ABS(Q10)=0, "-", ROUND(100*(O10-Q10)/ABS(Q10), 1)))) -> - | AB10: =IF(T10="-", "-", IF(X10="-", "-", IF(ABS(X10)=0, "-", ROUND(100*(T10-X10)/ABS(X10), 10)))) -> - | AC10: =IF(Y10="-", "-", IF(AA10="-", "-", IF(ABS(AA10)=0, "-", ROUND(100*(Y10-AA10)/ABS(AA10), 1)))) -> - | AD10: =IF(Z10="-", "-", IF(AB10="-", "-", IF(ABS(AB10)=0, "-", ROUND(100*(Z10-AB10)/ABS(AB10), 1)))) -> - | AM10: =IF(AE10="-", "-", IF(AI10="-", "-", IF(ABS(AI10)=0, "-", ROUND(100*(AE10-AI10)/ABS(AI10), 10)))) -> - | AN10: =IF(AJ10="-", "-", IF(AL10="-", "-", IF(ABS(AL10)=0, "-", ROUND(100*(AJ10-AL10)/ABS(AL10), 1)))) -> - | AO10: =IF(AK10="-", "-", IF(AM10="-", "-", IF(ABS(AM10)=0, "-", ROUND(100*(AK10-AM10)/ABS(AM10), 1)))) -> - | AX10: =IF(AP10="-", "-", IF(AT10="-", "-", IF(ABS(AT10)=0, "-", ROUND(100*(AP10-AT10)/ABS(AT10), 10)))) -> - | AY10: =IF(AU10="-", "-", IF(AW10="-", "-", IF(ABS(AW10)=0, "-", ROUND(100*(AU10-AW10)/ABS(AW10), 1)))) -> - | AZ10: =IF(AV10="-", "-", IF(AX10="-", "-", IF(ABS(AX10)=0, "-", ROUND(100*(AV10-AX10)/ABS(AX10), 1)))) -> - | BE10: 主産物 | BF10: 販売用 | BT10: =IF(BL10="-", "-", IF(BP10="-", "-", IF(ABS(BP10)=0, "-", ROUND(100*(BL10-BP10)/ABS(BP10), 10)))) -> - | BU10: =IF(BQ10="-", "-", IF(BS10="-", "-", IF(ABS(BS10)=0, "-", ROUND(100*(BQ10-BS10)/ABS(BS10), 1)))) -> - | BV10: =IF(BR10="-", "-", IF(BT10="-", "-", IF(ABS(BT10)=0, "-", ROUND(100*(BR10-BT10)/ABS(BT10), 1)))) -> - | CE10: =IF(BW10="-", "-", IF(CA10="-", "-", IF(ABS(CA10)=0, "-", ROUND(100*(BW10-CA10)/ABS(CA10), 10)))) -> - | CF10: =IF(CB10="-", "-", IF(CD10="-", "-", IF(ABS(CD10)=0, "-", ROUND(100*(CB10-CD10)/ABS(CD10), 1)))) -> - | CG10: =IF(CC10="-", "-", IF(CE10="-", "-", IF(ABS(CE10)=0, "-", ROUND(100*(CC10-CE10)/ABS(CE10), 1)))) -> -
C11: 種苗費 | Q11: =IF(I11="-", "-", IF(M11="-", "-", IF(ABS(M11)=0, "-", ROUND(100*(I11-M11)/ABS(M11), 10)))) -> - | R11: =IF(N11="-", "-", IF(P11="-", "-", IF(ABS(P11)=0, "-", ROUND(100*(N11-P11)/ABS(P11), 1)))) -> - | S11: =IF(O11="-", "-", IF(Q11="-", "-", IF(ABS(Q11)=0, "-", ROUND(100*(O11-Q11)/ABS(Q11), 1)))) -> - | AB11: =IF(T11="-", "-", IF(X11="-", "-", IF(ABS(X11)=0, "-", ROUND(100*(T11-X11)/ABS(X11), 10)))) -> - | AC11: =IF(Y11="-", "-", IF(AA11="-", "-", IF(ABS(AA11)=0, "-", ROUND(100*(Y11-AA11)/ABS(AA11), 1)))) -> - | AD11: =IF(Z11="-", "-", IF(AB11="-", "-", IF(ABS(AB11)=0, "-", ROUND(100*(Z11-AB11)/ABS(AB11), 1)))) -> - | AX11: =IF(AP11="-", "-", IF(AT11="-", "-", IF(ABS(AT11)=0, "-", ROUND(100*(AP11-AT11)/ABS(AT11), 10)))) -> - | AY11: =IF(AU11="-", "-", IF(AW11="-", "-", IF(ABS(AW11)=0, "-", ROUND(100*(AU11-AW11)/ABS(AW11), 1)))) -> - | AZ11: =IF(AV11="-", "-", IF(AX11="-", "-", IF(ABS(AX11)=0, "-", ROUND(100*(AV11-AX11)/ABS(AX11), 1)))) -> - | BF11: 組織用 | BT11: =IF(BL11="-", "-", IF(BP11="-", "-", IF(ABS(BP11)=0, "-", ROUND(100*(BL11-BP11)/ABS(BP11), 10)))) -> - | BU11: =IF(BQ11="-", "-", IF(BS11="-", "-", IF(ABS(BS11)=0, "-", ROUND(100*(BQ11-BS11)/ABS(BS11), 1)))) -> - | BV11: =IF(BR11="-", "-", IF(BT11="-", "-", IF(ABS(BT11)=0, "-", ROUND(100*(BR11-BT11)/ABS(BT11), 1)))) -> - | CE11: =IF(BW11="-", "-", IF(CA11="-", "-", IF(ABS(CA11)=0, "-", ROUND(100*(BW11-CA11)/ABS(CA11), 10)))) -> - | CF11: =IF(CB11="-", "-", IF(CD11="-", "-", IF(ABS(CD11)=0, "-", ROUND(100*(CB11-CD11)/ABS(CD11), 1)))) -> - | CG11: =IF(CC11="-", "-", IF(CE11="-", "-", IF(ABS(CE11)=0, "-", ROUND(100*(CC11-CE11)/ABS(CE11), 1)))) -> -
C12: 肥料費 | Q12: =IF(I12="-", "-", IF(M12="-", "-", IF(ABS(M12)=0, "-", ROUND(100*(I12-M12)/ABS(M12), 10)))) -> - | R12: =IF(N12="-", "-", IF(P12="-", "-", IF(ABS(P12)=0, "-", ROUND(100*(N12-P12)/ABS(P12), 1)))) -> - | S12: =IF(O12="-", "-", IF(Q12="-", "-", IF(ABS(Q12)=0, "-", ROUND(100*(O12-Q12)/ABS(Q12), 1)))) -> - | AB12: =IF(T12="-", "-", IF(X12="-", "-", IF(ABS(X12)=0, "-", ROUND(100*(T12-X12)/ABS(X12), 10)))) -> - | AC12: =IF(Y12="-", "-", IF(AA12="-", "-", IF(ABS(AA12)=0, "-", ROUND(100*(Y12-AA12)/ABS(AA12), 1)))) -> - | AD12: =IF(Z12="-", "-", IF(AB12="-", "-", IF(ABS(AB12)=0, "-", ROUND(100*(Z12-AB12)/ABS(AB12), 1)))) -> - | AX12: =IF(AP12="-", "-", IF(AT12="-", "-", IF(ABS(AT12)=0, "-", ROUND(100*(AP12-AT12)/ABS(AT12), 10)))) -> - | AY12: =IF(AU12="-", "-", IF(AW12="-", "-", IF(ABS(AW12)=0, "-", ROUND(100*(AU12-AW12)/ABS(AW12), 1)))) -> - | AZ12: =IF(AV12="-", "-", IF(AX12="-", "-", IF(ABS(AX12)=0, "-", ROUND(100*(AV12-AX12)/ABS(AX12), 1)))) -> - | BF12: 計 | BT12: =IF(BL12="-", "-", IF(BP12="-", "-", IF(ABS(BP12)=0, "-", ROUND(100*(BL12-BP12)/ABS(BP12), 10)))) -> - | BU12: =IF(BQ12="-", "-", IF(BS12="-", "-", IF(ABS(BS12)=0, "-", ROUND(100*(BQ12-BS12)/ABS(BS12), 1)))) -> - | BV12: =IF(BR12="-", "-", IF(BT12="-", "-", IF(ABS(BT12)=0, "-", ROUND(100*(BR12-BT12)/ABS(BT12), 1)))) -> - | CE12: =IF(BW12="-", "-", IF(CA12="-", "-", IF(ABS(CA12)=0, "-", ROUND(100*(BW12-CA12)/ABS(CA12), 10)))) -> - | CF12: =IF(CB12="-", "-", IF(CD12="-", "-", IF(ABS(CD12)=0, "-", ROUND(100*(CB12-CD12)/ABS(CD12), 1)))) -> - | CG12: =IF(CC12="-", "-", IF(CE12="-", "-", IF(ABS(CE12)=0, "-", ROUND(100*(CC12-CE12)/ABS(CE12), 1)))) -> -
C13: 農業薬剤費 | Q13: =IF(I13="-", "-", IF(M13="-", "-", IF(ABS(M13)=0, "-", ROUND(100*(I13-M13)/ABS(M13), 10)))) -> - | R13: =IF(N13="-", "-", IF(P13="-", "-", IF(ABS(P13)=0, "-", ROUND(100*(N13-P13)/ABS(P13), 1)))) -> - | S13: =IF(O13="-", "-", IF(Q13="-", "-", IF(ABS(Q13)=0, "-", ROUND(100*(O13-Q13)/ABS(Q13), 1)))) -> - | AX13: =IF(AP13="-", "-", IF(AT13="-", "-", IF(ABS(AT13)=0, "-", ROUND(100*(AP13-AT13)/ABS(AT13), 10)))) -> - | AY13: =IF(AU13="-", "-", IF(AW13="-", "-", IF(ABS(AW13)=0, "-", ROUND(100*(AU13-AW13)/ABS(AW13), 1)))) -> - | AZ13: =IF(AV13="-", "-", IF(AX13="-", "-", IF(ABS(AX13)=0, "-", ROUND(100*(AV13-AX13)/ABS(AX13), 1)))) -> - | BE13: 副産物 | BF13: くず米 | BT13: =IF(BL13="-", "-", IF(BP13="-", "-", IF(ABS(BP13)=0, "-", ROUND(100*(BL13-BP13)/ABS(BP13), 10)))) -> - | BU13: =IF(BQ13="-", "-", IF(BS13="-", "-", IF(ABS(BS13)=0, "-", ROUND(100*(BQ13-BS13)/ABS(BS13), 1)))) -> - | BV13: =IF(BR13="-", "-", IF(BT13="-", "-", IF(ABS(BT13)=0, "-", ROUND(100*(BR13-BT13)/ABS(BT13), 1)))) -> - | CE13: =IF(BW13="-", "-", IF(CA13="-", "-", IF(ABS(CA13)=0, "-", ROUND(100*(BW13-CA13)/ABS(CA13), 10)))) -> - | CF13: =IF(CB13="-", "-", IF(CD13="-", "-", IF(ABS(CD13)=0, "-", ROUND(100*(CB13-CD13)/ABS(CD13), 1)))) -> - | CG13: =IF(CC13="-", "-", IF(CE13="-", "-", IF(ABS(CE13)=0, "-", ROUND(100*(CC13-CE13)/ABS(CE13), 1)))) -> -
C14: 光熱動力費 | Q14: =IF(I14="-", "-", IF(M14="-", "-", IF(ABS(M14)=0, "-", ROUND(100*(I14-M14)/ABS(M14), 10)))) -> - | R14: =IF(N14="-", "-", IF(P14="-", "-", IF(ABS(P14)=0, "-", ROUND(100*(N14-P14)/ABS(P14), 1)))) -> - | S14: =IF(O14="-", "-", IF(Q14="-", "-", IF(ABS(Q14)=0, "-", ROUND(100*(O14-Q14)/ABS(Q14), 1)))) -> - | AB14: =IF(T14="-", "-", IF(X14="-", "-", IF(ABS(X14)=0, "-", ROUND(100*(T14-X14)/ABS(X14), 10)))) -> - | AC14: =IF(Y14="-", "-", IF(AA14="-", "-", IF(ABS(AA14)=0, "-", ROUND(100*(Y14-AA14)/ABS(AA14), 1)))) -> - | AD14: =IF(Z14="-", "-", IF(AB14="-", "-", IF(ABS(AB14)=0, "-", ROUND(100*(Z14-AB14)/ABS(AB14), 1)))) -> - | AX14: =IF(AP14="-", "-", IF(AT14="-", "-", IF(ABS(AT14)=0, "-", ROUND(100*(AP14-AT14)/ABS(AT14), 10)))) -> - | AY14: =IF(AU14="-", "-", IF(AW14="-", "-", IF(ABS(AW14)=0, "-", ROUND(100*(AU14-AW14)/ABS(AW14), 1)))) -> - | AZ14: =IF(AV14="-", "-", IF(AX14="-", "-", IF(ABS(AX14)=0, "-", ROUND(100*(AV14-AX14)/ABS(AX14), 1)))) -> - | BF14: 稲わら(もみがら含む) | BT14: =IF(BL14="-", "-", IF(BP14="-", "-", IF(ABS(BP14)=0, "-", ROUND(100*(BL14-BP14)/ABS(BP14), 10)))) -> - | BU14: =IF(BQ14="-", "-", IF(BS14="-", "-", IF(ABS(BS14)=0, "-", ROUND(100*(BQ14-BS14)/ABS(BS14), 1)))) -> - | BV14: =IF(BR14="-", "-", IF(BT14="-", "-", IF(ABS(BT14)=0, "-", ROUND(100*(BR14-BT14)/ABS(BT14), 1)))) -> - | CE14: =IF(BW14="-", "-", IF(CA14="-", "-", IF(ABS(CA14)=0, "-", ROUND(100*(BW14-CA14)/ABS(CA14), 10)))) -> - | CF14: =IF(CB14="-", "-", IF(CD14="-", "-", IF(ABS(CD14)=0, "-", ROUND(100*(CB14-CD14)/ABS(CD14), 1)))) -> - | CG14: =IF(CC14="-", "-", IF(CE14="-", "-", IF(ABS(CE14)=0, "-", ROUND(100*(CC14-CE14)/ABS(CE14), 1)))) -> -
C15: その他の諸材料費 | Q15: =IF(I15="-", "-", IF(M15="-", "-", IF(ABS(M15)=0, "-", ROUND(100*(I15-M15)/ABS(M15), 10)))) -> - | R15: =IF(N15="-", "-", IF(P15="-", "-", IF(ABS(P15)=0, "-", ROUND(100*(N15-P15)/ABS(P15), 1)))) -> - | S15: =IF(O15="-", "-", IF(Q15="-", "-", IF(ABS(Q15)=0, "-", ROUND(100*(O15-Q15)/ABS(Q15), 1)))) -> - | AB15: =IF(T15="-", "-", IF(X15="-", "-", IF(ABS(X15)=0, "-", ROUND(100*(T15-X15)/ABS(X15), 10)))) -> - | AC15: =IF(Y15="-", "-", IF(AA15="-", "-", IF(ABS(AA15)=0, "-", ROUND(100*(Y15-AA15)/ABS(AA15), 1)))) -> - | AD15: =IF(Z15="-", "-", IF(AB15="-", "-", IF(ABS(AB15)=0, "-", ROUND(100*(Z15-AB15)/ABS(AB15), 1)))) -> - | AX15: =IF(AP15="-", "-", IF(AT15="-", "-", IF(ABS(AT15)=0, "-", ROUND(100*(AP15-AT15)/ABS(AT15), 10)))) -> - | AY15: =IF(AU15="-", "-", IF(AW15="-", "-", IF(ABS(AW15)=0, "-", ROUND(100*(AU15-AW15)/ABS(AW15), 1)))) -> - | AZ15: =IF(AV15="-", "-", IF(AX15="-", "-", IF(ABS(AX15)=0, "-", ROUND(100*(AV15-AX15)/ABS(AX15), 1)))) -> - | BF15: 計 | CE15: =IF(BW15="-", "-", IF(CA15="-", "-", IF(ABS(CA15)=0, "-", ROUND(100*(BW15-CA15)/ABS(CA15), 10)))) -> - | CF15: =IF(CB15="-", "-", IF(CD15="-", "-", IF(ABS(CD15)=0, "-", ROUND(100*(CB15-CD15)/ABS(CD15), 1)))) -> - | CG15: =IF(CC15="-", "-", IF(CE15="-", "-", IF(ABS(CE15)=0, "-", ROUND(100*(CC15-CE15)/ABS(CE15), 1)))) -> -
C16: 土地改良及び水利費 | Q16: =IF(I16="-", "-", IF(M16="-", "-", IF(ABS(M16)=0, "-", ROUND(100*(I16-M16)/ABS(M16), 10)))) -> - | R16: =IF(N16="-", "-", IF(P16="-", "-", IF(ABS(P16)=0, "-", ROUND(100*(N16-P16)/ABS(P16), 1)))) -> - | S16: =IF(O16="-", "-", IF(Q16="-", "-", IF(ABS(Q16)=0, "-", ROUND(100*(O16-Q16)/ABS(Q16), 1)))) -> - | AX16: =IF(AP16="-", "-", IF(AT16="-", "-", IF(ABS(AT16)=0, "-", ROUND(100*(AP16-AT16)/ABS(AT16), 10)))) -> - | AY16: =IF(AU16="-", "-", IF(AW16="-", "-", IF(ABS(AW16)=0, "-", ROUND(100*(AU16-AW16)/ABS(AW16), 1)))) -> - | AZ16: =IF(AV16="-", "-", IF(AX16="-", "-", IF(ABS(AX16)=0, "-", ROUND(100*(AV16-AX16)/ABS(AX16), 1)))) -> - | BE16: 粗収益 | CE16: =IF(BW16="-", "-", IF(CA16="-", "-", IF(ABS(CA16)=0, "-", ROUND(100*(BW16-CA16)/ABS(CA16), 10)))) -> - | CF16: =IF(CB16="-", "-", IF(CD16="-", "-", IF(ABS(CD16)=0, "-", ROUND(100*(CB16-CD16)/ABS(CD16), 1)))) -> - | CG16: =IF(CC16="-", "-", IF(CE16="-", "-", IF(ABS(CE16)=0, "-", ROUND(100*(CC16-CE16)/ABS(CE16), 1)))) -> -
C17: 賃借料及び料金 | Q17: =IF(I17="-", "-", IF(M17="-", "-", IF(ABS(M17)=0, "-", ROUND(100*(I17-M17)/ABS(M17), 10)))) -> - | R17: =IF(N17="-", "-", IF(P17="-", "-", IF(ABS(P17)=0, "-", ROUND(100*(N17-P17)/ABS(P17), 1)))) -> - | S17: =IF(O17="-", "-", IF(Q17="-", "-", IF(ABS(Q17)=0, "-", ROUND(100*(O17-Q17)/ABS(Q17), 1)))) -> - | AX17: =IF(AP17="-", "-", IF(AT17="-", "-", IF(ABS(AT17)=0, "-", ROUND(100*(AP17-AT17)/ABS(AT17), 10)))) -> - | AY17: =IF(AU17="-", "-", IF(AW17="-", "-", IF(ABS(AW17)=0, "-", ROUND(100*(AU17-AW17)/ABS(AW17), 1)))) -> - | AZ17: =IF(AV17="-", "-", IF(AX17="-", "-", IF(ABS(AX17)=0, "-", ROUND(100*(AV17-AX17)/ABS(AX17), 1)))) -> -
C18: 物件税及び公課諸負担 | Q18: =IF(I18="-", "-", IF(M18="-", "-", IF(ABS(M18)=0, "-", ROUND(100*(I18-M18)/ABS(M18), 10)))) -> - | R18: =IF(N18="-", "-", IF(P18="-", "-", IF(ABS(P18)=0, "-", ROUND(100*(N18-P18)/ABS(P18), 1)))) -> - | S18: =IF(O18="-", "-", IF(Q18="-", "-", IF(ABS(Q18)=0, "-", ROUND(100*(O18-Q18)/ABS(Q18), 1)))) -> - | AX18: =IF(AP18="-", "-", IF(AT18="-", "-", IF(ABS(AT18)=0, "-", ROUND(100*(AP18-AT18)/ABS(AT18), 10)))) -> - | AY18: =IF(AU18="-", "-", IF(AW18="-", "-", IF(ABS(AW18)=0, "-", ROUND(100*(AU18-AW18)/ABS(AW18), 1)))) -> - | AZ18: =IF(AV18="-", "-", IF(AX18="-", "-", IF(ABS(AX18)=0, "-", ROUND(100*(AV18-AX18)/ABS(AX18), 1)))) -> -
C19: 建物費 | Q19: =IF(I19="-", "-", IF(M19="-", "-", IF(ABS(M19)=0, "-", ROUND(100*(I19-M19)/ABS(M19), 10)))) -> - | R19: =IF(N19="-", "-", IF(P19="-", "-", IF(ABS(P19)=0, "-", ROUND(100*(N19-P19)/ABS(P19), 1)))) -> - | S19: =IF(O19="-", "-", IF(Q19="-", "-", IF(ABS(Q19)=0, "-", ROUND(100*(O19-Q19)/ABS(Q19), 1)))) -> - | AM19: =IF(AE19="-", "-", IF(AI19="-", "-", IF(ABS(AI19)=0, "-", ROUND(100*(AE19-AI19)/ABS(AI19), 10)))) -> - | AN19: =IF(AJ19="-", "-", IF(AL19="-", "-", IF(ABS(AL19)=0, "-", ROUND(100*(AJ19-AL19)/ABS(AL19), 1)))) -> - | AO19: =IF(AK19="-", "-", IF(AM19="-", "-", IF(ABS(AM19)=0, "-", ROUND(100*(AK19-AM19)/ABS(AM19), 1)))) -> - | AX19: =IF(AP19="-", "-", IF(AT19="-", "-", IF(ABS(AT19)=0, "-", ROUND(100*(AP19-AT19)/ABS(AT19), 10)))) -> - | AY19: =IF(AU19="-", "-", IF(AW19="-", "-", IF(ABS(AW19)=0, "-", ROUND(100*(AU19-AW19)/ABS(AW19), 1)))) -> - | AZ19: =IF(AV19="-", "-", IF(AX19="-", "-", IF(ABS(AX19)=0, "-", ROUND(100*(AV19-AX19)/ABS(AX19), 1)))) -> -
C20: 自動車費 | Q20: =IF(I20="-", "-", IF(M20="-", "-", IF(ABS(M20)=0, "-", ROUND(100*(I20-M20)/ABS(M20), 10)))) -> - | R20: =IF(N20="-", "-", IF(P20="-", "-", IF(ABS(P20)=0, "-", ROUND(100*(N20-P20)/ABS(P20), 1)))) -> - | S20: =IF(O20="-", "-", IF(Q20="-", "-", IF(ABS(Q20)=0, "-", ROUND(100*(O20-Q20)/ABS(Q20), 1)))) -> - | AM20: =IF(AE20="-", "-", IF(AI20="-", "-", IF(ABS(AI20)=0, "-", ROUND(100*(AE20-AI20)/ABS(AI20), 10)))) -> - | AN20: =IF(AJ20="-", "-", IF(AL20="-", "-", IF(ABS(AL20)=0, "-", ROUND(100*(AJ20-AL20)/ABS(AL20), 1)))) -> - | AO20: =IF(AK20="-", "-", IF(AM20="-", "-", IF(ABS(AM20)=0, "-", ROUND(100*(AK20-AM20)/ABS(AM20), 1)))) -> - | AX20: =IF(AP20="-", "-", IF(AT20="-", "-", IF(ABS(AT20)=0, "-", ROUND(100*(AP20-AT20)/ABS(AT20), 10)))) -> - | AY20: =IF(AU20="-", "-", IF(AW20="-", "-", IF(ABS(AW20)=0, "-", ROUND(100*(AU20-AW20)/ABS(AW20), 1)))) -> - | AZ20: =IF(AV20="-", "-", IF(AX20="-", "-", IF(ABS(AX20)=0, "-", ROUND(100*(AV20-AX20)/ABS(AX20), 1)))) -> -
C21: 農機具費 | Q21: =IF(I21="-", "-", IF(M21="-", "-", IF(ABS(M21)=0, "-", ROUND(100*(I21-M21)/ABS(M21), 10)))) -> - | R21: =IF(N21="-", "-", IF(P21="-", "-", IF(ABS(P21)=0, "-", ROUND(100*(N21-P21)/ABS(P21), 1)))) -> - | S21: =IF(O21="-", "-", IF(Q21="-", "-", IF(ABS(Q21)=0, "-", ROUND(100*(O21-Q21)/ABS(Q21), 1)))) -> - | AM21: =IF(AE21="-", "-", IF(AI21="-", "-", IF(ABS(AI21)=0, "-", ROUND(100*(AE21-AI21)/ABS(AI21), 10)))) -> - | AN21: =IF(AJ21="-", "-", IF(AL21="-", "-", IF(ABS(AL21)=0, "-", ROUND(100*(AJ21-AL21)/ABS(AL21), 1)))) -> - | AO21: =IF(AK21="-", "-", IF(AM21="-", "-", IF(ABS(AM21)=0, "-", ROUND(100*(AK21-AM21)/ABS(AM21), 1)))) -> - | AX21: =IF(AP21="-", "-", IF(AT21="-", "-", IF(ABS(AT21)=0, "-", ROUND(100*(AP21-AT21)/ABS(AT21), 10)))) -> - | AY21: =IF(AU21="-", "-", IF(AW21="-", "-", IF(ABS(AW21)=0, "-", ROUND(100*(AU21-AW21)/ABS(AW21), 1)))) -> - | AZ21: =IF(AV21="-", "-", IF(AX21="-", "-", IF(ABS(AX21)=0, "-", ROUND(100*(AV21-AX21)/ABS(AX21), 1)))) -> - | BE21: ５ 収益性 | BV21: 単位：円
C22: 生産管理費 | Q22: =IF(I22="-", "-", IF(M22="-", "-", IF(ABS(M22)=0, "-", ROUND(100*(I22-M22)/ABS(M22), 10)))) -> - | R22: =IF(N22="-", "-", IF(P22="-", "-", IF(ABS(P22)=0, "-", ROUND(100*(N22-P22)/ABS(P22), 1)))) -> - | S22: =IF(O22="-", "-", IF(Q22="-", "-", IF(ABS(Q22)=0, "-", ROUND(100*(O22-Q22)/ABS(Q22), 1)))) -> - | AM22: =IF(AE22="-", "-", IF(AI22="-", "-", IF(ABS(AI22)=0, "-", ROUND(100*(AE22-AI22)/ABS(AI22), 10)))) -> - | AN22: =IF(AJ22="-", "-", IF(AL22="-", "-", IF(ABS(AL22)=0, "-", ROUND(100*(AJ22-AL22)/ABS(AL22), 1)))) -> - | AO22: =IF(AK22="-", "-", IF(AM22="-", "-", IF(ABS(AM22)=0, "-", ROUND(100*(AK22-AM22)/ABS(AM22), 1)))) -> - | AX22: =IF(AP22="-", "-", IF(AT22="-", "-", IF(ABS(AT22)=0, "-", ROUND(100*(AP22-AT22)/ABS(AT22), 10)))) -> - | AY22: =IF(AU22="-", "-", IF(AW22="-", "-", IF(ABS(AW22)=0, "-", ROUND(100*(AU22-AW22)/ABS(AW22), 1)))) -> - | AZ22: =IF(AV22="-", "-", IF(AX22="-", "-", IF(ABS(AX22)=0, "-", ROUND(100*(AV22-AX22)/ABS(AX22), 1)))) -> - | BL22: =IF($B$1<>"",$B$1,"") -> 0 | BP22: =IF($B$1<>"",$B$1-1,"") -> -1 | BT22: 増減率
B23: 労働費 | Q23: =IF(I23="-", "-", IF(M23="-", "-", IF(ABS(M23)=0, "-", ROUND(100*(I23-M23)/ABS(M23), 10)))) -> - | R23: =IF(N23="-", "-", IF(P23="-", "-", IF(ABS(P23)=0, "-", ROUND(100*(N23-P23)/ABS(P23), 1)))) -> - | S23: =IF(O23="-", "-", IF(Q23="-", "-", IF(ABS(Q23)=0, "-", ROUND(100*(O23-Q23)/ABS(Q23), 1)))) -> - | AB23: =IF(T23="-", "-", IF(X23="-", "-", IF(ABS(X23)=0, "-", ROUND(100*(T23-X23)/ABS(X23), 10)))) -> - | AC23: =IF(Y23="-", "-", IF(AA23="-", "-", IF(ABS(AA23)=0, "-", ROUND(100*(Y23-AA23)/ABS(AA23), 1)))) -> - | AD23: =IF(Z23="-", "-", IF(AB23="-", "-", IF(ABS(AB23)=0, "-", ROUND(100*(Z23-AB23)/ABS(AB23), 1)))) -> - | AX23: =IF(AP23="-", "-", IF(AT23="-", "-", IF(ABS(AT23)=0, "-", ROUND(100*(AP23-AT23)/ABS(AT23), 10)))) -> - | AY23: =IF(AU23="-", "-", IF(AW23="-", "-", IF(ABS(AW23)=0, "-", ROUND(100*(AU23-AW23)/ABS(AW23), 1)))) -> - | AZ23: =IF(AV23="-", "-", IF(AX23="-", "-", IF(ABS(AX23)=0, "-", ROUND(100*(AV23-AX23)/ABS(AX23), 1)))) -> - | BE23: 粗収益 | BT23: =IF(BL23="-", "-", IF(BP23="-", "-", IF(ABS(BP23)=0, "-", ROUND(100*(BL23-BP23)/ABS(BP23), 10)))) -> - | BU23: =IF(BQ23="-", "-", IF(BS23="-", "-", IF(ABS(BS23)=0, "-", ROUND(100*(BQ23-BS23)/ABS(BS23), 1)))) -> - | BV23: =IF(BR23="-", "-", IF(BT23="-", "-", IF(ABS(BT23)=0, "-", ROUND(100*(BR23-BT23)/ABS(BT23), 1)))) -> -
C24: 直接労働費 | Q24: =IF(I24="-", "-", IF(M24="-", "-", IF(ABS(M24)=0, "-", ROUND(100*(I24-M24)/ABS(M24), 10)))) -> - | R24: =IF(N24="-", "-", IF(P24="-", "-", IF(ABS(P24)=0, "-", ROUND(100*(N24-P24)/ABS(P24), 1)))) -> - | S24: =IF(O24="-", "-", IF(Q24="-", "-", IF(ABS(Q24)=0, "-", ROUND(100*(O24-Q24)/ABS(Q24), 1)))) -> - | AB24: =IF(T24="-", "-", IF(X24="-", "-", IF(ABS(X24)=0, "-", ROUND(100*(T24-X24)/ABS(X24), 10)))) -> - | AC24: =IF(Y24="-", "-", IF(AA24="-", "-", IF(ABS(AA24)=0, "-", ROUND(100*(Y24-AA24)/ABS(AA24), 1)))) -> - | AD24: =IF(Z24="-", "-", IF(AB24="-", "-", IF(ABS(AB24)=0, "-", ROUND(100*(Z24-AB24)/ABS(AB24), 1)))) -> - | AX24: =IF(AP24="-", "-", IF(AT24="-", "-", IF(ABS(AT24)=0, "-", ROUND(100*(AP24-AT24)/ABS(AT24), 10)))) -> - | AY24: =IF(AU24="-", "-", IF(AW24="-", "-", IF(ABS(AW24)=0, "-", ROUND(100*(AU24-AW24)/ABS(AW24), 1)))) -> - | AZ24: =IF(AV24="-", "-", IF(AX24="-", "-", IF(ABS(AX24)=0, "-", ROUND(100*(AV24-AX24)/ABS(AX24), 1)))) -> - | BE24: 生産費総額 | BT24: =IF(BL24="-", "-", IF(BP24="-", "-", IF(ABS(BP24)=0, "-", ROUND(100*(BL24-BP24)/ABS(BP24), 10)))) -> - | BU24: =IF(BQ24="-", "-", IF(BS24="-", "-", IF(ABS(BS24)=0, "-", ROUND(100*(BQ24-BS24)/ABS(BS24), 1)))) -> - | BV24: =IF(BR24="-", "-", IF(BT24="-", "-", IF(ABS(BT24)=0, "-", ROUND(100*(BR24-BT24)/ABS(BT24), 1)))) -> -
C25: 間接労働費 | Q25: =IF(I25="-", "-", IF(M25="-", "-", IF(ABS(M25)=0, "-", ROUND(100*(I25-M25)/ABS(M25), 10)))) -> - | R25: =IF(N25="-", "-", IF(P25="-", "-", IF(ABS(P25)=0, "-", ROUND(100*(N25-P25)/ABS(P25), 1)))) -> - | S25: =IF(O25="-", "-", IF(Q25="-", "-", IF(ABS(Q25)=0, "-", ROUND(100*(O25-Q25)/ABS(Q25), 1)))) -> - | AB25: =IF(T25="-", "-", IF(X25="-", "-", IF(ABS(X25)=0, "-", ROUND(100*(T25-X25)/ABS(X25), 10)))) -> - | AC25: =IF(Y25="-", "-", IF(AA25="-", "-", IF(ABS(AA25)=0, "-", ROUND(100*(Y25-AA25)/ABS(AA25), 1)))) -> - | AD25: =IF(Z25="-", "-", IF(AB25="-", "-", IF(ABS(AB25)=0, "-", ROUND(100*(Z25-AB25)/ABS(AB25), 1)))) -> - | AX25: =IF(AP25="-", "-", IF(AT25="-", "-", IF(ABS(AT25)=0, "-", ROUND(100*(AP25-AT25)/ABS(AT25), 10)))) -> - | AY25: =IF(AU25="-", "-", IF(AW25="-", "-", IF(ABS(AW25)=0, "-", ROUND(100*(AU25-AW25)/ABS(AW25), 1)))) -> - | AZ25: =IF(AV25="-", "-", IF(AX25="-", "-", IF(ABS(AX25)=0, "-", ROUND(100*(AV25-AX25)/ABS(AX25), 1)))) -> - | BE25: 利潤 | BT25: =IF(BL25="-", "-", IF(BP25="-", "-", IF(ABS(BP25)=0, "-", ROUND(100*(BL25-BP25)/ABS(BP25), 10)))) -> - | BU25: =IF(BQ25="-", "-", IF(BS25="-", "-", IF(ABS(BS25)=0, "-", ROUND(100*(BQ25-BS25)/ABS(BS25), 1)))) -> - | BV25: =IF(BR25="-", "-", IF(BT25="-", "-", IF(ABS(BT25)=0, "-", ROUND(100*(BR25-BT25)/ABS(BT25), 1)))) -> -
B26: 費用合計 | Q26: =IF(I26="-", "-", IF(M26="-", "-", IF(ABS(M26)=0, "-", ROUND(100*(I26-M26)/ABS(M26), 10)))) -> - | R26: =IF(N26="-", "-", IF(P26="-", "-", IF(ABS(P26)=0, "-", ROUND(100*(N26-P26)/ABS(P26), 1)))) -> - | S26: =IF(O26="-", "-", IF(Q26="-", "-", IF(ABS(Q26)=0, "-", ROUND(100*(O26-Q26)/ABS(Q26), 1)))) -> - | AB26: =IF(T26="-", "-", IF(X26="-", "-", IF(ABS(X26)=0, "-", ROUND(100*(T26-X26)/ABS(X26), 10)))) -> - | AC26: =IF(Y26="-", "-", IF(AA26="-", "-", IF(ABS(AA26)=0, "-", ROUND(100*(Y26-AA26)/ABS(AA26), 1)))) -> - | AD26: =IF(Z26="-", "-", IF(AB26="-", "-", IF(ABS(AB26)=0, "-", ROUND(100*(Z26-AB26)/ABS(AB26), 1)))) -> - | AM26: =IF(AE26="-", "-", IF(AI26="-", "-", IF(ABS(AI26)=0, "-", ROUND(100*(AE26-AI26)/ABS(AI26), 10)))) -> - | AN26: =IF(AJ26="-", "-", IF(AL26="-", "-", IF(ABS(AL26)=0, "-", ROUND(100*(AJ26-AL26)/ABS(AL26), 1)))) -> - | AO26: =IF(AK26="-", "-", IF(AM26="-", "-", IF(ABS(AM26)=0, "-", ROUND(100*(AK26-AM26)/ABS(AM26), 1)))) -> - | AX26: =IF(AP26="-", "-", IF(AT26="-", "-", IF(ABS(AT26)=0, "-", ROUND(100*(AP26-AT26)/ABS(AT26), 10)))) -> - | AY26: =IF(AU26="-", "-", IF(AW26="-", "-", IF(ABS(AW26)=0, "-", ROUND(100*(AU26-AW26)/ABS(AW26), 1)))) -> - | AZ26: =IF(AV26="-", "-", IF(AX26="-", "-", IF(ABS(AX26)=0, "-", ROUND(100*(AV26-AX26)/ABS(AX26), 1)))) -> - | BE26: 所得 | BT26: =IF(BL26="-", "-", IF(BP26="-", "-", IF(ABS(BP26)=0, "-", ROUND(100*(BL26-BP26)/ABS(BP26), 10)))) -> - | BU26: =IF(BQ26="-", "-", IF(BS26="-", "-", IF(ABS(BS26)=0, "-", ROUND(100*(BQ26-BS26)/ABS(BS26), 1)))) -> - | BV26: =IF(BR26="-", "-", IF(BT26="-", "-", IF(ABS(BT26)=0, "-", ROUND(100*(BR26-BT26)/ABS(BT26), 1)))) -> -
B27: 副産物価額 | AX27: =IF(AP27="-", "-", IF(AT27="-", "-", IF(ABS(AT27)=0, "-", ROUND(100*(AP27-AT27)/ABS(AT27), 10)))) -> - | AY27: =IF(AU27="-", "-", IF(AW27="-", "-", IF(ABS(AW27)=0, "-", ROUND(100*(AU27-AW27)/ABS(AW27), 1)))) -> - | AZ27: =IF(AV27="-", "-", IF(AX27="-", "-", IF(ABS(AX27)=0, "-", ROUND(100*(AV27-AX27)/ABS(AX27), 1)))) -> - | BF27: １日当たり | BT27: =IF(BL27="-", "-", IF(BP27="-", "-", IF(ABS(BP27)=0, "-", ROUND(100*(BL27-BP27)/ABS(BP27), 10)))) -> - | BU27: =IF(BQ27="-", "-", IF(BS27="-", "-", IF(ABS(BS27)=0, "-", ROUND(100*(BQ27-BS27)/ABS(BS27), 1)))) -> - | BV27: =IF(BR27="-", "-", IF(BT27="-", "-", IF(ABS(BT27)=0, "-", ROUND(100*(BR27-BT27)/ABS(BT27), 1)))) -> -
B28: 生産費 | AX28: =IF(AP28="-", "-", IF(AT28="-", "-", IF(ABS(AT28)=0, "-", ROUND(100*(AP28-AT28)/ABS(AT28), 10)))) -> - | AY28: =IF(AU28="-", "-", IF(AW28="-", "-", IF(ABS(AW28)=0, "-", ROUND(100*(AU28-AW28)/ABS(AW28), 1)))) -> - | AZ28: =IF(AV28="-", "-", IF(AX28="-", "-", IF(ABS(AX28)=0, "-", ROUND(100*(AV28-AX28)/ABS(AX28), 1)))) -> - | BE28: 構成員労働報酬 | BT28: =IF(BL28="-", "-", IF(BP28="-", "-", IF(ABS(BP28)=0, "-", ROUND(100*(BL28-BP28)/ABS(BP28), 10)))) -> - | BU28: =IF(BQ28="-", "-", IF(BS28="-", "-", IF(ABS(BS28)=0, "-", ROUND(100*(BQ28-BS28)/ABS(BS28), 1)))) -> - | BV28: =IF(BR28="-", "-", IF(BT28="-", "-", IF(ABS(BT28)=0, "-", ROUND(100*(BR28-BT28)/ABS(BT28), 1)))) -> -
B29: 支払利子 | AX29: =IF(AP29="-", "-", IF(AT29="-", "-", IF(ABS(AT29)=0, "-", ROUND(100*(AP29-AT29)/ABS(AT29), 10)))) -> - | AY29: =IF(AU29="-", "-", IF(AW29="-", "-", IF(ABS(AW29)=0, "-", ROUND(100*(AU29-AW29)/ABS(AW29), 1)))) -> - | AZ29: =IF(AV29="-", "-", IF(AX29="-", "-", IF(ABS(AX29)=0, "-", ROUND(100*(AV29-AX29)/ABS(AX29), 1)))) -> - | BF29: １日当たり | BT29: =IF(BL29="-", "-", IF(BP29="-", "-", IF(ABS(BP29)=0, "-", ROUND(100*(BL29-BP29)/ABS(BP29), 10)))) -> - | BU29: =IF(BQ29="-", "-", IF(BS29="-", "-", IF(ABS(BS29)=0, "-", ROUND(100*(BQ29-BS29)/ABS(BS29), 1)))) -> - | BV29: =IF(BR29="-", "-", IF(BT29="-", "-", IF(ABS(BT29)=0, "-", ROUND(100*(BR29-BT29)/ABS(BT29), 1)))) -> -
B30: 支払地代 | AX30: =IF(AP30="-", "-", IF(AT30="-", "-", IF(ABS(AT30)=0, "-", ROUND(100*(AP30-AT30)/ABS(AT30), 10)))) -> - | AY30: =IF(AU30="-", "-", IF(AW30="-", "-", IF(ABS(AW30)=0, "-", ROUND(100*(AU30-AW30)/ABS(AW30), 1)))) -> - | AZ30: =IF(AV30="-", "-", IF(AX30="-", "-", IF(ABS(AX30)=0, "-", ROUND(100*(AV30-AX30)/ABS(AX30), 1)))) -> -
B31: 利子・地代算入生産費 | AX31: =IF(AP31="-", "-", IF(AT31="-", "-", IF(ABS(AT31)=0, "-", ROUND(100*(AP31-AT31)/ABS(AT31), 10)))) -> - | AY31: =IF(AU31="-", "-", IF(AW31="-", "-", IF(ABS(AW31)=0, "-", ROUND(100*(AU31-AW31)/ABS(AW31), 1)))) -> - | AZ31: =IF(AV31="-", "-", IF(AX31="-", "-", IF(ABS(AX31)=0, "-", ROUND(100*(AV31-AX31)/ABS(AX31), 1)))) -> -
B32: 自己資本利子 | AX32: =IF(AP32="-", "-", IF(AT32="-", "-", IF(ABS(AT32)=0, "-", ROUND(100*(AP32-AT32)/ABS(AT32), 10)))) -> - | AY32: =IF(AU32="-", "-", IF(AW32="-", "-", IF(ABS(AW32)=0, "-", ROUND(100*(AU32-AW32)/ABS(AW32), 1)))) -> - | AZ32: =IF(AV32="-", "-", IF(AX32="-", "-", IF(ABS(AX32)=0, "-", ROUND(100*(AV32-AX32)/ABS(AX32), 1)))) -> -
B33: 自作地地代 | AX33: =IF(AP33="-", "-", IF(AT33="-", "-", IF(ABS(AT33)=0, "-", ROUND(100*(AP33-AT33)/ABS(AT33), 10)))) -> - | AY33: =IF(AU33="-", "-", IF(AW33="-", "-", IF(ABS(AW33)=0, "-", ROUND(100*(AU33-AW33)/ABS(AW33), 1)))) -> - | AZ33: =IF(AV33="-", "-", IF(AX33="-", "-", IF(ABS(AX33)=0, "-", ROUND(100*(AV33-AX33)/ABS(AX33), 1)))) -> - | BE33: ［参考］各種助成措置を加えた場合 | BV33: 単位：円
B34: 全算入生産費 | AX34: =IF(AP34="-", "-", IF(AT34="-", "-", IF(ABS(AT34)=0, "-", ROUND(100*(AP34-AT34)/ABS(AT34), 10)))) -> - | AY34: =IF(AU34="-", "-", IF(AW34="-", "-", IF(ABS(AW34)=0, "-", ROUND(100*(AU34-AW34)/ABS(AW34), 1)))) -> - | AZ34: =IF(AV34="-", "-", IF(AX34="-", "-", IF(ABS(AX34)=0, "-", ROUND(100*(AV34-AX34)/ABS(AX34), 1)))) -> - | BL34: =IF($B$1<>"",$B$1,"") -> 0 | BP34: =IF($B$1<>"",$B$1-1,"") -> -1 | BT34: 増減率
BE35: 粗収益 | BT35: =IF(BL35="-", "-", IF(BP35="-", "-", IF(ABS(BP35)=0, "-", ROUND(100*(BL35-BP35)/ABS(BP35), 10)))) -> - | BU35: =IF(BQ35="-", "-", IF(BS35="-", "-", IF(ABS(BS35)=0, "-", ROUND(100*(BQ35-BS35)/ABS(BS35), 1)))) -> - | BV35: =IF(BR35="-", "-", IF(BT35="-", "-", IF(ABS(BT35)=0, "-", ROUND(100*(BR35-BT35)/ABS(BT35), 1)))) -> -
BE36: 生産費総額 | BT36: =IF(BL36="-", "-", IF(BP36="-", "-", IF(ABS(BP36)=0, "-", ROUND(100*(BL36-BP36)/ABS(BP36), 10)))) -> - | BU36: =IF(BQ36="-", "-", IF(BS36="-", "-", IF(ABS(BS36)=0, "-", ROUND(100*(BQ36-BS36)/ABS(BS36), 1)))) -> - | BV36: =IF(BR36="-", "-", IF(BT36="-", "-", IF(ABS(BT36)=0, "-", ROUND(100*(BR36-BT36)/ABS(BT36), 1)))) -> -
B37: ２ 資本額及び資本利子 | AD37: 単位：円 | BE37: 利潤 | BT37: =IF(BL37="-", "-", IF(BP37="-", "-", IF(ABS(BP37)=0, "-", ROUND(100*(BL37-BP37)/ABS(BP37), 10)))) -> - | BU37: =IF(BQ37="-", "-", IF(BS37="-", "-", IF(ABS(BS37)=0, "-", ROUND(100*(BQ37-BS37)/ABS(BS37), 1)))) -> - | BV37: =IF(BR37="-", "-", IF(BT37="-", "-", IF(ABS(BT37)=0, "-", ROUND(100*(BR37-BT37)/ABS(BT37), 1)))) -> -
I38: 資本額 | T38: 利子額 | BE38: 所得 | BT38: =IF(BL38="-", "-", IF(BP38="-", "-", IF(ABS(BP38)=0, "-", ROUND(100*(BL38-BP38)/ABS(BP38), 10)))) -> - | BU38: =IF(BQ38="-", "-", IF(BS38="-", "-", IF(ABS(BS38)=0, "-", ROUND(100*(BQ38-BS38)/ABS(BS38), 1)))) -> - | BV38: =IF(BR38="-", "-", IF(BT38="-", "-", IF(ABS(BT38)=0, "-", ROUND(100*(BR38-BT38)/ABS(BT38), 1)))) -> -
I39: =IF($B$1<>"",$B$1,"") -> 0 | M39: =IF($B$1<>"",$B$1-1,"") -> -1 | Q39: 増減率 | T39: =IF($B$1<>"",$B$1,"") -> 0 | X39: =IF($B$1<>"",$B$1-1,"") -> -1 | AB39: 増減率 | BF39: １日当たり | BT39: =IF(BL39="-", "-", IF(BP39="-", "-", IF(ABS(BP39)=0, "-", ROUND(100*(BL39-BP39)/ABS(BP39), 10)))) -> - | BU39: =IF(BQ39="-", "-", IF(BS39="-", "-", IF(ABS(BS39)=0, "-", ROUND(100*(BQ39-BS39)/ABS(BS39), 1)))) -> - | BV39: =IF(BR39="-", "-", IF(BT39="-", "-", IF(ABS(BT39)=0, "-", ROUND(100*(BR39-BT39)/ABS(BT39), 1)))) -> -
B40: 資本額 | Q40: =IF(I40="-", "-", IF(M40="-", "-", IF(ABS(M40)=0, "-", ROUND(100*(I40-M40)/ABS(M40), 10)))) -> - | R40: =IF(N40="-", "-", IF(P40="-", "-", IF(ABS(P40)=0, "-", ROUND(100*(N40-P40)/ABS(P40), 1)))) -> - | S40: =IF(O40="-", "-", IF(Q40="-", "-", IF(ABS(Q40)=0, "-", ROUND(100*(O40-Q40)/ABS(Q40), 1)))) -> - | AB40: =IF(T40="-", "-", IF(X40="-", "-", IF(ABS(X40)=0, "-", ROUND(100*(T40-X40)/ABS(X40), 10)))) -> - | AC40: =IF(Y40="-", "-", IF(AA40="-", "-", IF(ABS(AA40)=0, "-", ROUND(100*(Y40-AA40)/ABS(AA40), 1)))) -> - | AD40: =IF(Z40="-", "-", IF(AB40="-", "-", IF(ABS(AB40)=0, "-", ROUND(100*(Z40-AB40)/ABS(AB40), 1)))) -> - | BE40: 構成員労働報酬 | BT40: =IF(BL40="-", "-", IF(BP40="-", "-", IF(ABS(BP40)=0, "-", ROUND(100*(BL40-BP40)/ABS(BP40), 10)))) -> - | BU40: =IF(BQ40="-", "-", IF(BS40="-", "-", IF(ABS(BS40)=0, "-", ROUND(100*(BQ40-BS40)/ABS(BS40), 1)))) -> - | BV40: =IF(BR40="-", "-", IF(BT40="-", "-", IF(ABS(BT40)=0, "-", ROUND(100*(BR40-BT40)/ABS(BT40), 1)))) -> -
C41: 借入資本 | Q41: =IF(I41="-", "-", IF(M41="-", "-", IF(ABS(M41)=0, "-", ROUND(100*(I41-M41)/ABS(M41), 10)))) -> - | R41: =IF(N41="-", "-", IF(P41="-", "-", IF(ABS(P41)=0, "-", ROUND(100*(N41-P41)/ABS(P41), 1)))) -> - | S41: =IF(O41="-", "-", IF(Q41="-", "-", IF(ABS(Q41)=0, "-", ROUND(100*(O41-Q41)/ABS(Q41), 1)))) -> - | AB41: =IF(T41="-", "-", IF(X41="-", "-", IF(ABS(X41)=0, "-", ROUND(100*(T41-X41)/ABS(X41), 10)))) -> - | AC41: =IF(Y41="-", "-", IF(AA41="-", "-", IF(ABS(AA41)=0, "-", ROUND(100*(Y41-AA41)/ABS(AA41), 1)))) -> - | AD41: =IF(Z41="-", "-", IF(AB41="-", "-", IF(ABS(AB41)=0, "-", ROUND(100*(Z41-AB41)/ABS(AB41), 1)))) -> - | BF41: １日当たり | BT41: =IF(BL41="-", "-", IF(BP41="-", "-", IF(ABS(BP41)=0, "-", ROUND(100*(BL41-BP41)/ABS(BP41), 10)))) -> - | BU41: =IF(BQ41="-", "-", IF(BS41="-", "-", IF(ABS(BS41)=0, "-", ROUND(100*(BQ41-BS41)/ABS(BS41), 1)))) -> - | BV41: =IF(BR41="-", "-", IF(BT41="-", "-", IF(ABS(BT41)=0, "-", ROUND(100*(BR41-BT41)/ABS(BT41), 1)))) -> -
C42: 自己資本 | Q42: =IF(I42="-", "-", IF(M42="-", "-", IF(ABS(M42)=0, "-", ROUND(100*(I42-M42)/ABS(M42), 10)))) -> - | R42: =IF(N42="-", "-", IF(P42="-", "-", IF(ABS(P42)=0, "-", ROUND(100*(N42-P42)/ABS(P42), 1)))) -> - | S42: =IF(O42="-", "-", IF(Q42="-", "-", IF(ABS(Q42)=0, "-", ROUND(100*(O42-Q42)/ABS(Q42), 1)))) -> - | AB42: =IF(T42="-", "-", IF(X42="-", "-", IF(ABS(X42)=0, "-", ROUND(100*(T42-X42)/ABS(X42), 10)))) -> - | AC42: =IF(Y42="-", "-", IF(AA42="-", "-", IF(ABS(AA42)=0, "-", ROUND(100*(Y42-AA42)/ABS(AA42), 1)))) -> - | AD42: =IF(Z42="-", "-", IF(AB42="-", "-", IF(ABS(AB42)=0, "-", ROUND(100*(Z42-AB42)/ABS(AB42), 1)))) -> -
...

Sheet No.2
B1: =AB4 | E1: 年産 米生産費統計結果（組織法人経営体） 集計結果検討表 Ｎｏ．２
G3: 集計番号 | J3: 集計名称 | Q3: 集計経営体数 | V3: 集計倍率 | AB3: 調査年 | AG3: 都道府県等 | AL3: 経営種類 | AQ3: 生産費区分 | AV3: 規模階層 | BA3: 平均値種類 | BF3: 加重・総和の別 | BK3: 集計区分
B4: 本年産 | G4: =IF(No.1!G4="","",No.1!G4) | J4: =IF(No.1!J4="","",No.1!J4) | Q4: =IF(No.1!Q4="","",No.1!Q4) | V4: =IF(No.1!V4="","",No.1!V4) | AB4: =IF(No.1!AB4="","",No.1!AB4) | AG4: =IF(No.1!AG4="","",No.1!AG4) | AH4: =IF(No.1!AH4="","",No.1!AH4) | AI4: =IF(No.1!AI4="","",No.1!AI4) | AJ4: =IF(No.1!AJ4="","",No.1!AJ4) | AK4: =IF(No.1!AK4="","",No.1!AK4) | AL4: =IF(No.1!AL4="","",No.1!AL4) | AM4: =IF(No.1!AM4="","",No.1!AM4) | AN4: =IF(No.1!AN4="","",No.1!AN4) | ... BO4: =IF(No.1!BO4="","",No.1!BO4)
B5: 前年産 | G5: =IF(No.1!G5="","",No.1!G5) | J5: =IF(No.1!J5="","",No.1!J5) | Q5: =IF(No.1!Q5="","",No.1!Q5) | V5: =IF(No.1!V5="","",No.1!V5)
B7: ７ 経営耕地（１経営体当たり） | AO7: 単位：ａ | AT7: 14 稲作作業の受託状況（１経営体当たり）
I8: 所有地 | T8: 借入地 | AE8: 計 | BB8: 数量
I9: =IF($B$1<>"",$B$1,"") | M9: =IF($B$1<>"",$B$1-1,"") | Q9: 増減率 | T9: =IF($B$1<>"",$B$1,"") | X9: =IF($B$1<>"",$B$1-1,"") | AB9: 増減率 | AE9: =IF($B$1<>"",$B$1,"") | AI9: =IF($B$1<>"",$B$1-1,"") | AM9: 増減率 | BB9: =IF($B$1<>"",$B$1,"") | BF9: =IF($B$1<>"",$B$1-1,"") | BJ9: 増減率
B10: 田 | Q10: =IF(I10="-", "-", IF(M10="-", "-", IF(ABS(M10)=0, "-", ROUND(100*(I10-M10)/ABS(M10), 10)))) -> - | R10: =IF(N10="-", "-", IF(P10="-", "-", IF(ABS(P10)=0, "-", ROUND(100*(N10-P10)/ABS(P10), 1)))) -> - | S10: =IF(O10="-", "-", IF(Q10="-", "-", IF(ABS(Q10)=0, "-", ROUND(100*(O10-Q10)/ABS(Q10), 1)))) -> - | AB10: =IF(T10="-", "-", IF(X10="-", "-", IF(ABS(X10)=0, "-", ROUND(100*(T10-X10)/ABS(X10), 10)))) -> - | AC10: =IF(Y10="-", "-", IF(AA10="-", "-", IF(ABS(AA10)=0, "-", ROUND(100*(Y10-AA10)/ABS(AA10), 1)))) -> - | AD10: =IF(Z10="-", "-", IF(AB10="-", "-", IF(ABS(AB10)=0, "-", ROUND(100*(Z10-AB10)/ABS(AB10), 1)))) -> - | AM10: =IF(AE10="-", "-", IF(AI10="-", "-", IF(ABS(AI10)=0, "-", ROUND(100*(AE10-AI10)/ABS(AI10), 10)))) -> - | AN10: =IF(AJ10="-", "-", IF(AL10="-", "-", IF(ABS(AL10)=0, "-", ROUND(100*(AJ10-AL10)/ABS(AL10), 1)))) -> - | AO10: =IF(AK10="-", "-", IF(AM10="-", "-", IF(ABS(AM10)=0, "-", ROUND(100*(AK10-AM10)/ABS(AM10), 1)))) -> - | AT10: 全作業 | BA10: ａ | BJ10: =IF(BB10="-", "-", IF(BF10="-", "-", IF(ABS(BF10)=0, "-", ROUND(100*(BB10-BF10)/ABS(BF10), 10)))) -> - | BK10: =IF(BG10="-", "-", IF(BI10="-", "-", IF(ABS(BI10)=0, "-", ROUND(100*(BG10-BI10)/ABS(BI10), 1)))) -> - | BL10: =IF(BH10="-", "-", IF(BJ10="-", "-", IF(ABS(BJ10)=0, "-", ROUND(100*(BH10-BJ10)/ABS(BJ10), 1)))) -> -
B11: 普通畑 | Q11: =IF(I11="-", "-", IF(M11="-", "-", IF(ABS(M11)=0, "-", ROUND(100*(I11-M11)/ABS(M11), 10)))) -> - | R11: =IF(N11="-", "-", IF(P11="-", "-", IF(ABS(P11)=0, "-", ROUND(100*(N11-P11)/ABS(P11), 1)))) -> - | S11: =IF(O11="-", "-", IF(Q11="-", "-", IF(ABS(Q11)=0, "-", ROUND(100*(O11-Q11)/ABS(Q11), 1)))) -> - | AB11: =IF(T11="-", "-", IF(X11="-", "-", IF(ABS(X11)=0, "-", ROUND(100*(T11-X11)/ABS(X11), 10)))) -> - | AC11: =IF(Y11="-", "-", IF(AA11="-", "-", IF(ABS(AA11)=0, "-", ROUND(100*(Y11-AA11)/ABS(AA11), 1)))) -> - | AD11: =IF(Z11="-", "-", IF(AB11="-", "-", IF(ABS(AB11)=0, "-", ROUND(100*(Z11-AB11)/ABS(AB11), 1)))) -> - | AM11: =IF(AE11="-", "-", IF(AI11="-", "-", IF(ABS(AI11)=0, "-", ROUND(100*(AE11-AI11)/ABS(AI11), 10)))) -> - | AN11: =IF(AJ11="-", "-", IF(AL11="-", "-", IF(ABS(AL11)=0, "-", ROUND(100*(AJ11-AL11)/ABS(AL11), 1)))) -> - | AO11: =IF(AK11="-", "-", IF(AM11="-", "-", IF(ABS(AM11)=0, "-", ROUND(100*(AK11-AM11)/ABS(AM11), 1)))) -> - | AT11: 耕うん・整地 | BA11: ａ | BJ11: =IF(BB11="-", "-", IF(BF11="-", "-", IF(ABS(BF11)=0, "-", ROUND(100*(BB11-BF11)/ABS(BF11), 10)))) -> - | BK11: =IF(BG11="-", "-", IF(BI11="-", "-", IF(ABS(BI11)=0, "-", ROUND(100*(BG11-BI11)/ABS(BI11), 1)))) -> - | BL11: =IF(BH11="-", "-", IF(BJ11="-", "-", IF(ABS(BJ11)=0, "-", ROUND(100*(BH11-BJ11)/ABS(BJ11), 1)))) -> -
B12: 樹園地 | Q12: =IF(I12="-", "-", IF(M12="-", "-", IF(ABS(M12)=0, "-", ROUND(100*(I12-M12)/ABS(M12), 10)))) -> - | R12: =IF(N12="-", "-", IF(P12="-", "-", IF(ABS(P12)=0, "-", ROUND(100*(N12-P12)/ABS(P12), 1)))) -> - | S12: =IF(O12="-", "-", IF(Q12="-", "-", IF(ABS(Q12)=0, "-", ROUND(100*(O12-Q12)/ABS(Q12), 1)))) -> - | AB12: =IF(T12="-", "-", IF(X12="-", "-", IF(ABS(X12)=0, "-", ROUND(100*(T12-X12)/ABS(X12), 10)))) -> - | AC12: =IF(Y12="-", "-", IF(AA12="-", "-", IF(ABS(AA12)=0, "-", ROUND(100*(Y12-AA12)/ABS(AA12), 1)))) -> - | AD12: =IF(Z12="-", "-", IF(AB12="-", "-", IF(ABS(AB12)=0, "-", ROUND(100*(Z12-AB12)/ABS(AB12), 1)))) -> - | AM12: =IF(AE12="-", "-", IF(AI12="-", "-", IF(ABS(AI12)=0, "-", ROUND(100*(AE12-AI12)/ABS(AI12), 10)))) -> - | AN12: =IF(AJ12="-", "-", IF(AL12="-", "-", IF(ABS(AL12)=0, "-", ROUND(100*(AJ12-AL12)/ABS(AL12), 1)))) -> - | AO12: =IF(AK12="-", "-", IF(AM12="-", "-", IF(ABS(AM12)=0, "-", ROUND(100*(AK12-AM12)/ABS(AM12), 1)))) -> - | AT12: 育苗 | BA12: ａ | BJ12: =IF(BB12="-", "-", IF(BF12="-", "-", IF(ABS(BF12)=0, "-", ROUND(100*(BB12-BF12)/ABS(BF12), 10)))) -> - | BK12: =IF(BG12="-", "-", IF(BI12="-", "-", IF(ABS(BI12)=0, "-", ROUND(100*(BG12-BI12)/ABS(BI12), 1)))) -> - | BL12: =IF(BH12="-", "-", IF(BJ12="-", "-", IF(ABS(BJ12)=0, "-", ROUND(100*(BH12-BJ12)/ABS(BJ12), 1)))) -> -
B13: 牧草地 | Q13: =IF(I13="-", "-", IF(M13="-", "-", IF(ABS(M13)=0, "-", ROUND(100*(I13-M13)/ABS(M13), 10)))) -> - | R13: =IF(N13="-", "-", IF(P13="-", "-", IF(ABS(P13)=0, "-", ROUND(100*(N13-P13)/ABS(P13), 1)))) -> - | S13: =IF(O13="-", "-", IF(Q13="-", "-", IF(ABS(Q13)=0, "-", ROUND(100*(O13-Q13)/ABS(Q13), 1)))) -> - | AB13: =IF(T13="-", "-", IF(X13="-", "-", IF(ABS(X13)=0, "-", ROUND(100*(T13-X13)/ABS(X13), 10)))) -> - | AC13: =IF(Y13="-", "-", IF(AA13="-", "-", IF(ABS(AA13)=0, "-", ROUND(100*(Y13-AA13)/ABS(AA13), 1)))) -> - | AD13: =IF(Z13="-", "-", IF(AB13="-", "-", IF(ABS(AB13)=0, "-", ROUND(100*(Z13-AB13)/ABS(AB13), 1)))) -> - | AM13: =IF(AE13="-", "-", IF(AI13="-", "-", IF(ABS(AI13)=0, "-", ROUND(100*(AE13-AI13)/ABS(AI13), 10)))) -> - | AN13: =IF(AJ13="-", "-", IF(AL13="-", "-", IF(ABS(AL13)=0, "-", ROUND(100*(AJ13-AL13)/ABS(AL13), 1)))) -> - | AO13: =IF(AK13="-", "-", IF(AM13="-", "-", IF(ABS(AM13)=0, "-", ROUND(100*(AK13-AM13)/ABS(AM13), 1)))) -> - | AT13: 田植 | BA13: ａ | BJ13: =IF(BB13="-", "-", IF(BF13="-", "-", IF(ABS(BF13)=0, "-", ROUND(100*(BB13-BF13)/ABS(BF13), 10)))) -> - | BK13: =IF(BG13="-", "-", IF(BI13="-", "-", IF(ABS(BI13)=0, "-", ROUND(100*(BG13-BI13)/ABS(BI13), 1)))) -> - | BL13: =IF(BH13="-", "-", IF(BJ13="-", "-", IF(ABS(BJ13)=0, "-", ROUND(100*(BH13-BJ13)/ABS(BJ13), 1)))) -> -
B14: 計 | Q14: =IF(I14="-", "-", IF(M14="-", "-", IF(ABS(M14)=0, "-", ROUND(100*(I14-M14)/ABS(M14), 10)))) -> - | R14: =IF(N14="-", "-", IF(P14="-", "-", IF(ABS(P14)=0, "-", ROUND(100*(N14-P14)/ABS(P14), 1)))) -> - | S14: =IF(O14="-", "-", IF(Q14="-", "-", IF(ABS(Q14)=0, "-", ROUND(100*(O14-Q14)/ABS(Q14), 1)))) -> - | AB14: =IF(T14="-", "-", IF(X14="-", "-", IF(ABS(X14)=0, "-", ROUND(100*(T14-X14)/ABS(X14), 10)))) -> - | AC14: =IF(Y14="-", "-", IF(AA14="-", "-", IF(ABS(AA14)=0, "-", ROUND(100*(Y14-AA14)/ABS(AA14), 1)))) -> - | AD14: =IF(Z14="-", "-", IF(AB14="-", "-", IF(ABS(AB14)=0, "-", ROUND(100*(Z14-AB14)/ABS(AB14), 1)))) -> - | AM14: =IF(AE14="-", "-", IF(AI14="-", "-", IF(ABS(AI14)=0, "-", ROUND(100*(AE14-AI14)/ABS(AI14), 10)))) -> - | AN14: =IF(AJ14="-", "-", IF(AL14="-", "-", IF(ABS(AL14)=0, "-", ROUND(100*(AJ14-AL14)/ABS(AL14), 1)))) -> - | AO14: =IF(AK14="-", "-", IF(AM14="-", "-", IF(ABS(AM14)=0, "-", ROUND(100*(AK14-AM14)/ABS(AM14), 1)))) -> - | AT14: 防除 | BA14: ａ | BJ14: =IF(BB14="-", "-", IF(BF14="-", "-", IF(ABS(BF14)=0, "-", ROUND(100*(BB14-BF14)/ABS(BF14), 10)))) -> - | BK14: =IF(BG14="-", "-", IF(BI14="-", "-", IF(ABS(BI14)=0, "-", ROUND(100*(BG14-BI14)/ABS(BI14), 1)))) -> - | BL14: =IF(BH14="-", "-", IF(BJ14="-", "-", IF(ABS(BJ14)=0, "-", ROUND(100*(BH14-BJ14)/ABS(BJ14), 1)))) -> -
AT15: 刈取・脱穀 | BA15: ａ | BJ15: =IF(BB15="-", "-", IF(BF15="-", "-", IF(ABS(BF15)=0, "-", ROUND(100*(BB15-BF15)/ABS(BF15), 10)))) -> - | BK15: =IF(BG15="-", "-", IF(BI15="-", "-", IF(ABS(BI15)=0, "-", ROUND(100*(BG15-BI15)/ABS(BI15), 1)))) -> - | BL15: =IF(BH15="-", "-", IF(BJ15="-", "-", IF(ABS(BJ15)=0, "-", ROUND(100*(BH15-BJ15)/ABS(BJ15), 1)))) -> -
AT16: 乾燥・調製 | BA16: kg | BJ16: =IF(BB16="-", "-", IF(BF16="-", "-", IF(ABS(BF16)=0, "-", ROUND(100*(BB16-BF16)/ABS(BF16), 10)))) -> - | BK16: =IF(BG16="-", "-", IF(BI16="-", "-", IF(ABS(BI16)=0, "-", ROUND(100*(BG16-BI16)/ABS(BI16), 1)))) -> - | BL16: =IF(BH16="-", "-", IF(BJ16="-", "-", IF(ABS(BJ16)=0, "-", ROUND(100*(BH16-BJ16)/ABS(BJ16), 1)))) -> -
B17: ８ 地 代（面積は１経営体当たり） | AO17: 単位：円、ａ
I18: 自作地 | T18: 借入地 | AE18: 計
I19: =IF($B$1<>"",$B$1,"") | M19: =IF($B$1<>"",$B$1-1,"") | Q19: 増減率 | T19: =IF($B$1<>"",$B$1,"") | X19: =IF($B$1<>"",$B$1-1,"") | AB19: 増減率 | AE19: =IF($B$1<>"",$B$1,"") | AI19: =IF($B$1<>"",$B$1-1,"") | AM19: 増減率 | AT19: 15 稲作作業の委託状況（１経営体当たり）
B20: 作付地 | D20: 作付実面積 | Q20: =IF(I20="-", "-", IF(M20="-", "-", IF(ABS(M20)=0, "-", ROUND(100*(I20-M20)/ABS(M20), 10)))) -> - | R20: =IF(N20="-", "-", IF(P20="-", "-", IF(ABS(P20)=0, "-", ROUND(100*(N20-P20)/ABS(P20), 1)))) -> - | S20: =IF(O20="-", "-", IF(Q20="-", "-", IF(ABS(Q20)=0, "-", ROUND(100*(O20-Q20)/ABS(Q20), 1)))) -> - | AB20: =IF(T20="-", "-", IF(X20="-", "-", IF(ABS(X20)=0, "-", ROUND(100*(T20-X20)/ABS(X20), 10)))) -> - | AC20: =IF(Y20="-", "-", IF(AA20="-", "-", IF(ABS(AA20)=0, "-", ROUND(100*(Y20-AA20)/ABS(AA20), 1)))) -> - | AD20: =IF(Z20="-", "-", IF(AB20="-", "-", IF(ABS(AB20)=0, "-", ROUND(100*(Z20-AB20)/ABS(AB20), 1)))) -> - | AM20: =IF(AE20="-", "-", IF(AI20="-", "-", IF(ABS(AI20)=0, "-", ROUND(100*(AE20-AI20)/ABS(AI20), 10)))) -> - | AN20: =IF(AJ20="-", "-", IF(AL20="-", "-", IF(ABS(AL20)=0, "-", ROUND(100*(AJ20-AL20)/ABS(AL20), 1)))) -> - | AO20: =IF(AK20="-", "-", IF(AM20="-", "-", IF(ABS(AM20)=0, "-", ROUND(100*(AK20-AM20)/ABS(AM20), 1)))) -> - | BB20: 数量
D21: 土地台帳面積 | Q21: =IF(I21="-", "-", IF(M21="-", "-", IF(ABS(M21)=0, "-", ROUND(100*(I21-M21)/ABS(M21), 10)))) -> - | R21: =IF(N21="-", "-", IF(P21="-", "-", IF(ABS(P21)=0, "-", ROUND(100*(N21-P21)/ABS(P21), 1)))) -> - | S21: =IF(O21="-", "-", IF(Q21="-", "-", IF(ABS(Q21)=0, "-", ROUND(100*(O21-Q21)/ABS(Q21), 1)))) -> - | AB21: =IF(T21="-", "-", IF(X21="-", "-", IF(ABS(X21)=0, "-", ROUND(100*(T21-X21)/ABS(X21), 10)))) -> - | AC21: =IF(Y21="-", "-", IF(AA21="-", "-", IF(ABS(AA21)=0, "-", ROUND(100*(Y21-AA21)/ABS(AA21), 1)))) -> - | AD21: =IF(Z21="-", "-", IF(AB21="-", "-", IF(ABS(AB21)=0, "-", ROUND(100*(Z21-AB21)/ABS(AB21), 1)))) -> - | AM21: =IF(AE21="-", "-", IF(AI21="-", "-", IF(ABS(AI21)=0, "-", ROUND(100*(AE21-AI21)/ABS(AI21), 10)))) -> - | AN21: =IF(AJ21="-", "-", IF(AL21="-", "-", IF(ABS(AL21)=0, "-", ROUND(100*(AJ21-AL21)/ABS(AL21), 1)))) -> - | AO21: =IF(AK21="-", "-", IF(AM21="-", "-", IF(ABS(AM21)=0, "-", ROUND(100*(AK21-AM21)/ABS(AM21), 1)))) -> - | BB21: =IF($B$1<>"",$B$1,"") | BF21: =IF($B$1<>"",$B$1-1,"") | BJ21: 増減率
D22: 地代総額 | Q22: =IF(I22="-", "-", IF(M22="-", "-", IF(ABS(M22)=0, "-", ROUND(100*(I22-M22)/ABS(M22), 10)))) -> - | R22: =IF(N22="-", "-", IF(P22="-", "-", IF(ABS(P22)=0, "-", ROUND(100*(N22-P22)/ABS(P22), 1)))) -> - | S22: =IF(O22="-", "-", IF(Q22="-", "-", IF(ABS(Q22)=0, "-", ROUND(100*(O22-Q22)/ABS(Q22), 1)))) -> - | AB22: =IF(T22="-", "-", IF(X22="-", "-", IF(ABS(X22)=0, "-", ROUND(100*(T22-X22)/ABS(X22), 10)))) -> - | AC22: =IF(Y22="-", "-", IF(AA22="-", "-", IF(ABS(AA22)=0, "-", ROUND(100*(Y22-AA22)/ABS(AA22), 1)))) -> - | AD22: =IF(Z22="-", "-", IF(AB22="-", "-", IF(ABS(AB22)=0, "-", ROUND(100*(Z22-AB22)/ABS(AB22), 1)))) -> - | AM22: =IF(AE22="-", "-", IF(AI22="-", "-", IF(ABS(AI22)=0, "-", ROUND(100*(AE22-AI22)/ABS(AI22), 10)))) -> - | AN22: =IF(AJ22="-", "-", IF(AL22="-", "-", IF(ABS(AL22)=0, "-", ROUND(100*(AJ22-AL22)/ABS(AL22), 1)))) -> - | AO22: =IF(AK22="-", "-", IF(AM22="-", "-", IF(ABS(AM22)=0, "-", ROUND(100*(AK22-AM22)/ABS(AM22), 1)))) -> - | AT22: 育苗 | BA22: ａ | BJ22: =IF(BB22="-", "-", IF(BF22="-", "-", IF(ABS(BF22)=0, "-", ROUND(100*(BB22-BF22)/ABS(BF22), 10)))) -> - | BK22: =IF(BG22="-", "-", IF(BI22="-", "-", IF(ABS(BI22)=0, "-", ROUND(100*(BG22-BI22)/ABS(BI22), 1)))) -> - | BL22: =IF(BH22="-", "-", IF(BJ22="-", "-", IF(ABS(BJ22)=0, "-", ROUND(100*(BH22-BJ22)/ABS(BJ22), 1)))) -> -
D23: 負担地代 | Q23: =IF(I23="-", "-", IF(M23="-", "-", IF(ABS(M23)=0, "-", ROUND(100*(I23-M23)/ABS(M23), 10)))) -> - | R23: =IF(N23="-", "-", IF(P23="-", "-", IF(ABS(P23)=0, "-", ROUND(100*(N23-P23)/ABS(P23), 1)))) -> - | S23: =IF(O23="-", "-", IF(Q23="-", "-", IF(ABS(Q23)=0, "-", ROUND(100*(O23-Q23)/ABS(Q23), 1)))) -> - | AB23: =IF(T23="-", "-", IF(X23="-", "-", IF(ABS(X23)=0, "-", ROUND(100*(T23-X23)/ABS(X23), 10)))) -> - | AC23: =IF(Y23="-", "-", IF(AA23="-", "-", IF(ABS(AA23)=0, "-", ROUND(100*(Y23-AA23)/ABS(AA23), 1)))) -> - | AD23: =IF(Z23="-", "-", IF(AB23="-", "-", IF(ABS(AB23)=0, "-", ROUND(100*(Z23-AB23)/ABS(AB23), 1)))) -> - | AM23: =IF(AE23="-", "-", IF(AI23="-", "-", IF(ABS(AI23)=0, "-", ROUND(100*(AE23-AI23)/ABS(AI23), 10)))) -> - | AN23: =IF(AJ23="-", "-", IF(AL23="-", "-", IF(ABS(AL23)=0, "-", ROUND(100*(AJ23-AL23)/ABS(AL23), 1)))) -> - | AO23: =IF(AK23="-", "-", IF(AM23="-", "-", IF(ABS(AM23)=0, "-", ROUND(100*(AK23-AM23)/ABS(AM23), 1)))) -> - | AT23: 防除 | BA23: ａ | BJ23: =IF(BB23="-", "-", IF(BF23="-", "-", IF(ABS(BF23)=0, "-", ROUND(100*(BB23-BF23)/ABS(BF23), 10)))) -> - | BK23: =IF(BG23="-", "-", IF(BI23="-", "-", IF(ABS(BI23)=0, "-", ROUND(100*(BG23-BI23)/ABS(BI23), 1)))) -> - | BL23: =IF(BH23="-", "-", IF(BJ23="-", "-", IF(ABS(BJ23)=0, "-", ROUND(100*(BH23-BJ23)/ABS(BJ23), 1)))) -> -
B24: 以 外作付地 | D24: 使用面積 | Q24: =IF(I24="-", "-", IF(M24="-", "-", IF(ABS(M24)=0, "-", ROUND(100*(I24-M24)/ABS(M24), 10)))) -> - | R24: =IF(N24="-", "-", IF(P24="-", "-", IF(ABS(P24)=0, "-", ROUND(100*(N24-P24)/ABS(P24), 1)))) -> - | S24: =IF(O24="-", "-", IF(Q24="-", "-", IF(ABS(Q24)=0, "-", ROUND(100*(O24-Q24)/ABS(Q24), 1)))) -> - | AB24: =IF(T24="-", "-", IF(X24="-", "-", IF(ABS(X24)=0, "-", ROUND(100*(T24-X24)/ABS(X24), 10)))) -> - | AC24: =IF(Y24="-", "-", IF(AA24="-", "-", IF(ABS(AA24)=0, "-", ROUND(100*(Y24-AA24)/ABS(AA24), 1)))) -> - | AD24: =IF(Z24="-", "-", IF(AB24="-", "-", IF(ABS(AB24)=0, "-", ROUND(100*(Z24-AB24)/ABS(AB24), 1)))) -> - | AM24: =IF(AE24="-", "-", IF(AI24="-", "-", IF(ABS(AI24)=0, "-", ROUND(100*(AE24-AI24)/ABS(AI24), 10)))) -> - | AN24: =IF(AJ24="-", "-", IF(AL24="-", "-", IF(ABS(AL24)=0, "-", ROUND(100*(AJ24-AL24)/ABS(AL24), 1)))) -> - | AO24: =IF(AK24="-", "-", IF(AM24="-", "-", IF(ABS(AM24)=0, "-", ROUND(100*(AK24-AM24)/ABS(AM24), 1)))) -> -
D25: 賃借料総額 | Q25: =IF(I25="-", "-", IF(M25="-", "-", IF(ABS(M25)=0, "-", ROUND(100*(I25-M25)/ABS(M25), 10)))) -> - | R25: =IF(N25="-", "-", IF(P25="-", "-", IF(ABS(P25)=0, "-", ROUND(100*(N25-P25)/ABS(P25), 1)))) -> - | S25: =IF(O25="-", "-", IF(Q25="-", "-", IF(ABS(Q25)=0, "-", ROUND(100*(O25-Q25)/ABS(Q25), 1)))) -> - | AB25: =IF(T25="-", "-", IF(X25="-", "-", IF(ABS(X25)=0, "-", ROUND(100*(T25-X25)/ABS(X25), 10)))) -> - | AC25: =IF(Y25="-", "-", IF(AA25="-", "-", IF(ABS(AA25)=0, "-", ROUND(100*(Y25-AA25)/ABS(AA25), 1)))) -> - | AD25: =IF(Z25="-", "-", IF(AB25="-", "-", IF(ABS(AB25)=0, "-", ROUND(100*(Z25-AB25)/ABS(AB25), 1)))) -> - | AM25: =IF(AE25="-", "-", IF(AI25="-", "-", IF(ABS(AI25)=0, "-", ROUND(100*(AE25-AI25)/ABS(AI25), 10)))) -> - | AN25: =IF(AJ25="-", "-", IF(AL25="-", "-", IF(ABS(AL25)=0, "-", ROUND(100*(AJ25-AL25)/ABS(AL25), 1)))) -> - | AO25: =IF(AK25="-", "-", IF(AM25="-", "-", IF(ABS(AM25)=0, "-", ROUND(100*(AK25-AM25)/ABS(AM25), 1)))) -> -
D26: 負担地代 | Q26: =IF(I26="-", "-", IF(M26="-", "-", IF(ABS(M26)=0, "-", ROUND(100*(I26-M26)/ABS(M26), 10)))) -> - | R26: =IF(N26="-", "-", IF(P26="-", "-", IF(ABS(P26)=0, "-", ROUND(100*(N26-P26)/ABS(P26), 1)))) -> - | S26: =IF(O26="-", "-", IF(Q26="-", "-", IF(ABS(Q26)=0, "-", ROUND(100*(O26-Q26)/ABS(Q26), 1)))) -> - | AB26: =IF(T26="-", "-", IF(X26="-", "-", IF(ABS(X26)=0, "-", ROUND(100*(T26-X26)/ABS(X26), 10)))) -> - | AC26: =IF(Y26="-", "-", IF(AA26="-", "-", IF(ABS(AA26)=0, "-", ROUND(100*(Y26-AA26)/ABS(AA26), 1)))) -> - | AD26: =IF(Z26="-", "-", IF(AB26="-", "-", IF(ABS(AB26)=0, "-", ROUND(100*(Z26-AB26)/ABS(AB26), 1)))) -> - | AM26: =IF(AE26="-", "-", IF(AI26="-", "-", IF(ABS(AI26)=0, "-", ROUND(100*(AE26-AI26)/ABS(AI26), 10)))) -> - | AN26: =IF(AJ26="-", "-", IF(AL26="-", "-", IF(ABS(AL26)=0, "-", ROUND(100*(AJ26-AL26)/ABS(AL26), 1)))) -> - | AO26: =IF(AK26="-", "-", IF(AM26="-", "-", IF(ABS(AM26)=0, "-", ROUND(100*(AK26-AM26)/ABS(AM26), 1)))) -> -
B27: 実勢地代 | Q27: =IF(I27="-", "-", IF(M27="-", "-", IF(ABS(M27)=0, "-", ROUND(100*(I27-M27)/ABS(M27), 10)))) -> - | R27: =IF(N27="-", "-", IF(P27="-", "-", IF(ABS(P27)=0, "-", ROUND(100*(N27-P27)/ABS(P27), 1)))) -> - | S27: =IF(O27="-", "-", IF(Q27="-", "-", IF(ABS(Q27)=0, "-", ROUND(100*(O27-Q27)/ABS(Q27), 1)))) -> - | AB27: =IF(T27="-", "-", IF(X27="-", "-", IF(ABS(X27)=0, "-", ROUND(100*(T27-X27)/ABS(X27), 10)))) -> - | AC27: =IF(Y27="-", "-", IF(AA27="-", "-", IF(ABS(AA27)=0, "-", ROUND(100*(Y27-AA27)/ABS(AA27), 1)))) -> - | AD27: =IF(Z27="-", "-", IF(AB27="-", "-", IF(ABS(AB27)=0, "-", ROUND(100*(Z27-AB27)/ABS(AB27), 1)))) -> - | AM27: =IF(AE27="-", "-", IF(AI27="-", "-", IF(ABS(AI27)=0, "-", ROUND(100*(AE27-AI27)/ABS(AI27), 10)))) -> - | AN27: =IF(AJ27="-", "-", IF(AL27="-", "-", IF(ABS(AL27)=0, "-", ROUND(100*(AJ27-AL27)/ABS(AL27), 1)))) -> - | AO27: =IF(AK27="-", "-", IF(AM27="-", "-", IF(ABS(AM27)=0, "-", ROUND(100*(AK27-AM27)/ABS(AM27), 1)))) -> -
B30: ９ 田の概況（総数） | X30: 10 「移植」「直まき」別作付面積（１経営体当たり）
I31: 該当の有無等 | AD31: 作付面積（ａ）
I32: =IF($B$1<>"",$B$1,"") | M32: =IF($B$1<>"",$B$1-1,"") | Q32: 増減率 | AD32: =IF($B$1<>"",$B$1,"") | AH32: =IF($B$1<>"",$B$1-1,"") | AL32: 増減率 | AT32: 16 うるち米の品種別作付面積（１経営体当たり） | CC32: 単位：ａ
B33: 田の団地数（1経営体当たり） | Q33: =IF(I33="-", "-", IF(M33="-", "-", IF(ABS(M33)=0, "-", ROUND(100*(I33-M33)/ABS(M33), 10)))) -> - | R33: =IF(N33="-", "-", IF(P33="-", "-", IF(ABS(P33)=0, "-", ROUND(100*(N33-P33)/ABS(P33), 1)))) -> - | S33: =IF(O33="-", "-", IF(Q33="-", "-", IF(ABS(Q33)=0, "-", ROUND(100*(O33-Q33)/ABS(Q33), 1)))) -> - | X33: 移植 | AL33: =IF(AD33="-", "-", IF(AH33="-", "-", IF(ABS(AH33)=0, "-", ROUND(100*(AD33-AH33)/ABS(AH33), 10)))) -> - | AM33: =IF(AI33="-", "-", IF(AK33="-", "-", IF(ABS(AK33)=0, "-", ROUND(100*(AI33-AK33)/ABS(AK33), 1)))) -> - | AN33: =IF(AJ33="-", "-", IF(AL33="-", "-", IF(ABS(AL33)=0, "-", ROUND(100*(AJ33-AL33)/ABS(AL33), 1)))) -> - | BA33: =IF($B$1<>"",$B$1,"") | BE33: =IF($B$1<>"",$B$1-1,"") | BI33: 増減率 | BS33: =IF($B$1<>"",$B$1,"") | BW33: =IF($B$1<>"",$B$1-1,"") | CA33: 増減率
B34: 田のうち 区画整理 済面積 | E34: 50％未満 | Q34: =IF(I34="-", "-", IF(M34="-", "-", IF(ABS(M34)=0, "-", ROUND(100*(I34-M34)/ABS(M34), 10)))) -> - | R34: =IF(N34="-", "-", IF(P34="-", "-", IF(ABS(P34)=0, "-", ROUND(100*(N34-P34)/ABS(P34), 1)))) -> - | S34: =IF(O34="-", "-", IF(Q34="-", "-", IF(ABS(Q34)=0, "-", ROUND(100*(O34-Q34)/ABS(Q34), 1)))) -> - | X34: 直まき | AL34: =IF(AD34="-", "-", IF(AH34="-", "-", IF(ABS(AH34)=0, "-", ROUND(100*(AD34-AH34)/ABS(AH34), 10)))) -> - | AM34: =IF(AI34="-", "-", IF(AK34="-", "-", IF(ABS(AK34)=0, "-", ROUND(100*(AI34-AK34)/ABS(AK34), 1)))) -> - | AN34: =IF(AJ34="-", "-", IF(AL34="-", "-", IF(ABS(AL34)=0, "-", ROUND(100*(AJ34-AL34)/ABS(AL34), 1)))) -> - | AT34: 計 | BI34: =IF(BA34="-", "-", IF(BE34="-", "-", IF(ABS(BE34)=0, "-", ROUND(100*(BA34-BE34)/ABS(BE34), 10)))) -> - | BJ34: =IF(BF34="-", "-", IF(BH34="-", "-", IF(ABS(BH34)=0, "-", ROUND(100*(BF34-BH34)/ABS(BH34), 1)))) -> - | BK34: =IF(BG34="-", "-", IF(BI34="-", "-", IF(ABS(BI34)=0, "-", ROUND(100*(BG34-BI34)/ABS(BI34), 1)))) -> -
E35: 50～80％ | Q35: =IF(I35="-", "-", IF(M35="-", "-", IF(ABS(M35)=0, "-", ROUND(100*(I35-M35)/ABS(M35), 10)))) -> - | R35: =IF(N35="-", "-", IF(P35="-", "-", IF(ABS(P35)=0, "-", ROUND(100*(N35-P35)/ABS(P35), 1)))) -> - | S35: =IF(O35="-", "-", IF(Q35="-", "-", IF(ABS(Q35)=0, "-", ROUND(100*(O35-Q35)/ABS(Q35), 1)))) -> - | X35: 計 | AL35: =IF(AD35="-", "-", IF(AH35="-", "-", IF(ABS(AH35)=0, "-", ROUND(100*(AD35-AH35)/ABS(AH35), 10)))) -> - | AM35: =IF(AI35="-", "-", IF(AK35="-", "-", IF(ABS(AK35)=0, "-", ROUND(100*(AI35-AK35)/ABS(AK35), 1)))) -> - | AN35: =IF(AJ35="-", "-", IF(AL35="-", "-", IF(ABS(AL35)=0, "-", ROUND(100*(AJ35-AL35)/ABS(AL35), 1)))) -> - | AT35: コード１ | BI35: =IF(BA35="-", "-", IF(BE35="-", "-", IF(ABS(BE35)=0, "-", ROUND(100*(BA35-BE35)/ABS(BE35), 10)))) -> - | BJ35: =IF(BF35="-", "-", IF(BH35="-", "-", IF(ABS(BH35)=0, "-", ROUND(100*(BF35-BH35)/ABS(BH35), 1)))) -> - | BK35: =IF(BG35="-", "-", IF(BI35="-", "-", IF(ABS(BI35)=0, "-", ROUND(100*(BG35-BI35)/ABS(BI35), 1)))) -> - | BL35: コード１６ | CA35: =IF(BS35="-", "-", IF(BW35="-", "-", IF(ABS(BW35)=0, "-", ROUND(100*(BS35-BW35)/ABS(BW35), 10)))) -> - | CB35: =IF(BX35="-", "-", IF(BZ35="-", "-", IF(ABS(BZ35)=0, "-", ROUND(100*(BX35-BZ35)/ABS(BZ35), 1)))) -> - | CC35: =IF(BY35="-", "-", IF(CA35="-", "-", IF(ABS(CA35)=0, "-", ROUND(100*(BY35-CA35)/ABS(CA35), 1)))) -> -
E36: 80％以上 | Q36: =IF(I36="-", "-", IF(M36="-", "-", IF(ABS(M36)=0, "-", ROUND(100*(I36-M36)/ABS(M36), 10)))) -> - | R36: =IF(N36="-", "-", IF(P36="-", "-", IF(ABS(P36)=0, "-", ROUND(100*(N36-P36)/ABS(P36), 1)))) -> - | S36: =IF(O36="-", "-", IF(Q36="-", "-", IF(ABS(Q36)=0, "-", ROUND(100*(O36-Q36)/ABS(Q36), 1)))) -> - | AT36: コード２ | BI36: =IF(BA36="-", "-", IF(BE36="-", "-", IF(ABS(BE36)=0, "-", ROUND(100*(BA36-BE36)/ABS(BE36), 10)))) -> - | BJ36: =IF(BF36="-", "-", IF(BH36="-", "-", IF(ABS(BH36)=0, "-", ROUND(100*(BF36-BH36)/ABS(BH36), 1)))) -> - | BK36: =IF(BG36="-", "-", IF(BI36="-", "-", IF(ABS(BI36)=0, "-", ROUND(100*(BG36-BI36)/ABS(BI36), 1)))) -> - | BL36: コード１７ | CA36: =IF(BS36="-", "-", IF(BW36="-", "-", IF(ABS(BW36)=0, "-", ROUND(100*(BS36-BW36)/ABS(BW36), 10)))) -> - | CB36: =IF(BX36="-", "-", IF(BZ36="-", "-", IF(ABS(BZ36)=0, "-", ROUND(100*(BX36-BZ36)/ABS(BZ36), 1)))) -> - | CC36: =IF(BY36="-", "-", IF(CA36="-", "-", IF(ABS(CA36)=0, "-", ROUND(100*(BY36-CA36)/ABS(CA36), 1)))) -> -
AT37: コード３ | BI37: =IF(BA37="-", "-", IF(BE37="-", "-", IF(ABS(BE37)=0, "-", ROUND(100*(BA37-BE37)/ABS(BE37), 10)))) -> - | BJ37: =IF(BF37="-", "-", IF(BH37="-", "-", IF(ABS(BH37)=0, "-", ROUND(100*(BF37-BH37)/ABS(BH37), 1)))) -> - | BK37: =IF(BG37="-", "-", IF(BI37="-", "-", IF(ABS(BI37)=0, "-", ROUND(100*(BG37-BI37)/ABS(BI37), 1)))) -> - | BL37: コード１８ | CA37: =IF(BS37="-", "-", IF(BW37="-", "-", IF(ABS(BW37)=0, "-", ROUND(100*(BS37-BW37)/ABS(BW37), 10)))) -> - | CB37: =IF(BX37="-", "-", IF(BZ37="-", "-", IF(ABS(BZ37)=0, "-", ROUND(100*(BX37-BZ37)/ABS(BZ37), 1)))) -> - | CC37: =IF(BY37="-", "-", IF(CA37="-", "-", IF(ABS(CA37)=0, "-", ROUND(100*(BY37-CA37)/ABS(CA37), 1)))) -> -
AT38: コード４ | BI38: =IF(BA38="-", "-", IF(BE38="-", "-", IF(ABS(BE38)=0, "-", ROUND(100*(BA38-BE38)/ABS(BE38), 10)))) -> - | BJ38: =IF(BF38="-", "-", IF(BH38="-", "-", IF(ABS(BH38)=0, "-", ROUND(100*(BF38-BH38)/ABS(BH38), 1)))) -> - | BK38: =IF(BG38="-", "-", IF(BI38="-", "-", IF(ABS(BI38)=0, "-", ROUND(100*(BG38-BI38)/ABS(BI38), 1)))) -> - | BL38: コード１９ | CA38: =IF(BS38="-", "-", IF(BW38="-", "-", IF(ABS(BW38)=0, "-", ROUND(100*(BS38-BW38)/ABS(BW38), 10)))) -> - | CB38: =IF(BX38="-", "-", IF(BZ38="-", "-", IF(ABS(BZ38)=0, "-", ROUND(100*(BX38-BZ38)/ABS(BZ38), 1)))) -> - | CC38: =IF(BY38="-", "-", IF(CA38="-", "-", IF(ABS(CA38)=0, "-", ROUND(100*(BY38-CA38)/ABS(CA38), 1)))) -> -
B39: 11 ほ場枚数及び面積（１経営体当たり） | AD39: 単位：枚、ａ | AT39: コード５ | BI39: =IF(BA39="-", "-", IF(BE39="-", "-", IF(ABS(BE39)=0, "-", ROUND(100*(BA39-BE39)/ABS(BE39), 10)))) -> - | BJ39: =IF(BF39="-", "-", IF(BH39="-", "-", IF(ABS(BH39)=0, "-", ROUND(100*(BF39-BH39)/ABS(BH39), 1)))) -> - | BK39: =IF(BG39="-", "-", IF(BI39="-", "-", IF(ABS(BI39)=0, "-", ROUND(100*(BG39-BI39)/ABS(BI39), 1)))) -> - | BL39: コード２０ | CA39: =IF(BS39="-", "-", IF(BW39="-", "-", IF(ABS(BW39)=0, "-", ROUND(100*(BS39-BW39)/ABS(BW39), 10)))) -> - | CB39: =IF(BX39="-", "-", IF(BZ39="-", "-", IF(ABS(BZ39)=0, "-", ROUND(100*(BX39-BZ39)/ABS(BZ39), 1)))) -> - | CC39: =IF(BY39="-", "-", IF(CA39="-", "-", IF(ABS(CA39)=0, "-", ROUND(100*(BY39-CA39)/ABS(CA39), 1)))) -> -
I40: 枚数 | T40: 面積 | AT40: コード６ | BI40: =IF(BA40="-", "-", IF(BE40="-", "-", IF(ABS(BE40)=0, "-", ROUND(100*(BA40-BE40)/ABS(BE40), 10)))) -> - | BJ40: =IF(BF40="-", "-", IF(BH40="-", "-", IF(ABS(BH40)=0, "-", ROUND(100*(BF40-BH40)/ABS(BH40), 1)))) -> - | BK40: =IF(BG40="-", "-", IF(BI40="-", "-", IF(ABS(BI40)=0, "-", ROUND(100*(BG40-BI40)/ABS(BI40), 1)))) -> - | BL40: コード２１ | CA40: =IF(BS40="-", "-", IF(BW40="-", "-", IF(ABS(BW40)=0, "-", ROUND(100*(BS40-BW40)/ABS(BW40), 10)))) -> - | CB40: =IF(BX40="-", "-", IF(BZ40="-", "-", IF(ABS(BZ40)=0, "-", ROUND(100*(BX40-BZ40)/ABS(BZ40), 1)))) -> - | CC40: =IF(BY40="-", "-", IF(CA40="-", "-", IF(ABS(CA40)=0, "-", ROUND(100*(BY40-CA40)/ABS(CA40), 1)))) -> -
I41: =IF($B$1<>"",$B$1,"") | M41: =IF($B$1<>"",$B$1-1,"") | Q41: 増減率 | T41: =IF($B$1<>"",$B$1,"") | X41: =IF($B$1<>"",$B$1-1,"") | AB41: 増減率 | AT41: コード７ | BI41: =IF(BA41="-", "-", IF(BE41="-", "-", IF(ABS(BE41)=0, "-", ROUND(100*(BA41-BE41)/ABS(BE41), 10)))) -> - | BJ41: =IF(BF41="-", "-", IF(BH41="-", "-", IF(ABS(BH41)=0, "-", ROUND(100*(BF41-BH41)/ABS(BH41), 1)))) -> - | BK41: =IF(BG41="-", "-", IF(BI41="-", "-", IF(ABS(BI41)=0, "-", ROUND(100*(BG41-BI41)/ABS(BI41), 1)))) -> - | BL41: コード２２ | CA41: =IF(BS41="-", "-", IF(BW41="-", "-", IF(ABS(BW41)=0, "-", ROUND(100*(BS41-BW41)/ABS(BW41), 10)))) -> - | CB41: =IF(BX41="-", "-", IF(BZ41="-", "-", IF(ABS(BZ41)=0, "-", ROUND(100*(BX41-BZ41)/ABS(BZ41), 1)))) -> - | CC41: =IF(BY41="-", "-", IF(CA41="-", "-", IF(ABS(CA41)=0, "-", ROUND(100*(BY41-CA41)/ABS(CA41), 1)))) -> -
B42: 未整理又は10a未満 | Q42: =IF(I42="-", "-", IF(M42="-", "-", IF(ABS(M42)=0, "-", ROUND(100*(I42-M42)/ABS(M42), 10)))) -> - | R42: =IF(N42="-", "-", IF(P42="-", "-", IF(ABS(P42)=0, "-", ROUND(100*(N42-P42)/ABS(P42), 1)))) -> - | S42: =IF(O42="-", "-", IF(Q42="-", "-", IF(ABS(Q42)=0, "-", ROUND(100*(O42-Q42)/ABS(Q42), 1)))) -> - | AB42: =IF(T42="-", "-", IF(X42="-", "-", IF(ABS(X42)=0, "-", ROUND(100*(T42-X42)/ABS(X42), 10)))) -> - | AC42: =IF(Y42="-", "-", IF(AA42="-", "-", IF(ABS(AA42)=0, "-", ROUND(100*(Y42-AA42)/ABS(AA42), 1)))) -> - | AD42: =IF(Z42="-", "-", IF(AB42="-", "-", IF(ABS(AB42)=0, "-", ROUND(100*(Z42-AB42)/ABS(AB42), 1)))) -> - | AT42: コード８ | BI42: =IF(BA42="-", "-", IF(BE42="-", "-", IF(ABS(BE42)=0, "-", ROUND(100*(BA42-BE42)/ABS(BE42), 10)))) -> - | BJ42: =IF(BF42="-", "-", IF(BH42="-", "-", IF(ABS(BH42)=0, "-", ROUND(100*(BF42-BH42)/ABS(BH42), 1)))) -> - | BK42: =IF(BG42="-", "-", IF(BI42="-", "-", IF(ABS(BI42)=0, "-", ROUND(100*(BG42-BI42)/ABS(BI42), 1)))) -> - | BL42: コード２３ | CA42: =IF(BS42="-", "-", IF(BW42="-", "-", IF(ABS(BW42)=0, "-", ROUND(100*(BS42-BW42)/ABS(BW42), 10)))) -> - | CB42: =IF(BX42="-", "-", IF(BZ42="-", "-", IF(ABS(BZ42)=0, "-", ROUND(100*(BX42-BZ42)/ABS(BZ42), 1)))) -> - | CC42: =IF(BY42="-", "-", IF(CA42="-", "-", IF(ABS(CA42)=0, "-", ROUND(100*(BY42-CA42)/ABS(CA42), 1)))) -> -
B43: 10～20ａ区画 | Q43: =IF(I43="-", "-", IF(M43="-", "-", IF(ABS(M43)=0, "-", ROUND(100*(I43-M43)/ABS(M43), 10)))) -> - | R43: =IF(N43="-", "-", IF(P43="-", "-", IF(ABS(P43)=0, "-", ROUND(100*(N43-P43)/ABS(P43), 1)))) -> - | S43: =IF(O43="-", "-", IF(Q43="-", "-", IF(ABS(Q43)=0, "-", ROUND(100*(O43-Q43)/ABS(Q43), 1)))) -> - | AB43: =IF(T43="-", "-", IF(X43="-", "-", IF(ABS(X43)=0, "-", ROUND(100*(T43-X43)/ABS(X43), 10)))) -> - | AC43: =IF(Y43="-", "-", IF(AA43="-", "-", IF(ABS(AA43)=0, "-", ROUND(100*(Y43-AA43)/ABS(AA43), 1)))) -> - | AD43: =IF(Z43="-", "-", IF(AB43="-", "-", IF(ABS(AB43)=0, "-", ROUND(100*(Z43-AB43)/ABS(AB43), 1)))) -> - | AT43: コード９ | BI43: =IF(BA43="-", "-", IF(BE43="-", "-", IF(ABS(BE43)=0, "-", ROUND(100*(BA43-BE43)/ABS(BE43), 10)))) -> - | BJ43: =IF(BF43="-", "-", IF(BH43="-", "-", IF(ABS(BH43)=0, "-", ROUND(100*(BF43-BH43)/ABS(BH43), 1)))) -> - | BK43: =IF(BG43="-", "-", IF(BI43="-", "-", IF(ABS(BI43)=0, "-", ROUND(100*(BG43-BI43)/ABS(BI43), 1)))) -> - | BL43: コード２４ | CA43: =IF(BS43="-", "-", IF(BW43="-", "-", IF(ABS(BW43)=0, "-", ROUND(100*(BS43-BW43)/ABS(BW43), 10)))) -> - | CB43: =IF(BX43="-", "-", IF(BZ43="-", "-", IF(ABS(BZ43)=0, "-", ROUND(100*(BX43-BZ43)/ABS(BZ43), 1)))) -> - | CC43: =IF(BY43="-", "-", IF(CA43="-", "-", IF(ABS(CA43)=0, "-", ROUND(100*(BY43-CA43)/ABS(CA43), 1)))) -> -
