Workbook

Sheet No1
B1: =B5&"年産 農業経営統計調査（米生産費統計（組織法人経営体）） 集計結果表№１" -> 年産 農業経営統計調査（米生産費統計（組織法人経営体）） 集計結果表№１
B2: 集計名称：
B3: ○ 指標部
A4: 1 | B4: 調査年 | H4: 都道府県等 | N4: 経営種類 | T4: 生産費区分 | Z4: 規模階層 | AF4: 平均値種類 | AL4: 集計経営体数 | AR4: 集計倍率 | AX4: 加重・総和の別 | BD4: 集計区分
A5: 2 | I5: =IF(H5<>"",DGET(リスト!A2:B71,"都道府県番号",リスト!B73:B74),"") | O5: =IF(N5>0,DGET(リスト!S2:T4,"経営種類",リスト!T6:T7),"") | U5: =IF(N5>0,DGET(リスト!D2:E3,"生産費区分",リスト!XDY15:XDY16),"") | AA5: =IF(Z5<>"",DGET(リスト!J3:K17,"規模階層",リスト!K19:K20),"") | AG5: =IF(AF5<>"",DGET(リスト!M2:N7,"平均値種類",リスト!N9:N10),"") | AY5: =IF(AX5>0,DGET(リスト!P2:Q4,"加重・総和の別",リスト!Q6:Q7),"") | BE5: =IF(BD5>0,DGET(リスト!G2:H7,"集計区分",リスト!H9:H10),"")
A6: 3 | B6: １ 生産費総括（円）
A7: 4 | H7: １０ ａ 当 た り | AF7: ６０ ｋｇ 当 た り
A8: 5 | H8: 購入 | N8: 自給 | T8: 償却 | Z8: 計 | AF8: 購入 | AL8: 自給 | AR8: 償却 | AX8: 計
A9: 6 | B9: 物財費 | BJ9: ４ 経営耕地（ａ）
A10: 7 | C10: 種苗費 | BP10: 所有地 | BV10: 借入地 | CB10: 計
A11: 8 | C11: 肥料費 | BJ11: 田
A12: 9 | C12: 農業薬剤費 | BJ12: 普通畑
A13: 10 | C13: 光熱動力費 | BJ13: 樹園地
A14: 11 | C14: その他諸材料費 | BJ14: 牧草地
A15: 12 | C15: 土地改良及び水利費 | BJ15: 計
A16: 13 | C16: 賃借料及び料金 | BJ16: ５ 地 代（円、ａ）
A17: 14 | C17: 物件税及び公課諸負担 | BP17: １ 経 営 体 当 た り
A18: 15 | C18: 建物費 | BP18: 自作地 | BV18: 借入地 | CB18: 計
A19: 16 | C19: 自動車費 | BJ19: 作付地 | BL19: 作付実面積
A20: 17 | C20: 農機具費 | BL20: 土地台帳面積
A21: 18 | C21: 生産管理費 | BL21: 地代総額
A22: 19 | B22: 労働費 | BL22: 負担地代
A23: 20 | C23: 直接労働費 | BJ23: 以 外 作付地 | BL23: 使用面積
A24: 21 | C24: 間接労働費 | BL24: 賃借料総額
A25: 22 | B25: 費用合計 | BL25: 負担地代
A26: 23 | B26: 副産物価額 | BP26: １０ ａ 当 た り
A27: 24 | B27: 生産費 | BP27: 自作地 | BV27: 借入地 | CB27: 計
A28: 25 | B28: 支払利子 | BJ28: 実勢地代
A29: 26 | B29: 支払地代 | BJ29: 作付地負担地代
A30: 27 | B30: 利子・地代算入生産費 | BJ30: 作付地以外地代
A31: 28 | B31: 自己資本利子
A32: 29 | B32: 自作地地代
A33: 30 | B33: 全算入生産費
A34: 31 | B34: ２ 投下労働時間（時間）10ａ当たり | BD34: ６ 資本額及び資本利子（円）
A35: 32 | H35: 構成員 | N35: 雇用 | T35: 計 | Z35: ６０ｋｇ当たり | BJ35: 資本額 | BV35: 利子額
A36: 33 | B36: 直接労働時間 | C36: 種子予措 | BJ36: １０ａ当たり | BP36: ６０ｋｇ当たり | BV36: １０ａ当たり | CB36: ６０ｋｇ当たり
A37: 34 | C37: 育苗 | BD37: 資本額計
A38: 35 | C38: 耕起整地 | BE38: 借入資本
A39: 36 | C39: 基肥 | BE39: 自己資本
A40: 37 | C40: 直まき | BD40: 資産別内訳 | BE40: 流動資本
...

Sheet No2
B1: =B5&"年産 農業経営統計調査（米生産費統計（組織法人経営体）） 集計結果表№２" -> 年産 農業経営統計調査（米生産費統計（組織法人経営体）） 集計結果表№２
B2: 集計名称： | F2: =IF('No1'!F2<>"",'No1'!F2,"")
B3: ○ 指標部
A4: 1 | B4: 調査年 | H4: 都道府県等 | N4: 経営種類 | T4: 生産費区分 | Z4: 規模階層 | AF4: 平均値種類 | AL4: 集計経営体数 | AR4: 集計倍率 | AX4: 加重・総和の別 | BD4: 集計区分
A5: 2 | B5: =IF('No1'!B5<>"",'No1'!B5,"") | H5: =IF('No1'!H5<>"",'No1'!H5,"") | I5: ='No1'!I5 | N5: =IF('No1'!N5<>"",'No1'!N5,"") | O5: ='No1'!O5 | T5: =IF('No1'!T5<>"",'No1'!T5,"") | U5: ='No1'!U5 | Z5: =IF('No1'!Z5<>"",'No1'!Z5,"") | AA5: ='No1'!AA5 | AF5: =IF('No1'!AF5<>"",'No1'!AF5,"") | AG5: ='No1'!AG5 | AL5: =IF('No1'!AL5<>"",'No1'!AL5,"") | AR5: =IF('No1'!AR5<>"",'No1'!AR5,"") | AX5: =IF('No1'!AX5<>"",'No1'!AX5,"") | AY5: ='No1'!AY5 | BD5: =IF('No1'!BD5<>"",'No1'!BD5,"") | BE5: ='No1'!BE5
A6: 3 | B6: 16 稲作作業の受委託状況 | AL6: 11 借入金（買掛未払金含む）の資金種類別内訳（円） | BP6: 10 物件税及び公課諸負担（円）
A7: 4 | B7: 受託作業 | N7: 数量 | T7: 委託作業 | AF7: 数量 | AR7: １経営体当たり | BD7: １０ ａ 当 た り | BV7: １経営体当たり | CB7: １０ａ当たり
A8: 5 | B8: 全作業 | M8: ａ | T8: 育苗 | AE8: ａ | AR8: 調始未償還残高 | AX8: 支払利子 | BD8: 調始未償還残高 | BJ8: 支払利子 | BP8: 物件税 | BQ8: 固定資産税
A9: 6 | B9: 耕うん・整地 | M9: ａ | T9: 防除 | AE9: ａ | AL9: 借入金 | AO9: 短期 | BR9: 建物
A10: 7 | B10: 育苗 | M10: ａ | AO10: 長期 | BR10: 農機具
A11: 8 | B11: 田植 | M11: ａ | AL11: 買掛未払金 | BQ11: 自動車重量税
A12: 9 | B12: 防除 | M12: ａ | AL12: 計 | BQ12: 自動車税
A13: 10 | B13: 刈取・脱穀 | M13: ａ | AL13: ９ 農業共済金、各種助成措置の状況（円） | BQ13: 不動産取得税
A14: 11 | B14: 乾燥・調製 | M14: kg | AR14: １経営体当たり | BD14: １０ ａ 当 た り | BQ14: 軽自動車税
A15: 12 | AR15: 拠出金 | AX15: 受取金 | BD15: 拠出金 | BJ15: 受取金 | BQ15: 水利地益税
A16: 13 | B16: 23 「移植」「直まき」別作付面積（ａ） | T16: ８ 収益性（円） | BQ16: 都市計画税
A17: 14 | H17: 面積 | Z17: １０ａ当たり | BQ17: 共同施設税
A18: 15 | B18: 移植 | T18: 粗収益 | BQ18: 小計
A19: 16 | B19: 直まき | T19: 生産費総額 | BP19: 公課諸負担 | BQ19: 集落協議会費
A20: 17 | B20: 計 | T20: 利潤 | BQ20: 農業協同組合費
A21: 18 | B21: 24 田の概況 | T21: 所得 | BQ21: 農事実行組合費
A22: 19 | H22: 該当の有無等 | U22: １日当たり | BQ22: 農業共済組合賦課金
A23: 20 | B23: 田の団地数 | T23: 構成員労働報酬 | BQ23: 自賠責保険
A24: 21 | B24: 済面積 区画整理 田のうち | D24: 50％未満 | U24: １日当たり | BQ24: 小計
A25: 22 | D25: 50～80％ | T25: 〔参考〕各種助成措置を加えた場合（円） | BP25: 合計
A26: 23 | D26: 80％以上 | Z26: １０ａ当たり
A27: 24 | B27: 25 ほ場枚数及び面積（ａ） | T27: 粗収益 | BJ27: 21 生産物の処分内訳（㎏、円）
A28: 25 | H28: 枚数 | N28: 面積 | T28: 生産費総額 | BP28: １０ ａ 当 た り
A29: 26 | B29: 未整理又は10a未満 | T29: 利潤 | BP29: 数量 | BV29: 価額 | CB29: 単価
A30: 27 | B30: 10～20ａ区画 | T30: 所得 | BJ30: 玄米（予定を含む） | BK30: 販売用 | BL30: 主食用
A31: 28 | B31: 20～30ａ区画 | U31: １日当たり | BL31: 加工用
A32: 29 | B32: 30～50ａ区画 | T32: 構成員労働報酬 | BL32: 区分出荷
A33: 30 | B33: 50ａ～１ha区画 | U33: １日当たり | BL33: 小計
A34: 31 | B34: １ha以上区画 | BK34: 組織用 | BL34: 種子用
A35: 32 | B35: 計 | BL35: 飯米用
A36: 33 | B36: 26 団地への距離等（㎞） | BL36: その他
A37: 34 | B37: ほ場間の距離 | BL37: 小計
A38: 35 | B38: 団地への平均距離 | BK38: 合計
A39: 36 | B39: 15 うるち米の品種別作付面積（ａ） | T39: 27 飼料用米作付状況（ａ） | BJ39: いなわら等 | BK39: 販売 | BL39: 加工用
A40: 37 | H40: 品種コード | N40: 面積 | T40: 飼料用米 | BL40: その他
...

Sheet No3
B1: =B5&"年産 農業経営統計調査（米生産費統計（組織法人経営体）） 集計結果表№３" -> 年産 農業経営統計調査（米生産費統計（組織法人経営体）） 集計結果表№３
B2: 集計名称： | F2: =IF('No1'!F2<>"",'No1'!F2,"")
B3: ○ 指標部
A4: 1 | B4: 調査年 | H4: 都道府県等 | N4: 経営種類 | T4: 生産費区分 | Z4: 規模階層 | AF4: 平均値種類 | AL4: 集計経営体数 | AR4: 集計倍率 | AX4: 加重・総和の別 | BD4: 集計区分
A5: 2 | B5: =IF('No1'!B5<>"",'No1'!B5,"") | H5: =IF('No1'!H5<>"",'No1'!H5,"") | I5: ='No1'!I5 | N5: =IF('No1'!N5<>"",'No1'!N5,"") | O5: ='No1'!O5 | T5: =IF('No1'!T5<>"",'No1'!T5,"") | U5: ='No1'!U5 | Z5: =IF('No1'!Z5<>"",'No1'!Z5,"") | AA5: ='No1'!AA5 | AF5: =IF('No1'!AF5<>"",'No1'!AF5,"") | AG5: ='No1'!AG5 | AL5: =IF('No1'!AL5<>"",'No1'!AL5,"") | AR5: =IF('No1'!AR5<>"",'No1'!AR5,"") | AX5: =IF('No1'!AX5<>"",'No1'!AX5,"") | AY5: ='No1'!AY5 | BD5: =IF('No1'!BD5<>"",'No1'!BD5,"") | BE5: ='No1'!BE5
A6: 3 | B6: 30 原単位 | AR6: 12 減価償却費（円）（使用台数は10経営体当たり） | BV6: 任意項目 10ａ当たり
A7: 4 | N7: １０ ａ 当 た り | AF7: ６０ ｋｇ 当 た り | BD7: 使用台数（台） | BJ7: １経営体当たり | BP7: １０ａ当たり
A8: 5 | N8: 数量 | T8: 価額 | Z8: 単価 | AF8: 数量 | AL8: 価額 | AR8: 建物・構築物 | AT8: 住宅
A9: 6 | B9: 種苗費 | D9: 種子もみ | G9: 購入 | AT9: 事務所
A10: 7 | G10: 自給 | AT10: 納屋・倉庫
A11: 8 | D11: 苗 | AT11: 作業場
A12: 9 | D12: 計 | AT12: 車庫
A13: 10 | B13: 肥料費 | D13: 窒素質肥料 | AT13: ライスセンター
A14: 11 | D14: りん酸質肥料 | AT14: 育苗ハウス
A15: 12 | D15: カリ質肥料 | AT15: 稲架
A16: 13 | D16: けい酸質肥料 | AT16: コンクリートけい畔
A17: 14 | D17: 炭酸カルシウム（石灰含む） | AT17: 暗きょ排水施設
A18: 15 | D18: 複合肥料 | AT18: 客土
A19: 16 | D19: 土壌改良資材 | AT19: 作業道
A20: 17 | D20: たい肥・きゅう肥 | AT20: 用水路
A21: 18 | D21: その他 | AT21: たい肥盤
A22: 19 | D22: 自給 | G22: たい肥 | AT22: その他
A23: 20 | G23: きゅう肥 | AT23: 計
A24: 21 | G24: 稲・麦わら | AW24: 処分差損失
A25: 22 | G25: その他 | AR25: 自動車 | AT25: 貨物自動車
A26: 23 | D26: 計 | AT26: その他
A27: 24 | B27: 農業薬剤費 | D27: 殺虫剤 | AT27: 計
A28: 25 | D28: 殺菌剤 | AW28: 処分差損失
A29: 26 | D29: 殺虫殺菌剤 | AR29: 農機具 | AT29: 電動機
A30: 27 | D30: 除草剤 | AT30: 発動機
A31: 28 | D31: その他 | AT31: 揚水ポンプ
A32: 29 | D32: 計 | AT32: 乗用トラクター | AW32: 20馬力未満
A33: 30 | B33: 光熱動力費 | D33: 動力 燃料 | G33: 重油 | AW33: 20～50馬力未満
A34: 31 | G34: 軽油 | AW34: 50～80馬力未満
A35: 32 | G35: 灯油 | AW35: 80～100馬力未満
A36: 33 | G36: ガソリン | AW36: 100馬力以上
A37: 34 | G37: 潤滑油 | AT37: 歩行用トラクター
A38: 35 | G38: 混合油 | AT38: 電熱育苗機
A39: 36 | D39: 電力料 | AT39: 田植機 | AW39: ２条植
A40: 37 | D40: その他 | AW40: ３～５条植
...

Sheet リスト
A2: 都道府県番号 | B2: コード | D2: 生産費区分 | E2: コード | G2: 集計区分 | H2: コード | J2: 米 | M2: 平均値種類 | N2: コード | P2: 加重・総和の別 | Q2: コード | S2: 経営種類 | T2: コード
A3: 全国 | B3: 0 | D3: 米 | E3: 80 | G3: 全調査対象 | H3: 1 | J3: 規模階層 | K3: コード | M3: 通常 | N3: 0 | P3: 加重平均 | Q3: 1 | S3: 個別経営体 | T3: 1
A4: 都府県平均 | B4: 60 | J4: 平均 | K4: 0 | M4: 総数 | N4: 1 | P4: 総和平均 | Q4: 2 | S4: 組織法人経営体 | T4: 2
A5: 北海道 | B5: 1 | J5: 5.0ha未満 | K5: 1 | M5: 10ａ当たり | N5: 2
A6: 東北 | B6: 61 | J6: 5.0～10.0 | K6: 2 | M6: 単位数量当たり | N6: 3 | Q6: コード | T6: コード
A7: 北陸 | B7: 62 | G7: 集計対象 | H7: 2 | J7: 10.0ha以上 | K7: 3 | M7: １経営体当たり | N7: 4 | Q7: ="="&'No1'!AX5 -> = | T7: ="="&'No1'!N5 -> =
A8: 関東・東山 | B8: 63 | J8: 10.0～15.0 | K8: 4
A9: 東海 | B9: 67 | H9: コード | J9: 15.0ha以上 | K9: 5 | N9: コード
A10: 近畿 | B10: 68 | H10: ="="&'No1'!BD5 -> = | J10: 15.0～20.0 | K10: 6 | N10: ="="&'No1'!AF5 -> =
A11: 中国 | B11: 71 | J11: 20.0ha以上 | K11: 7
A12: 四国 | B12: 74 | J12: 20.0～30.0 | K12: 8
A13: 九州 | B13: 75 | J13: 30.0ha以上 | K13: 9
A14: 沖縄 | B14: 47 | J14: 30.0～50.0 | K14: 10
A15: 北関東 | B15: 64 | E15: コード | J15: 50.0ha以上 | K15: 11
A16: 南関東 | B16: 65 | E16: ="="&'No1'!N5 -> = | J16: 50.0～100.0 | K16: 12
A17: 東山 | B17: 66 | J17: 100.0ha以上 | K17: 13
A18: 北東北 | B18: 69
A19: 南東北 | B19: 70 | K19: コード
A20: 山陰 | B20: 72 | K20: ="="&'No1'!Z5 -> =
A21: 山陽 | B21: 73
A22: 北九州 | B22: 76
A23: 南九州 | B23: 77
A24: 関東農政局 | B24: 93
A25: 東海農政局 | B25: 94
A26: 中国四国局 | B26: 95
A27: 青森 | B27: 2
A28: 岩手 | B28: 3
A29: 宮城 | B29: 4
A30: 秋田 | B30: 5
A31: 山形 | B31: 6
A32: 福島 | B32: 7
... A71: 鹿児島 | B71: 46
B73: コード
B74: ="="&'No1'!H5 -> =
