Workbook
Name 個別経営体: 'リスト '!$D$2:$D$6
Name 作業_Blank: 'リスト '!$H$2
Name 作業_牛乳: 'リスト '!$F$2:$F$12
Name 作業_牛乳以外: 'リスト '!$G$2:$G$11
Name 自給牧草給与割合: 設定!#REF!
Name 組織法人経営体: 'リスト '!$E$2:$E$3

Sheet 設定
C1: 畜産物生産費統計 設定シート
B2: 2020センサス番号<入力> | D2: 経営種類 | F2: 生産費区分
C5: 設定 | G5: 集計 <自動>
B6: 集計月 | C6: 作業者 | D6: 性別 | E6: 年齢 | F6: 雇用形態 | G6: 労働時間 | H6: 定型 | L6: 定型以外
B7: <選択> | C7: <入力> | D7: <選択> | E7: <入力> | F7: <選択> | H7: 飼料の調理・給与・給水 | I7: 敷料搬入・きゅう肥搬出 | J7: =IF($F$3="","",IF($F$3="牛乳","搾乳・牛乳処理・運搬","その他の飼育作業")) | K7: =IF($F$3="","",IF($F$3="牛乳","その他の飼育作業","")) | L7: =IF($D$3="組織法人経営体","内給飼料の生産","自給飼料の生産") -> 自給飼料の生産 | M7: 購入付帯労働時間 | N7: 建物・農機具等の修繕 | O7: 集会出席時間 | P7: 技術習得時間 | Q7: 簿記記帳時間 | R7: 経営管理労働時間
G8: 時間 | H8: 時間 | I8: 時間 | J8: 時間 | K8: 時間 | L8: 時間 | M8: 時間 | N8: 時間 | O8: 時間 | P8: 時間 | Q8: 時間 | R8: 時間
B9: <=12 | G9: =SUM(H9:R9) -> 0 | H9: =SUMIFS(月別入力!$I:$I,月別入力!$E:$E,$C9,月別入力!$B:$B,$B9,月別入力!$H:$H,$F9,月別入力!$D:$D,H$7) -> 0 | I9: =SUMIFS(月別入力!$I:$I,月別入力!$E:$E,$C9,月別入力!$B:$B,$B9,月別入力!$H:$H,$F9,月別入力!$D:$D,I$7) -> 0 | J9: =SUMIFS(月別入力!$I:$I,月別入力!$E:$E,$C9,月別入力!$B:$B,$B9,月別入力!$H:$H,$F9,月別入力!$D:$D,J$7) -> 0 | K9: =SUMIFS(月別入力!$I:$I,月別入力!$E:$E,$C9,月別入力!$B:$B,$B9,月別入力!$H:$H,$F9,月別入力!$D:$D,K$7) -> 0 | L9: =SUMIFS(月別入力!$I:$I,月別入力!$E:$E,$C9,月別入力!$B:$B,$B9,月別入力!$H:$H,$F9,月別入力!$D:$D,L$7) -> 0 | M9: =SUMIFS(月別入力!$I:$I,月別入力!$E:$E,$C9,月別入力!$B:$B,$B9,月別入力!$H:$H,$F9,月別入力!$D:$D,M$7) -> 0 | N9: =SUMIFS(月別入力!$I:$I,月別入力!$E:$E,$C9,月別入力!$B:$B,$B9,月別入力!$H:$H,$F9,月別入力!$D:$D,N$7) -> 0 | O9: =SUMIFS(月別入力!$I:$I,月別入力!$E:$E,$C9,月別入力!$B:$B,$B9,月別入力!$H:$H,$F9,月別入力!$D:$D,O$7) -> 0 | ... R9: =SUMIFS(月別入力!$I:$I,月別入力!$E:$E,$C9,月別入力!$B:$B,$B9,月別入力!$H:$H,$F9,月別入力!$D:$D,R$7) -> 0
B10: =B$9 -> <=12 | G10: =SUM(H10:R10) -> 0 | H10: =SUMIFS(月別入力!$I:$I,月別入力!$E:$E,$C10,月別入力!$B:$B,$B10,月別入力!$H:$H,$F10,月別入力!$D:$D,H$7) -> 0 | I10: =SUMIFS(月別入力!$I:$I,月別入力!$E:$E,$C10,月別入力!$B:$B,$B10,月別入力!$H:$H,$F10,月別入力!$D:$D,I$7) -> 0 | J10: =SUMIFS(月別入力!$I:$I,月別入力!$E:$E,$C10,月別入力!$B:$B,$B10,月別入力!$H:$H,$F10,月別入力!$D:$D,J$7) -> 0 | K10: =SUMIFS(月別入力!$I:$I,月別入力!$E:$E,$C10,月別入力!$B:$B,$B10,月別入力!$H:$H,$F10,月別入力!$D:$D,K$7) -> 0 | L10: =SUMIFS(月別入力!$I:$I,月別入力!$E:$E,$C10,月別入力!$B:$B,$B10,月別入力!$H:$H,$F10,月別入力!$D:$D,L$7) -> 0 | M10: =SUMIFS(月別入力!$I:$I,月別入力!$E:$E,$C10,月別入力!$B:$B,$B10,月別入力!$H:$H,$F10,月別入力!$D:$D,M$7) -> 0 | N10: =SUMIFS(月別入力!$I:$I,月別入力!$E:$E,$C10,月別入力!$B:$B,$B10,月別入力!$H:$H,$F10,月別入力!$D:$D,N$7) -> 0 | O10: =SUMIFS(月別入力!$I:$I,月別入力!$E:$E,$C10,月別入力!$B:$B,$B10,月別入力!$H:$H,$F10,月別入力!$D:$D,O$7) -> 0 | ... R10: =SUMIFS(月別入力!$I:$I,月別入力!$E:$E,$C10,月別入力!$B:$B,$B10,月別入力!$H:$H,$F10,月別入力!$D:$D,R$7) -> 0
B11: =B$9 -> <=12 | G11: =SUM(H11:R11) -> 0 | H11: =SUMIFS(月別入力!$I:$I,月別入力!$E:$E,$C11,月別入力!$B:$B,$B11,月別入力!$H:$H,$F11,月別入力!$D:$D,H$7) -> 0 | I11: =SUMIFS(月別入力!$I:$I,月別入力!$E:$E,$C11,月別入力!$B:$B,$B11,月別入力!$H:$H,$F11,月別入力!$D:$D,I$7) -> 0 | J11: =SUMIFS(月別入力!$I:$I,月別入力!$E:$E,$C11,月別入力!$B:$B,$B11,月別入力!$H:$H,$F11,月別入力!$D:$D,J$7) -> 0 | K11: =SUMIFS(月別入力!$I:$I,月別入力!$E:$E,$C11,月別入力!$B:$B,$B11,月別入力!$H:$H,$F11,月別入力!$D:$D,K$7) -> 0 | L11: =SUMIFS(月別入力!$I:$I,月別入力!$E:$E,$C11,月別入力!$B:$B,$B11,月別入力!$H:$H,$F11,月別入力!$D:$D,L$7) -> 0 | M11: =SUMIFS(月別入力!$I:$I,月別入力!$E:$E,$C11,月別入力!$B:$B,$B11,月別入力!$H:$H,$F11,月別入力!$D:$D,M$7) -> 0 | N11: =SUMIFS(月別入力!$I:$I,月別入力!$E:$E,$C11,月別入力!$B:$B,$B11,月別入力!$H:$H,$F11,月別入力!$D:$D,N$7) -> 0 | O11: =SUMIFS(月別入力!$I:$I,月別入力!$E:$E,$C11,月別入力!$B:$B,$B11,月別入力!$H:$H,$F11,月別入力!$D:$D,O$7) -> 0 | ... R11: =SUMIFS(月別入力!$I:$I,月別入力!$E:$E,$C11,月別入力!$B:$B,$B11,月別入力!$H:$H,$F11,月別入力!$D:$D,R$7) -> 0
B12: =B$9 -> <=12 | G12: =SUM(H12:R12) -> 0 | H12: =SUMIFS(月別入力!$I:$I,月別入力!$E:$E,$C12,月別入力!$B:$B,$B12,月別入力!$H:$H,$F12,月別入力!$D:$D,H$7) -> 0 | I12: =SUMIFS(月別入力!$I:$I,月別入力!$E:$E,$C12,月別入力!$B:$B,$B12,月別入力!$H:$H,$F12,月別入力!$D:$D,I$7) -> 0 | J12: =SUMIFS(月別入力!$I:$I,月別入力!$E:$E,$C12,月別入力!$B:$B,$B12,月別入力!$H:$H,$F12,月別入力!$D:$D,J$7) -> 0 | K12: =SUMIFS(月別入力!$I:$I,月別入力!$E:$E,$C12,月別入力!$B:$B,$B12,月別入力!$H:$H,$F12,月別入力!$D:$D,K$7) -> 0 | L12: =SUMIFS(月別入力!$I:$I,月別入力!$E:$E,$C12,月別入力!$B:$B,$B12,月別入力!$H:$H,$F12,月別入力!$D:$D,L$7) -> 0 | M12: =SUMIFS(月別入力!$I:$I,月別入力!$E:$E,$C12,月別入力!$B:$B,$B12,月別入力!$H:$H,$F12,月別入力!$D:$D,M$7) -> 0 | N12: =SUMIFS(月別入力!$I:$I,月別入力!$E:$E,$C12,月別入力!$B:$B,$B12,月別入力!$H:$H,$F12,月別入力!$D:$D,N$7) -> 0 | O12: =SUMIFS(月別入力!$I:$I,月別入力!$E:$E,$C12,月別入力!$B:$B,$B12,月別入力!$H:$H,$F12,月別入力!$D:$D,O$7) -> 0 | ... R12: =SUMIFS(月別入力!$I:$I,月別入力!$E:$E,$C12,月別入力!$B:$B,$B12,月別入力!$H:$H,$F12,月別入力!$D:$D,R$7) -> 0
B13: =B$9 -> <=12 | G13: =SUM(H13:R13) -> 0 | H13: =SUMIFS(月別入力!$I:$I,月別入力!$E:$E,$C13,月別入力!$B:$B,$B13,月別入力!$H:$H,$F13,月別入力!$D:$D,H$7) -> 0 | I13: =SUMIFS(月別入力!$I:$I,月別入力!$E:$E,$C13,月別入力!$B:$B,$B13,月別入力!$H:$H,$F13,月別入力!$D:$D,I$7) -> 0 | J13: =SUMIFS(月別入力!$I:$I,月別入力!$E:$E,$C13,月別入力!$B:$B,$B13,月別入力!$H:$H,$F13,月別入力!$D:$D,J$7) -> 0 | K13: =SUMIFS(月別入力!$I:$I,月別入力!$E:$E,$C13,月別入力!$B:$B,$B13,月別入力!$H:$H,$F13,月別入力!$D:$D,K$7) -> 0 | L13: =SUMIFS(月別入力!$I:$I,月別入力!$E:$E,$C13,月別入力!$B:$B,$B13,月別入力!$H:$H,$F13,月別入力!$D:$D,L$7) -> 0 | M13: =SUMIFS(月別入力!$I:$I,月別入力!$E:$E,$C13,月別入力!$B:$B,$B13,月別入力!$H:$H,$F13,月別入力!$D:$D,M$7) -> 0 | N13: =SUMIFS(月別入力!$I:$I,月別入力!$E:$E,$C13,月別入力!$B:$B,$B13,月別入力!$H:$H,$F13,月別入力!$D:$D,N$7) -> 0 | O13: =SUMIFS(月別入力!$I:$I,月別入力!$E:$E,$C13,月別入力!$B:$B,$B13,月別入力!$H:$H,$F13,月別入力!$D:$D,O$7) -> 0 | ... R13: =SUMIFS(月別入力!$I:$I,月別入力!$E:$E,$C13,月別入力!$B:$B,$B13,月別入力!$H:$H,$F13,月別入力!$D:$D,R$7) -> 0
B14: =B$9 -> <=12 | G14: =SUM(H14:R14) -> 0 | H14: =SUMIFS(月別入力!$I:$I,月別入力!$E:$E,$C14,月別入力!$B:$B,$B14,月別入力!$H:$H,$F14,月別入力!$D:$D,H$7) -> 0 | I14: =SUMIFS(月別入力!$I:$I,月別入力!$E:$E,$C14,月別入力!$B:$B,$B14,月別入力!$H:$H,$F14,月別入力!$D:$D,I$7) -> 0 | J14: =SUMIFS(月別入力!$I:$I,月別入力!$E:$E,$C14,月別入力!$B:$B,$B14,月別入力!$H:$H,$F14,月別入力!$D:$D,J$7) -> 0 | K14: =SUMIFS(月別入力!$I:$I,月別入力!$E:$E,$C14,月別入力!$B:$B,$B14,月別入力!$H:$H,$F14,月別入力!$D:$D,K$7) -> 0 | L14: =SUMIFS(月別入力!$I:$I,月別入力!$E:$E,$C14,月別入力!$B:$B,$B14,月別入力!$H:$H,$F14,月別入力!$D:$D,L$7) -> 0 | M14: =SUMIFS(月別入力!$I:$I,月別入力!$E:$E,$C14,月別入力!$B:$B,$B14,月別入力!$H:$H,$F14,月別入力!$D:$D,M$7) -> 0 | N14: =SUMIFS(月別入力!$I:$I,月別入力!$E:$E,$C14,月別入力!$B:$B,$B14,月別入力!$H:$H,$F14,月別入力!$D:$D,N$7) -> 0 | O14: =SUMIFS(月別入力!$I:$I,月別入力!$E:$E,$C14,月別入力!$B:$B,$B14,月別入力!$H:$H,$F14,月別入力!$D:$D,O$7) -> 0 | ... R14: =SUMIFS(月別入力!$I:$I,月別入力!$E:$E,$C14,月別入力!$B:$B,$B14,月別入力!$H:$H,$F14,月別入力!$D:$D,R$7) -> 0
B15: =B$9 -> <=12 | G15: =SUM(H15:R15) -> 0 | H15: =SUMIFS(月別入力!$I:$I,月別入力!$E:$E,$C15,月別入力!$B:$B,$B15,月別入力!$H:$H,$F15,月別入力!$D:$D,H$7) -> 0 | I15: =SUMIFS(月別入力!$I:$I,月別入力!$E:$E,$C15,月別入力!$B:$B,$B15,月別入力!$H:$H,$F15,月別入力!$D:$D,I$7) -> 0 | J15: =SUMIFS(月別入力!$I:$I,月別入力!$E:$E,$C15,月別入力!$B:$B,$B15,月別入力!$H:$H,$F15,月別入力!$D:$D,J$7) -> 0 | K15: =SUMIFS(月別入力!$I:$I,月別入力!$E:$E,$C15,月別入力!$B:$B,$B15,月別入力!$H:$H,$F15,月別入力!$D:$D,K$7) -> 0 | L15: =SUMIFS(月別入力!$I:$I,月別入力!$E:$E,$C15,月別入力!$B:$B,$B15,月別入力!$H:$H,$F15,月別入力!$D:$D,L$7) -> 0 | M15: =SUMIFS(月別入力!$I:$I,月別入力!$E:$E,$C15,月別入力!$B:$B,$B15,月別入力!$H:$H,$F15,月別入力!$D:$D,M$7) -> 0 | N15: =SUMIFS(月別入力!$I:$I,月別入力!$E:$E,$C15,月別入力!$B:$B,$B15,月別入力!$H:$H,$F15,月別入力!$D:$D,N$7) -> 0 | O15: =SUMIFS(月別入力!$I:$I,月別入力!$E:$E,$C15,月別入力!$B:$B,$B15,月別入力!$H:$H,$F15,月別入力!$D:$D,O$7) -> 0 | ... R15: =SUMIFS(月別入力!$I:$I,月別入力!$E:$E,$C15,月別入力!$B:$B,$B15,月別入力!$H:$H,$F15,月別入力!$D:$D,R$7) -> 0
B16: =B$9 -> <=12 | G16: =SUM(H16:R16) -> 0 | H16: =SUMIFS(月別入力!$I:$I,月別入力!$E:$E,$C16,月別入力!$B:$B,$B16,月別入力!$H:$H,$F16,月別入力!$D:$D,H$7) -> 0 | I16: =SUMIFS(月別入力!$I:$I,月別入力!$E:$E,$C16,月別入力!$B:$B,$B16,月別入力!$H:$H,$F16,月別入力!$D:$D,I$7) -> 0 | J16: =SUMIFS(月別入力!$I:$I,月別入力!$E:$E,$C16,月別入力!$B:$B,$B16,月別入力!$H:$H,$F16,月別入力!$D:$D,J$7) -> 0 | K16: =SUMIFS(月別入力!$I:$I,月別入力!$E:$E,$C16,月別入力!$B:$B,$B16,月別入力!$H:$H,$F16,月別入力!$D:$D,K$7) -> 0 | L16: =SUMIFS(月別入力!$I:$I,月別入力!$E:$E,$C16,月別入力!$B:$B,$B16,月別入力!$H:$H,$F16,月別入力!$D:$D,L$7) -> 0 | M16: =SUMIFS(月別入力!$I:$I,月別入力!$E:$E,$C16,月別入力!$B:$B,$B16,月別入力!$H:$H,$F16,月別入力!$D:$D,M$7) -> 0 | N16: =SUMIFS(月別入力!$I:$I,月別入力!$E:$E,$C16,月別入力!$B:$B,$B16,月別入力!$H:$H,$F16,月別入力!$D:$D,N$7) -> 0 | O16: =SUMIFS(月別入力!$I:$I,月別入力!$E:$E,$C16,月別入力!$B:$B,$B16,月別入力!$H:$H,$F16,月別入力!$D:$D,O$7) -> 0 | ... R16: =SUMIFS(月別入力!$I:$I,月別入力!$E:$E,$C16,月別入力!$B:$B,$B16,月別入力!$H:$H,$F16,月別入力!$D:$D,R$7) -> 0
B17: =B$9 -> <=12 | G17: =SUM(H17:R17) -> 0 | H17: =SUMIFS(月別入力!$I:$I,月別入力!$E:$E,$C17,月別入力!$B:$B,$B17,月別入力!$H:$H,$F17,月別入力!$D:$D,H$7) -> 0 | I17: =SUMIFS(月別入力!$I:$I,月別入力!$E:$E,$C17,月別入力!$B:$B,$B17,月別入力!$H:$H,$F17,月別入力!$D:$D,I$7) -> 0 | J17: =SUMIFS(月別入力!$I:$I,月別入力!$E:$E,$C17,月別入力!$B:$B,$B17,月別入力!$H:$H,$F17,月別入力!$D:$D,J$7) -> 0 | K17: =SUMIFS(月別入力!$I:$I,月別入力!$E:$E,$C17,月別入力!$B:$B,$B17,月別入力!$H:$H,$F17,月別入力!$D:$D,K$7) -> 0 | L17: =SUMIFS(月別入力!$I:$I,月別入力!$E:$E,$C17,月別入力!$B:$B,$B17,月別入力!$H:$H,$F17,月別入力!$D:$D,L$7) -> 0 | M17: =SUMIFS(月別入力!$I:$I,月別入力!$E:$E,$C17,月別入力!$B:$B,$B17,月別入力!$H:$H,$F17,月別入力!$D:$D,M$7) -> 0 | N17: =SUMIFS(月別入力!$I:$I,月別入力!$E:$E,$C17,月別入力!$B:$B,$B17,月別入力!$H:$H,$F17,月別入力!$D:$D,N$7) -> 0 | O17: =SUMIFS(月別入力!$I:$I,月別入力!$E:$E,$C17,月別入力!$B:$B,$B17,月別入力!$H:$H,$F17,月別入力!$D:$D,O$7) -> 0 | ... R17: =SUMIFS(月別入力!$I:$I,月別入力!$E:$E,$C17,月別入力!$B:$B,$B17,月別入力!$H:$H,$F17,月別入力!$D:$D,R$7) -> 0
B18: =B$9 -> <=12 | G18: =SUM(H18:R18) -> 0 | H18: =SUMIFS(月別入力!$I:$I,月別入力!$E:$E,$C18,月別入力!$B:$B,$B18,月別入力!$H:$H,$F18,月別入力!$D:$D,H$7) -> 0 | I18: =SUMIFS(月別入力!$I:$I,月別入力!$E:$E,$C18,月別入力!$B:$B,$B18,月別入力!$H:$H,$F18,月別入力!$D:$D,I$7) -> 0 | J18: =SUMIFS(月別入力!$I:$I,月別入力!$E:$E,$C18,月別入力!$B:$B,$B18,月別入力!$H:$H,$F18,月別入力!$D:$D,J$7) -> 0 | K18: =SUMIFS(月別入力!$I:$I,月別入力!$E:$E,$C18,月別入力!$B:$B,$B18,月別入力!$H:$H,$F18,月別入力!$D:$D,K$7) -> 0 | L18: =SUMIFS(月別入力!$I:$I,月別入力!$E:$E,$C18,月別入力!$B:$B,$B18,月別入力!$H:$H,$F18,月別入力!$D:$D,L$7) -> 0 | M18: =SUMIFS(月別入力!$I:$I,月別入力!$E:$E,$C18,月別入力!$B:$B,$B18,月別入力!$H:$H,$F18,月別入力!$D:$D,M$7) -> 0 | N18: =SUMIFS(月別入力!$I:$I,月別入力!$E:$E,$C18,月別入力!$B:$B,$B18,月別入力!$H:$H,$F18,月別入力!$D:$D,N$7) -> 0 | O18: =SUMIFS(月別入力!$I:$I,月別入力!$E:$E,$C18,月別入力!$B:$B,$B18,月別入力!$H:$H,$F18,月別入力!$D:$D,O$7) -> 0 | ... R18: =SUMIFS(月別入力!$I:$I,月別入力!$E:$E,$C18,月別入力!$B:$B,$B18,月別入力!$H:$H,$F18,月別入力!$D:$D,R$7) -> 0
B19: =B$9 -> <=12 | G19: =SUM(H19:R19) -> 0 | H19: =SUMIFS(月別入力!$I:$I,月別入力!$E:$E,$C19,月別入力!$B:$B,$B19,月別入力!$H:$H,$F19,月別入力!$D:$D,H$7) -> 0 | I19: =SUMIFS(月別入力!$I:$I,月別入力!$E:$E,$C19,月別入力!$B:$B,$B19,月別入力!$H:$H,$F19,月別入力!$D:$D,I$7) -> 0 | J19: =SUMIFS(月別入力!$I:$I,月別入力!$E:$E,$C19,月別入力!$B:$B,$B19,月別入力!$H:$H,$F19,月別入力!$D:$D,J$7) -> 0 | K19: =SUMIFS(月別入力!$I:$I,月別入力!$E:$E,$C19,月別入力!$B:$B,$B19,月別入力!$H:$H,$F19,月別入力!$D:$D,K$7) -> 0 | L19: =SUMIFS(月別入力!$I:$I,月別入力!$E:$E,$C19,月別入力!$B:$B,$B19,月別入力!$H:$H,$F19,月別入力!$D:$D,L$7) -> 0 | M19: =SUMIFS(月別入力!$I:$I,月別入力!$E:$E,$C19,月別入力!$B:$B,$B19,月別入力!$H:$H,$F19,月別入力!$D:$D,M$7) -> 0 | N19: =SUMIFS(月別入力!$I:$I,月別入力!$E:$E,$C19,月別入力!$B:$B,$B19,月別入力!$H:$H,$F19,月別入力!$D:$D,N$7) -> 0 | O19: =SUMIFS(月別入力!$I:$I,月別入力!$E:$E,$C19,月別入力!$B:$B,$B19,月別入力!$H:$H,$F19,月別入力!$D:$D,O$7) -> 0 | ... R19: =SUMIFS(月別入力!$I:$I,月別入力!$E:$E,$C19,月別入力!$B:$B,$B19,月別入力!$H:$H,$F19,月別入力!$D:$D,R$7) -> 0
B20: =B$9 -> <=12 | G20: =SUM(H20:R20) -> 0 | H20: =SUMIFS(月別入力!$I:$I,月別入力!$E:$E,$C20,月別入力!$B:$B,$B20,月別入力!$H:$H,$F20,月別入力!$D:$D,H$7) -> 0 | I20: =SUMIFS(月別入力!$I:$I,月別入力!$E:$E,$C20,月別入力!$B:$B,$B20,月別入力!$H:$H,$F20,月別入力!$D:$D,I$7) -> 0 | J20: =SUMIFS(月別入力!$I:$I,月別入力!$E:$E,$C20,月別入力!$B:$B,$B20,月別入力!$H:$H,$F20,月別入力!$D:$D,J$7) -> 0 | K20: =SUMIFS(月別入力!$I:$I,月別入力!$E:$E,$C20,月別入力!$B:$B,$B20,月別入力!$H:$H,$F20,月別入力!$D:$D,K$7) -> 0 | L20: =SUMIFS(月別入力!$I:$I,月別入力!$E:$E,$C20,月別入力!$B:$B,$B20,月別入力!$H:$H,$F20,月別入力!$D:$D,L$7) -> 0 | M20: =SUMIFS(月別入力!$I:$I,月別入力!$E:$E,$C20,月別入力!$B:$B,$B20,月別入力!$H:$H,$F20,月別入力!$D:$D,M$7) -> 0 | N20: =SUMIFS(月別入力!$I:$I,月別入力!$E:$E,$C20,月別入力!$B:$B,$B20,月別入力!$H:$H,$F20,月別入力!$D:$D,N$7) -> 0 | O20: =SUMIFS(月別入力!$I:$I,月別入力!$E:$E,$C20,月別入力!$B:$B,$B20,月別入力!$H:$H,$F20,月別入力!$D:$D,O$7) -> 0 | ... R20: =SUMIFS(月別入力!$I:$I,月別入力!$E:$E,$C20,月別入力!$B:$B,$B20,月別入力!$H:$H,$F20,月別入力!$D:$D,R$7) -> 0
B21: =B$9 -> <=12 | G21: =SUM(H21:R21) -> 0 | H21: =SUMIFS(月別入力!$I:$I,月別入力!$E:$E,$C21,月別入力!$B:$B,$B21,月別入力!$H:$H,$F21,月別入力!$D:$D,H$7) -> 0 | I21: =SUMIFS(月別入力!$I:$I,月別入力!$E:$E,$C21,月別入力!$B:$B,$B21,月別入力!$H:$H,$F21,月別入力!$D:$D,I$7) -> 0 | J21: =SUMIFS(月別入力!$I:$I,月別入力!$E:$E,$C21,月別入力!$B:$B,$B21,月別入力!$H:$H,$F21,月別入力!$D:$D,J$7) -> 0 | K21: =SUMIFS(月別入力!$I:$I,月別入力!$E:$E,$C21,月別入力!$B:$B,$B21,月別入力!$H:$H,$F21,月別入力!$D:$D,K$7) -> 0 | L21: =SUMIFS(月別入力!$I:$I,月別入力!$E:$E,$C21,月別入力!$B:$B,$B21,月別入力!$H:$H,$F21,月別入力!$D:$D,L$7) -> 0 | M21: =SUMIFS(月別入力!$I:$I,月別入力!$E:$E,$C21,月別入力!$B:$B,$B21,月別入力!$H:$H,$F21,月別入力!$D:$D,M$7) -> 0 | N21: =SUMIFS(月別入力!$I:$I,月別入力!$E:$E,$C21,月別入力!$B:$B,$B21,月別入力!$H:$H,$F21,月別入力!$D:$D,N$7) -> 0 | O21: =SUMIFS(月別入力!$I:$I,月別入力!$E:$E,$C21,月別入力!$B:$B,$B21,月別入力!$H:$H,$F21,月別入力!$D:$D,O$7) -> 0 | ... R21: =SUMIFS(月別入力!$I:$I,月別入力!$E:$E,$C21,月別入力!$B:$B,$B21,月別入力!$H:$H,$F21,月別入力!$D:$D,R$7) -> 0
... B36: =B$9 -> <=12 | G36: =SUM(H36:R36) -> 0 | H36: =SUMIFS(月別入力!$I:$I,月別入力!$E:$E,$C36,月別入力!$B:$B,$B36,月別入力!$H:$H,$F36,月別入力!$D:$D,H$7) -> 0 | I36: =SUMIFS(月別入力!$I:$I,月別入力!$E:$E,$C36,月別入力!$B:$B,$B36,月別入力!$H:$H,$F36,月別入力!$D:$D,I$7) -> 0 | J36: =SUMIFS(月別入力!$I:$I,月別入力!$E:$E,$C36,月別入力!$B:$B,$B36,月別入力!$H:$H,$F36,月別入力!$D:$D,J$7) -> 0 | K36: =SUMIFS(月別入力!$I:$I,月別入力!$E:$E,$C36,月別入力!$B:$B,$B36,月別入力!$H:$H,$F36,月別入力!$D:$D,K$7) -> 0 | L36: =SUMIFS(月別入力!$I:$I,月別入力!$E:$E,$C36,月別入力!$B:$B,$B36,月別入力!$H:$H,$F36,月別入力!$D:$D,L$7) -> 0 | M36: =SUMIFS(月別入力!$I:$I,月別入力!$E:$E,$C36,月別入力!$B:$B,$B36,月別入力!$H:$H,$F36,月別入力!$D:$D,M$7) -> 0 | N36: =SUMIFS(月別入力!$I:$I,月別入力!$E:$E,$C36,月別入力!$B:$B,$B36,月別入力!$H:$H,$F36,月別入力!$D:$D,N$7) -> 0 | O36: =SUMIFS(月別入力!$I:$I,月別入力!$E:$E,$C36,月別入力!$B:$B,$B36,月別入力!$H:$H,$F36,月別入力!$D:$D,O$7) -> 0 | ... R36: =SUMIFS(月別入力!$I:$I,月別入力!$E:$E,$C36,月別入力!$B:$B,$B36,月別入力!$H:$H,$F36,月別入力!$D:$D,R$7) -> 0
A37: =A$9 -> 0 | B37: =B$9 -> <=12 | G37: =SUM(H37:R37) -> 0 | H37: =SUMIFS(月別入力!$I:$I,月別入力!$E:$E,$C37,月別入力!$B:$B,$B37,月別入力!$H:$H,$F37,月別入力!$D:$D,H$7) -> 0 | I37: =SUMIFS(月別入力!$I:$I,月別入力!$E:$E,$C37,月別入力!$B:$B,$B37,月別入力!$H:$H,$F37,月別入力!$D:$D,I$7) -> 0 | J37: =SUMIFS(月別入力!$I:$I,月別入力!$E:$E,$C37,月別入力!$B:$B,$B37,月別入力!$H:$H,$F37,月別入力!$D:$D,J$7) -> 0 | K37: =SUMIFS(月別入力!$I:$I,月別入力!$E:$E,$C37,月別入力!$B:$B,$B37,月別入力!$H:$H,$F37,月別入力!$D:$D,K$7) -> 0 | L37: =SUMIFS(月別入力!$I:$I,月別入力!$E:$E,$C37,月別入力!$B:$B,$B37,月別入力!$H:$H,$F37,月別入力!$D:$D,L$7) -> 0 | M37: =SUMIFS(月別入力!$I:$I,月別入力!$E:$E,$C37,月別入力!$B:$B,$B37,月別入力!$H:$H,$F37,月別入力!$D:$D,M$7) -> 0 | N37: =SUMIFS(月別入力!$I:$I,月別入力!$E:$E,$C37,月別入力!$B:$B,$B37,月別入力!$H:$H,$F37,月別入力!$D:$D,N$7) -> 0 | O37: =SUMIFS(月別入力!$I:$I,月別入力!$E:$E,$C37,月別入力!$B:$B,$B37,月別入力!$H:$H,$F37,月別入力!$D:$D,O$7) -> 0 | ... R37: =SUMIFS(月別入力!$I:$I,月別入力!$E:$E,$C37,月別入力!$B:$B,$B37,月別入力!$H:$H,$F37,月別入力!$D:$D,R$7) -> 0
A38: =A$9 -> 0 | B38: =B$9 -> <=12 | G38: =SUM(H38:R38) -> 0 | H38: =SUMIFS(月別入力!$I:$I,月別入力!$E:$E,$C38,月別入力!$B:$B,$B38,月別入力!$H:$H,$F38,月別入力!$D:$D,H$7) -> 0 | I38: =SUMIFS(月別入力!$I:$I,月別入力!$E:$E,$C38,月別入力!$B:$B,$B38,月別入力!$H:$H,$F38,月別入力!$D:$D,I$7) -> 0 | J38: =SUMIFS(月別入力!$I:$I,月別入力!$E:$E,$C38,月別入力!$B:$B,$B38,月別入力!$H:$H,$F38,月別入力!$D:$D,J$7) -> 0 | K38: =SUMIFS(月別入力!$I:$I,月別入力!$E:$E,$C38,月別入力!$B:$B,$B38,月別入力!$H:$H,$F38,月別入力!$D:$D,K$7) -> 0 | L38: =SUMIFS(月別入力!$I:$I,月別入力!$E:$E,$C38,月別入力!$B:$B,$B38,月別入力!$H:$H,$F38,月別入力!$D:$D,L$7) -> 0 | M38: =SUMIFS(月別入力!$I:$I,月別入力!$E:$E,$C38,月別入力!$B:$B,$B38,月別入力!$H:$H,$F38,月別入力!$D:$D,M$7) -> 0 | N38: =SUMIFS(月別入力!$I:$I,月別入力!$E:$E,$C38,月別入力!$B:$B,$B38,月別入力!$H:$H,$F38,月別入力!$D:$D,N$7) -> 0 | O38: =SUMIFS(月別入力!$I:$I,月別入力!$E:$E,$C38,月別入力!$B:$B,$B38,月別入力!$H:$H,$F38,月別入力!$D:$D,O$7) -> 0 | ... R38: =SUMIFS(月別入力!$I:$I,月別入力!$E:$E,$C38,月別入力!$B:$B,$B38,月別入力!$H:$H,$F38,月別入力!$D:$D,R$7) -> 0
A39: =A$9 -> 0 | B39: =B$9 -> <=12 | G39: =SUM(H39:R39) -> 0 | H39: =SUMIFS(月別入力!$I:$I,月別入力!$E:$E,$C39,月別入力!$B:$B,$B39,月別入力!$H:$H,$F39,月別入力!$D:$D,H$7) -> 0 | I39: =SUMIFS(月別入力!$I:$I,月別入力!$E:$E,$C39,月別入力!$B:$B,$B39,月別入力!$H:$H,$F39,月別入力!$D:$D,I$7) -> 0 | J39: =SUMIFS(月別入力!$I:$I,月別入力!$E:$E,$C39,月別入力!$B:$B,$B39,月別入力!$H:$H,$F39,月別入力!$D:$D,J$7) -> 0 | K39: =SUMIFS(月別入力!$I:$I,月別入力!$E:$E,$C39,月別入力!$B:$B,$B39,月別入力!$H:$H,$F39,月別入力!$D:$D,K$7) -> 0 | L39: =SUMIFS(月別入力!$I:$I,月別入力!$E:$E,$C39,月別入力!$B:$B,$B39,月別入力!$H:$H,$F39,月別入力!$D:$D,L$7) -> 0 | M39: =SUMIFS(月別入力!$I:$I,月別入力!$E:$E,$C39,月別入力!$B:$B,$B39,月別入力!$H:$H,$F39,月別入力!$D:$D,M$7) -> 0 | N39: =SUMIFS(月別入力!$I:$I,月別入力!$E:$E,$C39,月別入力!$B:$B,$B39,月別入力!$H:$H,$F39,月別入力!$D:$D,N$7) -> 0 | O39: =SUMIFS(月別入力!$I:$I,月別入力!$E:$E,$C39,月別入力!$B:$B,$B39,月別入力!$H:$H,$F39,月別入力!$D:$D,O$7) -> 0 | ... R39: =SUMIFS(月別入力!$I:$I,月別入力!$E:$E,$C39,月別入力!$B:$B,$B39,月別入力!$H:$H,$F39,月別入力!$D:$D,R$7) -> 0
A40: =A$9 -> 0 | B40: =B$9 -> <=12 | G40: =SUM(H40:R40) -> 0 | H40: =SUMIFS(月別入力!$I:$I,月別入力!$E:$E,$C40,月別入力!$B:$B,$B40,月別入力!$H:$H,$F40,月別入力!$D:$D,H$7) -> 0 | I40: =SUMIFS(月別入力!$I:$I,月別入力!$E:$E,$C40,月別入力!$B:$B,$B40,月別入力!$H:$H,$F40,月別入力!$D:$D,I$7) -> 0 | J40: =SUMIFS(月別入力!$I:$I,月別入力!$E:$E,$C40,月別入力!$B:$B,$B40,月別入力!$H:$H,$F40,月別入力!$D:$D,J$7) -> 0 | K40: =SUMIFS(月別入力!$I:$I,月別入力!$E:$E,$C40,月別入力!$B:$B,$B40,月別入力!$H:$H,$F40,月別入力!$D:$D,K$7) -> 0 | L40: =SUMIFS(月別入力!$I:$I,月別入力!$E:$E,$C40,月別入力!$B:$B,$B40,月別入力!$H:$H,$F40,月別入力!$D:$D,L$7) -> 0 | M40: =SUMIFS(月別入力!$I:$I,月別入力!$E:$E,$C40,月別入力!$B:$B,$B40,月別入力!$H:$H,$F40,月別入力!$D:$D,M$7) -> 0 | N40: =SUMIFS(月別入力!$I:$I,月別入力!$E:$E,$C40,月別入力!$B:$B,$B40,月別入力!$H:$H,$F40,月別入力!$D:$D,N$7) -> 0 | O40: =SUMIFS(月別入力!$I:$I,月別入力!$E:$E,$C40,月別入力!$B:$B,$B40,月別入力!$H:$H,$F40,月別入力!$D:$D,O$7) -> 0 | ... R40: =SUMIFS(月別入力!$I:$I,月別入力!$E:$E,$C40,月別入力!$B:$B,$B40,月別入力!$H:$H,$F40,月別入力!$D:$D,R$7) -> 0
A41: =A$9 -> 0 | B41: =B$9 -> <=12 | G41: =SUM(H41:R41) -> 0 | H41: =SUMIFS(月別入力!$I:$I,月別入力!$E:$E,$C41,月別入力!$B:$B,$B41,月別入力!$H:$H,$F41,月別入力!$D:$D,H$7) -> 0 | I41: =SUMIFS(月別入力!$I:$I,月別入力!$E:$E,$C41,月別入力!$B:$B,$B41,月別入力!$H:$H,$F41,月別入力!$D:$D,I$7) -> 0 | J41: =SUMIFS(月別入力!$I:$I,月別入力!$E:$E,$C41,月別入力!$B:$B,$B41,月別入力!$H:$H,$F41,月別入力!$D:$D,J$7) -> 0 | K41: =SUMIFS(月別入力!$I:$I,月別入力!$E:$E,$C41,月別入力!$B:$B,$B41,月別入力!$H:$H,$F41,月別入力!$D:$D,K$7) -> 0 | L41: =SUMIFS(月別入力!$I:$I,月別入力!$E:$E,$C41,月別入力!$B:$B,$B41,月別入力!$H:$H,$F41,月別入力!$D:$D,L$7) -> 0 | M41: =SUMIFS(月別入力!$I:$I,月別入力!$E:$E,$C41,月別入力!$B:$B,$B41,月別入力!$H:$H,$F41,月別入力!$D:$D,M$7) -> 0 | N41: =SUMIFS(月別入力!$I:$I,月別入力!$E:$E,$C41,月別入力!$B:$B,$B41,月別入力!$H:$H,$F41,月別入力!$D:$D,N$7) -> 0 | O41: =SUMIFS(月別入力!$I:$I,月別入力!$E:$E,$C41,月別入力!$B:$B,$B41,月別入力!$H:$H,$F41,月別入力!$D:$D,O$7) -> 0 | ... R41: =SUMIFS(月別入力!$I:$I,月別入力!$E:$E,$C41,月別入力!$B:$B,$B41,月別入力!$H:$H,$F41,月別入力!$D:$D,R$7) -> 0
A42: =A$9 -> 0 | B42: =B$9 -> <=12 | G42: =SUM(H42:R42) -> 0 | H42: =SUMIFS(月別入力!$I:$I,月別入力!$E:$E,$C42,月別入力!$B:$B,$B42,月別入力!$H:$H,$F42,月別入力!$D:$D,H$7) -> 0 | I42: =SUMIFS(月別入力!$I:$I,月別入力!$E:$E,$C42,月別入力!$B:$B,$B42,月別入力!$H:$H,$F42,月別入力!$D:$D,I$7) -> 0 | J42: =SUMIFS(月別入力!$I:$I,月別入力!$E:$E,$C42,月別入力!$B:$B,$B42,月別入力!$H:$H,$F42,月別入力!$D:$D,J$7) -> 0 | K42: =SUMIFS(月別入力!$I:$I,月別入力!$E:$E,$C42,月別入力!$B:$B,$B42,月別入力!$H:$H,$F42,月別入力!$D:$D,K$7) -> 0 | L42: =SUMIFS(月別入力!$I:$I,月別入力!$E:$E,$C42,月別入力!$B:$B,$B42,月別入力!$H:$H,$F42,月別入力!$D:$D,L$7) -> 0 | M42: =SUMIFS(月別入力!$I:$I,月別入力!$E:$E,$C42,月別入力!$B:$B,$B42,月別入力!$H:$H,$F42,月別入力!$D:$D,M$7) -> 0 | N42: =SUMIFS(月別入力!$I:$I,月別入力!$E:$E,$C42,月別入力!$B:$B,$B42,月別入力!$H:$H,$F42,月別入力!$D:$D,N$7) -> 0 | O42: =SUMIFS(月別入力!$I:$I,月別入力!$E:$E,$C42,月別入力!$B:$B,$B42,月別入力!$H:$H,$F42,月別入力!$D:$D,O$7) -> 0 | ... R42: =SUMIFS(月別入力!$I:$I,月別入力!$E:$E,$C42,月別入力!$B:$B,$B42,月別入力!$H:$H,$F42,月別入力!$D:$D,R$7) -> 0
A43: =A$9 -> 0 | B43: =B$9 -> <=12 | G43: =SUM(H43:R43) -> 0 | H43: =SUMIFS(月別入力!$I:$I,月別入力!$E:$E,$C43,月別入力!$B:$B,$B43,月別入力!$H:$H,$F43,月別入力!$D:$D,H$7) -> 0 | I43: =SUMIFS(月別入力!$I:$I,月別入力!$E:$E,$C43,月別入力!$B:$B,$B43,月別入力!$H:$H,$F43,月別入力!$D:$D,I$7) -> 0 | J43: =SUMIFS(月別入力!$I:$I,月別入力!$E:$E,$C43,月別入力!$B:$B,$B43,月別入力!$H:$H,$F43,月別入力!$D:$D,J$7) -> 0 | K43: =SUMIFS(月別入力!$I:$I,月別入力!$E:$E,$C43,月別入力!$B:$B,$B43,月別入力!$H:$H,$F43,月別入力!$D:$D,K$7) -> 0 | L43: =SUMIFS(月別入力!$I:$I,月別入力!$E:$E,$C43,月別入力!$B:$B,$B43,月別入力!$H:$H,$F43,月別入力!$D:$D,L$7) -> 0 | M43: =SUMIFS(月別入力!$I:$I,月別入力!$E:$E,$C43,月別入力!$B:$B,$B43,月別入力!$H:$H,$F43,月別入力!$D:$D,M$7) -> 0 | N43: =SUMIFS(月別入力!$I:$I,月別入力!$E:$E,$C43,月別入力!$B:$B,$B43,月別入力!$H:$H,$F43,月別入力!$D:$D,N$7) -> 0 | O43: =SUMIFS(月別入力!$I:$I,月別入力!$E:$E,$C43,月別入力!$B:$B,$B43,月別入力!$H:$H,$F43,月別入力!$D:$D,O$7) -> 0 | ... R43: =SUMIFS(月別入力!$I:$I,月別入力!$E:$E,$C43,月別入力!$B:$B,$B43,月別入力!$H:$H,$F43,月別入力!$D:$D,R$7) -> 0
A44: =A$9 -> 0 | B44: =B$9 -> <=12 | G44: =SUM(H44:R44) -> 0 | H44: =SUMIFS(月別入力!$I:$I,月別入力!$E:$E,$C44,月別入力!$B:$B,$B44,月別入力!$H:$H,$F44,月別入力!$D:$D,H$7) -> 0 | I44: =SUMIFS(月別入力!$I:$I,月別入力!$E:$E,$C44,月別入力!$B:$B,$B44,月別入力!$H:$H,$F44,月別入力!$D:$D,I$7) -> 0 | J44: =SUMIFS(月別入力!$I:$I,月別入力!$E:$E,$C44,月別入力!$B:$B,$B44,月別入力!$H:$H,$F44,月別入力!$D:$D,J$7) -> 0 | K44: =SUMIFS(月別入力!$I:$I,月別入力!$E:$E,$C44,月別入力!$B:$B,$B44,月別入力!$H:$H,$F44,月別入力!$D:$D,K$7) -> 0 | L44: =SUMIFS(月別入力!$I:$I,月別入力!$E:$E,$C44,月別入力!$B:$B,$B44,月別入力!$H:$H,$F44,月別入力!$D:$D,L$7) -> 0 | M44: =SUMIFS(月別入力!$I:$I,月別入力!$E:$E,$C44,月別入力!$B:$B,$B44,月別入力!$H:$H,$F44,月別入力!$D:$D,M$7) -> 0 | N44: =SUMIFS(月別入力!$I:$I,月別入力!$E:$E,$C44,月別入力!$B:$B,$B44,月別入力!$H:$H,$F44,月別入力!$D:$D,N$7) -> 0 | O44: =SUMIFS(月別入力!$I:$I,月別入力!$E:$E,$C44,月別入力!$B:$B,$B44,月別入力!$H:$H,$F44,月別入力!$D:$D,O$7) -> 0 | ... R44: =SUMIFS(月別入力!$I:$I,月別入力!$E:$E,$C44,月別入力!$B:$B,$B44,月別入力!$H:$H,$F44,月別入力!$D:$D,R$7) -> 0
A45: =A$9 -> 0 | B45: =B$9 -> <=12 | G45: =SUM(H45:R45) -> 0 | H45: =SUMIFS(月別入力!$I:$I,月別入力!$E:$E,$C45,月別入力!$B:$B,$B45,月別入力!$H:$H,$F45,月別入力!$D:$D,H$7) -> 0 | I45: =SUMIFS(月別入力!$I:$I,月別入力!$E:$E,$C45,月別入力!$B:$B,$B45,月別入力!$H:$H,$F45,月別入力!$D:$D,I$7) -> 0 | J45: =SUMIFS(月別入力!$I:$I,月別入力!$E:$E,$C45,月別入力!$B:$B,$B45,月別入力!$H:$H,$F45,月別入力!$D:$D,J$7) -> 0 | K45: =SUMIFS(月別入力!$I:$I,月別入力!$E:$E,$C45,月別入力!$B:$B,$B45,月別入力!$H:$H,$F45,月別入力!$D:$D,K$7) -> 0 | L45: =SUMIFS(月別入力!$I:$I,月別入力!$E:$E,$C45,月別入力!$B:$B,$B45,月別入力!$H:$H,$F45,月別入力!$D:$D,L$7) -> 0 | M45: =SUMIFS(月別入力!$I:$I,月別入力!$E:$E,$C45,月別入力!$B:$B,$B45,月別入力!$H:$H,$F45,月別入力!$D:$D,M$7) -> 0 | N45: =SUMIFS(月別入力!$I:$I,月別入力!$E:$E,$C45,月別入力!$B:$B,$B45,月別入力!$H:$H,$F45,月別入力!$D:$D,N$7) -> 0 | O45: =SUMIFS(月別入力!$I:$I,月別入力!$E:$E,$C45,月別入力!$B:$B,$B45,月別入力!$H:$H,$F45,月別入力!$D:$D,O$7) -> 0 | ... R45: =SUMIFS(月別入力!$I:$I,月別入力!$E:$E,$C45,月別入力!$B:$B,$B45,月別入力!$H:$H,$F45,月別入力!$D:$D,R$7) -> 0
A46: =A$9 -> 0 | B46: =B$9 -> <=12 | G46: =SUM(H46:R46) -> 0 | H46: =SUMIFS(月別入力!$I:$I,月別入力!$E:$E,$C46,月別入力!$B:$B,$B46,月別入力!$H:$H,$F46,月別入力!$D:$D,H$7) -> 0 | I46: =SUMIFS(月別入力!$I:$I,月別入力!$E:$E,$C46,月別入力!$B:$B,$B46,月別入力!$H:$H,$F46,月別入力!$D:$D,I$7) -> 0 | J46: =SUMIFS(月別入力!$I:$I,月別入力!$E:$E,$C46,月別入力!$B:$B,$B46,月別入力!$H:$H,$F46,月別入力!$D:$D,J$7) -> 0 | K46: =SUMIFS(月別入力!$I:$I,月別入力!$E:$E,$C46,月別入力!$B:$B,$B46,月別入力!$H:$H,$F46,月別入力!$D:$D,K$7) -> 0 | L46: =SUMIFS(月別入力!$I:$I,月別入力!$E:$E,$C46,月別入力!$B:$B,$B46,月別入力!$H:$H,$F46,月別入力!$D:$D,L$7) -> 0 | M46: =SUMIFS(月別入力!$I:$I,月別入力!$E:$E,$C46,月別入力!$B:$B,$B46,月別入力!$H:$H,$F46,月別入力!$D:$D,M$7) -> 0 | N46: =SUMIFS(月別入力!$I:$I,月別入力!$E:$E,$C46,月別入力!$B:$B,$B46,月別入力!$H:$H,$F46,月別入力!$D:$D,N$7) -> 0 | O46: =SUMIFS(月別入力!$I:$I,月別入力!$E:$E,$C46,月別入力!$B:$B,$B46,月別入力!$H:$H,$F46,月別入力!$D:$D,O$7) -> 0 | ... R46: =SUMIFS(月別入力!$I:$I,月別入力!$E:$E,$C46,月別入力!$B:$B,$B46,月別入力!$H:$H,$F46,月別入力!$D:$D,R$7) -> 0
A47: =A$9 -> 0 | B47: =B$9 -> <=12 | G47: =SUM(H47:R47) -> 0 | H47: =SUMIFS(月別入力!$I:$I,月別入力!$E:$E,$C47,月別入力!$B:$B,$B47,月別入力!$H:$H,$F47,月別入力!$D:$D,H$7) -> 0 | I47: =SUMIFS(月別入力!$I:$I,月別入力!$E:$E,$C47,月別入力!$B:$B,$B47,月別入力!$H:$H,$F47,月別入力!$D:$D,I$7) -> 0 | J47: =SUMIFS(月別入力!$I:$I,月別入力!$E:$E,$C47,月別入力!$B:$B,$B47,月別入力!$H:$H,$F47,月別入力!$D:$D,J$7) -> 0 | K47: =SUMIFS(月別入力!$I:$I,月別入力!$E:$E,$C47,月別入力!$B:$B,$B47,月別入力!$H:$H,$F47,月別入力!$D:$D,K$7) -> 0 | L47: =SUMIFS(月別入力!$I:$I,月別入力!$E:$E,$C47,月別入力!$B:$B,$B47,月別入力!$H:$H,$F47,月別入力!$D:$D,L$7) -> 0 | M47: =SUMIFS(月別入力!$I:$I,月別入力!$E:$E,$C47,月別入力!$B:$B,$B47,月別入力!$H:$H,$F47,月別入力!$D:$D,M$7) -> 0 | N47: =SUMIFS(月別入力!$I:$I,月別入力!$E:$E,$C47,月別入力!$B:$B,$B47,月別入力!$H:$H,$F47,月別入力!$D:$D,N$7) -> 0 | O47: =SUMIFS(月別入力!$I:$I,月別入力!$E:$E,$C47,月別入力!$B:$B,$B47,月別入力!$H:$H,$F47,月別入力!$D:$D,O$7) -> 0 | ... R47: =SUMIFS(月別入力!$I:$I,月別入力!$E:$E,$C47,月別入力!$B:$B,$B47,月別入力!$H:$H,$F47,月別入力!$D:$D,R$7) -> 0
A48: =A$9 -> 0 | B48: =B$9 -> <=12 | G48: =SUM(H48:R48) -> 0 | H48: =SUMIFS(月別入力!$I:$I,月別入力!$E:$E,$C48,月別入力!$B:$B,$B48,月別入力!$H:$H,$F48,月別入力!$D:$D,H$7) -> 0 | I48: =SUMIFS(月別入力!$I:$I,月別入力!$E:$E,$C48,月別入力!$B:$B,$B48,月別入力!$H:$H,$F48,月別入力!$D:$D,I$7) -> 0 | J48: =SUMIFS(月別入力!$I:$I,月別入力!$E:$E,$C48,月別入力!$B:$B,$B48,月別入力!$H:$H,$F48,月別入力!$D:$D,J$7) -> 0 | K48: =SUMIFS(月別入力!$I:$I,月別入力!$E:$E,$C48,月別入力!$B:$B,$B48,月別入力!$H:$H,$F48,月別入力!$D:$D,K$7) -> 0 | L48: =SUMIFS(月別入力!$I:$I,月別入力!$E:$E,$C48,月別入力!$B:$B,$B48,月別入力!$H:$H,$F48,月別入力!$D:$D,L$7) -> 0 | M48: =SUMIFS(月別入力!$I:$I,月別入力!$E:$E,$C48,月別入力!$B:$B,$B48,月別入力!$H:$H,$F48,月別入力!$D:$D,M$7) -> 0 | N48: =SUMIFS(月別入力!$I:$I,月別入力!$E:$E,$C48,月別入力!$B:$B,$B48,月別入力!$H:$H,$F48,月別入力!$D:$D,N$7) -> 0 | O48: =SUMIFS(月別入力!$I:$I,月別入力!$E:$E,$C48,月別入力!$B:$B,$B48,月別入力!$H:$H,$F48,月別入力!$D:$D,O$7) -> 0 | ... R48: =SUMIFS(月別入力!$I:$I,月別入力!$E:$E,$C48,月別入力!$B:$B,$B48,月別入力!$H:$H,$F48,月別入力!$D:$D,R$7) -> 0
... A108: =A$9 -> 0 | B108: =B$9 -> <=12 | G108: =SUM(H108:R108) -> 0 | H108: =SUMIFS(月別入力!$I:$I,月別入力!$E:$E,$C108,月別入力!$B:$B,$B108,月別入力!$H:$H,$F108,月別入力!$D:$D,H$7) -> 0 | I108: =SUMIFS(月別入力!$I:$I,月別入力!$E:$E,$C108,月別入力!$B:$B,$B108,月別入力!$H:$H,$F108,月別入力!$D:$D,I$7) -> 0 | J108: =SUMIFS(月別入力!$I:$I,月別入力!$E:$E,$C108,月別入力!$B:$B,$B108,月別入力!$H:$H,$F108,月別入力!$D:$D,J$7) -> 0 | K108: =SUMIFS(月別入力!$I:$I,月別入力!$E:$E,$C108,月別入力!$B:$B,$B108,月別入力!$H:$H,$F108,月別入力!$D:$D,K$7) -> 0 | L108: =SUMIFS(月別入力!$I:$I,月別入力!$E:$E,$C108,月別入力!$B:$B,$B108,月別入力!$H:$H,$F108,月別入力!$D:$D,L$7) -> 0 | M108: =SUMIFS(月別入力!$I:$I,月別入力!$E:$E,$C108,月別入力!$B:$B,$B108,月別入力!$H:$H,$F108,月別入力!$D:$D,M$7) -> 0 | N108: =SUMIFS(月別入力!$I:$I,月別入力!$E:$E,$C108,月別入力!$B:$B,$B108,月別入力!$H:$H,$F108,月別入力!$D:$D,N$7) -> 0 | O108: =SUMIFS(月別入力!$I:$I,月別入力!$E:$E,$C108,月別入力!$B:$B,$B108,月別入力!$H:$H,$F108,月別入力!$D:$D,O$7) -> 0 | ... R108: =SUMIFS(月別入力!$I:$I,月別入力!$E:$E,$C108,月別入力!$B:$B,$B108,月別入力!$H:$H,$F108,月別入力!$D:$D,R$7) -> 0

Sheet 月別入力
B1: 畜産物生産費統計 入力シート（月別）
B2: 2020センサス番号 <自動>
B3: =設定!$B$3 -> 0
B5: 月 | C5: 作業 <入力> | D5: →集計分類 <選択> | E5: 作業者 <選択> | F5: 性別 <自動> | G5: 年齢 <自動> | H5: 雇用形態 <自動> | I5: 労働時間 <入力>
F7: =IFERROR(VLOOKUP($E7,設定!$C:$F,2,0),"") | G7: =IFERROR(VLOOKUP($E7,設定!$C:$F,3,0),"") | H7: =IFERROR(VLOOKUP($E7,設定!$C:$F,4,0),"")
F8: =IFERROR(VLOOKUP($E8,設定!$C:$F,2,0),"") | G8: =IFERROR(VLOOKUP($E8,設定!$C:$F,3,0),"") | H8: =IFERROR(VLOOKUP($E8,設定!$C:$F,4,0),"")
F9: =IFERROR(VLOOKUP($E9,設定!$C:$F,2,0),"") | G9: =IFERROR(VLOOKUP($E9,設定!$C:$F,3,0),"") | H9: =IFERROR(VLOOKUP($E9,設定!$C:$F,4,0),"")
F10: =IFERROR(VLOOKUP($E10,設定!$C:$F,2,0),"") | G10: =IFERROR(VLOOKUP($E10,設定!$C:$F,3,0),"") | H10: =IFERROR(VLOOKUP($E10,設定!$C:$F,4,0),"")
F11: =IFERROR(VLOOKUP($E11,設定!$C:$F,2,0),"") | G11: =IFERROR(VLOOKUP($E11,設定!$C:$F,3,0),"") | H11: =IFERROR(VLOOKUP($E11,設定!$C:$F,4,0),"")
F12: =IFERROR(VLOOKUP($E12,設定!$C:$F,2,0),"") | G12: =IFERROR(VLOOKUP($E12,設定!$C:$F,3,0),"") | H12: =IFERROR(VLOOKUP($E12,設定!$C:$F,4,0),"")
F13: =IFERROR(VLOOKUP($E13,設定!$C:$F,2,0),"") | G13: =IFERROR(VLOOKUP($E13,設定!$C:$F,3,0),"") | H13: =IFERROR(VLOOKUP($E13,設定!$C:$F,4,0),"")
F14: =IFERROR(VLOOKUP($E14,設定!$C:$F,2,0),"") | G14: =IFERROR(VLOOKUP($E14,設定!$C:$F,3,0),"") | H14: =IFERROR(VLOOKUP($E14,設定!$C:$F,4,0),"")
F15: =IFERROR(VLOOKUP($E15,設定!$C:$F,2,0),"") | G15: =IFERROR(VLOOKUP($E15,設定!$C:$F,3,0),"") | H15: =IFERROR(VLOOKUP($E15,設定!$C:$F,4,0),"")
F16: =IFERROR(VLOOKUP($E16,設定!$C:$F,2,0),"") | G16: =IFERROR(VLOOKUP($E16,設定!$C:$F,3,0),"") | H16: =IFERROR(VLOOKUP($E16,設定!$C:$F,4,0),"")
F17: =IFERROR(VLOOKUP($E17,設定!$C:$F,2,0),"") | G17: =IFERROR(VLOOKUP($E17,設定!$C:$F,3,0),"") | H17: =IFERROR(VLOOKUP($E17,設定!$C:$F,4,0),"")
F18: =IFERROR(VLOOKUP($E18,設定!$C:$F,2,0),"") | G18: =IFERROR(VLOOKUP($E18,設定!$C:$F,3,0),"") | H18: =IFERROR(VLOOKUP($E18,設定!$C:$F,4,0),"")
... F537: =IFERROR(VLOOKUP($E537,設定!$C:$F,2,0),"") | G537: =IFERROR(VLOOKUP($E537,設定!$C:$F,3,0),"") | H537: =IFERROR(VLOOKUP($E537,設定!$C:$F,4,0),"")

Sheet 【12】労働時間（個別・牛乳）
B2: 【12】作業別労働時間
S4: 労賃単価
C8: 氏 名 | D8: 性別 | E8: 年齢 | F8: 家族 ・ 雇用 | G8: 飼料の調理・ 給与・給水 | I8: 敷料搬入・きゅう肥搬出 | K8: 搾乳・牛乳 処理・運搬 | M8: その他の 飼育作業 | S8: 1：家族 2：雇用 3：ゆい・手間替え受け 4：手伝い・共同作業受け 5：同居人 | T8: 氏 名 | U8: 1：男 2：女 | V8: 年齢 | W8: 飼料の調理・給与・給水 | X8: 敷料搬入・きゅう肥搬出 | Y8: 搾乳・牛乳処理・運搬 | Z8: その他の 飼育作業 | AF8: 家族労働 | AL8: 雇用労働 | AY8: 家族労働 | BA8: 雇用労働
AF9: 計 | AH9: 家族 | AJ9: ゆい・手間替え受け | AL9: 計 | AN9: 雇用 | AP9: 手伝い・共同作業受け | AR9: 同居人 | BC9: 雇用 | BE9: 手伝い・共同作業受け、同居人
AF10: 男 | AG10: 女 | AH10: 男 | AI10: 女 | AJ10: 男 | AK10: 女 | AL10: 男 | AM10: 女 | AN10: 男 | AO10: 女 | AP10: 男 | AQ10: 女 | AR10: 男 | AS10: 女 | AY10: 男 | AZ10: 女 | BA10: 男 | BB10: 女 | BC10: 男 | BD10: 女 | BE10: 男 | BF10: 女
A11: =ROUND((ROW()-10)/2,0) -> 1 | C11: =IF(INDEX(設定!$C$9:$C$108,$A11,1)="","",INDEX(設定!$C$9:$C$108,$A11,1)) | D11: =IF(INDEX(設定!$D$9:$D$108,$A11,1)="","",INDEX(設定!$D$9:$D$108,$A11,1)) | E11: =IF(INDEX(設定!$E$9:$E$108,$A11,1)="","",INDEX(設定!$E$9:$E$108,$A11,1)) | F11: =IF(S11="","",IF(S11=1,"1：家族",IF(AND(S11>=2,S11<=5),"2：雇用",""))) | G11: =INT(INDEX(設定!$H$9:H$108,$A11,1)) -> 0 | H11: =IF(INDEX(設定!$H$9:$H$108,$A11,1)=0,"",ROUND(MOD(INDEX(設定!$H$9:$H$108,$A11,1),1)*60,0)) | I11: =INT(INDEX(設定!$I$9:$I$108,$A11,1)) -> 0 | J11: =IF(INDEX(設定!$I$9:$I$108,$A11,1)=0,"",ROUND(MOD(INDEX(設定!$I$9:$I$108,$A11,1),1)*60,0)) | K11: =INT(INDEX(設定!$J$9:$J$108,$A11,1)) -> 0 | L11: =IF(INDEX(設定!$J$9:$J$108,$A11,1)=0,"",ROUND(MOD(INDEX(設定!$J$9:$J$108,$A11,1),1)*60,0)) | M11: =INT(INDEX(設定!$K$9:$K$108,$A11,1)) -> 0 | N11: =IF(INDEX(設定!$K$9:$K$108,$A11,1)=0,"",ROUND(MOD(INDEX(設定!$K$9:$K$108,$A11,1),1)*60,0)) | S11: =IF(INDEX(設定!$F$9:$F$108,$A11,1)="","",VALUE(LEFT(INDEX(設定!$F$9:$F$108,$A11,1),1))) | T11: =IF(C11="","",C11) | U11: =IF(D11="","",IF(D11="1：男",1,IF(D11="2：女",2))) | V11: =IF(E11="","",E11) | W11: =IF(AND(G11="",H11="",G12=""),"",ROUND(SUM(G11,H11/60)*G12,1)) | X11: =IF(AND(I11="",J11="",I12=""),"",ROUND(SUM(I11,J11/60)*I12,1)) | Y11: =IF(AND(K11="",L11="",K12=""),"",ROUND(SUM(K11,L11/60)*K12,1)) | Z11: =IF(AND(M11="",N11="",M12=""),"",ROUND(SUM(M11,N11/60)*M12,1)) | AC11: 直接労働時間 | AF11: =SUM(AF12:AF15) -> 0 | AG11: =SUM(AG12:AG15) -> 0 | AL11: =AL16+AL21+AL26+AL31 -> 0 | AM11: =AM16+AM21+AM26+AM31 -> 0 | AN11: =AN16+AN21+AN26+AN31 -> 0 | AO11: =AO16+AO21+AO26+AO31 -> 0 | AP11: =AP12 -> 0 | AQ11: =AQ12 -> 0 | AR11: =SUM(AR12:AR15) -> 0 | AS11: =SUM(AS12:AS15) -> 0 | AV11: 直接労働費 | AY11: =SUM(AY12:AY15) -> 0 | AZ11: =SUM(AZ12:AZ15) -> 0 | BA11: =ROUND(BC11+BE11,0) -> 0 | BB11: =ROUND(BD11+BF11,0) -> 0 | BC11: =IFERROR($T$112*AN11/($AN$11+$AN$51),0) -> 0 | BD11: =IFERROR($T$113*AO11/($AO$11+$AO$51),0) -> 0 | BE11: =SUM(BE12:BE15) -> 0 | BF11: =SUM(BF12:BF15) -> 0
G12: =IF(SUM(G11:H11)>0,1,"") | I12: =IF(SUM(I11:J11)>0,1,"") | K12: =IF(SUM(K11:L11)>0,1,"") | M12: =IF(SUM(M11:N11)>0,1,"") | AD12: 65歳未満 | AF12: =AF17+AF22+AF27+AF32 -> 0 | AG12: =AG17+AG22+AG27+AG32 -> 0 | AH12: =AH17+AH22+AH27+AH32 -> 0 | AI12: =AI17+AI22+AI27+AI32 -> 0 | AJ12: =AJ17+AJ22+AJ27+AJ32 -> 0 | AK12: =AK17+AK22+AK27+AK32 -> 0 | AP12: =AP17+AP22+AP27+AP32 -> 0 | AQ12: =AQ17+AQ22+AQ27+AQ32 -> 0 | AR12: =AR17+AR22+AR27+AR32 -> 0 | AS12: =AS17+AS22+AS27+AS32 -> 0 | AW12: 65歳未満 | AY12: =AF12*$T$4 -> 0 | AZ12: =AG12*$T$4 -> 0 | BE12: =(AP12+AR12)*$T$4 -> 0 | BF12: =(AQ12+AS12)*$T$4 -> 0
A13: =ROUND((ROW()-10)/2,0) -> 2 | C13: =IF(INDEX(設定!$C$9:$C$108,$A13,1)="","",INDEX(設定!$C$9:$C$108,$A13,1)) | D13: =IF(INDEX(設定!$D$9:$D$108,$A13,1)="","",INDEX(設定!$D$9:$D$108,$A13,1)) | E13: =IF(INDEX(設定!$E$9:$E$108,$A13,1)="","",INDEX(設定!$E$9:$E$108,$A13,1)) | F13: =IF(S13="","",IF(S13=1,"1：家族",IF(AND(S13>=2,S13<=5),"2：雇用",""))) | G13: =INT(INDEX(設定!$H$9:H$108,$A13,1)) -> 0 | H13: =IF(INDEX(設定!$H$9:$H$108,$A13,1)=0,"",ROUND(MOD(INDEX(設定!$H$9:$H$108,$A13,1),1)*60,0)) | I13: =INT(INDEX(設定!$I$9:$I$108,$A13,1)) -> 0 | J13: =IF(INDEX(設定!$I$9:$I$108,$A13,1)=0,"",ROUND(MOD(INDEX(設定!$I$9:$I$108,$A13,1),1)*60,0)) | K13: =INT(INDEX(設定!$J$9:$J$108,$A13,1)) -> 0 | L13: =IF(INDEX(設定!$J$9:$J$108,$A13,1)=0,"",ROUND(MOD(INDEX(設定!$J$9:$J$108,$A13,1),1)*60,0)) | M13: =INT(INDEX(設定!$K$9:$K$108,$A13,1)) -> 0 | N13: =IF(INDEX(設定!$K$9:$K$108,$A13,1)=0,"",ROUND(MOD(INDEX(設定!$K$9:$K$108,$A13,1),1)*60,0)) | S13: =IF(INDEX(設定!$F$9:$F$108,$A13,1)="","",VALUE(LEFT(INDEX(設定!$F$9:$F$108,$A13,1),1))) | T13: =IF(C13="","",C13) | U13: =IF(D13="","",IF(D13="1：男",1,IF(D13="2：女",2))) | V13: =IF(E13="","",E13) | W13: =IF(AND(G13="",H13="",G14=""),"",ROUND(SUM(G13,H13/60)*G14,1)) | X13: =IF(AND(I13="",J13="",I14=""),"",ROUND(SUM(I13,J13/60)*I14,1)) | Y13: =IF(AND(K13="",L13="",K14=""),"",ROUND(SUM(K13,L13/60)*K14,1)) | Z13: =IF(AND(M13="",N13="",M14=""),"",ROUND(SUM(M13,N13/60)*M14,1)) | AD13: 65～70 | AF13: =AF18+AF23+AF28+AF33 -> 0 | AG13: =AG18+AG23+AG28+AG33 -> 0 | AH13: =AH18+AH23+AH28+AH33 -> 0 | AI13: =AI18+AI23+AI28+AI33 -> 0 | AR13: =AR18+AR23+AR28+AR33 -> 0 | AS13: =AS18+AS23+AS28+AS33 -> 0 | AW13: 65～70 | AY13: =AF13*$T$4*0.9 -> 0 | AZ13: =AG13*$T$4*0.9 -> 0 | BE13: =(AR13)*$T$4*0.9 -> 0 | BF13: =(AS13)*$T$4*0.9 -> 0
G14: =IF(SUM(G13:H13)>0,1,"") | I14: =IF(SUM(I13:J13)>0,1,"") | K14: =IF(SUM(K13:L13)>0,1,"") | M14: =IF(SUM(M13:N13)>0,1,"") | AD14: 70～75 | AF14: =AF19+AF24+AF29+AF34 -> 0 | AG14: =AG19+AG24+AG29+AG34 -> 0 | AH14: =AH19+AH24+AH29+AH34 -> 0 | AI14: =AI19+AI24+AI29+AI34 -> 0 | AR14: =AR19+AR24+AR29+AR34 -> 0 | AS14: =AS19+AS24+AS29+AS34 -> 0 | AW14: 70～75 | AY14: =AF14*$T$4*0.8 -> 0 | AZ14: =AG14*$T$4*0.8 -> 0 | BE14: =(AR14)*$T$4*0.8 -> 0 | BF14: =(AS14)*$T$4*0.8 -> 0
A15: =ROUND((ROW()-10)/2,0) -> 3 | C15: =IF(INDEX(設定!$C$9:$C$108,$A15,1)="","",INDEX(設定!$C$9:$C$108,$A15,1)) | D15: =IF(INDEX(設定!$D$9:$D$108,$A15,1)="","",INDEX(設定!$D$9:$D$108,$A15,1)) | E15: =IF(INDEX(設定!$E$9:$E$108,$A15,1)="","",INDEX(設定!$E$9:$E$108,$A15,1)) | F15: =IF(S15="","",IF(S15=1,"1：家族",IF(AND(S15>=2,S15<=5),"2：雇用",""))) | G15: =INT(INDEX(設定!$H$9:H$108,$A15,1)) -> 0 | H15: =IF(INDEX(設定!$H$9:$H$108,$A15,1)=0,"",ROUND(MOD(INDEX(設定!$H$9:$H$108,$A15,1),1)*60,0)) | I15: =INT(INDEX(設定!$I$9:$I$108,$A15,1)) -> 0 | J15: =IF(INDEX(設定!$I$9:$I$108,$A15,1)=0,"",ROUND(MOD(INDEX(設定!$I$9:$I$108,$A15,1),1)*60,0)) | K15: =INT(INDEX(設定!$J$9:$J$108,$A15,1)) -> 0 | L15: =IF(INDEX(設定!$J$9:$J$108,$A15,1)=0,"",ROUND(MOD(INDEX(設定!$J$9:$J$108,$A15,1),1)*60,0)) | M15: =INT(INDEX(設定!$K$9:$K$108,$A15,1)) -> 0 | N15: =IF(INDEX(設定!$K$9:$K$108,$A15,1)=0,"",ROUND(MOD(INDEX(設定!$K$9:$K$108,$A15,1),1)*60,0)) | S15: =IF(INDEX(設定!$F$9:$F$108,$A15,1)="","",VALUE(LEFT(INDEX(設定!$F$9:$F$108,$A15,1),1))) | T15: =IF(C15="","",C15) | U15: =IF(D15="","",IF(D15="1：男",1,IF(D15="2：女",2))) | V15: =IF(E15="","",E15) | W15: =IF(AND(G15="",H15="",G16=""),"",ROUND(SUM(G15,H15/60)*G16,1)) | X15: =IF(AND(I15="",J15="",I16=""),"",ROUND(SUM(I15,J15/60)*I16,1)) | Y15: =IF(AND(K15="",L15="",K16=""),"",ROUND(SUM(K15,L15/60)*K16,1)) | Z15: =IF(AND(M15="",N15="",M16=""),"",ROUND(SUM(M15,N15/60)*M16,1)) | AD15: 75歳以上 | AF15: =AF20+AF25+AF30+AF35 -> 0 | AG15: =AG20+AG25+AG30+AG35 -> 0 | AH15: =AH20+AH25+AH30+AH35 -> 0 | AI15: =AI20+AI25+AI30+AI35 -> 0 | AR15: =AR20+AR25+AR30+AR35 -> 0 | AS15: =AS20+AS25+AS30+AS35 -> 0 | AW15: 75歳以上 | AY15: =AF15*$T$4*0.7 -> 0 | AZ15: =AG15*$T$4*0.7 -> 0 | BE15: =(AR15)*$T$4*0.7 -> 0 | BF15: =(AS15)*$T$4*0.7 -> 0
G16: =IF(SUM(G15:H15)>0,1,"") | I16: =IF(SUM(I15:J15)>0,1,"") | K16: =IF(SUM(K15:L15)>0,1,"") | M16: =IF(SUM(M15:N15)>0,1,"") | AD16: 飼料の調理・ 給与・給水 | AF16: =SUM(AF17:AF20) -> 0 | AG16: =SUM(AG17:AG20) -> 0 | AL16: =AN16+AP16+AR16 -> 0 | AM16: =AO16+AQ16+AS16 -> 0 | AN16: =SUMIFS($W$11:$W$70,$S$11:$S$70,2,$U$11:$U$70,1) -> 0 | AO16: =SUMIFS($W$11:$W$70,$S$11:$S$70,2,$U$11:$U$70,2) -> 0 | AP16: =AP17 -> 0 | AQ16: =AQ17 -> 0 | AR16: =SUM(AR17:AR20) -> 0 | AS16: =SUM(AS17:AS20) -> 0
A17: =ROUND((ROW()-10)/2,0) -> 4 | C17: =IF(INDEX(設定!$C$9:$C$108,$A17,1)="","",INDEX(設定!$C$9:$C$108,$A17,1)) | D17: =IF(INDEX(設定!$D$9:$D$108,$A17,1)="","",INDEX(設定!$D$9:$D$108,$A17,1)) | E17: =IF(INDEX(設定!$E$9:$E$108,$A17,1)="","",INDEX(設定!$E$9:$E$108,$A17,1)) | F17: =IF(S17="","",IF(S17=1,"1：家族",IF(AND(S17>=2,S17<=5),"2：雇用",""))) | G17: =INT(INDEX(設定!$H$9:H$108,$A17,1)) -> 0 | H17: =IF(INDEX(設定!$H$9:$H$108,$A17,1)=0,"",ROUND(MOD(INDEX(設定!$H$9:$H$108,$A17,1),1)*60,0)) | I17: =INT(INDEX(設定!$I$9:$I$108,$A17,1)) -> 0 | J17: =IF(INDEX(設定!$I$9:$I$108,$A17,1)=0,"",ROUND(MOD(INDEX(設定!$I$9:$I$108,$A17,1),1)*60,0)) | K17: =INT(INDEX(設定!$J$9:$J$108,$A17,1)) -> 0 | L17: =IF(INDEX(設定!$J$9:$J$108,$A17,1)=0,"",ROUND(MOD(INDEX(設定!$J$9:$J$108,$A17,1),1)*60,0)) | M17: =INT(INDEX(設定!$K$9:$K$108,$A17,1)) -> 0 | N17: =IF(INDEX(設定!$K$9:$K$108,$A17,1)=0,"",ROUND(MOD(INDEX(設定!$K$9:$K$108,$A17,1),1)*60,0)) | S17: =IF(INDEX(設定!$F$9:$F$108,$A17,1)="","",VALUE(LEFT(INDEX(設定!$F$9:$F$108,$A17,1),1))) | T17: =IF(C17="","",C17) | U17: =IF(D17="","",IF(D17="1：男",1,IF(D17="2：女",2))) | V17: =IF(E17="","",E17) | W17: =IF(AND(G17="",H17="",G18=""),"",ROUND(SUM(G17,H17/60)*G18,1)) | X17: =IF(AND(I17="",J17="",I18=""),"",ROUND(SUM(I17,J17/60)*I18,1)) | Y17: =IF(AND(K17="",L17="",K18=""),"",ROUND(SUM(K17,L17/60)*K18,1)) | Z17: =IF(AND(M17="",N17="",M18=""),"",ROUND(SUM(M17,N17/60)*M18,1)) | AE17: 65歳未満 | AF17: =AH17+AJ17 -> 0 | AG17: =AI17+AK17 -> 0 | AH17: =SUMIFS($W$11:$W$70,$S$11:$S$70,1,$U$11:$U$70,1,$V$11:$V$70,"<65") -> 0 | AI17: =SUMIFS($W$11:$W$70,$S$11:$S$70,1,$U$11:$U$70,2,$V$11:$V$70,"<65") -> 0 | AJ17: =SUMIFS($W$11:$W$70,$S$11:$S$70,3,$U$11:$U$70,1) -> 0 | AK17: =SUMIFS($W$11:$W$70,$S$11:$S$70,3,$U$11:$U$70,2) -> 0 | AP17: =SUMIFS($W$11:$W$70,$S$11:$S$70,4,$U$11:$U$70,1) -> 0 | AQ17: =SUMIFS($W$11:$W$70,$S$11:$S$70,4,$U$11:$U$70,2) -> 0 | AR17: =SUMIFS($W$11:$W$70,$S$11:$S$70,5,$U$11:$U$70,1,$V$11:$V$70,"<65") -> 0 | AS17: =SUMIFS($W$11:$W$70,$S$11:$S$70,5,$U$11:$U$70,2,$V$11:$V$70,"<65") -> 0
G18: =IF(SUM(G17:H17)>0,1,"") | I18: =IF(SUM(I17:J17)>0,1,"") | K18: =IF(SUM(K17:L17)>0,1,"") | M18: =IF(SUM(M17:N17)>0,1,"") | AE18: 65～70 | AF18: =AH18+AJ18 -> 0 | AG18: =AI18+AK18 -> 0 | AH18: =SUMIFS($W$11:$W$70,$S$11:$S$70,1,$U$11:$U$70,1,$V$11:$V$70,">=65",$V$11:$V$70,"<70") -> 0 | AI18: =SUMIFS($W$11:$W$70,$S$11:$S$70,1,$U$11:$U$70,2,$V$11:$V$70,">=65",$V$11:$V$70,"<70") -> 0 | AR18: =SUMIFS($W$11:$W$70,$S$11:$S$70,5,$U$11:$U$70,1,$V$11:$V$70,">=65",$V$11:$V$70,"<70") -> 0 | AS18: =SUMIFS($W$11:$W$70,$S$11:$S$70,5,$U$11:$U$70,2,$V$11:$V$70,">=65",$V$11:$V$70,"<70") -> 0
A19: =ROUND((ROW()-10)/2,0) -> 5 | C19: =IF(INDEX(設定!$C$9:$C$108,$A19,1)="","",INDEX(設定!$C$9:$C$108,$A19,1)) | D19: =IF(INDEX(設定!$D$9:$D$108,$A19,1)="","",INDEX(設定!$D$9:$D$108,$A19,1)) | E19: =IF(INDEX(設定!$E$9:$E$108,$A19,1)="","",INDEX(設定!$E$9:$E$108,$A19,1)) | F19: =IF(S19="","",IF(S19=1,"1：家族",IF(AND(S19>=2,S19<=5),"2：雇用",""))) | G19: =INT(INDEX(設定!$H$9:H$108,$A19,1)) -> 0 | H19: =IF(INDEX(設定!$H$9:$H$108,$A19,1)=0,"",ROUND(MOD(INDEX(設定!$H$9:$H$108,$A19,1),1)*60,0)) | I19: =INT(INDEX(設定!$I$9:$I$108,$A19,1)) -> 0 | J19: =IF(INDEX(設定!$I$9:$I$108,$A19,1)=0,"",ROUND(MOD(INDEX(設定!$I$9:$I$108,$A19,1),1)*60,0)) | K19: =INT(INDEX(設定!$J$9:$J$108,$A19,1)) -> 0 | L19: =IF(INDEX(設定!$J$9:$J$108,$A19,1)=0,"",ROUND(MOD(INDEX(設定!$J$9:$J$108,$A19,1),1)*60,0)) | M19: =INT(INDEX(設定!$K$9:$K$108,$A19,1)) -> 0 | N19: =IF(INDEX(設定!$K$9:$K$108,$A19,1)=0,"",ROUND(MOD(INDEX(設定!$K$9:$K$108,$A19,1),1)*60,0)) | S19: =IF(INDEX(設定!$F$9:$F$108,$A19,1)="","",VALUE(LEFT(INDEX(設定!$F$9:$F$108,$A19,1),1))) | T19: =IF(C19="","",C19) | U19: =IF(D19="","",IF(D19="1：男",1,IF(D19="2：女",2))) | V19: =IF(E19="","",E19) | W19: =IF(AND(G19="",H19="",G20=""),"",ROUND(SUM(G19,H19/60)*G20,1)) | X19: =IF(AND(I19="",J19="",I20=""),"",ROUND(SUM(I19,J19/60)*I20,1)) | Y19: =IF(AND(K19="",L19="",K20=""),"",ROUND(SUM(K19,L19/60)*K20,1)) | Z19: =IF(AND(M19="",N19="",M20=""),"",ROUND(SUM(M19,N19/60)*M20,1)) | AE19: 70～75 | AF19: =AH19+AJ19 -> 0 | AG19: =AI19+AK19 -> 0 | AH19: =SUMIFS($W$11:$W$70,$S$11:$S$70,1,$U$11:$U$70,1,$V$11:$V$70,">=70",$V$11:$V$70,"<75") -> 0 | AI19: =SUMIFS($W$11:$W$70,$S$11:$S$70,1,$U$11:$U$70,2,$V$11:$V$70,">=70",$V$11:$V$70,"<75") -> 0 | AR19: =SUMIFS($W$11:$W$70,$S$11:$S$70,5,$U$11:$U$70,1,$V$11:$V$70,">=70",$V$11:$V$70,"<75") -> 0 | AS19: =SUMIFS($W$11:$W$70,$S$11:$S$70,5,$U$11:$U$70,2,$V$11:$V$70,">=70",$V$11:$V$70,"<75") -> 0
G20: =IF(SUM(G19:H19)>0,1,"") | I20: =IF(SUM(I19:J19)>0,1,"") | K20: =IF(SUM(K19:L19)>0,1,"") | M20: =IF(SUM(M19:N19)>0,1,"") | AE20: 75歳以上 | AF20: =AH20+AJ20 -> 0 | AG20: =AI20+AK20 -> 0 | AH20: =SUMIFS($W$11:$W$70,$S$11:$S$70,1,$U$11:$U$70,1,$V$11:$V$70,">=75") -> 0 | AI20: =SUMIFS($W$11:$W$70,$S$11:$S$70,1,$U$11:$U$70,2,$V$11:$V$70,">=75") -> 0 | AR20: =SUMIFS($W$11:$W$70,$S$11:$S$70,5,$U$11:$U$70,1,$V$11:$V$70,">=75") -> 0 | AS20: =SUMIFS($W$11:$W$70,$S$11:$S$70,5,$U$11:$U$70,2,$V$11:$V$70,">=75") -> 0
A21: =ROUND((ROW()-10)/2,0) -> 6 | C21: =IF(INDEX(設定!$C$9:$C$108,$A21,1)="","",INDEX(設定!$C$9:$C$108,$A21,1)) | D21: =IF(INDEX(設定!$D$9:$D$108,$A21,1)="","",INDEX(設定!$D$9:$D$108,$A21,1)) | E21: =IF(INDEX(設定!$E$9:$E$108,$A21,1)="","",INDEX(設定!$E$9:$E$108,$A21,1)) | F21: =IF(S21="","",IF(S21=1,"1：家族",IF(AND(S21>=2,S21<=5),"2：雇用",""))) | G21: =INT(INDEX(設定!$H$9:H$108,$A21,1)) -> 0 | H21: =IF(INDEX(設定!$H$9:$H$108,$A21,1)=0,"",ROUND(MOD(INDEX(設定!$H$9:$H$108,$A21,1),1)*60,0)) | I21: =INT(INDEX(設定!$I$9:$I$108,$A21,1)) -> 0 | J21: =IF(INDEX(設定!$I$9:$I$108,$A21,1)=0,"",ROUND(MOD(INDEX(設定!$I$9:$I$108,$A21,1),1)*60,0)) | K21: =INT(INDEX(設定!$J$9:$J$108,$A21,1)) -> 0 | L21: =IF(INDEX(設定!$J$9:$J$108,$A21,1)=0,"",ROUND(MOD(INDEX(設定!$J$9:$J$108,$A21,1),1)*60,0)) | M21: =INT(INDEX(設定!$K$9:$K$108,$A21,1)) -> 0 | N21: =IF(INDEX(設定!$K$9:$K$108,$A21,1)=0,"",ROUND(MOD(INDEX(設定!$K$9:$K$108,$A21,1),1)*60,0)) | S21: =IF(INDEX(設定!$F$9:$F$108,$A21,1)="","",VALUE(LEFT(INDEX(設定!$F$9:$F$108,$A21,1),1))) | T21: =IF(C21="","",C21) | U21: =IF(D21="","",IF(D21="1：男",1,IF(D21="2：女",2))) | V21: =IF(E21="","",E21) | W21: =IF(AND(G21="",H21="",G22=""),"",ROUND(SUM(G21,H21/60)*G22,1)) | X21: =IF(AND(I21="",J21="",I22=""),"",ROUND(SUM(I21,J21/60)*I22,1)) | Y21: =IF(AND(K21="",L21="",K22=""),"",ROUND(SUM(K21,L21/60)*K22,1)) | Z21: =IF(AND(M21="",N21="",M22=""),"",ROUND(SUM(M21,N21/60)*M22,1)) | AD21: 敷料搬入・ きゅう肥搬出 | AF21: =SUM(AF22:AF25) -> 0 | AG21: =SUM(AG22:AG25) -> 0 | AL21: =AN21+AP21+AR21 -> 0 | AM21: =AO21+AQ21+AS21 -> 0 | AN21: =SUMIFS($X$11:$X$70,$S$11:$S$70,2,$U$11:$U$70,1) -> 0 | AO21: =SUMIFS($X$11:$X$70,$S$11:$S$70,2,$U$11:$U$70,2) -> 0 | AP21: =AP22 -> 0 | AQ21: =AQ22 -> 0 | AR21: =SUM(AR22:AR25) -> 0 | AS21: =SUM(AS22:AS25) -> 0 | AW21: 敷料搬入・ きゅう肥搬出 | AY21: =SUM(AY22:AY25) -> 0 | AZ21: =SUM(AZ22:AZ25) -> 0 | BA21: =ROUND(BC21+BE21,0) -> 0 | BB21: =ROUND(BD21+BF21,0) -> 0 | BC21: =IFERROR($T$112*AN21/($AN$11+$AN$51),0) -> 0 | BD21: =IFERROR($T$113*AO21/($AO$11+$AO$51),0) -> 0 | BE21: =SUM(BE22:BE25) -> 0 | BF21: =SUM(BF22:BF25) -> 0
G22: =IF(SUM(G21:H21)>0,1,"") | I22: =IF(SUM(I21:J21)>0,1,"") | K22: =IF(SUM(K21:L21)>0,1,"") | M22: =IF(SUM(M21:N21)>0,1,"") | AE22: 65歳未満 | AF22: =AH22+AJ22 -> 0 | AG22: =AI22+AK22 -> 0 | AH22: =SUMIFS($X$11:$X$70,$S$11:$S$70,1,$U$11:$U$70,1,$V$11:$V$70,"<65") -> 0 | AI22: =SUMIFS($X$11:$X$70,$S$11:$S$70,1,$U$11:$U$70,2,$V$11:$V$70,"<65") -> 0 | AJ22: =SUMIFS($X$11:$X$70,$S$11:$S$70,3,$U$11:$U$70,1) -> 0 | AK22: =SUMIFS($X$11:$X$70,$S$11:$S$70,3,$U$11:$U$70,2) -> 0 | AP22: =SUMIFS($X$11:$X$70,$S$11:$S$70,4,$U$11:$U$70,1) -> 0 | AQ22: =SUMIFS($X$11:$X$70,$S$11:$S$70,4,$U$11:$U$70,2) -> 0 | AR22: =SUMIFS($X$11:$X$70,$S$11:$S$70,5,$U$11:$U$70,1,$V$11:$V$70,"<65") -> 0 | AS22: =SUMIFS($X$11:$X$70,$S$11:$S$70,5,$U$11:$U$70,2,$V$11:$V$70,"<65") -> 0 | AX22: 65歳未満 | AY22: =ROUND(AF22*$T$4,0) -> 0 | AZ22: =ROUND(AG22*$T$4,0) -> 0 | BE22: =(AP22+AR22)*$T$4 -> 0 | BF22: =(AQ22+AS22)*$T$4 -> 0
A23: =ROUND((ROW()-10)/2,0) -> 7 | C23: =IF(INDEX(設定!$C$9:$C$108,$A23,1)="","",INDEX(設定!$C$9:$C$108,$A23,1)) | D23: =IF(INDEX(設定!$D$9:$D$108,$A23,1)="","",INDEX(設定!$D$9:$D$108,$A23,1)) | E23: =IF(INDEX(設定!$E$9:$E$108,$A23,1)="","",INDEX(設定!$E$9:$E$108,$A23,1)) | F23: =IF(S23="","",IF(S23=1,"1：家族",IF(AND(S23>=2,S23<=5),"2：雇用",""))) | G23: =INT(INDEX(設定!$H$9:H$108,$A23,1)) -> 0 | H23: =IF(INDEX(設定!$H$9:$H$108,$A23,1)=0,"",ROUND(MOD(INDEX(設定!$H$9:$H$108,$A23,1),1)*60,0)) | I23: =INT(INDEX(設定!$I$9:$I$108,$A23,1)) -> 0 | J23: =IF(INDEX(設定!$I$9:$I$108,$A23,1)=0,"",ROUND(MOD(INDEX(設定!$I$9:$I$108,$A23,1),1)*60,0)) | K23: =INT(INDEX(設定!$J$9:$J$108,$A23,1)) -> 0 | L23: =IF(INDEX(設定!$J$9:$J$108,$A23,1)=0,"",ROUND(MOD(INDEX(設定!$J$9:$J$108,$A23,1),1)*60,0)) | M23: =INT(INDEX(設定!$K$9:$K$108,$A23,1)) -> 0 | N23: =IF(INDEX(設定!$K$9:$K$108,$A23,1)=0,"",ROUND(MOD(INDEX(設定!$K$9:$K$108,$A23,1),1)*60,0)) | S23: =IF(INDEX(設定!$F$9:$F$108,$A23,1)="","",VALUE(LEFT(INDEX(設定!$F$9:$F$108,$A23,1),1))) | T23: =IF(C23="","",C23) | U23: =IF(D23="","",IF(D23="1：男",1,IF(D23="2：女",2))) | V23: =IF(E23="","",E23) | W23: =IF(AND(G23="",H23="",G24=""),"",ROUND(SUM(G23,H23/60)*G24,1)) | X23: =IF(AND(I23="",J23="",I24=""),"",ROUND(SUM(I23,J23/60)*I24,1)) | Y23: =IF(AND(K23="",L23="",K24=""),"",ROUND(SUM(K23,L23/60)*K24,1)) | Z23: =IF(AND(M23="",N23="",M24=""),"",ROUND(SUM(M23,N23/60)*M24,1)) | AE23: 65～70 | AF23: =AH23+AJ23 -> 0 | AG23: =AI23+AK23 -> 0 | AH23: =SUMIFS($X$11:$X$70,$S$11:$S$70,1,$U$11:$U$70,1,$V$11:$V$70,">=65",$V$11:$V$70,"<70") -> 0 | AI23: =SUMIFS($X$11:$X$70,$S$11:$S$70,1,$U$11:$U$70,2,$V$11:$V$70,">=65",$V$11:$V$70,"<70") -> 0 | AR23: =SUMIFS($X$11:$X$70,$S$11:$S$70,5,$U$11:$U$70,1,$V$11:$V$70,">=65",$V$11:$V$70,"<70") -> 0 | AS23: =SUMIFS($X$11:$X$70,$S$11:$S$70,5,$U$11:$U$70,2,$V$11:$V$70,">=65",$V$11:$V$70,"<70") -> 0 | AX23: 65～70 | AY23: =ROUND(AF23*$T$4*0.9,0) -> 0 | AZ23: =ROUND(AG23*$T$4*0.9,0) -> 0 | BE23: =(AR23)*$T$4*0.9 -> 0 | BF23: =(AS23)*$T$4*0.9 -> 0
G24: =IF(SUM(G23:H23)>0,1,"") | I24: =IF(SUM(I23:J23)>0,1,"") | K24: =IF(SUM(K23:L23)>0,1,"") | M24: =IF(SUM(M23:N23)>0,1,"") | AE24: 70～75 | AF24: =AH24+AJ24 -> 0 | AG24: =AI24+AK24 -> 0 | AH24: =SUMIFS($X$11:$X$70,$S$11:$S$70,1,$U$11:$U$70,1,$V$11:$V$70,">=70",$V$11:$V$70,"<75") -> 0 | AI24: =SUMIFS($X$11:$X$70,$S$11:$S$70,1,$U$11:$U$70,2,$V$11:$V$70,">=70",$V$11:$V$70,"<75") -> 0 | AR24: =SUMIFS($X$11:$X$70,$S$11:$S$70,5,$U$11:$U$70,1,$V$11:$V$70,">=70",$V$11:$V$70,"<75") -> 0 | AS24: =SUMIFS($X$11:$X$70,$S$11:$S$70,5,$U$11:$U$70,2,$V$11:$V$70,">=70",$V$11:$V$70,"<75") -> 0 | AX24: 70～75 | AY24: =ROUND(AF24*$T$4*0.8,0) -> 0 | AZ24: =ROUND(AG24*$T$4*0.8,0) -> 0 | BE24: =(AR24)*$T$4*0.8 -> 0 | BF24: =(AS24)*$T$4*0.8 -> 0
A25: =ROUND((ROW()-10)/2,0) -> 8 | C25: =IF(INDEX(設定!$C$9:$C$108,$A25,1)="","",INDEX(設定!$C$9:$C$108,$A25,1)) | D25: =IF(INDEX(設定!$D$9:$D$108,$A25,1)="","",INDEX(設定!$D$9:$D$108,$A25,1)) | E25: =IF(INDEX(設定!$E$9:$E$108,$A25,1)="","",INDEX(設定!$E$9:$E$108,$A25,1)) | F25: =IF(S25="","",IF(S25=1,"1：家族",IF(AND(S25>=2,S25<=5),"2：雇用",""))) | G25: =INT(INDEX(設定!$H$9:H$108,$A25,1)) -> 0 | H25: =IF(INDEX(設定!$H$9:$H$108,$A25,1)=0,"",ROUND(MOD(INDEX(設定!$H$9:$H$108,$A25,1),1)*60,0)) | I25: =INT(INDEX(設定!$I$9:$I$108,$A25,1)) -> 0 | J25: =IF(INDEX(設定!$I$9:$I$108,$A25,1)=0,"",ROUND(MOD(INDEX(設定!$I$9:$I$108,$A25,1),1)*60,0)) | K25: =INT(INDEX(設定!$J$9:$J$108,$A25,1)) -> 0 | L25: =IF(INDEX(設定!$J$9:$J$108,$A25,1)=0,"",ROUND(MOD(INDEX(設定!$J$9:$J$108,$A25,1),1)*60,0)) | M25: =INT(INDEX(設定!$K$9:$K$108,$A25,1)) -> 0 | N25: =IF(INDEX(設定!$K$9:$K$108,$A25,1)=0,"",ROUND(MOD(INDEX(設定!$K$9:$K$108,$A25,1),1)*60,0)) | S25: =IF(INDEX(設定!$F$9:$F$108,$A25,1)="","",VALUE(LEFT(INDEX(設定!$F$9:$F$108,$A25,1),1))) | T25: =IF(C25="","",C25) | U25: =IF(D25="","",IF(D25="1：男",1,IF(D25="2：女",2))) | V25: =IF(E25="","",E25) | W25: =IF(AND(G25="",H25="",G26=""),"",ROUND(SUM(G25,H25/60)*G26,1)) | X25: =IF(AND(I25="",J25="",I26=""),"",ROUND(SUM(I25,J25/60)*I26,1)) | Y25: =IF(AND(K25="",L25="",K26=""),"",ROUND(SUM(K25,L25/60)*K26,1)) | Z25: =IF(AND(M25="",N25="",M26=""),"",ROUND(SUM(M25,N25/60)*M26,1)) | AE25: 75歳以上 | AF25: =AH25+AJ25 -> 0 | AG25: =AI25+AK25 -> 0 | AH25: =SUMIFS($X$11:$X$70,$S$11:$S$70,1,$U$11:$U$70,1,$V$11:$V$70,">=75") -> 0 | AI25: =SUMIFS($X$11:$X$70,$S$11:$S$70,1,$U$11:$U$70,2,$V$11:$V$70,">=75") -> 0 | AR25: =SUMIFS($X$11:$X$70,$S$11:$S$70,5,$U$11:$U$70,1,$V$11:$V$70,">=75") -> 0 | AS25: =SUMIFS($X$11:$X$70,$S$11:$S$70,5,$U$11:$U$70,2,$V$11:$V$70,">=75") -> 0 | AX25: 75歳以上 | AY25: =ROUND(AF25*$T$4*0.7,0) -> 0 | AZ25: =ROUND(AG25*$T$4*0.7,0) -> 0 | BE25: =(AR25)*$T$4*0.7 -> 0 | BF25: =(AS25)*$T$4*0.7 -> 0
G26: =IF(SUM(G25:H25)>0,1,"") | I26: =IF(SUM(I25:J25)>0,1,"") | K26: =IF(SUM(K25:L25)>0,1,"") | M26: =IF(SUM(M25:N25)>0,1,"") | AD26: 搾乳・牛乳処理・運搬 | AF26: =SUM(AF27:AF30) -> 0 | AG26: =SUM(AG27:AG30) -> 0 | AL26: =AN26+AP26+AR26 -> 0 | AM26: =AO26+AQ26+AS26 -> 0 | AN26: =SUMIFS($Y$11:$Y$70,$S$11:$S$70,2,$U$11:$U$70,1) -> 0 | AO26: =SUMIFS($Y$11:$Y$70,$S$11:$S$70,2,$U$11:$U$70,2) -> 0 | AP26: =AP27 -> 0 | AQ26: =AQ27 -> 0 | AR26: =SUM(AR27:AR30) -> 0 | AS26: =SUM(AS27:AS30) -> 0 | AW26: 搾乳・牛乳処理・運搬 | AY26: =SUM(AY27:AY30) -> 0 | AZ26: =SUM(AZ27:AZ30) -> 0 | BA26: =ROUND(BC26+BE26,0) -> 0 | BB26: =ROUND(BD26+BF26,0) -> 0 | BC26: =IFERROR($T$112*AN26/($AN$11+$AN$51),0) -> 0 | BD26: =IFERROR($T$113*AO26/($AO$11+$AO$51),0) -> 0 | BE26: =SUM(BE27:BE30) -> 0 | BF26: =SUM(BF27:BF30) -> 0
A27: =ROUND((ROW()-10)/2,0) -> 9 | C27: =IF(INDEX(設定!$C$9:$C$108,$A27,1)="","",INDEX(設定!$C$9:$C$108,$A27,1)) | D27: =IF(INDEX(設定!$D$9:$D$108,$A27,1)="","",INDEX(設定!$D$9:$D$108,$A27,1)) | E27: =IF(INDEX(設定!$E$9:$E$108,$A27,1)="","",INDEX(設定!$E$9:$E$108,$A27,1)) | F27: =IF(S27="","",IF(S27=1,"1：家族",IF(AND(S27>=2,S27<=5),"2：雇用",""))) | G27: =INT(INDEX(設定!$H$9:H$108,$A27,1)) -> 0 | H27: =IF(INDEX(設定!$H$9:$H$108,$A27,1)=0,"",ROUND(MOD(INDEX(設定!$H$9:$H$108,$A27,1),1)*60,0)) | I27: =INT(INDEX(設定!$I$9:$I$108,$A27,1)) -> 0 | J27: =IF(INDEX(設定!$I$9:$I$108,$A27,1)=0,"",ROUND(MOD(INDEX(設定!$I$9:$I$108,$A27,1),1)*60,0)) | K27: =INT(INDEX(設定!$J$9:$J$108,$A27,1)) -> 0 | L27: =IF(INDEX(設定!$J$9:$J$108,$A27,1)=0,"",ROUND(MOD(INDEX(設定!$J$9:$J$108,$A27,1),1)*60,0)) | M27: =INT(INDEX(設定!$K$9:$K$108,$A27,1)) -> 0 | N27: =IF(INDEX(設定!$K$9:$K$108,$A27,1)=0,"",ROUND(MOD(INDEX(設定!$K$9:$K$108,$A27,1),1)*60,0)) | S27: =IF(INDEX(設定!$F$9:$F$108,$A27,1)="","",VALUE(LEFT(INDEX(設定!$F$9:$F$108,$A27,1),1))) | T27: =IF(C27="","",C27) | U27: =IF(D27="","",IF(D27="1：男",1,IF(D27="2：女",2))) | V27: =IF(E27="","",E27) | W27: =IF(AND(G27="",H27="",G28=""),"",ROUND(SUM(G27,H27/60)*G28,1)) | X27: =IF(AND(I27="",J27="",I28=""),"",ROUND(SUM(I27,J27/60)*I28,1)) | Y27: =IF(AND(K27="",L27="",K28=""),"",ROUND(SUM(K27,L27/60)*K28,1)) | Z27: =IF(AND(M27="",N27="",M28=""),"",ROUND(SUM(M27,N27/60)*M28,1)) | AE27: 65歳未満 | AF27: =AH27+AJ27 -> 0 | AG27: =AI27+AK27 -> 0 | AH27: =SUMIFS($Y$11:$Y$70,$S$11:$S$70,1,$U$11:$U$70,1,$V$11:$V$70,"<65") -> 0 | AI27: =SUMIFS($Y$11:$Y$70,$S$11:$S$70,1,$U$11:$U$70,2,$V$11:$V$70,"<65") -> 0 | AJ27: =SUMIFS($Y$11:$Y$70,$S$11:$S$70,3,$U$11:$U$70,1) -> 0 | AK27: =SUMIFS($Y$11:$Y$70,$S$11:$S$70,3,$U$11:$U$70,2) -> 0 | AP27: =SUMIFS($Y$11:$Y$70,$S$11:$S$70,4,$U$11:$U$70,1) -> 0 | AQ27: =SUMIFS($Y$11:$Y$70,$S$11:$S$70,4,$U$11:$U$70,2) -> 0 | AR27: =SUMIFS($Y$11:$Y$70,$S$11:$S$70,5,$U$11:$U$70,1,$V$11:$V$70,"<65") -> 0 | AS27: =SUMIFS($Y$11:$Y$70,$S$11:$S$70,5,$U$11:$U$70,2,$V$11:$V$70,"<65") -> 0 | AX27: 65歳未満 | AY27: =ROUND(AF27*$T$4,0) -> 0 | AZ27: =ROUND(AG27*$T$4,0) -> 0 | BE27: =(AP27+AR27)*$T$4 -> 0 | BF27: =(AQ27+AS27)*$T$4 -> 0
G28: =IF(SUM(G27:H27)>0,1,"") | I28: =IF(SUM(I27:J27)>0,1,"") | K28: =IF(SUM(K27:L27)>0,1,"") | M28: =IF(SUM(M27:N27)>0,1,"") | AE28: 65～70 | AF28: =AH28+AJ28 -> 0 | AG28: =AI28+AK28 -> 0 | AH28: =SUMIFS($Y$11:$Y$70,$S$11:$S$70,1,$U$11:$U$70,1,$V$11:$V$70,">=65",$V$11:$V$70,"<70") -> 0 | AI28: =SUMIFS($Y$11:$Y$70,$S$11:$S$70,1,$U$11:$U$70,2,$V$11:$V$70,">=65",$V$11:$V$70,"<70") -> 0 | AR28: =SUMIFS($Y$11:$Y$70,$S$11:$S$70,5,$U$11:$U$70,1,$V$11:$V$70,">=65",$V$11:$V$70,"<70") -> 0 | AS28: =SUMIFS($Y$11:$Y$70,$S$11:$S$70,5,$U$11:$U$70,2,$V$11:$V$70,">=65",$V$11:$V$70,"<70") -> 0 | AX28: 65～70 | AY28: =ROUND(AF28*$T$4*0.9,0) -> 0 | AZ28: =ROUND(AG28*$T$4*0.9,0) -> 0 | BE28: =(AR28)*$T$4*0.9 -> 0 | BF28: =(AS28)*$T$4*0.9 -> 0
A29: =ROUND((ROW()-10)/2,0) -> 10 | C29: =IF(INDEX(設定!$C$9:$C$108,$A29,1)="","",INDEX(設定!$C$9:$C$108,$A29,1)) | D29: =IF(INDEX(設定!$D$9:$D$108,$A29,1)="","",INDEX(設定!$D$9:$D$108,$A29,1)) | E29: =IF(INDEX(設定!$E$9:$E$108,$A29,1)="","",INDEX(設定!$E$9:$E$108,$A29,1)) | F29: =IF(S29="","",IF(S29=1,"1：家族",IF(AND(S29>=2,S29<=5),"2：雇用",""))) | G29: =INT(INDEX(設定!$H$9:H$108,$A29,1)) -> 0 | H29: =IF(INDEX(設定!$H$9:$H$108,$A29,1)=0,"",ROUND(MOD(INDEX(設定!$H$9:$H$108,$A29,1),1)*60,0)) | I29: =INT(INDEX(設定!$I$9:$I$108,$A29,1)) -> 0 | J29: =IF(INDEX(設定!$I$9:$I$108,$A29,1)=0,"",ROUND(MOD(INDEX(設定!$I$9:$I$108,$A29,1),1)*60,0)) | K29: =INT(INDEX(設定!$J$9:$J$108,$A29,1)) -> 0 | L29: =IF(INDEX(設定!$J$9:$J$108,$A29,1)=0,"",ROUND(MOD(INDEX(設定!$J$9:$J$108,$A29,1),1)*60,0)) | M29: =INT(INDEX(設定!$K$9:$K$108,$A29,1)) -> 0 | N29: =IF(INDEX(設定!$K$9:$K$108,$A29,1)=0,"",ROUND(MOD(INDEX(設定!$K$9:$K$108,$A29,1),1)*60,0)) | S29: =IF(INDEX(設定!$F$9:$F$108,$A29,1)="","",VALUE(LEFT(INDEX(設定!$F$9:$F$108,$A29,1),1))) | T29: =IF(C29="","",C29) | U29: =IF(D29="","",IF(D29="1：男",1,IF(D29="2：女",2))) | V29: =IF(E29="","",E29) | W29: =IF(AND(G29="",H29="",G30=""),"",ROUND(SUM(G29,H29/60)*G30,1)) | X29: =IF(AND(I29="",J29="",I30=""),"",ROUND(SUM(I29,J29/60)*I30,1)) | Y29: =IF(AND(K29="",L29="",K30=""),"",ROUND(SUM(K29,L29/60)*K30,1)) | Z29: =IF(AND(M29="",N29="",M30=""),"",ROUND(SUM(M29,N29/60)*M30,1)) | AE29: 70～75 | AF29: =AH29+AJ29 -> 0 | AG29: =AI29+AK29 -> 0 | AH29: =SUMIFS($Y$11:$Y$70,$S$11:$S$70,1,$U$11:$U$70,1,$V$11:$V$70,">=70",$V$11:$V$70,"<75") -> 0 | AI29: =SUMIFS($Y$11:$Y$70,$S$11:$S$70,1,$U$11:$U$70,2,$V$11:$V$70,">=70",$V$11:$V$70,"<75") -> 0 | AR29: =SUMIFS($Y$11:$Y$70,$S$11:$S$70,5,$U$11:$U$70,1,$V$11:$V$70,">=70",$V$11:$V$70,"<75") -> 0 | AS29: =SUMIFS($Y$11:$Y$70,$S$11:$S$70,5,$U$11:$U$70,2,$V$11:$V$70,">=70",$V$11:$V$70,"<75") -> 0 | AX29: 70～75 | AY29: =ROUND(AF29*$T$4*0.8,0) -> 0 | AZ29: =ROUND(AG29*$T$4*0.8,0) -> 0 | BE29: =(AR29)*$T$4*0.8 -> 0 | BF29: =(AS29)*$T$4*0.8 -> 0
G30: =IF(SUM(G29:H29)>0,1,"") | I30: =IF(SUM(I29:J29)>0,1,"") | K30: =IF(SUM(K29:L29)>0,1,"") | M30: =IF(SUM(M29:N29)>0,1,"") | AE30: 75歳以上 | AF30: =AH30+AJ30 -> 0 | AG30: =AI30+AK30 -> 0 | AH30: =SUMIFS($Y$11:$Y$70,$S$11:$S$70,1,$U$11:$U$70,1,$V$11:$V$70,">=75") -> 0 | AI30: =SUMIFS($Y$11:$Y$70,$S$11:$S$70,1,$U$11:$U$70,2,$V$11:$V$70,">=75") -> 0 | AR30: =SUMIFS($Y$11:$Y$70,$S$11:$S$70,5,$U$11:$U$70,1,$V$11:$V$70,">=75") -> 0 | AS30: =SUMIFS($Y$11:$Y$70,$S$11:$S$70,5,$U$11:$U$70,2,$V$11:$V$70,">=75") -> 0 | AX30: 75歳以上 | AY30: =ROUND(AF30*$T$4*0.7,0) -> 0 | AZ30: =ROUND(AG30*$T$4*0.7,0) -> 0 | BE30: =(AR30)*$T$4*0.7 -> 0 | BF30: =(AS30)*$T$4*0.7 -> 0
A31: =ROUND((ROW()-10)/2,0) -> 11 | C31: =IF(INDEX(設定!$C$9:$C$108,$A31,1)="","",INDEX(設定!$C$9:$C$108,$A31,1)) | D31: =IF(INDEX(設定!$D$9:$D$108,$A31,1)="","",INDEX(設定!$D$9:$D$108,$A31,1)) | E31: =IF(INDEX(設定!$E$9:$E$108,$A31,1)="","",INDEX(設定!$E$9:$E$108,$A31,1)) | F31: =IF(S31="","",IF(S31=1,"1：家族",IF(AND(S31>=2,S31<=5),"2：雇用",""))) | G31: =INT(INDEX(設定!$H$9:H$108,$A31,1)) -> 0 | H31: =IF(INDEX(設定!$H$9:$H$108,$A31,1)=0,"",ROUND(MOD(INDEX(設定!$H$9:$H$108,$A31,1),1)*60,0)) | I31: =INT(INDEX(設定!$I$9:$I$108,$A31,1)) -> 0 | J31: =IF(INDEX(設定!$I$9:$I$108,$A31,1)=0,"",ROUND(MOD(INDEX(設定!$I$9:$I$108,$A31,1),1)*60,0)) | K31: =INT(INDEX(設定!$J$9:$J$108,$A31,1)) -> 0 | L31: =IF(INDEX(設定!$J$9:$J$108,$A31,1)=0,"",ROUND(MOD(INDEX(設定!$J$9:$J$108,$A31,1),1)*60,0)) | M31: =INT(INDEX(設定!$K$9:$K$108,$A31,1)) -> 0 | N31: =IF(INDEX(設定!$K$9:$K$108,$A31,1)=0,"",ROUND(MOD(INDEX(設定!$K$9:$K$108,$A31,1),1)*60,0)) | S31: =IF(INDEX(設定!$F$9:$F$108,$A31,1)="","",VALUE(LEFT(INDEX(設定!$F$9:$F$108,$A31,1),1))) | T31: =IF(C31="","",C31) | U31: =IF(D31="","",IF(D31="1：男",1,IF(D31="2：女",2))) | V31: =IF(E31="","",E31) | W31: =IF(AND(G31="",H31="",G32=""),"",ROUND(SUM(G31,H31/60)*G32,1)) | X31: =IF(AND(I31="",J31="",I32=""),"",ROUND(SUM(I31,J31/60)*I32,1)) | Y31: =IF(AND(K31="",L31="",K32=""),"",ROUND(SUM(K31,L31/60)*K32,1)) | Z31: =IF(AND(M31="",N31="",M32=""),"",ROUND(SUM(M31,N31/60)*M32,1)) | AD31: その他の 飼育作業 | AF31: =SUM(AF32:AF35) -> 0 | AG31: =SUM(AG32:AG35) -> 0 | AL31: =AN31+AP31+AR31 -> 0 | AM31: =AO31+AQ31+AS31 -> 0 | AN31: =SUMIFS($Z$11:$Z$70,$S$11:$S$70,2,$U$11:$U$70,1) -> 0 | AO31: =SUMIFS($Z$11:$Z$70,$S$11:$S$70,2,$U$11:$U$70,2) -> 0 | AP31: =AP32 -> 0 | AQ31: =AQ32 -> 0 | AR31: =SUM(AR32:AR35) -> 0 | AS31: =SUM(AS32:AS35) -> 0
G32: =IF(SUM(G31:H31)>0,1,"") | I32: =IF(SUM(I31:J31)>0,1,"") | K32: =IF(SUM(K31:L31)>0,1,"") | M32: =IF(SUM(M31:N31)>0,1,"") | AE32: 65歳未満 | AF32: =AH32+AJ32 -> 0 | AG32: =AI32+AK32 -> 0 | AH32: =SUMIFS($Z$11:$Z$70,$S$11:$S$70,1,$U$11:$U$70,1,$V$11:$V$70,"<65")+SUMIFS($W$77:$W$106,$S$77:$S$106,1,$U$77:$U$106,1,$V$77:$V$106,"<65") -> 0 | AI32: =SUMIFS($Z$11:$Z$70,$S$11:$S$70,1,$U$11:$U$70,2,$V$11:$V$70,"<65")+SUMIFS($W$77:$W$106,$S$77:$S$106,1,$U$77:$U$106,2,$V$77:$V$106,"<65") -> 0 | AJ32: =SUMIFS($Z$11:$Z$70,$S$11:$S$70,3,$U$11:$U$70,1) +SUMIFS($Y$77:$Y$106,$S$77:$S$106,3,$U$77:$U$106,1) -> 0 | AK32: =SUMIFS($Z$11:$Z$70,$S$11:$S$70,3,$U$11:$U$70,2) +SUMIFS($Y$77:$Y$106,$S$77:$S$106,3,$U$77:$U$106,2) -> 0 | AP32: =SUMIFS($Z$11:$Z$70,$S$11:$S$70,4,$U$11:$U$70,1) +SUMIFS($Y$77:$Y$106,$S$77:$S$106,4,$U$77:$U$106,1) -> 0 | AQ32: =SUMIFS($Z$11:$Z$70,$S$11:$S$70,4,$U$11:$U$70,2) +SUMIFS($Y$77:$Y$106,$S$77:$S$106,4,$U$77:$U$106,2) -> 0 | AR32: =SUMIFS($Z$11:$Z$70,$S$11:$S$70,5,$U$11:$U$70,1,$V$11:$V$70,"<65") -> 0 | AS32: =SUMIFS($Z$11:$Z$70,$S$11:$S$70,5,$U$11:$U$70,2,$V$11:$V$70,"<65") -> 0
A33: =ROUND((ROW()-10)/2,0) -> 12 | C33: =IF(INDEX(設定!$C$9:$C$108,$A33,1)="","",INDEX(設定!$C$9:$C$108,$A33,1)) | D33: =IF(INDEX(設定!$D$9:$D$108,$A33,1)="","",INDEX(設定!$D$9:$D$108,$A33,1)) | E33: =IF(INDEX(設定!$E$9:$E$108,$A33,1)="","",INDEX(設定!$E$9:$E$108,$A33,1)) | F33: =IF(S33="","",IF(S33=1,"1：家族",IF(AND(S33>=2,S33<=5),"2：雇用",""))) | G33: =INT(INDEX(設定!$H$9:H$108,$A33,1)) -> 0 | H33: =IF(INDEX(設定!$H$9:$H$108,$A33,1)=0,"",ROUND(MOD(INDEX(設定!$H$9:$H$108,$A33,1),1)*60,0)) | I33: =INT(INDEX(設定!$I$9:$I$108,$A33,1)) -> 0 | J33: =IF(INDEX(設定!$I$9:$I$108,$A33,1)=0,"",ROUND(MOD(INDEX(設定!$I$9:$I$108,$A33,1),1)*60,0)) | K33: =INT(INDEX(設定!$J$9:$J$108,$A33,1)) -> 0 | L33: =IF(INDEX(設定!$J$9:$J$108,$A33,1)=0,"",ROUND(MOD(INDEX(設定!$J$9:$J$108,$A33,1),1)*60,0)) | M33: =INT(INDEX(設定!$K$9:$K$108,$A33,1)) -> 0 | N33: =IF(INDEX(設定!$K$9:$K$108,$A33,1)=0,"",ROUND(MOD(INDEX(設定!$K$9:$K$108,$A33,1),1)*60,0)) | S33: =IF(INDEX(設定!$F$9:$F$108,$A33,1)="","",VALUE(LEFT(INDEX(設定!$F$9:$F$108,$A33,1),1))) | T33: =IF(C33="","",C33) | U33: =IF(D33="","",IF(D33="1：男",1,IF(D33="2：女",2))) | V33: =IF(E33="","",E33) | W33: =IF(AND(G33="",H33="",G34=""),"",ROUND(SUM(G33,H33/60)*G34,1)) | X33: =IF(AND(I33="",J33="",I34=""),"",ROUND(SUM(I33,J33/60)*I34,1)) | Y33: =IF(AND(K33="",L33="",K34=""),"",ROUND(SUM(K33,L33/60)*K34,1)) | Z33: =IF(AND(M33="",N33="",M34=""),"",ROUND(SUM(M33,N33/60)*M34,1)) | AE33: 65～70 | AF33: =AH33+AJ33 -> 0 | AG33: =AI33+AK33 -> 0 | AH33: =SUMIFS($Z$11:$Z$70,$S$11:$S$70,1,$U$11:$U$70,1,$V$11:$V$70,">=65",$V$11:$V$70,"<70")+SUMIFS($W$77:$W$106,$S$77:$S$106,1,$U$77:$U$106,1,$V$77:$V$106,">=65",$V$77:$V$106,"<70") -> 0 | AI33: =SUMIFS($Z$11:$Z$70,$S$11:$S$70,1,$U$11:$U$70,2,$V$11:$V$70,">=65",$V$11:$V$70,"<70")+SUMIFS($W$77:$W$106,$S$77:$S$106,1,$U$77:$U$106,2,$V$77:$V$106,">=65",$V$77:$V$106,"<70") -> 0 | AR33: =SUMIFS($Z$11:$Z$70,$S$11:$S$70,5,$U$11:$U$70,1,$V$11:$V$70,">=65",$V$11:$V$70,"<70") -> 0 | AS33: =SUMIFS($Z$11:$Z$70,$S$11:$S$70,5,$U$11:$U$70,2,$V$11:$V$70,">=65",$V$11:$V$70,"<70") -> 0
G34: =IF(SUM(G33:H33)>0,1,"") | I34: =IF(SUM(I33:J33)>0,1,"") | K34: =IF(SUM(K33:L33)>0,1,"") | M34: =IF(SUM(M33:N33)>0,1,"") | AE34: 70～75 | AF34: =AH34+AJ34 -> 0 | AG34: =AI34+AK34 -> 0 | AH34: =SUMIFS($Z$11:$Z$70,$S$11:$S$70,1,$U$11:$U$70,1,$V$11:$V$70,">=70",$V$11:$V$70,"<75")+SUMIFS($W$77:$W$106,$S$77:$S$106,1,$U$77:$U$106,1,$V$77:$V$106,">=70",$V$77:$V$106,"<75") -> 0 | AI34: =SUMIFS($Z$11:$Z$70,$S$11:$S$70,1,$U$11:$U$70,2,$V$11:$V$70,">=70",$V$11:$V$70,"<75")+SUMIFS($W$77:$W$106,$S$77:$S$106,1,$U$77:$U$106,2,$V$77:$V$106,">=70",$V$77:$V$106,"<75") -> 0 | AR34: =SUMIFS($Z$11:$Z$70,$S$11:$S$70,5,$U$11:$U$70,1,$V$11:$V$70,">=70",$V$11:$V$70,"<75") -> 0 | AS34: =SUMIFS($Z$11:$Z$70,$S$11:$S$70,5,$U$11:$U$70,2,$V$11:$V$70,">=70",$V$11:$V$70,"<75") -> 0
