Workbook

Sheet No.1
A1: 2019 | C1: 年産 小麦・大豆生産費統計（組織法人経営体） | O1: センサス番号
A2: 個別結果検討表 №１
A4: 【生産費】
A5: 区 分 | G5: 単位 | H5: =A1-2000 -> 19 | I5: 構成割合 | J5: =H5-1 -> 18 | K5: 構成割合 | L5: 増減率 | M5: 増減差 | N5: 主 な 増 減 要 因
I6: （％） | K6: （％） | L6: （％）
A7: 10 ａ 当 た り 生 産 費 | B7: 物財費 | G7: 円 | I7: =IFERROR(H7/$H$29*100,"-") -> - | K7: =IFERROR(J7/$J$29*100,"-") -> - | L7: =IFERROR(100*(H7-J7)/J7,"-") -> - | M7: =H7-J7 -> 0
C8: 種苗費 | G8: 〃 | I8: =IFERROR(H8/$H$29*100,"-") -> - | K8: =IFERROR(J8/$J$29*100,"-") -> - | L8: =IFERROR(100*(H8-J8)/J8,"-") -> - | M8: =H8-J8 -> 0
C9: 肥料費 | G9: 〃 | I9: =IFERROR(H9/$H$29*100,"-") -> - | K9: =IFERROR(J9/$J$29*100,"-") -> - | L9: =IFERROR(100*(H9-J9)/J9,"-") -> - | M9: =H9-J9 -> 0
C10: 農業薬剤費 | G10: 〃 | I10: =IFERROR(H10/$H$29*100,"-") -> - | K10: =IFERROR(J10/$J$29*100,"-") -> - | L10: =IFERROR(100*(H10-J10)/J10,"-") -> - | M10: =H10-J10 -> 0
C11: 光熱動力費 | G11: 〃 | I11: =IFERROR(H11/$H$29*100,"-") -> - | K11: =IFERROR(J11/$J$29*100,"-") -> - | L11: =IFERROR(100*(H11-J11)/J11,"-") -> - | M11: =H11-J11 -> 0
C12: その他の諸材料費 | G12: 〃 | I12: =IFERROR(H12/$H$29*100,"-") -> - | K12: =IFERROR(J12/$J$29*100,"-") -> - | L12: =IFERROR(100*(H12-J12)/J12,"-") -> - | M12: =H12-J12 -> 0
C13: 土地改良及び水利費 | G13: 〃 | I13: =IFERROR(H13/$H$29*100,"-") -> - | K13: =IFERROR(J13/$J$29*100,"-") -> - | L13: =IFERROR(100*(H13-J13)/J13,"-") -> - | M13: =H13-J13 -> 0
C14: 賃借料及び料金 | G14: 〃 | I14: =IFERROR(H14/$H$29*100,"-") -> - | K14: =IFERROR(J14/$J$29*100,"-") -> - | L14: =IFERROR(100*(H14-J14)/J14,"-") -> - | M14: =H14-J14 -> 0
C15: 物件税及び公課諸負担 | G15: 〃 | I15: =IFERROR(H15/$H$29*100,"-") -> - | K15: =IFERROR(J15/$J$29*100,"-") -> - | L15: =IFERROR(100*(H15-J15)/J15,"-") -> - | M15: =H15-J15 -> 0
C16: 建物費 | G16: 〃 | I16: =IFERROR(H16/$H$29*100,"-") -> - | K16: =IFERROR(J16/$J$29*100,"-") -> - | L16: =IFERROR(100*(H16-J16)/J16,"-") -> - | M16: =H16-J16 -> 0
D17: 償却費 | G17: 〃 | I17: =IFERROR(H17/$H$29*100,"-") -> - | K17: =IFERROR(J17/$J$29*100,"-") -> - | L17: =IFERROR(100*(H17-J17)/J17,"-") -> - | M17: =H17-J17 -> 0
C18: 自動車費 | G18: 〃 | I18: =IFERROR(H18/$H$29*100,"-") -> - | K18: =IFERROR(J18/$J$29*100,"-") -> - | L18: =IFERROR(100*(H18-J18)/J18,"-") -> - | M18: =H18-J18 -> 0
D19: 償却費 | G19: 〃 | I19: =IFERROR(H19/$H$29*100,"-") -> - | K19: =IFERROR(J19/$J$29*100,"-") -> - | L19: =IFERROR(100*(H19-J19)/J19,"-") -> - | M19: =H19-J19 -> 0
C20: 農機具費 | G20: 〃 | I20: =IFERROR(H20/$H$29*100,"-") -> - | K20: =IFERROR(J20/$J$29*100,"-") -> - | L20: =IFERROR(100*(H20-J20)/J20,"-") -> - | M20: =H20-J20 -> 0
D21: 償却費 | G21: 〃 | I21: =IFERROR(H21/$H$29*100,"-") -> - | K21: =IFERROR(J21/$J$29*100,"-") -> - | L21: =IFERROR(100*(H21-J21)/J21,"-") -> - | M21: =H21-J21 -> 0
C22: 生産管理費 | G22: 〃 | I22: =IFERROR(H22/$H$29*100,"-") -> - | K22: =IFERROR(J22/$J$29*100,"-") -> - | L22: =IFERROR(100*(H22-J22)/J22,"-") -> - | M22: =H22-J22 -> 0
D23: 償却費 | G23: 〃 | I23: =IFERROR(H23/$H$29*100,"-") -> - | K23: =IFERROR(J23/$J$29*100,"-") -> - | L23: =IFERROR(100*(H23-J23)/J23,"-") -> - | M23: =H23-J23 -> 0
B24: 労働費 | G24: 〃 | I24: =IFERROR(H24/$H$29*100,"-") -> - | K24: =IFERROR(J24/$J$29*100,"-") -> - | L24: =IFERROR(100*(H24-J24)/J24,"-") -> - | M24: =H24-J24 -> 0
D25: 構成員 | G25: 〃 | I25: =IFERROR(H25/$H$29*100,"-") -> - | K25: =IFERROR(J25/$J$29*100,"-") -> - | L25: =IFERROR(100*(H25-J25)/J25,"-") -> - | M25: =H25-J25 -> 0
C26: 直接労働費 | G26: 〃 | I26: =IFERROR(H26/$H$29*100,"-") -> - | K26: =IFERROR(J26/$J$29*100,"-") -> - | L26: =IFERROR(100*(H26-J26)/J26,"-") -> - | M26: =H26-J26 -> 0
D27: 構成員 | G27: 〃 | I27: =IFERROR(H27/$H$29*100,"-") -> - | K27: =IFERROR(J27/$J$29*100,"-") -> - | L27: =IFERROR(100*(H27-J27)/J27,"-") -> - | M27: =H27-J27 -> 0
C28: 間接労働費 | G28: 〃 | I28: =IFERROR(H28/$H$29*100,"-") -> - | K28: =IFERROR(J28/$J$29*100,"-") -> - | L28: =IFERROR(100*(H28-J28)/J28,"-") -> - | M28: =H28-J28 -> 0
B29: 費用合計 | G29: 〃 | I29: =IFERROR(H29/$H$29*100,"-") -> - | K29: =IFERROR(J29/$J$29*100,"-") -> - | L29: =IFERROR(100*(H29-J29)/J29,"-") -> - | M29: =H29-J29 -> 0
B30: 副産物価額 | G30: 〃 | L30: =IFERROR(100*(H30-J30)/J30,"-") -> - | M30: =H30-J30 -> 0
B31: 生産費（副産物価額差引） | G31: 〃 | L31: =IFERROR(100*(H31-J31)/J31,"-") -> - | M31: =H31-J31 -> 0
B32: 支払利子 | G32: 〃 | L32: =IFERROR(100*(H32-J32)/J32,"-") -> - | M32: =H32-J32 -> 0
B33: 支払地代 | G33: 〃 | L33: =IFERROR(100*(H33-J33)/J33,"-") -> - | M33: =H33-J33 -> 0
B34: 支払利子・地代算入生産費 | G34: 〃 | L34: =IFERROR(100*(H34-J34)/J34,"-") -> - | M34: =H34-J34 -> 0
B35: 自己資本利子 | G35: 〃 | L35: =IFERROR(100*(H35-J35)/J35,"-") -> - | M35: =H35-J35 -> 0
B36: 自作地地代 | G36: 〃 | L36: =IFERROR(100*(H36-J36)/J36,"-") -> - | M36: =H36-J36 -> 0
B37: 資本利子・地代全算入生産費 | G37: 〃 | L37: =IFERROR(100*(H37-J37)/J37,"-") -> - | M37: =H37-J37 -> 0
A38: 60kg当たり生産費 | G38: 〃 | L38: =IFERROR(100*(H38-J38)/J38,"-") -> - | M38: =H38-J38 -> 0
A39: 60kg当たり支払利子・地代算入生産費 | G39: 〃 | L39: =IFERROR(100*(H39-J39)/J39,"-") -> - | M39: =H39-J39 -> 0
A40: 60kg当たり全算入生産費 | G40: 〃 | L40: =IFERROR(100*(H40-J40)/J40,"-") -> - | M40: =H40-J40 -> 0
A41: 経営概況 | B41: 10ａ当たり収量 | G41: kg | L41: =IFERROR(100*(H41-J41)/J41,"-") -> - | M41: =H41-J41 -> 0
...

Sheet No.2
A1: =No.1!A1&"年産 小麦・大豆生産費統計（組織法人経営体）" -> 2019年産 小麦・大豆生産費統計（組織法人経営体） | U1: センサス番号
A2: 個別結果検討表 №２ | U2: =IF(No.1!O2="","",No.1!O2)
A4: 【労働時間（10ａ当たり）】 | O4: 【生産物の概要（10ａ当たり）】
E5: =No.1!H5 -> 19 | F5: =E5-1 -> 18 | G5: 増減率 | S5: =E5 -> 19 | T5: =F5 -> 18 | U5: 増減率
G6: （％） | U6: （％）
A7: 労働時間計 | G7: =IFERROR(100*(E7-F7)/F7,"-") -> - | O7: 主産物 | P7: 数量（kg） | U7: =IFERROR(100*(S7-T7)/T7,"-") -> -
B8: 直接労働時間 | G8: =IFERROR(100*(E8-F8)/F8,"-") -> - | P8: 価額 | U8: =IFERROR(100*(S8-T8)/T8,"-") -> -
C9: 種子予措 | G9: =IFERROR(100*(E9-F9)/F9,"-") -> - | O9: 副産物価額 | U9: =IFERROR(100*(S9-T9)/T9,"-") -> -
C10: 育苗 | G10: =IFERROR(100*(E10-F10)/F10,"-") -> - | O10: 粗収益 | U10: =IFERROR(100*(S10-T10)/T10,"-") -> -
C11: 耕起整地 | G11: =IFERROR(100*(E11-F11)/F11,"-") -> - | O11: （参考）奨励金 | U11: =IFERROR(100*(S11-T11)/T11,"-") -> -
C12: 基肥 | G12: =IFERROR(100*(E12-F12)/F12,"-") -> - | O12: 所得 | U12: =IFERROR(100*(S12-T12)/T12,"-") -> -
C13: は種 | G13: =IFERROR(100*(E13-F13)/F13,"-") -> - | P13: １日当たり | U13: =IFERROR(100*(S13-T13)/T13,"-") -> -
C14: 定植 | G14: =IFERROR(100*(E14-F14)/F14,"-") -> - | O14: 構成員労働報酬 | U14: =IFERROR(100*(S14-T14)/T14,"-") -> -
C15: 追肥 | G15: =IFERROR(100*(E15-F15)/F15,"-") -> - | P15: １日当たり | U15: =IFERROR(100*(S15-T15)/T15,"-") -> -
C16: 中耕除草 | G16: =IFERROR(100*(E16-F16)/F16,"-") -> - | O16: （参考）各種助成措置を加えた場合
C17: 麦踏み | G17: =IFERROR(100*(E17-F17)/F17,"-") -> - | P17: 粗収益 | U17: =IFERROR(100*(S17-T17)/T17,"-") -> -
C18: 管理 | G18: =IFERROR(100*(E18-F18)/F18,"-") -> - | P18: 所得 | U18: =IFERROR(100*(S18-T18)/T18,"-") -> -
C19: 防除 | G19: =IFERROR(100*(E19-F19)/F19,"-") -> - | Q19: １日当たり | U19: =IFERROR(100*(S19-T19)/T19,"-") -> -
C20: 刈取脱穀 | G20: =IFERROR(100*(E20-F20)/F20,"-") -> - | P20: 構成員労働報酬 | U20: =IFERROR(100*(S20-T20)/T20,"-") -> -
C21: 乾燥 | G21: =IFERROR(100*(E21-F21)/F21,"-") -> - | Q21: １日当たり | U21: =IFERROR(100*(S21-T21)/T21,"-") -> -
C22: 生産管理 | G22: =IFERROR(100*(E22-F22)/F22,"-") -> -
B23: 間接労働時間 | G23: =IFERROR(100*(E23-F23)/F23,"-") -> -
A24: 構成員労働時間 | G24: =IFERROR(100*(E24-F24)/F24,"-") -> -
A25: 雇用労働時間 | G25: =IFERROR(100*(E25-F25)/F25,"-") -> -
O26: 【物件税及び公課諸負担（10ａ当たり）】
S27: =E5 -> 19 | T27: =F5 -> 18 | U27: 増減率
S28: （円） | T28: （円） | U28: （％）
O29: 物件税 | U29: =IFERROR(100*(S29-T29)/T29,"-") -> -
O30: 公課諸負担 | U30: =IFERROR(100*(S30-T30)/T30,"-") -> -

Sheet No.3
A1: =No.1!A1&"年産 小麦・大豆生産費統計（組織法人経営体）" -> 2019年産 小麦・大豆生産費統計（組織法人経営体） | R1: センサス番号
A2: 個別結果検討表 №３ | R2: =IF(No.1!O2="","",No.1!O2)
A4: 【作付面積、地代】
I5: 自作地 | L5: 借入地 | O5: 計
I6: =No.1!H5 -> 19 | J6: =I6-1 -> 18 | K6: 増減率 | L6: =$I$6 -> 19 | M6: =$J$6 -> 18 | N6: 増減率 | O6: =$I$6 -> 19 | P6: =$J$6 -> 18 | Q6: 増減率
K7: （％） | N7: （％） | Q7: （％）
A8: 作付地 | C8: 作付実面積 | H8: （ａ） | K8: =IFERROR(100*(I8-J8)/J8,"-") -> - | N8: =IFERROR(100*(L8-M8)/M8,"-") -> - | Q8: =IFERROR(100*(O8-P8)/P8,"-") -> -
C9: 土地台帳面積 | H9: （ａ） | K9: =IFERROR(100*(I9-J9)/J9,"-") -> - | N9: =IFERROR(100*(L9-M9)/M9,"-") -> - | Q9: =IFERROR(100*(O9-P9)/P9,"-") -> -
C10: 10ａ当たり地代総額 | H10: （円） | K10: =IFERROR(100*(I10-J10)/J10,"-") -> - | N10: =IFERROR(100*(L10-M10)/M10,"-") -> - | Q10: =IFERROR(100*(O10-P10)/P10,"-") -> -
C11: 10ａ当たり負担地代 | H11: （円） | K11: =IFERROR(100*(I11-J11)/J11,"-") -> - | N11: =IFERROR(100*(L11-M11)/M11,"-") -> - | Q11: =IFERROR(100*(O11-P11)/P11,"-") -> -
A12: 作付地以外 | C12: 使用面積 | H12: （ａ） | K12: =IFERROR(100*(I12-J12)/J12,"-") -> - | N12: =IFERROR(100*(L12-M12)/M12,"-") -> - | Q12: =IFERROR(100*(O12-P12)/P12,"-") -> -
C13: 10ａ当たり賃借料総額 | H13: （円） | K13: =IFERROR(100*(I13-J13)/J13,"-") -> - | N13: =IFERROR(100*(L13-M13)/M13,"-") -> - | Q13: =IFERROR(100*(O13-P13)/P13,"-") -> -
C14: 10ａ当たり負担地代 | H14: （円） | K14: =IFERROR(100*(I14-J14)/J14,"-") -> - | N14: =IFERROR(100*(L14-M14)/M14,"-") -> - | Q14: =IFERROR(100*(O14-P14)/P14,"-") -> -
A15: 10ａ当たり実勢地代 | H15: （円） | K15: =IFERROR(100*(I15-J15)/J15,"-") -> - | N15: =IFERROR(100*(L15-M15)/M15,"-") -> - | Q15: =IFERROR(100*(O15-P15)/P15,"-") -> -
A18: 【調査作物の受託状況（１経営体当たり）】
I19: =$I$6 -> 19 | J19: =$J$6 -> 18 | K19: 増減率
K20: （％）
A21: 全作業 | H21: ａ | K21: =IFERROR(100*(I21-J21)/J21,"-") -> -
A22: 耕うん・整地 | H22: ａ | K22: =IFERROR(100*(I22-J22)/J22,"-") -> -
A23: は種 | H23: ａ | K23: =IFERROR(100*(I23-J23)/J23,"-") -> -
A24: 防除 | H24: ａ | K24: =IFERROR(100*(I24-J24)/J24,"-") -> -
A25: 刈取・脱穀 | H25: ａ | K25: =IFERROR(100*(I25-J25)/J25,"-") -> -
A26: 乾燥・調製 | H26: kg | K26: =IFERROR(100*(I26-J26)/J26,"-") -> -
A29: 【調査作物の委託状況（１経営体当たり）】
I30: =$I$6 -> 19 | J30: =$J$6 -> 18 | K30: 増減率
K31: （％）
A32: 耕うん・整地 | H32: ａ | K32: =IFERROR(100*(I32-J32)/J32,"-") -> -
A33: は種 | H33: ａ | K33: =IFERROR(100*(I33-J33)/J33,"-") -> -
A34: 防除 | H34: ａ | K34: =IFERROR(100*(I34-J34)/J34,"-") -> -
A35: 刈取・脱穀 | H35: ａ | K35: =IFERROR(100*(I35-J35)/J35,"-") -> -
A36: 乾燥・調製 | H36: kg | K36: =IFERROR(100*(I36-J36)/J36,"-") -> -

Sheet No.4
A1: =No.1!A1&"年産 小麦・大豆生産費統計（組織法人経営体）" -> 2019年産 小麦・大豆生産費統計（組織法人経営体） | O1: センサス番号
A2: 個別結果検討表 №４ | O2: =IF(No.1!O2="","",No.1!O2)
A4: 【費用の内訳（１経営体当たり・10ａ当たり）】
G5: 所 有 台 数 （ １ 経 営 体 当 た り ） | J5: 調 査 作 物 負 担 分 （ 1 0 ａ 当 た り ）
G6: =No.1!H5 -> 19 | H6: =G6-1 -> 18 | I6: 増減率 | J6: =G6 -> 19 | K6: =H6 -> 18 | L6: 増減率
G7: （台） | H7: （台） | I7: （％） | J7: (円) | K7: （円） | L7: （％）
A8: 減価償却費 | L8: =IFERROR(100*(J8-K8)/K8,"-") -> -
B9: 建物・構築物 | L9: =IFERROR(100*(J9-K9)/K9,"-") -> -
D10: 処分差損失 | L10: =IFERROR(100*(J10-K10)/K10,"-") -> -
C11: 住宅 | L11: =IFERROR(100*(J11-K11)/K11,"-") -> -
C12: 納屋・倉庫 | L12: =IFERROR(100*(J12-K12)/K12,"-") -> -
C13: 用水路 | L13: =IFERROR(100*(J13-K13)/K13,"-") -> -
C14: 暗きょ排水施設 | L14: =IFERROR(100*(J14-K14)/K14,"-") -> -
C15: コンクリートけい畔 | L15: =IFERROR(100*(J15-K15)/K15,"-") -> -
C16: 客土 | L16: =IFERROR(100*(J16-K16)/K16,"-") -> -
C17: たい肥盤 | L17: =IFERROR(100*(J17-K17)/K17,"-") -> -
C18: その他 | L18: =IFERROR(100*(J18-K18)/K18,"-") -> -
B19: 自動車 | L19: =IFERROR(100*(J19-K19)/K19,"-") -> -
D20: 処分差損失 | L20: =IFERROR(100*(J20-K20)/K20,"-") -> -
C21: 貨物自動車 | I21: =IFERROR(100*(G21-H21)/H21,"-") -> - | L21: =IFERROR(100*(J21-K21)/K21,"-") -> -
C22: その他 | L22: =IFERROR(100*(J22-K22)/K22,"-") -> -
B23: 農機具 | L23: =IFERROR(100*(J23-K23)/K23,"-") -> -
D24: 処分差損失 | L24: =IFERROR(100*(J24-K24)/K24,"-") -> -
C25: 乗用トラ クター | F25: 20馬力未満 | I25: =IFERROR(100*(G25-H25)/H25,"-") -> - | L25: =IFERROR(100*(J25-K25)/K25,"-") -> -
F26: 20～50馬力未満 | I26: =IFERROR(100*(G26-H26)/H26,"-") -> - | L26: =IFERROR(100*(J26-K26)/K26,"-") -> -
F27: 50馬力以上 | I27: =IFERROR(100*(G27-H27)/H27,"-") -> - | L27: =IFERROR(100*(J27-K27)/K27,"-") -> -
C28: 歩行用トラクター | I28: =IFERROR(100*(G28-H28)/H28,"-") -> - | L28: =IFERROR(100*(J28-K28)/K28,"-") -> -
C29: たい肥等散布機 | I29: =IFERROR(100*(G29-H29)/H29,"-") -> - | L29: =IFERROR(100*(J29-K29)/K29,"-") -> -
C30: 総合は種機 | I30: =IFERROR(100*(G30-H30)/H30,"-") -> - | L30: =IFERROR(100*(J30-K30)/K30,"-") -> -
C31: 中耕除草機 | I31: =IFERROR(100*(G31-H31)/H31,"-") -> - | L31: =IFERROR(100*(J31-K31)/K31,"-") -> -
C32: 肥料散布機 | I32: =IFERROR(100*(G32-H32)/H32,"-") -> - | L32: =IFERROR(100*(J32-K32)/K32,"-") -> -
C33: 動力噴霧機 | I33: =IFERROR(100*(G33-H33)/H33,"-") -> - | L33: =IFERROR(100*(J33-K33)/K33,"-") -> -
C34: 動力散粉機 | I34: =IFERROR(100*(G34-H34)/H34,"-") -> - | L34: =IFERROR(100*(J34-K34)/K34,"-") -> -
C35: 自脱型コ ンバイン | F35: ３条以下 | I35: =IFERROR(100*(G35-H35)/H35,"-") -> - | L35: =IFERROR(100*(J35-K35)/K35,"-") -> -
F36: ４条以上 | I36: =IFERROR(100*(G36-H36)/H36,"-") -> - | L36: =IFERROR(100*(J36-K36)/K36,"-") -> -
C37: 普通型コンバイン | I37: =IFERROR(100*(G37-H37)/H37,"-") -> - | L37: =IFERROR(100*(J37-K37)/K37,"-") -> -
C38: 調査作物収穫機 | I38: =IFERROR(100*(G38-H38)/H38,"-") -> - | L38: =IFERROR(100*(J38-K38)/K38,"-") -> -
C39: 脱穀機 | I39: =IFERROR(100*(G39-H39)/H39,"-") -> - | L39: =IFERROR(100*(J39-K39)/K39,"-") -> -
C40: 乾燥機 | I40: =IFERROR(100*(G40-H40)/H40,"-") -> - | L40: =IFERROR(100*(J40-K40)/K40,"-") -> -
C41: トレーラー | I41: =IFERROR(100*(G41-H41)/H41,"-") -> - | L41: =IFERROR(100*(J41-K41)/K41,"-") -> -
...

Sheet No.5
A1: =No.1!A1&"年産 小麦・大豆生産費統計（組織法人経営体）" -> 2019年産 小麦・大豆生産費統計（組織法人経営体） | Q1: センサス番号
A2: 個別結果検討表 №５ | Q2: =IF(No.1!O2="","",No.1!O2)
A4: 【生産物の処分内訳（10ａ当たり）】
G5: =No.1!H5 -> 19 | J5: =G5-1 -> 18 | M5: 増 減 率
G6: 数量 | H6: 価額 | I6: 単価 | J6: 数量 | K6: 価額 | L6: 単価 | M6: 数量 | N6: 価額 | O6: 単価
G7: （kg） | H7: （円） | I7: （円） | J7: （kg） | K7: （円） | L7: （円） | M7: （％） | N7: （％） | O7: （％）
A8: 小麦 | B8: 主産物 | C8: 販売用 | D8: １等 | M8: =IFERROR(100*(G8-J8)/J8,"-") -> - | N8: =IFERROR(100*(H8-K8)/K8,"-") -> - | O8: =IFERROR(100*(I8-L8)/L8,"-") -> -
D9: ２等 | M9: =IFERROR(100*(G9-J9)/J9,"-") -> - | N9: =IFERROR(100*(H9-K9)/K9,"-") -> - | O9: =IFERROR(100*(I9-L9)/L9,"-") -> -
D10: 規格外Ａ | M10: =IFERROR(100*(G10-J10)/J10,"-") -> - | N10: =IFERROR(100*(H10-K10)/K10,"-") -> - | O10: =IFERROR(100*(I10-L10)/L10,"-") -> -
D11: その他 | M11: =IFERROR(100*(G11-J11)/J11,"-") -> - | N11: =IFERROR(100*(H11-K11)/K11,"-") -> - | O11: =IFERROR(100*(I11-L11)/L11,"-") -> -
D12: 小計 | M12: =IFERROR(100*(G12-J12)/J12,"-") -> - | N12: =IFERROR(100*(H12-K12)/K12,"-") -> - | O12: =IFERROR(100*(I12-L12)/L12,"-") -> -
C13: 組織用 | D13: 食用 | M13: =IFERROR(100*(G13-J13)/J13,"-") -> - | N13: =IFERROR(100*(H13-K13)/K13,"-") -> - | O13: =IFERROR(100*(I13-L13)/L13,"-") -> -
D14: 種子用 | M14: =IFERROR(100*(G14-J14)/J14,"-") -> - | N14: =IFERROR(100*(H14-K14)/K14,"-") -> - | O14: =IFERROR(100*(I14-L14)/L14,"-") -> -
D15: その他 | M15: =IFERROR(100*(G15-J15)/J15,"-") -> - | N15: =IFERROR(100*(H15-K15)/K15,"-") -> - | O15: =IFERROR(100*(I15-L15)/L15,"-") -> -
D16: 小計 | M16: =IFERROR(100*(G16-J16)/J16,"-") -> - | N16: =IFERROR(100*(H16-K16)/K16,"-") -> - | O16: =IFERROR(100*(I16-L16)/L16,"-") -> -
C17: 合計 | M17: =IFERROR(100*(G17-J17)/J17,"-") -> - | N17: =IFERROR(100*(H17-K17)/K17,"-") -> - | O17: =IFERROR(100*(I17-L17)/L17,"-") -> -
B18: 副産物 | C18: 販売用 | D18: 規格外Ｂ | M18: =IFERROR(100*(G18-J18)/J18,"-") -> - | N18: =IFERROR(100*(H18-K18)/K18,"-") -> - | O18: =IFERROR(100*(I18-L18)/L18,"-") -> -
D19: 規格外Ｃ | M19: =IFERROR(100*(G19-J19)/J19,"-") -> - | N19: =IFERROR(100*(H19-K19)/K19,"-") -> - | O19: =IFERROR(100*(I19-L19)/L19,"-") -> -
D20: くず麦 | M20: =IFERROR(100*(G20-J20)/J20,"-") -> - | N20: =IFERROR(100*(H20-K20)/K20,"-") -> - | O20: =IFERROR(100*(I20-L20)/L20,"-") -> -
D21: 麦わら | M21: =IFERROR(100*(G21-J21)/J21,"-") -> - | N21: =IFERROR(100*(H21-K21)/K21,"-") -> - | O21: =IFERROR(100*(I21-L21)/L21,"-") -> -
D22: 小計 | N22: =IFERROR(100*(H22-K22)/K22,"-") -> -
C23: 組織用 | D23: 規格外Ｂ | M23: =IFERROR(100*(G23-J23)/J23,"-") -> - | N23: =IFERROR(100*(H23-K23)/K23,"-") -> - | O23: =IFERROR(100*(I23-L23)/L23,"-") -> -
D24: 規格外Ｃ | M24: =IFERROR(100*(G24-J24)/J24,"-") -> - | N24: =IFERROR(100*(H24-K24)/K24,"-") -> - | O24: =IFERROR(100*(I24-L24)/L24,"-") -> -
D25: くず麦 | M25: =IFERROR(100*(G25-J25)/J25,"-") -> - | N25: =IFERROR(100*(H25-K25)/K25,"-") -> - | O25: =IFERROR(100*(I25-L25)/L25,"-") -> -
D26: 麦わら | M26: =IFERROR(100*(G26-J26)/J26,"-") -> - | N26: =IFERROR(100*(H26-K26)/K26,"-") -> - | O26: =IFERROR(100*(I26-L26)/L26,"-") -> -
E27: 無評価 | M27: =IFERROR(100*(G27-J27)/J27,"-") -> -
D28: 小計 | N28: =IFERROR(100*(H28-K28)/K28,"-") -> -
C29: 合計 | N29: =IFERROR(100*(H29-K29)/K29,"-") -> -

Sheet No.5 (2)
A1: =No.1!A1&"年産 小麦・大豆生産費統計（組織法人経営体）" -> 2019年産 小麦・大豆生産費統計（組織法人経営体） | Q1: センサス番号
A2: 個別結果検討表 №５ | Q2: =IF(No.1!O2="","",No.1!O2)
A4: 【生産物の処分内訳（10ａ当たり）】
G5: =No.1!H5 -> 19 | J5: =G5-1 -> 18 | M5: 増 減 率
G6: 数量 | H6: 価額 | I6: 単価 | J6: 数量 | K6: 価額 | L6: 単価 | M6: 数量 | N6: 価額 | O6: 単価
G7: （kg） | H7: （円） | I7: （円） | J7: （kg） | K7: （円） | L7: （円） | M7: （％） | N7: （％） | O7: （％）
A8: 大豆 | B8: 主産物 | C8: 販売用 | D8: １等 | M8: =IFERROR(100*(G8-J8)/J8,"-") -> - | N8: =IFERROR(100*(H8-K8)/K8,"-") -> - | O8: =IFERROR(100*(I8-L8)/L8,"-") -> -
D9: ２等 | M9: =IFERROR(100*(G9-J9)/J9,"-") -> - | N9: =IFERROR(100*(H9-K9)/K9,"-") -> - | O9: =IFERROR(100*(I9-L9)/L9,"-") -> -
D10: ３等・規格外 | M10: =IFERROR(100*(G10-J10)/J10,"-") -> - | N10: =IFERROR(100*(H10-K10)/K10,"-") -> - | O10: =IFERROR(100*(I10-L10)/L10,"-") -> -
D11: 特定加工用 | M11: =IFERROR(100*(G11-J11)/J11,"-") -> - | N11: =IFERROR(100*(H11-K11)/K11,"-") -> - | O11: =IFERROR(100*(I11-L11)/L11,"-") -> -
D12: その他 | M12: =IFERROR(100*(G12-J12)/J12,"-") -> - | N12: =IFERROR(100*(H12-K12)/K12,"-") -> - | O12: =IFERROR(100*(I12-L12)/L12,"-") -> -
D13: 小計 | M13: =IFERROR(100*(G13-J13)/J13,"-") -> - | N13: =IFERROR(100*(H13-K13)/K13,"-") -> - | O13: =IFERROR(100*(I13-L13)/L13,"-") -> -
C14: 組織用 | D14: 食用 | M14: =IFERROR(100*(G14-J14)/J14,"-") -> - | N14: =IFERROR(100*(H14-K14)/K14,"-") -> - | O14: =IFERROR(100*(I14-L14)/L14,"-") -> -
D15: 種子用 | M15: =IFERROR(100*(G15-J15)/J15,"-") -> - | N15: =IFERROR(100*(H15-K15)/K15,"-") -> - | O15: =IFERROR(100*(I15-L15)/L15,"-") -> -
D16: その他 | M16: =IFERROR(100*(G16-J16)/J16,"-") -> - | N16: =IFERROR(100*(H16-K16)/K16,"-") -> - | O16: =IFERROR(100*(I16-L16)/L16,"-") -> -
D17: 小計 | M17: =IFERROR(100*(G17-J17)/J17,"-") -> - | N17: =IFERROR(100*(H17-K17)/K17,"-") -> - | O17: =IFERROR(100*(I17-L17)/L17,"-") -> -
C18: 合計 | M18: =IFERROR(100*(G18-J18)/J18,"-") -> - | N18: =IFERROR(100*(H18-K18)/K18,"-") -> - | O18: =IFERROR(100*(I18-L18)/L18,"-") -> -
B19: 副産物 | C19: 販売用 | M19: =IFERROR(100*(G19-J19)/J19,"-") -> - | N19: =IFERROR(100*(H19-K19)/K19,"-") -> - | O19: =IFERROR(100*(I19-L19)/L19,"-") -> -
C20: 組織用 | M20: =IFERROR(100*(G20-J20)/J20,"-") -> - | N20: =IFERROR(100*(H20-K20)/K20,"-") -> - | O20: =IFERROR(100*(I20-L20)/L20,"-") -> -
C21: 計 | M21: =IFERROR(100*(G21-J21)/J21,"-") -> - | N21: =IFERROR(100*(H21-K21)/K21,"-") -> - | O21: =IFERROR(100*(I21-L21)/L21,"-") -> -
